Workbook
Name ALLOC_BRAND_CAMP: ALLOC!$C$8
Name ALLOC_CAMP_CLASS: ALLOC!$C$9
Name ALLOC_GRP_BRAND: ALLOC!$C$6
Name ALLOC_GRP_MARQUE: ALLOC!$C$7
Name BUD_REF_CAP: PIL!$K$15:$K$28
Name HYP_ACQ_BUD_V01: cad!$C$23
Name HYP_ACQ_BUD_V02: cad!$D$23
Name HYP_ACQ_BUD_V03: cad!$E$23
Name HYP_BRAND_BUD_V01: cad!$C$24
Name HYP_BRAND_BUD_V02: cad!$D$24
Name HYP_BRAND_BUD_V03: cad!$E$24
Name HYP_CAP_RETENU: PIL!$J$15:$J$28
Name HYP_CONV_ADM_V01: cad!$C$27
Name HYP_CONV_ADM_V02: cad!$D$27
Name HYP_CONV_ADM_V03: cad!$E$27
Name HYP_CONV_LEAD_V01: cad!$C$26
Name HYP_CONV_LEAD_V02: cad!$D$26
Name HYP_CONV_LEAD_V03: cad!$E$26
Name HYP_FEE_V01: cad!$C$39
Name HYP_FEE_V02: cad!$D$39
Name HYP_FEE_V03: cad!$E$39
Name HYP_FTE_PERM_V01: cad!$C$34
Name HYP_FTE_PERM_V02: cad!$D$34
Name HYP_FTE_PERM_V03: cad!$E$34
Name HYP_INFL_EXT_V01: cad!$C$32
Name HYP_INFL_EXT_V02: cad!$D$32
Name HYP_INFL_EXT_V03: cad!$E$32
Name HYP_PASSAGE_V01: cad!$C$28
Name HYP_PASSAGE_V02: cad!$D$28
Name HYP_PASSAGE_V03: cad!$E$28
Name HYP_PRICE_COEF_IPAC: cad!$J$14
Name HYP_PRICE_COEF_ISCOM: cad!$J$13
Name HYP_PRICE_COEF_MBWAY: cad!$J$12
Name HYP_PRICE_COEF_PIGIER: cad!$J$15
Name HYP_PRICE_COEF_TUNON: cad!$J$16
Name HYP_PRICE_V01: cad!$C$25
Name HYP_PRICE_V02: cad!$D$25
Name HYP_PRICE_V03: cad!$E$25
Name HYP_PRODUCTIVITY_V01: cad!$C$35
Name HYP_PRODUCTIVITY_V02: cad!$D$35
Name HYP_PRODUCTIVITY_V03: cad!$E$35
Name HYP_SALARY_V01: cad!$C$33
Name HYP_SALARY_V02: cad!$D$33
Name HYP_SALARY_V03: cad!$E$33
Name HYP_STRUCT_COST_V01: cad!$C$36
Name HYP_STRUCT_COST_V02: cad!$D$36
Name HYP_STRUCT_COST_V03: cad!$E$36
Name SCENARIO_ACTIF: cad!$C$5
Name SCENARIO_CODE: cad!$P$1
Name TEC_EBITDA: cad!$F$6
Name TEC_PL: cad!$F$5

Sheet _TGK_HIDDEN
A1: Template00 | B1: =cad!A65546 -> 0
A2: Template01 | B2: =Allocation2!A65536 -> 0
A3: Template02 | B3: =Campagne!A65536 -> 0
A4: Template03 | B4: =Moteur!A65536 -> 0
A5: Template04 | B5: =Compta!A65536 -> 0
A6: Template05 | B6: =PNL!A65536 -> 0
A7: Template06 | B7: =PIL!A65538 -> 0
A10: Template09 | B10: =ALLOC!B65537 -> 0

Sheet cad
P1: =IF(cad!$C$5="Optimiste","V02",IF(cad!$C$5="Prudent","V03","V01")) -> V01
B2: POSTE DE COMMANDE CFO — Cadrage CA & EBITDA 2027
B5: Scenario actif : | C5: 1000 | E5: Croissance CA cible : | F5: 0.05
E6: Marge EBITDA cible : | F6: 0.15
B8: Reconciliation — Reference · Cible · Construit (scenario actif) | I8: Coeff prix par marque (decision)
B10: Indicateur | C10: Reference | D10: Cible | E10: Construit | F10: Ecart | G10: Ecart % | I10: Marque | J10: Coeff prix
C11: 2026
B12: Chiffre d'affaires | C12: 22544725 | D12: =C12*(1+cad!$F$5) -> 23671961 | E12: =SUMIFS(Moteur!$R$1:$R$175,Moteur!$B$1:$B$175,cad!$P$1) -> 0 | F12: =E12-D12 -> -23671961 | G12: =IFERROR(E12/D12-1,0) -> -1 | I12: MBway | J12: 1.2
B13: EBITDA | C13: 3291530 | D13: =D12*cad!$F$6 -> 3550794.2 | E13: =SUMIFS(_CALC_PNL!$T$1:$T$1347,_CALC_PNL!$D$1:$D$1347,cad!$P$1,_CALC_PNL!$C$1:$C$1347,"2027") -> 0 | F13: =E13-D13 -> -3550794.2 | G13: =IFERROR(E13/D13-1,0) -> -1 | I13: ISCOM | J13: 1.15
B14: Marge EBITDA % | C14: =IFERROR(C13/C12,0) -> 0.14600001 | D14: =cad!$F$6 -> 0.15 | E14: =IFERROR(E13/E12,0) -> 0 | F14: =E14-D14 -> -0.15 | I14: Ipac Bachelor Factory | J14: 0.95
B15: Effectif | C15: 1000 | E15: =SUMIFS(Moteur!$P$1:$P$175,Moteur!$B$1:$B$175,cad!$P$1) -> 0 | F15: =E15-#REF! -> #REF! | G15: =IFERROR(E15/#REF!-1,0) -> 0 | I15: Pigier | J15: 0.9
I16: Tunon | J16: 1.05
B19: Leviers de CROISSANCE / REVENUS
B21: Paramètre | C21: =C22 -> Cadrage | D21: =D22 -> Optimiste | E21: =E22 -> Prudent | F21: ACTIF (scenario)
C22: Cadrage | D22: Optimiste | E22: Prudent
B23: Variation du budget d'acquisition → leads payants | C23: 0.08 | D23: 0.15 | E23: -0.05 | F23: #N/A
B24: Variation du budget de marque → socle organique | C24: 0.1 | D24: 0.2 | E24: -0.05 | F24: #N/A
B25: Hausse tarifaire (prix) | C25: 0.002855 | D25: 0.035 | E25: 0.02 | F25: #N/A
B26: Gain du taux de conversion Lead → Candidature | C26: 0.01 | D26: 0.03 | E26: 0 | F26: #N/A
B27: Gain du taux de conversion Admis → Inscrit | C27: 0.01 | D27: 0.025 | E27: 0 | F27: #N/A
B28: Amélioration du taux de passage | C28: 0.005 | D28: 0.015 | E28: -0.01 | F28: #N/A
B30: Leviers de COUTS
B32: Inflation des charges externes | C32: 0.02 | D32: 0.015 | E32: 0.03 | F32: =INDEX(C32:E32,MATCH(cad!$C$5,$C$22:$E$22,0)) -> #N/A
B33: Politique salariale sur la masse permanente | C33: 0.025 | D33: 0.02 | E33: 0.03 | F33: =INDEX(C33:E33,MATCH(cad!$C$5,$C$22:$E$22,0)) -> #N/A
B34: Variation des effectifs permanents | C34: 0.04 | D34: 0.03 | E34: 0.05 | F34: =INDEX(C34:E34,MATCH(cad!$C$5,$C$22:$E$22,0)) -> #N/A
B35: Effort de productivité sur les achats et la structure | C35: 0.018697 | D35: 0.03 | E35: 0 | F35: =INDEX(C35:E35,MATCH(cad!$C$5,$C$22:$E$22,0)) -> #N/A
B36: Variation des coûts de structure (loyers, IT, siège…) | C36: 0 | D36: -0.03 | E36: 0.04 | F36: =INDEX(C36:E36,MATCH(cad!$C$5,$C$22:$E$22,0)) -> #N/A
B38: Constante — frais de dossier (decision)
B39: Frais de dossier par nouvel inscrit | C39: 90 | D39: 90 | E39: 90 | F39: =INDEX(C39:E39,MATCH(cad!$C$5,$C$22:$E$22,0)) -> #N/A

Sheet PIL
B2: PILOTAGE · Cockpit de decision CFO — Budget 2027
B6: CA 2027 | D6: EBITDA (après siège) | F6: Marge EBITDA | H6: Effectif | J6: Croissance CA vs 2026
B7: =E49 -> 0 | D7: =H49 -> 0 | F7: =I49 -> 0 | H7: =D49 -> 0 | J7: =IFERROR(E49/cad!$C$12-1,0) -> -1
B12: 1 · Cap strategique par campus (marque x ville) — arbitrage du budget d'acquisition
U13: à masquer | V13: à masquer | W13: à masquer
A14: Campus | B14: Marque | C14: Ville | D14: CAC marginal | E14: Croiss. leads | F14: Intensité mkt | G14: Cap Eff | H14: Cap mom. | I14: Cap pot. | J14: Cap retenu | K14: Budget acq réf. | L14: Entity | U14: CAP_EFF (live) | V14: CAP_MOM (live) | W14: CAP_POT (live)
A15: MBWAY_PAR | B15: MBway | C15: Paris | D15: 1475 | E15: 0.110736 | F15: 0.021757 | G15: 0.81 | H15: 1.06 | I15: 0.86 | J15: 1 | K15: 68291 | L15: MBWAY_PAR
A16: MBWAY_LYO | B16: MBway | C16: Lyon | D16: 1102 | E16: 0.118872 | F16: 0.016735 | G16: 1.09 | H16: 1.14 | I16: 1.12 | J16: 1 | K16: 41783
A17: MBWAY_NAN | B17: MBway | C17: Nantes | D17: 964 | E17: 0.123795 | F17: 0.01461 | G17: 1.25 | H17: 1.18 | I17: 1.29 | J17: 1 | K17: 31533
A18: MBWAY_BOR | B18: MBway | C18: Bordeaux | D18: 890 | E18: 0.126095 | F18: 0.014052 | G18: 1.35 | H18: 1.21 | I18: 1.34 | J18: 1 | K18: 24923
A19: ISCOM_PAR | B19: ISCOM | C19: Paris | D19: 1540 | E19: 0.077745 | F19: 0.020903 | G19: 0.78 | H19: 0.74 | I19: 0.9 | J19: 1 | K19: 60800
A20: ISCOM_LIL | B20: ISCOM | C20: Lille | D20: 979 | E20: 0.081545 | F20: 0.014363 | G20: 1.23 | H20: 0.78 | I20: 1.31 | J20: 1 | K20: 25220
A21: ISCOM_TLS | B21: ISCOM | C21: Toulouse | D21: 919 | E21: 0.082117 | F21: 0.013565 | G21: 1.31 | H21: 0.79 | I21: 1.39 | J21: 1 | K21: 22083
A22: IPAC_NAN | B22: Ipac | C22: Nantes | D22: 1216 | E22: 0.137885 | F22: 0.021344 | G22: 0.99 | H22: 1.32 | I22: 0.88 | J22: 1 | K22: 21760
A23: IPAC_REN | B23: Ipac | C23: Rennes | D23: 1041 | E23: 0.144781 | F23: 0.019104 | G23: 1.16 | H23: 1.39 | I23: 0.98 | J23: 1 | K23: 14933
A24: IPAC_MTP | B24: Ipac | C24: Montpellier | D24: 1034 | E24: 0.144781 | F24: 0.019418 | G24: 1.16 | H24: 1.39 | I24: 0.97 | J24: 1 | K24: 15178
A25: PIGIER_LYO | B25: Pigier | C25: Lyon | D25: 1705 | E25: 0.085003 | F25: 0.02928 | G25: 0.71 | H25: 0.81 | I25: 0.64 | J25: 1 | K25: 36612
A26: PIGIER_BOR | B26: Pigier | C26: Bordeaux | D26: 1368 | E26: 0.087533 | F26: 0.02436 | G26: 0.88 | H26: 0.84 | I26: 0.77 | J26: 1 | K26: 21968
A27: TUNON_PAR | B27: Tunon | C27: Paris | D27: 2193 | E27: 0.069519 | F27: 0.027841 | G27: 0.55 | H27: 0.67 | I27: 0.68 | J27: 1 | K27: 30240
A28: TUNON_LYO | B28: Tunon | C28: Lyon | D28: 1625 | E28: 0.072555 | F28: 0.021828 | G28: 0.74 | H28: 0.69 | I28: 0.86 | J28: 1 | K28: 18850
B30: 2 · Synthese par campus (resultats budget, live)
A32: Campus | B32: Marque | C32: Ville | D32: Effectif | E32: CA 2027 | F32: Prix moy. | G32: Part CA | H32: EBITDA campus | I32: Mrg EBITDA | J32: EBITDA/etud. | K32: Rejoue | L32: CAC marg.
A33: MBWAY_PAR | B33: MBway | C33: Paris | D33: =SUMIFS(Moteur!$P$1:$P$175,Moteur!$D$1:$D$175,$A33,Moteur!$B$1:$B$175,cad!$P$1) -> 0 | E33: =SUMIFS(Moteur!$R$1:$R$175,Moteur!$D$1:$D$175,$A33,Moteur!$B$1:$B$175,cad!$P$1) -> 0 | F33: =IFERROR(E33/D33,0) -> 0 | G33: =IFERROR(E33/SUM($E$33:$E$46),0) -> 0 | H33: =SUMIFS(_CALC_PNL!$T$1:$T$1347,_CALC_PNL!$A$1:$A$1347,$A33,_CALC_PNL!$D$1:$D$1347,cad!$P$1,_CALC_PNL!$C$1:$C$1347,"2027") -> 0 | I33: =IFERROR(H33/E33,0) -> 0 | J33: =IFERROR(H33/D33,0) -> 0 | K33: =SUMIFS(PIL!$K$15:$K$28,PIL!$A$15:$A$28,$A33)*SUMIFS(PIL!$J$15:$J$28,PIL!$A$15:$A$28,$A33)*(SUM(PIL!$K$15:$K$28)/SUMPRODUCT(PIL!$K$15:$K$28,PIL!$J$15:$J$28)) -> 68291 | L33: =SUMIFS(PIL!$D$15:$D$28,PIL!$A$15:$A$28,$A33) -> 1475
A34: MBWAY_LYO | B34: MBway | C34: Lyon | D34: =SUMIFS(Moteur!$P$1:$P$175,Moteur!$D$1:$D$175,$A34,Moteur!$B$1:$B$175,cad!$P$1) -> 0 | E34: =SUMIFS(Moteur!$R$1:$R$175,Moteur!$D$1:$D$175,$A34,Moteur!$B$1:$B$175,cad!$P$1) -> 0 | F34: =IFERROR(E34/D34,0) -> 0 | G34: =IFERROR(E34/SUM($E$33:$E$46),0) -> 0 | H34: =SUMIFS(_CALC_PNL!$T$1:$T$1347,_CALC_PNL!$A$1:$A$1347,$A34,_CALC_PNL!$D$1:$D$1347,cad!$P$1,_CALC_PNL!$C$1:$C$1347,"2027") -> 0 | I34: =IFERROR(H34/E34,0) -> 0 | J34: =IFERROR(H34/D34,0) -> 0 | K34: =SUMIFS(PIL!$K$15:$K$28,PIL!$A$15:$A$28,$A34)*SUMIFS(PIL!$J$15:$J$28,PIL!$A$15:$A$28,$A34)*(SUM(PIL!$K$15:$K$28)/SUMPRODUCT(PIL!$K$15:$K$28,PIL!$J$15:$J$28)) -> 41783 | L34: =SUMIFS(PIL!$D$15:$D$28,PIL!$A$15:$A$28,$A34) -> 1102
A35: MBWAY_NAN | B35: MBway | C35: Nantes | D35: =SUMIFS(Moteur!$P$1:$P$175,Moteur!$D$1:$D$175,$A35,Moteur!$B$1:$B$175,cad!$P$1) -> 0 | E35: =SUMIFS(Moteur!$R$1:$R$175,Moteur!$D$1:$D$175,$A35,Moteur!$B$1:$B$175,cad!$P$1) -> 0 | F35: =IFERROR(E35/D35,0) -> 0 | G35: =IFERROR(E35/SUM($E$33:$E$46),0) -> 0 | H35: =SUMIFS(_CALC_PNL!$T$1:$T$1347,_CALC_PNL!$A$1:$A$1347,$A35,_CALC_PNL!$D$1:$D$1347,cad!$P$1,_CALC_PNL!$C$1:$C$1347,"2027") -> 0 | I35: =IFERROR(H35/E35,0) -> 0 | J35: =IFERROR(H35/D35,0) -> 0 | K35: =SUMIFS(PIL!$K$15:$K$28,PIL!$A$15:$A$28,$A35)*SUMIFS(PIL!$J$15:$J$28,PIL!$A$15:$A$28,$A35)*(SUM(PIL!$K$15:$K$28)/SUMPRODUCT(PIL!$K$15:$K$28,PIL!$J$15:$J$28)) -> 31533 | L35: =SUMIFS(PIL!$D$15:$D$28,PIL!$A$15:$A$28,$A35) -> 964
A36: MBWAY_BOR | B36: MBway | C36: Bordeaux | D36: =SUMIFS(Moteur!$P$1:$P$175,Moteur!$D$1:$D$175,$A36,Moteur!$B$1:$B$175,cad!$P$1) -> 0 | E36: =SUMIFS(Moteur!$R$1:$R$175,Moteur!$D$1:$D$175,$A36,Moteur!$B$1:$B$175,cad!$P$1) -> 0 | F36: =IFERROR(E36/D36,0) -> 0 | G36: =IFERROR(E36/SUM($E$33:$E$46),0) -> 0 | H36: =SUMIFS(_CALC_PNL!$T$1:$T$1347,_CALC_PNL!$A$1:$A$1347,$A36,_CALC_PNL!$D$1:$D$1347,cad!$P$1,_CALC_PNL!$C$1:$C$1347,"2027") -> 0 | I36: =IFERROR(H36/E36,0) -> 0 | J36: =IFERROR(H36/D36,0) -> 0 | K36: =SUMIFS(PIL!$K$15:$K$28,PIL!$A$15:$A$28,$A36)*SUMIFS(PIL!$J$15:$J$28,PIL!$A$15:$A$28,$A36)*(SUM(PIL!$K$15:$K$28)/SUMPRODUCT(PIL!$K$15:$K$28,PIL!$J$15:$J$28)) -> 24923 | L36: =SUMIFS(PIL!$D$15:$D$28,PIL!$A$15:$A$28,$A36) -> 890
A37: ISCOM_PAR | B37: ISCOM | C37: Paris | D37: =SUMIFS(Moteur!$P$1:$P$175,Moteur!$D$1:$D$175,$A37,Moteur!$B$1:$B$175,cad!$P$1) -> 0 | E37: =SUMIFS(Moteur!$R$1:$R$175,Moteur!$D$1:$D$175,$A37,Moteur!$B$1:$B$175,cad!$P$1) -> 0 | F37: =IFERROR(E37/D37,0) -> 0 | G37: =IFERROR(E37/SUM($E$33:$E$46),0) -> 0 | H37: =SUMIFS(_CALC_PNL!$T$1:$T$1347,_CALC_PNL!$A$1:$A$1347,$A37,_CALC_PNL!$D$1:$D$1347,cad!$P$1,_CALC_PNL!$C$1:$C$1347,"2027") -> 0 | I37: =IFERROR(H37/E37,0) -> 0 | J37: =IFERROR(H37/D37,0) -> 0 | K37: =SUMIFS(PIL!$K$15:$K$28,PIL!$A$15:$A$28,$A37)*SUMIFS(PIL!$J$15:$J$28,PIL!$A$15:$A$28,$A37)*(SUM(PIL!$K$15:$K$28)/SUMPRODUCT(PIL!$K$15:$K$28,PIL!$J$15:$J$28)) -> 60800 | L37: =SUMIFS(PIL!$D$15:$D$28,PIL!$A$15:$A$28,$A37) -> 1540
A38: ISCOM_LIL | B38: ISCOM | C38: Lille | D38: =SUMIFS(Moteur!$P$1:$P$175,Moteur!$D$1:$D$175,$A38,Moteur!$B$1:$B$175,cad!$P$1) -> 0 | E38: =SUMIFS(Moteur!$R$1:$R$175,Moteur!$D$1:$D$175,$A38,Moteur!$B$1:$B$175,cad!$P$1) -> 0 | F38: =IFERROR(E38/D38,0) -> 0 | G38: =IFERROR(E38/SUM($E$33:$E$46),0) -> 0 | H38: =SUMIFS(_CALC_PNL!$T$1:$T$1347,_CALC_PNL!$A$1:$A$1347,$A38,_CALC_PNL!$D$1:$D$1347,cad!$P$1,_CALC_PNL!$C$1:$C$1347,"2027") -> 0 | I38: =IFERROR(H38/E38,0) -> 0 | J38: =IFERROR(H38/D38,0) -> 0 | K38: =SUMIFS(PIL!$K$15:$K$28,PIL!$A$15:$A$28,$A38)*SUMIFS(PIL!$J$15:$J$28,PIL!$A$15:$A$28,$A38)*(SUM(PIL!$K$15:$K$28)/SUMPRODUCT(PIL!$K$15:$K$28,PIL!$J$15:$J$28)) -> 25220 | L38: =SUMIFS(PIL!$D$15:$D$28,PIL!$A$15:$A$28,$A38) -> 979
A39: ISCOM_TLS | B39: ISCOM | C39: Toulouse | D39: =SUMIFS(Moteur!$P$1:$P$175,Moteur!$D$1:$D$175,$A39,Moteur!$B$1:$B$175,cad!$P$1) -> 0 | E39: =SUMIFS(Moteur!$R$1:$R$175,Moteur!$D$1:$D$175,$A39,Moteur!$B$1:$B$175,cad!$P$1) -> 0 | F39: =IFERROR(E39/D39,0) -> 0 | G39: =IFERROR(E39/SUM($E$33:$E$46),0) -> 0 | H39: =SUMIFS(_CALC_PNL!$T$1:$T$1347,_CALC_PNL!$A$1:$A$1347,$A39,_CALC_PNL!$D$1:$D$1347,cad!$P$1,_CALC_PNL!$C$1:$C$1347,"2027") -> 0 | I39: =IFERROR(H39/E39,0) -> 0 | J39: =IFERROR(H39/D39,0) -> 0 | K39: =SUMIFS(PIL!$K$15:$K$28,PIL!$A$15:$A$28,$A39)*SUMIFS(PIL!$J$15:$J$28,PIL!$A$15:$A$28,$A39)*(SUM(PIL!$K$15:$K$28)/SUMPRODUCT(PIL!$K$15:$K$28,PIL!$J$15:$J$28)) -> 22083 | L39: =SUMIFS(PIL!$D$15:$D$28,PIL!$A$15:$A$28,$A39) -> 919
A40: IPAC_NAN | B40: Ipac | C40: Nantes | D40: =SUMIFS(Moteur!$P$1:$P$175,Moteur!$D$1:$D$175,$A40,Moteur!$B$1:$B$175,cad!$P$1) -> 0 | E40: =SUMIFS(Moteur!$R$1:$R$175,Moteur!$D$1:$D$175,$A40,Moteur!$B$1:$B$175,cad!$P$1) -> 0 | F40: =IFERROR(E40/D40,0) -> 0 | G40: =IFERROR(E40/SUM($E$33:$E$46),0) -> 0 | H40: =SUMIFS(_CALC_PNL!$T$1:$T$1347,_CALC_PNL!$A$1:$A$1347,$A40,_CALC_PNL!$D$1:$D$1347,cad!$P$1,_CALC_PNL!$C$1:$C$1347,"2027") -> 0 | I40: =IFERROR(H40/E40,0) -> 0 | J40: =IFERROR(H40/D40,0) -> 0 | K40: =SUMIFS(PIL!$K$15:$K$28,PIL!$A$15:$A$28,$A40)*SUMIFS(PIL!$J$15:$J$28,PIL!$A$15:$A$28,$A40)*(SUM(PIL!$K$15:$K$28)/SUMPRODUCT(PIL!$K$15:$K$28,PIL!$J$15:$J$28)) -> 21760 | L40: =SUMIFS(PIL!$D$15:$D$28,PIL!$A$15:$A$28,$A40) -> 1216
A41: IPAC_REN | B41: Ipac | C41: Rennes | D41: =SUMIFS(Moteur!$P$1:$P$175,Moteur!$D$1:$D$175,$A41,Moteur!$B$1:$B$175,cad!$P$1) -> 0 | E41: =SUMIFS(Moteur!$R$1:$R$175,Moteur!$D$1:$D$175,$A41,Moteur!$B$1:$B$175,cad!$P$1) -> 0 | F41: =IFERROR(E41/D41,0) -> 0 | G41: =IFERROR(E41/SUM($E$33:$E$46),0) -> 0 | H41: =SUMIFS(_CALC_PNL!$T$1:$T$1347,_CALC_PNL!$A$1:$A$1347,$A41,_CALC_PNL!$D$1:$D$1347,cad!$P$1,_CALC_PNL!$C$1:$C$1347,"2027") -> 0 | I41: =IFERROR(H41/E41,0) -> 0 | J41: =IFERROR(H41/D41,0) -> 0 | K41: =SUMIFS(PIL!$K$15:$K$28,PIL!$A$15:$A$28,$A41)*SUMIFS(PIL!$J$15:$J$28,PIL!$A$15:$A$28,$A41)*(SUM(PIL!$K$15:$K$28)/SUMPRODUCT(PIL!$K$15:$K$28,PIL!$J$15:$J$28)) -> 14933 | L41: =SUMIFS(PIL!$D$15:$D$28,PIL!$A$15:$A$28,$A41) -> 1041
A42: IPAC_MTP | B42: Ipac | C42: Montpellier | D42: =SUMIFS(Moteur!$P$1:$P$175,Moteur!$D$1:$D$175,$A42,Moteur!$B$1:$B$175,cad!$P$1) -> 0 | E42: =SUMIFS(Moteur!$R$1:$R$175,Moteur!$D$1:$D$175,$A42,Moteur!$B$1:$B$175,cad!$P$1) -> 0 | F42: =IFERROR(E42/D42,0) -> 0 | G42: =IFERROR(E42/SUM($E$33:$E$46),0) -> 0 | H42: =SUMIFS(_CALC_PNL!$T$1:$T$1347,_CALC_PNL!$A$1:$A$1347,$A42,_CALC_PNL!$D$1:$D$1347,cad!$P$1,_CALC_PNL!$C$1:$C$1347,"2027") -> 0 | I42: =IFERROR(H42/E42,0) -> 0 | J42: =IFERROR(H42/D42,0) -> 0 | K42: =SUMIFS(PIL!$K$15:$K$28,PIL!$A$15:$A$28,$A42)*SUMIFS(PIL!$J$15:$J$28,PIL!$A$15:$A$28,$A42)*(SUM(PIL!$K$15:$K$28)/SUMPRODUCT(PIL!$K$15:$K$28,PIL!$J$15:$J$28)) -> 15178 | L42: =SUMIFS(PIL!$D$15:$D$28,PIL!$A$15:$A$28,$A42) -> 1034
A43: PIGIER_LYO | B43: Pigier | C43: Lyon | D43: =SUMIFS(Moteur!$P$1:$P$175,Moteur!$D$1:$D$175,$A43,Moteur!$B$1:$B$175,cad!$P$1) -> 0 | E43: =SUMIFS(Moteur!$R$1:$R$175,Moteur!$D$1:$D$175,$A43,Moteur!$B$1:$B$175,cad!$P$1) -> 0 | F43: =IFERROR(E43/D43,0) -> 0 | G43: =IFERROR(E43/SUM($E$33:$E$46),0) -> 0 | H43: =SUMIFS(_CALC_PNL!$T$1:$T$1347,_CALC_PNL!$A$1:$A$1347,$A43,_CALC_PNL!$D$1:$D$1347,cad!$P$1,_CALC_PNL!$C$1:$C$1347,"2027") -> 0 | I43: =IFERROR(H43/E43,0) -> 0 | J43: =IFERROR(H43/D43,0) -> 0 | K43: =SUMIFS(PIL!$K$15:$K$28,PIL!$A$15:$A$28,$A43)*SUMIFS(PIL!$J$15:$J$28,PIL!$A$15:$A$28,$A43)*(SUM(PIL!$K$15:$K$28)/SUMPRODUCT(PIL!$K$15:$K$28,PIL!$J$15:$J$28)) -> 36612 | L43: =SUMIFS(PIL!$D$15:$D$28,PIL!$A$15:$A$28,$A43) -> 1705
A44: PIGIER_BOR | B44: Pigier | C44: Bordeaux | D44: =SUMIFS(Moteur!$P$1:$P$175,Moteur!$D$1:$D$175,$A44,Moteur!$B$1:$B$175,cad!$P$1) -> 0 | E44: =SUMIFS(Moteur!$R$1:$R$175,Moteur!$D$1:$D$175,$A44,Moteur!$B$1:$B$175,cad!$P$1) -> 0 | F44: =IFERROR(E44/D44,0) -> 0 | G44: =IFERROR(E44/SUM($E$33:$E$46),0) -> 0 | H44: =SUMIFS(_CALC_PNL!$T$1:$T$1347,_CALC_PNL!$A$1:$A$1347,$A44,_CALC_PNL!$D$1:$D$1347,cad!$P$1,_CALC_PNL!$C$1:$C$1347,"2027") -> 0 | I44: =IFERROR(H44/E44,0) -> 0 | J44: =IFERROR(H44/D44,0) -> 0 | K44: =SUMIFS(PIL!$K$15:$K$28,PIL!$A$15:$A$28,$A44)*SUMIFS(PIL!$J$15:$J$28,PIL!$A$15:$A$28,$A44)*(SUM(PIL!$K$15:$K$28)/SUMPRODUCT(PIL!$K$15:$K$28,PIL!$J$15:$J$28)) -> 21968 | L44: =SUMIFS(PIL!$D$15:$D$28,PIL!$A$15:$A$28,$A44) -> 1368
... A46: TUNON_LYO | B46: Tunon | C46: Lyon | D46: =SUMIFS(Moteur!$P$1:$P$175,Moteur!$D$1:$D$175,$A46,Moteur!$B$1:$B$175,cad!$P$1) -> 0 | E46: =SUMIFS(Moteur!$R$1:$R$175,Moteur!$D$1:$D$175,$A46,Moteur!$B$1:$B$175,cad!$P$1) -> 0 | F46: =IFERROR(E46/D46,0) -> 0 | G46: =IFERROR(E46/SUM($E$33:$E$46),0) -> 0 | H46: =SUMIFS(_CALC_PNL!$T$1:$T$1347,_CALC_PNL!$A$1:$A$1347,$A46,_CALC_PNL!$D$1:$D$1347,cad!$P$1,_CALC_PNL!$C$1:$C$1347,"2027") -> 0 | I46: =IFERROR(H46/E46,0) -> 0 | J46: =IFERROR(H46/D46,0) -> 0 | K46: =SUMIFS(PIL!$K$15:$K$28,PIL!$A$15:$A$28,$A46)*SUMIFS(PIL!$J$15:$J$28,PIL!$A$15:$A$28,$A46)*(SUM(PIL!$K$15:$K$28)/SUMPRODUCT(PIL!$K$15:$K$28,PIL!$J$15:$J$28)) -> 18850 | L46: =SUMIFS(PIL!$D$15:$D$28,PIL!$A$15:$A$28,$A46) -> 1625
A47: Sous-total campus | D47: =SUM(D33:D46) -> 0 | E47: =SUM(E33:E46) -> 0 | F47: =IFERROR(E47/D47,0) -> 0 | G47: =SUM(G33:G46) -> 0 | H47: =SUM(H33:H46) -> 0 | I47: =IFERROR(H47/E47,0) -> 0 | J47: =IFERROR(H47/D47,0) -> 0 | K47: =SUM(K33:K46) -> 434174
A48: Siege / holding (GRP) | H48: =SUMIFS(_CALC_PNL!$T$1:$T$1347,_CALC_PNL!$A$1:$A$1347,"GRP",_CALC_PNL!$D$1:$D$1347,cad!$P$1,_CALC_PNL!$C$1:$C$1347,"2027") -> 0
A49: GROUPE 2027 V01 | D49: =D47 -> 0 | E49: =E47 -> 0 | F49: =IFERROR(E49/D49,0) -> 0 | G49: =SUM(G33:G46) -> 0 | H49: =H47+H48 -> 0 | I49: =IFERROR(H49/E49,0) -> 0 | J49: =IFERROR(H49/D49,0) -> 0 | K49: =SUM(K33:K46) -> 434174

Sheet ALLOC
N1: =IF($C$6="Chiffre d'affaires","REV_CA",IF($C$6="Nombre de classes","VOL_CLASS","VOL_EFF")) -> REV_CA
B2: 3 · Allocation222 & RENTABILITE — cout complet du groupe a la classe | N2: =IF($C$7="Chiffre d'affaires","REV_CA",IF($C$7="Nombre de classes","VOL_CLASS","VOL_EFF")) -> REV_CA
N3: =IF($C$8="Chiffre d'affaires","REV_CA",IF($C$8="Nombre de classes","VOL_CLASS","VOL_EFF")) -> VOL_EFF
N4: =IF($C$9="Chiffre d'affaires","REV_CA",IF($C$9="Nombre de classes","VOL_CLASS","VOL_EFF")) -> VOL_CLASS
B5: Cles d'Allocation222 (saisie)
B6: Siège administratif → marque | C6: Chiffre d'affaires
B7: Publicité de marque → marque | C7: Chiffre d'affaires
B8: Marque → campus | C8: Effectif
B9: Campus → classe | C9: Nombre de classes
B14: Maille fine — deplie campus/classe avec les [+]
B17: Marque ▸ Campus ▸ Classe | C17: Effectif | D17: CA | E17: VAC | F17: PERM | G17: ODIR | H17: STRUCT | I17: Frais marque | J17: Holding | K17: Cout complet | L17: Marge complete | M17: Marge %
B18: MBway | C18: =SUMIFS(_CALC_ALLOC!$G$1:$G$349,_CALC_ALLOC!$A$1:$A$349,"2026",_CALC_ALLOC!$C$1:$C$349,"MBWAY") -> #VALUE! | D18: =SUMIFS(_CALC_ALLOC!$I$1:$I$349,_CALC_ALLOC!$A$1:$A$349,"2026",_CALC_ALLOC!$C$1:$C$349,"MBWAY") -> 0 | E18: =SUMIFS(_CALC_ALLOC!$AI$1:$AI$349,_CALC_ALLOC!$A$1:$A$349,"2026",_CALC_ALLOC!$C$1:$C$349,"MBWAY") -> 0 | F18: =SUMIFS(_CALC_ALLOC!$AJ$1:$AJ$349,_CALC_ALLOC!$A$1:$A$349,"2026",_CALC_ALLOC!$C$1:$C$349,"MBWAY") -> 0 | G18: =SUMIFS(_CALC_ALLOC!$AK$1:$AK$349,_CALC_ALLOC!$A$1:$A$349,"2026",_CALC_ALLOC!$C$1:$C$349,"MBWAY") -> 0 | H18: =SUMIFS(_CALC_ALLOC!$AL$1:$AL$349,_CALC_ALLOC!$A$1:$A$349,"2026",_CALC_ALLOC!$C$1:$C$349,"MBWAY") -> 0 | I18: =SUMIFS(_CALC_ALLOC!$AR$1:$AR$349,_CALC_ALLOC!$A$1:$A$349,"2026",_CALC_ALLOC!$C$1:$C$349,"MBWAY") -> 0 | J18: =SUMIFS(_CALC_ALLOC!$AM$1:$AM$349,_CALC_ALLOC!$A$1:$A$349,"2026",_CALC_ALLOC!$C$1:$C$349,"MBWAY") -> 0 | K18: =E18+F18+G18+H18+I18+J18 -> 0 | L18: =SUMIFS(_CALC_ALLOC!$AN$1:$AN$349,_CALC_ALLOC!$A$1:$A$349,"2026",_CALC_ALLOC!$C$1:$C$349,"MBWAY") -> 0 | M18: =IFERROR(L18/D18,0) -> 0
B19: Paris (MBWAY_PAR) | C19: =SUMIFS(_CALC_ALLOC!$G$1:$G$349,_CALC_ALLOC!$A$1:$A$349,"2026",_CALC_ALLOC!$B$1:$B$349,"MBWAY_PAR") -> 0 | D19: =SUMIFS(_CALC_ALLOC!$I$1:$I$349,_CALC_ALLOC!$A$1:$A$349,"2026",_CALC_ALLOC!$B$1:$B$349,"MBWAY_PAR") -> 0 | E19: =SUMIFS(_CALC_ALLOC!$AI$1:$AI$349,_CALC_ALLOC!$A$1:$A$349,"2026",_CALC_ALLOC!$B$1:$B$349,"MBWAY_PAR") -> 0 | F19: =SUMIFS(_CALC_ALLOC!$AJ$1:$AJ$349,_CALC_ALLOC!$A$1:$A$349,"2026",_CALC_ALLOC!$B$1:$B$349,"MBWAY_PAR") -> 0 | G19: =SUMIFS(_CALC_ALLOC!$AK$1:$AK$349,_CALC_ALLOC!$A$1:$A$349,"2026",_CALC_ALLOC!$B$1:$B$349,"MBWAY_PAR") -> 0 | H19: =SUMIFS(_CALC_ALLOC!$AL$1:$AL$349,_CALC_ALLOC!$A$1:$A$349,"2026",_CALC_ALLOC!$B$1:$B$349,"MBWAY_PAR") -> 0 | I19: =SUMIFS(_CALC_ALLOC!$AR$1:$AR$349,_CALC_ALLOC!$A$1:$A$349,"2026",_CALC_ALLOC!$B$1:$B$349,"MBWAY_PAR") -> 0 | J19: =SUMIFS(_CALC_ALLOC!$AM$1:$AM$349,_CALC_ALLOC!$A$1:$A$349,"2026",_CALC_ALLOC!$B$1:$B$349,"MBWAY_PAR") -> 0 | K19: =E19+F19+G19+H19+I19+J19 -> 0 | L19: =SUMIFS(_CALC_ALLOC!$AN$1:$AN$349,_CALC_ALLOC!$A$1:$A$349,"2026",_CALC_ALLOC!$B$1:$B$349,"MBWAY_PAR") -> 0 | M19: =IFERROR(L19/D19,0) -> 0
B20: BAC_MGT B1 INIT | C20: =SUMIFS(_CALC_ALLOC!$G$1:$G$349,_CALC_ALLOC!$A$1:$A$349,"2026",_CALC_ALLOC!$B$1:$B$349,"MBWAY_PAR",_CALC_ALLOC!$D$1:$D$349,"BAC_MGT",_CALC_ALLOC!$E$1:$E$349,"B1",_CALC_ALLOC!$F$1:$F$349,"INIT") -> 0 | D20: =SUMIFS(_CALC_ALLOC!$I$1:$I$349,_CALC_ALLOC!$A$1:$A$349,"2026",_CALC_ALLOC!$B$1:$B$349,"MBWAY_PAR",_CALC_ALLOC!$D$1:$D$349,"BAC_MGT",_CALC_ALLOC!$E$1:$E$349,"B1",_CALC_ALLOC!$F$1:$F$349,"INIT") -> 0 | E20: =SUMIFS(_CALC_ALLOC!$AI$1:$AI$349,_CALC_ALLOC!$A$1:$A$349,"2026",_CALC_ALLOC!$B$1:$B$349,"MBWAY_PAR",_CALC_ALLOC!$D$1:$D$349,"BAC_MGT",_CALC_ALLOC!$E$1:$E$349,"B1",_CALC_ALLOC!$F$1:$F$349,"INIT") -> 0 | F20: =SUMIFS(_CALC_ALLOC!$AJ$1:$AJ$349,_CALC_ALLOC!$A$1:$A$349,"2026",_CALC_ALLOC!$B$1:$B$349,"MBWAY_PAR",_CALC_ALLOC!$D$1:$D$349,"BAC_MGT",_CALC_ALLOC!$E$1:$E$349,"B1",_CALC_ALLOC!$F$1:$F$349,"INIT") -> 0 | G20: =SUMIFS(_CALC_ALLOC!$AK$1:$AK$349,_CALC_ALLOC!$A$1:$A$349,"2026",_CALC_ALLOC!$B$1:$B$349,"MBWAY_PAR",_CALC_ALLOC!$D$1:$D$349,"BAC_MGT",_CALC_ALLOC!$E$1:$E$349,"B1",_CALC_ALLOC!$F$1:$F$349,"INIT") -> 0 | H20: =SUMIFS(_CALC_ALLOC!$AL$1:$AL$349,_CALC_ALLOC!$A$1:$A$349,"2026",_CALC_ALLOC!$B$1:$B$349,"MBWAY_PAR",_CALC_ALLOC!$D$1:$D$349,"BAC_MGT",_CALC_ALLOC!$E$1:$E$349,"B1",_CALC_ALLOC!$F$1:$F$349,"INIT") -> 0 | I20: =SUMIFS(_CALC_ALLOC!$AR$1:$AR$349,_CALC_ALLOC!$A$1:$A$349,"2026",_CALC_ALLOC!$B$1:$B$349,"MBWAY_PAR",_CALC_ALLOC!$D$1:$D$349,"BAC_MGT",_CALC_ALLOC!$E$1:$E$349,"B1",_CALC_ALLOC!$F$1:$F$349,"INIT") -> 0 | J20: =SUMIFS(_CALC_ALLOC!$AM$1:$AM$349,_CALC_ALLOC!$A$1:$A$349,"2026",_CALC_ALLOC!$B$1:$B$349,"MBWAY_PAR",_CALC_ALLOC!$D$1:$D$349,"BAC_MGT",_CALC_ALLOC!$E$1:$E$349,"B1",_CALC_ALLOC!$F$1:$F$349,"INIT") -> 0 | K20: =E20+F20+G20+H20+I20+J20 -> 0 | L20: =SUMIFS(_CALC_ALLOC!$AN$1:$AN$349,_CALC_ALLOC!$A$1:$A$349,"2026",_CALC_ALLOC!$B$1:$B$349,"MBWAY_PAR",_CALC_ALLOC!$D$1:$D$349,"BAC_MGT",_CALC_ALLOC!$E$1:$E$349,"B1",_CALC_ALLOC!$F$1:$F$349,"INIT") -> 0 | M20: =IFERROR(L20/D20,0) -> 0
B21: BAC_MGT B2 ALT | C21: =SUMIFS(_CALC_ALLOC!$G$1:$G$349,_CALC_ALLOC!$A$1:$A$349,"2026",_CALC_ALLOC!$B$1:$B$349,"MBWAY_PAR",_CALC_ALLOC!$D$1:$D$349,"BAC_MGT",_CALC_ALLOC!$E$1:$E$349,"B2",_CALC_ALLOC!$F$1:$F$349,"ALT") -> 0 | D21: =SUMIFS(_CALC_ALLOC!$I$1:$I$349,_CALC_ALLOC!$A$1:$A$349,"2026",_CALC_ALLOC!$B$1:$B$349,"MBWAY_PAR",_CALC_ALLOC!$D$1:$D$349,"BAC_MGT",_CALC_ALLOC!$E$1:$E$349,"B2",_CALC_ALLOC!$F$1:$F$349,"ALT") -> 0 | E21: =SUMIFS(_CALC_ALLOC!$AI$1:$AI$349,_CALC_ALLOC!$A$1:$A$349,"2026",_CALC_ALLOC!$B$1:$B$349,"MBWAY_PAR",_CALC_ALLOC!$D$1:$D$349,"BAC_MGT",_CALC_ALLOC!$E$1:$E$349,"B2",_CALC_ALLOC!$F$1:$F$349,"ALT") -> 0 | F21: =SUMIFS(_CALC_ALLOC!$AJ$1:$AJ$349,_CALC_ALLOC!$A$1:$A$349,"2026",_CALC_ALLOC!$B$1:$B$349,"MBWAY_PAR",_CALC_ALLOC!$D$1:$D$349,"BAC_MGT",_CALC_ALLOC!$E$1:$E$349,"B2",_CALC_ALLOC!$F$1:$F$349,"ALT") -> 0 | G21: =SUMIFS(_CALC_ALLOC!$AK$1:$AK$349,_CALC_ALLOC!$A$1:$A$349,"2026",_CALC_ALLOC!$B$1:$B$349,"MBWAY_PAR",_CALC_ALLOC!$D$1:$D$349,"BAC_MGT",_CALC_ALLOC!$E$1:$E$349,"B2",_CALC_ALLOC!$F$1:$F$349,"ALT") -> 0 | H21: =SUMIFS(_CALC_ALLOC!$AL$1:$AL$349,_CALC_ALLOC!$A$1:$A$349,"2026",_CALC_ALLOC!$B$1:$B$349,"MBWAY_PAR",_CALC_ALLOC!$D$1:$D$349,"BAC_MGT",_CALC_ALLOC!$E$1:$E$349,"B2",_CALC_ALLOC!$F$1:$F$349,"ALT") -> 0 | I21: =SUMIFS(_CALC_ALLOC!$AR$1:$AR$349,_CALC_ALLOC!$A$1:$A$349,"2026",_CALC_ALLOC!$B$1:$B$349,"MBWAY_PAR",_CALC_ALLOC!$D$1:$D$349,"BAC_MGT",_CALC_ALLOC!$E$1:$E$349,"B2",_CALC_ALLOC!$F$1:$F$349,"ALT") -> 0 | J21: =SUMIFS(_CALC_ALLOC!$AM$1:$AM$349,_CALC_ALLOC!$A$1:$A$349,"2026",_CALC_ALLOC!$B$1:$B$349,"MBWAY_PAR",_CALC_ALLOC!$D$1:$D$349,"BAC_MGT",_CALC_ALLOC!$E$1:$E$349,"B2",_CALC_ALLOC!$F$1:$F$349,"ALT") -> 0 | K21: =E21+F21+G21+H21+I21+J21 -> 0 | L21: =SUMIFS(_CALC_ALLOC!$AN$1:$AN$349,_CALC_ALLOC!$A$1:$A$349,"2026",_CALC_ALLOC!$B$1:$B$349,"MBWAY_PAR",_CALC_ALLOC!$D$1:$D$349,"BAC_MGT",_CALC_ALLOC!$E$1:$E$349,"B2",_CALC_ALLOC!$F$1:$F$349,"ALT") -> 0 | M21: =IFERROR(L21/D21,0) -> 0
B22: BAC_MGT B3 ALT | C22: =SUMIFS(_CALC_ALLOC!$G$1:$G$349,_CALC_ALLOC!$A$1:$A$349,"2026",_CALC_ALLOC!$B$1:$B$349,"MBWAY_PAR",_CALC_ALLOC!$D$1:$D$349,"BAC_MGT",_CALC_ALLOC!$E$1:$E$349,"B3",_CALC_ALLOC!$F$1:$F$349,"ALT") -> 0 | D22: =SUMIFS(_CALC_ALLOC!$I$1:$I$349,_CALC_ALLOC!$A$1:$A$349,"2026",_CALC_ALLOC!$B$1:$B$349,"MBWAY_PAR",_CALC_ALLOC!$D$1:$D$349,"BAC_MGT",_CALC_ALLOC!$E$1:$E$349,"B3",_CALC_ALLOC!$F$1:$F$349,"ALT") -> 0 | E22: =SUMIFS(_CALC_ALLOC!$AI$1:$AI$349,_CALC_ALLOC!$A$1:$A$349,"2026",_CALC_ALLOC!$B$1:$B$349,"MBWAY_PAR",_CALC_ALLOC!$D$1:$D$349,"BAC_MGT",_CALC_ALLOC!$E$1:$E$349,"B3",_CALC_ALLOC!$F$1:$F$349,"ALT") -> 0 | F22: =SUMIFS(_CALC_ALLOC!$AJ$1:$AJ$349,_CALC_ALLOC!$A$1:$A$349,"2026",_CALC_ALLOC!$B$1:$B$349,"MBWAY_PAR",_CALC_ALLOC!$D$1:$D$349,"BAC_MGT",_CALC_ALLOC!$E$1:$E$349,"B3",_CALC_ALLOC!$F$1:$F$349,"ALT") -> 0 | G22: =SUMIFS(_CALC_ALLOC!$AK$1:$AK$349,_CALC_ALLOC!$A$1:$A$349,"2026",_CALC_ALLOC!$B$1:$B$349,"MBWAY_PAR",_CALC_ALLOC!$D$1:$D$349,"BAC_MGT",_CALC_ALLOC!$E$1:$E$349,"B3",_CALC_ALLOC!$F$1:$F$349,"ALT") -> 0 | H22: =SUMIFS(_CALC_ALLOC!$AL$1:$AL$349,_CALC_ALLOC!$A$1:$A$349,"2026",_CALC_ALLOC!$B$1:$B$349,"MBWAY_PAR",_CALC_ALLOC!$D$1:$D$349,"BAC_MGT",_CALC_ALLOC!$E$1:$E$349,"B3",_CALC_ALLOC!$F$1:$F$349,"ALT") -> 0 | I22: =SUMIFS(_CALC_ALLOC!$AR$1:$AR$349,_CALC_ALLOC!$A$1:$A$349,"2026",_CALC_ALLOC!$B$1:$B$349,"MBWAY_PAR",_CALC_ALLOC!$D$1:$D$349,"BAC_MGT",_CALC_ALLOC!$E$1:$E$349,"B3",_CALC_ALLOC!$F$1:$F$349,"ALT") -> 0 | J22: =SUMIFS(_CALC_ALLOC!$AM$1:$AM$349,_CALC_ALLOC!$A$1:$A$349,"2026",_CALC_ALLOC!$B$1:$B$349,"MBWAY_PAR",_CALC_ALLOC!$D$1:$D$349,"BAC_MGT",_CALC_ALLOC!$E$1:$E$349,"B3",_CALC_ALLOC!$F$1:$F$349,"ALT") -> 0 | K22: =E22+F22+G22+H22+I22+J22 -> 0 | L22: =SUMIFS(_CALC_ALLOC!$AN$1:$AN$349,_CALC_ALLOC!$A$1:$A$349,"2026",_CALC_ALLOC!$B$1:$B$349,"MBWAY_PAR",_CALC_ALLOC!$D$1:$D$349,"BAC_MGT",_CALC_ALLOC!$E$1:$E$349,"B3",_CALC_ALLOC!$F$1:$F$349,"ALT") -> 0 | M22: =IFERROR(L22/D22,0) -> 0
B23: MAS_MGT M1 ALT | C23: =SUMIFS(_CALC_ALLOC!$G$1:$G$349,_CALC_ALLOC!$A$1:$A$349,"2026",_CALC_ALLOC!$B$1:$B$349,"MBWAY_PAR",_CALC_ALLOC!$D$1:$D$349,"MAS_MGT",_CALC_ALLOC!$E$1:$E$349,"M1",_CALC_ALLOC!$F$1:$F$349,"ALT") -> 0 | D23: =SUMIFS(_CALC_ALLOC!$I$1:$I$349,_CALC_ALLOC!$A$1:$A$349,"2026",_CALC_ALLOC!$B$1:$B$349,"MBWAY_PAR",_CALC_ALLOC!$D$1:$D$349,"MAS_MGT",_CALC_ALLOC!$E$1:$E$349,"M1",_CALC_ALLOC!$F$1:$F$349,"ALT") -> 0 | E23: =SUMIFS(_CALC_ALLOC!$AI$1:$AI$349,_CALC_ALLOC!$A$1:$A$349,"2026",_CALC_ALLOC!$B$1:$B$349,"MBWAY_PAR",_CALC_ALLOC!$D$1:$D$349,"MAS_MGT",_CALC_ALLOC!$E$1:$E$349,"M1",_CALC_ALLOC!$F$1:$F$349,"ALT") -> 0 | F23: =SUMIFS(_CALC_ALLOC!$AJ$1:$AJ$349,_CALC_ALLOC!$A$1:$A$349,"2026",_CALC_ALLOC!$B$1:$B$349,"MBWAY_PAR",_CALC_ALLOC!$D$1:$D$349,"MAS_MGT",_CALC_ALLOC!$E$1:$E$349,"M1",_CALC_ALLOC!$F$1:$F$349,"ALT") -> 0 | G23: =SUMIFS(_CALC_ALLOC!$AK$1:$AK$349,_CALC_ALLOC!$A$1:$A$349,"2026",_CALC_ALLOC!$B$1:$B$349,"MBWAY_PAR",_CALC_ALLOC!$D$1:$D$349,"MAS_MGT",_CALC_ALLOC!$E$1:$E$349,"M1",_CALC_ALLOC!$F$1:$F$349,"ALT") -> 0 | H23: =SUMIFS(_CALC_ALLOC!$AL$1:$AL$349,_CALC_ALLOC!$A$1:$A$349,"2026",_CALC_ALLOC!$B$1:$B$349,"MBWAY_PAR",_CALC_ALLOC!$D$1:$D$349,"MAS_MGT",_CALC_ALLOC!$E$1:$E$349,"M1",_CALC_ALLOC!$F$1:$F$349,"ALT") -> 0 | I23: =SUMIFS(_CALC_ALLOC!$AR$1:$AR$349,_CALC_ALLOC!$A$1:$A$349,"2026",_CALC_ALLOC!$B$1:$B$349,"MBWAY_PAR",_CALC_ALLOC!$D$1:$D$349,"MAS_MGT",_CALC_ALLOC!$E$1:$E$349,"M1",_CALC_ALLOC!$F$1:$F$349,"ALT") -> 0 | J23: =SUMIFS(_CALC_ALLOC!$AM$1:$AM$349,_CALC_ALLOC!$A$1:$A$349,"2026",_CALC_ALLOC!$B$1:$B$349,"MBWAY_PAR",_CALC_ALLOC!$D$1:$D$349,"MAS_MGT",_CALC_ALLOC!$E$1:$E$349,"M1",_CALC_ALLOC!$F$1:$F$349,"ALT") -> 0 | K23: =E23+F23+G23+H23+I23+J23 -> 0 | L23: =SUMIFS(_CALC_ALLOC!$AN$1:$AN$349,_CALC_ALLOC!$A$1:$A$349,"2026",_CALC_ALLOC!$B$1:$B$349,"MBWAY_PAR",_CALC_ALLOC!$D$1:$D$349,"MAS_MGT",_CALC_ALLOC!$E$1:$E$349,"M1",_CALC_ALLOC!$F$1:$F$349,"ALT") -> 0 | M23: =IFERROR(L23/D23,0) -> 0
B24: MAS_MGT M2 ALT | C24: =SUMIFS(_CALC_ALLOC!$G$1:$G$349,_CALC_ALLOC!$A$1:$A$349,"2026",_CALC_ALLOC!$B$1:$B$349,"MBWAY_PAR",_CALC_ALLOC!$D$1:$D$349,"MAS_MGT",_CALC_ALLOC!$E$1:$E$349,"M2",_CALC_ALLOC!$F$1:$F$349,"ALT") -> 0 | D24: =SUMIFS(_CALC_ALLOC!$I$1:$I$349,_CALC_ALLOC!$A$1:$A$349,"2026",_CALC_ALLOC!$B$1:$B$349,"MBWAY_PAR",_CALC_ALLOC!$D$1:$D$349,"MAS_MGT",_CALC_ALLOC!$E$1:$E$349,"M2",_CALC_ALLOC!$F$1:$F$349,"ALT") -> 0 | E24: =SUMIFS(_CALC_ALLOC!$AI$1:$AI$349,_CALC_ALLOC!$A$1:$A$349,"2026",_CALC_ALLOC!$B$1:$B$349,"MBWAY_PAR",_CALC_ALLOC!$D$1:$D$349,"MAS_MGT",_CALC_ALLOC!$E$1:$E$349,"M2",_CALC_ALLOC!$F$1:$F$349,"ALT") -> 0 | F24: =SUMIFS(_CALC_ALLOC!$AJ$1:$AJ$349,_CALC_ALLOC!$A$1:$A$349,"2026",_CALC_ALLOC!$B$1:$B$349,"MBWAY_PAR",_CALC_ALLOC!$D$1:$D$349,"MAS_MGT",_CALC_ALLOC!$E$1:$E$349,"M2",_CALC_ALLOC!$F$1:$F$349,"ALT") -> 0 | G24: =SUMIFS(_CALC_ALLOC!$AK$1:$AK$349,_CALC_ALLOC!$A$1:$A$349,"2026",_CALC_ALLOC!$B$1:$B$349,"MBWAY_PAR",_CALC_ALLOC!$D$1:$D$349,"MAS_MGT",_CALC_ALLOC!$E$1:$E$349,"M2",_CALC_ALLOC!$F$1:$F$349,"ALT") -> 0 | H24: =SUMIFS(_CALC_ALLOC!$AL$1:$AL$349,_CALC_ALLOC!$A$1:$A$349,"2026",_CALC_ALLOC!$B$1:$B$349,"MBWAY_PAR",_CALC_ALLOC!$D$1:$D$349,"MAS_MGT",_CALC_ALLOC!$E$1:$E$349,"M2",_CALC_ALLOC!$F$1:$F$349,"ALT") -> 0 | I24: =SUMIFS(_CALC_ALLOC!$AR$1:$AR$349,_CALC_ALLOC!$A$1:$A$349,"2026",_CALC_ALLOC!$B$1:$B$349,"MBWAY_PAR",_CALC_ALLOC!$D$1:$D$349,"MAS_MGT",_CALC_ALLOC!$E$1:$E$349,"M2",_CALC_ALLOC!$F$1:$F$349,"ALT") -> 0 | J24: =SUMIFS(_CALC_ALLOC!$AM$1:$AM$349,_CALC_ALLOC!$A$1:$A$349,"2026",_CALC_ALLOC!$B$1:$B$349,"MBWAY_PAR",_CALC_ALLOC!$D$1:$D$349,"MAS_MGT",_CALC_ALLOC!$E$1:$E$349,"M2",_CALC_ALLOC!$F$1:$F$349,"ALT") -> 0 | K24: =E24+F24+G24+H24+I24+J24 -> 0 | L24: =SUMIFS(_CALC_ALLOC!$AN$1:$AN$349,_CALC_ALLOC!$A$1:$A$349,"2026",_CALC_ALLOC!$B$1:$B$349,"MBWAY_PAR",_CALC_ALLOC!$D$1:$D$349,"MAS_MGT",_CALC_ALLOC!$E$1:$E$349,"M2",_CALC_ALLOC!$F$1:$F$349,"ALT") -> 0 | M24: =IFERROR(L24/D24,0) -> 0
B25: Lyon (MBWAY_LYO) | C25: =SUMIFS(_CALC_ALLOC!$G$1:$G$349,_CALC_ALLOC!$A$1:$A$349,"2026",_CALC_ALLOC!$B$1:$B$349,"MBWAY_LYO") -> 0 | D25: =SUMIFS(_CALC_ALLOC!$I$1:$I$349,_CALC_ALLOC!$A$1:$A$349,"2026",_CALC_ALLOC!$B$1:$B$349,"MBWAY_LYO") -> 0 | E25: =SUMIFS(_CALC_ALLOC!$AI$1:$AI$349,_CALC_ALLOC!$A$1:$A$349,"2026",_CALC_ALLOC!$B$1:$B$349,"MBWAY_LYO") -> 0 | F25: =SUMIFS(_CALC_ALLOC!$AJ$1:$AJ$349,_CALC_ALLOC!$A$1:$A$349,"2026",_CALC_ALLOC!$B$1:$B$349,"MBWAY_LYO") -> 0 | G25: =SUMIFS(_CALC_ALLOC!$AK$1:$AK$349,_CALC_ALLOC!$A$1:$A$349,"2026",_CALC_ALLOC!$B$1:$B$349,"MBWAY_LYO") -> 0 | H25: =SUMIFS(_CALC_ALLOC!$AL$1:$AL$349,_CALC_ALLOC!$A$1:$A$349,"2026",_CALC_ALLOC!$B$1:$B$349,"MBWAY_LYO") -> 0 | I25: =SUMIFS(_CALC_ALLOC!$AR$1:$AR$349,_CALC_ALLOC!$A$1:$A$349,"2026",_CALC_ALLOC!$B$1:$B$349,"MBWAY_LYO") -> 0 | J25: =SUMIFS(_CALC_ALLOC!$AM$1:$AM$349,_CALC_ALLOC!$A$1:$A$349,"2026",_CALC_ALLOC!$B$1:$B$349,"MBWAY_LYO") -> 0 | K25: =E25+F25+G25+H25+I25+J25 -> 0 | L25: =SUMIFS(_CALC_ALLOC!$AN$1:$AN$349,_CALC_ALLOC!$A$1:$A$349,"2026",_CALC_ALLOC!$B$1:$B$349,"MBWAY_LYO") -> 0 | M25: =IFERROR(L25/D25,0) -> 0
B26: BAC_MGT B1 INIT | C26: =SUMIFS(_CALC_ALLOC!$G$1:$G$349,_CALC_ALLOC!$A$1:$A$349,"2026",_CALC_ALLOC!$B$1:$B$349,"MBWAY_LYO",_CALC_ALLOC!$D$1:$D$349,"BAC_MGT",_CALC_ALLOC!$E$1:$E$349,"B1",_CALC_ALLOC!$F$1:$F$349,"INIT") -> 0 | D26: =SUMIFS(_CALC_ALLOC!$I$1:$I$349,_CALC_ALLOC!$A$1:$A$349,"2026",_CALC_ALLOC!$B$1:$B$349,"MBWAY_LYO",_CALC_ALLOC!$D$1:$D$349,"BAC_MGT",_CALC_ALLOC!$E$1:$E$349,"B1",_CALC_ALLOC!$F$1:$F$349,"INIT") -> 0 | E26: =SUMIFS(_CALC_ALLOC!$AI$1:$AI$349,_CALC_ALLOC!$A$1:$A$349,"2026",_CALC_ALLOC!$B$1:$B$349,"MBWAY_LYO",_CALC_ALLOC!$D$1:$D$349,"BAC_MGT",_CALC_ALLOC!$E$1:$E$349,"B1",_CALC_ALLOC!$F$1:$F$349,"INIT") -> 0 | F26: =SUMIFS(_CALC_ALLOC!$AJ$1:$AJ$349,_CALC_ALLOC!$A$1:$A$349,"2026",_CALC_ALLOC!$B$1:$B$349,"MBWAY_LYO",_CALC_ALLOC!$D$1:$D$349,"BAC_MGT",_CALC_ALLOC!$E$1:$E$349,"B1",_CALC_ALLOC!$F$1:$F$349,"INIT") -> 0 | G26: =SUMIFS(_CALC_ALLOC!$AK$1:$AK$349,_CALC_ALLOC!$A$1:$A$349,"2026",_CALC_ALLOC!$B$1:$B$349,"MBWAY_LYO",_CALC_ALLOC!$D$1:$D$349,"BAC_MGT",_CALC_ALLOC!$E$1:$E$349,"B1",_CALC_ALLOC!$F$1:$F$349,"INIT") -> 0 | H26: =SUMIFS(_CALC_ALLOC!$AL$1:$AL$349,_CALC_ALLOC!$A$1:$A$349,"2026",_CALC_ALLOC!$B$1:$B$349,"MBWAY_LYO",_CALC_ALLOC!$D$1:$D$349,"BAC_MGT",_CALC_ALLOC!$E$1:$E$349,"B1",_CALC_ALLOC!$F$1:$F$349,"INIT") -> 0 | I26: =SUMIFS(_CALC_ALLOC!$AR$1:$AR$349,_CALC_ALLOC!$A$1:$A$349,"2026",_CALC_ALLOC!$B$1:$B$349,"MBWAY_LYO",_CALC_ALLOC!$D$1:$D$349,"BAC_MGT",_CALC_ALLOC!$E$1:$E$349,"B1",_CALC_ALLOC!$F$1:$F$349,"INIT") -> 0 | J26: =SUMIFS(_CALC_ALLOC!$AM$1:$AM$349,_CALC_ALLOC!$A$1:$A$349,"2026",_CALC_ALLOC!$B$1:$B$349,"MBWAY_LYO",_CALC_ALLOC!$D$1:$D$349,"BAC_MGT",_CALC_ALLOC!$E$1:$E$349,"B1",_CALC_ALLOC!$F$1:$F$349,"INIT") -> 0 | K26: =E26+F26+G26+H26+I26+J26 -> 0 | L26: =SUMIFS(_CALC_ALLOC!$AN$1:$AN$349,_CALC_ALLOC!$A$1:$A$349,"2026",_CALC_ALLOC!$B$1:$B$349,"MBWAY_LYO",_CALC_ALLOC!$D$1:$D$349,"BAC_MGT",_CALC_ALLOC!$E$1:$E$349,"B1",_CALC_ALLOC!$F$1:$F$349,"INIT") -> 0 | M26: =IFERROR(L26/D26,0) -> 0
B27: BAC_MGT B2 ALT | C27: =SUMIFS(_CALC_ALLOC!$G$1:$G$349,_CALC_ALLOC!$A$1:$A$349,"2026",_CALC_ALLOC!$B$1:$B$349,"MBWAY_LYO",_CALC_ALLOC!$D$1:$D$349,"BAC_MGT",_CALC_ALLOC!$E$1:$E$349,"B2",_CALC_ALLOC!$F$1:$F$349,"ALT") -> 0 | D27: =SUMIFS(_CALC_ALLOC!$I$1:$I$349,_CALC_ALLOC!$A$1:$A$349,"2026",_CALC_ALLOC!$B$1:$B$349,"MBWAY_LYO",_CALC_ALLOC!$D$1:$D$349,"BAC_MGT",_CALC_ALLOC!$E$1:$E$349,"B2",_CALC_ALLOC!$F$1:$F$349,"ALT") -> 0 | E27: =SUMIFS(_CALC_ALLOC!$AI$1:$AI$349,_CALC_ALLOC!$A$1:$A$349,"2026",_CALC_ALLOC!$B$1:$B$349,"MBWAY_LYO",_CALC_ALLOC!$D$1:$D$349,"BAC_MGT",_CALC_ALLOC!$E$1:$E$349,"B2",_CALC_ALLOC!$F$1:$F$349,"ALT") -> 0 | F27: =SUMIFS(_CALC_ALLOC!$AJ$1:$AJ$349,_CALC_ALLOC!$A$1:$A$349,"2026",_CALC_ALLOC!$B$1:$B$349,"MBWAY_LYO",_CALC_ALLOC!$D$1:$D$349,"BAC_MGT",_CALC_ALLOC!$E$1:$E$349,"B2",_CALC_ALLOC!$F$1:$F$349,"ALT") -> 0 | G27: =SUMIFS(_CALC_ALLOC!$AK$1:$AK$349,_CALC_ALLOC!$A$1:$A$349,"2026",_CALC_ALLOC!$B$1:$B$349,"MBWAY_LYO",_CALC_ALLOC!$D$1:$D$349,"BAC_MGT",_CALC_ALLOC!$E$1:$E$349,"B2",_CALC_ALLOC!$F$1:$F$349,"ALT") -> 0 | H27: =SUMIFS(_CALC_ALLOC!$AL$1:$AL$349,_CALC_ALLOC!$A$1:$A$349,"2026",_CALC_ALLOC!$B$1:$B$349,"MBWAY_LYO",_CALC_ALLOC!$D$1:$D$349,"BAC_MGT",_CALC_ALLOC!$E$1:$E$349,"B2",_CALC_ALLOC!$F$1:$F$349,"ALT") -> 0 | I27: =SUMIFS(_CALC_ALLOC!$AR$1:$AR$349,_CALC_ALLOC!$A$1:$A$349,"2026",_CALC_ALLOC!$B$1:$B$349,"MBWAY_LYO",_CALC_ALLOC!$D$1:$D$349,"BAC_MGT",_CALC_ALLOC!$E$1:$E$349,"B2",_CALC_ALLOC!$F$1:$F$349,"ALT") -> 0 | J27: =SUMIFS(_CALC_ALLOC!$AM$1:$AM$349,_CALC_ALLOC!$A$1:$A$349,"2026",_CALC_ALLOC!$B$1:$B$349,"MBWAY_LYO",_CALC_ALLOC!$D$1:$D$349,"BAC_MGT",_CALC_ALLOC!$E$1:$E$349,"B2",_CALC_ALLOC!$F$1:$F$349,"ALT") -> 0 | K27: =E27+F27+G27+H27+I27+J27 -> 0 | L27: =SUMIFS(_CALC_ALLOC!$AN$1:$AN$349,_CALC_ALLOC!$A$1:$A$349,"2026",_CALC_ALLOC!$B$1:$B$349,"MBWAY_LYO",_CALC_ALLOC!$D$1:$D$349,"BAC_MGT",_CALC_ALLOC!$E$1:$E$349,"B2",_CALC_ALLOC!$F$1:$F$349,"ALT") -> 0 | M27: =IFERROR(L27/D27,0) -> 0
B28: BAC_MGT B3 ALT | C28: =SUMIFS(_CALC_ALLOC!$G$1:$G$349,_CALC_ALLOC!$A$1:$A$349,"2026",_CALC_ALLOC!$B$1:$B$349,"MBWAY_LYO",_CALC_ALLOC!$D$1:$D$349,"BAC_MGT",_CALC_ALLOC!$E$1:$E$349,"B3",_CALC_ALLOC!$F$1:$F$349,"ALT") -> 0 | D28: =SUMIFS(_CALC_ALLOC!$I$1:$I$349,_CALC_ALLOC!$A$1:$A$349,"2026",_CALC_ALLOC!$B$1:$B$349,"MBWAY_LYO",_CALC_ALLOC!$D$1:$D$349,"BAC_MGT",_CALC_ALLOC!$E$1:$E$349,"B3",_CALC_ALLOC!$F$1:$F$349,"ALT") -> 0 | E28: =SUMIFS(_CALC_ALLOC!$AI$1:$AI$349,_CALC_ALLOC!$A$1:$A$349,"2026",_CALC_ALLOC!$B$1:$B$349,"MBWAY_LYO",_CALC_ALLOC!$D$1:$D$349,"BAC_MGT",_CALC_ALLOC!$E$1:$E$349,"B3",_CALC_ALLOC!$F$1:$F$349,"ALT") -> 0 | F28: =SUMIFS(_CALC_ALLOC!$AJ$1:$AJ$349,_CALC_ALLOC!$A$1:$A$349,"2026",_CALC_ALLOC!$B$1:$B$349,"MBWAY_LYO",_CALC_ALLOC!$D$1:$D$349,"BAC_MGT",_CALC_ALLOC!$E$1:$E$349,"B3",_CALC_ALLOC!$F$1:$F$349,"ALT") -> 0 | G28: =SUMIFS(_CALC_ALLOC!$AK$1:$AK$349,_CALC_ALLOC!$A$1:$A$349,"2026",_CALC_ALLOC!$B$1:$B$349,"MBWAY_LYO",_CALC_ALLOC!$D$1:$D$349,"BAC_MGT",_CALC_ALLOC!$E$1:$E$349,"B3",_CALC_ALLOC!$F$1:$F$349,"ALT") -> 0 | H28: =SUMIFS(_CALC_ALLOC!$AL$1:$AL$349,_CALC_ALLOC!$A$1:$A$349,"2026",_CALC_ALLOC!$B$1:$B$349,"MBWAY_LYO",_CALC_ALLOC!$D$1:$D$349,"BAC_MGT",_CALC_ALLOC!$E$1:$E$349,"B3",_CALC_ALLOC!$F$1:$F$349,"ALT") -> 0 | I28: =SUMIFS(_CALC_ALLOC!$AR$1:$AR$349,_CALC_ALLOC!$A$1:$A$349,"2026",_CALC_ALLOC!$B$1:$B$349,"MBWAY_LYO",_CALC_ALLOC!$D$1:$D$349,"BAC_MGT",_CALC_ALLOC!$E$1:$E$349,"B3",_CALC_ALLOC!$F$1:$F$349,"ALT") -> 0 | J28: =SUMIFS(_CALC_ALLOC!$AM$1:$AM$349,_CALC_ALLOC!$A$1:$A$349,"2026",_CALC_ALLOC!$B$1:$B$349,"MBWAY_LYO",_CALC_ALLOC!$D$1:$D$349,"BAC_MGT",_CALC_ALLOC!$E$1:$E$349,"B3",_CALC_ALLOC!$F$1:$F$349,"ALT") -> 0 | K28: =E28+F28+G28+H28+I28+J28 -> 0 | L28: =SUMIFS(_CALC_ALLOC!$AN$1:$AN$349,_CALC_ALLOC!$A$1:$A$349,"2026",_CALC_ALLOC!$B$1:$B$349,"MBWAY_LYO",_CALC_ALLOC!$D$1:$D$349,"BAC_MGT",_CALC_ALLOC!$E$1:$E$349,"B3",_CALC_ALLOC!$F$1:$F$349,"ALT") -> 0 | M28: =IFERROR(L28/D28,0) -> 0
B29: MAS_MGT M1 ALT | C29: =SUMIFS(_CALC_ALLOC!$G$1:$G$349,_CALC_ALLOC!$A$1:$A$349,"2026",_CALC_ALLOC!$B$1:$B$349,"MBWAY_LYO",_CALC_ALLOC!$D$1:$D$349,"MAS_MGT",_CALC_ALLOC!$E$1:$E$349,"M1",_CALC_ALLOC!$F$1:$F$349,"ALT") -> 0 | D29: =SUMIFS(_CALC_ALLOC!$I$1:$I$349,_CALC_ALLOC!$A$1:$A$349,"2026",_CALC_ALLOC!$B$1:$B$349,"MBWAY_LYO",_CALC_ALLOC!$D$1:$D$349,"MAS_MGT",_CALC_ALLOC!$E$1:$E$349,"M1",_CALC_ALLOC!$F$1:$F$349,"ALT") -> 0 | E29: =SUMIFS(_CALC_ALLOC!$AI$1:$AI$349,_CALC_ALLOC!$A$1:$A$349,"2026",_CALC_ALLOC!$B$1:$B$349,"MBWAY_LYO",_CALC_ALLOC!$D$1:$D$349,"MAS_MGT",_CALC_ALLOC!$E$1:$E$349,"M1",_CALC_ALLOC!$F$1:$F$349,"ALT") -> 0 | F29: =SUMIFS(_CALC_ALLOC!$AJ$1:$AJ$349,_CALC_ALLOC!$A$1:$A$349,"2026",_CALC_ALLOC!$B$1:$B$349,"MBWAY_LYO",_CALC_ALLOC!$D$1:$D$349,"MAS_MGT",_CALC_ALLOC!$E$1:$E$349,"M1",_CALC_ALLOC!$F$1:$F$349,"ALT") -> 0 | G29: =SUMIFS(_CALC_ALLOC!$AK$1:$AK$349,_CALC_ALLOC!$A$1:$A$349,"2026",_CALC_ALLOC!$B$1:$B$349,"MBWAY_LYO",_CALC_ALLOC!$D$1:$D$349,"MAS_MGT",_CALC_ALLOC!$E$1:$E$349,"M1",_CALC_ALLOC!$F$1:$F$349,"ALT") -> 0 | H29: =SUMIFS(_CALC_ALLOC!$AL$1:$AL$349,_CALC_ALLOC!$A$1:$A$349,"2026",_CALC_ALLOC!$B$1:$B$349,"MBWAY_LYO",_CALC_ALLOC!$D$1:$D$349,"MAS_MGT",_CALC_ALLOC!$E$1:$E$349,"M1",_CALC_ALLOC!$F$1:$F$349,"ALT") -> 0 | I29: =SUMIFS(_CALC_ALLOC!$AR$1:$AR$349,_CALC_ALLOC!$A$1:$A$349,"2026",_CALC_ALLOC!$B$1:$B$349,"MBWAY_LYO",_CALC_ALLOC!$D$1:$D$349,"MAS_MGT",_CALC_ALLOC!$E$1:$E$349,"M1",_CALC_ALLOC!$F$1:$F$349,"ALT") -> 0 | J29: =SUMIFS(_CALC_ALLOC!$AM$1:$AM$349,_CALC_ALLOC!$A$1:$A$349,"2026",_CALC_ALLOC!$B$1:$B$349,"MBWAY_LYO",_CALC_ALLOC!$D$1:$D$349,"MAS_MGT",_CALC_ALLOC!$E$1:$E$349,"M1",_CALC_ALLOC!$F$1:$F$349,"ALT") -> 0 | K29: =E29+F29+G29+H29+I29+J29 -> 0 | L29: =SUMIFS(_CALC_ALLOC!$AN$1:$AN$349,_CALC_ALLOC!$A$1:$A$349,"2026",_CALC_ALLOC!$B$1:$B$349,"MBWAY_LYO",_CALC_ALLOC!$D$1:$D$349,"MAS_MGT",_CALC_ALLOC!$E$1:$E$349,"M1",_CALC_ALLOC!$F$1:$F$349,"ALT") -> 0 | M29: =IFERROR(L29/D29,0) -> 0
B30: MAS_MGT M2 ALT | C30: =SUMIFS(_CALC_ALLOC!$G$1:$G$349,_CALC_ALLOC!$A$1:$A$349,"2026",_CALC_ALLOC!$B$1:$B$349,"MBWAY_LYO",_CALC_ALLOC!$D$1:$D$349,"MAS_MGT",_CALC_ALLOC!$E$1:$E$349,"M2",_CALC_ALLOC!$F$1:$F$349,"ALT") -> 0 | D30: =SUMIFS(_CALC_ALLOC!$I$1:$I$349,_CALC_ALLOC!$A$1:$A$349,"2026",_CALC_ALLOC!$B$1:$B$349,"MBWAY_LYO",_CALC_ALLOC!$D$1:$D$349,"MAS_MGT",_CALC_ALLOC!$E$1:$E$349,"M2",_CALC_ALLOC!$F$1:$F$349,"ALT") -> 0 | E30: =SUMIFS(_CALC_ALLOC!$AI$1:$AI$349,_CALC_ALLOC!$A$1:$A$349,"2026",_CALC_ALLOC!$B$1:$B$349,"MBWAY_LYO",_CALC_ALLOC!$D$1:$D$349,"MAS_MGT",_CALC_ALLOC!$E$1:$E$349,"M2",_CALC_ALLOC!$F$1:$F$349,"ALT") -> 0 | F30: =SUMIFS(_CALC_ALLOC!$AJ$1:$AJ$349,_CALC_ALLOC!$A$1:$A$349,"2026",_CALC_ALLOC!$B$1:$B$349,"MBWAY_LYO",_CALC_ALLOC!$D$1:$D$349,"MAS_MGT",_CALC_ALLOC!$E$1:$E$349,"M2",_CALC_ALLOC!$F$1:$F$349,"ALT") -> 0 | G30: =SUMIFS(_CALC_ALLOC!$AK$1:$AK$349,_CALC_ALLOC!$A$1:$A$349,"2026",_CALC_ALLOC!$B$1:$B$349,"MBWAY_LYO",_CALC_ALLOC!$D$1:$D$349,"MAS_MGT",_CALC_ALLOC!$E$1:$E$349,"M2",_CALC_ALLOC!$F$1:$F$349,"ALT") -> 0 | H30: =SUMIFS(_CALC_ALLOC!$AL$1:$AL$349,_CALC_ALLOC!$A$1:$A$349,"2026",_CALC_ALLOC!$B$1:$B$349,"MBWAY_LYO",_CALC_ALLOC!$D$1:$D$349,"MAS_MGT",_CALC_ALLOC!$E$1:$E$349,"M2",_CALC_ALLOC!$F$1:$F$349,"ALT") -> 0 | I30: =SUMIFS(_CALC_ALLOC!$AR$1:$AR$349,_CALC_ALLOC!$A$1:$A$349,"2026",_CALC_ALLOC!$B$1:$B$349,"MBWAY_LYO",_CALC_ALLOC!$D$1:$D$349,"MAS_MGT",_CALC_ALLOC!$E$1:$E$349,"M2",_CALC_ALLOC!$F$1:$F$349,"ALT") -> 0 | J30: =SUMIFS(_CALC_ALLOC!$AM$1:$AM$349,_CALC_ALLOC!$A$1:$A$349,"2026",_CALC_ALLOC!$B$1:$B$349,"MBWAY_LYO",_CALC_ALLOC!$D$1:$D$349,"MAS_MGT",_CALC_ALLOC!$E$1:$E$349,"M2",_CALC_ALLOC!$F$1:$F$349,"ALT") -> 0 | K30: =E30+F30+G30+H30+I30+J30 -> 0 | L30: =SUMIFS(_CALC_ALLOC!$AN$1:$AN$349,_CALC_ALLOC!$A$1:$A$349,"2026",_CALC_ALLOC!$B$1:$B$349,"MBWAY_LYO",_CALC_ALLOC!$D$1:$D$349,"MAS_MGT",_CALC_ALLOC!$E$1:$E$349,"M2",_CALC_ALLOC!$F$1:$F$349,"ALT") -> 0 | M30: =IFERROR(L30/D30,0) -> 0
B31: Nantes (MBWAY_NAN) | C31: =SUMIFS(_CALC_ALLOC!$G$1:$G$349,_CALC_ALLOC!$A$1:$A$349,"2026",_CALC_ALLOC!$B$1:$B$349,"MBWAY_NAN") -> 0 | D31: =SUMIFS(_CALC_ALLOC!$I$1:$I$349,_CALC_ALLOC!$A$1:$A$349,"2026",_CALC_ALLOC!$B$1:$B$349,"MBWAY_NAN") -> 0 | E31: =SUMIFS(_CALC_ALLOC!$AI$1:$AI$349,_CALC_ALLOC!$A$1:$A$349,"2026",_CALC_ALLOC!$B$1:$B$349,"MBWAY_NAN") -> 0 | F31: =SUMIFS(_CALC_ALLOC!$AJ$1:$AJ$349,_CALC_ALLOC!$A$1:$A$349,"2026",_CALC_ALLOC!$B$1:$B$349,"MBWAY_NAN") -> 0 | G31: =SUMIFS(_CALC_ALLOC!$AK$1:$AK$349,_CALC_ALLOC!$A$1:$A$349,"2026",_CALC_ALLOC!$B$1:$B$349,"MBWAY_NAN") -> 0 | H31: =SUMIFS(_CALC_ALLOC!$AL$1:$AL$349,_CALC_ALLOC!$A$1:$A$349,"2026",_CALC_ALLOC!$B$1:$B$349,"MBWAY_NAN") -> 0 | I31: =SUMIFS(_CALC_ALLOC!$AR$1:$AR$349,_CALC_ALLOC!$A$1:$A$349,"2026",_CALC_ALLOC!$B$1:$B$349,"MBWAY_NAN") -> 0 | J31: =SUMIFS(_CALC_ALLOC!$AM$1:$AM$349,_CALC_ALLOC!$A$1:$A$349,"2026",_CALC_ALLOC!$B$1:$B$349,"MBWAY_NAN") -> 0 | K31: =E31+F31+G31+H31+I31+J31 -> 0 | L31: =SUMIFS(_CALC_ALLOC!$AN$1:$AN$349,_CALC_ALLOC!$A$1:$A$349,"2026",_CALC_ALLOC!$B$1:$B$349,"MBWAY_NAN") -> 0 | M31: =IFERROR(L31/D31,0) -> 0
B32: BAC_MGT B1 INIT | C32: =SUMIFS(_CALC_ALLOC!$G$1:$G$349,_CALC_ALLOC!$A$1:$A$349,"2026",_CALC_ALLOC!$B$1:$B$349,"MBWAY_NAN",_CALC_ALLOC!$D$1:$D$349,"BAC_MGT",_CALC_ALLOC!$E$1:$E$349,"B1",_CALC_ALLOC!$F$1:$F$349,"INIT") -> 0 | D32: =SUMIFS(_CALC_ALLOC!$I$1:$I$349,_CALC_ALLOC!$A$1:$A$349,"2026",_CALC_ALLOC!$B$1:$B$349,"MBWAY_NAN",_CALC_ALLOC!$D$1:$D$349,"BAC_MGT",_CALC_ALLOC!$E$1:$E$349,"B1",_CALC_ALLOC!$F$1:$F$349,"INIT") -> 0 | E32: =SUMIFS(_CALC_ALLOC!$AI$1:$AI$349,_CALC_ALLOC!$A$1:$A$349,"2026",_CALC_ALLOC!$B$1:$B$349,"MBWAY_NAN",_CALC_ALLOC!$D$1:$D$349,"BAC_MGT",_CALC_ALLOC!$E$1:$E$349,"B1",_CALC_ALLOC!$F$1:$F$349,"INIT") -> 0 | F32: =SUMIFS(_CALC_ALLOC!$AJ$1:$AJ$349,_CALC_ALLOC!$A$1:$A$349,"2026",_CALC_ALLOC!$B$1:$B$349,"MBWAY_NAN",_CALC_ALLOC!$D$1:$D$349,"BAC_MGT",_CALC_ALLOC!$E$1:$E$349,"B1",_CALC_ALLOC!$F$1:$F$349,"INIT") -> 0 | G32: =SUMIFS(_CALC_ALLOC!$AK$1:$AK$349,_CALC_ALLOC!$A$1:$A$349,"2026",_CALC_ALLOC!$B$1:$B$349,"MBWAY_NAN",_CALC_ALLOC!$D$1:$D$349,"BAC_MGT",_CALC_ALLOC!$E$1:$E$349,"B1",_CALC_ALLOC!$F$1:$F$349,"INIT") -> 0 | H32: =SUMIFS(_CALC_ALLOC!$AL$1:$AL$349,_CALC_ALLOC!$A$1:$A$349,"2026",_CALC_ALLOC!$B$1:$B$349,"MBWAY_NAN",_CALC_ALLOC!$D$1:$D$349,"BAC_MGT",_CALC_ALLOC!$E$1:$E$349,"B1",_CALC_ALLOC!$F$1:$F$349,"INIT") -> 0 | I32: =SUMIFS(_CALC_ALLOC!$AR$1:$AR$349,_CALC_ALLOC!$A$1:$A$349,"2026",_CALC_ALLOC!$B$1:$B$349,"MBWAY_NAN",_CALC_ALLOC!$D$1:$D$349,"BAC_MGT",_CALC_ALLOC!$E$1:$E$349,"B1",_CALC_ALLOC!$F$1:$F$349,"INIT") -> 0 | J32: =SUMIFS(_CALC_ALLOC!$AM$1:$AM$349,_CALC_ALLOC!$A$1:$A$349,"2026",_CALC_ALLOC!$B$1:$B$349,"MBWAY_NAN",_CALC_ALLOC!$D$1:$D$349,"BAC_MGT",_CALC_ALLOC!$E$1:$E$349,"B1",_CALC_ALLOC!$F$1:$F$349,"INIT") -> 0 | K32: =E32+F32+G32+H32+I32+J32 -> 0 | L32: =SUMIFS(_CALC_ALLOC!$AN$1:$AN$349,_CALC_ALLOC!$A$1:$A$349,"2026",_CALC_ALLOC!$B$1:$B$349,"MBWAY_NAN",_CALC_ALLOC!$D$1:$D$349,"BAC_MGT",_CALC_ALLOC!$E$1:$E$349,"B1",_CALC_ALLOC!$F$1:$F$349,"INIT") -> 0 | M32: =IFERROR(L32/D32,0) -> 0
B33: BAC_MGT B2 ALT | C33: =SUMIFS(_CALC_ALLOC!$G$1:$G$349,_CALC_ALLOC!$A$1:$A$349,"2026",_CALC_ALLOC!$B$1:$B$349,"MBWAY_NAN",_CALC_ALLOC!$D$1:$D$349,"BAC_MGT",_CALC_ALLOC!$E$1:$E$349,"B2",_CALC_ALLOC!$F$1:$F$349,"ALT") -> 0 | D33: =SUMIFS(_CALC_ALLOC!$I$1:$I$349,_CALC_ALLOC!$A$1:$A$349,"2026",_CALC_ALLOC!$B$1:$B$349,"MBWAY_NAN",_CALC_ALLOC!$D$1:$D$349,"BAC_MGT",_CALC_ALLOC!$E$1:$E$349,"B2",_CALC_ALLOC!$F$1:$F$349,"ALT") -> 0 | E33: =SUMIFS(_CALC_ALLOC!$AI$1:$AI$349,_CALC_ALLOC!$A$1:$A$349,"2026",_CALC_ALLOC!$B$1:$B$349,"MBWAY_NAN",_CALC_ALLOC!$D$1:$D$349,"BAC_MGT",_CALC_ALLOC!$E$1:$E$349,"B2",_CALC_ALLOC!$F$1:$F$349,"ALT") -> 0 | F33: =SUMIFS(_CALC_ALLOC!$AJ$1:$AJ$349,_CALC_ALLOC!$A$1:$A$349,"2026",_CALC_ALLOC!$B$1:$B$349,"MBWAY_NAN",_CALC_ALLOC!$D$1:$D$349,"BAC_MGT",_CALC_ALLOC!$E$1:$E$349,"B2",_CALC_ALLOC!$F$1:$F$349,"ALT") -> 0 | G33: =SUMIFS(_CALC_ALLOC!$AK$1:$AK$349,_CALC_ALLOC!$A$1:$A$349,"2026",_CALC_ALLOC!$B$1:$B$349,"MBWAY_NAN",_CALC_ALLOC!$D$1:$D$349,"BAC_MGT",_CALC_ALLOC!$E$1:$E$349,"B2",_CALC_ALLOC!$F$1:$F$349,"ALT") -> 0 | H33: =SUMIFS(_CALC_ALLOC!$AL$1:$AL$349,_CALC_ALLOC!$A$1:$A$349,"2026",_CALC_ALLOC!$B$1:$B$349,"MBWAY_NAN",_CALC_ALLOC!$D$1:$D$349,"BAC_MGT",_CALC_ALLOC!$E$1:$E$349,"B2",_CALC_ALLOC!$F$1:$F$349,"ALT") -> 0 | I33: =SUMIFS(_CALC_ALLOC!$AR$1:$AR$349,_CALC_ALLOC!$A$1:$A$349,"2026",_CALC_ALLOC!$B$1:$B$349,"MBWAY_NAN",_CALC_ALLOC!$D$1:$D$349,"BAC_MGT",_CALC_ALLOC!$E$1:$E$349,"B2",_CALC_ALLOC!$F$1:$F$349,"ALT") -> 0 | J33: =SUMIFS(_CALC_ALLOC!$AM$1:$AM$349,_CALC_ALLOC!$A$1:$A$349,"2026",_CALC_ALLOC!$B$1:$B$349,"MBWAY_NAN",_CALC_ALLOC!$D$1:$D$349,"BAC_MGT",_CALC_ALLOC!$E$1:$E$349,"B2",_CALC_ALLOC!$F$1:$F$349,"ALT") -> 0 | K33: =E33+F33+G33+H33+I33+J33 -> 0 | L33: =SUMIFS(_CALC_ALLOC!$AN$1:$AN$349,_CALC_ALLOC!$A$1:$A$349,"2026",_CALC_ALLOC!$B$1:$B$349,"MBWAY_NAN",_CALC_ALLOC!$D$1:$D$349,"BAC_MGT",_CALC_ALLOC!$E$1:$E$349,"B2",_CALC_ALLOC!$F$1:$F$349,"ALT") -> 0 | M33: =IFERROR(L33/D33,0) -> 0
B34: BAC_MGT B3 ALT | C34: =SUMIFS(_CALC_ALLOC!$G$1:$G$349,_CALC_ALLOC!$A$1:$A$349,"2026",_CALC_ALLOC!$B$1:$B$349,"MBWAY_NAN",_CALC_ALLOC!$D$1:$D$349,"BAC_MGT",_CALC_ALLOC!$E$1:$E$349,"B3",_CALC_ALLOC!$F$1:$F$349,"ALT") -> 0 | D34: =SUMIFS(_CALC_ALLOC!$I$1:$I$349,_CALC_ALLOC!$A$1:$A$349,"2026",_CALC_ALLOC!$B$1:$B$349,"MBWAY_NAN",_CALC_ALLOC!$D$1:$D$349,"BAC_MGT",_CALC_ALLOC!$E$1:$E$349,"B3",_CALC_ALLOC!$F$1:$F$349,"ALT") -> 0 | E34: =SUMIFS(_CALC_ALLOC!$AI$1:$AI$349,_CALC_ALLOC!$A$1:$A$349,"2026",_CALC_ALLOC!$B$1:$B$349,"MBWAY_NAN",_CALC_ALLOC!$D$1:$D$349,"BAC_MGT",_CALC_ALLOC!$E$1:$E$349,"B3",_CALC_ALLOC!$F$1:$F$349,"ALT") -> 0 | F34: =SUMIFS(_CALC_ALLOC!$AJ$1:$AJ$349,_CALC_ALLOC!$A$1:$A$349,"2026",_CALC_ALLOC!$B$1:$B$349,"MBWAY_NAN",_CALC_ALLOC!$D$1:$D$349,"BAC_MGT",_CALC_ALLOC!$E$1:$E$349,"B3",_CALC_ALLOC!$F$1:$F$349,"ALT") -> 0 | G34: =SUMIFS(_CALC_ALLOC!$AK$1:$AK$349,_CALC_ALLOC!$A$1:$A$349,"2026",_CALC_ALLOC!$B$1:$B$349,"MBWAY_NAN",_CALC_ALLOC!$D$1:$D$349,"BAC_MGT",_CALC_ALLOC!$E$1:$E$349,"B3",_CALC_ALLOC!$F$1:$F$349,"ALT") -> 0 | H34: =SUMIFS(_CALC_ALLOC!$AL$1:$AL$349,_CALC_ALLOC!$A$1:$A$349,"2026",_CALC_ALLOC!$B$1:$B$349,"MBWAY_NAN",_CALC_ALLOC!$D$1:$D$349,"BAC_MGT",_CALC_ALLOC!$E$1:$E$349,"B3",_CALC_ALLOC!$F$1:$F$349,"ALT") -> 0 | I34: =SUMIFS(_CALC_ALLOC!$AR$1:$AR$349,_CALC_ALLOC!$A$1:$A$349,"2026",_CALC_ALLOC!$B$1:$B$349,"MBWAY_NAN",_CALC_ALLOC!$D$1:$D$349,"BAC_MGT",_CALC_ALLOC!$E$1:$E$349,"B3",_CALC_ALLOC!$F$1:$F$349,"ALT") -> 0 | J34: =SUMIFS(_CALC_ALLOC!$AM$1:$AM$349,_CALC_ALLOC!$A$1:$A$349,"2026",_CALC_ALLOC!$B$1:$B$349,"MBWAY_NAN",_CALC_ALLOC!$D$1:$D$349,"BAC_MGT",_CALC_ALLOC!$E$1:$E$349,"B3",_CALC_ALLOC!$F$1:$F$349,"ALT") -> 0 | K34: =E34+F34+G34+H34+I34+J34 -> 0 | L34: =SUMIFS(_CALC_ALLOC!$AN$1:$AN$349,_CALC_ALLOC!$A$1:$A$349,"2026",_CALC_ALLOC!$B$1:$B$349,"MBWAY_NAN",_CALC_ALLOC!$D$1:$D$349,"BAC_MGT",_CALC_ALLOC!$E$1:$E$349,"B3",_CALC_ALLOC!$F$1:$F$349,"ALT") -> 0 | M34: =IFERROR(L34/D34,0) -> 0
B35: MAS_MGT M1 ALT | C35: =SUMIFS(_CALC_ALLOC!$G$1:$G$349,_CALC_ALLOC!$A$1:$A$349,"2026",_CALC_ALLOC!$B$1:$B$349,"MBWAY_NAN",_CALC_ALLOC!$D$1:$D$349,"MAS_MGT",_CALC_ALLOC!$E$1:$E$349,"M1",_CALC_ALLOC!$F$1:$F$349,"ALT") -> 0 | D35: =SUMIFS(_CALC_ALLOC!$I$1:$I$349,_CALC_ALLOC!$A$1:$A$349,"2026",_CALC_ALLOC!$B$1:$B$349,"MBWAY_NAN",_CALC_ALLOC!$D$1:$D$349,"MAS_MGT",_CALC_ALLOC!$E$1:$E$349,"M1",_CALC_ALLOC!$F$1:$F$349,"ALT") -> 0 | E35: =SUMIFS(_CALC_ALLOC!$AI$1:$AI$349,_CALC_ALLOC!$A$1:$A$349,"2026",_CALC_ALLOC!$B$1:$B$349,"MBWAY_NAN",_CALC_ALLOC!$D$1:$D$349,"MAS_MGT",_CALC_ALLOC!$E$1:$E$349,"M1",_CALC_ALLOC!$F$1:$F$349,"ALT") -> 0 | F35: =SUMIFS(_CALC_ALLOC!$AJ$1:$AJ$349,_CALC_ALLOC!$A$1:$A$349,"2026",_CALC_ALLOC!$B$1:$B$349,"MBWAY_NAN",_CALC_ALLOC!$D$1:$D$349,"MAS_MGT",_CALC_ALLOC!$E$1:$E$349,"M1",_CALC_ALLOC!$F$1:$F$349,"ALT") -> 0 | G35: =SUMIFS(_CALC_ALLOC!$AK$1:$AK$349,_CALC_ALLOC!$A$1:$A$349,"2026",_CALC_ALLOC!$B$1:$B$349,"MBWAY_NAN",_CALC_ALLOC!$D$1:$D$349,"MAS_MGT",_CALC_ALLOC!$E$1:$E$349,"M1",_CALC_ALLOC!$F$1:$F$349,"ALT") -> 0 | H35: =SUMIFS(_CALC_ALLOC!$AL$1:$AL$349,_CALC_ALLOC!$A$1:$A$349,"2026",_CALC_ALLOC!$B$1:$B$349,"MBWAY_NAN",_CALC_ALLOC!$D$1:$D$349,"MAS_MGT",_CALC_ALLOC!$E$1:$E$349,"M1",_CALC_ALLOC!$F$1:$F$349,"ALT") -> 0 | I35: =SUMIFS(_CALC_ALLOC!$AR$1:$AR$349,_CALC_ALLOC!$A$1:$A$349,"2026",_CALC_ALLOC!$B$1:$B$349,"MBWAY_NAN",_CALC_ALLOC!$D$1:$D$349,"MAS_MGT",_CALC_ALLOC!$E$1:$E$349,"M1",_CALC_ALLOC!$F$1:$F$349,"ALT") -> 0 | J35: =SUMIFS(_CALC_ALLOC!$AM$1:$AM$349,_CALC_ALLOC!$A$1:$A$349,"2026",_CALC_ALLOC!$B$1:$B$349,"MBWAY_NAN",_CALC_ALLOC!$D$1:$D$349,"MAS_MGT",_CALC_ALLOC!$E$1:$E$349,"M1",_CALC_ALLOC!$F$1:$F$349,"ALT") -> 0 | K35: =E35+F35+G35+H35+I35+J35 -> 0 | L35: =SUMIFS(_CALC_ALLOC!$AN$1:$AN$349,_CALC_ALLOC!$A$1:$A$349,"2026",_CALC_ALLOC!$B$1:$B$349,"MBWAY_NAN",_CALC_ALLOC!$D$1:$D$349,"MAS_MGT",_CALC_ALLOC!$E$1:$E$349,"M1",_CALC_ALLOC!$F$1:$F$349,"ALT") -> 0 | M35: =IFERROR(L35/D35,0) -> 0
B36: MAS_MGT M2 ALT | C36: =SUMIFS(_CALC_ALLOC!$G$1:$G$349,_CALC_ALLOC!$A$1:$A$349,"2026",_CALC_ALLOC!$B$1:$B$349,"MBWAY_NAN",_CALC_ALLOC!$D$1:$D$349,"MAS_MGT",_CALC_ALLOC!$E$1:$E$349,"M2",_CALC_ALLOC!$F$1:$F$349,"ALT") -> 0 | D36: =SUMIFS(_CALC_ALLOC!$I$1:$I$349,_CALC_ALLOC!$A$1:$A$349,"2026",_CALC_ALLOC!$B$1:$B$349,"MBWAY_NAN",_CALC_ALLOC!$D$1:$D$349,"MAS_MGT",_CALC_ALLOC!$E$1:$E$349,"M2",_CALC_ALLOC!$F$1:$F$349,"ALT") -> 0 | E36: =SUMIFS(_CALC_ALLOC!$AI$1:$AI$349,_CALC_ALLOC!$A$1:$A$349,"2026",_CALC_ALLOC!$B$1:$B$349,"MBWAY_NAN",_CALC_ALLOC!$D$1:$D$349,"MAS_MGT",_CALC_ALLOC!$E$1:$E$349,"M2",_CALC_ALLOC!$F$1:$F$349,"ALT") -> 0 | F36: =SUMIFS(_CALC_ALLOC!$AJ$1:$AJ$349,_CALC_ALLOC!$A$1:$A$349,"2026",_CALC_ALLOC!$B$1:$B$349,"MBWAY_NAN",_CALC_ALLOC!$D$1:$D$349,"MAS_MGT",_CALC_ALLOC!$E$1:$E$349,"M2",_CALC_ALLOC!$F$1:$F$349,"ALT") -> 0 | G36: =SUMIFS(_CALC_ALLOC!$AK$1:$AK$349,_CALC_ALLOC!$A$1:$A$349,"2026",_CALC_ALLOC!$B$1:$B$349,"MBWAY_NAN",_CALC_ALLOC!$D$1:$D$349,"MAS_MGT",_CALC_ALLOC!$E$1:$E$349,"M2",_CALC_ALLOC!$F$1:$F$349,"ALT") -> 0 | H36: =SUMIFS(_CALC_ALLOC!$AL$1:$AL$349,_CALC_ALLOC!$A$1:$A$349,"2026",_CALC_ALLOC!$B$1:$B$349,"MBWAY_NAN",_CALC_ALLOC!$D$1:$D$349,"MAS_MGT",_CALC_ALLOC!$E$1:$E$349,"M2",_CALC_ALLOC!$F$1:$F$349,"ALT") -> 0 | I36: =SUMIFS(_CALC_ALLOC!$AR$1:$AR$349,_CALC_ALLOC!$A$1:$A$349,"2026",_CALC_ALLOC!$B$1:$B$349,"MBWAY_NAN",_CALC_ALLOC!$D$1:$D$349,"MAS_MGT",_CALC_ALLOC!$E$1:$E$349,"M2",_CALC_ALLOC!$F$1:$F$349,"ALT") -> 0 | J36: =SUMIFS(_CALC_ALLOC!$AM$1:$AM$349,_CALC_ALLOC!$A$1:$A$349,"2026",_CALC_ALLOC!$B$1:$B$349,"MBWAY_NAN",_CALC_ALLOC!$D$1:$D$349,"MAS_MGT",_CALC_ALLOC!$E$1:$E$349,"M2",_CALC_ALLOC!$F$1:$F$349,"ALT") -> 0 | K36: =E36+F36+G36+H36+I36+J36 -> 0 | L36: =SUMIFS(_CALC_ALLOC!$AN$1:$AN$349,_CALC_ALLOC!$A$1:$A$349,"2026",_CALC_ALLOC!$B$1:$B$349,"MBWAY_NAN",_CALC_ALLOC!$D$1:$D$349,"MAS_MGT",_CALC_ALLOC!$E$1:$E$349,"M2",_CALC_ALLOC!$F$1:$F$349,"ALT") -> 0 | M36: =IFERROR(L36/D36,0) -> 0
B37: Bordeaux (MBWAY_BOR) | C37: =SUMIFS(_CALC_ALLOC!$G$1:$G$349,_CALC_ALLOC!$A$1:$A$349,"2026",_CALC_ALLOC!$B$1:$B$349,"MBWAY_BOR") -> 0 | D37: =SUMIFS(_CALC_ALLOC!$I$1:$I$349,_CALC_ALLOC!$A$1:$A$349,"2026",_CALC_ALLOC!$B$1:$B$349,"MBWAY_BOR") -> 0 | E37: =SUMIFS(_CALC_ALLOC!$AI$1:$AI$349,_CALC_ALLOC!$A$1:$A$349,"2026",_CALC_ALLOC!$B$1:$B$349,"MBWAY_BOR") -> 0 | F37: =SUMIFS(_CALC_ALLOC!$AJ$1:$AJ$349,_CALC_ALLOC!$A$1:$A$349,"2026",_CALC_ALLOC!$B$1:$B$349,"MBWAY_BOR") -> 0 | G37: =SUMIFS(_CALC_ALLOC!$AK$1:$AK$349,_CALC_ALLOC!$A$1:$A$349,"2026",_CALC_ALLOC!$B$1:$B$349,"MBWAY_BOR") -> 0 | H37: =SUMIFS(_CALC_ALLOC!$AL$1:$AL$349,_CALC_ALLOC!$A$1:$A$349,"2026",_CALC_ALLOC!$B$1:$B$349,"MBWAY_BOR") -> 0 | I37: =SUMIFS(_CALC_ALLOC!$AR$1:$AR$349,_CALC_ALLOC!$A$1:$A$349,"2026",_CALC_ALLOC!$B$1:$B$349,"MBWAY_BOR") -> 0 | J37: =SUMIFS(_CALC_ALLOC!$AM$1:$AM$349,_CALC_ALLOC!$A$1:$A$349,"2026",_CALC_ALLOC!$B$1:$B$349,"MBWAY_BOR") -> 0 | K37: =E37+F37+G37+H37+I37+J37 -> 0 | L37: =SUMIFS(_CALC_ALLOC!$AN$1:$AN$349,_CALC_ALLOC!$A$1:$A$349,"2026",_CALC_ALLOC!$B$1:$B$349,"MBWAY_BOR") -> 0 | M37: =IFERROR(L37/D37,0) -> 0
B38: BAC_MGT B1 INIT | C38: =SUMIFS(_CALC_ALLOC!$G$1:$G$349,_CALC_ALLOC!$A$1:$A$349,"2026",_CALC_ALLOC!$B$1:$B$349,"MBWAY_BOR",_CALC_ALLOC!$D$1:$D$349,"BAC_MGT",_CALC_ALLOC!$E$1:$E$349,"B1",_CALC_ALLOC!$F$1:$F$349,"INIT") -> 0 | D38: =SUMIFS(_CALC_ALLOC!$I$1:$I$349,_CALC_ALLOC!$A$1:$A$349,"2026",_CALC_ALLOC!$B$1:$B$349,"MBWAY_BOR",_CALC_ALLOC!$D$1:$D$349,"BAC_MGT",_CALC_ALLOC!$E$1:$E$349,"B1",_CALC_ALLOC!$F$1:$F$349,"INIT") -> 0 | E38: =SUMIFS(_CALC_ALLOC!$AI$1:$AI$349,_CALC_ALLOC!$A$1:$A$349,"2026",_CALC_ALLOC!$B$1:$B$349,"MBWAY_BOR",_CALC_ALLOC!$D$1:$D$349,"BAC_MGT",_CALC_ALLOC!$E$1:$E$349,"B1",_CALC_ALLOC!$F$1:$F$349,"INIT") -> 0 | F38: =SUMIFS(_CALC_ALLOC!$AJ$1:$AJ$349,_CALC_ALLOC!$A$1:$A$349,"2026",_CALC_ALLOC!$B$1:$B$349,"MBWAY_BOR",_CALC_ALLOC!$D$1:$D$349,"BAC_MGT",_CALC_ALLOC!$E$1:$E$349,"B1",_CALC_ALLOC!$F$1:$F$349,"INIT") -> 0 | G38: =SUMIFS(_CALC_ALLOC!$AK$1:$AK$349,_CALC_ALLOC!$A$1:$A$349,"2026",_CALC_ALLOC!$B$1:$B$349,"MBWAY_BOR",_CALC_ALLOC!$D$1:$D$349,"BAC_MGT",_CALC_ALLOC!$E$1:$E$349,"B1",_CALC_ALLOC!$F$1:$F$349,"INIT") -> 0 | H38: =SUMIFS(_CALC_ALLOC!$AL$1:$AL$349,_CALC_ALLOC!$A$1:$A$349,"2026",_CALC_ALLOC!$B$1:$B$349,"MBWAY_BOR",_CALC_ALLOC!$D$1:$D$349,"BAC_MGT",_CALC_ALLOC!$E$1:$E$349,"B1",_CALC_ALLOC!$F$1:$F$349,"INIT") -> 0 | I38: =SUMIFS(_CALC_ALLOC!$AR$1:$AR$349,_CALC_ALLOC!$A$1:$A$349,"2026",_CALC_ALLOC!$B$1:$B$349,"MBWAY_BOR",_CALC_ALLOC!$D$1:$D$349,"BAC_MGT",_CALC_ALLOC!$E$1:$E$349,"B1",_CALC_ALLOC!$F$1:$F$349,"INIT") -> 0 | J38: =SUMIFS(_CALC_ALLOC!$AM$1:$AM$349,_CALC_ALLOC!$A$1:$A$349,"2026",_CALC_ALLOC!$B$1:$B$349,"MBWAY_BOR",_CALC_ALLOC!$D$1:$D$349,"BAC_MGT",_CALC_ALLOC!$E$1:$E$349,"B1",_CALC_ALLOC!$F$1:$F$349,"INIT") -> 0 | K38: =E38+F38+G38+H38+I38+J38 -> 0 | L38: =SUMIFS(_CALC_ALLOC!$AN$1:$AN$349,_CALC_ALLOC!$A$1:$A$349,"2026",_CALC_ALLOC!$B$1:$B$349,"MBWAY_BOR",_CALC_ALLOC!$D$1:$D$349,"BAC_MGT",_CALC_ALLOC!$E$1:$E$349,"B1",_CALC_ALLOC!$F$1:$F$349,"INIT") -> 0 | M38: =IFERROR(L38/D38,0) -> 0
B39: BAC_MGT B2 ALT | C39: =SUMIFS(_CALC_ALLOC!$G$1:$G$349,_CALC_ALLOC!$A$1:$A$349,"2026",_CALC_ALLOC!$B$1:$B$349,"MBWAY_BOR",_CALC_ALLOC!$D$1:$D$349,"BAC_MGT",_CALC_ALLOC!$E$1:$E$349,"B2",_CALC_ALLOC!$F$1:$F$349,"ALT") -> 0 | D39: =SUMIFS(_CALC_ALLOC!$I$1:$I$349,_CALC_ALLOC!$A$1:$A$349,"2026",_CALC_ALLOC!$B$1:$B$349,"MBWAY_BOR",_CALC_ALLOC!$D$1:$D$349,"BAC_MGT",_CALC_ALLOC!$E$1:$E$349,"B2",_CALC_ALLOC!$F$1:$F$349,"ALT") -> 0 | E39: =SUMIFS(_CALC_ALLOC!$AI$1:$AI$349,_CALC_ALLOC!$A$1:$A$349,"2026",_CALC_ALLOC!$B$1:$B$349,"MBWAY_BOR",_CALC_ALLOC!$D$1:$D$349,"BAC_MGT",_CALC_ALLOC!$E$1:$E$349,"B2",_CALC_ALLOC!$F$1:$F$349,"ALT") -> 0 | F39: =SUMIFS(_CALC_ALLOC!$AJ$1:$AJ$349,_CALC_ALLOC!$A$1:$A$349,"2026",_CALC_ALLOC!$B$1:$B$349,"MBWAY_BOR",_CALC_ALLOC!$D$1:$D$349,"BAC_MGT",_CALC_ALLOC!$E$1:$E$349,"B2",_CALC_ALLOC!$F$1:$F$349,"ALT") -> 0 | G39: =SUMIFS(_CALC_ALLOC!$AK$1:$AK$349,_CALC_ALLOC!$A$1:$A$349,"2026",_CALC_ALLOC!$B$1:$B$349,"MBWAY_BOR",_CALC_ALLOC!$D$1:$D$349,"BAC_MGT",_CALC_ALLOC!$E$1:$E$349,"B2",_CALC_ALLOC!$F$1:$F$349,"ALT") -> 0 | H39: =SUMIFS(_CALC_ALLOC!$AL$1:$AL$349,_CALC_ALLOC!$A$1:$A$349,"2026",_CALC_ALLOC!$B$1:$B$349,"MBWAY_BOR",_CALC_ALLOC!$D$1:$D$349,"BAC_MGT",_CALC_ALLOC!$E$1:$E$349,"B2",_CALC_ALLOC!$F$1:$F$349,"ALT") -> 0 | I39: =SUMIFS(_CALC_ALLOC!$AR$1:$AR$349,_CALC_ALLOC!$A$1:$A$349,"2026",_CALC_ALLOC!$B$1:$B$349,"MBWAY_BOR",_CALC_ALLOC!$D$1:$D$349,"BAC_MGT",_CALC_ALLOC!$E$1:$E$349,"B2",_CALC_ALLOC!$F$1:$F$349,"ALT") -> 0 | J39: =SUMIFS(_CALC_ALLOC!$AM$1:$AM$349,_CALC_ALLOC!$A$1:$A$349,"2026",_CALC_ALLOC!$B$1:$B$349,"MBWAY_BOR",_CALC_ALLOC!$D$1:$D$349,"BAC_MGT",_CALC_ALLOC!$E$1:$E$349,"B2",_CALC_ALLOC!$F$1:$F$349,"ALT") -> 0 | K39: =E39+F39+G39+H39+I39+J39 -> 0 | L39: =SUMIFS(_CALC_ALLOC!$AN$1:$AN$349,_CALC_ALLOC!$A$1:$A$349,"2026",_CALC_ALLOC!$B$1:$B$349,"MBWAY_BOR",_CALC_ALLOC!$D$1:$D$349,"BAC_MGT",_CALC_ALLOC!$E$1:$E$349,"B2",_CALC_ALLOC!$F$1:$F$349,"ALT") -> 0 | M39: =IFERROR(L39/D39,0) -> 0
B40: BAC_MGT B3 ALT | C40: =SUMIFS(_CALC_ALLOC!$G$1:$G$349,_CALC_ALLOC!$A$1:$A$349,"2026",_CALC_ALLOC!$B$1:$B$349,"MBWAY_BOR",_CALC_ALLOC!$D$1:$D$349,"BAC_MGT",_CALC_ALLOC!$E$1:$E$349,"B3",_CALC_ALLOC!$F$1:$F$349,"ALT") -> 0 | D40: =SUMIFS(_CALC_ALLOC!$I$1:$I$349,_CALC_ALLOC!$A$1:$A$349,"2026",_CALC_ALLOC!$B$1:$B$349,"MBWAY_BOR",_CALC_ALLOC!$D$1:$D$349,"BAC_MGT",_CALC_ALLOC!$E$1:$E$349,"B3",_CALC_ALLOC!$F$1:$F$349,"ALT") -> 0 | E40: =SUMIFS(_CALC_ALLOC!$AI$1:$AI$349,_CALC_ALLOC!$A$1:$A$349,"2026",_CALC_ALLOC!$B$1:$B$349,"MBWAY_BOR",_CALC_ALLOC!$D$1:$D$349,"BAC_MGT",_CALC_ALLOC!$E$1:$E$349,"B3",_CALC_ALLOC!$F$1:$F$349,"ALT") -> 0 | F40: =SUMIFS(_CALC_ALLOC!$AJ$1:$AJ$349,_CALC_ALLOC!$A$1:$A$349,"2026",_CALC_ALLOC!$B$1:$B$349,"MBWAY_BOR",_CALC_ALLOC!$D$1:$D$349,"BAC_MGT",_CALC_ALLOC!$E$1:$E$349,"B3",_CALC_ALLOC!$F$1:$F$349,"ALT") -> 0 | G40: =SUMIFS(_CALC_ALLOC!$AK$1:$AK$349,_CALC_ALLOC!$A$1:$A$349,"2026",_CALC_ALLOC!$B$1:$B$349,"MBWAY_BOR",_CALC_ALLOC!$D$1:$D$349,"BAC_MGT",_CALC_ALLOC!$E$1:$E$349,"B3",_CALC_ALLOC!$F$1:$F$349,"ALT") -> 0 | H40: =SUMIFS(_CALC_ALLOC!$AL$1:$AL$349,_CALC_ALLOC!$A$1:$A$349,"2026",_CALC_ALLOC!$B$1:$B$349,"MBWAY_BOR",_CALC_ALLOC!$D$1:$D$349,"BAC_MGT",_CALC_ALLOC!$E$1:$E$349,"B3",_CALC_ALLOC!$F$1:$F$349,"ALT") -> 0 | I40: =SUMIFS(_CALC_ALLOC!$AR$1:$AR$349,_CALC_ALLOC!$A$1:$A$349,"2026",_CALC_ALLOC!$B$1:$B$349,"MBWAY_BOR",_CALC_ALLOC!$D$1:$D$349,"BAC_MGT",_CALC_ALLOC!$E$1:$E$349,"B3",_CALC_ALLOC!$F$1:$F$349,"ALT") -> 0 | J40: =SUMIFS(_CALC_ALLOC!$AM$1:$AM$349,_CALC_ALLOC!$A$1:$A$349,"2026",_CALC_ALLOC!$B$1:$B$349,"MBWAY_BOR",_CALC_ALLOC!$D$1:$D$349,"BAC_MGT",_CALC_ALLOC!$E$1:$E$349,"B3",_CALC_ALLOC!$F$1:$F$349,"ALT") -> 0 | K40: =E40+F40+G40+H40+I40+J40 -> 0 | L40: =SUMIFS(_CALC_ALLOC!$AN$1:$AN$349,_CALC_ALLOC!$A$1:$A$349,"2026",_CALC_ALLOC!$B$1:$B$349,"MBWAY_BOR",_CALC_ALLOC!$D$1:$D$349,"BAC_MGT",_CALC_ALLOC!$E$1:$E$349,"B3",_CALC_ALLOC!$F$1:$F$349,"ALT") -> 0 | M40: =IFERROR(L40/D40,0) -> 0
