Workbook
Name ALLOC_BRAND_CAMP: Allocation!$C$8
Name ALLOC_CAMP_CLASS: Allocation!$C$9
Name ALLOC_GRP_BRAND: Allocation!$C$6
Name ALLOC_GRP_MARQUE: Allocation!$C$7

Sheet Allocation
N1: =IF($C$6="Chiffre d'affaires","REV_CA",IF($C$6="Nombre de classes","VOL_CLASS","VOL_EFF")) -> VOL_EFF | P1: =IF($C$12="Optimiste","V02",IF($C$12="Prudent","V03","V01")) -> V02 | BF1: SCENARIO | BG1: VERSION | BH1: PERIODE | BI1: EXERCICE | BJ1: ENTITY | BK1: MARQUE | BL1: PROGRAMME | BM1: AN_ETUDE | BN1: MODALITE | BO1: VOL_EFF | BP1: VOL_CLASS | BQ1: CA | BR1: COST_VAC | BS1: COST_PERM | BT1: COST_ODIR | BU1: COST_STRUCT | BV1: COST_MARQUE | BW1: COST_HOLDING | BX1: COST_SIEGE | BY1: COST_VARIABLE | BZ1: COST_STRUCTURE | CA1: COST_COMPLET | CB1: MARGE_COMPLETE | CC1: VOL_NEW | CD1: POOL_VAC | CE1: POOL_PERM | CF1: POOL_ODIR | CG1: POOL_MKT | CH1: POOL_STRUCT | CI1: POOL_HOLDING | CJ1: POOL_FRAIS_MARQUE
D2: Allocation & RENTABILITE - Coût complet du groupe à la classe | N2: =IF($C$7="Chiffre d'affaires","REV_CA",IF($C$7="Nombre de classes","VOL_CLASS","VOL_EFF")) -> REV_CA | BF2: 2027BUD_V1 | BG2: ACT | BH2: 12 | BI2: 2024 | BJ2: IPAC_MTP | BK2: IPAC | BL2: BAC_CCE | BM2: B1 | BN2: ALT | BO2: 36 | BP2: 2 | BQ2: 242640 | BR2: 22035.978 | BS2: 42519.027 | BT2: 26165.051 | BU2: 85770.028 | BV2: 5796.892 | BW2: 33312.214 | BX2: 39109.106 | BY2: 48201.029 | BZ2: 167398.16 | CA2: 215599.19 | CB2: 27040.809 | CC2: 36 | CD2: 66108 | CE2: 127557.21 | CF2: 39731 | CG2: 12543 | CH2: 257310.34 | CI2: 2639292 | CJ2: 499926
N3: =IF($C$8="Chiffre d'affaires","REV_CA",IF($C$8="Nombre de classes","VOL_CLASS","VOL_EFF")) -> VOL_EFF | BF3: 2027BUD_V1 | BG3: ACT | BH3: 12 | BI3: 2024 | BJ3: IPAC_MTP | BK3: IPAC | BL3: BAC_CCE | BM3: B2 | BN3: ALT | BO3: 35 | BP3: 2 | BQ3: 232750 | BR3: 22035.978 | BS3: 42519.027 | BT3: 13243.653 | BU3: 85770.028 | BV3: 5796.892 | BW3: 33312.214 | BX3: 39109.106 | BY3: 35279.631 | BZ3: 167398.16 | CA3: 202677.79 | CB3: 30072.207 | CC3: 0 | CD3: 66108 | CE3: 127557.21 | CF3: 39731 | CG3: 12543 | CH3: 257310.34 | CI3: 2639292 | CJ3: 499926
E4: Scénario | F4: Frais de structure campus | G4: Frais de marque | H4: Holding | I4: Total alloué | N4: =IF($C$9="Chiffre d'affaires","REV_CA",IF($C$9="Nombre de classes","VOL_CLASS","VOL_EFF")) -> VOL_CLASS | BF4: 2027BUD_V1 | BG4: ACT | BH4: 12 | BI4: 2024 | BJ4: IPAC_MTP | BK4: IPAC | BL4: BAC_CCE | BM4: B3 | BN4: ALT | BO4: 34 | BP4: 2 | BQ4: 226100 | BR4: 22035.978 | BS4: 42519.027 | BT4: 12865.255 | BU4: 85770.028 | BV4: 5796.892 | BW4: 33312.214 | BX4: 39109.106 | BY4: 34901.233 | BZ4: 167398.16 | CA4: 202299.39 | CB4: 23800.605 | CC4: 0 | CD4: 66108 | CE4: 127557.21 | CF4: 39731 | CG4: 12543 | CH4: 257310.34 | CI4: 2639292 | CJ4: 499926
B5: Cles d'Allocation | E5: Cadrage | F5: 9045300.6 | G5: 743978.4 | H5: 2975861.6 | I5: 12765141 | BF5: 2027BUD_V1 | BG5: ACT | BH5: 12 | BI5: 2024 | BJ5: IPAC_NAN | BK5: IPAC | BL5: BAC_CCE | BM5: B1 | BN5: ALT | BO5: 44 | BP5: 2 | BQ5: 311960 | BR5: 22035.978 | BS5: 51911.148 | BT5: 34778.025 | BU5: 120276.53 | BV5: 7121.8895 | BW5: 40926.398 | BX5: 48048.287 | BY5: 56814.003 | BZ5: 220235.97 | CA5: 277049.97 | CB5: 34910.028 | CC5: 44 | CD5: 66108 | CE5: 155733.6 | CF5: 49240 | CG5: 17983 | CH5: 360829.96 | CI5: 2639292 | CJ5: 499926
B6: Clé d’allocation siège administratif → marque | C6: Effectif | E6: Optimiste | F6: 8810446.7 | G6: 777795.6 | H6: 2894010 | I6: 12482252 | BF6: 2027BUD_V1 | BG6: ACT | BH6: 12 | BI6: 2024 | BJ6: IPAC_NAN | BK6: IPAC | BL6: BAC_CCE | BM6: B2 | BN6: ALT | BO6: 43 | BP6: 2 | BQ6: 301000 | BR6: 22035.978 | BS6: 51911.148 | BT6: 16413.317 | BU6: 120276.53 | BV6: 7121.8895 | BW6: 40926.398 | BX6: 48048.287 | BY6: 38449.295 | BZ6: 220235.97 | CA6: 258685.26 | CB6: 42314.737 | CC6: 0 | CD6: 66108 | CE6: 155733.6 | CF6: 49240 | CG6: 17983 | CH6: 360829.96 | CI6: 2639292 | CJ6: 499926
B7: Clé d’allocation Pub de marque → marque | C7: Chiffre d'affaires | E7: Prudent | F7: 9361926.3 | G7: 642526.8 | H7: 3092074.3 | I7: 13096527 | BF7: 2027BUD_V1 | BG7: ACT | BH7: 12 | BI7: 2024 | BJ7: IPAC_NAN | BK7: IPAC | BL7: BAC_CCE | BM7: B3 | BN7: ALT | BO7: 42 | BP7: 2 | BQ7: 294000 | BR7: 22035.978 | BS7: 51911.148 | BT7: 16031.608 | BU7: 120276.53 | BV7: 7121.8895 | BW7: 40926.398 | BX7: 48048.287 | BY7: 38067.586 | BZ7: 220235.97 | CA7: 258303.55 | CB7: 35696.445 | CC7: 0 | CD7: 66108 | CE7: 155733.6 | CF7: 49240 | CG7: 17983 | CH7: 360829.96 | CI7: 2639292 | CJ7: 499926
B8: Clé d’allocation Marque → Campus | C8: Effectif | BF8: 2027BUD_V1 | BG8: ACT | BH8: 12 | BI8: 2024 | BJ8: IPAC_REN | BK8: IPAC | BL8: BAC_CCE | BM8: B1 | BN8: ALT | BO8: 36 | BP8: 2 | BQ8: 242640 | BR8: 22035.978 | BS8: 42541.344 | BT8: 25963.051 | BU8: 85815.041 | BV8: 5796.892 | BW8: 33312.214 | BX8: 39109.106 | BY8: 47999.029 | BZ8: 167465.49 | CA8: 215464.52 | CB8: 27175.479 | CC8: 36 | CD8: 66108 | CE8: 127624.16 | CF8: 39731 | CG8: 12341 | CH8: 257445.38 | CI8: 2639292 | CJ8: 499926
B9: Clé d’allocation Campus → Classe | C9: Nombre de classes | BF9: 2027BUD_V1 | BG9: ACT | BH9: 12 | BI9: 2024 | BJ9: IPAC_REN | BK9: IPAC | BL9: BAC_CCE | BM9: B2 | BN9: ALT | BO9: 35 | BP9: 2 | BQ9: 232750 | BR9: 22035.978 | BS9: 42541.344 | BT9: 13243.653 | BU9: 85815.041 | BV9: 5796.892 | BW9: 33312.214 | BX9: 39109.106 | BY9: 35279.631 | BZ9: 167465.49 | CA9: 202745.12 | CB9: 30004.877 | CC9: 0 | CD9: 66108 | CE9: 127624.16 | CF9: 39731 | CG9: 12341 | CH9: 257445.38 | CI9: 2639292 | CJ9: 499926
BF10: 2027BUD_V1 | BG10: ACT | BH10: 12 | BI10: 2024 | BJ10: IPAC_REN | BK10: IPAC | BL10: BAC_CCE | BM10: B3 | BN10: ALT | BO10: 34 | BP10: 2 | BQ10: 226100 | BR10: 22035.978 | BS10: 42541.344 | BT10: 12865.255 | BU10: 85815.041 | BV10: 5796.892 | BW10: 33312.214 | BX10: 39109.106 | BY10: 34901.233 | BZ10: 167465.49 | CA10: 202366.72 | CB10: 23733.275 | CC10: 0 | CD10: 66108 | CE10: 127624.16 | CF10: 39731 | CG10: 12341 | CH10: 257445.38 | CI10: 2639292 | CJ10: 499926
BF11: 2027BUD_V1 | BG11: ACT | BH11: 12 | BI11: 2024 | BJ11: ISCOM_LIL | BK11: ISCOM | BL11: BAC_COM | BM11: B1 | BN11: INIT | BO11: 44 | BP11: 2 | BQ11: 327360 | BR11: 27545 | BS11: 64855.365 | BT11: 27222.12 | BU11: 120992.63 | BV11: 8006.1197 | BW11: 41307.198 | BX11: 49313.318 | BY11: 54767.12 | BZ11: 235161.32 | CA11: 289928.43 | CB11: 37431.565 | CC11: 44 | CD11: 110180 | CE11: 259421.46 | CF11: 82858 | CG11: 20843 | CH11: 604963.16 | CI11: 2639292 | CJ11: 499926
B12: Version budget restituée | C12: Optimiste | D12: ="version "&$P$1&" · "&TEXT(COUNTIF(_CALC_ALLOC!$AS$1:$AS$420,"2027|"&$P$1),"0")&" classes lues sur 60" | BF12: 2027BUD_V1 | BG12: ACT | BH12: 12 | BI12: 2024 | BJ12: ISCOM_LIL | BK12: ISCOM | BL12: BAC_COM | BM12: B2 | BN12: ALT | BO12: 43 | BP12: 2 | BQ12: 294980 | BR12: 22036 | BS12: 51884.292 | BT12: 16418.81 | BU12: 120992.63 | BV12: 8006.1197 | BW12: 41307.198 | BX12: 49313.318 | BY12: 38454.81 | BZ12: 222190.24 | CA12: 260645.05 | CB12: 34334.948 | CC12: 0 | CD12: 110180 | CE12: 259421.46 | CF12: 82858 | CG12: 20843 | CH12: 604963.16 | CI12: 2639292 | CJ12: 499926
BF13: 2027BUD_V1 | BG13: ACT | BH13: 12 | BI13: 2024 | BJ13: ISCOM_LIL | BK13: ISCOM | BL13: BAC_COM | BM13: B3 | BN13: ALT | BO13: 42 | BP13: 2 | BQ13: 288120 | BR13: 22036 | BS13: 51884.292 | BT13: 16037 | BU13: 120992.63 | BV13: 8006.1197 | BW13: 41307.198 | BX13: 49313.318 | BY13: 38073 | BZ13: 222190.24 | CA13: 260263.24 | CB13: 27856.758 | CC13: 0 | CD13: 110180 | CE13: 259421.46 | CF13: 82858 | CG13: 20843 | CH13: 604963.16 | CI13: 2639292 | CJ13: 499926
B14: Maille fine — deplie campus/classe avec les [+] | BF14: 2027BUD_V1 | BG14: ACT | BH14: 12 | BI14: 2024 | BJ14: ISCOM_LIL | BK14: ISCOM | BL14: MAS_COM | BM14: M1 | BN14: ALT | BO14: 44 | BP14: 2 | BQ14: 327360 | BR14: 19281.5 | BS14: 45398.755 | BT14: 27222.12 | BU14: 120992.63 | BV14: 8006.1197 | BW14: 41307.198 | BX14: 49313.318 | BY14: 46503.62 | BZ14: 215704.71 | CA14: 262208.33 | CB14: 65151.675 | CC14: 44 | CD14: 110180 | CE14: 259421.46 | CF14: 82858 | CG14: 20843 | CH14: 604963.16 | CI14: 2639292 | CJ14: 499926
BF15: 2027BUD_V1 | BG15: ACT | BH15: 12 | BI15: 2024 | BJ15: ISCOM_LIL | BK15: ISCOM | BL15: MAS_COM | BM15: M2 | BN15: ALT | BO15: 44 | BP15: 2 | BQ15: 323400 | BR15: 19281.5 | BS15: 45398.755 | BT15: 16800.62 | BU15: 120992.63 | BV15: 8006.1197 | BW15: 41307.198 | BX15: 49313.318 | BY15: 36082.12 | BZ15: 215704.71 | CA15: 251786.83 | CB15: 71613.175 | CC15: 0 | CD15: 110180 | CE15: 259421.46 | CF15: 82858 | CG15: 20843 | CH15: 604963.16 | CI15: 2639292 | CJ15: 499926
BF16: 2027BUD_V1 | BG16: ACT | BH16: 12 | BI16: 2024 | BJ16: ISCOM_PAR | BK16: ISCOM | BL16: BAC_COM | BM16: B1 | BN16: INIT | BO16: 64 | BP16: 3 | BQ16: 543360 | BR16: 41317.75 | BS16: 110892.23 | BT16: 49625.73 | BU16: 202318.32 | BV16: 11584.913 | BW16: 59771.812 | BX16: 71356.724 | BY16: 90943.48 | BZ16: 384567.28 | CA16: 475510.76 | CB16: 67849.239 | CC16: 64 | CD16: 165271 | CE16: 443568.93 | CF16: 120212 | CG16: 50248 | CH16: 1011591.6 | CI16: 2639292 | CJ16: 499926
B17: Marque ▸ Campus ▸ Classe | C17: Effectif | D17: CA | E17: VAC | F17: PERM | G17: ODIR | H17: STRUCT | I17: Frais marque | J17: Holding | K17: Cout complet | L17: Marge complete | M17: Marge % | BF17: 2027BUD_V1 | BG17: ACT | BH17: 12 | BI17: 2024 | BJ17: ISCOM_PAR | BK17: ISCOM | BL17: BAC_COM | BM17: B2 | BN17: ALT | BO17: 62 | BP17: 3 | BQ17: 486080 | BR17: 33054.2 | BS17: 88713.786 | BT17: 23736.1 | BU17: 202318.32 | BV17: 11584.913 | BW17: 59771.812 | BX17: 71356.724 | BY17: 56790.3 | BZ17: 362388.83 | CA17: 419179.13 | CB17: 66900.866 | CC17: 0 | CD17: 165271 | CE17: 443568.93 | CF17: 120212 | CG17: 50248 | CH17: 1011591.6 | CI17: 2639292 | CJ17: 499926
B18: MBway | C18: =SUMIFS(_CALC_ALLOC!$G$1:$G$420,_CALC_ALLOC!$AS$1:$AS$420,"2027|"&$P$1,_CALC_ALLOC!$C$1:$C$420,$V18) -> 0 | D18: =SUMIFS(_CALC_ALLOC!$I$1:$I$420,_CALC_ALLOC!$AS$1:$AS$420,"2027|"&$P$1,_CALC_ALLOC!$C$1:$C$420,$V18) -> 0 | E18: =SUMIFS(_CALC_ALLOC!$AI$1:$AI$420,_CALC_ALLOC!$AS$1:$AS$420,"2027|"&$P$1,_CALC_ALLOC!$C$1:$C$420,$V18) -> 0 | F18: =SUMIFS(_CALC_ALLOC!$AJ$1:$AJ$420,_CALC_ALLOC!$AS$1:$AS$420,"2027|"&$P$1,_CALC_ALLOC!$C$1:$C$420,$V18) -> 0 | G18: =SUMIFS(_CALC_ALLOC!$AK$1:$AK$420,_CALC_ALLOC!$AS$1:$AS$420,"2027|"&$P$1,_CALC_ALLOC!$C$1:$C$420,$V18) -> 0 | H18: =SUMIFS(_CALC_ALLOC!$AL$1:$AL$420,_CALC_ALLOC!$AS$1:$AS$420,"2027|"&$P$1,_CALC_ALLOC!$C$1:$C$420,$V18) -> 0 | I18: =SUMIFS(_CALC_ALLOC!$AR$1:$AR$420,_CALC_ALLOC!$AS$1:$AS$420,"2027|"&$P$1,_CALC_ALLOC!$C$1:$C$420,$V18) -> 0 | J18: =SUMIFS(_CALC_ALLOC!$AM$1:$AM$420,_CALC_ALLOC!$AS$1:$AS$420,"2027|"&$P$1,_CALC_ALLOC!$C$1:$C$420,$V18) -> 0 | K18: =E18+F18+G18+H18+I18+J18 -> 0 | L18: =SUMIFS(_CALC_ALLOC!$AN$1:$AN$420,_CALC_ALLOC!$AS$1:$AS$420,"2027|"&$P$1,_CALC_ALLOC!$C$1:$C$420,$V18) -> 0 | M18: =IF(D18=0,0,L18/D18) -> 0 | T18: MBWAY | V18: MBWAY | Z18: 1 | BF18: 2027BUD_V1 | BG18: ACT | BH18: 12 | BI18: 2024 | BJ18: ISCOM_PAR | BK18: ISCOM | BL18: BAC_COM | BM18: B3 | BN18: ALT | BO18: 61 | BP18: 3 | BQ18: 478240 | BR18: 33054.2 | BS18: 88713.786 | BT18: 23353.225 | BU18: 202318.32 | BV18: 11584.913 | BW18: 59771.812 | BX18: 71356.724 | BY18: 56407.425 | BZ18: 362388.83 | CA18: 418796.26 | CB18: 59443.741 | CC18: 0 | CD18: 165271 | CE18: 443568.93 | CF18: 120212 | CG18: 50248 | CH18: 1011591.6 | CI18: 2639292 | CJ18: 499926
B19: Paris | C19: =SUMIFS(_CALC_ALLOC!$G$1:$G$420,_CALC_ALLOC!$AS$1:$AS$420,"2027|"&$P$1,_CALC_ALLOC!$B$1:$B$420,$U19) -> 0 | D19: =SUMIFS(_CALC_ALLOC!$I$1:$I$420,_CALC_ALLOC!$AS$1:$AS$420,"2027|"&$P$1,_CALC_ALLOC!$B$1:$B$420,$U19) -> 0 | E19: =SUMIFS(_CALC_ALLOC!$AI$1:$AI$420,_CALC_ALLOC!$AS$1:$AS$420,"2027|"&$P$1,_CALC_ALLOC!$B$1:$B$420,$U19) -> 0 | F19: =SUMIFS(_CALC_ALLOC!$AJ$1:$AJ$420,_CALC_ALLOC!$AS$1:$AS$420,"2027|"&$P$1,_CALC_ALLOC!$B$1:$B$420,$U19) -> 0 | G19: =SUMIFS(_CALC_ALLOC!$AK$1:$AK$420,_CALC_ALLOC!$AS$1:$AS$420,"2027|"&$P$1,_CALC_ALLOC!$B$1:$B$420,$U19) -> 0 | H19: =SUMIFS(_CALC_ALLOC!$AL$1:$AL$420,_CALC_ALLOC!$AS$1:$AS$420,"2027|"&$P$1,_CALC_ALLOC!$B$1:$B$420,$U19) -> 0 | I19: =SUMIFS(_CALC_ALLOC!$AR$1:$AR$420,_CALC_ALLOC!$AS$1:$AS$420,"2027|"&$P$1,_CALC_ALLOC!$B$1:$B$420,$U19) -> 0 | J19: =SUMIFS(_CALC_ALLOC!$AM$1:$AM$420,_CALC_ALLOC!$AS$1:$AS$420,"2027|"&$P$1,_CALC_ALLOC!$B$1:$B$420,$U19) -> 0 | K19: =E19+F19+G19+H19+I19+J19 -> 0 | L19: =SUMIFS(_CALC_ALLOC!$AN$1:$AN$420,_CALC_ALLOC!$AS$1:$AS$420,"2027|"&$P$1,_CALC_ALLOC!$B$1:$B$420,$U19) -> 0 | M19: =IF(D19=0,0,L19/D19) -> 0 | T19: MBWAY_PAR | U19: MBWAY_PAR | V19: MBWAY | Z19: 2 | BF19: 2027BUD_V1 | BG19: ACT | BH19: 12 | BI19: 2024 | BJ19: ISCOM_PAR | BK19: ISCOM | BL19: MAS_COM | BM19: M1 | BN19: ALT | BO19: 64 | BP19: 3 | BQ19: 543360 | BR19: 28922.425 | BS19: 77624.563 | BT19: 49625.73 | BU19: 202318.32 | BV19: 11584.913 | BW19: 59771.812 | BX19: 71356.724 | BY19: 78548.155 | BZ19: 351299.61 | CA19: 429847.77 | CB19: 113512.23 | CC19: 64 | CD19: 165271 | CE19: 443568.93 | CF19: 120212 | CG19: 50248 | CH19: 1011591.6 | CI19: 2639292 | CJ19: 499926
B20: Bachelor Management, 1re année, initial | C20: =SUMIFS(_CALC_ALLOC!$G$1:$G$420,_CALC_ALLOC!$AS$1:$AS$420,"2027|"&$P$1,_CALC_ALLOC!$B$1:$B$420,$U20,_CALC_ALLOC!$D$1:$D$420,$W20,_CALC_ALLOC!$E$1:$E$420,$X20,_CALC_ALLOC!$F$1:$F$420,$Y20) -> 0 | D20: =SUMIFS(_CALC_ALLOC!$I$1:$I$420,_CALC_ALLOC!$AS$1:$AS$420,"2027|"&$P$1,_CALC_ALLOC!$B$1:$B$420,$U20,_CALC_ALLOC!$D$1:$D$420,$W20,_CALC_ALLOC!$E$1:$E$420,$X20,_CALC_ALLOC!$F$1:$F$420,$Y20) -> 0 | E20: =SUMIFS(_CALC_ALLOC!$AI$1:$AI$420,_CALC_ALLOC!$AS$1:$AS$420,"2027|"&$P$1,_CALC_ALLOC!$B$1:$B$420,$U20,_CALC_ALLOC!$D$1:$D$420,$W20,_CALC_ALLOC!$E$1:$E$420,$X20,_CALC_ALLOC!$F$1:$F$420,$Y20) -> 0 | F20: =SUMIFS(_CALC_ALLOC!$AJ$1:$AJ$420,_CALC_ALLOC!$AS$1:$AS$420,"2027|"&$P$1,_CALC_ALLOC!$B$1:$B$420,$U20,_CALC_ALLOC!$D$1:$D$420,$W20,_CALC_ALLOC!$E$1:$E$420,$X20,_CALC_ALLOC!$F$1:$F$420,$Y20) -> 0 | G20: =SUMIFS(_CALC_ALLOC!$AK$1:$AK$420,_CALC_ALLOC!$AS$1:$AS$420,"2027|"&$P$1,_CALC_ALLOC!$B$1:$B$420,$U20,_CALC_ALLOC!$D$1:$D$420,$W20,_CALC_ALLOC!$E$1:$E$420,$X20,_CALC_ALLOC!$F$1:$F$420,$Y20) -> 0 | H20: =SUMIFS(_CALC_ALLOC!$AL$1:$AL$420,_CALC_ALLOC!$AS$1:$AS$420,"2027|"&$P$1,_CALC_ALLOC!$B$1:$B$420,$U20,_CALC_ALLOC!$D$1:$D$420,$W20,_CALC_ALLOC!$E$1:$E$420,$X20,_CALC_ALLOC!$F$1:$F$420,$Y20) -> 0 | I20: =SUMIFS(_CALC_ALLOC!$AR$1:$AR$420,_CALC_ALLOC!$AS$1:$AS$420,"2027|"&$P$1,_CALC_ALLOC!$B$1:$B$420,$U20,_CALC_ALLOC!$D$1:$D$420,$W20,_CALC_ALLOC!$E$1:$E$420,$X20,_CALC_ALLOC!$F$1:$F$420,$Y20) -> 0 | J20: =SUMIFS(_CALC_ALLOC!$AM$1:$AM$420,_CALC_ALLOC!$AS$1:$AS$420,"2027|"&$P$1,_CALC_ALLOC!$B$1:$B$420,$U20,_CALC_ALLOC!$D$1:$D$420,$W20,_CALC_ALLOC!$E$1:$E$420,$X20,_CALC_ALLOC!$F$1:$F$420,$Y20) -> 0 | K20: =E20+F20+G20+H20+I20+J20 -> 0 | L20: =SUMIFS(_CALC_ALLOC!$AN$1:$AN$420,_CALC_ALLOC!$AS$1:$AS$420,"2027|"&$P$1,_CALC_ALLOC!$B$1:$B$420,$U20,_CALC_ALLOC!$D$1:$D$420,$W20,_CALC_ALLOC!$E$1:$E$420,$X20,_CALC_ALLOC!$F$1:$F$420,$Y20) -> 0 | M20: =IF(D20=0,0,L20/D20) -> 0 | T20: MBWAY_PAR|BAC_MGT|B1|INIT | U20: MBWAY_PAR | V20: MBWAY | W20: BAC_MGT | X20: B1 | Y20: INIT | Z20: 3 | BF20: 2027BUD_V1 | BG20: ACT | BH20: 12 | BI20: 2024 | BJ20: ISCOM_PAR | BK20: ISCOM | BL20: MAS_COM | BM20: M2 | BN20: ALT | BO20: 63 | BP20: 3 | BQ20: 529200 | BR20: 28922.425 | BS20: 77624.563 | BT20: 24118.855 | BU20: 202318.32 | BV20: 11584.913 | BW20: 59771.812 | BX20: 71356.724 | BY20: 53041.28 | BZ20: 351299.61 | CA20: 404340.89 | CB20: 124859.11 | CC20: 0 | CD20: 165271 | CE20: 443568.93 | CF20: 120212 | CG20: 50248 | CH20: 1011591.6 | CI20: 2639292 | CJ20: 499926
B21: Bachelor Management, 2e année, alternance | C21: =SUMIFS(_CALC_ALLOC!$G$1:$G$420,_CALC_ALLOC!$AS$1:$AS$420,"2027|"&$P$1,_CALC_ALLOC!$B$1:$B$420,$U21,_CALC_ALLOC!$D$1:$D$420,$W21,_CALC_ALLOC!$E$1:$E$420,$X21,_CALC_ALLOC!$F$1:$F$420,$Y21) -> 0 | D21: =SUMIFS(_CALC_ALLOC!$I$1:$I$420,_CALC_ALLOC!$AS$1:$AS$420,"2027|"&$P$1,_CALC_ALLOC!$B$1:$B$420,$U21,_CALC_ALLOC!$D$1:$D$420,$W21,_CALC_ALLOC!$E$1:$E$420,$X21,_CALC_ALLOC!$F$1:$F$420,$Y21) -> 0 | E21: =SUMIFS(_CALC_ALLOC!$AI$1:$AI$420,_CALC_ALLOC!$AS$1:$AS$420,"2027|"&$P$1,_CALC_ALLOC!$B$1:$B$420,$U21,_CALC_ALLOC!$D$1:$D$420,$W21,_CALC_ALLOC!$E$1:$E$420,$X21,_CALC_ALLOC!$F$1:$F$420,$Y21) -> 0 | F21: =SUMIFS(_CALC_ALLOC!$AJ$1:$AJ$420,_CALC_ALLOC!$AS$1:$AS$420,"2027|"&$P$1,_CALC_ALLOC!$B$1:$B$420,$U21,_CALC_ALLOC!$D$1:$D$420,$W21,_CALC_ALLOC!$E$1:$E$420,$X21,_CALC_ALLOC!$F$1:$F$420,$Y21) -> 0 | G21: =SUMIFS(_CALC_ALLOC!$AK$1:$AK$420,_CALC_ALLOC!$AS$1:$AS$420,"2027|"&$P$1,_CALC_ALLOC!$B$1:$B$420,$U21,_CALC_ALLOC!$D$1:$D$420,$W21,_CALC_ALLOC!$E$1:$E$420,$X21,_CALC_ALLOC!$F$1:$F$420,$Y21) -> 0 | H21: =SUMIFS(_CALC_ALLOC!$AL$1:$AL$420,_CALC_ALLOC!$AS$1:$AS$420,"2027|"&$P$1,_CALC_ALLOC!$B$1:$B$420,$U21,_CALC_ALLOC!$D$1:$D$420,$W21,_CALC_ALLOC!$E$1:$E$420,$X21,_CALC_ALLOC!$F$1:$F$420,$Y21) -> 0 | I21: =SUMIFS(_CALC_ALLOC!$AR$1:$AR$420,_CALC_ALLOC!$AS$1:$AS$420,"2027|"&$P$1,_CALC_ALLOC!$B$1:$B$420,$U21,_CALC_ALLOC!$D$1:$D$420,$W21,_CALC_ALLOC!$E$1:$E$420,$X21,_CALC_ALLOC!$F$1:$F$420,$Y21) -> 0 | J21: =SUMIFS(_CALC_ALLOC!$AM$1:$AM$420,_CALC_ALLOC!$AS$1:$AS$420,"2027|"&$P$1,_CALC_ALLOC!$B$1:$B$420,$U21,_CALC_ALLOC!$D$1:$D$420,$W21,_CALC_ALLOC!$E$1:$E$420,$X21,_CALC_ALLOC!$F$1:$F$420,$Y21) -> 0 | K21: =E21+F21+G21+H21+I21+J21 -> 0 | L21: =SUMIFS(_CALC_ALLOC!$AN$1:$AN$420,_CALC_ALLOC!$AS$1:$AS$420,"2027|"&$P$1,_CALC_ALLOC!$B$1:$B$420,$U21,_CALC_ALLOC!$D$1:$D$420,$W21,_CALC_ALLOC!$E$1:$E$420,$X21,_CALC_ALLOC!$F$1:$F$420,$Y21) -> 0 | M21: =IF(D21=0,0,L21/D21) -> 0 | T21: MBWAY_PAR|BAC_MGT|B2|ALT | U21: MBWAY_PAR | V21: MBWAY | W21: BAC_MGT | X21: B2 | Y21: ALT | Z21: 3 | BF21: 2027BUD_V1 | BG21: ACT | BH21: 12 | BI21: 2024 | BJ21: ISCOM_TLS | BK21: ISCOM | BL21: BAC_COM | BM21: B1 | BN21: INIT | BO21: 42 | BP21: 2 | BQ21: 306180 | BR21: 27545 | BS21: 61223.45 | BT21: 25118.694 | BU21: 110126.31 | BV21: 7600.2884 | BW21: 39213.331 | BX21: 46813.62 | BY21: 52663.694 | BZ21: 218163.38 | CA21: 270827.08 | CB21: 35352.922 | CC21: 42 | CD21: 110180 | CE21: 244893.8 | CF21: 78443 | CG21: 18251 | CH21: 550631.57 | CI21: 2639292 | CJ21: 499926
B22: Bachelor Management, 3e année, alternance | C22: =SUMIFS(_CALC_ALLOC!$G$1:$G$420,_CALC_ALLOC!$AS$1:$AS$420,"2027|"&$P$1,_CALC_ALLOC!$B$1:$B$420,$U22,_CALC_ALLOC!$D$1:$D$420,$W22,_CALC_ALLOC!$E$1:$E$420,$X22,_CALC_ALLOC!$F$1:$F$420,$Y22) -> 0 | D22: =SUMIFS(_CALC_ALLOC!$I$1:$I$420,_CALC_ALLOC!$AS$1:$AS$420,"2027|"&$P$1,_CALC_ALLOC!$B$1:$B$420,$U22,_CALC_ALLOC!$D$1:$D$420,$W22,_CALC_ALLOC!$E$1:$E$420,$X22,_CALC_ALLOC!$F$1:$F$420,$Y22) -> 0 | E22: =SUMIFS(_CALC_ALLOC!$AI$1:$AI$420,_CALC_ALLOC!$AS$1:$AS$420,"2027|"&$P$1,_CALC_ALLOC!$B$1:$B$420,$U22,_CALC_ALLOC!$D$1:$D$420,$W22,_CALC_ALLOC!$E$1:$E$420,$X22,_CALC_ALLOC!$F$1:$F$420,$Y22) -> 0 | F22: =SUMIFS(_CALC_ALLOC!$AJ$1:$AJ$420,_CALC_ALLOC!$AS$1:$AS$420,"2027|"&$P$1,_CALC_ALLOC!$B$1:$B$420,$U22,_CALC_ALLOC!$D$1:$D$420,$W22,_CALC_ALLOC!$E$1:$E$420,$X22,_CALC_ALLOC!$F$1:$F$420,$Y22) -> 0 | G22: =SUMIFS(_CALC_ALLOC!$AK$1:$AK$420,_CALC_ALLOC!$AS$1:$AS$420,"2027|"&$P$1,_CALC_ALLOC!$B$1:$B$420,$U22,_CALC_ALLOC!$D$1:$D$420,$W22,_CALC_ALLOC!$E$1:$E$420,$X22,_CALC_ALLOC!$F$1:$F$420,$Y22) -> 0 | H22: =SUMIFS(_CALC_ALLOC!$AL$1:$AL$420,_CALC_ALLOC!$AS$1:$AS$420,"2027|"&$P$1,_CALC_ALLOC!$B$1:$B$420,$U22,_CALC_ALLOC!$D$1:$D$420,$W22,_CALC_ALLOC!$E$1:$E$420,$X22,_CALC_ALLOC!$F$1:$F$420,$Y22) -> 0 | I22: =SUMIFS(_CALC_ALLOC!$AR$1:$AR$420,_CALC_ALLOC!$AS$1:$AS$420,"2027|"&$P$1,_CALC_ALLOC!$B$1:$B$420,$U22,_CALC_ALLOC!$D$1:$D$420,$W22,_CALC_ALLOC!$E$1:$E$420,$X22,_CALC_ALLOC!$F$1:$F$420,$Y22) -> 0 | J22: =SUMIFS(_CALC_ALLOC!$AM$1:$AM$420,_CALC_ALLOC!$AS$1:$AS$420,"2027|"&$P$1,_CALC_ALLOC!$B$1:$B$420,$U22,_CALC_ALLOC!$D$1:$D$420,$W22,_CALC_ALLOC!$E$1:$E$420,$X22,_CALC_ALLOC!$F$1:$F$420,$Y22) -> 0 | K22: =E22+F22+G22+H22+I22+J22 -> 0 | L22: =SUMIFS(_CALC_ALLOC!$AN$1:$AN$420,_CALC_ALLOC!$AS$1:$AS$420,"2027|"&$P$1,_CALC_ALLOC!$B$1:$B$420,$U22,_CALC_ALLOC!$D$1:$D$420,$W22,_CALC_ALLOC!$E$1:$E$420,$X22,_CALC_ALLOC!$F$1:$F$420,$Y22) -> 0 | M22: =IF(D22=0,0,L22/D22) -> 0 | T22: MBWAY_PAR|BAC_MGT|B3|ALT | U22: MBWAY_PAR | V22: MBWAY | W22: BAC_MGT | X22: B3 | Y22: ALT | Z22: 3 | BF22: 2027BUD_V1 | BG22: ACT | BH22: 12 | BI22: 2024 | BJ22: ISCOM_TLS | BK22: ISCOM | BL22: BAC_COM | BM22: B2 | BN22: ALT | BO22: 41 | BP22: 2 | BQ22: 275520 | BR22: 22036 | BS22: 48978.76 | BT22: 15612.432 | BU22: 110126.31 | BV22: 7600.2884 | BW22: 39213.331 | BX22: 46813.62 | BY22: 37648.432 | BZ22: 205918.69 | CA22: 243567.13 | CB22: 31952.875 | CC22: 0 | CD22: 110180 | CE22: 244893.8 | CF22: 78443 | CG22: 18251 | CH22: 550631.57 | CI22: 2639292 | CJ22: 499926
B23: Mastère Management, 1re année, alternance | C23: =SUMIFS(_CALC_ALLOC!$G$1:$G$420,_CALC_ALLOC!$AS$1:$AS$420,"2027|"&$P$1,_CALC_ALLOC!$B$1:$B$420,$U23,_CALC_ALLOC!$D$1:$D$420,$W23,_CALC_ALLOC!$E$1:$E$420,$X23,_CALC_ALLOC!$F$1:$F$420,$Y23) -> 0 | D23: =SUMIFS(_CALC_ALLOC!$I$1:$I$420,_CALC_ALLOC!$AS$1:$AS$420,"2027|"&$P$1,_CALC_ALLOC!$B$1:$B$420,$U23,_CALC_ALLOC!$D$1:$D$420,$W23,_CALC_ALLOC!$E$1:$E$420,$X23,_CALC_ALLOC!$F$1:$F$420,$Y23) -> 0 | E23: =SUMIFS(_CALC_ALLOC!$AI$1:$AI$420,_CALC_ALLOC!$AS$1:$AS$420,"2027|"&$P$1,_CALC_ALLOC!$B$1:$B$420,$U23,_CALC_ALLOC!$D$1:$D$420,$W23,_CALC_ALLOC!$E$1:$E$420,$X23,_CALC_ALLOC!$F$1:$F$420,$Y23) -> 0 | F23: =SUMIFS(_CALC_ALLOC!$AJ$1:$AJ$420,_CALC_ALLOC!$AS$1:$AS$420,"2027|"&$P$1,_CALC_ALLOC!$B$1:$B$420,$U23,_CALC_ALLOC!$D$1:$D$420,$W23,_CALC_ALLOC!$E$1:$E$420,$X23,_CALC_ALLOC!$F$1:$F$420,$Y23) -> 0 | G23: =SUMIFS(_CALC_ALLOC!$AK$1:$AK$420,_CALC_ALLOC!$AS$1:$AS$420,"2027|"&$P$1,_CALC_ALLOC!$B$1:$B$420,$U23,_CALC_ALLOC!$D$1:$D$420,$W23,_CALC_ALLOC!$E$1:$E$420,$X23,_CALC_ALLOC!$F$1:$F$420,$Y23) -> 0 | H23: =SUMIFS(_CALC_ALLOC!$AL$1:$AL$420,_CALC_ALLOC!$AS$1:$AS$420,"2027|"&$P$1,_CALC_ALLOC!$B$1:$B$420,$U23,_CALC_ALLOC!$D$1:$D$420,$W23,_CALC_ALLOC!$E$1:$E$420,$X23,_CALC_ALLOC!$F$1:$F$420,$Y23) -> 0 | I23: =SUMIFS(_CALC_ALLOC!$AR$1:$AR$420,_CALC_ALLOC!$AS$1:$AS$420,"2027|"&$P$1,_CALC_ALLOC!$B$1:$B$420,$U23,_CALC_ALLOC!$D$1:$D$420,$W23,_CALC_ALLOC!$E$1:$E$420,$X23,_CALC_ALLOC!$F$1:$F$420,$Y23) -> 0 | J23: =SUMIFS(_CALC_ALLOC!$AM$1:$AM$420,_CALC_ALLOC!$AS$1:$AS$420,"2027|"&$P$1,_CALC_ALLOC!$B$1:$B$420,$U23,_CALC_ALLOC!$D$1:$D$420,$W23,_CALC_ALLOC!$E$1:$E$420,$X23,_CALC_ALLOC!$F$1:$F$420,$Y23) -> 0 | K23: =E23+F23+G23+H23+I23+J23 -> 0 | L23: =SUMIFS(_CALC_ALLOC!$AN$1:$AN$420,_CALC_ALLOC!$AS$1:$AS$420,"2027|"&$P$1,_CALC_ALLOC!$B$1:$B$420,$U23,_CALC_ALLOC!$D$1:$D$420,$W23,_CALC_ALLOC!$E$1:$E$420,$X23,_CALC_ALLOC!$F$1:$F$420,$Y23) -> 0 | M23: =IF(D23=0,0,L23/D23) -> 0 | T23: MBWAY_PAR|MAS_MGT|M1|ALT | U23: MBWAY_PAR | V23: MBWAY | W23: MAS_MGT | X23: M1 | Y23: ALT | Z23: 3 | BF23: 2027BUD_V1 | BG23: ACT | BH23: 12 | BI23: 2024 | BJ23: ISCOM_TLS | BK23: ISCOM | BL23: BAC_COM | BM23: B3 | BN23: ALT | BO23: 40 | BP23: 2 | BQ23: 268800 | BR23: 22036 | BS23: 48978.76 | BT23: 15231.591 | BU23: 110126.31 | BV23: 7600.2884 | BW23: 39213.331 | BX23: 46813.62 | BY23: 37267.591 | BZ23: 205918.69 | CA23: 243186.28 | CB23: 25613.715 | CC23: 0 | CD23: 110180 | CE23: 244893.8 | CF23: 78443 | CG23: 18251 | CH23: 550631.57 | CI23: 2639292 | CJ23: 499926
B24: Mastère Management, 2e année, alternance | C24: =SUMIFS(_CALC_ALLOC!$G$1:$G$420,_CALC_ALLOC!$AS$1:$AS$420,"2027|"&$P$1,_CALC_ALLOC!$B$1:$B$420,$U24,_CALC_ALLOC!$D$1:$D$420,$W24,_CALC_ALLOC!$E$1:$E$420,$X24,_CALC_ALLOC!$F$1:$F$420,$Y24) -> 0 | D24: =SUMIFS(_CALC_ALLOC!$I$1:$I$420,_CALC_ALLOC!$AS$1:$AS$420,"2027|"&$P$1,_CALC_ALLOC!$B$1:$B$420,$U24,_CALC_ALLOC!$D$1:$D$420,$W24,_CALC_ALLOC!$E$1:$E$420,$X24,_CALC_ALLOC!$F$1:$F$420,$Y24) -> 0 | E24: =SUMIFS(_CALC_ALLOC!$AI$1:$AI$420,_CALC_ALLOC!$AS$1:$AS$420,"2027|"&$P$1,_CALC_ALLOC!$B$1:$B$420,$U24,_CALC_ALLOC!$D$1:$D$420,$W24,_CALC_ALLOC!$E$1:$E$420,$X24,_CALC_ALLOC!$F$1:$F$420,$Y24) -> 0 | F24: =SUMIFS(_CALC_ALLOC!$AJ$1:$AJ$420,_CALC_ALLOC!$AS$1:$AS$420,"2027|"&$P$1,_CALC_ALLOC!$B$1:$B$420,$U24,_CALC_ALLOC!$D$1:$D$420,$W24,_CALC_ALLOC!$E$1:$E$420,$X24,_CALC_ALLOC!$F$1:$F$420,$Y24) -> 0 | G24: =SUMIFS(_CALC_ALLOC!$AK$1:$AK$420,_CALC_ALLOC!$AS$1:$AS$420,"2027|"&$P$1,_CALC_ALLOC!$B$1:$B$420,$U24,_CALC_ALLOC!$D$1:$D$420,$W24,_CALC_ALLOC!$E$1:$E$420,$X24,_CALC_ALLOC!$F$1:$F$420,$Y24) -> 0 | H24: =SUMIFS(_CALC_ALLOC!$AL$1:$AL$420,_CALC_ALLOC!$AS$1:$AS$420,"2027|"&$P$1,_CALC_ALLOC!$B$1:$B$420,$U24,_CALC_ALLOC!$D$1:$D$420,$W24,_CALC_ALLOC!$E$1:$E$420,$X24,_CALC_ALLOC!$F$1:$F$420,$Y24) -> 0 | I24: =SUMIFS(_CALC_ALLOC!$AR$1:$AR$420,_CALC_ALLOC!$AS$1:$AS$420,"2027|"&$P$1,_CALC_ALLOC!$B$1:$B$420,$U24,_CALC_ALLOC!$D$1:$D$420,$W24,_CALC_ALLOC!$E$1:$E$420,$X24,_CALC_ALLOC!$F$1:$F$420,$Y24) -> 0 | J24: =SUMIFS(_CALC_ALLOC!$AM$1:$AM$420,_CALC_ALLOC!$AS$1:$AS$420,"2027|"&$P$1,_CALC_ALLOC!$B$1:$B$420,$U24,_CALC_ALLOC!$D$1:$D$420,$W24,_CALC_ALLOC!$E$1:$E$420,$X24,_CALC_ALLOC!$F$1:$F$420,$Y24) -> 0 | K24: =E24+F24+G24+H24+I24+J24 -> 0 | L24: =SUMIFS(_CALC_ALLOC!$AN$1:$AN$420,_CALC_ALLOC!$AS$1:$AS$420,"2027|"&$P$1,_CALC_ALLOC!$B$1:$B$420,$U24,_CALC_ALLOC!$D$1:$D$420,$W24,_CALC_ALLOC!$E$1:$E$420,$X24,_CALC_ALLOC!$F$1:$F$420,$Y24) -> 0 | M24: =IF(D24=0,0,L24/D24) -> 0 | T24: MBWAY_PAR|MAS_MGT|M2|ALT | U24: MBWAY_PAR | V24: MBWAY | W24: MAS_MGT | X24: M2 | Y24: ALT | Z24: 3 | BF24: 2027BUD_V1 | BG24: ACT | BH24: 12 | BI24: 2024 | BJ24: ISCOM_TLS | BK24: ISCOM | BL24: MAS_COM | BM24: M1 | BN24: ALT | BO24: 42 | BP24: 2 | BQ24: 306180 | BR24: 19281.5 | BS24: 42856.415 | BT24: 25118.694 | BU24: 110126.31 | BV24: 7600.2884 | BW24: 39213.331 | BX24: 46813.62 | BY24: 44400.194 | BZ24: 199796.35 | CA24: 244196.54 | CB24: 61983.457 | CC24: 42 | CD24: 110180 | CE24: 244893.8 | CF24: 78443 | CG24: 18251 | CH24: 550631.57 | CI24: 2639292 | CJ24: 499926
B25: Lyon | C25: =SUMIFS(_CALC_ALLOC!$G$1:$G$420,_CALC_ALLOC!$AS$1:$AS$420,"2027|"&$P$1,_CALC_ALLOC!$B$1:$B$420,$U25) -> 0 | D25: =SUMIFS(_CALC_ALLOC!$I$1:$I$420,_CALC_ALLOC!$AS$1:$AS$420,"2027|"&$P$1,_CALC_ALLOC!$B$1:$B$420,$U25) -> 0 | E25: =SUMIFS(_CALC_ALLOC!$AI$1:$AI$420,_CALC_ALLOC!$AS$1:$AS$420,"2027|"&$P$1,_CALC_ALLOC!$B$1:$B$420,$U25) -> 0 | F25: =SUMIFS(_CALC_ALLOC!$AJ$1:$AJ$420,_CALC_ALLOC!$AS$1:$AS$420,"2027|"&$P$1,_CALC_ALLOC!$B$1:$B$420,$U25) -> 0 | G25: =SUMIFS(_CALC_ALLOC!$AK$1:$AK$420,_CALC_ALLOC!$AS$1:$AS$420,"2027|"&$P$1,_CALC_ALLOC!$B$1:$B$420,$U25) -> 0 | H25: =SUMIFS(_CALC_ALLOC!$AL$1:$AL$420,_CALC_ALLOC!$AS$1:$AS$420,"2027|"&$P$1,_CALC_ALLOC!$B$1:$B$420,$U25) -> 0 | I25: =SUMIFS(_CALC_ALLOC!$AR$1:$AR$420,_CALC_ALLOC!$AS$1:$AS$420,"2027|"&$P$1,_CALC_ALLOC!$B$1:$B$420,$U25) -> 0 | J25: =SUMIFS(_CALC_ALLOC!$AM$1:$AM$420,_CALC_ALLOC!$AS$1:$AS$420,"2027|"&$P$1,_CALC_ALLOC!$B$1:$B$420,$U25) -> 0 | K25: =E25+F25+G25+H25+I25+J25 -> 0 | L25: =SUMIFS(_CALC_ALLOC!$AN$1:$AN$420,_CALC_ALLOC!$AS$1:$AS$420,"2027|"&$P$1,_CALC_ALLOC!$B$1:$B$420,$U25) -> 0 | M25: =IF(D25=0,0,L25/D25) -> 0 | T25: MBWAY_LYO | U25: MBWAY_LYO | V25: MBWAY | Z25: 2 | BF25: 2027BUD_V1 | BG25: ACT | BH25: 12 | BI25: 2024 | BJ25: ISCOM_TLS | BK25: ISCOM | BL25: MAS_COM | BM25: M2 | BN25: ALT | BO25: 41 | BP25: 2 | BQ25: 295200 | BR25: 19281.5 | BS25: 42856.415 | BT25: 15612.432 | BU25: 110126.31 | BV25: 7600.2884 | BW25: 39213.331 | BX25: 46813.62 | BY25: 34893.932 | BZ25: 199796.35 | CA25: 234690.28 | CB25: 60509.72 | CC25: 0 | CD25: 110180 | CE25: 244893.8 | CF25: 78443 | CG25: 18251 | CH25: 550631.57 | CI25: 2639292 | CJ25: 499926
B26: Bachelor Management, 1re année, initial | C26: =SUMIFS(_CALC_ALLOC!$G$1:$G$420,_CALC_ALLOC!$AS$1:$AS$420,"2027|"&$P$1,_CALC_ALLOC!$B$1:$B$420,$U26,_CALC_ALLOC!$D$1:$D$420,$W26,_CALC_ALLOC!$E$1:$E$420,$X26,_CALC_ALLOC!$F$1:$F$420,$Y26) -> 0 | D26: =SUMIFS(_CALC_ALLOC!$I$1:$I$420,_CALC_ALLOC!$AS$1:$AS$420,"2027|"&$P$1,_CALC_ALLOC!$B$1:$B$420,$U26,_CALC_ALLOC!$D$1:$D$420,$W26,_CALC_ALLOC!$E$1:$E$420,$X26,_CALC_ALLOC!$F$1:$F$420,$Y26) -> 0 | E26: =SUMIFS(_CALC_ALLOC!$AI$1:$AI$420,_CALC_ALLOC!$AS$1:$AS$420,"2027|"&$P$1,_CALC_ALLOC!$B$1:$B$420,$U26,_CALC_ALLOC!$D$1:$D$420,$W26,_CALC_ALLOC!$E$1:$E$420,$X26,_CALC_ALLOC!$F$1:$F$420,$Y26) -> 0 | F26: =SUMIFS(_CALC_ALLOC!$AJ$1:$AJ$420,_CALC_ALLOC!$AS$1:$AS$420,"2027|"&$P$1,_CALC_ALLOC!$B$1:$B$420,$U26,_CALC_ALLOC!$D$1:$D$420,$W26,_CALC_ALLOC!$E$1:$E$420,$X26,_CALC_ALLOC!$F$1:$F$420,$Y26) -> 0 | G26: =SUMIFS(_CALC_ALLOC!$AK$1:$AK$420,_CALC_ALLOC!$AS$1:$AS$420,"2027|"&$P$1,_CALC_ALLOC!$B$1:$B$420,$U26,_CALC_ALLOC!$D$1:$D$420,$W26,_CALC_ALLOC!$E$1:$E$420,$X26,_CALC_ALLOC!$F$1:$F$420,$Y26) -> 0 | H26: =SUMIFS(_CALC_ALLOC!$AL$1:$AL$420,_CALC_ALLOC!$AS$1:$AS$420,"2027|"&$P$1,_CALC_ALLOC!$B$1:$B$420,$U26,_CALC_ALLOC!$D$1:$D$420,$W26,_CALC_ALLOC!$E$1:$E$420,$X26,_CALC_ALLOC!$F$1:$F$420,$Y26) -> 0 | I26: =SUMIFS(_CALC_ALLOC!$AR$1:$AR$420,_CALC_ALLOC!$AS$1:$AS$420,"2027|"&$P$1,_CALC_ALLOC!$B$1:$B$420,$U26,_CALC_ALLOC!$D$1:$D$420,$W26,_CALC_ALLOC!$E$1:$E$420,$X26,_CALC_ALLOC!$F$1:$F$420,$Y26) -> 0 | J26: =SUMIFS(_CALC_ALLOC!$AM$1:$AM$420,_CALC_ALLOC!$AS$1:$AS$420,"2027|"&$P$1,_CALC_ALLOC!$B$1:$B$420,$U26,_CALC_ALLOC!$D$1:$D$420,$W26,_CALC_ALLOC!$E$1:$E$420,$X26,_CALC_ALLOC!$F$1:$F$420,$Y26) -> 0 | K26: =E26+F26+G26+H26+I26+J26 -> 0 | L26: =SUMIFS(_CALC_ALLOC!$AN$1:$AN$420,_CALC_ALLOC!$AS$1:$AS$420,"2027|"&$P$1,_CALC_ALLOC!$B$1:$B$420,$U26,_CALC_ALLOC!$D$1:$D$420,$W26,_CALC_ALLOC!$E$1:$E$420,$X26,_CALC_ALLOC!$F$1:$F$420,$Y26) -> 0 | M26: =IF(D26=0,0,L26/D26) -> 0 | T26: MBWAY_LYO|BAC_MGT|B1|INIT | U26: MBWAY_LYO | V26: MBWAY | W26: BAC_MGT | X26: B1 | Y26: INIT | Z26: 3 | BF26: 2027BUD_V1 | BG26: ACT | BH26: 12 | BI26: 2024 | BJ26: MBWAY_BOR | BK26: MBWAY | BL26: BAC_MGT | BM26: B1 | BN26: INIT | BO26: 45 | BP26: 2 | BQ26: 331425 | BR26: 27545 | BS26: 64185.895 | BT26: 27515.708 | BU26: 121392.64 | BV26: 8229.0045 | BW26: 42068.694 | BX26: 50297.698 | BY26: 55060.708 | BZ26: 235876.23 | CA26: 290936.94 | CB26: 40488.063 | CC26: 45 | CD26: 110180 | CE26: 256743.58 | CF26: 84556 | CG26: 20597 | CH26: 606963.18 | CI26: 2639292 | CJ26: 499926
B27: Bachelor Management, 2e année, alternance | C27: =SUMIFS(_CALC_ALLOC!$G$1:$G$420,_CALC_ALLOC!$AS$1:$AS$420,"2027|"&$P$1,_CALC_ALLOC!$B$1:$B$420,$U27,_CALC_ALLOC!$D$1:$D$420,$W27,_CALC_ALLOC!$E$1:$E$420,$X27,_CALC_ALLOC!$F$1:$F$420,$Y27) -> 0 | D27: =SUMIFS(_CALC_ALLOC!$I$1:$I$420,_CALC_ALLOC!$AS$1:$AS$420,"2027|"&$P$1,_CALC_ALLOC!$B$1:$B$420,$U27,_CALC_ALLOC!$D$1:$D$420,$W27,_CALC_ALLOC!$E$1:$E$420,$X27,_CALC_ALLOC!$F$1:$F$420,$Y27) -> 0 | E27: =SUMIFS(_CALC_ALLOC!$AI$1:$AI$420,_CALC_ALLOC!$AS$1:$AS$420,"2027|"&$P$1,_CALC_ALLOC!$B$1:$B$420,$U27,_CALC_ALLOC!$D$1:$D$420,$W27,_CALC_ALLOC!$E$1:$E$420,$X27,_CALC_ALLOC!$F$1:$F$420,$Y27) -> 0 | F27: =SUMIFS(_CALC_ALLOC!$AJ$1:$AJ$420,_CALC_ALLOC!$AS$1:$AS$420,"2027|"&$P$1,_CALC_ALLOC!$B$1:$B$420,$U27,_CALC_ALLOC!$D$1:$D$420,$W27,_CALC_ALLOC!$E$1:$E$420,$X27,_CALC_ALLOC!$F$1:$F$420,$Y27) -> 0 | G27: =SUMIFS(_CALC_ALLOC!$AK$1:$AK$420,_CALC_ALLOC!$AS$1:$AS$420,"2027|"&$P$1,_CALC_ALLOC!$B$1:$B$420,$U27,_CALC_ALLOC!$D$1:$D$420,$W27,_CALC_ALLOC!$E$1:$E$420,$X27,_CALC_ALLOC!$F$1:$F$420,$Y27) -> 0 | H27: =SUMIFS(_CALC_ALLOC!$AL$1:$AL$420,_CALC_ALLOC!$AS$1:$AS$420,"2027|"&$P$1,_CALC_ALLOC!$B$1:$B$420,$U27,_CALC_ALLOC!$D$1:$D$420,$W27,_CALC_ALLOC!$E$1:$E$420,$X27,_CALC_ALLOC!$F$1:$F$420,$Y27) -> 0 | I27: =SUMIFS(_CALC_ALLOC!$AR$1:$AR$420,_CALC_ALLOC!$AS$1:$AS$420,"2027|"&$P$1,_CALC_ALLOC!$B$1:$B$420,$U27,_CALC_ALLOC!$D$1:$D$420,$W27,_CALC_ALLOC!$E$1:$E$420,$X27,_CALC_ALLOC!$F$1:$F$420,$Y27) -> 0 | J27: =SUMIFS(_CALC_ALLOC!$AM$1:$AM$420,_CALC_ALLOC!$AS$1:$AS$420,"2027|"&$P$1,_CALC_ALLOC!$B$1:$B$420,$U27,_CALC_ALLOC!$D$1:$D$420,$W27,_CALC_ALLOC!$E$1:$E$420,$X27,_CALC_ALLOC!$F$1:$F$420,$Y27) -> 0 | K27: =E27+F27+G27+H27+I27+J27 -> 0 | L27: =SUMIFS(_CALC_ALLOC!$AN$1:$AN$420,_CALC_ALLOC!$AS$1:$AS$420,"2027|"&$P$1,_CALC_ALLOC!$B$1:$B$420,$U27,_CALC_ALLOC!$D$1:$D$420,$W27,_CALC_ALLOC!$E$1:$E$420,$X27,_CALC_ALLOC!$F$1:$F$420,$Y27) -> 0 | M27: =IF(D27=0,0,L27/D27) -> 0 | T27: MBWAY_LYO|BAC_MGT|B2|ALT | U27: MBWAY_LYO | V27: MBWAY | W27: BAC_MGT | X27: B2 | Y27: ALT | Z27: 3 | BF27: 2027BUD_V1 | BG27: ACT | BH27: 12 | BI27: 2024 | BJ27: MBWAY_BOR | BK27: MBWAY | BL27: BAC_MGT | BM27: B2 | BN27: ALT | BO27: 44 | BP27: 2 | BQ27: 298760 | BR27: 22036 | BS27: 51348.716 | BT27: 16834.677 | BU27: 121392.64 | BV27: 8229.0045 | BW27: 42068.694 | BX27: 50297.698 | BY27: 38870.677 | BZ27: 223039.05 | CA27: 261909.73 | CB27: 36850.273 | CC27: 0 | CD27: 110180 | CE27: 256743.58 | CF27: 84556 | CG27: 20597 | CH27: 606963.18 | CI27: 2639292 | CJ27: 499926
B28: Bachelor Management, 3e année, alternance | C28: =SUMIFS(_CALC_ALLOC!$G$1:$G$420,_CALC_ALLOC!$AS$1:$AS$420,"2027|"&$P$1,_CALC_ALLOC!$B$1:$B$420,$U28,_CALC_ALLOC!$D$1:$D$420,$W28,_CALC_ALLOC!$E$1:$E$420,$X28,_CALC_ALLOC!$F$1:$F$420,$Y28) -> 0 | D28: =SUMIFS(_CALC_ALLOC!$I$1:$I$420,_CALC_ALLOC!$AS$1:$AS$420,"2027|"&$P$1,_CALC_ALLOC!$B$1:$B$420,$U28,_CALC_ALLOC!$D$1:$D$420,$W28,_CALC_ALLOC!$E$1:$E$420,$X28,_CALC_ALLOC!$F$1:$F$420,$Y28) -> 0 | E28: =SUMIFS(_CALC_ALLOC!$AI$1:$AI$420,_CALC_ALLOC!$AS$1:$AS$420,"2027|"&$P$1,_CALC_ALLOC!$B$1:$B$420,$U28,_CALC_ALLOC!$D$1:$D$420,$W28,_CALC_ALLOC!$E$1:$E$420,$X28,_CALC_ALLOC!$F$1:$F$420,$Y28) -> 0 | F28: =SUMIFS(_CALC_ALLOC!$AJ$1:$AJ$420,_CALC_ALLOC!$AS$1:$AS$420,"2027|"&$P$1,_CALC_ALLOC!$B$1:$B$420,$U28,_CALC_ALLOC!$D$1:$D$420,$W28,_CALC_ALLOC!$E$1:$E$420,$X28,_CALC_ALLOC!$F$1:$F$420,$Y28) -> 0 | G28: =SUMIFS(_CALC_ALLOC!$AK$1:$AK$420,_CALC_ALLOC!$AS$1:$AS$420,"2027|"&$P$1,_CALC_ALLOC!$B$1:$B$420,$U28,_CALC_ALLOC!$D$1:$D$420,$W28,_CALC_ALLOC!$E$1:$E$420,$X28,_CALC_ALLOC!$F$1:$F$420,$Y28) -> 0 | H28: =SUMIFS(_CALC_ALLOC!$AL$1:$AL$420,_CALC_ALLOC!$AS$1:$AS$420,"2027|"&$P$1,_CALC_ALLOC!$B$1:$B$420,$U28,_CALC_ALLOC!$D$1:$D$420,$W28,_CALC_ALLOC!$E$1:$E$420,$X28,_CALC_ALLOC!$F$1:$F$420,$Y28) -> 0 | I28: =SUMIFS(_CALC_ALLOC!$AR$1:$AR$420,_CALC_ALLOC!$AS$1:$AS$420,"2027|"&$P$1,_CALC_ALLOC!$B$1:$B$420,$U28,_CALC_ALLOC!$D$1:$D$420,$W28,_CALC_ALLOC!$E$1:$E$420,$X28,_CALC_ALLOC!$F$1:$F$420,$Y28) -> 0 | J28: =SUMIFS(_CALC_ALLOC!$AM$1:$AM$420,_CALC_ALLOC!$AS$1:$AS$420,"2027|"&$P$1,_CALC_ALLOC!$B$1:$B$420,$U28,_CALC_ALLOC!$D$1:$D$420,$W28,_CALC_ALLOC!$E$1:$E$420,$X28,_CALC_ALLOC!$F$1:$F$420,$Y28) -> 0 | K28: =E28+F28+G28+H28+I28+J28 -> 0 | L28: =SUMIFS(_CALC_ALLOC!$AN$1:$AN$420,_CALC_ALLOC!$AS$1:$AS$420,"2027|"&$P$1,_CALC_ALLOC!$B$1:$B$420,$U28,_CALC_ALLOC!$D$1:$D$420,$W28,_CALC_ALLOC!$E$1:$E$420,$X28,_CALC_ALLOC!$F$1:$F$420,$Y28) -> 0 | M28: =IF(D28=0,0,L28/D28) -> 0 | T28: MBWAY_LYO|BAC_MGT|B3|ALT | U28: MBWAY_LYO | V28: MBWAY | W28: BAC_MGT | X28: B3 | Y28: ALT | Z28: 3 | BF28: 2027BUD_V1 | BG28: ACT | BH28: 12 | BI28: 2024 | BJ28: MBWAY_BOR | BK28: MBWAY | BL28: BAC_MGT | BM28: B3 | BN28: ALT | BO28: 43 | BP28: 2 | BQ28: 291970 | BR28: 22036 | BS28: 51348.716 | BT28: 16452.061 | BU28: 121392.64 | BV28: 8229.0045 | BW28: 42068.694 | BX28: 50297.698 | BY28: 38488.061 | BZ28: 223039.05 | CA28: 261527.11 | CB28: 30442.889 | CC28: 0 | CD28: 110180 | CE28: 256743.58 | CF28: 84556 | CG28: 20597 | CH28: 606963.18 | CI28: 2639292 | CJ28: 499926
B29: Mastère Management, 1re année, alternance | C29: =SUMIFS(_CALC_ALLOC!$G$1:$G$420,_CALC_ALLOC!$AS$1:$AS$420,"2027|"&$P$1,_CALC_ALLOC!$B$1:$B$420,$U29,_CALC_ALLOC!$D$1:$D$420,$W29,_CALC_ALLOC!$E$1:$E$420,$X29,_CALC_ALLOC!$F$1:$F$420,$Y29) -> 0 | D29: =SUMIFS(_CALC_ALLOC!$I$1:$I$420,_CALC_ALLOC!$AS$1:$AS$420,"2027|"&$P$1,_CALC_ALLOC!$B$1:$B$420,$U29,_CALC_ALLOC!$D$1:$D$420,$W29,_CALC_ALLOC!$E$1:$E$420,$X29,_CALC_ALLOC!$F$1:$F$420,$Y29) -> 0 | E29: =SUMIFS(_CALC_ALLOC!$AI$1:$AI$420,_CALC_ALLOC!$AS$1:$AS$420,"2027|"&$P$1,_CALC_ALLOC!$B$1:$B$420,$U29,_CALC_ALLOC!$D$1:$D$420,$W29,_CALC_ALLOC!$E$1:$E$420,$X29,_CALC_ALLOC!$F$1:$F$420,$Y29) -> 0 | F29: =SUMIFS(_CALC_ALLOC!$AJ$1:$AJ$420,_CALC_ALLOC!$AS$1:$AS$420,"2027|"&$P$1,_CALC_ALLOC!$B$1:$B$420,$U29,_CALC_ALLOC!$D$1:$D$420,$W29,_CALC_ALLOC!$E$1:$E$420,$X29,_CALC_ALLOC!$F$1:$F$420,$Y29) -> 0 | G29: =SUMIFS(_CALC_ALLOC!$AK$1:$AK$420,_CALC_ALLOC!$AS$1:$AS$420,"2027|"&$P$1,_CALC_ALLOC!$B$1:$B$420,$U29,_CALC_ALLOC!$D$1:$D$420,$W29,_CALC_ALLOC!$E$1:$E$420,$X29,_CALC_ALLOC!$F$1:$F$420,$Y29) -> 0 | H29: =SUMIFS(_CALC_ALLOC!$AL$1:$AL$420,_CALC_ALLOC!$AS$1:$AS$420,"2027|"&$P$1,_CALC_ALLOC!$B$1:$B$420,$U29,_CALC_ALLOC!$D$1:$D$420,$W29,_CALC_ALLOC!$E$1:$E$420,$X29,_CALC_ALLOC!$F$1:$F$420,$Y29) -> 0 | I29: =SUMIFS(_CALC_ALLOC!$AR$1:$AR$420,_CALC_ALLOC!$AS$1:$AS$420,"2027|"&$P$1,_CALC_ALLOC!$B$1:$B$420,$U29,_CALC_ALLOC!$D$1:$D$420,$W29,_CALC_ALLOC!$E$1:$E$420,$X29,_CALC_ALLOC!$F$1:$F$420,$Y29) -> 0 | J29: =SUMIFS(_CALC_ALLOC!$AM$1:$AM$420,_CALC_ALLOC!$AS$1:$AS$420,"2027|"&$P$1,_CALC_ALLOC!$B$1:$B$420,$U29,_CALC_ALLOC!$D$1:$D$420,$W29,_CALC_ALLOC!$E$1:$E$420,$X29,_CALC_ALLOC!$F$1:$F$420,$Y29) -> 0 | K29: =E29+F29+G29+H29+I29+J29 -> 0 | L29: =SUMIFS(_CALC_ALLOC!$AN$1:$AN$420,_CALC_ALLOC!$AS$1:$AS$420,"2027|"&$P$1,_CALC_ALLOC!$B$1:$B$420,$U29,_CALC_ALLOC!$D$1:$D$420,$W29,_CALC_ALLOC!$E$1:$E$420,$X29,_CALC_ALLOC!$F$1:$F$420,$Y29) -> 0 | M29: =IF(D29=0,0,L29/D29) -> 0 | T29: MBWAY_LYO|MAS_MGT|M1|ALT | U29: MBWAY_LYO | V29: MBWAY | W29: MAS_MGT | X29: M1 | Y29: ALT | Z29: 3 | BF29: 2027BUD_V1 | BG29: ACT | BH29: 12 | BI29: 2024 | BJ29: MBWAY_BOR | BK29: MBWAY | BL29: MAS_MGT | BM29: M1 | BN29: ALT | BO29: 45 | BP29: 2 | BQ29: 331425 | BR29: 19281.5 | BS29: 44930.126 | BT29: 27515.708 | BU29: 121392.64 | BV29: 8229.0045 | BW29: 42068.694 | BX29: 50297.698 | BY29: 46797.208 | BZ29: 216620.46 | CA29: 263417.67 | CB29: 68007.331 | CC29: 45 | CD29: 110180 | CE29: 256743.58 | CF29: 84556 | CG29: 20597 | CH29: 606963.18 | CI29: 2639292 | CJ29: 499926
B30: Mastère Management, 2e année, alternance | C30: =SUMIFS(_CALC_ALLOC!$G$1:$G$420,_CALC_ALLOC!$AS$1:$AS$420,"2027|"&$P$1,_CALC_ALLOC!$B$1:$B$420,$U30,_CALC_ALLOC!$D$1:$D$420,$W30,_CALC_ALLOC!$E$1:$E$420,$X30,_CALC_ALLOC!$F$1:$F$420,$Y30) -> 0 | D30: =SUMIFS(_CALC_ALLOC!$I$1:$I$420,_CALC_ALLOC!$AS$1:$AS$420,"2027|"&$P$1,_CALC_ALLOC!$B$1:$B$420,$U30,_CALC_ALLOC!$D$1:$D$420,$W30,_CALC_ALLOC!$E$1:$E$420,$X30,_CALC_ALLOC!$F$1:$F$420,$Y30) -> 0 | E30: =SUMIFS(_CALC_ALLOC!$AI$1:$AI$420,_CALC_ALLOC!$AS$1:$AS$420,"2027|"&$P$1,_CALC_ALLOC!$B$1:$B$420,$U30,_CALC_ALLOC!$D$1:$D$420,$W30,_CALC_ALLOC!$E$1:$E$420,$X30,_CALC_ALLOC!$F$1:$F$420,$Y30) -> 0 | F30: =SUMIFS(_CALC_ALLOC!$AJ$1:$AJ$420,_CALC_ALLOC!$AS$1:$AS$420,"2027|"&$P$1,_CALC_ALLOC!$B$1:$B$420,$U30,_CALC_ALLOC!$D$1:$D$420,$W30,_CALC_ALLOC!$E$1:$E$420,$X30,_CALC_ALLOC!$F$1:$F$420,$Y30) -> 0 | G30: =SUMIFS(_CALC_ALLOC!$AK$1:$AK$420,_CALC_ALLOC!$AS$1:$AS$420,"2027|"&$P$1,_CALC_ALLOC!$B$1:$B$420,$U30,_CALC_ALLOC!$D$1:$D$420,$W30,_CALC_ALLOC!$E$1:$E$420,$X30,_CALC_ALLOC!$F$1:$F$420,$Y30) -> 0 | H30: =SUMIFS(_CALC_ALLOC!$AL$1:$AL$420,_CALC_ALLOC!$AS$1:$AS$420,"2027|"&$P$1,_CALC_ALLOC!$B$1:$B$420,$U30,_CALC_ALLOC!$D$1:$D$420,$W30,_CALC_ALLOC!$E$1:$E$420,$X30,_CALC_ALLOC!$F$1:$F$420,$Y30) -> 0 | I30: =SUMIFS(_CALC_ALLOC!$AR$1:$AR$420,_CALC_ALLOC!$AS$1:$AS$420,"2027|"&$P$1,_CALC_ALLOC!$B$1:$B$420,$U30,_CALC_ALLOC!$D$1:$D$420,$W30,_CALC_ALLOC!$E$1:$E$420,$X30,_CALC_ALLOC!$F$1:$F$420,$Y30) -> 0 | J30: =SUMIFS(_CALC_ALLOC!$AM$1:$AM$420,_CALC_ALLOC!$AS$1:$AS$420,"2027|"&$P$1,_CALC_ALLOC!$B$1:$B$420,$U30,_CALC_ALLOC!$D$1:$D$420,$W30,_CALC_ALLOC!$E$1:$E$420,$X30,_CALC_ALLOC!$F$1:$F$420,$Y30) -> 0 | K30: =E30+F30+G30+H30+I30+J30 -> 0 | L30: =SUMIFS(_CALC_ALLOC!$AN$1:$AN$420,_CALC_ALLOC!$AS$1:$AS$420,"2027|"&$P$1,_CALC_ALLOC!$B$1:$B$420,$U30,_CALC_ALLOC!$D$1:$D$420,$W30,_CALC_ALLOC!$E$1:$E$420,$X30,_CALC_ALLOC!$F$1:$F$420,$Y30) -> 0 | M30: =IF(D30=0,0,L30/D30) -> 0 | T30: MBWAY_LYO|MAS_MGT|M2|ALT | U30: MBWAY_LYO | V30: MBWAY | W30: MAS_MGT | X30: M2 | Y30: ALT | Z30: 3 | BF30: 2027BUD_V1 | BG30: ACT | BH30: 12 | BI30: 2024 | BJ30: MBWAY_BOR | BK30: MBWAY | BL30: MAS_MGT | BM30: M2 | BN30: ALT | BO30: 44 | BP30: 2 | BQ30: 320100 | BR30: 19281.5 | BS30: 44930.126 | BT30: 16834.677 | BU30: 121392.64 | BV30: 8229.0045 | BW30: 42068.694 | BX30: 50297.698 | BY30: 36116.177 | BZ30: 216620.46 | CA30: 252736.64 | CB30: 67363.362 | CC30: 0 | CD30: 110180 | CE30: 256743.58 | CF30: 84556 | CG30: 20597 | CH30: 606963.18 | CI30: 2639292 | CJ30: 499926
B31: Nantes | C31: =SUMIFS(_CALC_ALLOC!$G$1:$G$420,_CALC_ALLOC!$AS$1:$AS$420,"2027|"&$P$1,_CALC_ALLOC!$B$1:$B$420,$U31) -> 0 | D31: =SUMIFS(_CALC_ALLOC!$I$1:$I$420,_CALC_ALLOC!$AS$1:$AS$420,"2027|"&$P$1,_CALC_ALLOC!$B$1:$B$420,$U31) -> 0 | E31: =SUMIFS(_CALC_ALLOC!$AI$1:$AI$420,_CALC_ALLOC!$AS$1:$AS$420,"2027|"&$P$1,_CALC_ALLOC!$B$1:$B$420,$U31) -> 0 | F31: =SUMIFS(_CALC_ALLOC!$AJ$1:$AJ$420,_CALC_ALLOC!$AS$1:$AS$420,"2027|"&$P$1,_CALC_ALLOC!$B$1:$B$420,$U31) -> 0 | G31: =SUMIFS(_CALC_ALLOC!$AK$1:$AK$420,_CALC_ALLOC!$AS$1:$AS$420,"2027|"&$P$1,_CALC_ALLOC!$B$1:$B$420,$U31) -> 0 | H31: =SUMIFS(_CALC_ALLOC!$AL$1:$AL$420,_CALC_ALLOC!$AS$1:$AS$420,"2027|"&$P$1,_CALC_ALLOC!$B$1:$B$420,$U31) -> 0 | I31: =SUMIFS(_CALC_ALLOC!$AR$1:$AR$420,_CALC_ALLOC!$AS$1:$AS$420,"2027|"&$P$1,_CALC_ALLOC!$B$1:$B$420,$U31) -> 0 | J31: =SUMIFS(_CALC_ALLOC!$AM$1:$AM$420,_CALC_ALLOC!$AS$1:$AS$420,"2027|"&$P$1,_CALC_ALLOC!$B$1:$B$420,$U31) -> 0 | K31: =E31+F31+G31+H31+I31+J31 -> 0 | L31: =SUMIFS(_CALC_ALLOC!$AN$1:$AN$420,_CALC_ALLOC!$AS$1:$AS$420,"2027|"&$P$1,_CALC_ALLOC!$B$1:$B$420,$U31) -> 0 | M31: =IF(D31=0,0,L31/D31) -> 0 | T31: MBWAY_NAN | U31: MBWAY_NAN | V31: MBWAY | Z31: 2 | BF31: 2027BUD_V1 | BG31: ACT | BH31: 12 | BI31: 2024 | BJ31: MBWAY_LYO | BK31: MBWAY | BL31: BAC_MGT | BM31: B1 | BN31: INIT | BO31: 59 | BP31: 3 | BQ31: 469935 | BR31: 41317.711 | BS31: 106414.01 | BT31: 39727.824 | BU31: 201383.22 | BV31: 12416.529 | BW31: 63476.349 | BX31: 75892.878 | BY31: 81045.535 | BZ31: 383690.11 | CA31: 464735.64 | CB31: 5199.3554 | CC31: 59 | CD31: 143235 | CE31: 368902.58 | CF31: 110025 | CG31: 34532 | CH31: 872661.51 | CI31: 2639292 | CJ31: 499926
B32: Bachelor Management, 1re année, initial | C32: =SUMIFS(_CALC_ALLOC!$G$1:$G$420,_CALC_ALLOC!$AS$1:$AS$420,"2027|"&$P$1,_CALC_ALLOC!$B$1:$B$420,$U32,_CALC_ALLOC!$D$1:$D$420,$W32,_CALC_ALLOC!$E$1:$E$420,$X32,_CALC_ALLOC!$F$1:$F$420,$Y32) -> 0 | D32: =SUMIFS(_CALC_ALLOC!$I$1:$I$420,_CALC_ALLOC!$AS$1:$AS$420,"2027|"&$P$1,_CALC_ALLOC!$B$1:$B$420,$U32,_CALC_ALLOC!$D$1:$D$420,$W32,_CALC_ALLOC!$E$1:$E$420,$X32,_CALC_ALLOC!$F$1:$F$420,$Y32) -> 0 | E32: =SUMIFS(_CALC_ALLOC!$AI$1:$AI$420,_CALC_ALLOC!$AS$1:$AS$420,"2027|"&$P$1,_CALC_ALLOC!$B$1:$B$420,$U32,_CALC_ALLOC!$D$1:$D$420,$W32,_CALC_ALLOC!$E$1:$E$420,$X32,_CALC_ALLOC!$F$1:$F$420,$Y32) -> 0 | F32: =SUMIFS(_CALC_ALLOC!$AJ$1:$AJ$420,_CALC_ALLOC!$AS$1:$AS$420,"2027|"&$P$1,_CALC_ALLOC!$B$1:$B$420,$U32,_CALC_ALLOC!$D$1:$D$420,$W32,_CALC_ALLOC!$E$1:$E$420,$X32,_CALC_ALLOC!$F$1:$F$420,$Y32) -> 0 | G32: =SUMIFS(_CALC_ALLOC!$AK$1:$AK$420,_CALC_ALLOC!$AS$1:$AS$420,"2027|"&$P$1,_CALC_ALLOC!$B$1:$B$420,$U32,_CALC_ALLOC!$D$1:$D$420,$W32,_CALC_ALLOC!$E$1:$E$420,$X32,_CALC_ALLOC!$F$1:$F$420,$Y32) -> 0 | H32: =SUMIFS(_CALC_ALLOC!$AL$1:$AL$420,_CALC_ALLOC!$AS$1:$AS$420,"2027|"&$P$1,_CALC_ALLOC!$B$1:$B$420,$U32,_CALC_ALLOC!$D$1:$D$420,$W32,_CALC_ALLOC!$E$1:$E$420,$X32,_CALC_ALLOC!$F$1:$F$420,$Y32) -> 0 | I32: =SUMIFS(_CALC_ALLOC!$AR$1:$AR$420,_CALC_ALLOC!$AS$1:$AS$420,"2027|"&$P$1,_CALC_ALLOC!$B$1:$B$420,$U32,_CALC_ALLOC!$D$1:$D$420,$W32,_CALC_ALLOC!$E$1:$E$420,$X32,_CALC_ALLOC!$F$1:$F$420,$Y32) -> 0 | J32: =SUMIFS(_CALC_ALLOC!$AM$1:$AM$420,_CALC_ALLOC!$AS$1:$AS$420,"2027|"&$P$1,_CALC_ALLOC!$B$1:$B$420,$U32,_CALC_ALLOC!$D$1:$D$420,$W32,_CALC_ALLOC!$E$1:$E$420,$X32,_CALC_ALLOC!$F$1:$F$420,$Y32) -> 0 | K32: =E32+F32+G32+H32+I32+J32 -> 0 | L32: =SUMIFS(_CALC_ALLOC!$AN$1:$AN$420,_CALC_ALLOC!$AS$1:$AS$420,"2027|"&$P$1,_CALC_ALLOC!$B$1:$B$420,$U32,_CALC_ALLOC!$D$1:$D$420,$W32,_CALC_ALLOC!$E$1:$E$420,$X32,_CALC_ALLOC!$F$1:$F$420,$Y32) -> 0 | M32: =IF(D32=0,0,L32/D32) -> 0 | T32: MBWAY_NAN|BAC_MGT|B1|INIT | U32: MBWAY_NAN | V32: MBWAY | W32: BAC_MGT | X32: B1 | Y32: INIT | Z32: 3 | BF32: 2027BUD_V1 | BG32: ACT | BH32: 12 | BI32: 2024 | BJ32: MBWAY_LYO | BK32: MBWAY | BL32: BAC_MGT | BM32: B2 | BN32: ALT | BO32: 57 | BP32: 2 | BQ32: 418950 | BR32: 22036.132 | BS32: 56754.186 | BT32: 21700.341 | BU32: 134255.48 | BV32: 8277.6861 | BW32: 42317.566 | BX32: 50595.252 | BY32: 43736.473 | BZ32: 241604.92 | CA32: 285341.39 | CB32: 133608.61 | CC32: 0 | CD32: 143235 | CE32: 368902.58 | CF32: 110025 | CG32: 34532 | CH32: 872661.51 | CI32: 2639292 | CJ32: 499926
B33: Bachelor Management, 2e année, alternance | C33: =SUMIFS(_CALC_ALLOC!$G$1:$G$420,_CALC_ALLOC!$AS$1:$AS$420,"2027|"&$P$1,_CALC_ALLOC!$B$1:$B$420,$U33,_CALC_ALLOC!$D$1:$D$420,$W33,_CALC_ALLOC!$E$1:$E$420,$X33,_CALC_ALLOC!$F$1:$F$420,$Y33) -> 0 | D33: =SUMIFS(_CALC_ALLOC!$I$1:$I$420,_CALC_ALLOC!$AS$1:$AS$420,"2027|"&$P$1,_CALC_ALLOC!$B$1:$B$420,$U33,_CALC_ALLOC!$D$1:$D$420,$W33,_CALC_ALLOC!$E$1:$E$420,$X33,_CALC_ALLOC!$F$1:$F$420,$Y33) -> 0 | E33: =SUMIFS(_CALC_ALLOC!$AI$1:$AI$420,_CALC_ALLOC!$AS$1:$AS$420,"2027|"&$P$1,_CALC_ALLOC!$B$1:$B$420,$U33,_CALC_ALLOC!$D$1:$D$420,$W33,_CALC_ALLOC!$E$1:$E$420,$X33,_CALC_ALLOC!$F$1:$F$420,$Y33) -> 0 | F33: =SUMIFS(_CALC_ALLOC!$AJ$1:$AJ$420,_CALC_ALLOC!$AS$1:$AS$420,"2027|"&$P$1,_CALC_ALLOC!$B$1:$B$420,$U33,_CALC_ALLOC!$D$1:$D$420,$W33,_CALC_ALLOC!$E$1:$E$420,$X33,_CALC_ALLOC!$F$1:$F$420,$Y33) -> 0 | G33: =SUMIFS(_CALC_ALLOC!$AK$1:$AK$420,_CALC_ALLOC!$AS$1:$AS$420,"2027|"&$P$1,_CALC_ALLOC!$B$1:$B$420,$U33,_CALC_ALLOC!$D$1:$D$420,$W33,_CALC_ALLOC!$E$1:$E$420,$X33,_CALC_ALLOC!$F$1:$F$420,$Y33) -> 0 | H33: =SUMIFS(_CALC_ALLOC!$AL$1:$AL$420,_CALC_ALLOC!$AS$1:$AS$420,"2027|"&$P$1,_CALC_ALLOC!$B$1:$B$420,$U33,_CALC_ALLOC!$D$1:$D$420,$W33,_CALC_ALLOC!$E$1:$E$420,$X33,_CALC_ALLOC!$F$1:$F$420,$Y33) -> 0 | I33: =SUMIFS(_CALC_ALLOC!$AR$1:$AR$420,_CALC_ALLOC!$AS$1:$AS$420,"2027|"&$P$1,_CALC_ALLOC!$B$1:$B$420,$U33,_CALC_ALLOC!$D$1:$D$420,$W33,_CALC_ALLOC!$E$1:$E$420,$X33,_CALC_ALLOC!$F$1:$F$420,$Y33) -> 0 | J33: =SUMIFS(_CALC_ALLOC!$AM$1:$AM$420,_CALC_ALLOC!$AS$1:$AS$420,"2027|"&$P$1,_CALC_ALLOC!$B$1:$B$420,$U33,_CALC_ALLOC!$D$1:$D$420,$W33,_CALC_ALLOC!$E$1:$E$420,$X33,_CALC_ALLOC!$F$1:$F$420,$Y33) -> 0 | K33: =E33+F33+G33+H33+I33+J33 -> 0 | L33: =SUMIFS(_CALC_ALLOC!$AN$1:$AN$420,_CALC_ALLOC!$AS$1:$AS$420,"2027|"&$P$1,_CALC_ALLOC!$B$1:$B$420,$U33,_CALC_ALLOC!$D$1:$D$420,$W33,_CALC_ALLOC!$E$1:$E$420,$X33,_CALC_ALLOC!$F$1:$F$420,$Y33) -> 0 | M33: =IF(D33=0,0,L33/D33) -> 0 | T33: MBWAY_NAN|BAC_MGT|B2|ALT | U33: MBWAY_NAN | V33: MBWAY | W33: BAC_MGT | X33: B2 | Y33: ALT | Z33: 3 | BF33: 2027BUD_V1 | BG33: ACT | BH33: 12 | BI33: 2024 | BJ33: MBWAY_LYO | BK33: MBWAY | BL33: BAC_MGT | BM33: B3 | BN33: ALT | BO33: 56 | BP33: 2 | BQ33: 411600 | BR33: 22036.132 | BS33: 56754.186 | BT33: 21319.654 | BU33: 134255.48 | BV33: 8277.6861 | BW33: 42317.566 | BX33: 50595.252 | BY33: 43355.786 | BZ33: 241604.92 | CA33: 284960.71 | CB33: 126639.29 | CC33: 0 | CD33: 143235 | CE33: 368902.58 | CF33: 110025 | CG33: 34532 | CH33: 872661.51 | CI33: 2639292 | CJ33: 499926
B34: Bachelor Management, 3e année, alternance | C34: =SUMIFS(_CALC_ALLOC!$G$1:$G$420,_CALC_ALLOC!$AS$1:$AS$420,"2027|"&$P$1,_CALC_ALLOC!$B$1:$B$420,$U34,_CALC_ALLOC!$D$1:$D$420,$W34,_CALC_ALLOC!$E$1:$E$420,$X34,_CALC_ALLOC!$F$1:$F$420,$Y34) -> 0 | D34: =SUMIFS(_CALC_ALLOC!$I$1:$I$420,_CALC_ALLOC!$AS$1:$AS$420,"2027|"&$P$1,_CALC_ALLOC!$B$1:$B$420,$U34,_CALC_ALLOC!$D$1:$D$420,$W34,_CALC_ALLOC!$E$1:$E$420,$X34,_CALC_ALLOC!$F$1:$F$420,$Y34) -> 0 | E34: =SUMIFS(_CALC_ALLOC!$AI$1:$AI$420,_CALC_ALLOC!$AS$1:$AS$420,"2027|"&$P$1,_CALC_ALLOC!$B$1:$B$420,$U34,_CALC_ALLOC!$D$1:$D$420,$W34,_CALC_ALLOC!$E$1:$E$420,$X34,_CALC_ALLOC!$F$1:$F$420,$Y34) -> 0 | F34: =SUMIFS(_CALC_ALLOC!$AJ$1:$AJ$420,_CALC_ALLOC!$AS$1:$AS$420,"2027|"&$P$1,_CALC_ALLOC!$B$1:$B$420,$U34,_CALC_ALLOC!$D$1:$D$420,$W34,_CALC_ALLOC!$E$1:$E$420,$X34,_CALC_ALLOC!$F$1:$F$420,$Y34) -> 0 | G34: =SUMIFS(_CALC_ALLOC!$AK$1:$AK$420,_CALC_ALLOC!$AS$1:$AS$420,"2027|"&$P$1,_CALC_ALLOC!$B$1:$B$420,$U34,_CALC_ALLOC!$D$1:$D$420,$W34,_CALC_ALLOC!$E$1:$E$420,$X34,_CALC_ALLOC!$F$1:$F$420,$Y34) -> 0 | H34: =SUMIFS(_CALC_ALLOC!$AL$1:$AL$420,_CALC_ALLOC!$AS$1:$AS$420,"2027|"&$P$1,_CALC_ALLOC!$B$1:$B$420,$U34,_CALC_ALLOC!$D$1:$D$420,$W34,_CALC_ALLOC!$E$1:$E$420,$X34,_CALC_ALLOC!$F$1:$F$420,$Y34) -> 0 | I34: =SUMIFS(_CALC_ALLOC!$AR$1:$AR$420,_CALC_ALLOC!$AS$1:$AS$420,"2027|"&$P$1,_CALC_ALLOC!$B$1:$B$420,$U34,_CALC_ALLOC!$D$1:$D$420,$W34,_CALC_ALLOC!$E$1:$E$420,$X34,_CALC_ALLOC!$F$1:$F$420,$Y34) -> 0 | J34: =SUMIFS(_CALC_ALLOC!$AM$1:$AM$420,_CALC_ALLOC!$AS$1:$AS$420,"2027|"&$P$1,_CALC_ALLOC!$B$1:$B$420,$U34,_CALC_ALLOC!$D$1:$D$420,$W34,_CALC_ALLOC!$E$1:$E$420,$X34,_CALC_ALLOC!$F$1:$F$420,$Y34) -> 0 | K34: =E34+F34+G34+H34+I34+J34 -> 0 | L34: =SUMIFS(_CALC_ALLOC!$AN$1:$AN$420,_CALC_ALLOC!$AS$1:$AS$420,"2027|"&$P$1,_CALC_ALLOC!$B$1:$B$420,$U34,_CALC_ALLOC!$D$1:$D$420,$W34,_CALC_ALLOC!$E$1:$E$420,$X34,_CALC_ALLOC!$F$1:$F$420,$Y34) -> 0 | M34: =IF(D34=0,0,L34/D34) -> 0 | T34: MBWAY_NAN|BAC_MGT|B3|ALT | U34: MBWAY_NAN | V34: MBWAY | W34: BAC_MGT | X34: B3 | Y34: ALT | Z34: 3 | BF34: 2027BUD_V1 | BG34: ACT | BH34: 12 | BI34: 2024 | BJ34: MBWAY_LYO | BK34: MBWAY | BL34: MAS_MGT | BM34: M1 | BN34: ALT | BO34: 59 | BP34: 3 | BQ34: 469935 | BR34: 28922.441 | BS34: 74489.916 | BT34: 39727.824 | BU34: 201383.22 | BV34: 12416.529 | BW34: 63476.349 | BX34: 75892.878 | BY34: 68650.265 | BZ34: 351766.02 | CA34: 420416.28 | CB34: 49518.717 | CC34: 59 | CD34: 143235 | CE34: 368902.58 | CF34: 110025 | CG34: 34532 | CH34: 872661.51 | CI34: 2639292 | CJ34: 499926
B35: Mastère Management, 1re année, alternance | C35: =SUMIFS(_CALC_ALLOC!$G$1:$G$420,_CALC_ALLOC!$AS$1:$AS$420,"2027|"&$P$1,_CALC_ALLOC!$B$1:$B$420,$U35,_CALC_ALLOC!$D$1:$D$420,$W35,_CALC_ALLOC!$E$1:$E$420,$X35,_CALC_ALLOC!$F$1:$F$420,$Y35) -> 0 | D35: =SUMIFS(_CALC_ALLOC!$I$1:$I$420,_CALC_ALLOC!$AS$1:$AS$420,"2027|"&$P$1,_CALC_ALLOC!$B$1:$B$420,$U35,_CALC_ALLOC!$D$1:$D$420,$W35,_CALC_ALLOC!$E$1:$E$420,$X35,_CALC_ALLOC!$F$1:$F$420,$Y35) -> 0 | E35: =SUMIFS(_CALC_ALLOC!$AI$1:$AI$420,_CALC_ALLOC!$AS$1:$AS$420,"2027|"&$P$1,_CALC_ALLOC!$B$1:$B$420,$U35,_CALC_ALLOC!$D$1:$D$420,$W35,_CALC_ALLOC!$E$1:$E$420,$X35,_CALC_ALLOC!$F$1:$F$420,$Y35) -> 0 | F35: =SUMIFS(_CALC_ALLOC!$AJ$1:$AJ$420,_CALC_ALLOC!$AS$1:$AS$420,"2027|"&$P$1,_CALC_ALLOC!$B$1:$B$420,$U35,_CALC_ALLOC!$D$1:$D$420,$W35,_CALC_ALLOC!$E$1:$E$420,$X35,_CALC_ALLOC!$F$1:$F$420,$Y35) -> 0 | G35: =SUMIFS(_CALC_ALLOC!$AK$1:$AK$420,_CALC_ALLOC!$AS$1:$AS$420,"2027|"&$P$1,_CALC_ALLOC!$B$1:$B$420,$U35,_CALC_ALLOC!$D$1:$D$420,$W35,_CALC_ALLOC!$E$1:$E$420,$X35,_CALC_ALLOC!$F$1:$F$420,$Y35) -> 0 | H35: =SUMIFS(_CALC_ALLOC!$AL$1:$AL$420,_CALC_ALLOC!$AS$1:$AS$420,"2027|"&$P$1,_CALC_ALLOC!$B$1:$B$420,$U35,_CALC_ALLOC!$D$1:$D$420,$W35,_CALC_ALLOC!$E$1:$E$420,$X35,_CALC_ALLOC!$F$1:$F$420,$Y35) -> 0 | I35: =SUMIFS(_CALC_ALLOC!$AR$1:$AR$420,_CALC_ALLOC!$AS$1:$AS$420,"2027|"&$P$1,_CALC_ALLOC!$B$1:$B$420,$U35,_CALC_ALLOC!$D$1:$D$420,$W35,_CALC_ALLOC!$E$1:$E$420,$X35,_CALC_ALLOC!$F$1:$F$420,$Y35) -> 0 | J35: =SUMIFS(_CALC_ALLOC!$AM$1:$AM$420,_CALC_ALLOC!$AS$1:$AS$420,"2027|"&$P$1,_CALC_ALLOC!$B$1:$B$420,$U35,_CALC_ALLOC!$D$1:$D$420,$W35,_CALC_ALLOC!$E$1:$E$420,$X35,_CALC_ALLOC!$F$1:$F$420,$Y35) -> 0 | K35: =E35+F35+G35+H35+I35+J35 -> 0 | L35: =SUMIFS(_CALC_ALLOC!$AN$1:$AN$420,_CALC_ALLOC!$AS$1:$AS$420,"2027|"&$P$1,_CALC_ALLOC!$B$1:$B$420,$U35,_CALC_ALLOC!$D$1:$D$420,$W35,_CALC_ALLOC!$E$1:$E$420,$X35,_CALC_ALLOC!$F$1:$F$420,$Y35) -> 0 | M35: =IF(D35=0,0,L35/D35) -> 0 | T35: MBWAY_NAN|MAS_MGT|M1|ALT | U35: MBWAY_NAN | V35: MBWAY | W35: MAS_MGT | X35: M1 | Y35: ALT | Z35: 3 | BF35: 2027BUD_V1 | BG35: ACT | BH35: 12 | BI35: 2024 | BJ35: MBWAY_LYO | BK35: MBWAY | BL35: MAS_MGT | BM35: M2 | BN35: ALT | BO35: 58 | BP35: 3 | BQ35: 456750 | BR35: 28922.441 | BS35: 74489.916 | BT35: 22081.137 | BU35: 201383.22 | BV35: 12416.529 | BW35: 63476.349 | BX35: 75892.878 | BY35: 51003.578 | BZ35: 351766.02 | CA35: 402769.6 | CB35: 53980.404 | CC35: 0 | CD35: 143235 | CE35: 368902.58 | CF35: 110025 | CG35: 34532 | CH35: 872661.51 | CI35: 2639292 | CJ35: 499926
B36: Mastère Management, 2e année, alternance | C36: =SUMIFS(_CALC_ALLOC!$G$1:$G$420,_CALC_ALLOC!$AS$1:$AS$420,"2027|"&$P$1,_CALC_ALLOC!$B$1:$B$420,$U36,_CALC_ALLOC!$D$1:$D$420,$W36,_CALC_ALLOC!$E$1:$E$420,$X36,_CALC_ALLOC!$F$1:$F$420,$Y36) -> 0 | D36: =SUMIFS(_CALC_ALLOC!$I$1:$I$420,_CALC_ALLOC!$AS$1:$AS$420,"2027|"&$P$1,_CALC_ALLOC!$B$1:$B$420,$U36,_CALC_ALLOC!$D$1:$D$420,$W36,_CALC_ALLOC!$E$1:$E$420,$X36,_CALC_ALLOC!$F$1:$F$420,$Y36) -> 0 | E36: =SUMIFS(_CALC_ALLOC!$AI$1:$AI$420,_CALC_ALLOC!$AS$1:$AS$420,"2027|"&$P$1,_CALC_ALLOC!$B$1:$B$420,$U36,_CALC_ALLOC!$D$1:$D$420,$W36,_CALC_ALLOC!$E$1:$E$420,$X36,_CALC_ALLOC!$F$1:$F$420,$Y36) -> 0 | F36: =SUMIFS(_CALC_ALLOC!$AJ$1:$AJ$420,_CALC_ALLOC!$AS$1:$AS$420,"2027|"&$P$1,_CALC_ALLOC!$B$1:$B$420,$U36,_CALC_ALLOC!$D$1:$D$420,$W36,_CALC_ALLOC!$E$1:$E$420,$X36,_CALC_ALLOC!$F$1:$F$420,$Y36) -> 0 | G36: =SUMIFS(_CALC_ALLOC!$AK$1:$AK$420,_CALC_ALLOC!$AS$1:$AS$420,"2027|"&$P$1,_CALC_ALLOC!$B$1:$B$420,$U36,_CALC_ALLOC!$D$1:$D$420,$W36,_CALC_ALLOC!$E$1:$E$420,$X36,_CALC_ALLOC!$F$1:$F$420,$Y36) -> 0 | H36: =SUMIFS(_CALC_ALLOC!$AL$1:$AL$420,_CALC_ALLOC!$AS$1:$AS$420,"2027|"&$P$1,_CALC_ALLOC!$B$1:$B$420,$U36,_CALC_ALLOC!$D$1:$D$420,$W36,_CALC_ALLOC!$E$1:$E$420,$X36,_CALC_ALLOC!$F$1:$F$420,$Y36) -> 0 | I36: =SUMIFS(_CALC_ALLOC!$AR$1:$AR$420,_CALC_ALLOC!$AS$1:$AS$420,"2027|"&$P$1,_CALC_ALLOC!$B$1:$B$420,$U36,_CALC_ALLOC!$D$1:$D$420,$W36,_CALC_ALLOC!$E$1:$E$420,$X36,_CALC_ALLOC!$F$1:$F$420,$Y36) -> 0 | J36: =SUMIFS(_CALC_ALLOC!$AM$1:$AM$420,_CALC_ALLOC!$AS$1:$AS$420,"2027|"&$P$1,_CALC_ALLOC!$B$1:$B$420,$U36,_CALC_ALLOC!$D$1:$D$420,$W36,_CALC_ALLOC!$E$1:$E$420,$X36,_CALC_ALLOC!$F$1:$F$420,$Y36) -> 0 | K36: =E36+F36+G36+H36+I36+J36 -> 0 | L36: =SUMIFS(_CALC_ALLOC!$AN$1:$AN$420,_CALC_ALLOC!$AS$1:$AS$420,"2027|"&$P$1,_CALC_ALLOC!$B$1:$B$420,$U36,_CALC_ALLOC!$D$1:$D$420,$W36,_CALC_ALLOC!$E$1:$E$420,$X36,_CALC_ALLOC!$F$1:$F$420,$Y36) -> 0 | M36: =IF(D36=0,0,L36/D36) -> 0 | T36: MBWAY_NAN|MAS_MGT|M2|ALT | U36: MBWAY_NAN | V36: MBWAY | W36: MAS_MGT | X36: M2 | Y36: ALT | Z36: 3 | BF36: 2027BUD_V1 | BG36: ACT | BH36: 12 | BI36: 2024 | BJ36: MBWAY_NAN | BK36: MBWAY | BL36: BAC_MGT | BM36: B1 | BN36: INIT | BO36: 53 | BP36: 2 | BQ36: 402270 | BR36: 28130.937 | BS36: 67425.875 | BT36: 33226.027 | BU36: 123506.23 | BV36: 8129.6605 | BW36: 41560.823 | BX36: 49690.483 | BY36: 61356.964 | BZ36: 240622.59 | CA36: 301979.55 | CB36: 100290.45 | CC36: 53 | CD36: 132216 | CE36: 316903.04 | CF36: 99837 | CG36: 26060 | CH36: 741040.34 | CI36: 2639292 | CJ36: 499926
B37: Bordeaux | C37: =SUMIFS(_CALC_ALLOC!$G$1:$G$420,_CALC_ALLOC!$AS$1:$AS$420,"2027|"&$P$1,_CALC_ALLOC!$B$1:$B$420,$U37) -> 0 | D37: =SUMIFS(_CALC_ALLOC!$I$1:$I$420,_CALC_ALLOC!$AS$1:$AS$420,"2027|"&$P$1,_CALC_ALLOC!$B$1:$B$420,$U37) -> 0 | E37: =SUMIFS(_CALC_ALLOC!$AI$1:$AI$420,_CALC_ALLOC!$AS$1:$AS$420,"2027|"&$P$1,_CALC_ALLOC!$B$1:$B$420,$U37) -> 0 | F37: =SUMIFS(_CALC_ALLOC!$AJ$1:$AJ$420,_CALC_ALLOC!$AS$1:$AS$420,"2027|"&$P$1,_CALC_ALLOC!$B$1:$B$420,$U37) -> 0 | G37: =SUMIFS(_CALC_ALLOC!$AK$1:$AK$420,_CALC_ALLOC!$AS$1:$AS$420,"2027|"&$P$1,_CALC_ALLOC!$B$1:$B$420,$U37) -> 0 | H37: =SUMIFS(_CALC_ALLOC!$AL$1:$AL$420,_CALC_ALLOC!$AS$1:$AS$420,"2027|"&$P$1,_CALC_ALLOC!$B$1:$B$420,$U37) -> 0 | I37: =SUMIFS(_CALC_ALLOC!$AR$1:$AR$420,_CALC_ALLOC!$AS$1:$AS$420,"2027|"&$P$1,_CALC_ALLOC!$B$1:$B$420,$U37) -> 0 | J37: =SUMIFS(_CALC_ALLOC!$AM$1:$AM$420,_CALC_ALLOC!$AS$1:$AS$420,"2027|"&$P$1,_CALC_ALLOC!$B$1:$B$420,$U37) -> 0 | K37: =E37+F37+G37+H37+I37+J37 -> 0 | L37: =SUMIFS(_CALC_ALLOC!$AN$1:$AN$420,_CALC_ALLOC!$AS$1:$AS$420,"2027|"&$P$1,_CALC_ALLOC!$B$1:$B$420,$U37) -> 0 | M37: =IF(D37=0,0,L37/D37) -> 0 | T37: MBWAY_BOR | U37: MBWAY_BOR | V37: MBWAY | Z37: 2 | BF37: 2027BUD_V1 | BG37: ACT | BH37: 12 | BI37: 2024 | BJ37: MBWAY_NAN | BK37: MBWAY | BL37: BAC_MGT | BM37: B2 | BN37: ALT | BO37: 52 | BP37: 2 | BQ37: 364000 | BR37: 22504.75 | BS37: 53940.7 | BT37: 19814.949 | BU37: 123506.23 | BV37: 8129.6605 | BW37: 41560.823 | BX37: 49690.483 | BY37: 42319.699 | BZ37: 227137.41 | CA37: 269457.11 | CB37: 94542.889 | CC37: 0 | CD37: 132216 | CE37: 316903.04 | CF37: 99837 | CG37: 26060 | CH37: 741040.34 | CI37: 2639292 | CJ37: 499926
B38: Bachelor Management, 1re année, initial | C38: =SUMIFS(_CALC_ALLOC!$G$1:$G$420,_CALC_ALLOC!$AS$1:$AS$420,"2027|"&$P$1,_CALC_ALLOC!$B$1:$B$420,$U38,_CALC_ALLOC!$D$1:$D$420,$W38,_CALC_ALLOC!$E$1:$E$420,$X38,_CALC_ALLOC!$F$1:$F$420,$Y38) -> 0 | D38: =SUMIFS(_CALC_ALLOC!$I$1:$I$420,_CALC_ALLOC!$AS$1:$AS$420,"2027|"&$P$1,_CALC_ALLOC!$B$1:$B$420,$U38,_CALC_ALLOC!$D$1:$D$420,$W38,_CALC_ALLOC!$E$1:$E$420,$X38,_CALC_ALLOC!$F$1:$F$420,$Y38) -> 0 | E38: =SUMIFS(_CALC_ALLOC!$AI$1:$AI$420,_CALC_ALLOC!$AS$1:$AS$420,"2027|"&$P$1,_CALC_ALLOC!$B$1:$B$420,$U38,_CALC_ALLOC!$D$1:$D$420,$W38,_CALC_ALLOC!$E$1:$E$420,$X38,_CALC_ALLOC!$F$1:$F$420,$Y38) -> 0 | F38: =SUMIFS(_CALC_ALLOC!$AJ$1:$AJ$420,_CALC_ALLOC!$AS$1:$AS$420,"2027|"&$P$1,_CALC_ALLOC!$B$1:$B$420,$U38,_CALC_ALLOC!$D$1:$D$420,$W38,_CALC_ALLOC!$E$1:$E$420,$X38,_CALC_ALLOC!$F$1:$F$420,$Y38) -> 0 | G38: =SUMIFS(_CALC_ALLOC!$AK$1:$AK$420,_CALC_ALLOC!$AS$1:$AS$420,"2027|"&$P$1,_CALC_ALLOC!$B$1:$B$420,$U38,_CALC_ALLOC!$D$1:$D$420,$W38,_CALC_ALLOC!$E$1:$E$420,$X38,_CALC_ALLOC!$F$1:$F$420,$Y38) -> 0 | H38: =SUMIFS(_CALC_ALLOC!$AL$1:$AL$420,_CALC_ALLOC!$AS$1:$AS$420,"2027|"&$P$1,_CALC_ALLOC!$B$1:$B$420,$U38,_CALC_ALLOC!$D$1:$D$420,$W38,_CALC_ALLOC!$E$1:$E$420,$X38,_CALC_ALLOC!$F$1:$F$420,$Y38) -> 0 | I38: =SUMIFS(_CALC_ALLOC!$AR$1:$AR$420,_CALC_ALLOC!$AS$1:$AS$420,"2027|"&$P$1,_CALC_ALLOC!$B$1:$B$420,$U38,_CALC_ALLOC!$D$1:$D$420,$W38,_CALC_ALLOC!$E$1:$E$420,$X38,_CALC_ALLOC!$F$1:$F$420,$Y38) -> 0 | J38: =SUMIFS(_CALC_ALLOC!$AM$1:$AM$420,_CALC_ALLOC!$AS$1:$AS$420,"2027|"&$P$1,_CALC_ALLOC!$B$1:$B$420,$U38,_CALC_ALLOC!$D$1:$D$420,$W38,_CALC_ALLOC!$E$1:$E$420,$X38,_CALC_ALLOC!$F$1:$F$420,$Y38) -> 0 | K38: =E38+F38+G38+H38+I38+J38 -> 0 | L38: =SUMIFS(_CALC_ALLOC!$AN$1:$AN$420,_CALC_ALLOC!$AS$1:$AS$420,"2027|"&$P$1,_CALC_ALLOC!$B$1:$B$420,$U38,_CALC_ALLOC!$D$1:$D$420,$W38,_CALC_ALLOC!$E$1:$E$420,$X38,_CALC_ALLOC!$F$1:$F$420,$Y38) -> 0 | M38: =IF(D38=0,0,L38/D38) -> 0 | T38: MBWAY_BOR|BAC_MGT|B1|INIT | U38: MBWAY_BOR | V38: MBWAY | W38: BAC_MGT | X38: B1 | Y38: INIT | Z38: 3 | BF38: 2027BUD_V1 | BG38: ACT | BH38: 12 | BI38: 2024 | BJ38: MBWAY_NAN | BK38: MBWAY | BL38: BAC_MGT | BM38: B3 | BN38: ALT | BO38: 51 | BP38: 2 | BQ38: 357000 | BR38: 22504.75 | BS38: 53940.7 | BT38: 19433.871 | BU38: 123506.23 | BV38: 8129.6605 | BW38: 41560.823 | BX38: 49690.483 | BY38: 41938.621 | BZ38: 227137.41 | CA38: 269076.03 | CB38: 87923.966 | CC38: 0 | CD38: 132216 | CE38: 316903.04 | CF38: 99837 | CG38: 26060 | CH38: 741040.34 | CI38: 2639292 | CJ38: 499926
