Workbook
Name ALLOC_BRAND_CAMP: ALLOC!$C$8
Name ALLOC_CAMP_CLASS: ALLOC!$C$9
Name ALLOC_GRP_BRAND: ALLOC!$C$6
Name ALLOC_GRP_MARQUE: ALLOC!$C$7

Sheet ALLOC
N1: =IF($C$6="Chiffre d'affaires","REV_CA",IF($C$6="Nombre de classes","VOL_CLASS","VOL_EFF")) -> VOL_EFF
B2: 3 · Allocation & RENTABILITE — cout complet du groupe a la classe | N2: =IF($C$7="Chiffre d'affaires","REV_CA",IF($C$7="Nombre de classes","VOL_CLASS","VOL_EFF")) -> VOL_EFF
N3: =IF($C$8="Chiffre d'affaires","REV_CA",IF($C$8="Nombre de classes","VOL_CLASS","VOL_EFF")) -> REV_CA
N4: =IF($C$9="Chiffre d'affaires","REV_CA",IF($C$9="Nombre de classes","VOL_CLASS","VOL_EFF")) -> VOL_EFF
B5: Cles d'Allocation222 (saisie)
B6: Clé d’allocation siège administratif → marque | C6: Effectif
B7: Clé d’allocation Campus → Classe | C7: Effectif
B8: Clé d’allocation Marque → Campus | C8: Chiffre d'affaires
B9: Clé d’allocation Pub de marque → marque | C9: Effectif
B14: Maille fine — deplie campus/classe avec les [+]
B17: Marque ▸ Campus ▸ Classe | C17: Effectif | D17: CA | E17: VAC | F17: PERM | G17: ODIR | H17: STRUCT | I17: Frais marque | J17: Holding | K17: Cout complet | L17: Marge complete | M17: Marge %
B18: MBway | C18: =SUMIFS(_CALC_ALLOC!$G$1:$G$175,_CALC_ALLOC!$A$1:$A$175,"2026",_CALC_ALLOC!$C$1:$C$175,"MBWAY") -> 0 | D18: =SUMIFS(_CALC_ALLOC!$I$1:$I$175,_CALC_ALLOC!$A$1:$A$175,"2026",_CALC_ALLOC!$C$1:$C$175,"MBWAY") -> 0 | E18: =SUMIFS(_CALC_ALLOC!$AI$1:$AI$175,_CALC_ALLOC!$A$1:$A$175,"2026",_CALC_ALLOC!$C$1:$C$175,"MBWAY") -> 0 | F18: =SUMIFS(_CALC_ALLOC!$AJ$1:$AJ$175,_CALC_ALLOC!$A$1:$A$175,"2026",_CALC_ALLOC!$C$1:$C$175,"MBWAY") -> 0 | G18: =SUMIFS(_CALC_ALLOC!$AK$1:$AK$175,_CALC_ALLOC!$A$1:$A$175,"2026",_CALC_ALLOC!$C$1:$C$175,"MBWAY") -> 0 | H18: =SUMIFS(_CALC_ALLOC!$AL$1:$AL$175,_CALC_ALLOC!$A$1:$A$175,"2026",_CALC_ALLOC!$C$1:$C$175,"MBWAY") -> 0 | I18: =SUMIFS(_CALC_ALLOC!$AR$1:$AR$175,_CALC_ALLOC!$A$1:$A$175,"2026",_CALC_ALLOC!$C$1:$C$175,"MBWAY") -> 0 | J18: =SUMIFS(_CALC_ALLOC!$AM$1:$AM$175,_CALC_ALLOC!$A$1:$A$175,"2026",_CALC_ALLOC!$C$1:$C$175,"MBWAY") -> 0 | K18: =E18+F18+G18+H18+I18+J18 -> 0 | L18: =SUMIFS(_CALC_ALLOC!$AN$1:$AN$175,_CALC_ALLOC!$A$1:$A$175,"2026",_CALC_ALLOC!$C$1:$C$175,"MBWAY") -> 0 | M18: =IFERROR(L18/D18,0) -> 0
B19: Paris (MBWAY_PAR) | C19: =SUMIFS(_CALC_ALLOC!$G$1:$G$175,_CALC_ALLOC!$A$1:$A$175,"2026",_CALC_ALLOC!$B$1:$B$175,"MBWAY_PAR") -> 0 | D19: =SUMIFS(_CALC_ALLOC!$I$1:$I$175,_CALC_ALLOC!$A$1:$A$175,"2026",_CALC_ALLOC!$B$1:$B$175,"MBWAY_PAR") -> 0 | E19: =SUMIFS(_CALC_ALLOC!$AI$1:$AI$175,_CALC_ALLOC!$A$1:$A$175,"2026",_CALC_ALLOC!$B$1:$B$175,"MBWAY_PAR") -> 0 | F19: =SUMIFS(_CALC_ALLOC!$AJ$1:$AJ$175,_CALC_ALLOC!$A$1:$A$175,"2026",_CALC_ALLOC!$B$1:$B$175,"MBWAY_PAR") -> 0 | G19: =SUMIFS(_CALC_ALLOC!$AK$1:$AK$175,_CALC_ALLOC!$A$1:$A$175,"2026",_CALC_ALLOC!$B$1:$B$175,"MBWAY_PAR") -> 0 | H19: =SUMIFS(_CALC_ALLOC!$AL$1:$AL$175,_CALC_ALLOC!$A$1:$A$175,"2026",_CALC_ALLOC!$B$1:$B$175,"MBWAY_PAR") -> 0 | I19: =SUMIFS(_CALC_ALLOC!$AR$1:$AR$175,_CALC_ALLOC!$A$1:$A$175,"2026",_CALC_ALLOC!$B$1:$B$175,"MBWAY_PAR") -> 0 | J19: =SUMIFS(_CALC_ALLOC!$AM$1:$AM$175,_CALC_ALLOC!$A$1:$A$175,"2026",_CALC_ALLOC!$B$1:$B$175,"MBWAY_PAR") -> 0 | K19: =E19+F19+G19+H19+I19+J19 -> 0 | L19: =SUMIFS(_CALC_ALLOC!$AN$1:$AN$175,_CALC_ALLOC!$A$1:$A$175,"2026",_CALC_ALLOC!$B$1:$B$175,"MBWAY_PAR") -> 0 | M19: =IFERROR(L19/D19,0) -> 0
B20: BAC_MGT B1 INIT | C20: =SUMIFS(_CALC_ALLOC!$G$1:$G$175,_CALC_ALLOC!$A$1:$A$175,"2026",_CALC_ALLOC!$B$1:$B$175,"MBWAY_PAR",_CALC_ALLOC!$D$1:$D$175,"BAC_MGT",_CALC_ALLOC!$E$1:$E$175,"B1",_CALC_ALLOC!$F$1:$F$175,"INIT") -> 0 | D20: =SUMIFS(_CALC_ALLOC!$I$1:$I$175,_CALC_ALLOC!$A$1:$A$175,"2026",_CALC_ALLOC!$B$1:$B$175,"MBWAY_PAR",_CALC_ALLOC!$D$1:$D$175,"BAC_MGT",_CALC_ALLOC!$E$1:$E$175,"B1",_CALC_ALLOC!$F$1:$F$175,"INIT") -> 0 | E20: =SUMIFS(_CALC_ALLOC!$AI$1:$AI$175,_CALC_ALLOC!$A$1:$A$175,"2026",_CALC_ALLOC!$B$1:$B$175,"MBWAY_PAR",_CALC_ALLOC!$D$1:$D$175,"BAC_MGT",_CALC_ALLOC!$E$1:$E$175,"B1",_CALC_ALLOC!$F$1:$F$175,"INIT") -> 0 | F20: =SUMIFS(_CALC_ALLOC!$AJ$1:$AJ$175,_CALC_ALLOC!$A$1:$A$175,"2026",_CALC_ALLOC!$B$1:$B$175,"MBWAY_PAR",_CALC_ALLOC!$D$1:$D$175,"BAC_MGT",_CALC_ALLOC!$E$1:$E$175,"B1",_CALC_ALLOC!$F$1:$F$175,"INIT") -> 0 | G20: =SUMIFS(_CALC_ALLOC!$AK$1:$AK$175,_CALC_ALLOC!$A$1:$A$175,"2026",_CALC_ALLOC!$B$1:$B$175,"MBWAY_PAR",_CALC_ALLOC!$D$1:$D$175,"BAC_MGT",_CALC_ALLOC!$E$1:$E$175,"B1",_CALC_ALLOC!$F$1:$F$175,"INIT") -> 0 | H20: =SUMIFS(_CALC_ALLOC!$AL$1:$AL$175,_CALC_ALLOC!$A$1:$A$175,"2026",_CALC_ALLOC!$B$1:$B$175,"MBWAY_PAR",_CALC_ALLOC!$D$1:$D$175,"BAC_MGT",_CALC_ALLOC!$E$1:$E$175,"B1",_CALC_ALLOC!$F$1:$F$175,"INIT") -> 0 | I20: =SUMIFS(_CALC_ALLOC!$AR$1:$AR$175,_CALC_ALLOC!$A$1:$A$175,"2026",_CALC_ALLOC!$B$1:$B$175,"MBWAY_PAR",_CALC_ALLOC!$D$1:$D$175,"BAC_MGT",_CALC_ALLOC!$E$1:$E$175,"B1",_CALC_ALLOC!$F$1:$F$175,"INIT") -> 0 | J20: =SUMIFS(_CALC_ALLOC!$AM$1:$AM$175,_CALC_ALLOC!$A$1:$A$175,"2026",_CALC_ALLOC!$B$1:$B$175,"MBWAY_PAR",_CALC_ALLOC!$D$1:$D$175,"BAC_MGT",_CALC_ALLOC!$E$1:$E$175,"B1",_CALC_ALLOC!$F$1:$F$175,"INIT") -> 0 | K20: =E20+F20+G20+H20+I20+J20 -> 0 | L20: =SUMIFS(_CALC_ALLOC!$AN$1:$AN$175,_CALC_ALLOC!$A$1:$A$175,"2026",_CALC_ALLOC!$B$1:$B$175,"MBWAY_PAR",_CALC_ALLOC!$D$1:$D$175,"BAC_MGT",_CALC_ALLOC!$E$1:$E$175,"B1",_CALC_ALLOC!$F$1:$F$175,"INIT") -> 0 | M20: =IFERROR(L20/D20,0) -> 0
B21: BAC_MGT B2 ALT | C21: =SUMIFS(_CALC_ALLOC!$G$1:$G$175,_CALC_ALLOC!$A$1:$A$175,"2026",_CALC_ALLOC!$B$1:$B$175,"MBWAY_PAR",_CALC_ALLOC!$D$1:$D$175,"BAC_MGT",_CALC_ALLOC!$E$1:$E$175,"B2",_CALC_ALLOC!$F$1:$F$175,"ALT") -> 0 | D21: =SUMIFS(_CALC_ALLOC!$I$1:$I$175,_CALC_ALLOC!$A$1:$A$175,"2026",_CALC_ALLOC!$B$1:$B$175,"MBWAY_PAR",_CALC_ALLOC!$D$1:$D$175,"BAC_MGT",_CALC_ALLOC!$E$1:$E$175,"B2",_CALC_ALLOC!$F$1:$F$175,"ALT") -> 0 | E21: =SUMIFS(_CALC_ALLOC!$AI$1:$AI$175,_CALC_ALLOC!$A$1:$A$175,"2026",_CALC_ALLOC!$B$1:$B$175,"MBWAY_PAR",_CALC_ALLOC!$D$1:$D$175,"BAC_MGT",_CALC_ALLOC!$E$1:$E$175,"B2",_CALC_ALLOC!$F$1:$F$175,"ALT") -> 0 | F21: =SUMIFS(_CALC_ALLOC!$AJ$1:$AJ$175,_CALC_ALLOC!$A$1:$A$175,"2026",_CALC_ALLOC!$B$1:$B$175,"MBWAY_PAR",_CALC_ALLOC!$D$1:$D$175,"BAC_MGT",_CALC_ALLOC!$E$1:$E$175,"B2",_CALC_ALLOC!$F$1:$F$175,"ALT") -> 0 | G21: =SUMIFS(_CALC_ALLOC!$AK$1:$AK$175,_CALC_ALLOC!$A$1:$A$175,"2026",_CALC_ALLOC!$B$1:$B$175,"MBWAY_PAR",_CALC_ALLOC!$D$1:$D$175,"BAC_MGT",_CALC_ALLOC!$E$1:$E$175,"B2",_CALC_ALLOC!$F$1:$F$175,"ALT") -> 0 | H21: =SUMIFS(_CALC_ALLOC!$AL$1:$AL$175,_CALC_ALLOC!$A$1:$A$175,"2026",_CALC_ALLOC!$B$1:$B$175,"MBWAY_PAR",_CALC_ALLOC!$D$1:$D$175,"BAC_MGT",_CALC_ALLOC!$E$1:$E$175,"B2",_CALC_ALLOC!$F$1:$F$175,"ALT") -> 0 | I21: =SUMIFS(_CALC_ALLOC!$AR$1:$AR$175,_CALC_ALLOC!$A$1:$A$175,"2026",_CALC_ALLOC!$B$1:$B$175,"MBWAY_PAR",_CALC_ALLOC!$D$1:$D$175,"BAC_MGT",_CALC_ALLOC!$E$1:$E$175,"B2",_CALC_ALLOC!$F$1:$F$175,"ALT") -> 0 | J21: =SUMIFS(_CALC_ALLOC!$AM$1:$AM$175,_CALC_ALLOC!$A$1:$A$175,"2026",_CALC_ALLOC!$B$1:$B$175,"MBWAY_PAR",_CALC_ALLOC!$D$1:$D$175,"BAC_MGT",_CALC_ALLOC!$E$1:$E$175,"B2",_CALC_ALLOC!$F$1:$F$175,"ALT") -> 0 | K21: =E21+F21+G21+H21+I21+J21 -> 0 | L21: =SUMIFS(_CALC_ALLOC!$AN$1:$AN$175,_CALC_ALLOC!$A$1:$A$175,"2026",_CALC_ALLOC!$B$1:$B$175,"MBWAY_PAR",_CALC_ALLOC!$D$1:$D$175,"BAC_MGT",_CALC_ALLOC!$E$1:$E$175,"B2",_CALC_ALLOC!$F$1:$F$175,"ALT") -> 0 | M21: =IFERROR(L21/D21,0) -> 0
B22: BAC_MGT B3 ALT | C22: =SUMIFS(_CALC_ALLOC!$G$1:$G$175,_CALC_ALLOC!$A$1:$A$175,"2026",_CALC_ALLOC!$B$1:$B$175,"MBWAY_PAR",_CALC_ALLOC!$D$1:$D$175,"BAC_MGT",_CALC_ALLOC!$E$1:$E$175,"B3",_CALC_ALLOC!$F$1:$F$175,"ALT") -> 0 | D22: =SUMIFS(_CALC_ALLOC!$I$1:$I$175,_CALC_ALLOC!$A$1:$A$175,"2026",_CALC_ALLOC!$B$1:$B$175,"MBWAY_PAR",_CALC_ALLOC!$D$1:$D$175,"BAC_MGT",_CALC_ALLOC!$E$1:$E$175,"B3",_CALC_ALLOC!$F$1:$F$175,"ALT") -> 0 | E22: =SUMIFS(_CALC_ALLOC!$AI$1:$AI$175,_CALC_ALLOC!$A$1:$A$175,"2026",_CALC_ALLOC!$B$1:$B$175,"MBWAY_PAR",_CALC_ALLOC!$D$1:$D$175,"BAC_MGT",_CALC_ALLOC!$E$1:$E$175,"B3",_CALC_ALLOC!$F$1:$F$175,"ALT") -> 0 | F22: =SUMIFS(_CALC_ALLOC!$AJ$1:$AJ$175,_CALC_ALLOC!$A$1:$A$175,"2026",_CALC_ALLOC!$B$1:$B$175,"MBWAY_PAR",_CALC_ALLOC!$D$1:$D$175,"BAC_MGT",_CALC_ALLOC!$E$1:$E$175,"B3",_CALC_ALLOC!$F$1:$F$175,"ALT") -> 0 | G22: =SUMIFS(_CALC_ALLOC!$AK$1:$AK$175,_CALC_ALLOC!$A$1:$A$175,"2026",_CALC_ALLOC!$B$1:$B$175,"MBWAY_PAR",_CALC_ALLOC!$D$1:$D$175,"BAC_MGT",_CALC_ALLOC!$E$1:$E$175,"B3",_CALC_ALLOC!$F$1:$F$175,"ALT") -> 0 | H22: =SUMIFS(_CALC_ALLOC!$AL$1:$AL$175,_CALC_ALLOC!$A$1:$A$175,"2026",_CALC_ALLOC!$B$1:$B$175,"MBWAY_PAR",_CALC_ALLOC!$D$1:$D$175,"BAC_MGT",_CALC_ALLOC!$E$1:$E$175,"B3",_CALC_ALLOC!$F$1:$F$175,"ALT") -> 0 | I22: =SUMIFS(_CALC_ALLOC!$AR$1:$AR$175,_CALC_ALLOC!$A$1:$A$175,"2026",_CALC_ALLOC!$B$1:$B$175,"MBWAY_PAR",_CALC_ALLOC!$D$1:$D$175,"BAC_MGT",_CALC_ALLOC!$E$1:$E$175,"B3",_CALC_ALLOC!$F$1:$F$175,"ALT") -> 0 | J22: =SUMIFS(_CALC_ALLOC!$AM$1:$AM$175,_CALC_ALLOC!$A$1:$A$175,"2026",_CALC_ALLOC!$B$1:$B$175,"MBWAY_PAR",_CALC_ALLOC!$D$1:$D$175,"BAC_MGT",_CALC_ALLOC!$E$1:$E$175,"B3",_CALC_ALLOC!$F$1:$F$175,"ALT") -> 0 | K22: =E22+F22+G22+H22+I22+J22 -> 0 | L22: =SUMIFS(_CALC_ALLOC!$AN$1:$AN$175,_CALC_ALLOC!$A$1:$A$175,"2026",_CALC_ALLOC!$B$1:$B$175,"MBWAY_PAR",_CALC_ALLOC!$D$1:$D$175,"BAC_MGT",_CALC_ALLOC!$E$1:$E$175,"B3",_CALC_ALLOC!$F$1:$F$175,"ALT") -> 0 | M22: =IFERROR(L22/D22,0) -> 0
B23: MAS_MGT M1 ALT | C23: =SUMIFS(_CALC_ALLOC!$G$1:$G$175,_CALC_ALLOC!$A$1:$A$175,"2026",_CALC_ALLOC!$B$1:$B$175,"MBWAY_PAR",_CALC_ALLOC!$D$1:$D$175,"MAS_MGT",_CALC_ALLOC!$E$1:$E$175,"M1",_CALC_ALLOC!$F$1:$F$175,"ALT") -> 0 | D23: =SUMIFS(_CALC_ALLOC!$I$1:$I$175,_CALC_ALLOC!$A$1:$A$175,"2026",_CALC_ALLOC!$B$1:$B$175,"MBWAY_PAR",_CALC_ALLOC!$D$1:$D$175,"MAS_MGT",_CALC_ALLOC!$E$1:$E$175,"M1",_CALC_ALLOC!$F$1:$F$175,"ALT") -> 0 | E23: =SUMIFS(_CALC_ALLOC!$AI$1:$AI$175,_CALC_ALLOC!$A$1:$A$175,"2026",_CALC_ALLOC!$B$1:$B$175,"MBWAY_PAR",_CALC_ALLOC!$D$1:$D$175,"MAS_MGT",_CALC_ALLOC!$E$1:$E$175,"M1",_CALC_ALLOC!$F$1:$F$175,"ALT") -> 0 | F23: =SUMIFS(_CALC_ALLOC!$AJ$1:$AJ$175,_CALC_ALLOC!$A$1:$A$175,"2026",_CALC_ALLOC!$B$1:$B$175,"MBWAY_PAR",_CALC_ALLOC!$D$1:$D$175,"MAS_MGT",_CALC_ALLOC!$E$1:$E$175,"M1",_CALC_ALLOC!$F$1:$F$175,"ALT") -> 0 | G23: =SUMIFS(_CALC_ALLOC!$AK$1:$AK$175,_CALC_ALLOC!$A$1:$A$175,"2026",_CALC_ALLOC!$B$1:$B$175,"MBWAY_PAR",_CALC_ALLOC!$D$1:$D$175,"MAS_MGT",_CALC_ALLOC!$E$1:$E$175,"M1",_CALC_ALLOC!$F$1:$F$175,"ALT") -> 0 | H23: =SUMIFS(_CALC_ALLOC!$AL$1:$AL$175,_CALC_ALLOC!$A$1:$A$175,"2026",_CALC_ALLOC!$B$1:$B$175,"MBWAY_PAR",_CALC_ALLOC!$D$1:$D$175,"MAS_MGT",_CALC_ALLOC!$E$1:$E$175,"M1",_CALC_ALLOC!$F$1:$F$175,"ALT") -> 0 | I23: =SUMIFS(_CALC_ALLOC!$AR$1:$AR$175,_CALC_ALLOC!$A$1:$A$175,"2026",_CALC_ALLOC!$B$1:$B$175,"MBWAY_PAR",_CALC_ALLOC!$D$1:$D$175,"MAS_MGT",_CALC_ALLOC!$E$1:$E$175,"M1",_CALC_ALLOC!$F$1:$F$175,"ALT") -> 0 | J23: =SUMIFS(_CALC_ALLOC!$AM$1:$AM$175,_CALC_ALLOC!$A$1:$A$175,"2026",_CALC_ALLOC!$B$1:$B$175,"MBWAY_PAR",_CALC_ALLOC!$D$1:$D$175,"MAS_MGT",_CALC_ALLOC!$E$1:$E$175,"M1",_CALC_ALLOC!$F$1:$F$175,"ALT") -> 0 | K23: =E23+F23+G23+H23+I23+J23 -> 0 | L23: =SUMIFS(_CALC_ALLOC!$AN$1:$AN$175,_CALC_ALLOC!$A$1:$A$175,"2026",_CALC_ALLOC!$B$1:$B$175,"MBWAY_PAR",_CALC_ALLOC!$D$1:$D$175,"MAS_MGT",_CALC_ALLOC!$E$1:$E$175,"M1",_CALC_ALLOC!$F$1:$F$175,"ALT") -> 0 | M23: =IFERROR(L23/D23,0) -> 0
B24: MAS_MGT M2 ALT | C24: =SUMIFS(_CALC_ALLOC!$G$1:$G$175,_CALC_ALLOC!$A$1:$A$175,"2026",_CALC_ALLOC!$B$1:$B$175,"MBWAY_PAR",_CALC_ALLOC!$D$1:$D$175,"MAS_MGT",_CALC_ALLOC!$E$1:$E$175,"M2",_CALC_ALLOC!$F$1:$F$175,"ALT") -> 0 | D24: =SUMIFS(_CALC_ALLOC!$I$1:$I$175,_CALC_ALLOC!$A$1:$A$175,"2026",_CALC_ALLOC!$B$1:$B$175,"MBWAY_PAR",_CALC_ALLOC!$D$1:$D$175,"MAS_MGT",_CALC_ALLOC!$E$1:$E$175,"M2",_CALC_ALLOC!$F$1:$F$175,"ALT") -> 0 | E24: =SUMIFS(_CALC_ALLOC!$AI$1:$AI$175,_CALC_ALLOC!$A$1:$A$175,"2026",_CALC_ALLOC!$B$1:$B$175,"MBWAY_PAR",_CALC_ALLOC!$D$1:$D$175,"MAS_MGT",_CALC_ALLOC!$E$1:$E$175,"M2",_CALC_ALLOC!$F$1:$F$175,"ALT") -> 0 | F24: =SUMIFS(_CALC_ALLOC!$AJ$1:$AJ$175,_CALC_ALLOC!$A$1:$A$175,"2026",_CALC_ALLOC!$B$1:$B$175,"MBWAY_PAR",_CALC_ALLOC!$D$1:$D$175,"MAS_MGT",_CALC_ALLOC!$E$1:$E$175,"M2",_CALC_ALLOC!$F$1:$F$175,"ALT") -> 0 | G24: =SUMIFS(_CALC_ALLOC!$AK$1:$AK$175,_CALC_ALLOC!$A$1:$A$175,"2026",_CALC_ALLOC!$B$1:$B$175,"MBWAY_PAR",_CALC_ALLOC!$D$1:$D$175,"MAS_MGT",_CALC_ALLOC!$E$1:$E$175,"M2",_CALC_ALLOC!$F$1:$F$175,"ALT") -> 0 | H24: =SUMIFS(_CALC_ALLOC!$AL$1:$AL$175,_CALC_ALLOC!$A$1:$A$175,"2026",_CALC_ALLOC!$B$1:$B$175,"MBWAY_PAR",_CALC_ALLOC!$D$1:$D$175,"MAS_MGT",_CALC_ALLOC!$E$1:$E$175,"M2",_CALC_ALLOC!$F$1:$F$175,"ALT") -> 0 | I24: =SUMIFS(_CALC_ALLOC!$AR$1:$AR$175,_CALC_ALLOC!$A$1:$A$175,"2026",_CALC_ALLOC!$B$1:$B$175,"MBWAY_PAR",_CALC_ALLOC!$D$1:$D$175,"MAS_MGT",_CALC_ALLOC!$E$1:$E$175,"M2",_CALC_ALLOC!$F$1:$F$175,"ALT") -> 0 | J24: =SUMIFS(_CALC_ALLOC!$AM$1:$AM$175,_CALC_ALLOC!$A$1:$A$175,"2026",_CALC_ALLOC!$B$1:$B$175,"MBWAY_PAR",_CALC_ALLOC!$D$1:$D$175,"MAS_MGT",_CALC_ALLOC!$E$1:$E$175,"M2",_CALC_ALLOC!$F$1:$F$175,"ALT") -> 0 | K24: =E24+F24+G24+H24+I24+J24 -> 0 | L24: =SUMIFS(_CALC_ALLOC!$AN$1:$AN$175,_CALC_ALLOC!$A$1:$A$175,"2026",_CALC_ALLOC!$B$1:$B$175,"MBWAY_PAR",_CALC_ALLOC!$D$1:$D$175,"MAS_MGT",_CALC_ALLOC!$E$1:$E$175,"M2",_CALC_ALLOC!$F$1:$F$175,"ALT") -> 0 | M24: =IFERROR(L24/D24,0) -> 0
B25: Lyon (MBWAY_LYO) | C25: =SUMIFS(_CALC_ALLOC!$G$1:$G$175,_CALC_ALLOC!$A$1:$A$175,"2026",_CALC_ALLOC!$B$1:$B$175,"MBWAY_LYO") -> 0 | D25: =SUMIFS(_CALC_ALLOC!$I$1:$I$175,_CALC_ALLOC!$A$1:$A$175,"2026",_CALC_ALLOC!$B$1:$B$175,"MBWAY_LYO") -> 0 | E25: =SUMIFS(_CALC_ALLOC!$AI$1:$AI$175,_CALC_ALLOC!$A$1:$A$175,"2026",_CALC_ALLOC!$B$1:$B$175,"MBWAY_LYO") -> 0 | F25: =SUMIFS(_CALC_ALLOC!$AJ$1:$AJ$175,_CALC_ALLOC!$A$1:$A$175,"2026",_CALC_ALLOC!$B$1:$B$175,"MBWAY_LYO") -> 0 | G25: =SUMIFS(_CALC_ALLOC!$AK$1:$AK$175,_CALC_ALLOC!$A$1:$A$175,"2026",_CALC_ALLOC!$B$1:$B$175,"MBWAY_LYO") -> 0 | H25: =SUMIFS(_CALC_ALLOC!$AL$1:$AL$175,_CALC_ALLOC!$A$1:$A$175,"2026",_CALC_ALLOC!$B$1:$B$175,"MBWAY_LYO") -> 0 | I25: =SUMIFS(_CALC_ALLOC!$AR$1:$AR$175,_CALC_ALLOC!$A$1:$A$175,"2026",_CALC_ALLOC!$B$1:$B$175,"MBWAY_LYO") -> 0 | J25: =SUMIFS(_CALC_ALLOC!$AM$1:$AM$175,_CALC_ALLOC!$A$1:$A$175,"2026",_CALC_ALLOC!$B$1:$B$175,"MBWAY_LYO") -> 0 | K25: =E25+F25+G25+H25+I25+J25 -> 0 | L25: =SUMIFS(_CALC_ALLOC!$AN$1:$AN$175,_CALC_ALLOC!$A$1:$A$175,"2026",_CALC_ALLOC!$B$1:$B$175,"MBWAY_LYO") -> 0 | M25: =IFERROR(L25/D25,0) -> 0
B26: BAC_MGT B1 INIT | C26: =SUMIFS(_CALC_ALLOC!$G$1:$G$175,_CALC_ALLOC!$A$1:$A$175,"2026",_CALC_ALLOC!$B$1:$B$175,"MBWAY_LYO",_CALC_ALLOC!$D$1:$D$175,"BAC_MGT",_CALC_ALLOC!$E$1:$E$175,"B1",_CALC_ALLOC!$F$1:$F$175,"INIT") -> 0 | D26: =SUMIFS(_CALC_ALLOC!$I$1:$I$175,_CALC_ALLOC!$A$1:$A$175,"2026",_CALC_ALLOC!$B$1:$B$175,"MBWAY_LYO",_CALC_ALLOC!$D$1:$D$175,"BAC_MGT",_CALC_ALLOC!$E$1:$E$175,"B1",_CALC_ALLOC!$F$1:$F$175,"INIT") -> 0 | E26: =SUMIFS(_CALC_ALLOC!$AI$1:$AI$175,_CALC_ALLOC!$A$1:$A$175,"2026",_CALC_ALLOC!$B$1:$B$175,"MBWAY_LYO",_CALC_ALLOC!$D$1:$D$175,"BAC_MGT",_CALC_ALLOC!$E$1:$E$175,"B1",_CALC_ALLOC!$F$1:$F$175,"INIT") -> 0 | F26: =SUMIFS(_CALC_ALLOC!$AJ$1:$AJ$175,_CALC_ALLOC!$A$1:$A$175,"2026",_CALC_ALLOC!$B$1:$B$175,"MBWAY_LYO",_CALC_ALLOC!$D$1:$D$175,"BAC_MGT",_CALC_ALLOC!$E$1:$E$175,"B1",_CALC_ALLOC!$F$1:$F$175,"INIT") -> 0 | G26: =SUMIFS(_CALC_ALLOC!$AK$1:$AK$175,_CALC_ALLOC!$A$1:$A$175,"2026",_CALC_ALLOC!$B$1:$B$175,"MBWAY_LYO",_CALC_ALLOC!$D$1:$D$175,"BAC_MGT",_CALC_ALLOC!$E$1:$E$175,"B1",_CALC_ALLOC!$F$1:$F$175,"INIT") -> 0 | H26: =SUMIFS(_CALC_ALLOC!$AL$1:$AL$175,_CALC_ALLOC!$A$1:$A$175,"2026",_CALC_ALLOC!$B$1:$B$175,"MBWAY_LYO",_CALC_ALLOC!$D$1:$D$175,"BAC_MGT",_CALC_ALLOC!$E$1:$E$175,"B1",_CALC_ALLOC!$F$1:$F$175,"INIT") -> 0 | I26: =SUMIFS(_CALC_ALLOC!$AR$1:$AR$175,_CALC_ALLOC!$A$1:$A$175,"2026",_CALC_ALLOC!$B$1:$B$175,"MBWAY_LYO",_CALC_ALLOC!$D$1:$D$175,"BAC_MGT",_CALC_ALLOC!$E$1:$E$175,"B1",_CALC_ALLOC!$F$1:$F$175,"INIT") -> 0 | J26: =SUMIFS(_CALC_ALLOC!$AM$1:$AM$175,_CALC_ALLOC!$A$1:$A$175,"2026",_CALC_ALLOC!$B$1:$B$175,"MBWAY_LYO",_CALC_ALLOC!$D$1:$D$175,"BAC_MGT",_CALC_ALLOC!$E$1:$E$175,"B1",_CALC_ALLOC!$F$1:$F$175,"INIT") -> 0 | K26: =E26+F26+G26+H26+I26+J26 -> 0 | L26: =SUMIFS(_CALC_ALLOC!$AN$1:$AN$175,_CALC_ALLOC!$A$1:$A$175,"2026",_CALC_ALLOC!$B$1:$B$175,"MBWAY_LYO",_CALC_ALLOC!$D$1:$D$175,"BAC_MGT",_CALC_ALLOC!$E$1:$E$175,"B1",_CALC_ALLOC!$F$1:$F$175,"INIT") -> 0 | M26: =IFERROR(L26/D26,0) -> 0
B27: BAC_MGT B2 ALT | C27: =SUMIFS(_CALC_ALLOC!$G$1:$G$175,_CALC_ALLOC!$A$1:$A$175,"2026",_CALC_ALLOC!$B$1:$B$175,"MBWAY_LYO",_CALC_ALLOC!$D$1:$D$175,"BAC_MGT",_CALC_ALLOC!$E$1:$E$175,"B2",_CALC_ALLOC!$F$1:$F$175,"ALT") -> 0 | D27: =SUMIFS(_CALC_ALLOC!$I$1:$I$175,_CALC_ALLOC!$A$1:$A$175,"2026",_CALC_ALLOC!$B$1:$B$175,"MBWAY_LYO",_CALC_ALLOC!$D$1:$D$175,"BAC_MGT",_CALC_ALLOC!$E$1:$E$175,"B2",_CALC_ALLOC!$F$1:$F$175,"ALT") -> 0 | E27: =SUMIFS(_CALC_ALLOC!$AI$1:$AI$175,_CALC_ALLOC!$A$1:$A$175,"2026",_CALC_ALLOC!$B$1:$B$175,"MBWAY_LYO",_CALC_ALLOC!$D$1:$D$175,"BAC_MGT",_CALC_ALLOC!$E$1:$E$175,"B2",_CALC_ALLOC!$F$1:$F$175,"ALT") -> 0 | F27: =SUMIFS(_CALC_ALLOC!$AJ$1:$AJ$175,_CALC_ALLOC!$A$1:$A$175,"2026",_CALC_ALLOC!$B$1:$B$175,"MBWAY_LYO",_CALC_ALLOC!$D$1:$D$175,"BAC_MGT",_CALC_ALLOC!$E$1:$E$175,"B2",_CALC_ALLOC!$F$1:$F$175,"ALT") -> 0 | G27: =SUMIFS(_CALC_ALLOC!$AK$1:$AK$175,_CALC_ALLOC!$A$1:$A$175,"2026",_CALC_ALLOC!$B$1:$B$175,"MBWAY_LYO",_CALC_ALLOC!$D$1:$D$175,"BAC_MGT",_CALC_ALLOC!$E$1:$E$175,"B2",_CALC_ALLOC!$F$1:$F$175,"ALT") -> 0 | H27: =SUMIFS(_CALC_ALLOC!$AL$1:$AL$175,_CALC_ALLOC!$A$1:$A$175,"2026",_CALC_ALLOC!$B$1:$B$175,"MBWAY_LYO",_CALC_ALLOC!$D$1:$D$175,"BAC_MGT",_CALC_ALLOC!$E$1:$E$175,"B2",_CALC_ALLOC!$F$1:$F$175,"ALT") -> 0 | I27: =SUMIFS(_CALC_ALLOC!$AR$1:$AR$175,_CALC_ALLOC!$A$1:$A$175,"2026",_CALC_ALLOC!$B$1:$B$175,"MBWAY_LYO",_CALC_ALLOC!$D$1:$D$175,"BAC_MGT",_CALC_ALLOC!$E$1:$E$175,"B2",_CALC_ALLOC!$F$1:$F$175,"ALT") -> 0 | J27: =SUMIFS(_CALC_ALLOC!$AM$1:$AM$175,_CALC_ALLOC!$A$1:$A$175,"2026",_CALC_ALLOC!$B$1:$B$175,"MBWAY_LYO",_CALC_ALLOC!$D$1:$D$175,"BAC_MGT",_CALC_ALLOC!$E$1:$E$175,"B2",_CALC_ALLOC!$F$1:$F$175,"ALT") -> 0 | K27: =E27+F27+G27+H27+I27+J27 -> 0 | L27: =SUMIFS(_CALC_ALLOC!$AN$1:$AN$175,_CALC_ALLOC!$A$1:$A$175,"2026",_CALC_ALLOC!$B$1:$B$175,"MBWAY_LYO",_CALC_ALLOC!$D$1:$D$175,"BAC_MGT",_CALC_ALLOC!$E$1:$E$175,"B2",_CALC_ALLOC!$F$1:$F$175,"ALT") -> 0 | M27: =IFERROR(L27/D27,0) -> 0
B28: BAC_MGT B3 ALT | C28: =SUMIFS(_CALC_ALLOC!$G$1:$G$175,_CALC_ALLOC!$A$1:$A$175,"2026",_CALC_ALLOC!$B$1:$B$175,"MBWAY_LYO",_CALC_ALLOC!$D$1:$D$175,"BAC_MGT",_CALC_ALLOC!$E$1:$E$175,"B3",_CALC_ALLOC!$F$1:$F$175,"ALT") -> 0 | D28: =SUMIFS(_CALC_ALLOC!$I$1:$I$175,_CALC_ALLOC!$A$1:$A$175,"2026",_CALC_ALLOC!$B$1:$B$175,"MBWAY_LYO",_CALC_ALLOC!$D$1:$D$175,"BAC_MGT",_CALC_ALLOC!$E$1:$E$175,"B3",_CALC_ALLOC!$F$1:$F$175,"ALT") -> 0 | E28: =SUMIFS(_CALC_ALLOC!$AI$1:$AI$175,_CALC_ALLOC!$A$1:$A$175,"2026",_CALC_ALLOC!$B$1:$B$175,"MBWAY_LYO",_CALC_ALLOC!$D$1:$D$175,"BAC_MGT",_CALC_ALLOC!$E$1:$E$175,"B3",_CALC_ALLOC!$F$1:$F$175,"ALT") -> 0 | F28: =SUMIFS(_CALC_ALLOC!$AJ$1:$AJ$175,_CALC_ALLOC!$A$1:$A$175,"2026",_CALC_ALLOC!$B$1:$B$175,"MBWAY_LYO",_CALC_ALLOC!$D$1:$D$175,"BAC_MGT",_CALC_ALLOC!$E$1:$E$175,"B3",_CALC_ALLOC!$F$1:$F$175,"ALT") -> 0 | G28: =SUMIFS(_CALC_ALLOC!$AK$1:$AK$175,_CALC_ALLOC!$A$1:$A$175,"2026",_CALC_ALLOC!$B$1:$B$175,"MBWAY_LYO",_CALC_ALLOC!$D$1:$D$175,"BAC_MGT",_CALC_ALLOC!$E$1:$E$175,"B3",_CALC_ALLOC!$F$1:$F$175,"ALT") -> 0 | H28: =SUMIFS(_CALC_ALLOC!$AL$1:$AL$175,_CALC_ALLOC!$A$1:$A$175,"2026",_CALC_ALLOC!$B$1:$B$175,"MBWAY_LYO",_CALC_ALLOC!$D$1:$D$175,"BAC_MGT",_CALC_ALLOC!$E$1:$E$175,"B3",_CALC_ALLOC!$F$1:$F$175,"ALT") -> 0 | I28: =SUMIFS(_CALC_ALLOC!$AR$1:$AR$175,_CALC_ALLOC!$A$1:$A$175,"2026",_CALC_ALLOC!$B$1:$B$175,"MBWAY_LYO",_CALC_ALLOC!$D$1:$D$175,"BAC_MGT",_CALC_ALLOC!$E$1:$E$175,"B3",_CALC_ALLOC!$F$1:$F$175,"ALT") -> 0 | J28: =SUMIFS(_CALC_ALLOC!$AM$1:$AM$175,_CALC_ALLOC!$A$1:$A$175,"2026",_CALC_ALLOC!$B$1:$B$175,"MBWAY_LYO",_CALC_ALLOC!$D$1:$D$175,"BAC_MGT",_CALC_ALLOC!$E$1:$E$175,"B3",_CALC_ALLOC!$F$1:$F$175,"ALT") -> 0 | K28: =E28+F28+G28+H28+I28+J28 -> 0 | L28: =SUMIFS(_CALC_ALLOC!$AN$1:$AN$175,_CALC_ALLOC!$A$1:$A$175,"2026",_CALC_ALLOC!$B$1:$B$175,"MBWAY_LYO",_CALC_ALLOC!$D$1:$D$175,"BAC_MGT",_CALC_ALLOC!$E$1:$E$175,"B3",_CALC_ALLOC!$F$1:$F$175,"ALT") -> 0 | M28: =IFERROR(L28/D28,0) -> 0
B29: MAS_MGT M1 ALT | C29: =SUMIFS(_CALC_ALLOC!$G$1:$G$175,_CALC_ALLOC!$A$1:$A$175,"2026",_CALC_ALLOC!$B$1:$B$175,"MBWAY_LYO",_CALC_ALLOC!$D$1:$D$175,"MAS_MGT",_CALC_ALLOC!$E$1:$E$175,"M1",_CALC_ALLOC!$F$1:$F$175,"ALT") -> 0 | D29: =SUMIFS(_CALC_ALLOC!$I$1:$I$175,_CALC_ALLOC!$A$1:$A$175,"2026",_CALC_ALLOC!$B$1:$B$175,"MBWAY_LYO",_CALC_ALLOC!$D$1:$D$175,"MAS_MGT",_CALC_ALLOC!$E$1:$E$175,"M1",_CALC_ALLOC!$F$1:$F$175,"ALT") -> 0 | E29: =SUMIFS(_CALC_ALLOC!$AI$1:$AI$175,_CALC_ALLOC!$A$1:$A$175,"2026",_CALC_ALLOC!$B$1:$B$175,"MBWAY_LYO",_CALC_ALLOC!$D$1:$D$175,"MAS_MGT",_CALC_ALLOC!$E$1:$E$175,"M1",_CALC_ALLOC!$F$1:$F$175,"ALT") -> 0 | F29: =SUMIFS(_CALC_ALLOC!$AJ$1:$AJ$175,_CALC_ALLOC!$A$1:$A$175,"2026",_CALC_ALLOC!$B$1:$B$175,"MBWAY_LYO",_CALC_ALLOC!$D$1:$D$175,"MAS_MGT",_CALC_ALLOC!$E$1:$E$175,"M1",_CALC_ALLOC!$F$1:$F$175,"ALT") -> 0 | G29: =SUMIFS(_CALC_ALLOC!$AK$1:$AK$175,_CALC_ALLOC!$A$1:$A$175,"2026",_CALC_ALLOC!$B$1:$B$175,"MBWAY_LYO",_CALC_ALLOC!$D$1:$D$175,"MAS_MGT",_CALC_ALLOC!$E$1:$E$175,"M1",_CALC_ALLOC!$F$1:$F$175,"ALT") -> 0 | H29: =SUMIFS(_CALC_ALLOC!$AL$1:$AL$175,_CALC_ALLOC!$A$1:$A$175,"2026",_CALC_ALLOC!$B$1:$B$175,"MBWAY_LYO",_CALC_ALLOC!$D$1:$D$175,"MAS_MGT",_CALC_ALLOC!$E$1:$E$175,"M1",_CALC_ALLOC!$F$1:$F$175,"ALT") -> 0 | I29: =SUMIFS(_CALC_ALLOC!$AR$1:$AR$175,_CALC_ALLOC!$A$1:$A$175,"2026",_CALC_ALLOC!$B$1:$B$175,"MBWAY_LYO",_CALC_ALLOC!$D$1:$D$175,"MAS_MGT",_CALC_ALLOC!$E$1:$E$175,"M1",_CALC_ALLOC!$F$1:$F$175,"ALT") -> 0 | J29: =SUMIFS(_CALC_ALLOC!$AM$1:$AM$175,_CALC_ALLOC!$A$1:$A$175,"2026",_CALC_ALLOC!$B$1:$B$175,"MBWAY_LYO",_CALC_ALLOC!$D$1:$D$175,"MAS_MGT",_CALC_ALLOC!$E$1:$E$175,"M1",_CALC_ALLOC!$F$1:$F$175,"ALT") -> 0 | K29: =E29+F29+G29+H29+I29+J29 -> 0 | L29: =SUMIFS(_CALC_ALLOC!$AN$1:$AN$175,_CALC_ALLOC!$A$1:$A$175,"2026",_CALC_ALLOC!$B$1:$B$175,"MBWAY_LYO",_CALC_ALLOC!$D$1:$D$175,"MAS_MGT",_CALC_ALLOC!$E$1:$E$175,"M1",_CALC_ALLOC!$F$1:$F$175,"ALT") -> 0 | M29: =IFERROR(L29/D29,0) -> 0
B30: MAS_MGT M2 ALT | C30: =SUMIFS(_CALC_ALLOC!$G$1:$G$175,_CALC_ALLOC!$A$1:$A$175,"2026",_CALC_ALLOC!$B$1:$B$175,"MBWAY_LYO",_CALC_ALLOC!$D$1:$D$175,"MAS_MGT",_CALC_ALLOC!$E$1:$E$175,"M2",_CALC_ALLOC!$F$1:$F$175,"ALT") -> 0 | D30: =SUMIFS(_CALC_ALLOC!$I$1:$I$175,_CALC_ALLOC!$A$1:$A$175,"2026",_CALC_ALLOC!$B$1:$B$175,"MBWAY_LYO",_CALC_ALLOC!$D$1:$D$175,"MAS_MGT",_CALC_ALLOC!$E$1:$E$175,"M2",_CALC_ALLOC!$F$1:$F$175,"ALT") -> 0 | E30: =SUMIFS(_CALC_ALLOC!$AI$1:$AI$175,_CALC_ALLOC!$A$1:$A$175,"2026",_CALC_ALLOC!$B$1:$B$175,"MBWAY_LYO",_CALC_ALLOC!$D$1:$D$175,"MAS_MGT",_CALC_ALLOC!$E$1:$E$175,"M2",_CALC_ALLOC!$F$1:$F$175,"ALT") -> 0 | F30: =SUMIFS(_CALC_ALLOC!$AJ$1:$AJ$175,_CALC_ALLOC!$A$1:$A$175,"2026",_CALC_ALLOC!$B$1:$B$175,"MBWAY_LYO",_CALC_ALLOC!$D$1:$D$175,"MAS_MGT",_CALC_ALLOC!$E$1:$E$175,"M2",_CALC_ALLOC!$F$1:$F$175,"ALT") -> 0 | G30: =SUMIFS(_CALC_ALLOC!$AK$1:$AK$175,_CALC_ALLOC!$A$1:$A$175,"2026",_CALC_ALLOC!$B$1:$B$175,"MBWAY_LYO",_CALC_ALLOC!$D$1:$D$175,"MAS_MGT",_CALC_ALLOC!$E$1:$E$175,"M2",_CALC_ALLOC!$F$1:$F$175,"ALT") -> 0 | H30: =SUMIFS(_CALC_ALLOC!$AL$1:$AL$175,_CALC_ALLOC!$A$1:$A$175,"2026",_CALC_ALLOC!$B$1:$B$175,"MBWAY_LYO",_CALC_ALLOC!$D$1:$D$175,"MAS_MGT",_CALC_ALLOC!$E$1:$E$175,"M2",_CALC_ALLOC!$F$1:$F$175,"ALT") -> 0 | I30: =SUMIFS(_CALC_ALLOC!$AR$1:$AR$175,_CALC_ALLOC!$A$1:$A$175,"2026",_CALC_ALLOC!$B$1:$B$175,"MBWAY_LYO",_CALC_ALLOC!$D$1:$D$175,"MAS_MGT",_CALC_ALLOC!$E$1:$E$175,"M2",_CALC_ALLOC!$F$1:$F$175,"ALT") -> 0 | J30: =SUMIFS(_CALC_ALLOC!$AM$1:$AM$175,_CALC_ALLOC!$A$1:$A$175,"2026",_CALC_ALLOC!$B$1:$B$175,"MBWAY_LYO",_CALC_ALLOC!$D$1:$D$175,"MAS_MGT",_CALC_ALLOC!$E$1:$E$175,"M2",_CALC_ALLOC!$F$1:$F$175,"ALT") -> 0 | K30: =E30+F30+G30+H30+I30+J30 -> 0 | L30: =SUMIFS(_CALC_ALLOC!$AN$1:$AN$175,_CALC_ALLOC!$A$1:$A$175,"2026",_CALC_ALLOC!$B$1:$B$175,"MBWAY_LYO",_CALC_ALLOC!$D$1:$D$175,"MAS_MGT",_CALC_ALLOC!$E$1:$E$175,"M2",_CALC_ALLOC!$F$1:$F$175,"ALT") -> 0 | M30: =IFERROR(L30/D30,0) -> 0
B31: Nantes (MBWAY_NAN) | C31: =SUMIFS(_CALC_ALLOC!$G$1:$G$175,_CALC_ALLOC!$A$1:$A$175,"2026",_CALC_ALLOC!$B$1:$B$175,"MBWAY_NAN") -> 0 | D31: =SUMIFS(_CALC_ALLOC!$I$1:$I$175,_CALC_ALLOC!$A$1:$A$175,"2026",_CALC_ALLOC!$B$1:$B$175,"MBWAY_NAN") -> 0 | E31: =SUMIFS(_CALC_ALLOC!$AI$1:$AI$175,_CALC_ALLOC!$A$1:$A$175,"2026",_CALC_ALLOC!$B$1:$B$175,"MBWAY_NAN") -> 0 | F31: =SUMIFS(_CALC_ALLOC!$AJ$1:$AJ$175,_CALC_ALLOC!$A$1:$A$175,"2026",_CALC_ALLOC!$B$1:$B$175,"MBWAY_NAN") -> 0 | G31: =SUMIFS(_CALC_ALLOC!$AK$1:$AK$175,_CALC_ALLOC!$A$1:$A$175,"2026",_CALC_ALLOC!$B$1:$B$175,"MBWAY_NAN") -> 0 | H31: =SUMIFS(_CALC_ALLOC!$AL$1:$AL$175,_CALC_ALLOC!$A$1:$A$175,"2026",_CALC_ALLOC!$B$1:$B$175,"MBWAY_NAN") -> 0 | I31: =SUMIFS(_CALC_ALLOC!$AR$1:$AR$175,_CALC_ALLOC!$A$1:$A$175,"2026",_CALC_ALLOC!$B$1:$B$175,"MBWAY_NAN") -> 0 | J31: =SUMIFS(_CALC_ALLOC!$AM$1:$AM$175,_CALC_ALLOC!$A$1:$A$175,"2026",_CALC_ALLOC!$B$1:$B$175,"MBWAY_NAN") -> 0 | K31: =E31+F31+G31+H31+I31+J31 -> 0 | L31: =SUMIFS(_CALC_ALLOC!$AN$1:$AN$175,_CALC_ALLOC!$A$1:$A$175,"2026",_CALC_ALLOC!$B$1:$B$175,"MBWAY_NAN") -> 0 | M31: =IFERROR(L31/D31,0) -> 0
B32: BAC_MGT B1 INIT | C32: =SUMIFS(_CALC_ALLOC!$G$1:$G$175,_CALC_ALLOC!$A$1:$A$175,"2026",_CALC_ALLOC!$B$1:$B$175,"MBWAY_NAN",_CALC_ALLOC!$D$1:$D$175,"BAC_MGT",_CALC_ALLOC!$E$1:$E$175,"B1",_CALC_ALLOC!$F$1:$F$175,"INIT") -> 0 | D32: =SUMIFS(_CALC_ALLOC!$I$1:$I$175,_CALC_ALLOC!$A$1:$A$175,"2026",_CALC_ALLOC!$B$1:$B$175,"MBWAY_NAN",_CALC_ALLOC!$D$1:$D$175,"BAC_MGT",_CALC_ALLOC!$E$1:$E$175,"B1",_CALC_ALLOC!$F$1:$F$175,"INIT") -> 0 | E32: =SUMIFS(_CALC_ALLOC!$AI$1:$AI$175,_CALC_ALLOC!$A$1:$A$175,"2026",_CALC_ALLOC!$B$1:$B$175,"MBWAY_NAN",_CALC_ALLOC!$D$1:$D$175,"BAC_MGT",_CALC_ALLOC!$E$1:$E$175,"B1",_CALC_ALLOC!$F$1:$F$175,"INIT") -> 0 | F32: =SUMIFS(_CALC_ALLOC!$AJ$1:$AJ$175,_CALC_ALLOC!$A$1:$A$175,"2026",_CALC_ALLOC!$B$1:$B$175,"MBWAY_NAN",_CALC_ALLOC!$D$1:$D$175,"BAC_MGT",_CALC_ALLOC!$E$1:$E$175,"B1",_CALC_ALLOC!$F$1:$F$175,"INIT") -> 0 | G32: =SUMIFS(_CALC_ALLOC!$AK$1:$AK$175,_CALC_ALLOC!$A$1:$A$175,"2026",_CALC_ALLOC!$B$1:$B$175,"MBWAY_NAN",_CALC_ALLOC!$D$1:$D$175,"BAC_MGT",_CALC_ALLOC!$E$1:$E$175,"B1",_CALC_ALLOC!$F$1:$F$175,"INIT") -> 0 | H32: =SUMIFS(_CALC_ALLOC!$AL$1:$AL$175,_CALC_ALLOC!$A$1:$A$175,"2026",_CALC_ALLOC!$B$1:$B$175,"MBWAY_NAN",_CALC_ALLOC!$D$1:$D$175,"BAC_MGT",_CALC_ALLOC!$E$1:$E$175,"B1",_CALC_ALLOC!$F$1:$F$175,"INIT") -> 0 | I32: =SUMIFS(_CALC_ALLOC!$AR$1:$AR$175,_CALC_ALLOC!$A$1:$A$175,"2026",_CALC_ALLOC!$B$1:$B$175,"MBWAY_NAN",_CALC_ALLOC!$D$1:$D$175,"BAC_MGT",_CALC_ALLOC!$E$1:$E$175,"B1",_CALC_ALLOC!$F$1:$F$175,"INIT") -> 0 | J32: =SUMIFS(_CALC_ALLOC!$AM$1:$AM$175,_CALC_ALLOC!$A$1:$A$175,"2026",_CALC_ALLOC!$B$1:$B$175,"MBWAY_NAN",_CALC_ALLOC!$D$1:$D$175,"BAC_MGT",_CALC_ALLOC!$E$1:$E$175,"B1",_CALC_ALLOC!$F$1:$F$175,"INIT") -> 0 | K32: =E32+F32+G32+H32+I32+J32 -> 0 | L32: =SUMIFS(_CALC_ALLOC!$AN$1:$AN$175,_CALC_ALLOC!$A$1:$A$175,"2026",_CALC_ALLOC!$B$1:$B$175,"MBWAY_NAN",_CALC_ALLOC!$D$1:$D$175,"BAC_MGT",_CALC_ALLOC!$E$1:$E$175,"B1",_CALC_ALLOC!$F$1:$F$175,"INIT") -> 0 | M32: =IFERROR(L32/D32,0) -> 0
B33: BAC_MGT B2 ALT | C33: =SUMIFS(_CALC_ALLOC!$G$1:$G$175,_CALC_ALLOC!$A$1:$A$175,"2026",_CALC_ALLOC!$B$1:$B$175,"MBWAY_NAN",_CALC_ALLOC!$D$1:$D$175,"BAC_MGT",_CALC_ALLOC!$E$1:$E$175,"B2",_CALC_ALLOC!$F$1:$F$175,"ALT") -> 0 | D33: =SUMIFS(_CALC_ALLOC!$I$1:$I$175,_CALC_ALLOC!$A$1:$A$175,"2026",_CALC_ALLOC!$B$1:$B$175,"MBWAY_NAN",_CALC_ALLOC!$D$1:$D$175,"BAC_MGT",_CALC_ALLOC!$E$1:$E$175,"B2",_CALC_ALLOC!$F$1:$F$175,"ALT") -> 0 | E33: =SUMIFS(_CALC_ALLOC!$AI$1:$AI$175,_CALC_ALLOC!$A$1:$A$175,"2026",_CALC_ALLOC!$B$1:$B$175,"MBWAY_NAN",_CALC_ALLOC!$D$1:$D$175,"BAC_MGT",_CALC_ALLOC!$E$1:$E$175,"B2",_CALC_ALLOC!$F$1:$F$175,"ALT") -> 0 | F33: =SUMIFS(_CALC_ALLOC!$AJ$1:$AJ$175,_CALC_ALLOC!$A$1:$A$175,"2026",_CALC_ALLOC!$B$1:$B$175,"MBWAY_NAN",_CALC_ALLOC!$D$1:$D$175,"BAC_MGT",_CALC_ALLOC!$E$1:$E$175,"B2",_CALC_ALLOC!$F$1:$F$175,"ALT") -> 0 | G33: =SUMIFS(_CALC_ALLOC!$AK$1:$AK$175,_CALC_ALLOC!$A$1:$A$175,"2026",_CALC_ALLOC!$B$1:$B$175,"MBWAY_NAN",_CALC_ALLOC!$D$1:$D$175,"BAC_MGT",_CALC_ALLOC!$E$1:$E$175,"B2",_CALC_ALLOC!$F$1:$F$175,"ALT") -> 0 | H33: =SUMIFS(_CALC_ALLOC!$AL$1:$AL$175,_CALC_ALLOC!$A$1:$A$175,"2026",_CALC_ALLOC!$B$1:$B$175,"MBWAY_NAN",_CALC_ALLOC!$D$1:$D$175,"BAC_MGT",_CALC_ALLOC!$E$1:$E$175,"B2",_CALC_ALLOC!$F$1:$F$175,"ALT") -> 0 | I33: =SUMIFS(_CALC_ALLOC!$AR$1:$AR$175,_CALC_ALLOC!$A$1:$A$175,"2026",_CALC_ALLOC!$B$1:$B$175,"MBWAY_NAN",_CALC_ALLOC!$D$1:$D$175,"BAC_MGT",_CALC_ALLOC!$E$1:$E$175,"B2",_CALC_ALLOC!$F$1:$F$175,"ALT") -> 0 | J33: =SUMIFS(_CALC_ALLOC!$AM$1:$AM$175,_CALC_ALLOC!$A$1:$A$175,"2026",_CALC_ALLOC!$B$1:$B$175,"MBWAY_NAN",_CALC_ALLOC!$D$1:$D$175,"BAC_MGT",_CALC_ALLOC!$E$1:$E$175,"B2",_CALC_ALLOC!$F$1:$F$175,"ALT") -> 0 | K33: =E33+F33+G33+H33+I33+J33 -> 0 | L33: =SUMIFS(_CALC_ALLOC!$AN$1:$AN$175,_CALC_ALLOC!$A$1:$A$175,"2026",_CALC_ALLOC!$B$1:$B$175,"MBWAY_NAN",_CALC_ALLOC!$D$1:$D$175,"BAC_MGT",_CALC_ALLOC!$E$1:$E$175,"B2",_CALC_ALLOC!$F$1:$F$175,"ALT") -> 0 | M33: =IFERROR(L33/D33,0) -> 0
B34: BAC_MGT B3 ALT | C34: =SUMIFS(_CALC_ALLOC!$G$1:$G$175,_CALC_ALLOC!$A$1:$A$175,"2026",_CALC_ALLOC!$B$1:$B$175,"MBWAY_NAN",_CALC_ALLOC!$D$1:$D$175,"BAC_MGT",_CALC_ALLOC!$E$1:$E$175,"B3",_CALC_ALLOC!$F$1:$F$175,"ALT") -> 0 | D34: =SUMIFS(_CALC_ALLOC!$I$1:$I$175,_CALC_ALLOC!$A$1:$A$175,"2026",_CALC_ALLOC!$B$1:$B$175,"MBWAY_NAN",_CALC_ALLOC!$D$1:$D$175,"BAC_MGT",_CALC_ALLOC!$E$1:$E$175,"B3",_CALC_ALLOC!$F$1:$F$175,"ALT") -> 0 | E34: =SUMIFS(_CALC_ALLOC!$AI$1:$AI$175,_CALC_ALLOC!$A$1:$A$175,"2026",_CALC_ALLOC!$B$1:$B$175,"MBWAY_NAN",_CALC_ALLOC!$D$1:$D$175,"BAC_MGT",_CALC_ALLOC!$E$1:$E$175,"B3",_CALC_ALLOC!$F$1:$F$175,"ALT") -> 0 | F34: =SUMIFS(_CALC_ALLOC!$AJ$1:$AJ$175,_CALC_ALLOC!$A$1:$A$175,"2026",_CALC_ALLOC!$B$1:$B$175,"MBWAY_NAN",_CALC_ALLOC!$D$1:$D$175,"BAC_MGT",_CALC_ALLOC!$E$1:$E$175,"B3",_CALC_ALLOC!$F$1:$F$175,"ALT") -> 0 | G34: =SUMIFS(_CALC_ALLOC!$AK$1:$AK$175,_CALC_ALLOC!$A$1:$A$175,"2026",_CALC_ALLOC!$B$1:$B$175,"MBWAY_NAN",_CALC_ALLOC!$D$1:$D$175,"BAC_MGT",_CALC_ALLOC!$E$1:$E$175,"B3",_CALC_ALLOC!$F$1:$F$175,"ALT") -> 0 | H34: =SUMIFS(_CALC_ALLOC!$AL$1:$AL$175,_CALC_ALLOC!$A$1:$A$175,"2026",_CALC_ALLOC!$B$1:$B$175,"MBWAY_NAN",_CALC_ALLOC!$D$1:$D$175,"BAC_MGT",_CALC_ALLOC!$E$1:$E$175,"B3",_CALC_ALLOC!$F$1:$F$175,"ALT") -> 0 | I34: =SUMIFS(_CALC_ALLOC!$AR$1:$AR$175,_CALC_ALLOC!$A$1:$A$175,"2026",_CALC_ALLOC!$B$1:$B$175,"MBWAY_NAN",_CALC_ALLOC!$D$1:$D$175,"BAC_MGT",_CALC_ALLOC!$E$1:$E$175,"B3",_CALC_ALLOC!$F$1:$F$175,"ALT") -> 0 | J34: =SUMIFS(_CALC_ALLOC!$AM$1:$AM$175,_CALC_ALLOC!$A$1:$A$175,"2026",_CALC_ALLOC!$B$1:$B$175,"MBWAY_NAN",_CALC_ALLOC!$D$1:$D$175,"BAC_MGT",_CALC_ALLOC!$E$1:$E$175,"B3",_CALC_ALLOC!$F$1:$F$175,"ALT") -> 0 | K34: =E34+F34+G34+H34+I34+J34 -> 0 | L34: =SUMIFS(_CALC_ALLOC!$AN$1:$AN$175,_CALC_ALLOC!$A$1:$A$175,"2026",_CALC_ALLOC!$B$1:$B$175,"MBWAY_NAN",_CALC_ALLOC!$D$1:$D$175,"BAC_MGT",_CALC_ALLOC!$E$1:$E$175,"B3",_CALC_ALLOC!$F$1:$F$175,"ALT") -> 0 | M34: =IFERROR(L34/D34,0) -> 0
B35: MAS_MGT M1 ALT | C35: =SUMIFS(_CALC_ALLOC!$G$1:$G$175,_CALC_ALLOC!$A$1:$A$175,"2026",_CALC_ALLOC!$B$1:$B$175,"MBWAY_NAN",_CALC_ALLOC!$D$1:$D$175,"MAS_MGT",_CALC_ALLOC!$E$1:$E$175,"M1",_CALC_ALLOC!$F$1:$F$175,"ALT") -> 0 | D35: =SUMIFS(_CALC_ALLOC!$I$1:$I$175,_CALC_ALLOC!$A$1:$A$175,"2026",_CALC_ALLOC!$B$1:$B$175,"MBWAY_NAN",_CALC_ALLOC!$D$1:$D$175,"MAS_MGT",_CALC_ALLOC!$E$1:$E$175,"M1",_CALC_ALLOC!$F$1:$F$175,"ALT") -> 0 | E35: =SUMIFS(_CALC_ALLOC!$AI$1:$AI$175,_CALC_ALLOC!$A$1:$A$175,"2026",_CALC_ALLOC!$B$1:$B$175,"MBWAY_NAN",_CALC_ALLOC!$D$1:$D$175,"MAS_MGT",_CALC_ALLOC!$E$1:$E$175,"M1",_CALC_ALLOC!$F$1:$F$175,"ALT") -> 0 | F35: =SUMIFS(_CALC_ALLOC!$AJ$1:$AJ$175,_CALC_ALLOC!$A$1:$A$175,"2026",_CALC_ALLOC!$B$1:$B$175,"MBWAY_NAN",_CALC_ALLOC!$D$1:$D$175,"MAS_MGT",_CALC_ALLOC!$E$1:$E$175,"M1",_CALC_ALLOC!$F$1:$F$175,"ALT") -> 0 | G35: =SUMIFS(_CALC_ALLOC!$AK$1:$AK$175,_CALC_ALLOC!$A$1:$A$175,"2026",_CALC_ALLOC!$B$1:$B$175,"MBWAY_NAN",_CALC_ALLOC!$D$1:$D$175,"MAS_MGT",_CALC_ALLOC!$E$1:$E$175,"M1",_CALC_ALLOC!$F$1:$F$175,"ALT") -> 0 | H35: =SUMIFS(_CALC_ALLOC!$AL$1:$AL$175,_CALC_ALLOC!$A$1:$A$175,"2026",_CALC_ALLOC!$B$1:$B$175,"MBWAY_NAN",_CALC_ALLOC!$D$1:$D$175,"MAS_MGT",_CALC_ALLOC!$E$1:$E$175,"M1",_CALC_ALLOC!$F$1:$F$175,"ALT") -> 0 | I35: =SUMIFS(_CALC_ALLOC!$AR$1:$AR$175,_CALC_ALLOC!$A$1:$A$175,"2026",_CALC_ALLOC!$B$1:$B$175,"MBWAY_NAN",_CALC_ALLOC!$D$1:$D$175,"MAS_MGT",_CALC_ALLOC!$E$1:$E$175,"M1",_CALC_ALLOC!$F$1:$F$175,"ALT") -> 0 | J35: =SUMIFS(_CALC_ALLOC!$AM$1:$AM$175,_CALC_ALLOC!$A$1:$A$175,"2026",_CALC_ALLOC!$B$1:$B$175,"MBWAY_NAN",_CALC_ALLOC!$D$1:$D$175,"MAS_MGT",_CALC_ALLOC!$E$1:$E$175,"M1",_CALC_ALLOC!$F$1:$F$175,"ALT") -> 0 | K35: =E35+F35+G35+H35+I35+J35 -> 0 | L35: =SUMIFS(_CALC_ALLOC!$AN$1:$AN$175,_CALC_ALLOC!$A$1:$A$175,"2026",_CALC_ALLOC!$B$1:$B$175,"MBWAY_NAN",_CALC_ALLOC!$D$1:$D$175,"MAS_MGT",_CALC_ALLOC!$E$1:$E$175,"M1",_CALC_ALLOC!$F$1:$F$175,"ALT") -> 0 | M35: =IFERROR(L35/D35,0) -> 0
B36: MAS_MGT M2 ALT | C36: =SUMIFS(_CALC_ALLOC!$G$1:$G$175,_CALC_ALLOC!$A$1:$A$175,"2026",_CALC_ALLOC!$B$1:$B$175,"MBWAY_NAN",_CALC_ALLOC!$D$1:$D$175,"MAS_MGT",_CALC_ALLOC!$E$1:$E$175,"M2",_CALC_ALLOC!$F$1:$F$175,"ALT") -> 0 | D36: =SUMIFS(_CALC_ALLOC!$I$1:$I$175,_CALC_ALLOC!$A$1:$A$175,"2026",_CALC_ALLOC!$B$1:$B$175,"MBWAY_NAN",_CALC_ALLOC!$D$1:$D$175,"MAS_MGT",_CALC_ALLOC!$E$1:$E$175,"M2",_CALC_ALLOC!$F$1:$F$175,"ALT") -> 0 | E36: =SUMIFS(_CALC_ALLOC!$AI$1:$AI$175,_CALC_ALLOC!$A$1:$A$175,"2026",_CALC_ALLOC!$B$1:$B$175,"MBWAY_NAN",_CALC_ALLOC!$D$1:$D$175,"MAS_MGT",_CALC_ALLOC!$E$1:$E$175,"M2",_CALC_ALLOC!$F$1:$F$175,"ALT") -> 0 | F36: =SUMIFS(_CALC_ALLOC!$AJ$1:$AJ$175,_CALC_ALLOC!$A$1:$A$175,"2026",_CALC_ALLOC!$B$1:$B$175,"MBWAY_NAN",_CALC_ALLOC!$D$1:$D$175,"MAS_MGT",_CALC_ALLOC!$E$1:$E$175,"M2",_CALC_ALLOC!$F$1:$F$175,"ALT") -> 0 | G36: =SUMIFS(_CALC_ALLOC!$AK$1:$AK$175,_CALC_ALLOC!$A$1:$A$175,"2026",_CALC_ALLOC!$B$1:$B$175,"MBWAY_NAN",_CALC_ALLOC!$D$1:$D$175,"MAS_MGT",_CALC_ALLOC!$E$1:$E$175,"M2",_CALC_ALLOC!$F$1:$F$175,"ALT") -> 0 | H36: =SUMIFS(_CALC_ALLOC!$AL$1:$AL$175,_CALC_ALLOC!$A$1:$A$175,"2026",_CALC_ALLOC!$B$1:$B$175,"MBWAY_NAN",_CALC_ALLOC!$D$1:$D$175,"MAS_MGT",_CALC_ALLOC!$E$1:$E$175,"M2",_CALC_ALLOC!$F$1:$F$175,"ALT") -> 0 | I36: =SUMIFS(_CALC_ALLOC!$AR$1:$AR$175,_CALC_ALLOC!$A$1:$A$175,"2026",_CALC_ALLOC!$B$1:$B$175,"MBWAY_NAN",_CALC_ALLOC!$D$1:$D$175,"MAS_MGT",_CALC_ALLOC!$E$1:$E$175,"M2",_CALC_ALLOC!$F$1:$F$175,"ALT") -> 0 | J36: =SUMIFS(_CALC_ALLOC!$AM$1:$AM$175,_CALC_ALLOC!$A$1:$A$175,"2026",_CALC_ALLOC!$B$1:$B$175,"MBWAY_NAN",_CALC_ALLOC!$D$1:$D$175,"MAS_MGT",_CALC_ALLOC!$E$1:$E$175,"M2",_CALC_ALLOC!$F$1:$F$175,"ALT") -> 0 | K36: =E36+F36+G36+H36+I36+J36 -> 0 | L36: =SUMIFS(_CALC_ALLOC!$AN$1:$AN$175,_CALC_ALLOC!$A$1:$A$175,"2026",_CALC_ALLOC!$B$1:$B$175,"MBWAY_NAN",_CALC_ALLOC!$D$1:$D$175,"MAS_MGT",_CALC_ALLOC!$E$1:$E$175,"M2",_CALC_ALLOC!$F$1:$F$175,"ALT") -> 0 | M36: =IFERROR(L36/D36,0) -> 0
B37: Bordeaux (MBWAY_BOR) | C37: =SUMIFS(_CALC_ALLOC!$G$1:$G$175,_CALC_ALLOC!$A$1:$A$175,"2026",_CALC_ALLOC!$B$1:$B$175,"MBWAY_BOR") -> 0 | D37: =SUMIFS(_CALC_ALLOC!$I$1:$I$175,_CALC_ALLOC!$A$1:$A$175,"2026",_CALC_ALLOC!$B$1:$B$175,"MBWAY_BOR") -> 0 | E37: =SUMIFS(_CALC_ALLOC!$AI$1:$AI$175,_CALC_ALLOC!$A$1:$A$175,"2026",_CALC_ALLOC!$B$1:$B$175,"MBWAY_BOR") -> 0 | F37: =SUMIFS(_CALC_ALLOC!$AJ$1:$AJ$175,_CALC_ALLOC!$A$1:$A$175,"2026",_CALC_ALLOC!$B$1:$B$175,"MBWAY_BOR") -> 0 | G37: =SUMIFS(_CALC_ALLOC!$AK$1:$AK$175,_CALC_ALLOC!$A$1:$A$175,"2026",_CALC_ALLOC!$B$1:$B$175,"MBWAY_BOR") -> 0 | H37: =SUMIFS(_CALC_ALLOC!$AL$1:$AL$175,_CALC_ALLOC!$A$1:$A$175,"2026",_CALC_ALLOC!$B$1:$B$175,"MBWAY_BOR") -> 0 | I37: =SUMIFS(_CALC_ALLOC!$AR$1:$AR$175,_CALC_ALLOC!$A$1:$A$175,"2026",_CALC_ALLOC!$B$1:$B$175,"MBWAY_BOR") -> 0 | J37: =SUMIFS(_CALC_ALLOC!$AM$1:$AM$175,_CALC_ALLOC!$A$1:$A$175,"2026",_CALC_ALLOC!$B$1:$B$175,"MBWAY_BOR") -> 0 | K37: =E37+F37+G37+H37+I37+J37 -> 0 | L37: =SUMIFS(_CALC_ALLOC!$AN$1:$AN$175,_CALC_ALLOC!$A$1:$A$175,"2026",_CALC_ALLOC!$B$1:$B$175,"MBWAY_BOR") -> 0 | M37: =IFERROR(L37/D37,0) -> 0
B38: BAC_MGT B1 INIT | C38: =SUMIFS(_CALC_ALLOC!$G$1:$G$175,_CALC_ALLOC!$A$1:$A$175,"2026",_CALC_ALLOC!$B$1:$B$175,"MBWAY_BOR",_CALC_ALLOC!$D$1:$D$175,"BAC_MGT",_CALC_ALLOC!$E$1:$E$175,"B1",_CALC_ALLOC!$F$1:$F$175,"INIT") -> 0 | D38: =SUMIFS(_CALC_ALLOC!$I$1:$I$175,_CALC_ALLOC!$A$1:$A$175,"2026",_CALC_ALLOC!$B$1:$B$175,"MBWAY_BOR",_CALC_ALLOC!$D$1:$D$175,"BAC_MGT",_CALC_ALLOC!$E$1:$E$175,"B1",_CALC_ALLOC!$F$1:$F$175,"INIT") -> 0 | E38: =SUMIFS(_CALC_ALLOC!$AI$1:$AI$175,_CALC_ALLOC!$A$1:$A$175,"2026",_CALC_ALLOC!$B$1:$B$175,"MBWAY_BOR",_CALC_ALLOC!$D$1:$D$175,"BAC_MGT",_CALC_ALLOC!$E$1:$E$175,"B1",_CALC_ALLOC!$F$1:$F$175,"INIT") -> 0 | F38: =SUMIFS(_CALC_ALLOC!$AJ$1:$AJ$175,_CALC_ALLOC!$A$1:$A$175,"2026",_CALC_ALLOC!$B$1:$B$175,"MBWAY_BOR",_CALC_ALLOC!$D$1:$D$175,"BAC_MGT",_CALC_ALLOC!$E$1:$E$175,"B1",_CALC_ALLOC!$F$1:$F$175,"INIT") -> 0 | G38: =SUMIFS(_CALC_ALLOC!$AK$1:$AK$175,_CALC_ALLOC!$A$1:$A$175,"2026",_CALC_ALLOC!$B$1:$B$175,"MBWAY_BOR",_CALC_ALLOC!$D$1:$D$175,"BAC_MGT",_CALC_ALLOC!$E$1:$E$175,"B1",_CALC_ALLOC!$F$1:$F$175,"INIT") -> 0 | H38: =SUMIFS(_CALC_ALLOC!$AL$1:$AL$175,_CALC_ALLOC!$A$1:$A$175,"2026",_CALC_ALLOC!$B$1:$B$175,"MBWAY_BOR",_CALC_ALLOC!$D$1:$D$175,"BAC_MGT",_CALC_ALLOC!$E$1:$E$175,"B1",_CALC_ALLOC!$F$1:$F$175,"INIT") -> 0 | I38: =SUMIFS(_CALC_ALLOC!$AR$1:$AR$175,_CALC_ALLOC!$A$1:$A$175,"2026",_CALC_ALLOC!$B$1:$B$175,"MBWAY_BOR",_CALC_ALLOC!$D$1:$D$175,"BAC_MGT",_CALC_ALLOC!$E$1:$E$175,"B1",_CALC_ALLOC!$F$1:$F$175,"INIT") -> 0 | J38: =SUMIFS(_CALC_ALLOC!$AM$1:$AM$175,_CALC_ALLOC!$A$1:$A$175,"2026",_CALC_ALLOC!$B$1:$B$175,"MBWAY_BOR",_CALC_ALLOC!$D$1:$D$175,"BAC_MGT",_CALC_ALLOC!$E$1:$E$175,"B1",_CALC_ALLOC!$F$1:$F$175,"INIT") -> 0 | K38: =E38+F38+G38+H38+I38+J38 -> 0 | L38: =SUMIFS(_CALC_ALLOC!$AN$1:$AN$175,_CALC_ALLOC!$A$1:$A$175,"2026",_CALC_ALLOC!$B$1:$B$175,"MBWAY_BOR",_CALC_ALLOC!$D$1:$D$175,"BAC_MGT",_CALC_ALLOC!$E$1:$E$175,"B1",_CALC_ALLOC!$F$1:$F$175,"INIT") -> 0 | M38: =IFERROR(L38/D38,0) -> 0
B39: BAC_MGT B2 ALT | C39: =SUMIFS(_CALC_ALLOC!$G$1:$G$175,_CALC_ALLOC!$A$1:$A$175,"2026",_CALC_ALLOC!$B$1:$B$175,"MBWAY_BOR",_CALC_ALLOC!$D$1:$D$175,"BAC_MGT",_CALC_ALLOC!$E$1:$E$175,"B2",_CALC_ALLOC!$F$1:$F$175,"ALT") -> 0 | D39: =SUMIFS(_CALC_ALLOC!$I$1:$I$175,_CALC_ALLOC!$A$1:$A$175,"2026",_CALC_ALLOC!$B$1:$B$175,"MBWAY_BOR",_CALC_ALLOC!$D$1:$D$175,"BAC_MGT",_CALC_ALLOC!$E$1:$E$175,"B2",_CALC_ALLOC!$F$1:$F$175,"ALT") -> 0 | E39: =SUMIFS(_CALC_ALLOC!$AI$1:$AI$175,_CALC_ALLOC!$A$1:$A$175,"2026",_CALC_ALLOC!$B$1:$B$175,"MBWAY_BOR",_CALC_ALLOC!$D$1:$D$175,"BAC_MGT",_CALC_ALLOC!$E$1:$E$175,"B2",_CALC_ALLOC!$F$1:$F$175,"ALT") -> 0 | F39: =SUMIFS(_CALC_ALLOC!$AJ$1:$AJ$175,_CALC_ALLOC!$A$1:$A$175,"2026",_CALC_ALLOC!$B$1:$B$175,"MBWAY_BOR",_CALC_ALLOC!$D$1:$D$175,"BAC_MGT",_CALC_ALLOC!$E$1:$E$175,"B2",_CALC_ALLOC!$F$1:$F$175,"ALT") -> 0 | G39: =SUMIFS(_CALC_ALLOC!$AK$1:$AK$175,_CALC_ALLOC!$A$1:$A$175,"2026",_CALC_ALLOC!$B$1:$B$175,"MBWAY_BOR",_CALC_ALLOC!$D$1:$D$175,"BAC_MGT",_CALC_ALLOC!$E$1:$E$175,"B2",_CALC_ALLOC!$F$1:$F$175,"ALT") -> 0 | H39: =SUMIFS(_CALC_ALLOC!$AL$1:$AL$175,_CALC_ALLOC!$A$1:$A$175,"2026",_CALC_ALLOC!$B$1:$B$175,"MBWAY_BOR",_CALC_ALLOC!$D$1:$D$175,"BAC_MGT",_CALC_ALLOC!$E$1:$E$175,"B2",_CALC_ALLOC!$F$1:$F$175,"ALT") -> 0 | I39: =SUMIFS(_CALC_ALLOC!$AR$1:$AR$175,_CALC_ALLOC!$A$1:$A$175,"2026",_CALC_ALLOC!$B$1:$B$175,"MBWAY_BOR",_CALC_ALLOC!$D$1:$D$175,"BAC_MGT",_CALC_ALLOC!$E$1:$E$175,"B2",_CALC_ALLOC!$F$1:$F$175,"ALT") -> 0 | J39: =SUMIFS(_CALC_ALLOC!$AM$1:$AM$175,_CALC_ALLOC!$A$1:$A$175,"2026",_CALC_ALLOC!$B$1:$B$175,"MBWAY_BOR",_CALC_ALLOC!$D$1:$D$175,"BAC_MGT",_CALC_ALLOC!$E$1:$E$175,"B2",_CALC_ALLOC!$F$1:$F$175,"ALT") -> 0 | K39: =E39+F39+G39+H39+I39+J39 -> 0 | L39: =SUMIFS(_CALC_ALLOC!$AN$1:$AN$175,_CALC_ALLOC!$A$1:$A$175,"2026",_CALC_ALLOC!$B$1:$B$175,"MBWAY_BOR",_CALC_ALLOC!$D$1:$D$175,"BAC_MGT",_CALC_ALLOC!$E$1:$E$175,"B2",_CALC_ALLOC!$F$1:$F$175,"ALT") -> 0 | M39: =IFERROR(L39/D39,0) -> 0
B40: BAC_MGT B3 ALT | C40: =SUMIFS(_CALC_ALLOC!$G$1:$G$175,_CALC_ALLOC!$A$1:$A$175,"2026",_CALC_ALLOC!$B$1:$B$175,"MBWAY_BOR",_CALC_ALLOC!$D$1:$D$175,"BAC_MGT",_CALC_ALLOC!$E$1:$E$175,"B3",_CALC_ALLOC!$F$1:$F$175,"ALT") -> 0 | D40: =SUMIFS(_CALC_ALLOC!$I$1:$I$175,_CALC_ALLOC!$A$1:$A$175,"2026",_CALC_ALLOC!$B$1:$B$175,"MBWAY_BOR",_CALC_ALLOC!$D$1:$D$175,"BAC_MGT",_CALC_ALLOC!$E$1:$E$175,"B3",_CALC_ALLOC!$F$1:$F$175,"ALT") -> 0 | E40: =SUMIFS(_CALC_ALLOC!$AI$1:$AI$175,_CALC_ALLOC!$A$1:$A$175,"2026",_CALC_ALLOC!$B$1:$B$175,"MBWAY_BOR",_CALC_ALLOC!$D$1:$D$175,"BAC_MGT",_CALC_ALLOC!$E$1:$E$175,"B3",_CALC_ALLOC!$F$1:$F$175,"ALT") -> 0 | F40: =SUMIFS(_CALC_ALLOC!$AJ$1:$AJ$175,_CALC_ALLOC!$A$1:$A$175,"2026",_CALC_ALLOC!$B$1:$B$175,"MBWAY_BOR",_CALC_ALLOC!$D$1:$D$175,"BAC_MGT",_CALC_ALLOC!$E$1:$E$175,"B3",_CALC_ALLOC!$F$1:$F$175,"ALT") -> 0 | G40: =SUMIFS(_CALC_ALLOC!$AK$1:$AK$175,_CALC_ALLOC!$A$1:$A$175,"2026",_CALC_ALLOC!$B$1:$B$175,"MBWAY_BOR",_CALC_ALLOC!$D$1:$D$175,"BAC_MGT",_CALC_ALLOC!$E$1:$E$175,"B3",_CALC_ALLOC!$F$1:$F$175,"ALT") -> 0 | H40: =SUMIFS(_CALC_ALLOC!$AL$1:$AL$175,_CALC_ALLOC!$A$1:$A$175,"2026",_CALC_ALLOC!$B$1:$B$175,"MBWAY_BOR",_CALC_ALLOC!$D$1:$D$175,"BAC_MGT",_CALC_ALLOC!$E$1:$E$175,"B3",_CALC_ALLOC!$F$1:$F$175,"ALT") -> 0 | I40: =SUMIFS(_CALC_ALLOC!$AR$1:$AR$175,_CALC_ALLOC!$A$1:$A$175,"2026",_CALC_ALLOC!$B$1:$B$175,"MBWAY_BOR",_CALC_ALLOC!$D$1:$D$175,"BAC_MGT",_CALC_ALLOC!$E$1:$E$175,"B3",_CALC_ALLOC!$F$1:$F$175,"ALT") -> 0 | J40: =SUMIFS(_CALC_ALLOC!$AM$1:$AM$175,_CALC_ALLOC!$A$1:$A$175,"2026",_CALC_ALLOC!$B$1:$B$175,"MBWAY_BOR",_CALC_ALLOC!$D$1:$D$175,"BAC_MGT",_CALC_ALLOC!$E$1:$E$175,"B3",_CALC_ALLOC!$F$1:$F$175,"ALT") -> 0 | K40: =E40+F40+G40+H40+I40+J40 -> 0 | L40: =SUMIFS(_CALC_ALLOC!$AN$1:$AN$175,_CALC_ALLOC!$A$1:$A$175,"2026",_CALC_ALLOC!$B$1:$B$175,"MBWAY_BOR",_CALC_ALLOC!$D$1:$D$175,"BAC_MGT",_CALC_ALLOC!$E$1:$E$175,"B3",_CALC_ALLOC!$F$1:$F$175,"ALT") -> 0 | M40: =IFERROR(L40/D40,0) -> 0
B41: MAS_MGT M1 ALT | C41: =SUMIFS(_CALC_ALLOC!$G$1:$G$175,_CALC_ALLOC!$A$1:$A$175,"2026",_CALC_ALLOC!$B$1:$B$175,"MBWAY_BOR",_CALC_ALLOC!$D$1:$D$175,"MAS_MGT",_CALC_ALLOC!$E$1:$E$175,"M1",_CALC_ALLOC!$F$1:$F$175,"ALT") -> 0 | D41: =SUMIFS(_CALC_ALLOC!$I$1:$I$175,_CALC_ALLOC!$A$1:$A$175,"2026",_CALC_ALLOC!$B$1:$B$175,"MBWAY_BOR",_CALC_ALLOC!$D$1:$D$175,"MAS_MGT",_CALC_ALLOC!$E$1:$E$175,"M1",_CALC_ALLOC!$F$1:$F$175,"ALT") -> 0 | E41: =SUMIFS(_CALC_ALLOC!$AI$1:$AI$175,_CALC_ALLOC!$A$1:$A$175,"2026",_CALC_ALLOC!$B$1:$B$175,"MBWAY_BOR",_CALC_ALLOC!$D$1:$D$175,"MAS_MGT",_CALC_ALLOC!$E$1:$E$175,"M1",_CALC_ALLOC!$F$1:$F$175,"ALT") -> 0 | F41: =SUMIFS(_CALC_ALLOC!$AJ$1:$AJ$175,_CALC_ALLOC!$A$1:$A$175,"2026",_CALC_ALLOC!$B$1:$B$175,"MBWAY_BOR",_CALC_ALLOC!$D$1:$D$175,"MAS_MGT",_CALC_ALLOC!$E$1:$E$175,"M1",_CALC_ALLOC!$F$1:$F$175,"ALT") -> 0 | G41: =SUMIFS(_CALC_ALLOC!$AK$1:$AK$175,_CALC_ALLOC!$A$1:$A$175,"2026",_CALC_ALLOC!$B$1:$B$175,"MBWAY_BOR",_CALC_ALLOC!$D$1:$D$175,"MAS_MGT",_CALC_ALLOC!$E$1:$E$175,"M1",_CALC_ALLOC!$F$1:$F$175,"ALT") -> 0 | H41: =SUMIFS(_CALC_ALLOC!$AL$1:$AL$175,_CALC_ALLOC!$A$1:$A$175,"2026",_CALC_ALLOC!$B$1:$B$175,"MBWAY_BOR",_CALC_ALLOC!$D$1:$D$175,"MAS_MGT",_CALC_ALLOC!$E$1:$E$175,"M1",_CALC_ALLOC!$F$1:$F$175,"ALT") -> 0 | I41: =SUMIFS(_CALC_ALLOC!$AR$1:$AR$175,_CALC_ALLOC!$A$1:$A$175,"2026",_CALC_ALLOC!$B$1:$B$175,"MBWAY_BOR",_CALC_ALLOC!$D$1:$D$175,"MAS_MGT",_CALC_ALLOC!$E$1:$E$175,"M1",_CALC_ALLOC!$F$1:$F$175,"ALT") -> 0 | J41: =SUMIFS(_CALC_ALLOC!$AM$1:$AM$175,_CALC_ALLOC!$A$1:$A$175,"2026",_CALC_ALLOC!$B$1:$B$175,"MBWAY_BOR",_CALC_ALLOC!$D$1:$D$175,"MAS_MGT",_CALC_ALLOC!$E$1:$E$175,"M1",_CALC_ALLOC!$F$1:$F$175,"ALT") -> 0 | K41: =E41+F41+G41+H41+I41+J41 -> 0 | L41: =SUMIFS(_CALC_ALLOC!$AN$1:$AN$175,_CALC_ALLOC!$A$1:$A$175,"2026",_CALC_ALLOC!$B$1:$B$175,"MBWAY_BOR",_CALC_ALLOC!$D$1:$D$175,"MAS_MGT",_CALC_ALLOC!$E$1:$E$175,"M1",_CALC_ALLOC!$F$1:$F$175,"ALT") -> 0 | M41: =IFERROR(L41/D41,0) -> 0
B42: MAS_MGT M2 ALT | C42: =SUMIFS(_CALC_ALLOC!$G$1:$G$175,_CALC_ALLOC!$A$1:$A$175,"2026",_CALC_ALLOC!$B$1:$B$175,"MBWAY_BOR",_CALC_ALLOC!$D$1:$D$175,"MAS_MGT",_CALC_ALLOC!$E$1:$E$175,"M2",_CALC_ALLOC!$F$1:$F$175,"ALT") -> 0 | D42: =SUMIFS(_CALC_ALLOC!$I$1:$I$175,_CALC_ALLOC!$A$1:$A$175,"2026",_CALC_ALLOC!$B$1:$B$175,"MBWAY_BOR",_CALC_ALLOC!$D$1:$D$175,"MAS_MGT",_CALC_ALLOC!$E$1:$E$175,"M2",_CALC_ALLOC!$F$1:$F$175,"ALT") -> 0 | E42: =SUMIFS(_CALC_ALLOC!$AI$1:$AI$175,_CALC_ALLOC!$A$1:$A$175,"2026",_CALC_ALLOC!$B$1:$B$175,"MBWAY_BOR",_CALC_ALLOC!$D$1:$D$175,"MAS_MGT",_CALC_ALLOC!$E$1:$E$175,"M2",_CALC_ALLOC!$F$1:$F$175,"ALT") -> 0 | F42: =SUMIFS(_CALC_ALLOC!$AJ$1:$AJ$175,_CALC_ALLOC!$A$1:$A$175,"2026",_CALC_ALLOC!$B$1:$B$175,"MBWAY_BOR",_CALC_ALLOC!$D$1:$D$175,"MAS_MGT",_CALC_ALLOC!$E$1:$E$175,"M2",_CALC_ALLOC!$F$1:$F$175,"ALT") -> 0 | G42: =SUMIFS(_CALC_ALLOC!$AK$1:$AK$175,_CALC_ALLOC!$A$1:$A$175,"2026",_CALC_ALLOC!$B$1:$B$175,"MBWAY_BOR",_CALC_ALLOC!$D$1:$D$175,"MAS_MGT",_CALC_ALLOC!$E$1:$E$175,"M2",_CALC_ALLOC!$F$1:$F$175,"ALT") -> 0 | H42: =SUMIFS(_CALC_ALLOC!$AL$1:$AL$175,_CALC_ALLOC!$A$1:$A$175,"2026",_CALC_ALLOC!$B$1:$B$175,"MBWAY_BOR",_CALC_ALLOC!$D$1:$D$175,"MAS_MGT",_CALC_ALLOC!$E$1:$E$175,"M2",_CALC_ALLOC!$F$1:$F$175,"ALT") -> 0 | I42: =SUMIFS(_CALC_ALLOC!$AR$1:$AR$175,_CALC_ALLOC!$A$1:$A$175,"2026",_CALC_ALLOC!$B$1:$B$175,"MBWAY_BOR",_CALC_ALLOC!$D$1:$D$175,"MAS_MGT",_CALC_ALLOC!$E$1:$E$175,"M2",_CALC_ALLOC!$F$1:$F$175,"ALT") -> 0 | J42: =SUMIFS(_CALC_ALLOC!$AM$1:$AM$175,_CALC_ALLOC!$A$1:$A$175,"2026",_CALC_ALLOC!$B$1:$B$175,"MBWAY_BOR",_CALC_ALLOC!$D$1:$D$175,"MAS_MGT",_CALC_ALLOC!$E$1:$E$175,"M2",_CALC_ALLOC!$F$1:$F$175,"ALT") -> 0 | K42: =E42+F42+G42+H42+I42+J42 -> 0 | L42: =SUMIFS(_CALC_ALLOC!$AN$1:$AN$175,_CALC_ALLOC!$A$1:$A$175,"2026",_CALC_ALLOC!$B$1:$B$175,"MBWAY_BOR",_CALC_ALLOC!$D$1:$D$175,"MAS_MGT",_CALC_ALLOC!$E$1:$E$175,"M2",_CALC_ALLOC!$F$1:$F$175,"ALT") -> 0 | M42: =IFERROR(L42/D42,0) -> 0
B43: ISCOM | C43: =SUMIFS(_CALC_ALLOC!$G$1:$G$175,_CALC_ALLOC!$A$1:$A$175,"2026",_CALC_ALLOC!$C$1:$C$175,"ISCOM") -> 0 | D43: =SUMIFS(_CALC_ALLOC!$I$1:$I$175,_CALC_ALLOC!$A$1:$A$175,"2026",_CALC_ALLOC!$C$1:$C$175,"ISCOM") -> 0 | E43: =SUMIFS(_CALC_ALLOC!$AI$1:$AI$175,_CALC_ALLOC!$A$1:$A$175,"2026",_CALC_ALLOC!$C$1:$C$175,"ISCOM") -> 0 | F43: =SUMIFS(_CALC_ALLOC!$AJ$1:$AJ$175,_CALC_ALLOC!$A$1:$A$175,"2026",_CALC_ALLOC!$C$1:$C$175,"ISCOM") -> 0 | G43: =SUMIFS(_CALC_ALLOC!$AK$1:$AK$175,_CALC_ALLOC!$A$1:$A$175,"2026",_CALC_ALLOC!$C$1:$C$175,"ISCOM") -> 0 | H43: =SUMIFS(_CALC_ALLOC!$AL$1:$AL$175,_CALC_ALLOC!$A$1:$A$175,"2026",_CALC_ALLOC!$C$1:$C$175,"ISCOM") -> 0 | I43: =SUMIFS(_CALC_ALLOC!$AR$1:$AR$175,_CALC_ALLOC!$A$1:$A$175,"2026",_CALC_ALLOC!$C$1:$C$175,"ISCOM") -> 0 | J43: =SUMIFS(_CALC_ALLOC!$AM$1:$AM$175,_CALC_ALLOC!$A$1:$A$175,"2026",_CALC_ALLOC!$C$1:$C$175,"ISCOM") -> 0 | K43: =E43+F43+G43+H43+I43+J43 -> 0 | L43: =SUMIFS(_CALC_ALLOC!$AN$1:$AN$175,_CALC_ALLOC!$A$1:$A$175,"2026",_CALC_ALLOC!$C$1:$C$175,"ISCOM") -> 0 | M43: =IFERROR(L43/D43,0) -> 0
B44: Paris (ISCOM_PAR) | C44: =SUMIFS(_CALC_ALLOC!$G$1:$G$175,_CALC_ALLOC!$A$1:$A$175,"2026",_CALC_ALLOC!$B$1:$B$175,"ISCOM_PAR") -> 0 | D44: =SUMIFS(_CALC_ALLOC!$I$1:$I$175,_CALC_ALLOC!$A$1:$A$175,"2026",_CALC_ALLOC!$B$1:$B$175,"ISCOM_PAR") -> 0 | E44: =SUMIFS(_CALC_ALLOC!$AI$1:$AI$175,_CALC_ALLOC!$A$1:$A$175,"2026",_CALC_ALLOC!$B$1:$B$175,"ISCOM_PAR") -> 0 | F44: =SUMIFS(_CALC_ALLOC!$AJ$1:$AJ$175,_CALC_ALLOC!$A$1:$A$175,"2026",_CALC_ALLOC!$B$1:$B$175,"ISCOM_PAR") -> 0 | G44: =SUMIFS(_CALC_ALLOC!$AK$1:$AK$175,_CALC_ALLOC!$A$1:$A$175,"2026",_CALC_ALLOC!$B$1:$B$175,"ISCOM_PAR") -> 0 | H44: =SUMIFS(_CALC_ALLOC!$AL$1:$AL$175,_CALC_ALLOC!$A$1:$A$175,"2026",_CALC_ALLOC!$B$1:$B$175,"ISCOM_PAR") -> 0 | I44: =SUMIFS(_CALC_ALLOC!$AR$1:$AR$175,_CALC_ALLOC!$A$1:$A$175,"2026",_CALC_ALLOC!$B$1:$B$175,"ISCOM_PAR") -> 0 | J44: =SUMIFS(_CALC_ALLOC!$AM$1:$AM$175,_CALC_ALLOC!$A$1:$A$175,"2026",_CALC_ALLOC!$B$1:$B$175,"ISCOM_PAR") -> 0 | K44: =E44+F44+G44+H44+I44+J44 -> 0 | L44: =SUMIFS(_CALC_ALLOC!$AN$1:$AN$175,_CALC_ALLOC!$A$1:$A$175,"2026",_CALC_ALLOC!$B$1:$B$175,"ISCOM_PAR") -> 0 | M44: =IFERROR(L44/D44,0) -> 0
B45: BAC_COM B1 INIT | C45: =SUMIFS(_CALC_ALLOC!$G$1:$G$175,_CALC_ALLOC!$A$1:$A$175,"2026",_CALC_ALLOC!$B$1:$B$175,"ISCOM_PAR",_CALC_ALLOC!$D$1:$D$175,"BAC_COM",_CALC_ALLOC!$E$1:$E$175,"B1",_CALC_ALLOC!$F$1:$F$175,"INIT") -> 0 | D45: =SUMIFS(_CALC_ALLOC!$I$1:$I$175,_CALC_ALLOC!$A$1:$A$175,"2026",_CALC_ALLOC!$B$1:$B$175,"ISCOM_PAR",_CALC_ALLOC!$D$1:$D$175,"BAC_COM",_CALC_ALLOC!$E$1:$E$175,"B1",_CALC_ALLOC!$F$1:$F$175,"INIT") -> 0 | E45: =SUMIFS(_CALC_ALLOC!$AI$1:$AI$175,_CALC_ALLOC!$A$1:$A$175,"2026",_CALC_ALLOC!$B$1:$B$175,"ISCOM_PAR",_CALC_ALLOC!$D$1:$D$175,"BAC_COM",_CALC_ALLOC!$E$1:$E$175,"B1",_CALC_ALLOC!$F$1:$F$175,"INIT") -> 0 | F45: =SUMIFS(_CALC_ALLOC!$AJ$1:$AJ$175,_CALC_ALLOC!$A$1:$A$175,"2026",_CALC_ALLOC!$B$1:$B$175,"ISCOM_PAR",_CALC_ALLOC!$D$1:$D$175,"BAC_COM",_CALC_ALLOC!$E$1:$E$175,"B1",_CALC_ALLOC!$F$1:$F$175,"INIT") -> 0 | G45: =SUMIFS(_CALC_ALLOC!$AK$1:$AK$175,_CALC_ALLOC!$A$1:$A$175,"2026",_CALC_ALLOC!$B$1:$B$175,"ISCOM_PAR",_CALC_ALLOC!$D$1:$D$175,"BAC_COM",_CALC_ALLOC!$E$1:$E$175,"B1",_CALC_ALLOC!$F$1:$F$175,"INIT") -> 0 | H45: =SUMIFS(_CALC_ALLOC!$AL$1:$AL$175,_CALC_ALLOC!$A$1:$A$175,"2026",_CALC_ALLOC!$B$1:$B$175,"ISCOM_PAR",_CALC_ALLOC!$D$1:$D$175,"BAC_COM",_CALC_ALLOC!$E$1:$E$175,"B1",_CALC_ALLOC!$F$1:$F$175,"INIT") -> 0 | I45: =SUMIFS(_CALC_ALLOC!$AR$1:$AR$175,_CALC_ALLOC!$A$1:$A$175,"2026",_CALC_ALLOC!$B$1:$B$175,"ISCOM_PAR",_CALC_ALLOC!$D$1:$D$175,"BAC_COM",_CALC_ALLOC!$E$1:$E$175,"B1",_CALC_ALLOC!$F$1:$F$175,"INIT") -> 0 | J45: =SUMIFS(_CALC_ALLOC!$AM$1:$AM$175,_CALC_ALLOC!$A$1:$A$175,"2026",_CALC_ALLOC!$B$1:$B$175,"ISCOM_PAR",_CALC_ALLOC!$D$1:$D$175,"BAC_COM",_CALC_ALLOC!$E$1:$E$175,"B1",_CALC_ALLOC!$F$1:$F$175,"INIT") -> 0 | K45: =E45+F45+G45+H45+I45+J45 -> 0 | L45: =SUMIFS(_CALC_ALLOC!$AN$1:$AN$175,_CALC_ALLOC!$A$1:$A$175,"2026",_CALC_ALLOC!$B$1:$B$175,"ISCOM_PAR",_CALC_ALLOC!$D$1:$D$175,"BAC_COM",_CALC_ALLOC!$E$1:$E$175,"B1",_CALC_ALLOC!$F$1:$F$175,"INIT") -> 0 | M45: =IFERROR(L45/D45,0) -> 0
B46: BAC_COM B2 ALT | C46: =SUMIFS(_CALC_ALLOC!$G$1:$G$175,_CALC_ALLOC!$A$1:$A$175,"2026",_CALC_ALLOC!$B$1:$B$175,"ISCOM_PAR",_CALC_ALLOC!$D$1:$D$175,"BAC_COM",_CALC_ALLOC!$E$1:$E$175,"B2",_CALC_ALLOC!$F$1:$F$175,"ALT") -> 0 | D46: =SUMIFS(_CALC_ALLOC!$I$1:$I$175,_CALC_ALLOC!$A$1:$A$175,"2026",_CALC_ALLOC!$B$1:$B$175,"ISCOM_PAR",_CALC_ALLOC!$D$1:$D$175,"BAC_COM",_CALC_ALLOC!$E$1:$E$175,"B2",_CALC_ALLOC!$F$1:$F$175,"ALT") -> 0 | E46: =SUMIFS(_CALC_ALLOC!$AI$1:$AI$175,_CALC_ALLOC!$A$1:$A$175,"2026",_CALC_ALLOC!$B$1:$B$175,"ISCOM_PAR",_CALC_ALLOC!$D$1:$D$175,"BAC_COM",_CALC_ALLOC!$E$1:$E$175,"B2",_CALC_ALLOC!$F$1:$F$175,"ALT") -> 0 | F46: =SUMIFS(_CALC_ALLOC!$AJ$1:$AJ$175,_CALC_ALLOC!$A$1:$A$175,"2026",_CALC_ALLOC!$B$1:$B$175,"ISCOM_PAR",_CALC_ALLOC!$D$1:$D$175,"BAC_COM",_CALC_ALLOC!$E$1:$E$175,"B2",_CALC_ALLOC!$F$1:$F$175,"ALT") -> 0 | G46: =SUMIFS(_CALC_ALLOC!$AK$1:$AK$175,_CALC_ALLOC!$A$1:$A$175,"2026",_CALC_ALLOC!$B$1:$B$175,"ISCOM_PAR",_CALC_ALLOC!$D$1:$D$175,"BAC_COM",_CALC_ALLOC!$E$1:$E$175,"B2",_CALC_ALLOC!$F$1:$F$175,"ALT") -> 0 | H46: =SUMIFS(_CALC_ALLOC!$AL$1:$AL$175,_CALC_ALLOC!$A$1:$A$175,"2026",_CALC_ALLOC!$B$1:$B$175,"ISCOM_PAR",_CALC_ALLOC!$D$1:$D$175,"BAC_COM",_CALC_ALLOC!$E$1:$E$175,"B2",_CALC_ALLOC!$F$1:$F$175,"ALT") -> 0 | I46: =SUMIFS(_CALC_ALLOC!$AR$1:$AR$175,_CALC_ALLOC!$A$1:$A$175,"2026",_CALC_ALLOC!$B$1:$B$175,"ISCOM_PAR",_CALC_ALLOC!$D$1:$D$175,"BAC_COM",_CALC_ALLOC!$E$1:$E$175,"B2",_CALC_ALLOC!$F$1:$F$175,"ALT") -> 0 | J46: =SUMIFS(_CALC_ALLOC!$AM$1:$AM$175,_CALC_ALLOC!$A$1:$A$175,"2026",_CALC_ALLOC!$B$1:$B$175,"ISCOM_PAR",_CALC_ALLOC!$D$1:$D$175,"BAC_COM",_CALC_ALLOC!$E$1:$E$175,"B2",_CALC_ALLOC!$F$1:$F$175,"ALT") -> 0 | K46: =E46+F46+G46+H46+I46+J46 -> 0 | L46: =SUMIFS(_CALC_ALLOC!$AN$1:$AN$175,_CALC_ALLOC!$A$1:$A$175,"2026",_CALC_ALLOC!$B$1:$B$175,"ISCOM_PAR",_CALC_ALLOC!$D$1:$D$175,"BAC_COM",_CALC_ALLOC!$E$1:$E$175,"B2",_CALC_ALLOC!$F$1:$F$175,"ALT") -> 0 | M46: =IFERROR(L46/D46,0) -> 0
...

Sheet Allocation2
A1: SCENARIO | B1: VERSION | C1: PERIODE | D1: EXERCICE | E1: ENTITY | F1: MARQUE | G1: PROGRAMME | H1: AN_ETUDE | I1: MODALITE | J1: VOL_EFF | K1: VOL_CLASS | L1: CA | M1: COST_VAC | N1: COST_PERM | O1: COST_ODIR | P1: COST_STRUCT | Q1: COST_MARQUE | R1: COST_HOLDING | S1: COST_SIEGE | T1: COST_VARIABLE | U1: COST_STRUCTURE | V1: COST_COMPLET | W1: MARGE_COMPLETE | X1: VOL_NEW | Y1: POOL_VAC | Z1: POOL_PERM | AA1: POOL_ODIR | AB1: POOL_MKT | AC1: POOL_STRUCT | AD1: POOL_HOLDING | AE1: POOL_FRAIS_MARQUE
A2: 2027BUD_V1 | B2: ACT | C2: 12 | D2: 2026 | E2: MBWAY_PAR | F2: MBWAY | G2: BAC_MGT | H2: B1 | I2: INIT | J2: 78 | K2: 3 | L2: 662220 | M2: 45273.5 | N2: 151300.5 | O2: 63168.851 | P2: 296639.1 | Q2: 18639.416 | R2: 73943.233 | S2: 92582.649 | T2: 108442.35 | U2: 540522.25 | V2: 648964.6 | W2: 13255.396 | X2: 78 | Y2: 181094 | Z2: 605202 | AA2: 142140 | AB2: 68291 | AC2: 1452771 | AD2: 2891983 | AE2: 676344
A3: 2027BUD_V1 | B3: ACT | C3: 12 | D3: 2026 | E3: MBWAY_PAR | F3: MBWAY | G3: BAC_MGT | H3: B2 | I3: ALT | J3: 76 | K3: 3 | L3: 595840 | M3: 36218.8 | N3: 121040.4 | O3: 28279.162 | P3: 289032.97 | Q3: 18161.482 | R3: 72047.253 | S3: 90208.735 | T3: 64497.962 | U3: 500282.11 | V3: 564780.07 | W3: 31059.929 | X3: 0 | Y3: 181094 | Z3: 605202 | AA3: 142140 | AB3: 68291 | AC3: 1452771 | AD3: 2891983 | AE3: 676344
A4: 2027BUD_V1 | B4: ACT | C4: 12 | D4: 2026 | E4: MBWAY_PAR | F4: MBWAY | G4: BAC_MGT | H4: B3 | I4: ALT | J4: 74 | K4: 3 | L4: 580160 | M4: 36218.8 | N4: 121040.4 | O4: 27534.974 | P4: 281426.84 | Q4: 17683.549 | R4: 70151.272 | S4: 87834.821 | T4: 63753.774 | U4: 490302.06 | V4: 554055.84 | W4: 26104.162 | X4: 0 | Y4: 181094 | Z4: 605202 | AA4: 142140 | AB4: 68291 | AC4: 1452771 | AD4: 2891983 | AE4: 676344
A5: 2027BUD_V1 | B5: ACT | C5: 12 | D5: 2026 | E5: MBWAY_PAR | F5: MBWAY | G5: MAS_MGT | H5: M1 | I5: ALT | J5: 78 | K5: 3 | L5: 662220 | M5: 31691.45 | N5: 105910.35 | O5: 63168.851 | P5: 296639.1 | Q5: 18639.416 | R5: 73943.233 | S5: 92582.649 | T5: 94860.301 | U5: 495132.1 | V5: 589992.4 | W5: 72227.596 | X5: 78 | Y5: 181094 | Z5: 605202 | AA5: 142140 | AB5: 68291 | AC5: 1452771 | AD5: 2891983 | AE5: 676344
A6: 2027BUD_V1 | B6: ACT | C6: 12 | D6: 2026 | E6: MBWAY_PAR | F6: MBWAY | G6: MAS_MGT | H6: M2 | I6: ALT | J6: 76 | K6: 3 | L6: 638400 | M6: 31691.45 | N6: 105910.35 | O6: 28279.162 | P6: 289032.97 | Q6: 18161.482 | R6: 72047.253 | S6: 90208.735 | T6: 59970.612 | U6: 485152.06 | V6: 545122.67 | W6: 93277.329 | X6: 0 | Y6: 181094 | Z6: 605202 | AA6: 142140 | AB6: 68291 | AC6: 1452771 | AD6: 2891983 | AE6: 676344
A7: 2027BUD_V1 | B7: ACT | C7: 12 | D7: 2026 | E7: MBWAY_LYO | F7: MBWAY | G7: BAC_MGT | H7: B1 | I7: INIT | J7: 66 | K7: 3 | L7: 525690 | M7: 45273.462 | N7: 104602.79 | O7: 45449.815 | P7: 174738.26 | Q7: 14791.017 | R7: 58676.496 | S7: 73467.513 | T7: 90723.276 | U7: 352808.56 | V7: 443531.84 | W7: 82158.163 | X7: 66 | Y7: 156948 | Z7: 362623 | AA7: 120559 | AB7: 41783 | AC7: 857806 | AD7: 2891983 | AE7: 676344
A8: 2027BUD_V1 | B8: ACT | C8: 12 | D8: 2026 | E8: MBWAY_LYO | F8: MBWAY | G8: BAC_MGT | H8: B2 | I8: ALT | J8: 64 | K8: 2 | L8: 470400 | M8: 24145.846 | N8: 55788.154 | O8: 23814.123 | P8: 169443.16 | Q8: 14342.805 | R8: 56898.421 | S8: 71241.225 | T8: 47959.97 | U8: 296472.54 | V8: 344432.51 | W8: 125967.49 | X8: 0 | Y8: 156948 | Z8: 362623 | AA8: 120559 | AB8: 41783 | AC8: 857806 | AD8: 2891983 | AE8: 676344
A9: 2027BUD_V1 | B9: ACT | C9: 12 | D9: 2026 | E9: MBWAY_LYO | F9: MBWAY | G9: BAC_MGT | H9: B3 | I9: ALT | J9: 63 | K9: 2 | L9: 463050 | M9: 24145.846 | N9: 55788.154 | O9: 23442.028 | P9: 166795.61 | Q9: 14118.698 | R9: 56009.383 | S9: 70128.081 | T9: 47587.874 | U9: 292711.85 | V9: 340299.72 | W9: 122750.28 | X9: 0 | Y9: 156948 | Z9: 362623 | AA9: 120559 | AB9: 41783 | AC9: 857806 | AD9: 2891983 | AE9: 676344
A10: 2027BUD_V1 | B10: ACT | C10: 12 | D10: 2026 | E10: MBWAY_LYO | F10: MBWAY | G10: MAS_MGT | H10: M1 | I10: ALT | J10: 66 | K10: 3 | L10: 525690 | M10: 31691.423 | N10: 73221.952 | O10: 45449.815 | P10: 174738.26 | Q10: 14791.017 | R10: 58676.496 | S10: 73467.513 | T10: 77141.238 | U10: 321427.72 | V10: 398568.96 | W10: 127121.04 | X10: 66 | Y10: 156948 | Z10: 362623 | AA10: 120559 | AB10: 41783 | AC10: 857806 | AD10: 2891983 | AE10: 676344
A11: 2027BUD_V1 | B11: ACT | C11: 12 | D11: 2026 | E11: MBWAY_LYO | F11: MBWAY | G11: MAS_MGT | H11: M2 | I11: ALT | J11: 65 | K11: 3 | L11: 511875 | M11: 31691.423 | N11: 73221.952 | O11: 24186.219 | P11: 172090.71 | Q11: 14566.911 | R11: 57787.458 | S11: 72354.369 | T11: 55877.642 | U11: 317667.03 | V11: 373544.67 | W11: 138330.33 | X11: 0 | Y11: 156948 | Z11: 362623 | AA11: 120559 | AB11: 41783 | AC11: 857806 | AD11: 2891983 | AE11: 676344
A12: 2027BUD_V1 | B12: ACT | C12: 12 | D12: 2026 | E12: MBWAY_NAN | F12: MBWAY | G12: BAC_MGT | H12: B1 | I12: INIT | J12: 60 | K12: 2 | L12: 455400 | M12: 30824.468 | N12: 63588.298 | O12: 38092.214 | P12: 142624.69 | Q12: 12809.955 | R12: 50817.553 | S12: 63627.508 | T12: 68916.682 | U12: 269840.5 | V12: 338757.18 | W12: 116642.82 | X12: 60 | Y12: 144875 | Z12: 298865 | AA12: 109396 | AB12: 31533 | AC12: 698861 | AD12: 2891983 | AE12: 676344
A13: 2027BUD_V1 | B13: ACT | C13: 12 | D13: 2026 | E13: MBWAY_NAN | F13: MBWAY | G13: BAC_MGT | H13: B2 | I13: ALT | J13: 58 | K13: 2 | L13: 406000 | M13: 24659.574 | N13: 50870.638 | O13: 21581.524 | P13: 137870.54 | Q13: 12382.957 | R13: 49123.634 | S13: 61506.591 | T13: 46241.098 | U13: 250247.77 | V13: 296488.87 | W13: 109511.13 | X13: 0 | Y13: 144875 | Z13: 298865 | AA13: 109396 | AB13: 31533 | AC13: 698861 | AD13: 2891983 | AE13: 676344
... A349: 2027BUD_V1 | B349: V03 | C349: 12 | D349: 2027 | E349: TUNON_LYO | F349: TUNON | G349: BAC_TOU | H349: B3 | I349: ALT | J349: 37.61 | K349: 2 | L349: 282238.6 | M349: 23662.109 | N349: 60334.722 | O349: 14257.544 | P349: 121375.97 | Q349: 8009.608 | R349: 41910.512 | S349: 49920.12 | T349: 37919.654 | U349: 231630.81 | V349: 269550.47 | W349: 12688.138 | X349: 0 | Y349: 70986.328 | Z349: 181004.17 | AA349: 42662.55 | AB349: 17907.5 | AC349: 363190.76 | AD349: 3092074.3 | AE349: 642526.8

Sheet _CALC_ALLOC
A1: EXERCICE | B1: ENTITY | C1: MARQUE | D1: PROG | E1: AN | F1: MOD | G1: VOL_EFF | H1: VOL_CLASS | I1: CA | J1: VOL_NEW | K1: HRS | L1: E_EFF | M1: E_CLS | N1: E_CA | O1: E_HRS | P1: E_NEW | Q1: M_EFF | R1: M_CLS | S1: M_CA | T1: G_EFF | U1: G_CLS | V1: G_CA | W1: VAC | X1: PERM | Y1: ODIR | Z1: MKT | AA1: STRUCT_CAMP | AB1: SIEGE | AC1: D3C | AD1: D3E | AE1: D2E | AF1: D2M | AG1: D1M | AH1: D1G | AI1: COST_VAC | AJ1: COST_PERM | AK1: COST_ODIR | AL1: COST_STRUCT | AM1: COST_SIEGE | AN1: MARGE | AO1: FRAIS_MARQUE_TOT | AP1: D1M_K4 | AQ1: D1G_K4 | AR1: COST_MARQUE | AT1: ■ VIOLET = colonne branchee sur une saisie (cad / Pilotage / 3_Allocation) -> a recabler cote Tagetik
