Workbook
Name BUD_REF_CAP: Pilotage!$K$19:$K$32
Name HYP_ACQ_BUD_V01: Cadrage!$C$23
Name HYP_ACQ_BUD_V02: Cadrage!$D$23
Name HYP_ACQ_BUD_V03: Cadrage!$E$23
Name HYP_BRAND_BUD_V01: Cadrage!$C$24
Name HYP_BRAND_BUD_V02: Cadrage!$D$24
Name HYP_BRAND_BUD_V03: Cadrage!$E$24
Name HYP_CAP_RETENU: Pilotage!$J$19:$J$32
Name HYP_CONV_ADM_V01: Cadrage!$C$27
Name HYP_CONV_ADM_V02: Cadrage!$D$27
Name HYP_CONV_ADM_V03: Cadrage!$E$27
Name HYP_CONV_LEAD_V01: Cadrage!$C$26
Name HYP_CONV_LEAD_V02: Cadrage!$D$26
Name HYP_CONV_LEAD_V03: Cadrage!$E$26
Name HYP_FEE_V01: Cadrage!$C$42
Name HYP_FEE_V02: Cadrage!$D$42
Name HYP_FEE_V03: Cadrage!$E$42
Name HYP_FTE_PERM_V01: Cadrage!$C$34
Name HYP_FTE_PERM_V02: Cadrage!$D$34
Name HYP_FTE_PERM_V03: Cadrage!$E$34
Name HYP_INFL_EXT_V01: Cadrage!$C$32
Name HYP_INFL_EXT_V02: Cadrage!$D$32
Name HYP_INFL_EXT_V03: Cadrage!$E$32
Name HYP_PASSAGE_V01: Cadrage!$C$28
Name HYP_PASSAGE_V02: Cadrage!#REF!
Name HYP_PASSAGE_V03: Cadrage!$D$28
Name HYP_PRICE_COEF_IPAC: Cadrage!#REF!
Name HYP_PRICE_COEF_ISCOM: Cadrage!$K$35
Name HYP_PRICE_COEF_MBWAY: Cadrage!$K$34
Name HYP_PRICE_COEF_PIGIER: Cadrage!$K$36
Name HYP_PRICE_COEF_TUNON: Cadrage!#REF!
Name HYP_PRICE_V01: Cadrage!$C$25
Name HYP_PRICE_V02: Cadrage!$D$25
Name HYP_PRICE_V03: Cadrage!$E$25
Name HYP_PRODUCTIVITY_V01: Cadrage!$C$35
Name HYP_PRODUCTIVITY_V02: Cadrage!$D$35
Name HYP_PRODUCTIVITY_V03: Cadrage!$E$35
Name HYP_SALARY_V01: Cadrage!$C$33
Name HYP_SALARY_V02: Cadrage!$D$33
Name HYP_SALARY_V03: Cadrage!$E$33
Name HYP_STRUCT_COST_V01: Cadrage!#REF!
Name HYP_STRUCT_COST_V02: Cadrage!#REF!
Name HYP_STRUCT_COST_V03: Cadrage!#REF!
Name SCENARIO_ACTIF: Cadrage!$C$5
Name SCENARIO_CODE: Cadrage!$P$1
Name TEC_EBITDA: Cadrage!$F$6
Name TEC_PL: Cadrage!#REF!

Sheet _TGK_HIDDEN
A1: Template00 | B1: =Cadrage!A65545 -> 0
A2: Template01 | B2: =Socle!A65536 -> 0
A3: Template02 | B3: =Campagne!A65536 -> 0
A4: Template03 | B4: =Moteur!A65536 -> 0
A5: Template04 | B5: =Comptabilité!A65536 -> 0
A6: Template05 | B6: =PNL!A65536 -> 0
A7: Template06 | B7: =Pilotage!A65544 -> 0

Sheet Cadrage
P1: =IF($C$5="Cadrage","V01",IF($C$5="Optimiste","V02","V03")) -> V01
C2: Hypothèses & scénarios 2027
B5: Scenario actif : | C5: Cadrage | D5: Objectif d'EBITDA | F5: 0.065
B7: OBJECTIF 2027 | D7: CE QUE LES LEVIERS PRODUISENT | F7: RESTE À TROUVER
B8: =C13*(1+F5) -> 4095766.4 | D8: =D13 -> 4111503.6 | F8: =$B$8-D8 -> -15737.279
B9: ="+"&TEXT($F$5,"0,00%")&" sur "&TEXT(C13,"# ##0 €")&" en 2026, soit "&TEXT($B$8-C13,"+# ##0 €")&" à trouver" -> +007% sur 3845 790 € en 2026, soit +249 976 € à trouver | D9: ="scénario « "&$C$5&" » · marge "&TEXT(D14,"0,0%") -> scénario « Cadrage » · marge 17% | F9: objectif moins construit · se ferme à chaque levier
B10: ① RÉCONCILIATION | F10: de 2026 au scénario construit
B11: Indicateur | C11: Référence 2026 | D11: Construit 2027 | E11: Écart | F11: Écart % | W11: EXERCICE | X11: CA | Y11: EBITDA | Z11: MARGE EBITDA
B12: Chiffre d'affaires | C12: 23098985 | D12: =_xlfn.SUMIFS(Moteur!$R$1:$R$200,Moteur!$B$1:$B$200,Cadrage!$P$1) -> 24231704 | E12: =D12-C12 -> 1132718.5 | F12: =_xlfn.IFERROR(D12/C12-1,0) -> 0.04903759 | W12: 2024 | X12: 20567210 | Y12: 3151035 | Z12: 0.1532
B13: EBITDA | C13: 3845790 | D13: =_xlfn.SUMIFS(_CALC_PNL!$T$1:$T$1347,_CALC_PNL!$D$1:$D$1347,Cadrage!$P$1,_CALC_PNL!$C$1:$C$1347,"2027") -> 4111503.6 | E13: =D13-C13 -> 265713.63 | F13: =_xlfn.IFERROR(D13/C13-1,0) -> 0.06909208 | W13: 2025 | X13: 21758770 | Y13: 3467768 | Z13: 0.1594
B14: Marge EBITDA % | C14: =_xlfn.IFERROR(C13/C12,0) -> 0.16649173 | D14: =_xlfn.IFERROR(D13/D12,0) -> 0.16967456 | E14: =D14-C14 -> 0.0031828285 | W14: 2026 | X14: 23098985 | Y14: 3845790 | Z14: 0.1665
B15: Effectif | C15: 3114 | D15: =_xlfn.SUMIFS(Moteur!$P$1:$P$200,Moteur!$B$1:$B$200,Cadrage!$P$1) -> 3253.6168 | E15: =D15-C15 -> 139.61681 | F15: =_xlfn.IFERROR(D15/C15-1,0) -> 0.044835198 | W15: 2027 | X15: =D12 -> 24231704 | Y15: =D13 -> 4111503.6 | Z15: =D14 -> 0.16967456
B18: ② LES DOUZE LEVIERS
B19: Levier | C19: Cadrage | D19: Optimiste | E19: Prudent | F19: RETENU
B21: CROISSANCE · ce qui fait le chiffre d'affaires
C22: Cadrage | D22: Optimiste | E22: Prudent
B23: Variation du budget d'acquisition → leads payants | C23: 0.08 | D23: 0.15 | E23: -0.05 | F23: =INDEX(C23:E23,MATCH(Cadrage!$C$5,$C$22:$E$22,0)) -> 0.08
B24: Variation du budget de marque → socle organique | C24: 0.1 | D24: 0.15 | E24: -0.05 | F24: =INDEX(C24:E24,MATCH(Cadrage!$C$5,$C$22:$E$22,0)) -> 0.1
B25: Hausse tarifaire (prix) | C25: 0.0029 | D25: 0.035 | E25: 0.02 | F25: =INDEX(C25:E25,MATCH(Cadrage!$C$5,$C$22:$E$22,0)) -> 0.0029
B26: Gain du taux de conversion Lead → Candidature | C26: 0.01 | D26: 0.03 | E26: -0.01 | F26: =INDEX(C26:E26,MATCH(Cadrage!$C$5,$C$22:$E$22,0)) -> 0.01
B27: Gain du taux de conversion Admis → Inscrit | C27: 0.01 | D27: 0.025 | E27: -0.01 | F27: =INDEX(C27:E27,MATCH(Cadrage!$C$5,$C$22:$E$22,0)) -> 0.01
B28: Amélioration du taux de passage | C28: 0.005 | D28: 0.015 | E28: -0.01 | F28: =INDEX(C28:E28,MATCH(Cadrage!$C$5,$C$22:$E$22,0)) -> 0.005
B32: COÛTS · ce qui fait la marge | J32: ③ COEFFICIENTS DE PRIX
B34: Inflation des charges externes | C34: 0.02 | D34: 0.015 | E34: 0.03 | F34: =INDEX(C34:E34,MATCH(Cadrage!$C$5,$C$22:$E$22,0)) -> 0.02 | J34: MBway | K34: 1.2
B35: Politique salariale sur la masse permanente | C35: 0.025 | D35: 0.02 | E35: 0.03 | F35: =INDEX(C35:E35,MATCH(Cadrage!$C$5,$C$22:$E$22,0)) -> 0.025 | J35: ISCOM | K35: 1.15
B36: Variation des effectifs permanents | C36: 0.04 | D36: 0.03 | E36: 0.05 | F36: =INDEX(C36:E36,MATCH(Cadrage!$C$5,$C$22:$E$22,0)) -> 0.04 | J36: Ipac Bachelor Factory | K36: 0.95
B37: Effort de productivité sur les achats et la structure | C37: 0.0185 | D37: 0.03 | F37: =INDEX(C37:E37,MATCH(Cadrage!$C$5,$C$22:$E$22,0)) -> 0.0185 | J37: Pigier | K37: 0.9
B38: Variation des coûts de structure (loyers, IT, siège…) | D38: -0.03 | E38: 0.04 | F38: =INDEX(C38:E38,MATCH(Cadrage!$C$5,$C$22:$E$22,0)) -> 0 | J38: Tunon | K38: 1.05
B40: CONSTANTE · hors scénario, saisie directe
B42: Frais de dossier par nouvel inscrit | C42: 90 | D42: 90 | E42: 90 | F42: =INDEX(C42:E42,MATCH(Cadrage!$C$5,$C$22:$E$22,0)) -> 90

Sheet Pilotage
O1: code scénario -> | P1: =IF($E$6="Cadrage","V01",IF($E$6="Optimiste","V02","V03")) -> V01
G2: PILOTAGE · Cockpit de decision CFO · Budget 2027
B6: Scenario actif : | E6: Cadrage
B9: CA 2027 | D9: EBITDA (apres siege) | F9: Marge EBITDA | H9: Effectif | J9: Croissance CA vs 2026
B10: =E55 -> 24231704 | D10: =H55 -> 4111503.6 | F10: =I55 -> 0.16967456 | H10: =D55 -> 3253.6168 | J10: =_xlfn.IFERROR(E55/Cadrage!$C$12-1,0) -> 0.04903759
B11: ="contre "&TEXT(Cadrage!$C$12,"#,##0 €")&" en 2026" -> contre 23.098.985 € en 2026 | D11: ="contre "&TEXT(Cadrage!$C$13,"#,##0 €")&" en 2026" -> contre 3.845.790 € en 2026 | F11: ="contre "&TEXT(Cadrage!$C$14,"0.0%")&" en 2026" -> contre 16,6% en 2026 | H11: ="contre "&TEXT(Cadrage!$C$15,"#,##0")&" en 2026" -> contre 3.114 en 2026 | J11: vs 2026
B16: 1 · Cap strategique par campus (marque x campus) - arbitrage du budget d'acquisition
U17: à masquer | V17: à masquer | W17: à masquer
A18: Campus | B18: Marque | C18: Ville | D18: CAC marginal | E18: Croiss. leads | F18: Intensité mkt | G18: Cap Eff | H18: Cap mom. | I18: Cap pot. | J18: Cap retenu | K18: Budget acq réf. | L18: Entity | U18: CAP_EFF (live) | V18: CAP_MOM (live) | W18: CAP_POT (live)
A19: =$L19 -> IPAC_MTP | B19: =IF(LEFT($L19,5)="MBWAY","MBway",IF(LEFT($L19,5)="ISCOM","ISCOM",IF(LEFT($L19,4)="IPAC","Ipac",IF(LEFT($L19,6)="PIGIER","Pigier",IF(LEFT($L19,5)="TUNON","Tunon",""))))) -> Ipac | C19: =IF(RIGHT($L19,3)="PAR","Paris",IF(RIGHT($L19,3)="LYO","Lyon",IF(RIGHT($L19,3)="NAN","Nantes",IF(RIGHT($L19,3)="BOR","Bordeaux",IF(RIGHT($L19,3)="LIL","Lille",IF(RIGHT($L19,3)="TLS","Toulouse",IF(RIGHT($L19,3)="REN","Rennes",IF(RIGHT($L19,3)="MTP","Montpellier","")))))))) -> Montpellier | D19: 1033.9846 | E19: 0.144781 | F19: 0.019417 | G19: 1.1626041 | H19: 1.385517 | I19: 0.94434 | J19: 1 | K19: 15178 | L19: IPAC_MTP
A20: =$L20 -> IPAC_NAN | B20: =IF(LEFT($L20,5)="MBWAY","MBway",IF(LEFT($L20,5)="ISCOM","ISCOM",IF(LEFT($L20,4)="IPAC","Ipac",IF(LEFT($L20,6)="PIGIER","Pigier",IF(LEFT($L20,5)="TUNON","Tunon",""))))) -> Ipac | C20: =IF(RIGHT($L20,3)="PAR","Paris",IF(RIGHT($L20,3)="LYO","Lyon",IF(RIGHT($L20,3)="NAN","Nantes",IF(RIGHT($L20,3)="BOR","Bordeaux",IF(RIGHT($L20,3)="LIL","Lille",IF(RIGHT($L20,3)="TLS","Toulouse",IF(RIGHT($L20,3)="REN","Rennes",IF(RIGHT($L20,3)="MTP","Montpellier","")))))))) -> Nantes | D20: 1216.2931 | E20: 0.137884 | F20: 0.021343 | G20: 0.98834297 | H20: 1.319514 | I20: 0.85913 | J20: 1 | K20: 21760 | L20: IPAC_NAN
A21: =$L21 -> IPAC_REN | B21: =IF(LEFT($L21,5)="MBWAY","MBway",IF(LEFT($L21,5)="ISCOM","ISCOM",IF(LEFT($L21,4)="IPAC","Ipac",IF(LEFT($L21,6)="PIGIER","Pigier",IF(LEFT($L21,5)="TUNON","Tunon",""))))) -> Ipac | C21: =IF(RIGHT($L21,3)="PAR","Paris",IF(RIGHT($L21,3)="LYO","Lyon",IF(RIGHT($L21,3)="NAN","Nantes",IF(RIGHT($L21,3)="BOR","Bordeaux",IF(RIGHT($L21,3)="LIL","Lille",IF(RIGHT($L21,3)="TLS","Toulouse",IF(RIGHT($L21,3)="REN","Rennes",IF(RIGHT($L21,3)="MTP","Montpellier","")))))))) -> Rennes | D21: 1040.5564 | E21: 0.144781 | F21: 0.019104 | G21: 1.1552615 | H21: 1.385517 | I21: 0.959834 | J21: 1 | K21: 14933 | L21: IPAC_REN
A22: =$L22 -> ISCOM_LIL | B22: =IF(LEFT($L22,5)="MBWAY","MBway",IF(LEFT($L22,5)="ISCOM","ISCOM",IF(LEFT($L22,4)="IPAC","Ipac",IF(LEFT($L22,6)="PIGIER","Pigier",IF(LEFT($L22,5)="TUNON","Tunon",""))))) -> ISCOM | C22: =IF(RIGHT($L22,3)="PAR","Paris",IF(RIGHT($L22,3)="LYO","Lyon",IF(RIGHT($L22,3)="NAN","Nantes",IF(RIGHT($L22,3)="BOR","Bordeaux",IF(RIGHT($L22,3)="LIL","Lille",IF(RIGHT($L22,3)="TLS","Toulouse",IF(RIGHT($L22,3)="REN","Rennes",IF(RIGHT($L22,3)="MTP","Montpellier","")))))))) -> Lille | D22: 978.58461 | E22: 0.081545 | F22: 0.014363 | G22: 1.2284219 | H22: 0.780364 | I22: 1.276654 | J22: 1 | K22: 25220 | L22: ISCOM_LIL
A23: =$L23 -> ISCOM_PAR | B23: =IF(LEFT($L23,5)="MBWAY","MBway",IF(LEFT($L23,5)="ISCOM","ISCOM",IF(LEFT($L23,4)="IPAC","Ipac",IF(LEFT($L23,6)="PIGIER","Pigier",IF(LEFT($L23,5)="TUNON","Tunon",""))))) -> ISCOM | C23: =IF(RIGHT($L23,3)="PAR","Paris",IF(RIGHT($L23,3)="LYO","Lyon",IF(RIGHT($L23,3)="NAN","Nantes",IF(RIGHT($L23,3)="BOR","Bordeaux",IF(RIGHT($L23,3)="LIL","Lille",IF(RIGHT($L23,3)="TLS","Toulouse",IF(RIGHT($L23,3)="REN","Rennes",IF(RIGHT($L23,3)="MTP","Montpellier","")))))))) -> Paris | D23: 1540.325 | E23: 0.077744 | F23: 0.020902 | G23: 0.78042932 | H23: 0.74399 | I23: 0.877261 | J23: 1 | K23: 60800 | L23: ISCOM_PAR
A24: =$L24 -> ISCOM_TLS | B24: =IF(LEFT($L24,5)="MBWAY","MBway",IF(LEFT($L24,5)="ISCOM","ISCOM",IF(LEFT($L24,4)="IPAC","Ipac",IF(LEFT($L24,6)="PIGIER","Pigier",IF(LEFT($L24,5)="TUNON","Tunon",""))))) -> ISCOM | C24: =IF(RIGHT($L24,3)="PAR","Paris",IF(RIGHT($L24,3)="LYO","Lyon",IF(RIGHT($L24,3)="NAN","Nantes",IF(RIGHT($L24,3)="BOR","Bordeaux",IF(RIGHT($L24,3)="LIL","Lille",IF(RIGHT($L24,3)="TLS","Toulouse",IF(RIGHT($L24,3)="REN","Rennes",IF(RIGHT($L24,3)="MTP","Montpellier","")))))))) -> Toulouse | D24: 919.03477 | E24: 0.082116 | F24: 0.013564 | G24: 1.3080188 | H24: 0.785829 | I24: 1.351829 | J24: 1 | K24: 22083 | L24: ISCOM_TLS
A25: =$L25 -> MBWAY_BOR | B25: =IF(LEFT($L25,5)="MBWAY","MBway",IF(LEFT($L25,5)="ISCOM","ISCOM",IF(LEFT($L25,4)="IPAC","Ipac",IF(LEFT($L25,6)="PIGIER","Pigier",IF(LEFT($L25,5)="TUNON","Tunon",""))))) -> MBway | C25: =IF(RIGHT($L25,3)="PAR","Paris",IF(RIGHT($L25,3)="LYO","Lyon",IF(RIGHT($L25,3)="NAN","Nantes",IF(RIGHT($L25,3)="BOR","Bordeaux",IF(RIGHT($L25,3)="LIL","Lille",IF(RIGHT($L25,3)="TLS","Toulouse",IF(RIGHT($L25,3)="REN","Rennes",IF(RIGHT($L25,3)="MTP","Montpellier","")))))))) -> Bordeaux | D25: 889.59329 | E25: 0.126094 | F25: 0.014052 | G25: 1.3513083 | H25: 1.206687 | I25: 1.304934 | J25: 1 | K25: 24923 | L25: MBWAY_BOR
A26: =$L26 -> MBWAY_LYO | B26: =IF(LEFT($L26,5)="MBWAY","MBway",IF(LEFT($L26,5)="ISCOM","ISCOM",IF(LEFT($L26,4)="IPAC","Ipac",IF(LEFT($L26,6)="PIGIER","Pigier",IF(LEFT($L26,5)="TUNON","Tunon",""))))) -> MBway | C26: =IF(RIGHT($L26,3)="PAR","Paris",IF(RIGHT($L26,3)="LYO","Lyon",IF(RIGHT($L26,3)="NAN","Nantes",IF(RIGHT($L26,3)="BOR","Bordeaux",IF(RIGHT($L26,3)="LIL","Lille",IF(RIGHT($L26,3)="TLS","Toulouse",IF(RIGHT($L26,3)="REN","Rennes",IF(RIGHT($L26,3)="MTP","Montpellier","")))))))) -> Lyon | D26: 1101.6048 | E26: 0.118871 | F26: 0.016735 | G26: 1.0912396 | H26: 1.137565 | I26: 1.095717 | J26: 1 | K26: 41783 | L26: MBWAY_LYO
A27: =$L27 -> MBWAY_NAN | B27: =IF(LEFT($L27,5)="MBWAY","MBway",IF(LEFT($L27,5)="ISCOM","ISCOM",IF(LEFT($L27,4)="IPAC","Ipac",IF(LEFT($L27,6)="PIGIER","Pigier",IF(LEFT($L27,5)="TUNON","Tunon",""))))) -> MBway | C27: =IF(RIGHT($L27,3)="PAR","Paris",IF(RIGHT($L27,3)="LYO","Lyon",IF(RIGHT($L27,3)="NAN","Nantes",IF(RIGHT($L27,3)="BOR","Bordeaux",IF(RIGHT($L27,3)="LIL","Lille",IF(RIGHT($L27,3)="TLS","Toulouse",IF(RIGHT($L27,3)="REN","Rennes",IF(RIGHT($L27,3)="MTP","Montpellier","")))))))) -> Nantes | D27: 963.57687 | E27: 0.123795 | F27: 0.01461 | G27: 1.2475546 | H27: 1.184686 | I27: 1.255097 | J27: 1 | K27: 31533 | L27: MBWAY_NAN
A28: =$L28 -> MBWAY_PAR | B28: =IF(LEFT($L28,5)="MBWAY","MBway",IF(LEFT($L28,5)="ISCOM","ISCOM",IF(LEFT($L28,4)="IPAC","Ipac",IF(LEFT($L28,6)="PIGIER","Pigier",IF(LEFT($L28,5)="TUNON","Tunon",""))))) -> MBway | C28: =IF(RIGHT($L28,3)="PAR","Paris",IF(RIGHT($L28,3)="LYO","Lyon",IF(RIGHT($L28,3)="NAN","Nantes",IF(RIGHT($L28,3)="BOR","Bordeaux",IF(RIGHT($L28,3)="LIL","Lille",IF(RIGHT($L28,3)="TLS","Toulouse",IF(RIGHT($L28,3)="REN","Rennes",IF(RIGHT($L28,3)="MTP","Montpellier","")))))))) -> Paris | D28: 1475.0192 | E28: 0.110736 | F28: 0.021756 | G28: 0.81498244 | H28: 1.059715 | I28: 0.842823 | J28: 1 | K28: 68291 | L28: MBWAY_PAR
A29: =$L29 -> PIGIER_BOR | B29: =IF(LEFT($L29,5)="MBWAY","MBway",IF(LEFT($L29,5)="ISCOM","ISCOM",IF(LEFT($L29,4)="IPAC","Ipac",IF(LEFT($L29,6)="PIGIER","Pigier",IF(LEFT($L29,5)="TUNON","Tunon",""))))) -> Pigier | C29: =IF(RIGHT($L29,3)="PAR","Paris",IF(RIGHT($L29,3)="LYO","Lyon",IF(RIGHT($L29,3)="NAN","Nantes",IF(RIGHT($L29,3)="BOR","Bordeaux",IF(RIGHT($L29,3)="LIL","Lille",IF(RIGHT($L29,3)="TLS","Toulouse",IF(RIGHT($L29,3)="REN","Rennes",IF(RIGHT($L29,3)="MTP","Montpellier","")))))))) -> Bordeaux | D29: 1368.091 | E29: 0.087533 | F29: 0.019395 | G29: 0.87868042 | H29: 0.837668 | I29: 0.945444 | J29: 1 | K29: 21968 | L29: PIGIER_BOR
A30: =$L30 -> PIGIER_LYO | B30: =IF(LEFT($L30,5)="MBWAY","MBway",IF(LEFT($L30,5)="ISCOM","ISCOM",IF(LEFT($L30,4)="IPAC","Ipac",IF(LEFT($L30,6)="PIGIER","Pigier",IF(LEFT($L30,5)="TUNON","Tunon",""))))) -> Pigier | C30: =IF(RIGHT($L30,3)="PAR","Paris",IF(RIGHT($L30,3)="LYO","Lyon",IF(RIGHT($L30,3)="NAN","Nantes",IF(RIGHT($L30,3)="BOR","Bordeaux",IF(RIGHT($L30,3)="LIL","Lille",IF(RIGHT($L30,3)="TLS","Toulouse",IF(RIGHT($L30,3)="REN","Rennes",IF(RIGHT($L30,3)="MTP","Montpellier","")))))))) -> Lyon | D30: 1704.9846 | E30: 0.085003 | F30: 0.023262 | G30: 0.70505903 | H30: 0.813456 | I30: 0.788252 | J30: 1 | K30: 36612 | L30: PIGIER_LYO
... A32: =$L32 -> TUNON_PAR | B32: =IF(LEFT($L32,5)="MBWAY","MBway",IF(LEFT($L32,5)="ISCOM","ISCOM",IF(LEFT($L32,4)="IPAC","Ipac",IF(LEFT($L32,6)="PIGIER","Pigier",IF(LEFT($L32,5)="TUNON","Tunon",""))))) -> Tunon | C32: =IF(RIGHT($L32,3)="PAR","Paris",IF(RIGHT($L32,3)="LYO","Lyon",IF(RIGHT($L32,3)="NAN","Nantes",IF(RIGHT($L32,3)="BOR","Bordeaux",IF(RIGHT($L32,3)="LIL","Lille",IF(RIGHT($L32,3)="TLS","Toulouse",IF(RIGHT($L32,3)="REN","Rennes",IF(RIGHT($L32,3)="MTP","Montpellier","")))))))) -> Paris | D32: 2192.8927 | E32: 0.069518 | F32: 0.027841 | G32: 0.54818677 | H32: 0.665269 | I32: 0.658626 | J32: 1 | K32: 30240 | L32: TUNON_PAR
B36: 2 · Synthese par campus (resultats budget, live)
A38: Campus | B38: Marque | C38: Ville | D38: Effectif | E38: CA 2027 | F38: Prix moy. | G38: Part CA | H38: EBITDA campus | I38: Mrg EBITDA | J38: EBITDA/etud. | K38: Rejoue | L38: CAC marg.
A39: =A19 -> IPAC_MTP | B39: =B19 -> Ipac | C39: =C19 -> Montpellier | D39: =_xlfn.SUMIFS(Moteur!$P$1:$P$200,Moteur!$D$1:$D$200,$A39,Moteur!$B$1:$B$200,$P$1) -> 122.1326 | E39: =_xlfn.SUMIFS(Moteur!$R$1:$R$200,Moteur!$D$1:$D$200,$A39,Moteur!$B$1:$B$200,$P$1) -> 818445.73 | F39: =_xlfn.IFERROR(E39/D39,0) -> 6701.2881 | G39: =_xlfn.IFERROR(E39/SUM($E$39:$E$52),0) -> 0.033775823 | H39: =_xlfn.SUMIFS(_CALC_PNL!$T$1:$T$1347,_CALC_PNL!$A$1:$A$1347,$A39,_CALC_PNL!$D$1:$D$1347,$P$1,_CALC_PNL!$C$1:$C$1347,"2027") -> 254308.3 | I39: =_xlfn.IFERROR(H39/E39,0) -> 0.31072103 | J39: =_xlfn.IFERROR(H39/D39,0) -> 2082.2312 | K39: =_xlfn.SUMIFS(Pilotage!$K$19:$K$32,Pilotage!$A$19:$A$32,$A39)*_xlfn.SUMIFS(Pilotage!$J$19:$J$32,Pilotage!$A$19:$A$32,$A39)*(SUM(Pilotage!$K$19:$K$32)/SUMPRODUCT(Pilotage!$K$19:$K$32,Pilotage!$J$19:$J$32)) -> 15178 | L39: =_xlfn.SUMIFS(Pilotage!$D$19:$D$32,Pilotage!$A$19:$A$32,$A39) -> 1033.9846
A40: =A20 -> IPAC_NAN | B40: =B20 -> Ipac | C40: =C20 -> Nantes | D40: =_xlfn.SUMIFS(Moteur!$P$1:$P$200,Moteur!$D$1:$D$200,$A40,Moteur!$B$1:$B$200,$P$1) -> 151.32252 | E40: =_xlfn.SUMIFS(Moteur!$R$1:$R$200,Moteur!$D$1:$D$200,$A40,Moteur!$B$1:$B$200,$P$1) -> 1067200.8 | F40: =_xlfn.IFERROR(E40/D40,0) -> 7052.4917 | G40: =_xlfn.IFERROR(E40/SUM($E$39:$E$52),0) -> 0.044041509 | H40: =_xlfn.SUMIFS(_CALC_PNL!$T$1:$T$1347,_CALC_PNL!$A$1:$A$1347,$A40,_CALC_PNL!$D$1:$D$1347,$P$1,_CALC_PNL!$C$1:$C$1347,"2027") -> 331184.51 | I40: =_xlfn.IFERROR(H40/E40,0) -> 0.31033008 | J40: =_xlfn.IFERROR(H40/D40,0) -> 2188.6003 | K40: =_xlfn.SUMIFS(Pilotage!$K$19:$K$32,Pilotage!$A$19:$A$32,$A40)*_xlfn.SUMIFS(Pilotage!$J$19:$J$32,Pilotage!$A$19:$A$32,$A40)*(SUM(Pilotage!$K$19:$K$32)/SUMPRODUCT(Pilotage!$K$19:$K$32,Pilotage!$J$19:$J$32)) -> 21760 | L40: =_xlfn.SUMIFS(Pilotage!$D$19:$D$32,Pilotage!$A$19:$A$32,$A40) -> 1216.2931
A41: =A21 -> IPAC_REN | B41: =B21 -> Ipac | C41: =C21 -> Rennes | D41: =_xlfn.SUMIFS(Moteur!$P$1:$P$200,Moteur!$D$1:$D$200,$A41,Moteur!$B$1:$B$200,$P$1) -> 122.12158 | E41: =_xlfn.SUMIFS(Moteur!$R$1:$R$200,Moteur!$D$1:$D$200,$A41,Moteur!$B$1:$B$200,$P$1) -> 818371.29 | F41: =_xlfn.IFERROR(E41/D41,0) -> 6701.2829 | G41: =_xlfn.IFERROR(E41/SUM($E$39:$E$52),0) -> 0.033772751 | H41: =_xlfn.SUMIFS(_CALC_PNL!$T$1:$T$1347,_CALC_PNL!$A$1:$A$1347,$A41,_CALC_PNL!$D$1:$D$1347,$P$1,_CALC_PNL!$C$1:$C$1347,"2027") -> 254316.41 | I41: =_xlfn.IFERROR(H41/E41,0) -> 0.3107592 | J41: =_xlfn.IFERROR(H41/D41,0) -> 2082.4853 | K41: =_xlfn.SUMIFS(Pilotage!$K$19:$K$32,Pilotage!$A$19:$A$32,$A41)*_xlfn.SUMIFS(Pilotage!$J$19:$J$32,Pilotage!$A$19:$A$32,$A41)*(SUM(Pilotage!$K$19:$K$32)/SUMPRODUCT(Pilotage!$K$19:$K$32,Pilotage!$J$19:$J$32)) -> 14933 | L41: =_xlfn.SUMIFS(Pilotage!$D$19:$D$32,Pilotage!$A$19:$A$32,$A41) -> 1040.5564
A42: =A22 -> ISCOM_LIL | B42: =B22 -> ISCOM | C42: =C22 -> Lille | D42: =_xlfn.SUMIFS(Moteur!$P$1:$P$200,Moteur!$D$1:$D$200,$A42,Moteur!$B$1:$B$200,$P$1) -> 255.08663 | E42: =_xlfn.SUMIFS(Moteur!$R$1:$R$200,Moteur!$D$1:$D$200,$A42,Moteur!$B$1:$B$200,$P$1) -> 1844124.5 | F42: =_xlfn.IFERROR(E42/D42,0) -> 7229.4049 | G42: =_xlfn.IFERROR(E42/SUM($E$39:$E$52),0) -> 0.076103793 | H42: =_xlfn.SUMIFS(_CALC_PNL!$T$1:$T$1347,_CALC_PNL!$A$1:$A$1347,$A42,_CALC_PNL!$D$1:$D$1347,$P$1,_CALC_PNL!$C$1:$C$1347,"2027") -> 602778.74 | I42: =_xlfn.IFERROR(H42/E42,0) -> 0.32686444 | J42: =_xlfn.IFERROR(H42/D42,0) -> 2363.0354 | K42: =_xlfn.SUMIFS(Pilotage!$K$19:$K$32,Pilotage!$A$19:$A$32,$A42)*_xlfn.SUMIFS(Pilotage!$J$19:$J$32,Pilotage!$A$19:$A$32,$A42)*(SUM(Pilotage!$K$19:$K$32)/SUMPRODUCT(Pilotage!$K$19:$K$32,Pilotage!$J$19:$J$32)) -> 25220 | L42: =_xlfn.SUMIFS(Pilotage!$D$19:$D$32,Pilotage!$A$19:$A$32,$A42) -> 978.58461
A43: =A23 -> ISCOM_PAR | B43: =B23 -> ISCOM | C43: =C23 -> Paris | D43: =_xlfn.SUMIFS(Moteur!$P$1:$P$200,Moteur!$D$1:$D$200,$A43,Moteur!$B$1:$B$200,$P$1) -> 369.35233 | E43: =_xlfn.SUMIFS(Moteur!$R$1:$R$200,Moteur!$D$1:$D$200,$A43,Moteur!$B$1:$B$200,$P$1) -> 3048653.5 | F43: =_xlfn.IFERROR(E43/D43,0) -> 8254.0524 | G43: =_xlfn.IFERROR(E43/SUM($E$39:$E$52),0) -> 0.12581259 | H43: =_xlfn.SUMIFS(_CALC_PNL!$T$1:$T$1347,_CALC_PNL!$A$1:$A$1347,$A43,_CALC_PNL!$D$1:$D$1347,$P$1,_CALC_PNL!$C$1:$C$1347,"2027") -> 985765.87 | I43: =_xlfn.IFERROR(H43/E43,0) -> 0.32334468 | J43: =_xlfn.IFERROR(H43/D43,0) -> 2668.9039 | K43: =_xlfn.SUMIFS(Pilotage!$K$19:$K$32,Pilotage!$A$19:$A$32,$A43)*_xlfn.SUMIFS(Pilotage!$J$19:$J$32,Pilotage!$A$19:$A$32,$A43)*(SUM(Pilotage!$K$19:$K$32)/SUMPRODUCT(Pilotage!$K$19:$K$32,Pilotage!$J$19:$J$32)) -> 60800 | L43: =_xlfn.SUMIFS(Pilotage!$D$19:$D$32,Pilotage!$A$19:$A$32,$A43) -> 1540.325
A44: =A24 -> ISCOM_TLS | B44: =B24 -> ISCOM | C44: =C24 -> Toulouse | D44: =_xlfn.SUMIFS(Moteur!$P$1:$P$200,Moteur!$D$1:$D$200,$A44,Moteur!$B$1:$B$200,$P$1) -> 241.48135 | E44: =_xlfn.SUMIFS(Moteur!$R$1:$R$200,Moteur!$D$1:$D$200,$A44,Moteur!$B$1:$B$200,$P$1) -> 1709754.8 | F44: =_xlfn.IFERROR(E44/D44,0) -> 7080.2771 | G44: =_xlfn.IFERROR(E44/SUM($E$39:$E$52),0) -> 0.070558591 | H44: =_xlfn.SUMIFS(_CALC_PNL!$T$1:$T$1347,_CALC_PNL!$A$1:$A$1347,$A44,_CALC_PNL!$D$1:$D$1347,$P$1,_CALC_PNL!$C$1:$C$1347,"2027") -> 560009.03 | I44: =_xlfn.IFERROR(H44/E44,0) -> 0.32753762 | J44: =_xlfn.IFERROR(H44/D44,0) -> 2319.0571 | K44: =_xlfn.SUMIFS(Pilotage!$K$19:$K$32,Pilotage!$A$19:$A$32,$A44)*_xlfn.SUMIFS(Pilotage!$J$19:$J$32,Pilotage!$A$19:$A$32,$A44)*(SUM(Pilotage!$K$19:$K$32)/SUMPRODUCT(Pilotage!$K$19:$K$32,Pilotage!$J$19:$J$32)) -> 22083 | L44: =_xlfn.SUMIFS(Pilotage!$D$19:$D$32,Pilotage!$A$19:$A$32,$A44) -> 919.03477
A45: =A25 -> MBWAY_BOR | B45: =B25 -> MBway | C45: =C25 -> Bordeaux | D45: =_xlfn.SUMIFS(Moteur!$P$1:$P$200,Moteur!$D$1:$D$200,$A45,Moteur!$B$1:$B$200,$P$1) -> 260.41179 | E45: =_xlfn.SUMIFS(Moteur!$R$1:$R$200,Moteur!$D$1:$D$200,$A45,Moteur!$B$1:$B$200,$P$1) -> 1863775.7 | F45: =_xlfn.IFERROR(E45/D45,0) -> 7157.0326 | G45: =_xlfn.IFERROR(E45/SUM($E$39:$E$52),0) -> 0.076914761 | H45: =_xlfn.SUMIFS(_CALC_PNL!$T$1:$T$1347,_CALC_PNL!$A$1:$A$1347,$A45,_CALC_PNL!$D$1:$D$1347,$P$1,_CALC_PNL!$C$1:$C$1347,"2027") -> 625402.3 | I45: =_xlfn.IFERROR(H45/E45,0) -> 0.33555664 | J45: =_xlfn.IFERROR(H45/D45,0) -> 2401.5898 | K45: =_xlfn.SUMIFS(Pilotage!$K$19:$K$32,Pilotage!$A$19:$A$32,$A45)*_xlfn.SUMIFS(Pilotage!$J$19:$J$32,Pilotage!$A$19:$A$32,$A45)*(SUM(Pilotage!$K$19:$K$32)/SUMPRODUCT(Pilotage!$K$19:$K$32,Pilotage!$J$19:$J$32)) -> 24923 | L45: =_xlfn.SUMIFS(Pilotage!$D$19:$D$32,Pilotage!$A$19:$A$32,$A45) -> 889.59329
A46: =A26 -> MBWAY_LYO | B46: =B26 -> MBway | C46: =C26 -> Lyon | D46: =_xlfn.SUMIFS(Moteur!$P$1:$P$200,Moteur!$D$1:$D$200,$A46,Moteur!$B$1:$B$200,$P$1) -> 338.49824 | E46: =_xlfn.SUMIFS(Moteur!$R$1:$R$200,Moteur!$D$1:$D$200,$A46,Moteur!$B$1:$B$200,$P$1) -> 2620797.3 | F46: =_xlfn.IFERROR(E46/D46,0) -> 7742.4254 | G46: =_xlfn.IFERROR(E46/SUM($E$39:$E$52),0) -> 0.10815572 | H46: =_xlfn.SUMIFS(_CALC_PNL!$T$1:$T$1347,_CALC_PNL!$A$1:$A$1347,$A46,_CALC_PNL!$D$1:$D$1347,$P$1,_CALC_PNL!$C$1:$C$1347,"2027") -> 876442.71 | I46: =_xlfn.IFERROR(H46/E46,0) -> 0.33441835 | J46: =_xlfn.IFERROR(H46/D46,0) -> 2589.2091 | K46: =_xlfn.SUMIFS(Pilotage!$K$19:$K$32,Pilotage!$A$19:$A$32,$A46)*_xlfn.SUMIFS(Pilotage!$J$19:$J$32,Pilotage!$A$19:$A$32,$A46)*(SUM(Pilotage!$K$19:$K$32)/SUMPRODUCT(Pilotage!$K$19:$K$32,Pilotage!$J$19:$J$32)) -> 41783 | L46: =_xlfn.SUMIFS(Pilotage!$D$19:$D$32,Pilotage!$A$19:$A$32,$A46) -> 1101.6048
A47: =A27 -> MBWAY_NAN | B47: =B27 -> MBway | C47: =C27 -> Nantes | D47: =_xlfn.SUMIFS(Moteur!$P$1:$P$200,Moteur!$D$1:$D$200,$A47,Moteur!$B$1:$B$200,$P$1) -> 307.34298 | E47: =_xlfn.SUMIFS(Moteur!$R$1:$R$200,Moteur!$D$1:$D$200,$A47,Moteur!$B$1:$B$200,$P$1) -> 2267018.6 | F47: =_xlfn.IFERROR(E47/D47,0) -> 7376.1849 | G47: =_xlfn.IFERROR(E47/SUM($E$39:$E$52),0) -> 0.093555892 | H47: =_xlfn.SUMIFS(_CALC_PNL!$T$1:$T$1347,_CALC_PNL!$A$1:$A$1347,$A47,_CALC_PNL!$D$1:$D$1347,$P$1,_CALC_PNL!$C$1:$C$1347,"2027") -> 763702.73 | I47: =_xlfn.IFERROR(H47/E47,0) -> 0.33687537 | J47: =_xlfn.IFERROR(H47/D47,0) -> 2484.855 | K47: =_xlfn.SUMIFS(Pilotage!$K$19:$K$32,Pilotage!$A$19:$A$32,$A47)*_xlfn.SUMIFS(Pilotage!$J$19:$J$32,Pilotage!$A$19:$A$32,$A47)*(SUM(Pilotage!$K$19:$K$32)/SUMPRODUCT(Pilotage!$K$19:$K$32,Pilotage!$J$19:$J$32)) -> 31533 | L47: =_xlfn.SUMIFS(Pilotage!$D$19:$D$32,Pilotage!$A$19:$A$32,$A47) -> 963.57687
A48: =A28 -> MBWAY_PAR | B48: =B28 -> MBway | C48: =C28 -> Paris | D48: =_xlfn.SUMIFS(Moteur!$P$1:$P$200,Moteur!$D$1:$D$200,$A48,Moteur!$B$1:$B$200,$P$1) -> 398.78245 | E48: =_xlfn.SUMIFS(Moteur!$R$1:$R$200,Moteur!$D$1:$D$200,$A48,Moteur!$B$1:$B$200,$P$1) -> 3292150.8 | F48: =_xlfn.IFERROR(E48/D48,0) -> 8255.5057 | G48: =_xlfn.IFERROR(E48/SUM($E$39:$E$52),0) -> 0.1358613 | H48: =_xlfn.SUMIFS(_CALC_PNL!$T$1:$T$1347,_CALC_PNL!$A$1:$A$1347,$A48,_CALC_PNL!$D$1:$D$1347,$P$1,_CALC_PNL!$C$1:$C$1347,"2027") -> 1096393.8 | I48: =_xlfn.IFERROR(H48/E48,0) -> 0.33303268 | J48: =_xlfn.IFERROR(H48/D48,0) -> 2749.3532 | K48: =_xlfn.SUMIFS(Pilotage!$K$19:$K$32,Pilotage!$A$19:$A$32,$A48)*_xlfn.SUMIFS(Pilotage!$J$19:$J$32,Pilotage!$A$19:$A$32,$A48)*(SUM(Pilotage!$K$19:$K$32)/SUMPRODUCT(Pilotage!$K$19:$K$32,Pilotage!$J$19:$J$32)) -> 68291 | L48: =_xlfn.SUMIFS(Pilotage!$D$19:$D$32,Pilotage!$A$19:$A$32,$A48) -> 1475.0192
A49: =A29 -> PIGIER_BOR | B49: =B29 -> Pigier | C49: =C29 -> Bordeaux | D49: =_xlfn.SUMIFS(Moteur!$P$1:$P$200,Moteur!$D$1:$D$200,$A49,Moteur!$B$1:$B$200,$P$1) -> 184.71663 | E49: =_xlfn.SUMIFS(Moteur!$R$1:$R$200,Moteur!$D$1:$D$200,$A49,Moteur!$B$1:$B$200,$P$1) -> 1191512.5 | F49: =_xlfn.IFERROR(E49/D49,0) -> 6450.4887 | G49: =_xlfn.IFERROR(E49/SUM($E$39:$E$52),0) -> 0.049171637 | H49: =_xlfn.SUMIFS(_CALC_PNL!$T$1:$T$1347,_CALC_PNL!$A$1:$A$1347,$A49,_CALC_PNL!$D$1:$D$1347,$P$1,_CALC_PNL!$C$1:$C$1347,"2027") -> 455099.2 | I49: =_xlfn.IFERROR(H49/E49,0) -> 0.38195082 | J49: =_xlfn.IFERROR(H49/D49,0) -> 2463.7695 | K49: =_xlfn.SUMIFS(Pilotage!$K$19:$K$32,Pilotage!$A$19:$A$32,$A49)*_xlfn.SUMIFS(Pilotage!$J$19:$J$32,Pilotage!$A$19:$A$32,$A49)*(SUM(Pilotage!$K$19:$K$32)/SUMPRODUCT(Pilotage!$K$19:$K$32,Pilotage!$J$19:$J$32)) -> 21968 | L49: =_xlfn.SUMIFS(Pilotage!$D$19:$D$32,Pilotage!$A$19:$A$32,$A49) -> 1368.091
A50: =A30 -> PIGIER_LYO | B50: =B30 -> Pigier | C50: =C30 -> Lyon | D50: =_xlfn.SUMIFS(Moteur!$P$1:$P$200,Moteur!$D$1:$D$200,$A50,Moteur!$B$1:$B$200,$P$1) -> 236.94751 | E50: =_xlfn.SUMIFS(Moteur!$R$1:$R$200,Moteur!$D$1:$D$200,$A50,Moteur!$B$1:$B$200,$P$1) -> 1653869.9 | F50: =_xlfn.IFERROR(E50/D50,0) -> 6979.8999 | G50: =_xlfn.IFERROR(E50/SUM($E$39:$E$52),0) -> 0.068252317 | H50: =_xlfn.SUMIFS(_CALC_PNL!$T$1:$T$1347,_CALC_PNL!$A$1:$A$1347,$A50,_CALC_PNL!$D$1:$D$1347,$P$1,_CALC_PNL!$C$1:$C$1347,"2027") -> 626670.52 | I50: =_xlfn.IFERROR(H50/E50,0) -> 0.37891162 | J50: =_xlfn.IFERROR(H50/D50,0) -> 2644.7652 | K50: =_xlfn.SUMIFS(Pilotage!$K$19:$K$32,Pilotage!$A$19:$A$32,$A50)*_xlfn.SUMIFS(Pilotage!$J$19:$J$32,Pilotage!$A$19:$A$32,$A50)*(SUM(Pilotage!$K$19:$K$32)/SUMPRODUCT(Pilotage!$K$19:$K$32,Pilotage!$J$19:$J$32)) -> 36612 | L50: =_xlfn.SUMIFS(Pilotage!$D$19:$D$32,Pilotage!$A$19:$A$32,$A50) -> 1704.9846
... A52: =A32 -> TUNON_PAR | B52: =B32 -> Tunon | C52: =C32 -> Paris | D52: =_xlfn.SUMIFS(Moteur!$P$1:$P$200,Moteur!$D$1:$D$200,$A52,Moteur!$B$1:$B$200,$P$1) -> 143.56031 | E52: =_xlfn.SUMIFS(Moteur!$R$1:$R$200,Moteur!$D$1:$D$200,$A52,Moteur!$B$1:$B$200,$P$1) -> 1133628.6 | F52: =_xlfn.IFERROR(E52/D52,0) -> 7896.5321 | G52: =_xlfn.IFERROR(E52/SUM($E$39:$E$52),0) -> 0.046782868 | H52: =_xlfn.SUMIFS(_CALC_PNL!$T$1:$T$1347,_CALC_PNL!$A$1:$A$1347,$A52,_CALC_PNL!$D$1:$D$1347,$P$1,_CALC_PNL!$C$1:$C$1347,"2027") -> 220510.28 | I52: =_xlfn.IFERROR(H52/E52,0) -> 0.19451722 | J52: =_xlfn.IFERROR(H52/D52,0) -> 1536.0115 | K52: =_xlfn.SUMIFS(Pilotage!$K$19:$K$32,Pilotage!$A$19:$A$32,$A52)*_xlfn.SUMIFS(Pilotage!$J$19:$J$32,Pilotage!$A$19:$A$32,$A52)*(SUM(Pilotage!$K$19:$K$32)/SUMPRODUCT(Pilotage!$K$19:$K$32,Pilotage!$J$19:$J$32)) -> 30240 | L52: =_xlfn.SUMIFS(Pilotage!$D$19:$D$32,Pilotage!$A$19:$A$32,$A52) -> 2192.8927
A53: Sous-total campus | B53: Sous-total campus | D53: =SUM(D39:D52) -> 3253.6168 | E53: =SUM(E39:E52) -> 24231704 | F53: =_xlfn.IFERROR(E53/D53,0) -> 7447.6206 | G53: =SUM(G39:G52) -> 1 | H53: =SUM(H39:H52) -> 7831343.6 | I53: =_xlfn.IFERROR(H53/E53,0) -> 0.32318585 | J53: =_xlfn.IFERROR(H53/D53,0) -> 2406.9656 | K53: =SUM(K39:K52) -> 434174
A54: Siege / holding (GRP) | B54: Siege / holding (GRP) | H54: =_xlfn.SUMIFS(_CALC_PNL!$T$1:$T$1347,_CALC_PNL!$A$1:$A$1347,"GRP",_CALC_PNL!$D$1:$D$1347,$P$1,_CALC_PNL!$C$1:$C$1347,"2027") -> -3719840
A55: GROUPE 2027 V01 | B55: GROUPE 2027 V01 | D55: =D53 -> 3253.6168 | E55: =E53 -> 24231704 | F55: =_xlfn.IFERROR(E55/D55,0) -> 7447.6206 | G55: =SUM(G39:G52) -> 1 | H55: =H53+H54 -> 4111503.6 | I55: =_xlfn.IFERROR(H55/E55,0) -> 0.16967456 | J55: =_xlfn.IFERROR(H55/D55,0) -> 1263.6717 | K55: =SUM(K39:K52) -> 434174

Sheet Socle
A1: SCENARIO | B1: PERIODE | C1: ENTITY | D1: PROGRAMME | E1: AN_ETUDE | F1: MODALITE | G1: EXERCICE | H1: VOL_LEAD | I1: VOL_CAND | J1: VOL_ADMIS | K1: VOL_NEW | L1: VOL_REINS | M1: VOL_EFF | N1: VOL_EFF_INF | O1: VOL_CLASS | P1: REV_STUD | Q1: REV_FRAIS_INS | R1: VOL_LEAD_ORG | S1: VOL_LEAD_PAY | T1: DEPENSE_ACQ | U1: DEPENSE_MARQUE | V1: TX_PASSAGE | W1: TX_LEAD_CAND | X1: TX_CAND_ADMIS | Y1: TX_YIELD_ADMIS_INSC | Z1: VOL_LEAD_TOTAL | AA1: PART_ORG | AB1: CPL | AC1: CA
A2: 2027BUD_V1 | B2: 12 | C2: IPAC_MTP | D2: BAC_CCE | E2: B1 | F2: ALT | G2: 2026 | H2: 680 | I2: 136 | J2: 95 | K2: 40 | L2: 0 | M2: 40 | N2: 0 | O2: 2 | P2: 6650 | Q2: 90 | R2: 258 | S2: 422 | T2: 15178 | U2: 23514 | V2: 0 | W2: 0.2 | X2: 0.69852941 | Y2: 0.42105263 | Z2: 680 | AA2: 0.37941177 | AB2: 35.966825 | AC2: 269600
A3: 2027BUD_V1 | B3: 12 | C3: IPAC_MTP | D3: BAC_CCE | E3: B2 | F3: ALT | G3: 2026 | H3: 0 | I3: 0 | J3: 0 | K3: 0 | L3: 39 | M3: 39 | N3: 40 | O3: 2 | P3: 6650 | Q3: 90 | R3: 0 | S3: 0 | T3: 0 | U3: 0 | V3: 0.975 | W3: 0 | X3: 0 | Y3: 0 | Z3: 0 | AA3: 0 | AB3: 0 | AC3: 259350
A4: 2027BUD_V1 | B4: 12 | C4: IPAC_MTP | D4: BAC_CCE | E4: B3 | F4: ALT | G4: 2026 | H4: 0 | I4: 0 | J4: 0 | K4: 0 | L4: 38 | M4: 38 | N4: 39 | O4: 2 | P4: 6650 | Q4: 90 | R4: 0 | S4: 0 | T4: 0 | U4: 0 | V4: 0.97435897 | W4: 0 | X4: 0 | Y4: 0 | Z4: 0 | AA4: 0 | AB4: 0 | AC4: 252700
A5: 2027BUD_V1 | B5: 12 | C5: IPAC_MTP | D5: BAC_CCE | E5: B1 | F5: ALT | G5: 2025 | H5: 642 | I5: 128 | J5: 90 | K5: 38 | L5: 0 | M5: 38 | N5: 0 | O5: 2 | P5: 6650 | Q5: 90 | R5: 237 | S5: 399 | T5: 13798 | U5: 17870 | V5: 0 | W5: 0.19937695 | X5: 0.703125 | Y5: 0.42222222 | Z5: 636 | AA5: 0.37264151 | AB5: 34.581454 | AC5: 256120
A6: 2027BUD_V1 | B6: 12 | C6: IPAC_MTP | D6: BAC_CCE | E6: B2 | F6: ALT | G6: 2025 | H6: 0 | I6: 0 | J6: 0 | K6: 0 | L6: 37 | M6: 37 | N6: 38 | O6: 2 | P6: 6650 | Q6: 90 | R6: 0 | S6: 0 | T6: 0 | U6: 0 | V6: 0.97368421 | W6: 0 | X6: 0 | Y6: 0 | Z6: 0 | AA6: 0 | AB6: 0 | AC6: 246050
A7: 2027BUD_V1 | B7: 12 | C7: IPAC_MTP | D7: BAC_CCE | E7: B3 | F7: ALT | G7: 2025 | H7: 0 | I7: 0 | J7: 0 | K7: 0 | L7: 36 | M7: 36 | N7: 37 | O7: 2 | P7: 6650 | Q7: 90 | R7: 0 | S7: 0 | T7: 0 | U7: 0 | V7: 0.97297297 | W7: 0 | X7: 0 | Y7: 0 | Z7: 0 | AA7: 0 | AB7: 0 | AC7: 239400
A8: 2027BUD_V1 | B8: 12 | C8: IPAC_MTP | D8: BAC_CCE | E8: B1 | F8: ALT | G8: 2024 | H8: 605 | I8: 121 | J8: 85 | K8: 36 | L8: 0 | M8: 36 | N8: 0 | O8: 2 | P8: 6650 | Q8: 90 | R8: 217 | S8: 377 | T8: 12543 | U8: 13581 | V8: 0 | W8: 0.2 | X8: 0.70247934 | Y8: 0.42352941 | Z8: 594 | AA8: 0.36531987 | AB8: 33.270557 | AC8: 242640
A9: 2027BUD_V1 | B9: 12 | C9: IPAC_MTP | D9: BAC_CCE | E9: B2 | F9: ALT | G9: 2024 | H9: 0 | I9: 0 | J9: 0 | K9: 0 | L9: 35 | M9: 35 | N9: 36 | O9: 2 | P9: 6650 | Q9: 90 | R9: 0 | S9: 0 | T9: 0 | U9: 0 | V9: 0.97222222 | W9: 0 | X9: 0 | Y9: 0 | Z9: 0 | AA9: 0 | AB9: 0 | AC9: 232750
A10: 2027BUD_V1 | B10: 12 | C10: IPAC_MTP | D10: BAC_CCE | E10: B3 | F10: ALT | G10: 2024 | H10: 0 | I10: 0 | J10: 0 | K10: 0 | L10: 34 | M10: 34 | N10: 35 | O10: 2 | P10: 6650 | Q10: 90 | R10: 0 | S10: 0 | T10: 0 | U10: 0 | V10: 0.97142857 | W10: 0 | X10: 0 | Y10: 0 | Z10: 0 | AA10: 0 | AB10: 0 | AC10: 226100
A11: 2027BUD_V1 | B11: 12 | C11: IPAC_NAN | D11: BAC_CCE | E11: B1 | F11: ALT | G11: 2024 | H11: 756 | I11: 151 | J11: 106 | K11: 44 | L11: 0 | M11: 44 | N11: 0 | O11: 2 | P11: 7000 | Q11: 90 | R11: 258 | S11: 489 | T11: 17983 | U11: 15937 | V11: 0 | W11: 0.19973545 | X11: 0.70198675 | Y11: 0.41509434 | Z11: 747 | AA11: 0.34538153 | AB11: 36.775051 | AC11: 311960
A12: 2027BUD_V1 | B12: 12 | C12: IPAC_NAN | D12: BAC_CCE | E12: B2 | F12: ALT | G12: 2024 | H12: 0 | I12: 0 | J12: 0 | K12: 0 | L12: 43 | M12: 43 | N12: 44 | O12: 2 | P12: 7000 | Q12: 90 | R12: 0 | S12: 0 | T12: 0 | U12: 0 | V12: 0.97727273 | W12: 0 | X12: 0 | Y12: 0 | Z12: 0 | AA12: 0 | AB12: 0 | AC12: 301000
A13: 2027BUD_V1 | B13: 12 | C13: IPAC_NAN | D13: BAC_CCE | E13: B3 | F13: ALT | G13: 2024 | H13: 0 | I13: 0 | J13: 0 | K13: 0 | L13: 42 | M13: 42 | N13: 43 | O13: 2 | P13: 7000 | Q13: 90 | R13: 0 | S13: 0 | T13: 0 | U13: 0 | V13: 0.97674419 | W13: 0 | X13: 0 | Y13: 0 | Z13: 0 | AA13: 0 | AB13: 0 | AC13: 294000
... A181: 2027BUD_V1 | B181: 12 | C181: TUNON_PAR | D181: BAC_TOU | E181: B3 | F181: ALT | G181: 2026 | H181: 0 | I181: 0 | J181: 0 | K181: 0 | L181: 45 | M181: 45 | N181: 46 | O181: 2 | P181: 7840 | Q181: 90 | R181: 0 | S181: 0 | T181: 0 | U181: 0 | V181: 0.97826087 | W181: 0 | X181: 0 | Y181: 0 | Z181: 0 | AA181: 0 | AB181: 0 | AC181: 352800

Sheet Campagne
A1: SCENARIO | B1: PERIODE | C1: ENTITY | D1: ORG_REF | E1: PAID_REF | F1: LEAD_REF | G1: SPEND_ACQ_REF | H1: SPEND_BRAND_REF | I1: PART_ORG | J1: CPL | K1: REND_ACQ | L1: CONVERSION | M1: REND_BRAND | N1: CAC_MARGINAL
A2: 2027BUD_V1 | B2: 12 | C2: IPAC_MTP | D2: 258 | E2: 422 | F2: 680 | G2: 15178 | H2: 23514 | I2: 0.379411 | J2: 35.966824 | K2: 0.59134489 | L2: 0.058823 | M2: 0.31527519 | N2: 1033.9846
A3: 2027BUD_V1 | B3: 12 | C3: IPAC_NAN | D3: 306 | E3: 544 | F3: 850 | G3: 21760 | H3: 27889 | I3: 0.36 | J3: 40 | K3: 0.55908079 | L3: 0.058823 | M3: 0.30491226 | N3: 1216.2931
A4: 2027BUD_V1 | B4: 12 | C4: IPAC_REN | D4: 265 | E4: 415 | F4: 680 | G4: 14933 | H4: 24152 | I4: 0.389705 | J4: 35.983132 | K4: 0.58787656 | L4: 0.058823 | M4: 0.31735415 | N4: 1040.5564
A5: 2027BUD_V1 | B5: 12 | C5: ISCOM_LIL | D5: 630 | E5: 630 | F5: 1260 | G5: 25220 | H5: 57418 | I5: 0.5 | J5: 40.031746 | K5: 0.51584831 | L5: 0.079302 | M5: 0.34838058 | N5: 978.58461
A6: 2027BUD_V1 | B6: 12 | C6: ISCOM_PAR | D6: 690 | E6: 1126 | F6: 1816 | G6: 60800 | H6: 62886 | I6: 0.379955 | J6: 53.996447 | K6: 0.44208627 | L6: 0.079295 | M6: 0.31719351 | N6: 1540.325
A7: 2027BUD_V1 | B7: 12 | C7: ISCOM_TLS | D7: 605 | E7: 581 | F7: 1186 | G7: 22083 | H7: 55139 | I7: 0.510118 | J7: 38.008605 | K7: 0.52180337 | L7: 0.079258 | M7: 0.35585226 | N7: 919.03477
A8: 2027BUD_V1 | B8: 12 | C8: MBWAY_BOR | D8: 630 | E8: 656 | F8: 1286 | G8: 24923 | H8: 57418 | I8: 0.489891 | J8: 37.992378 | K8: 0.53845529 | L8: 0.079315 | M8: 0.34824917 | N8: 889.59329
A9: 2027BUD_V1 | B9: 12 | C9: MBWAY_LYO | D9: 716 | E9: 950 | F9: 1666 | G9: 41783 | H9: 65255 | I9: 0.429771 | J9: 43.982105 | K9: 0.50391241 | L9: 0.079231 | M9: 0.32659376 | N9: 1101.6048
A10: 2027BUD_V1 | B10: 12 | C10: MBWAY_NAN | D10: 728 | E10: 788 | F10: 1516 | G10: 31533 | H10: 66349 | I10: 0.480211 | J10: 40.016497 | K10: 0.52465564 | L10: 0.079155 | M10: 0.34345059 | N10: 963.57687
A11: 2027BUD_V1 | B11: 12 | C11: MBWAY_PAR | D11: 711 | E11: 1265 | F11: 1976 | G11: 68291 | H11: 64800 | I11: 0.359817 | J11: 53.98498 | K11: 0.46359595 | L11: 0.078947 | M11: 0.30805412 | N11: 1475.0192
A12: 2027BUD_V1 | B12: 12 | C12: PIGIER_BOR | D12: 652 | E12: 578 | F12: 1230 | G12: 21968 | H12: 59423 | I12: 0.530081 | J12: 38.00692 | K12: 0.47459663 | L12: 0.058536 | M12: 0.35757396 | N12: 1368.091
A13: 2027BUD_V1 | B13: 12 | C13: PIGIER_LYO | D13: 738 | E13: 832 | F13: 1570 | G13: 36612 | H13: 67261 | I13: 0.470063 | J13: 44.004807 | K13: 0.44045026 | L13: 0.058598 | M13: 0.34304578 | N13: 1704.9846
... A15: 2027BUD_V1 | B15: 12 | C15: TUNON_PAR | D15: 240 | E15: 560 | F15: 800 | G15: 30240 | H15: 21873 | I15: 0.3 | J15: 54 | K15: 0.41914907 | L15: 0.05875 | M15: 0.27988845 | N15: 2192.8927

Sheet Moteur
A1: SCENARIO | B1: VERSION | C1: PERIODE | D1: ENTITY | E1: MARQUE | F1: PROGRAMME | G1: AN_ETUDE | H1: MODALITE | I1: EXERCICE | J1: NOUVEAUX | K1: EFFECTIF | L1: PRIX | M1: CA | O1: NOUVEAUX (live) | P1: EFFECTIF (live) | Q1: PRIX (live) | R1: 🟢 CA (live) | S1: Δ CA vs Tagetik
A2: 2027BUD_V1 | B2: V01 | C2: 12 | D2: MBWAY_PAR | E2: MBWAY | F2: BAC_MGT | G2: B1 | H2: INIT | I2: 2027 | J2: 84.920597 | K2: 84.920597 | L2: 8429.232 | M2: 723458.27 | O2: =IF(D2="","",_CALC_MOTEUR!AE2) -> 84.920594 | P2: =IF(D2="","",_CALC_MOTEUR!AF2) -> 84.920594 | Q2: =IF(D2="","",_CALC_MOTEUR!AG2) -> 8429.232 | R2: =IF(D2="","",_CALC_MOTEUR!AH2) -> 723458.24 | S2: =IF(D2="","",R2-M2) -> -0.024558644
A3: 2027BUD_V1 | B3: V01 | C3: 12 | D3: MBWAY_PAR | E3: MBWAY | F3: BAC_MGT | G3: B2 | H3: ALT | I3: 2027 | J3: 0 | K3: 76.39 | L3: 7867.2832 | M3: 600981.76 | O3: =IF(D3="","",_CALC_MOTEUR!AE3) -> 0 | P3: =IF(D3="","",_CALC_MOTEUR!AF3) -> 76.39 | Q3: =IF(D3="","",_CALC_MOTEUR!AG3) -> 7867.2832 | R3: =IF(D3="","",_CALC_MOTEUR!AH3) -> 600981.76 | S3: =IF(D3="","",R3-M3) -> -0.00022028398
A4: 2027BUD_V1 | B4: V01 | C4: 12 | D4: MBWAY_PAR | E4: MBWAY | F4: BAC_MGT | G4: B3 | H4: ALT | I4: 2027 | J4: 0 | K4: 74.38 | L4: 7867.2832 | M4: 585168.52 | O4: =IF(D4="","",_CALC_MOTEUR!AE4) -> 0 | P4: =IF(D4="","",_CALC_MOTEUR!AF4) -> 74.38 | Q4: =IF(D4="","",_CALC_MOTEUR!AG4) -> 7867.2832 | R4: =IF(D4="","",_CALC_MOTEUR!AH4) -> 585168.52 | S4: =IF(D4="","",R4-M4) -> 0.00028322195
A5: 2027BUD_V1 | B5: V01 | C5: 12 | D5: MBWAY_PAR | E5: MBWAY | F5: MAS_MGT | G5: M1 | H5: ALT | I5: 2027 | J5: 86.70186 | K5: 86.70186 | L5: 8429.232 | M5: 738633.26 | O5: =IF(D5="","",_CALC_MOTEUR!AE5) -> 86.701858 | P5: =IF(D5="","",_CALC_MOTEUR!AF5) -> 86.701858 | Q5: =IF(D5="","",_CALC_MOTEUR!AG5) -> 8429.232 | R5: =IF(D5="","",_CALC_MOTEUR!AH5) -> 738633.24 | S5: =IF(D5="","",R5-M5) -> -0.019111536
A6: 2027BUD_V1 | B6: V01 | C6: 12 | D6: MBWAY_PAR | E6: MBWAY | F6: MAS_MGT | G6: M2 | H6: ALT | I6: 2027 | J6: 0 | K6: 76.39 | L6: 8429.232 | M6: 643909.03 | O6: =IF(D6="","",_CALC_MOTEUR!AE6) -> 0 | P6: =IF(D6="","",_CALC_MOTEUR!AF6) -> 76.39 | Q6: =IF(D6="","",_CALC_MOTEUR!AG6) -> 8429.232 | R6: =IF(D6="","",_CALC_MOTEUR!AH6) -> 643909.03 | S6: =IF(D6="","",R6-M6) -> -0.00023601903
A7: 2027BUD_V1 | B7: V01 | C7: 12 | D7: MBWAY_LYO | E7: MBWAY | F7: BAC_MGT | G7: B1 | H7: INIT | I7: 2027 | J7: 72.005855 | K7: 72.005855 | L7: 7902.405 | M7: 575499.96 | O7: =IF(D7="","",_CALC_MOTEUR!AE7) -> 72.005873 | P7: =IF(D7="","",_CALC_MOTEUR!AF7) -> 72.005873 | Q7: =IF(D7="","",_CALC_MOTEUR!AG7) -> 7902.405 | R7: =IF(D7="","",_CALC_MOTEUR!AH7) -> 575500.1 | S7: =IF(D7="","",R7-M7) -> 0.14050092
A8: 2027BUD_V1 | B8: V01 | C8: 12 | D8: MBWAY_LYO | E8: MBWAY | F8: BAC_MGT | G8: B2 | H8: ALT | I8: 2027 | J8: 0 | K8: 64.33 | L8: 7375.578 | M8: 474470.93 | O8: =IF(D8="","",_CALC_MOTEUR!AE8) -> 0 | P8: =IF(D8="","",_CALC_MOTEUR!AF8) -> 64.33 | Q8: =IF(D8="","",_CALC_MOTEUR!AG8) -> 7375.578 | R8: =IF(D8="","",_CALC_MOTEUR!AH8) -> 474470.93 | S8: =IF(D8="","",R8-M8) -> 0.00014751201
A9: 2027BUD_V1 | B9: V01 | C9: 12 | D9: MBWAY_LYO | E9: MBWAY | F9: BAC_MGT | G9: B3 | H9: ALT | I9: 2027 | J9: 0 | K9: 63.32 | L9: 7375.578 | M9: 467021.6 | O9: =IF(D9="","",_CALC_MOTEUR!AE9) -> 0 | P9: =IF(D9="","",_CALC_MOTEUR!AF9) -> 63.32 | Q9: =IF(D9="","",_CALC_MOTEUR!AG9) -> 7375.578 | R9: =IF(D9="","",_CALC_MOTEUR!AH9) -> 467021.6 | S9: =IF(D9="","",R9-M9) -> 0
A10: 2027BUD_V1 | B10: V01 | C10: 12 | D10: MBWAY_LYO | E10: MBWAY | F10: MAS_MGT | G10: M1 | H10: ALT | I10: 2027 | J10: 73.512347 | K10: 73.512347 | L10: 7902.405 | M10: 587540.45 | O10: =IF(D10="","",_CALC_MOTEUR!AE10) -> 73.512365 | P10: =IF(D10="","",_CALC_MOTEUR!AF10) -> 73.512365 | Q10: =IF(D10="","",_CALC_MOTEUR!AG10) -> 7902.405 | R10: =IF(D10="","",_CALC_MOTEUR!AH10) -> 587540.59 | S10: =IF(D10="","",R10-M10) -> 0.14475602
A11: 2027BUD_V1 | B11: V01 | C11: 12 | D11: MBWAY_LYO | E11: MBWAY | F11: MAS_MGT | G11: M2 | H11: ALT | I11: 2027 | J11: 0 | K11: 65.33 | L11: 7902.405 | M11: 516264.12 | O11: =IF(D11="","",_CALC_MOTEUR!AE11) -> 0 | P11: =IF(D11="","",_CALC_MOTEUR!AF11) -> 65.33 | Q11: =IF(D11="","",_CALC_MOTEUR!AG11) -> 7902.405 | R11: =IF(D11="","",_CALC_MOTEUR!AH11) -> 516264.12 | S11: =IF(D11="","",R11-M11) -> 7.9024001e-05
A12: 2027BUD_V1 | B12: V01 | C12: 12 | D12: MBWAY_NAN | E12: MBWAY | F12: BAC_MGT | G12: B1 | H12: INIT | I12: 2027 | J12: 65.539302 | K12: 65.539302 | L12: 7526.1 | M12: 499153.88 | O12: =IF(D12="","",_CALC_MOTEUR!AE12) -> 65.539313 | P12: =IF(D12="","",_CALC_MOTEUR!AF12) -> 65.539313 | Q12: =IF(D12="","",_CALC_MOTEUR!AG12) -> 7526.1 | R12: =IF(D12="","",_CALC_MOTEUR!AH12) -> 499153.96 | S12: =IF(D12="","",R12-M12) -> 0.080706865
A13: 2027BUD_V1 | B13: V01 | C13: 12 | D13: MBWAY_NAN | E13: MBWAY | F13: BAC_MGT | G13: B2 | H13: ALT | I13: 2027 | J13: 0 | K13: 58.3 | L13: 7024.36 | M13: 409520.19 | O13: =IF(D13="","",_CALC_MOTEUR!AE13) -> 0 | P13: =IF(D13="","",_CALC_MOTEUR!AF13) -> 58.3 | Q13: =IF(D13="","",_CALC_MOTEUR!AG13) -> 7024.36 | R13: =IF(D13="","",_CALC_MOTEUR!AH13) -> 409520.19 | S13: =IF(D13="","",R13-M13) -> 0.00014048698
... A181: 2027BUD_V1 | B181: V03 | C181: 12 | D181: PIGIER_LYO | E181: PIGIER | F181: BAC_RH | G181: B3 | H181: ALT | I181: 2027 | J181: 0 | K181: 43.55 | L181: 7482.3 | M181: 325854.16 | O181: =IF(D181="","",_CALC_MOTEUR!AE181) -> 0 | P181: =IF(D181="","",_CALC_MOTEUR!AF181) -> 43.55 | Q181: =IF(D181="","",_CALC_MOTEUR!AG181) -> 7482.3 | R181: =IF(D181="","",_CALC_MOTEUR!AH181) -> 325854.17 | S181: =IF(D181="","",R181-M181) -> 7.4823038e-05
O182: =IF(D182="","",_CALC_MOTEUR!AE182) | P182: =IF(D182="","",_CALC_MOTEUR!AF182) | Q182: =IF(D182="","",_CALC_MOTEUR!AG182) | R182: =IF(D182="","",_CALC_MOTEUR!AH182) | S182: =IF(D182="","",R182-M182)
O183: =IF(D183="","",_CALC_MOTEUR!AE183) | P183: =IF(D183="","",_CALC_MOTEUR!AF183) | Q183: =IF(D183="","",_CALC_MOTEUR!AG183) | R183: =IF(D183="","",_CALC_MOTEUR!AH183) | S183: =IF(D183="","",R183-M183)
O184: =IF(D184="","",_CALC_MOTEUR!AE184) | P184: =IF(D184="","",_CALC_MOTEUR!AF184) | Q184: =IF(D184="","",_CALC_MOTEUR!AG184) | R184: =IF(D184="","",_CALC_MOTEUR!AH184) | S184: =IF(D184="","",R184-M184)
O185: =IF(D185="","",_CALC_MOTEUR!AE185) | P185: =IF(D185="","",_CALC_MOTEUR!AF185) | Q185: =IF(D185="","",_CALC_MOTEUR!AG185) | R185: =IF(D185="","",_CALC_MOTEUR!AH185) | S185: =IF(D185="","",R185-M185)
O186: =IF(D186="","",_CALC_MOTEUR!AE186) | P186: =IF(D186="","",_CALC_MOTEUR!AF186) | Q186: =IF(D186="","",_CALC_MOTEUR!AG186) | R186: =IF(D186="","",_CALC_MOTEUR!AH186) | S186: =IF(D186="","",R186-M186)
O187: =IF(D187="","",_CALC_MOTEUR!AE187) | P187: =IF(D187="","",_CALC_MOTEUR!AF187) | Q187: =IF(D187="","",_CALC_MOTEUR!AG187) | R187: =IF(D187="","",_CALC_MOTEUR!AH187) | S187: =IF(D187="","",R187-M187)
O188: =IF(D188="","",_CALC_MOTEUR!AE188) | P188: =IF(D188="","",_CALC_MOTEUR!AF188) | Q188: =IF(D188="","",_CALC_MOTEUR!AG188) | R188: =IF(D188="","",_CALC_MOTEUR!AH188) | S188: =IF(D188="","",R188-M188)
O189: =IF(D189="","",_CALC_MOTEUR!AE189) | P189: =IF(D189="","",_CALC_MOTEUR!AF189) | Q189: =IF(D189="","",_CALC_MOTEUR!AG189) | R189: =IF(D189="","",_CALC_MOTEUR!AH189) | S189: =IF(D189="","",R189-M189)
O190: =IF(D190="","",_CALC_MOTEUR!AE190) | P190: =IF(D190="","",_CALC_MOTEUR!AF190) | Q190: =IF(D190="","",_CALC_MOTEUR!AG190) | R190: =IF(D190="","",_CALC_MOTEUR!AH190) | S190: =IF(D190="","",R190-M190)
O191: =IF(D191="","",_CALC_MOTEUR!AE191) | P191: =IF(D191="","",_CALC_MOTEUR!AF191) | Q191: =IF(D191="","",_CALC_MOTEUR!AG191) | R191: =IF(D191="","",_CALC_MOTEUR!AH191) | S191: =IF(D191="","",R191-M191)
O192: =IF(D192="","",_CALC_MOTEUR!AE192) | P192: =IF(D192="","",_CALC_MOTEUR!AF192) | Q192: =IF(D192="","",_CALC_MOTEUR!AG192) | R192: =IF(D192="","",_CALC_MOTEUR!AH192) | S192: =IF(D192="","",R192-M192)
O193: =IF(D193="","",_CALC_MOTEUR!AE193) | P193: =IF(D193="","",_CALC_MOTEUR!AF193) | Q193: =IF(D193="","",_CALC_MOTEUR!AG193) | R193: =IF(D193="","",_CALC_MOTEUR!AH193) | S193: =IF(D193="","",R193-M193)
... O207: =IF(D207="","",_CALC_MOTEUR!AE207) | P207: =IF(D207="","",_CALC_MOTEUR!AF207) | Q207: =IF(D207="","",_CALC_MOTEUR!AG207) | R207: =IF(D207="","",_CALC_MOTEUR!AH207) | S207: =IF(D207="","",R207-M207)

Sheet Comptabilité
A1: Entity | B1: Account | C1: EXERCICE | D1: Scenario | E1: Period | F1: Amount
A2: MBWAY_PAR | B2: 7062 | C2: 2024 | D2: 2027BUD_V1 | E2: 12 | F2: 2201360
A3: MBWAY_LYO | B3: 7062 | C3: 2024 | D3: 2027BUD_V1 | E3: 12 | F3: 1751925
A4: MBWAY_NAN | B4: 7062 | C4: 2024 | D4: 2027BUD_V1 | E4: 12 | F4: 1516000
A5: MBWAY_BOR | B5: 7062 | C5: 2024 | D5: 2027BUD_V1 | E5: 12 | F5: 1238205
A6: ISCOM_PAR | B6: 7062 | C6: 2024 | D6: 2027BUD_V1 | E6: 12 | F6: 2031120
A7: ISCOM_LIL | B7: 7062 | C7: 2024 | D7: 2027BUD_V1 | E7: 12 | F7: 1229900
A8: ISCOM_TLS | B8: 7062 | C8: 2024 | D8: 2027BUD_V1 | E8: 12 | F8: 1141920
A9: IPAC_NAN | B9: 7062 | C9: 2024 | D9: 2027BUD_V1 | E9: 12 | F9: 903000
A10: IPAC_REN | B10: 7062 | C10: 2024 | D10: 2027BUD_V1 | E10: 12 | F10: 698250
A11: IPAC_MTP | B11: 7062 | C11: 2024 | D11: 2027BUD_V1 | E11: 12 | F11: 698250
A12: TUNON_PAR | B12: 7062 | C12: 2024 | D12: 2027BUD_V1 | E12: 12 | F12: 964320
A13: TUNON_LYO | B13: 7062 | C13: 2024 | D13: 2027BUD_V1 | E13: 12 | F13: 771750
... A673: PIGIER_LYO | B673: 7062 | C673: 2026 | D673: 2027BUD_V1 | E673: 12 | F673: 1565550

Sheet PNL
A1: ENTITY | B1: ACCOUNT | C1: EXERCICE | D1: VERSION | E1: SCENARIO | F1: PERIOD | G1: AMOUNT | H1: 🟢 AMOUNT (live) | I1: Δ vs Tagetik
A2: MBWAY_PAR | B2: 7062 | C2: 2024 | D2: ACT | E2: 2027BUD_V1 | F2: 12 | G2: 2201360 | H2: =IF(PNL!A2="","",_CALC_PNL!P2) -> 2201360 | I2: =IF(PNL!A2="","",IF(_CALC_PNL!E2=1,H2-G2,""))
A3: MBWAY_LYO | B3: 7062 | C3: 2024 | D3: ACT | E3: 2027BUD_V1 | F3: 12 | G3: 1751925 | H3: =IF(PNL!A3="","",_CALC_PNL!P3) -> 1751925 | I3: =IF(PNL!A3="","",IF(_CALC_PNL!E3=1,H3-G3,""))
A4: MBWAY_NAN | B4: 7062 | C4: 2024 | D4: ACT | E4: 2027BUD_V1 | F4: 12 | G4: 1516000 | H4: =IF(PNL!A4="","",_CALC_PNL!P4) -> 1516000 | I4: =IF(PNL!A4="","",IF(_CALC_PNL!E4=1,H4-G4,""))
A5: MBWAY_BOR | B5: 7062 | C5: 2024 | D5: ACT | E5: 2027BUD_V1 | F5: 12 | G5: 1238205 | H5: =IF(PNL!A5="","",_CALC_PNL!P5) -> 1238205 | I5: =IF(PNL!A5="","",IF(_CALC_PNL!E5=1,H5-G5,""))
A6: ISCOM_PAR | B6: 7062 | C6: 2024 | D6: ACT | E6: 2027BUD_V1 | F6: 12 | G6: 2031120 | H6: =IF(PNL!A6="","",_CALC_PNL!P6) -> 2031120 | I6: =IF(PNL!A6="","",IF(_CALC_PNL!E6=1,H6-G6,""))
A7: ISCOM_LIL | B7: 7062 | C7: 2024 | D7: ACT | E7: 2027BUD_V1 | F7: 12 | G7: 1229900 | H7: =IF(PNL!A7="","",_CALC_PNL!P7) -> 1229900 | I7: =IF(PNL!A7="","",IF(_CALC_PNL!E7=1,H7-G7,""))
A8: ISCOM_TLS | B8: 7062 | C8: 2024 | D8: ACT | E8: 2027BUD_V1 | F8: 12 | G8: 1141920 | H8: =IF(PNL!A8="","",_CALC_PNL!P8) -> 1141920 | I8: =IF(PNL!A8="","",IF(_CALC_PNL!E8=1,H8-G8,""))
A9: IPAC_NAN | B9: 7062 | C9: 2024 | D9: ACT | E9: 2027BUD_V1 | F9: 12 | G9: 903000 | H9: =IF(PNL!A9="","",_CALC_PNL!P9) -> 903000 | I9: =IF(PNL!A9="","",IF(_CALC_PNL!E9=1,H9-G9,""))
A10: IPAC_REN | B10: 7062 | C10: 2024 | D10: ACT | E10: 2027BUD_V1 | F10: 12 | G10: 698250 | H10: =IF(PNL!A10="","",_CALC_PNL!P10) -> 698250 | I10: =IF(PNL!A10="","",IF(_CALC_PNL!E10=1,H10-G10,""))
A11: IPAC_MTP | B11: 7062 | C11: 2024 | D11: ACT | E11: 2027BUD_V1 | F11: 12 | G11: 698250 | H11: =IF(PNL!A11="","",_CALC_PNL!P11) -> 698250 | I11: =IF(PNL!A11="","",IF(_CALC_PNL!E11=1,H11-G11,""))
A12: TUNON_PAR | B12: 7062 | C12: 2024 | D12: ACT | E12: 2027BUD_V1 | F12: 12 | G12: 964320 | H12: =IF(PNL!A12="","",_CALC_PNL!P12) -> 964320 | I12: =IF(PNL!A12="","",IF(_CALC_PNL!E12=1,H12-G12,""))
A13: TUNON_LYO | B13: 7062 | C13: 2024 | D13: ACT | E13: 2027BUD_V1 | F13: 12 | G13: 771750 | H13: =IF(PNL!A13="","",_CALC_PNL!P13) -> 771750 | I13: =IF(PNL!A13="","",IF(_CALC_PNL!E13=1,H13-G13,""))
... A1345: TUNON_PAR | B1345: 708 | C1345: 2027 | D1345: V03 | E1345: 2027BUD_V1 | F1345: 12 | G1345: 4148.0311 | H1345: =IF(PNL!A1345="","",_CALC_PNL!P1345) -> 4148.0314 | I1345: =IF(PNL!A1345="","",IF(_CALC_PNL!E1345=1,H1345-G1345,"")) -> 0.00033472774
H1346: =IF(PNL!A1346="","",_CALC_PNL!P1346) | I1346: =IF(PNL!A1346="","",IF(_CALC_PNL!E1346=1,H1346-G1346,""))
H1347: =IF(PNL!A1347="","",_CALC_PNL!P1347) | I1347: =IF(PNL!A1347="","",IF(_CALC_PNL!E1347=1,H1347-G1347,""))

Sheet _CALC_MOTEUR
A1: KENT | B1: KVER | C1: KPROG | D1: KAN | E1: KMOD | F1: KMARQ | G1: VOL_LEAD | H1: VOL_EFF_INF | I1: REV_STUD | J1: RLC | K1: RCA | L1: YLD | M1: PASSAGE | N1: IS_ENTRY | O1: ORG_REF | P1: PAID_REF | Q1: LEAD_REF | R1: REND_ACQ | S1: REND_BRAND | T1: REJOUE | U1: BUD_REF | V1: ACQ | W1: BRAND | X1: PRICE | Y1: GLC | Z1: GCV | AA1: PASS | AB1: FEE | AC1: PRICE_COEF | AD1: NOUV_CALC | AE1: NOUVEAUX | AF1: EFFECTIF | AG1: PRIX | AH1: CA | AJ1: ■ VIOLET = colonne branchee sur une saisie (cad / Pilotage / 3_Allocation) -> a recabler cote Tagetik
A2: =IF(Moteur!D2="","",Moteur!D2) -> MBWAY_PAR | B2: =IF(Moteur!B2="","",Moteur!B2) -> V01 | C2: =IF(Moteur!F2="","",Moteur!F2) -> BAC_MGT | D2: =IF(Moteur!G2="","",Moteur!G2) -> B1 | E2: =IF(Moteur!H2="","",Moteur!H2) -> INIT | F2: =IF(Moteur!E2="","",Moteur!E2) -> MBWAY | G2: =IF($A2="","",_xlfn.SUMIFS(Socle!$H$1:$H$658,Socle!$C$1:$C$658,$A2,Socle!$D$1:$D$658,$C2,Socle!$E$1:$E$658,$D2,Socle!$F$1:$F$658,$E2,Socle!$G$1:$G$658,"2026")) -> 646 | H2: =IF($A2="","",_xlfn.SUMIFS(Socle!$N$1:$N$658,Socle!$C$1:$C$658,$A2,Socle!$D$1:$D$658,$C2,Socle!$E$1:$E$658,$D2,Socle!$F$1:$F$658,$E2,Socle!$G$1:$G$658,"2026")) -> 0 | I2: =IF($A2="","",_xlfn.SUMIFS(Socle!$P$1:$P$658,Socle!$C$1:$C$658,$A2,Socle!$D$1:$D$658,$C2,Socle!$E$1:$E$658,$D2,Socle!$F$1:$F$658,$E2,Socle!$G$1:$G$658,"2026")) -> 8400 | J2: =IF($A2="","",_xlfn.SUMIFS(Socle!$W$1:$W$658,Socle!$C$1:$C$658,$A2,Socle!$D$1:$D$658,$C2,Socle!$E$1:$E$658,$D2,Socle!$F$1:$F$658,$E2,Socle!$G$1:$G$658,"2026")) -> 0.28018576 | K2: =IF($A2="","",_xlfn.SUMIFS(Socle!$X$1:$X$658,Socle!$C$1:$C$658,$A2,Socle!$D$1:$D$658,$C2,Socle!$E$1:$E$658,$D2,Socle!$F$1:$F$658,$E2,Socle!$G$1:$G$658,"2026")) -> 0.71823204 | L2: =IF($A2="","",_xlfn.SUMIFS(Socle!$Y$1:$Y$658,Socle!$C$1:$C$658,$A2,Socle!$D$1:$D$658,$C2,Socle!$E$1:$E$658,$D2,Socle!$F$1:$F$658,$E2,Socle!$G$1:$G$658,"2026")) -> 0.6 | M2: =IF($A2="","",_xlfn.SUMIFS(Socle!$V$1:$V$658,Socle!$C$1:$C$658,$A2,Socle!$D$1:$D$658,$C2,Socle!$E$1:$E$658,$D2,Socle!$F$1:$F$658,$E2,Socle!$G$1:$G$658,"2026")) -> 0 | N2: =IF($A2="","",IF(OR($D2="B1",$D2="M1",$D2="BTS1"),1,0)) -> 1 | O2: =IF($A2="","",_xlfn.SUMIFS(Campagne!$D$1:$D$141,Campagne!$C$1:$C$141,$A2)) -> 711 | P2: =IF($A2="","",_xlfn.SUMIFS(Campagne!$E$1:$E$141,Campagne!$C$1:$C$141,$A2)) -> 1265 | Q2: =IF($A2="","",_xlfn.SUMIFS(Campagne!$F$1:$F$141,Campagne!$C$1:$C$141,$A2)) -> 1976 | R2: =IF($A2="","",_xlfn.SUMIFS(Campagne!$K$1:$K$141,Campagne!$C$1:$C$141,$A2)) -> 0.46359595 | S2: =IF($A2="","",_xlfn.SUMIFS(Campagne!$M$1:$M$141,Campagne!$C$1:$C$141,$A2)) -> 0.30805412 | T2: =IF($A2="","",_xlfn.SUMIFS(Pilotage!$K$19:$K$32,Pilotage!$A$19:$A$32,$A2)*_xlfn.SUMIFS(Pilotage!$J$19:$J$32,Pilotage!$A$19:$A$32,$A2)*(SUM(Pilotage!$K$19:$K$32)/SUMPRODUCT(Pilotage!$K$19:$K$32,Pilotage!$J$19:$J$32))) -> 68291 | U2: =IF($A2="","",_xlfn.SUMIFS(Pilotage!$K$19:$K$32,Pilotage!$A$19:$A$32,$A2)) -> 68291 | V2: =IF($A2="","",IF($B2="V01",Cadrage!$C$23,IF($B2="V02",Cadrage!$D$23,Cadrage!$E$23))) -> 0.08 | W2: =IF($A2="","",IF($B2="V01",Cadrage!$C$24,IF($B2="V02",Cadrage!$D$24,Cadrage!$E$24))) -> 0.1 | X2: =IF($A2="","",IF($B2="V01",Cadrage!$C$25,IF($B2="V02",Cadrage!$D$25,Cadrage!$E$25))) -> 0.0029 | Y2: =IF($A2="","",IF($B2="V01",Cadrage!$C$26,IF($B2="V02",Cadrage!$D$26,Cadrage!$E$26))) -> 0.01 | Z2: =IF($A2="","",IF($B2="V01",Cadrage!$C$27,IF($B2="V02",Cadrage!$D$27,Cadrage!$E$27))) -> 0.01 | AA2: =IF($A2="","",IF($B2="V01",Cadrage!$C$28,IF($B2="V02",Cadrage!$D$28,Cadrage!$E$28))) -> 0.005 | AB2: =IF($A2="","",IF($B2="V01",Cadrage!$C$42,IF($B2="V02",Cadrage!$D$42,Cadrage!$E$42))) -> 90 | AC2: =IF($A2="","",IF($F2="MBWAY",Cadrage!$K$34,IF($F2="ISCOM",Cadrage!$K$35,IF($F2="IPAC",Cadrage!$K$36,IF($F2="PIGIER",Cadrage!$K$37,Cadrage!$K$38))))) -> 1.2 | AD2: =IF($A2="","",($O2*(1+$W2)^$S2+$P2*_xlfn.IFERROR((($T2/$U2)*(1+$V2))^$R2,0))*_xlfn.IFERROR($G2/$Q2,0)*($J2+$Y2)*$K2*($L2+$Z2)) -> 84.920594 | AE2: =IF($A2="","",IF($N2=1,$AD2,0)) -> 84.920594 | AF2: =IF($A2="","",IF($N2=1,$AD2,$H2*($M2+$AA2))) -> 84.920594 | AG2: =IF($A2="","",$I2*(1+$X2*$AC2)) -> 8429.232 | AH2: =IF($A2="","",$AF2*$AG2+$AE2*$AB2) -> 723458.24
A3: =IF(Moteur!D3="","",Moteur!D3) -> MBWAY_PAR | B3: =IF(Moteur!B3="","",Moteur!B3) -> V01 | C3: =IF(Moteur!F3="","",Moteur!F3) -> BAC_MGT | D3: =IF(Moteur!G3="","",Moteur!G3) -> B2 | E3: =IF(Moteur!H3="","",Moteur!H3) -> ALT | F3: =IF(Moteur!E3="","",Moteur!E3) -> MBWAY | G3: =IF($A3="","",_xlfn.SUMIFS(Socle!$H$1:$H$658,Socle!$C$1:$C$658,$A3,Socle!$D$1:$D$658,$C3,Socle!$E$1:$E$658,$D3,Socle!$F$1:$F$658,$E3,Socle!$G$1:$G$658,"2026")) -> 0 | H3: =IF($A3="","",_xlfn.SUMIFS(Socle!$N$1:$N$658,Socle!$C$1:$C$658,$A3,Socle!$D$1:$D$658,$C3,Socle!$E$1:$E$658,$D3,Socle!$F$1:$F$658,$E3,Socle!$G$1:$G$658,"2026")) -> 78 | I3: =IF($A3="","",_xlfn.SUMIFS(Socle!$P$1:$P$658,Socle!$C$1:$C$658,$A3,Socle!$D$1:$D$658,$C3,Socle!$E$1:$E$658,$D3,Socle!$F$1:$F$658,$E3,Socle!$G$1:$G$658,"2026")) -> 7840 | J3: =IF($A3="","",_xlfn.SUMIFS(Socle!$W$1:$W$658,Socle!$C$1:$C$658,$A3,Socle!$D$1:$D$658,$C3,Socle!$E$1:$E$658,$D3,Socle!$F$1:$F$658,$E3,Socle!$G$1:$G$658,"2026")) -> 0 | K3: =IF($A3="","",_xlfn.SUMIFS(Socle!$X$1:$X$658,Socle!$C$1:$C$658,$A3,Socle!$D$1:$D$658,$C3,Socle!$E$1:$E$658,$D3,Socle!$F$1:$F$658,$E3,Socle!$G$1:$G$658,"2026")) -> 0 | L3: =IF($A3="","",_xlfn.SUMIFS(Socle!$Y$1:$Y$658,Socle!$C$1:$C$658,$A3,Socle!$D$1:$D$658,$C3,Socle!$E$1:$E$658,$D3,Socle!$F$1:$F$658,$E3,Socle!$G$1:$G$658,"2026")) -> 0 | M3: =IF($A3="","",_xlfn.SUMIFS(Socle!$V$1:$V$658,Socle!$C$1:$C$658,$A3,Socle!$D$1:$D$658,$C3,Socle!$E$1:$E$658,$D3,Socle!$F$1:$F$658,$E3,Socle!$G$1:$G$658,"2026")) -> 0.97435897 | N3: =IF($A3="","",IF(OR($D3="B1",$D3="M1",$D3="BTS1"),1,0)) -> 0 | O3: =IF($A3="","",_xlfn.SUMIFS(Campagne!$D$1:$D$141,Campagne!$C$1:$C$141,$A3)) -> 711 | P3: =IF($A3="","",_xlfn.SUMIFS(Campagne!$E$1:$E$141,Campagne!$C$1:$C$141,$A3)) -> 1265 | Q3: =IF($A3="","",_xlfn.SUMIFS(Campagne!$F$1:$F$141,Campagne!$C$1:$C$141,$A3)) -> 1976 | R3: =IF($A3="","",_xlfn.SUMIFS(Campagne!$K$1:$K$141,Campagne!$C$1:$C$141,$A3)) -> 0.46359595 | S3: =IF($A3="","",_xlfn.SUMIFS(Campagne!$M$1:$M$141,Campagne!$C$1:$C$141,$A3)) -> 0.30805412 | T3: =IF($A3="","",_xlfn.SUMIFS(Pilotage!$K$19:$K$32,Pilotage!$A$19:$A$32,$A3)*_xlfn.SUMIFS(Pilotage!$J$19:$J$32,Pilotage!$A$19:$A$32,$A3)*(SUM(Pilotage!$K$19:$K$32)/SUMPRODUCT(Pilotage!$K$19:$K$32,Pilotage!$J$19:$J$32))) -> 68291 | U3: =IF($A3="","",_xlfn.SUMIFS(Pilotage!$K$19:$K$32,Pilotage!$A$19:$A$32,$A3)) -> 68291 | V3: =IF($A3="","",IF($B3="V01",Cadrage!$C$23,IF($B3="V02",Cadrage!$D$23,Cadrage!$E$23))) -> 0.08 | W3: =IF($A3="","",IF($B3="V01",Cadrage!$C$24,IF($B3="V02",Cadrage!$D$24,Cadrage!$E$24))) -> 0.1 | X3: =IF($A3="","",IF($B3="V01",Cadrage!$C$25,IF($B3="V02",Cadrage!$D$25,Cadrage!$E$25))) -> 0.0029 | Y3: =IF($A3="","",IF($B3="V01",Cadrage!$C$26,IF($B3="V02",Cadrage!$D$26,Cadrage!$E$26))) -> 0.01 | Z3: =IF($A3="","",IF($B3="V01",Cadrage!$C$27,IF($B3="V02",Cadrage!$D$27,Cadrage!$E$27))) -> 0.01 | AA3: =IF($A3="","",IF($B3="V01",Cadrage!$C$28,IF($B3="V02",Cadrage!$D$28,Cadrage!$E$28))) -> 0.005 | AB3: =IF($A3="","",IF($B3="V01",Cadrage!$C$42,IF($B3="V02",Cadrage!$D$42,Cadrage!$E$42))) -> 90 | AC3: =IF($A3="","",IF($F3="MBWAY",Cadrage!$K$34,IF($F3="ISCOM",Cadrage!$K$35,IF($F3="IPAC",Cadrage!$K$36,IF($F3="PIGIER",Cadrage!$K$37,Cadrage!$K$38))))) -> 1.2 | AD3: =IF($A3="","",($O3*(1+$W3)^$S3+$P3*_xlfn.IFERROR((($T3/$U3)*(1+$V3))^$R3,0))*_xlfn.IFERROR($G3/$Q3,0)*($J3+$Y3)*$K3*($L3+$Z3)) -> 0 | AE3: =IF($A3="","",IF($N3=1,$AD3,0)) -> 0 | AF3: =IF($A3="","",IF($N3=1,$AD3,$H3*($M3+$AA3))) -> 76.39 | AG3: =IF($A3="","",$I3*(1+$X3*$AC3)) -> 7867.2832 | AH3: =IF($A3="","",$AF3*$AG3+$AE3*$AB3) -> 600981.76
A4: =IF(Moteur!D4="","",Moteur!D4) -> MBWAY_PAR | B4: =IF(Moteur!B4="","",Moteur!B4) -> V01 | C4: =IF(Moteur!F4="","",Moteur!F4) -> BAC_MGT | D4: =IF(Moteur!G4="","",Moteur!G4) -> B3 | E4: =IF(Moteur!H4="","",Moteur!H4) -> ALT | F4: =IF(Moteur!E4="","",Moteur!E4) -> MBWAY | G4: =IF($A4="","",_xlfn.SUMIFS(Socle!$H$1:$H$658,Socle!$C$1:$C$658,$A4,Socle!$D$1:$D$658,$C4,Socle!$E$1:$E$658,$D4,Socle!$F$1:$F$658,$E4,Socle!$G$1:$G$658,"2026")) -> 0 | H4: =IF($A4="","",_xlfn.SUMIFS(Socle!$N$1:$N$658,Socle!$C$1:$C$658,$A4,Socle!$D$1:$D$658,$C4,Socle!$E$1:$E$658,$D4,Socle!$F$1:$F$658,$E4,Socle!$G$1:$G$658,"2026")) -> 76 | I4: =IF($A4="","",_xlfn.SUMIFS(Socle!$P$1:$P$658,Socle!$C$1:$C$658,$A4,Socle!$D$1:$D$658,$C4,Socle!$E$1:$E$658,$D4,Socle!$F$1:$F$658,$E4,Socle!$G$1:$G$658,"2026")) -> 7840 | J4: =IF($A4="","",_xlfn.SUMIFS(Socle!$W$1:$W$658,Socle!$C$1:$C$658,$A4,Socle!$D$1:$D$658,$C4,Socle!$E$1:$E$658,$D4,Socle!$F$1:$F$658,$E4,Socle!$G$1:$G$658,"2026")) -> 0 | K4: =IF($A4="","",_xlfn.SUMIFS(Socle!$X$1:$X$658,Socle!$C$1:$C$658,$A4,Socle!$D$1:$D$658,$C4,Socle!$E$1:$E$658,$D4,Socle!$F$1:$F$658,$E4,Socle!$G$1:$G$658,"2026")) -> 0 | L4: =IF($A4="","",_xlfn.SUMIFS(Socle!$Y$1:$Y$658,Socle!$C$1:$C$658,$A4,Socle!$D$1:$D$658,$C4,Socle!$E$1:$E$658,$D4,Socle!$F$1:$F$658,$E4,Socle!$G$1:$G$658,"2026")) -> 0 | M4: =IF($A4="","",_xlfn.SUMIFS(Socle!$V$1:$V$658,Socle!$C$1:$C$658,$A4,Socle!$D$1:$D$658,$C4,Socle!$E$1:$E$658,$D4,Socle!$F$1:$F$658,$E4,Socle!$G$1:$G$658,"2026")) -> 0.97368421 | N4: =IF($A4="","",IF(OR($D4="B1",$D4="M1",$D4="BTS1"),1,0)) -> 0 | O4: =IF($A4="","",_xlfn.SUMIFS(Campagne!$D$1:$D$141,Campagne!$C$1:$C$141,$A4)) -> 711 | P4: =IF($A4="","",_xlfn.SUMIFS(Campagne!$E$1:$E$141,Campagne!$C$1:$C$141,$A4)) -> 1265 | Q4: =IF($A4="","",_xlfn.SUMIFS(Campagne!$F$1:$F$141,Campagne!$C$1:$C$141,$A4)) -> 1976 | R4: =IF($A4="","",_xlfn.SUMIFS(Campagne!$K$1:$K$141,Campagne!$C$1:$C$141,$A4)) -> 0.46359595 | S4: =IF($A4="","",_xlfn.SUMIFS(Campagne!$M$1:$M$141,Campagne!$C$1:$C$141,$A4)) -> 0.30805412 | T4: =IF($A4="","",_xlfn.SUMIFS(Pilotage!$K$19:$K$32,Pilotage!$A$19:$A$32,$A4)*_xlfn.SUMIFS(Pilotage!$J$19:$J$32,Pilotage!$A$19:$A$32,$A4)*(SUM(Pilotage!$K$19:$K$32)/SUMPRODUCT(Pilotage!$K$19:$K$32,Pilotage!$J$19:$J$32))) -> 68291 | U4: =IF($A4="","",_xlfn.SUMIFS(Pilotage!$K$19:$K$32,Pilotage!$A$19:$A$32,$A4)) -> 68291 | V4: =IF($A4="","",IF($B4="V01",Cadrage!$C$23,IF($B4="V02",Cadrage!$D$23,Cadrage!$E$23))) -> 0.08 | W4: =IF($A4="","",IF($B4="V01",Cadrage!$C$24,IF($B4="V02",Cadrage!$D$24,Cadrage!$E$24))) -> 0.1 | X4: =IF($A4="","",IF($B4="V01",Cadrage!$C$25,IF($B4="V02",Cadrage!$D$25,Cadrage!$E$25))) -> 0.0029 | Y4: =IF($A4="","",IF($B4="V01",Cadrage!$C$26,IF($B4="V02",Cadrage!$D$26,Cadrage!$E$26))) -> 0.01 | Z4: =IF($A4="","",IF($B4="V01",Cadrage!$C$27,IF($B4="V02",Cadrage!$D$27,Cadrage!$E$27))) -> 0.01 | AA4: =IF($A4="","",IF($B4="V01",Cadrage!$C$28,IF($B4="V02",Cadrage!$D$28,Cadrage!$E$28))) -> 0.005 | AB4: =IF($A4="","",IF($B4="V01",Cadrage!$C$42,IF($B4="V02",Cadrage!$D$42,Cadrage!$E$42))) -> 90 | AC4: =IF($A4="","",IF($F4="MBWAY",Cadrage!$K$34,IF($F4="ISCOM",Cadrage!$K$35,IF($F4="IPAC",Cadrage!$K$36,IF($F4="PIGIER",Cadrage!$K$37,Cadrage!$K$38))))) -> 1.2 | AD4: =IF($A4="","",($O4*(1+$W4)^$S4+$P4*_xlfn.IFERROR((($T4/$U4)*(1+$V4))^$R4,0))*_xlfn.IFERROR($G4/$Q4,0)*($J4+$Y4)*$K4*($L4+$Z4)) -> 0 | AE4: =IF($A4="","",IF($N4=1,$AD4,0)) -> 0 | AF4: =IF($A4="","",IF($N4=1,$AD4,$H4*($M4+$AA4))) -> 74.38 | AG4: =IF($A4="","",$I4*(1+$X4*$AC4)) -> 7867.2832 | AH4: =IF($A4="","",$AF4*$AG4+$AE4*$AB4) -> 585168.52
