Workbook

Sheet Base 2026
B2: LA BASE — telle qu'elle est lue en base
B3: AW_002_000002_000001 et AW_002_000004_000001. Aucune formule ici : c'est l'extrait, pas un retraitement.
B5: Volumes et recettes | C5: 2024 | D5: 2025 | E5: 2026
B6: Effectifs | C6: 2773 | D6: 2933 | E6: 3114
B7: Inscrits de l'annee | C7: 1092 | D7: 1159 | E7: 1229
B8: Chiffre d'affaires | C8: 20567210 | D8: 21758770 | E8: 23098985
B9: Chiffre d'affaires par eleve | C9: 7416.9528 | D9: 7418.6055 | E9: 7417.7858
B10: strictement plat sur trois ans : la croissance est 100 % volume
B12: Postes de cout | C12: 2024 | D12: 2025 | E12: 2026 | F12: € / eleve 2026
B13: Masse salariale permanents | C13: 8248040.6 | D13: 8625801.8 | E13: 9037358.3 | F13: =E13/E$6
B14: Vacataires | C14: 1443361 | D14: 1509499 | E14: 1581554 | F14: =E14/E$6
B15: Acquisition etudiants | C15: 358819 | D15: 394702 | E15: 434174 | F15: =E15/E$6
B16: Autres couts campus | C16: 4226736.4 | D16: 4420600.2 | E16: 4631781.6 | F16: =E16/E$6
B17: Couts de siege | C17: 3139218 | D17: 3340399 | E17: 3568327 | F17: =E17/E$6
B18: Cout complet | C18: =SUM(C13:C17) | D18: =SUM(D13:D17) | E18: =SUM(E13:E17)
B19: EBITDA | C19: =C8-C18 | D19: =D8-D18 | E19: =E8-E18
B20: Marge | C20: =C19/C8 | D20: =D19/D8 | E20: =E19/E8
B22: CAF — cout d'acquisition par inscrit | C22: 328.58883 | D22: 340.55393 | E22: 353.27421
B23: +7 %/an : il faut depenser de plus en plus pour recruter un eleve

Sheet Cadrage 2027
B2: CADRAGE 2027 — PILOTÉ PAR L'EBITDA
B3: On ne construit plus le budget pour découvrir l'EBITDA. On saisit l'EBITDA, et on cherche ce qu'il faut faire pour l'atteindre.
B6: ① LE CONSTAT — ce que le réseau apporte | J6: CE QUE LE CADRAGE DIT
B7: La rentrée est engagée. La finance ne la négocie pas : elle en hérite.
J8: Le CA n'est pas un levier.
C9: 2026 (base) | D9: hypothèse | E9: 2027 (constat) | J9: Les effectifs de la rentrée sont connus quand le cadrage s'ouvre. Le CA est un constat ; seul le prix reste discutable.
B10: Effectifs | C10: ='Base 2026'!$E$6 | D10: 0.06 | E10: =C10*(1+D10)
B11: Inscrits de l'année | C11: ='Base 2026'!$E$7 | D11: taux d'entrée maintenu | E11: =E10*C11/C10
B12: Chiffre d'affaires par élève | C12: ='Base 2026'!$E$9 | D12: 0 | E12: =C12*(1+D12)
B13: CHIFFRE D'AFFAIRES 2027 | C13: =C10*C12 | E13: =E10*E12 | J13: Le fil de l'eau détruit de la marge.
B14: L'historique ne montre aucun effet prix : 7 418 € par élève en 2024 comme en 2026. | J14: Coûts unitaires reconduits et indexés sur un volume en hausse : 16,65 % → 14,69 %. L'inaction a un coût chiffré.
B17: ② LA CIBLE — la seule chose que la direction saisit
J18: Le poids décide de la puissance.
B19: Marge d'EBITDA visée en 2027 | D19: 0.175 | E19: ="pour mémoire 2026 : "&TEXT('Base 2026'!$E$20,"0,00 %") | J19: La masse salariale fait 47 % des coûts, l'acquisition 2 %. Un point sur l'une vaut vingt points sur l'autre.
B20: EBITDA cible | E20: =D19*$E$13
B23: ③ LE TENDANCIEL — le budget au fil de l'eau | J23: Le siège ne se dilue pas.
B24: Coûts unitaires 2026 reconduits, indexés de leur inflation propre, appliqués au volume 2027. Aucune décision de gestion. | J24: 1 132 € par élève en 2024, 1 146 € en 2026 : il croît plus vite que le réseau qu'il sert.
B26: Poste | C26: € / unité 2026 | D26: indexation | E26: € / unité 2027 | F26: volume 2027 | G26: montant 2027 | H26: % du CA
B27: Masse salariale permanents | C27: ='Base 2026'!$F$13 | D27: 0.025 | E27: =C27*(1+D27) | F27: =$E$10 | G27: =E27*F27 | H27: =G27/$E$13
B28: Vacataires | C28: ='Base 2026'!$F$14 | D28: 0.02 | E28: =C28*(1+D28) | F28: =$E$10 | G28: =E28*F28 | H28: =G28/$E$13 | J28: Le prix n'a jamais bougé.
B29: Acquisition etudiants | C29: ='Base 2026'!$E$22 | D29: 0.07 | E29: =C29*(1+D29) | F29: =$E$11 | G29: =E29*F29 | H29: =G29/$E$13 | J29: Zéro revalorisation en trois ans. C'est le levier le plus puissant et le seul jamais actionné.
B30: Autres couts campus | C30: ='Base 2026'!$F$16 | D30: 0.02 | E30: =C30*(1+D30) | F30: =$E$10 | G30: =E30*F30 | H30: =G30/$E$13
B31: Couts de siege | C31: ='Base 2026'!$F$17 | D31: 0.02 | E31: =C31*(1+D31) | F31: =$E$10 | G31: =E31*F31 | H31: =G31/$E$13
B32: Coût complet | G32: =SUM(G27:G31) | H32: =G32/$E$13
B33: EBITDA TENDANCIEL | G33: =$E$13-G32 | H33: =G33/$E$13
B34: La marge 2026 était de 16,65 %. Sans décision, elle se dégrade : le levier d'exploitation qui portait 2024-2026 ne se reconduit pas tout seul.
B37: ④ L'ÉCART À COMBLER | G37: =$E$20-$G$33
B38: ="EBITDA cible "&TEXT(""&$E$20,"# ##0 €")&" - tendanciel "&TEXT($G$33,"# ##0 €") | G38: à trouver dans les coûts
B41: ⑤ LES LEVIERS — les seules décisions de gestion
B42: Chacun est assis sur une grandeur réelle. Les effets se cumulent en cascade : leur somme est exacte, sans terme croisé.
B44: Levier | C44: assiette 2027 | D44: réglage | E44: effet EBITDA | F44: en points | G44: % de l'écart
B45: Politique salariale — points retirés à la NAO | D45: 0.01 | E45: =G27 | F45: =G27-C27*(1+D27-D45)*F27 | G45: =F45/$E$13 | H45: =F45/$G$37
B46: Encadrement — % d'élèves en plus par ETP | D46: 0.02 | E46: =G27*(1-(D27-D45)/(1+D27)) | F46: =E46*D46 | G46: =F46/$E$13 | H46: =F46/$G$37
B47: Vacataires — % d'heures en moins par élève | D47: 0.03 | E47: =G28 | F47: =E47*D47 | G47: =F47/$E$13 | H47: =F47/$G$37
B48: Acquisition — % de CAF en moins par inscrit | D48: 0.065 | E48: =G29 | F48: =E48*D48 | G48: =F48/$E$13 | H48: =F48/$G$37
B49: Siège — % de coût en moins par élève | D49: 0.05 | E49: =G31 | F49: =E49*D49 | G49: =F49/$E$13 | H49: =F49/$G$37
B50: Grille tarifaire — revalorisation | D50: 0.005 | E50: =$E$13 | F50: =E50*D50 | G50: =F50/$E$13 | H50: =F50/$G$37
B51: TOTAL TROUVÉ | F51: =SUM(F45:F50) | G51: =F51/$E$13 | H51: =F51/$G$37
B52: L'acquisition ne rapporte que 0,02 pt par point de CAF : le cadrage se joue sur la masse salariale, pas sur le marketing.
B55: ⑥ LE SOLDE | G55: =$G$37-F51
...
