Workbook

Sheet Données
A1: SOCLE DE DONNÉES — cockpit EDUSERVICES · 14 campus × 5 marques
A3: ① PÉRIMÈTRE (les filtres du cockpit)
A4: Filtre | B4: Valeur
A5: Scénario | B5: REEL
A6: Version | B6: V_FINAL
A7: Exercice | B7: 2026
A8: Période | B8: 12 — Cumul
A9: Marque | B9: Toutes
A10: Campus | B10: Tous
A11: Modalité | B11: Toutes
A13: ② SOCLE CAMPUS — la seule saisie (source : V_COCKPIT / V_ALLOCATION, grain campus × exercice)
A14: Entity | B14: Marque | C14: CA 2024 | D14: CA 2025 | E14: CA 2026 | F14: EBITDA 2024 | G14: EBITDA 2025 | H14: EBITDA 2026 | I14: Inscrits 26 | J14: Effectifs 26 | K14: Places 26 | L14: Mix alt. 26
A15: MBWAY_BOR | B15: MBway | C15: 1537990 | D15: 1656282 | E15: 1784942 | F15: 237542 | G15: 268273 | H15: 307544 | I15: 102 | J15: 251 | K15: 296 | L15: 0.7959
A16: MBWAY_LYO | B16: MBway | C16: 2154491 | D16: 2320201 | E16: 2500434 | F16: 354945 | G16: 399596 | H16: 456436 | I16: 132 | J16: 324 | K16: 412 | L16: 0.7959
A17: MBWAY_NAN | B17: MBway | C17: 1865360 | D17: 2008832 | E17: 2164878 | F17: 299628 | G17: 337733 | H17: 386312 | I17: 120 | J17: 295 | K17: 348 | L17: 0.7959
A18: MBWAY_PAR | B18: MBway | C18: 2715965 | D18: 2924860 | E18: 3152062 | F18: 469817 | G18: 527720 | H18: 601217 | I18: 156 | J18: 383 | K18: 470 | L18: 0.7959
A19: ISCOM_LIL | B19: ISCOM | C19: 1627556 | D19: 1687214 | E19: 1750304 | F19: 246201 | G19: 272204 | H19: 288015 | I19: 99 | J19: 243 | K19: 296 | L19: 0.7959
A20: ISCOM_PAR | B20: ISCOM | C20: 2686759 | D20: 2785243 | E20: 2889390 | F20: 450936 | G20: 495292 | H20: 523028 | I20: 143 | J20: 351 | K20: 444 | L20: 0.7959
A21: ISCOM_TLS | B21: ISCOM | C21: 1505766 | D21: 1560960 | E21: 1619329 | F21: 224660 | G21: 248616 | H21: 263130 | I21: 94 | J21: 230 | K21: 296 | L21: 0.7959
A22: IPAC_MTP | B22: Ipac | C22: 650230 | D22: 713330 | E22: 783111 | F22: 74568 | G22: 90342 | H22: 108000 | I22: 40 | J22: 117 | K22: 192 | L22: 1
A23: IPAC_NAN | B23: Ipac | C23: 855566 | D23: 938593 | E23: 1030409 | F23: 105663 | G23: 127069 | H23: 151056 | I23: 50 | J23: 146 | K23: 192 | L23: 1
A24: IPAC_REN | B24: Ipac | C24: 650230 | D24: 713330 | E24: 783111 | F24: 74568 | G24: 90342 | H24: 108000 | I24: 40 | J24: 117 | K24: 192 | L24: 1
A25: PIGIER_BOR | B25: Pigier | C25: 1027213 | D25: 1075204 | E25: 1126238 | F25: 196141 | G25: 212061 | H25: 231329 | I25: 72 | J25: 175 | K25: 312 | L25: 1
A26: PIGIER_LYO | B26: Pigier | C26: 1438970 | D26: 1506199 | E26: 1577690 | F26: 289961 | G26: 312883 | H26: 340591 | I26: 93 | J26: 227 | K26: 312 | L26: 1
... A28: TUNON_PAR | B28: Tunon | C28: 1024236 | D28: 1051471 | E28: 1080198 | F28: 65804 | G28: 60619 | H28: 48547 | I28: 47 | J28: 137 | K28: 192 | L28: 1
A29: TOTAL GROUPE | C29: =SUM(C15:C28) | D29: =SUM(D15:D28) | E29: =SUM(E15:E28) | F29: =SUM(F15:F28) | G29: =SUM(G15:G28) | H29: =SUM(H15:H28) | I29: =SUM(I15:I28) | J29: =SUM(J15:J28) | K29: =SUM(K15:K28)
A30: ③ ACQUISITION (groupe)
A31: Mesure | B31: 2024 | C31: 2025 | D31: 2026
A32: Dépenses d'acquisition (€) | B32: 358170 | C32: 394702 | D32: 434174
A33: Inscrits (nouveaux) | B33: 1092 | C33: 1159 | D33: 1229
A34: ④ BRIDGE EBITDA 2025 → 2026 (l'effet coûts est le résidu : le pont boucle toujours)
A35: Étape | B35: Montant (€)
A37: EBITDA 2025 | B37: =SUM($G$15:$G$28)
A38: Effet activité | B38: 211706
A39: Effet prix / mix | B39: 289000
A40: Effet coûts (résidu) | B40: =B41-B37-B38-B39
A41: EBITDA 2026 | B41: =SUM($H$15:$H$28)
A43: ⑤ AGRÉGATS PAR MARQUE — 100 % calculés depuis ②
A44: Marque | B44: CA 2024 | C44: CA 2025 | D44: CA 2026 | E44: EBITDA 2024 | F44: EBITDA 2025 | G44: EBITDA 2026 | H44: Marge 2024 | I44: Marge 2025 | J44: Marge 2026
A46: MBway | B46: =SUMIF(Données!$B$15:$B$28,$A46,Données!$C$15:$C$28) | C46: =SUMIF(Données!$B$15:$B$28,$A46,Données!$D$15:$D$28) | D46: =SUMIF(Données!$B$15:$B$28,$A46,Données!$E$15:$E$28) | E46: =SUMIF(Données!$B$15:$B$28,$A46,Données!$F$15:$F$28) | F46: =SUMIF(Données!$B$15:$B$28,$A46,Données!$G$15:$G$28) | G46: =SUMIF(Données!$B$15:$B$28,$A46,Données!$H$15:$H$28) | H46: =E46/B46 | I46: =F46/C46 | J46: =G46/D46
...

Sheet Cockpit
B2: Cockpit de performance — EDUSERVICES GROUP | M2: RÉEL · CLÔTURE 2026
B3: Constat 2024 → 2026 · 14 campus · 5 marques · socle CRM & comptabilité rapprochés
B5: Scénario | C5: =Données!B5 | D5: Version | E5: =Données!B6 | F5: Exercice | G5: =Données!B7 | H5: Période | I5: =Données!B8 | J5: Marque | K5: =Données!B9 | L5: Campus | M5: =Données!B10
B7: CHIFFRE D'AFFAIRES | D7: EBITDA | F7: MARGE EBITDA | H7: INSCRITS (NOUVEAUX) | J7: COÛT D'ACQUISITION | L7: REMPLISSAGE MOYEN
B8: =C35 | D8: =E35 | F8: =H35 | H8: =J35 | J8: =Données!D32/Données!D33 | L8: =K35
B9: =D35 | D9: =F35 | F9: =I35 | H9: =J35/Données!C33-1 | J9: =(Données!D32/Données!D33)/(Données!C32/Données!C33)-1 | L9: =SUM(Données!$K$15:$K$28)-SUM(Données!$J$15:$J$28)
B11: Bridge EBITDA 2025 → 2026 | E11: M€ · axe tronqué à 3,2 | F11: Marge EBITDA par marque | I11: 2024 · 2025 · 2026 | J11: Tension acquisition | M11: base 100 = 2024
B33: Portefeuille — marque & campus | M33: exercice 2026 · variation vs 2025
B34: Marque / campus | C34: CA 2026 | D34: Δ CA | E34: EBITDA | F34: Δ EBITDA | G34: Part EBITDA | H34: Marge EBITDA | I34: Δ marge | J34: Inscrits | K34: Rempl. | L34: Mix alt. | M34: Alerte
B35: GROUPE | C35: =SUM(Données!$E$15:$E$28) | D35: =C35/SUM(Données!$D$15:$D$28)-1 | E35: =SUM(Données!$H$15:$H$28) | F35: =E35/SUM(Données!$G$15:$G$28)-1 | G35: =E35/$E$35 | H35: =E35/C35 | I35: =(H35-SUM(Données!$G$15:$G$28)/SUM(Données!$D$15:$D$28))*100 | J35: =SUM(Données!$I$15:$I$28) | K35: =SUM(Données!$J$15:$J$28)/SUM(Données!$K$15:$K$28) | L35: =SUMPRODUCT(Données!$J$15:$J$28,Données!$L$15:$L$28)/SUM(Données!$J$15:$J$28) | M35: =IF(H35<0.08,"FRAGILE","")
B36: MBway | C36: =SUMIF(Données!$B$15:$B$28,$B36,Données!$E$15:$E$28) | D36: =C36/SUMIF(Données!$B$15:$B$28,$B36,Données!$D$15:$D$28)-1 | E36: =SUMIF(Données!$B$15:$B$28,$B36,Données!$H$15:$H$28) | F36: =E36/SUMIF(Données!$B$15:$B$28,$B36,Données!$G$15:$G$28)-1 | G36: =E36/$E$35 | H36: =E36/C36 | I36: =(H36-SUMIF(Données!$B$15:$B$28,$B36,Données!$G$15:$G$28)/SUMIF(Données!$B$15:$B$28,$B36,Données!$D$15:$D$28))*100 | J36: =SUMIF(Données!$B$15:$B$28,$B36,Données!$I$15:$I$28) | K36: =SUMIF(Données!$B$15:$B$28,$B36,Données!$J$15:$J$28)/SUMIF(Données!$B$15:$B$28,$B36,Données!$K$15:$K$28) | L36: =SUMPRODUCT((Données!$B$15:$B$28=$B36)*Données!$J$15:$J$28*Données!$L$15:$L$28)/SUMIF(Données!$B$15:$B$28,$B36,Données!$J$15:$J$28) | M36: =IF(H36<0.08,"FRAGILE","")
B37: MBWAY_BOR | C37: =VLOOKUP($B37,Données!$A$15:$L$28,5,0) | D37: =C37/VLOOKUP($B37,Données!$A$15:$L$28,4,0)-1 | E37: =VLOOKUP($B37,Données!$A$15:$L$28,8,0) | F37: =IF(VLOOKUP($B37,Données!$A$15:$L$28,7,0)<=0,"n/s",E37/VLOOKUP($B37,Données!$A$15:$L$28,7,0)-1) | G37: =E37/$E$35 | H37: =E37/C37 | I37: =(H37-VLOOKUP($B37,Données!$A$15:$L$28,7,0)/VLOOKUP($B37,Données!$A$15:$L$28,4,0))*100 | J37: =VLOOKUP($B37,Données!$A$15:$L$28,9,0) | K37: =VLOOKUP($B37,Données!$A$15:$L$28,10,0)/VLOOKUP($B37,Données!$A$15:$L$28,11,0) | L37: =VLOOKUP($B37,Données!$A$15:$L$28,12,0) | M37: =IF(H37<0.08,"FRAGILE","")
B38: MBWAY_LYO | C38: =VLOOKUP($B38,Données!$A$15:$L$28,5,0) | D38: =C38/VLOOKUP($B38,Données!$A$15:$L$28,4,0)-1 | E38: =VLOOKUP($B38,Données!$A$15:$L$28,8,0) | F38: =IF(VLOOKUP($B38,Données!$A$15:$L$28,7,0)<=0,"n/s",E38/VLOOKUP($B38,Données!$A$15:$L$28,7,0)-1) | G38: =E38/$E$35 | H38: =E38/C38 | I38: =(H38-VLOOKUP($B38,Données!$A$15:$L$28,7,0)/VLOOKUP($B38,Données!$A$15:$L$28,4,0))*100 | J38: =VLOOKUP($B38,Données!$A$15:$L$28,9,0) | K38: =VLOOKUP($B38,Données!$A$15:$L$28,10,0)/VLOOKUP($B38,Données!$A$15:$L$28,11,0) | L38: =VLOOKUP($B38,Données!$A$15:$L$28,12,0) | M38: =IF(H38<0.08,"FRAGILE","")
B39: MBWAY_NAN | C39: =VLOOKUP($B39,Données!$A$15:$L$28,5,0) | D39: =C39/VLOOKUP($B39,Données!$A$15:$L$28,4,0)-1 | E39: =VLOOKUP($B39,Données!$A$15:$L$28,8,0) | F39: =IF(VLOOKUP($B39,Données!$A$15:$L$28,7,0)<=0,"n/s",E39/VLOOKUP($B39,Données!$A$15:$L$28,7,0)-1) | G39: =E39/$E$35 | H39: =E39/C39 | I39: =(H39-VLOOKUP($B39,Données!$A$15:$L$28,7,0)/VLOOKUP($B39,Données!$A$15:$L$28,4,0))*100 | J39: =VLOOKUP($B39,Données!$A$15:$L$28,9,0) | K39: =VLOOKUP($B39,Données!$A$15:$L$28,10,0)/VLOOKUP($B39,Données!$A$15:$L$28,11,0) | L39: =VLOOKUP($B39,Données!$A$15:$L$28,12,0) | M39: =IF(H39<0.08,"FRAGILE","")
B40: MBWAY_PAR | C40: =VLOOKUP($B40,Données!$A$15:$L$28,5,0) | D40: =C40/VLOOKUP($B40,Données!$A$15:$L$28,4,0)-1 | E40: =VLOOKUP($B40,Données!$A$15:$L$28,8,0) | F40: =IF(VLOOKUP($B40,Données!$A$15:$L$28,7,0)<=0,"n/s",E40/VLOOKUP($B40,Données!$A$15:$L$28,7,0)-1) | G40: =E40/$E$35 | H40: =E40/C40 | I40: =(H40-VLOOKUP($B40,Données!$A$15:$L$28,7,0)/VLOOKUP($B40,Données!$A$15:$L$28,4,0))*100 | J40: =VLOOKUP($B40,Données!$A$15:$L$28,9,0) | K40: =VLOOKUP($B40,Données!$A$15:$L$28,10,0)/VLOOKUP($B40,Données!$A$15:$L$28,11,0) | L40: =VLOOKUP($B40,Données!$A$15:$L$28,12,0) | M40: =IF(H40<0.08,"FRAGILE","")
B41: ISCOM | C41: =SUMIF(Données!$B$15:$B$28,$B41,Données!$E$15:$E$28) | D41: =C41/SUMIF(Données!$B$15:$B$28,$B41,Données!$D$15:$D$28)-1 | E41: =SUMIF(Données!$B$15:$B$28,$B41,Données!$H$15:$H$28) | F41: =E41/SUMIF(Données!$B$15:$B$28,$B41,Données!$G$15:$G$28)-1 | G41: =E41/$E$35 | H41: =E41/C41 | I41: =(H41-SUMIF(Données!$B$15:$B$28,$B41,Données!$G$15:$G$28)/SUMIF(Données!$B$15:$B$28,$B41,Données!$D$15:$D$28))*100 | J41: =SUMIF(Données!$B$15:$B$28,$B41,Données!$I$15:$I$28) | K41: =SUMIF(Données!$B$15:$B$28,$B41,Données!$J$15:$J$28)/SUMIF(Données!$B$15:$B$28,$B41,Données!$K$15:$K$28) | L41: =SUMPRODUCT((Données!$B$15:$B$28=$B41)*Données!$J$15:$J$28*Données!$L$15:$L$28)/SUMIF(Données!$B$15:$B$28,$B41,Données!$J$15:$J$28) | M41: =IF(H41<0.08,"FRAGILE","")
B42: ISCOM_LIL | C42: =VLOOKUP($B42,Données!$A$15:$L$28,5,0) | D42: =C42/VLOOKUP($B42,Données!$A$15:$L$28,4,0)-1 | E42: =VLOOKUP($B42,Données!$A$15:$L$28,8,0) | F42: =IF(VLOOKUP($B42,Données!$A$15:$L$28,7,0)<=0,"n/s",E42/VLOOKUP($B42,Données!$A$15:$L$28,7,0)-1) | G42: =E42/$E$35 | H42: =E42/C42 | I42: =(H42-VLOOKUP($B42,Données!$A$15:$L$28,7,0)/VLOOKUP($B42,Données!$A$15:$L$28,4,0))*100 | J42: =VLOOKUP($B42,Données!$A$15:$L$28,9,0) | K42: =VLOOKUP($B42,Données!$A$15:$L$28,10,0)/VLOOKUP($B42,Données!$A$15:$L$28,11,0) | L42: =VLOOKUP($B42,Données!$A$15:$L$28,12,0) | M42: =IF(H42<0.08,"FRAGILE","")
B43: ISCOM_PAR | C43: =VLOOKUP($B43,Données!$A$15:$L$28,5,0) | D43: =C43/VLOOKUP($B43,Données!$A$15:$L$28,4,0)-1 | E43: =VLOOKUP($B43,Données!$A$15:$L$28,8,0) | F43: =IF(VLOOKUP($B43,Données!$A$15:$L$28,7,0)<=0,"n/s",E43/VLOOKUP($B43,Données!$A$15:$L$28,7,0)-1) | G43: =E43/$E$35 | H43: =E43/C43 | I43: =(H43-VLOOKUP($B43,Données!$A$15:$L$28,7,0)/VLOOKUP($B43,Données!$A$15:$L$28,4,0))*100 | J43: =VLOOKUP($B43,Données!$A$15:$L$28,9,0) | K43: =VLOOKUP($B43,Données!$A$15:$L$28,10,0)/VLOOKUP($B43,Données!$A$15:$L$28,11,0) | L43: =VLOOKUP($B43,Données!$A$15:$L$28,12,0) | M43: =IF(H43<0.08,"FRAGILE","")
B44: ISCOM_TLS | C44: =VLOOKUP($B44,Données!$A$15:$L$28,5,0) | D44: =C44/VLOOKUP($B44,Données!$A$15:$L$28,4,0)-1 | E44: =VLOOKUP($B44,Données!$A$15:$L$28,8,0) | F44: =IF(VLOOKUP($B44,Données!$A$15:$L$28,7,0)<=0,"n/s",E44/VLOOKUP($B44,Données!$A$15:$L$28,7,0)-1) | G44: =E44/$E$35 | H44: =E44/C44 | I44: =(H44-VLOOKUP($B44,Données!$A$15:$L$28,7,0)/VLOOKUP($B44,Données!$A$15:$L$28,4,0))*100 | J44: =VLOOKUP($B44,Données!$A$15:$L$28,9,0) | K44: =VLOOKUP($B44,Données!$A$15:$L$28,10,0)/VLOOKUP($B44,Données!$A$15:$L$28,11,0) | L44: =VLOOKUP($B44,Données!$A$15:$L$28,12,0) | M44: =IF(H44<0.08,"FRAGILE","")
B45: Ipac | C45: =SUMIF(Données!$B$15:$B$28,$B45,Données!$E$15:$E$28) | D45: =C45/SUMIF(Données!$B$15:$B$28,$B45,Données!$D$15:$D$28)-1 | E45: =SUMIF(Données!$B$15:$B$28,$B45,Données!$H$15:$H$28) | F45: =E45/SUMIF(Données!$B$15:$B$28,$B45,Données!$G$15:$G$28)-1 | G45: =E45/$E$35 | H45: =E45/C45 | I45: =(H45-SUMIF(Données!$B$15:$B$28,$B45,Données!$G$15:$G$28)/SUMIF(Données!$B$15:$B$28,$B45,Données!$D$15:$D$28))*100 | J45: =SUMIF(Données!$B$15:$B$28,$B45,Données!$I$15:$I$28) | K45: =SUMIF(Données!$B$15:$B$28,$B45,Données!$J$15:$J$28)/SUMIF(Données!$B$15:$B$28,$B45,Données!$K$15:$K$28) | L45: =SUMPRODUCT((Données!$B$15:$B$28=$B45)*Données!$J$15:$J$28*Données!$L$15:$L$28)/SUMIF(Données!$B$15:$B$28,$B45,Données!$J$15:$J$28) | M45: =IF(H45<0.08,"FRAGILE","")
B46: IPAC_MTP | C46: =VLOOKUP($B46,Données!$A$15:$L$28,5,0) | D46: =C46/VLOOKUP($B46,Données!$A$15:$L$28,4,0)-1 | E46: =VLOOKUP($B46,Données!$A$15:$L$28,8,0) | F46: =IF(VLOOKUP($B46,Données!$A$15:$L$28,7,0)<=0,"n/s",E46/VLOOKUP($B46,Données!$A$15:$L$28,7,0)-1) | G46: =E46/$E$35 | H46: =E46/C46 | I46: =(H46-VLOOKUP($B46,Données!$A$15:$L$28,7,0)/VLOOKUP($B46,Données!$A$15:$L$28,4,0))*100 | J46: =VLOOKUP($B46,Données!$A$15:$L$28,9,0) | K46: =VLOOKUP($B46,Données!$A$15:$L$28,10,0)/VLOOKUP($B46,Données!$A$15:$L$28,11,0) | L46: =VLOOKUP($B46,Données!$A$15:$L$28,12,0) | M46: =IF(H46<0.08,"FRAGILE","")
B47: IPAC_NAN | C47: =VLOOKUP($B47,Données!$A$15:$L$28,5,0) | D47: =C47/VLOOKUP($B47,Données!$A$15:$L$28,4,0)-1 | E47: =VLOOKUP($B47,Données!$A$15:$L$28,8,0) | F47: =IF(VLOOKUP($B47,Données!$A$15:$L$28,7,0)<=0,"n/s",E47/VLOOKUP($B47,Données!$A$15:$L$28,7,0)-1) | G47: =E47/$E$35 | H47: =E47/C47 | I47: =(H47-VLOOKUP($B47,Données!$A$15:$L$28,7,0)/VLOOKUP($B47,Données!$A$15:$L$28,4,0))*100 | J47: =VLOOKUP($B47,Données!$A$15:$L$28,9,0) | K47: =VLOOKUP($B47,Données!$A$15:$L$28,10,0)/VLOOKUP($B47,Données!$A$15:$L$28,11,0) | L47: =VLOOKUP($B47,Données!$A$15:$L$28,12,0) | M47: =IF(H47<0.08,"FRAGILE","")
B48: IPAC_REN | C48: =VLOOKUP($B48,Données!$A$15:$L$28,5,0) | D48: =C48/VLOOKUP($B48,Données!$A$15:$L$28,4,0)-1 | E48: =VLOOKUP($B48,Données!$A$15:$L$28,8,0) | F48: =IF(VLOOKUP($B48,Données!$A$15:$L$28,7,0)<=0,"n/s",E48/VLOOKUP($B48,Données!$A$15:$L$28,7,0)-1) | G48: =E48/$E$35 | H48: =E48/C48 | I48: =(H48-VLOOKUP($B48,Données!$A$15:$L$28,7,0)/VLOOKUP($B48,Données!$A$15:$L$28,4,0))*100 | J48: =VLOOKUP($B48,Données!$A$15:$L$28,9,0) | K48: =VLOOKUP($B48,Données!$A$15:$L$28,10,0)/VLOOKUP($B48,Données!$A$15:$L$28,11,0) | L48: =VLOOKUP($B48,Données!$A$15:$L$28,12,0) | M48: =IF(H48<0.08,"FRAGILE","")
B49: Pigier | C49: =SUMIF(Données!$B$15:$B$28,$B49,Données!$E$15:$E$28) | D49: =C49/SUMIF(Données!$B$15:$B$28,$B49,Données!$D$15:$D$28)-1 | E49: =SUMIF(Données!$B$15:$B$28,$B49,Données!$H$15:$H$28) | F49: =E49/SUMIF(Données!$B$15:$B$28,$B49,Données!$G$15:$G$28)-1 | G49: =E49/$E$35 | H49: =E49/C49 | I49: =(H49-SUMIF(Données!$B$15:$B$28,$B49,Données!$G$15:$G$28)/SUMIF(Données!$B$15:$B$28,$B49,Données!$D$15:$D$28))*100 | J49: =SUMIF(Données!$B$15:$B$28,$B49,Données!$I$15:$I$28) | K49: =SUMIF(Données!$B$15:$B$28,$B49,Données!$J$15:$J$28)/SUMIF(Données!$B$15:$B$28,$B49,Données!$K$15:$K$28) | L49: =SUMPRODUCT((Données!$B$15:$B$28=$B49)*Données!$J$15:$J$28*Données!$L$15:$L$28)/SUMIF(Données!$B$15:$B$28,$B49,Données!$J$15:$J$28) | M49: =IF(H49<0.08,"FRAGILE","")
B50: PIGIER_BOR | C50: =VLOOKUP($B50,Données!$A$15:$L$28,5,0) | D50: =C50/VLOOKUP($B50,Données!$A$15:$L$28,4,0)-1 | E50: =VLOOKUP($B50,Données!$A$15:$L$28,8,0) | F50: =IF(VLOOKUP($B50,Données!$A$15:$L$28,7,0)<=0,"n/s",E50/VLOOKUP($B50,Données!$A$15:$L$28,7,0)-1) | G50: =E50/$E$35 | H50: =E50/C50 | I50: =(H50-VLOOKUP($B50,Données!$A$15:$L$28,7,0)/VLOOKUP($B50,Données!$A$15:$L$28,4,0))*100 | J50: =VLOOKUP($B50,Données!$A$15:$L$28,9,0) | K50: =VLOOKUP($B50,Données!$A$15:$L$28,10,0)/VLOOKUP($B50,Données!$A$15:$L$28,11,0) | L50: =VLOOKUP($B50,Données!$A$15:$L$28,12,0) | M50: =IF(H50<0.08,"FRAGILE","")
B51: PIGIER_LYO | C51: =VLOOKUP($B51,Données!$A$15:$L$28,5,0) | D51: =C51/VLOOKUP($B51,Données!$A$15:$L$28,4,0)-1 | E51: =VLOOKUP($B51,Données!$A$15:$L$28,8,0) | F51: =IF(VLOOKUP($B51,Données!$A$15:$L$28,7,0)<=0,"n/s",E51/VLOOKUP($B51,Données!$A$15:$L$28,7,0)-1) | G51: =E51/$E$35 | H51: =E51/C51 | I51: =(H51-VLOOKUP($B51,Données!$A$15:$L$28,7,0)/VLOOKUP($B51,Données!$A$15:$L$28,4,0))*100 | J51: =VLOOKUP($B51,Données!$A$15:$L$28,9,0) | K51: =VLOOKUP($B51,Données!$A$15:$L$28,10,0)/VLOOKUP($B51,Données!$A$15:$L$28,11,0) | L51: =VLOOKUP($B51,Données!$A$15:$L$28,12,0) | M51: =IF(H51<0.08,"FRAGILE","")
B52: Tunon | C52: =SUMIF(Données!$B$15:$B$28,$B52,Données!$E$15:$E$28) | D52: =C52/SUMIF(Données!$B$15:$B$28,$B52,Données!$D$15:$D$28)-1 | E52: =SUMIF(Données!$B$15:$B$28,$B52,Données!$H$15:$H$28) | F52: =E52/SUMIF(Données!$B$15:$B$28,$B52,Données!$G$15:$G$28)-1 | G52: =E52/$E$35 | H52: =E52/C52 | I52: =(H52-SUMIF(Données!$B$15:$B$28,$B52,Données!$G$15:$G$28)/SUMIF(Données!$B$15:$B$28,$B52,Données!$D$15:$D$28))*100 | J52: =SUMIF(Données!$B$15:$B$28,$B52,Données!$I$15:$I$28) | K52: =SUMIF(Données!$B$15:$B$28,$B52,Données!$J$15:$J$28)/SUMIF(Données!$B$15:$B$28,$B52,Données!$K$15:$K$28) | L52: =SUMPRODUCT((Données!$B$15:$B$28=$B52)*Données!$J$15:$J$28*Données!$L$15:$L$28)/SUMIF(Données!$B$15:$B$28,$B52,Données!$J$15:$J$28) | M52: =IF(H52<0.08,"FRAGILE","")
B53: TUNON_LYO | C53: =VLOOKUP($B53,Données!$A$15:$L$28,5,0) | D53: =C53/VLOOKUP($B53,Données!$A$15:$L$28,4,0)-1 | E53: =VLOOKUP($B53,Données!$A$15:$L$28,8,0) | F53: =IF(VLOOKUP($B53,Données!$A$15:$L$28,7,0)<=0,"n/s",E53/VLOOKUP($B53,Données!$A$15:$L$28,7,0)-1) | G53: =E53/$E$35 | H53: =E53/C53 | I53: =(H53-VLOOKUP($B53,Données!$A$15:$L$28,7,0)/VLOOKUP($B53,Données!$A$15:$L$28,4,0))*100 | J53: =VLOOKUP($B53,Données!$A$15:$L$28,9,0) | K53: =VLOOKUP($B53,Données!$A$15:$L$28,10,0)/VLOOKUP($B53,Données!$A$15:$L$28,11,0) | L53: =VLOOKUP($B53,Données!$A$15:$L$28,12,0) | M53: =IF(H53<0.08,"FRAGILE","")
B54: TUNON_PAR | C54: =VLOOKUP($B54,Données!$A$15:$L$28,5,0) | D54: =C54/VLOOKUP($B54,Données!$A$15:$L$28,4,0)-1 | E54: =VLOOKUP($B54,Données!$A$15:$L$28,8,0) | F54: =IF(VLOOKUP($B54,Données!$A$15:$L$28,7,0)<=0,"n/s",E54/VLOOKUP($B54,Données!$A$15:$L$28,7,0)-1) | G54: =E54/$E$35 | H54: =E54/C54 | I54: =(H54-VLOOKUP($B54,Données!$A$15:$L$28,7,0)/VLOOKUP($B54,Données!$A$15:$L$28,4,0))*100 | J54: =VLOOKUP($B54,Données!$A$15:$L$28,9,0) | K54: =VLOOKUP($B54,Données!$A$15:$L$28,10,0)/VLOOKUP($B54,Données!$A$15:$L$28,11,0) | L54: =VLOOKUP($B54,Données!$A$15:$L$28,12,0) | M54: =IF(H54<0.08,"FRAGILE","")
B56: Le signal du cockpit. Tunon pèse 8,4 % du CA mais 2,1 % de l'EBITDA. Ipac, le réseau le plus jeune, pèse 11,2 % du CA pour 9,5 % de l'EBITDA — il monte en charge, avec Rennes et Montpellier à 61 % de remplissage. À l'inverse Pigier, la plus petite des cinq, est la plus rentable (21,2 %). Et le groupe n'occupe que 75 % de ses places : 1 032 places ouvertes et vides. Le cadrage 2027 ne peut pas être un « + x % » uniforme.
B60: Source : socle CRM et comptabilité rapprochés · vues V_COCKPIT, V_MOTEUR_CAL, V_ALLOCATION · les marges se lisent en POINTS. Tout le cockpit est en formules : seul l'onglet Données se saisit.
