Workbook

Sheet Données
A1: DONNÉES DU DRILL — grain CLASSE (source : V_ALLOCATION / V_CAMPUS_CLASSE)
A3: Une ligne = une cohorte-classe. Tout remonte exactement au socle campus du cockpit.
A4: Marque | B4: Campus | C4: Programme | D4: Année | E4: Modalité | F4: Nb cl. | G4: Capa. | H4: Places | I4: Effectif | J4: CA 2025 | K4: CA 2026 | L4: Coût variable | M4: Coût direct | N4: Coût siège | O4: EBITDA 2025 | P4: EBITDA 2026 | Q4: Contribution | R4: Coût complet | S4: Marge complète | T4: Inclus | U4: Rang | W4: — membres par niveau — | AC4: Marque | AD4: Campus | AE4: Marque (validation) | AF4: Campus (validation) | AG4: Programme (validation) | AH4: Année d'étude (validation) | AI4: Modalité (validation)
A5: MBway | B5: MBWAY_PAR | C5: BAC_MGT | D5: B1 | E5: ALT | F5: 3 | G5: 32 | H5: =F5*G5 | I5: 92 | J5: 728030 | K5: 780403 | L5: 33396 | M5: 604822 | N5: 44282 | O5: 115427 | P5: =K5-L5-M5 | Q5: =K5-L5 | R5: =L5+M5+N5 | S5: =K5-R5 | T5: =IF(AND(OR(Drill!$C$6="(Tous)",$A5=Drill!$C$6),OR(Drill!$D$6="(Tous)",$B5=Drill!$D$6),OR(Drill!$E$6="(Tous)",$C5=Drill!$E$6),OR(Drill!$F$6="(Tous)",$D5=Drill!$F$6),OR(Drill!$G$6="(Tous)",$E5=Drill!$G$6)),1,0) | U5: =IF(T5=1,SUM($T$5:T5),"") | W5: MBway | X5: MBWAY_PAR | Y5: BAC_COM | Z5: B1 | AA5: ALT | AC5: Marque | AE5: (Tous) | AF5: (Tous) | AG5: (Tous) | AH5: (Tous) | AI5: (Tous)
A6: MBway | B6: MBWAY_PAR | C6: BAC_MGT | D6: B1 | E6: INIT | F6: 1 | G6: 32 | H6: =F6*G6 | I6: 30 | J6: 256371 | K6: 278152 | L6: 10890 | M6: 201607 | N6: 14440 | O6: 54947 | P6: =K6-L6-M6 | Q6: =K6-L6 | R6: =L6+M6+N6 | S6: =K6-R6 | T6: =IF(AND(OR(Drill!$C$6="(Tous)",$A6=Drill!$C$6),OR(Drill!$D$6="(Tous)",$B6=Drill!$D$6),OR(Drill!$E$6="(Tous)",$C6=Drill!$E$6),OR(Drill!$F$6="(Tous)",$D6=Drill!$F$6),OR(Drill!$G$6="(Tous)",$E6=Drill!$G$6)),1,0) | U6: =IF(T6=1,SUM($T$5:T6),"") | W6: Iscom | X6: MBWAY_LYO | Y6: BAC_GES | Z6: B2 | AA6: INIT | AC6: Campus | AE6: MBway | AF6: MBWAY_PAR | AG6: BAC_COM | AH6: B1 | AI6: ALT
A7: MBway | B7: MBWAY_PAR | C7: BAC_MGT | D7: B2 | E7: ALT | F7: 4 | G7: 32 | H7: =F7*G7 | I7: 120 | J7: 927085 | K7: 1017917 | L7: 43560 | M7: 806429 | N7: 57759 | O7: 144758 | P7: =K7-L7-M7 | Q7: =K7-L7 | R7: =L7+M7+N7 | S7: =K7-R7 | T7: =IF(AND(OR(Drill!$C$6="(Tous)",$A7=Drill!$C$6),OR(Drill!$D$6="(Tous)",$B7=Drill!$D$6),OR(Drill!$E$6="(Tous)",$C7=Drill!$E$6),OR(Drill!$F$6="(Tous)",$D7=Drill!$F$6),OR(Drill!$G$6="(Tous)",$E7=Drill!$G$6)),1,0) | U7: =IF(T7=1,SUM($T$5:T7),"") | W7: Pigier | X7: MBWAY_BOR | Y7: BAC_MGT | Z7: B3 | AC7: Programme | AE7: Iscom | AF7: MBWAY_LYO | AG7: BAC_GES | AH7: B2 | AI7: INIT
A8: MBway | B8: MBWAY_PAR | C8: BAC_MGT | D8: B3 | E8: ALT | F8: 3 | G8: 32 | H8: =F8*G8 | I8: 91 | J8: 720117 | K8: 771920 | L8: 33033 | M8: 604822 | N8: 43801 | O8: 108836 | P8: =K8-L8-M8 | Q8: =K8-L8 | R8: =L8+M8+N8 | S8: =K8-R8 | T8: =IF(AND(OR(Drill!$C$6="(Tous)",$A8=Drill!$C$6),OR(Drill!$D$6="(Tous)",$B8=Drill!$D$6),OR(Drill!$E$6="(Tous)",$C8=Drill!$E$6),OR(Drill!$F$6="(Tous)",$D8=Drill!$F$6),OR(Drill!$G$6="(Tous)",$E8=Drill!$G$6)),1,0) | U8: =IF(T8=1,SUM($T$5:T8),"") | W8: Tunon | X8: ISCOM_PAR | Y8: BAC_RH | Z8: M1 | AC8: Année d'étude | AE8: Pigier | AF8: MBWAY_BOR | AG8: BAC_MGT | AH8: B3
A9: MBway | B9: MBWAY_PAR | C9: MAS_MGT | D9: M1 | E9: ALT | F9: 3 | G9: 26 | H9: =F9*G9 | I9: 74 | J9: 659292 | K9: 715304 | L9: 26862 | M9: 523403 | N9: 35618 | O9: 138123 | P9: =K9-L9-M9 | Q9: =K9-L9 | R9: =L9+M9+N9 | S9: =K9-R9 | T9: =IF(AND(OR(Drill!$C$6="(Tous)",$A9=Drill!$C$6),OR(Drill!$D$6="(Tous)",$B9=Drill!$D$6),OR(Drill!$E$6="(Tous)",$C9=Drill!$E$6),OR(Drill!$F$6="(Tous)",$D9=Drill!$F$6),OR(Drill!$G$6="(Tous)",$E9=Drill!$G$6)),1,0) | U9: =IF(T9=1,SUM($T$5:T9),"") | X9: ISCOM_LIL | Y9: BAC_TOU | Z9: M2 | AC9: Modalité | AE9: Tunon | AF9: ISCOM_PAR | AG9: BAC_RH | AH9: M1
A10: MBway | B10: MBWAY_PAR | C10: MAS_MGT | D10: M2 | E10: ALT | F10: 2 | G10: 26 | H10: =F10*G10 | I10: 49 | J10: 431382 | K10: 473647 | L10: 17787 | M10: 348936 | N10: 23585 | O10: 92172 | P10: =K10-L10-M10 | Q10: =K10-L10 | R10: =L10+M10+N10 | S10: =K10-R10 | T10: =IF(AND(OR(Drill!$C$6="(Tous)",$A10=Drill!$C$6),OR(Drill!$D$6="(Tous)",$B10=Drill!$D$6),OR(Drill!$E$6="(Tous)",$C10=Drill!$E$6),OR(Drill!$F$6="(Tous)",$D10=Drill!$F$6),OR(Drill!$G$6="(Tous)",$E10=Drill!$G$6)),1,0) | U10: =IF(T10=1,SUM($T$5:T10),"") | X10: PIGIER_BOR | Y10: BTS_GES | Z10: BTS1 | AF10: ISCOM_LIL | AG10: BAC_TOU | AH10: M2
A11: MBway | B11: MBWAY_PAR | C11: MAS_MKT | D11: M1 | E11: ALT | F11: 1 | G11: 26 | H11: =F11*G11 | I11: 22 | J11: 198386 | K11: 212658 | L11: 7986 | M11: 174468 | N11: 10589 | O11: 24520 | P11: =K11-L11-M11 | Q11: =K11-L11 | R11: =L11+M11+N11 | S11: =K11-R11 | T11: =IF(AND(OR(Drill!$C$6="(Tous)",$A11=Drill!$C$6),OR(Drill!$D$6="(Tous)",$B11=Drill!$D$6),OR(Drill!$E$6="(Tous)",$C11=Drill!$E$6),OR(Drill!$F$6="(Tous)",$D11=Drill!$F$6),OR(Drill!$G$6="(Tous)",$E11=Drill!$G$6)),1,0) | U11: =IF(T11=1,SUM($T$5:T11),"") | X11: PIGIER_LYO | Y11: BTS_TOU | Z11: BTS2 | AF11: PIGIER_BOR | AG11: BTS_GES | AH11: BTS1
A12: MBway | B12: MBWAY_LYO | C12: BAC_MGT | D12: B1 | E12: ALT | F12: 3 | G12: 32 | H12: =F12*G12 | I12: 84 | J12: 670597 | K12: 710733 | L12: 30492 | M12: 573609 | N12: 40431 | O12: 94820 | P12: =K12-L12-M12 | Q12: =K12-L12 | R12: =L12+M12+N12 | S12: =K12-R12 | T12: =IF(AND(OR(Drill!$C$6="(Tous)",$A12=Drill!$C$6),OR(Drill!$D$6="(Tous)",$B12=Drill!$D$6),OR(Drill!$E$6="(Tous)",$C12=Drill!$E$6),OR(Drill!$F$6="(Tous)",$D12=Drill!$F$6),OR(Drill!$G$6="(Tous)",$E12=Drill!$G$6)),1,0) | U12: =IF(T12=1,SUM($T$5:T12),"") | X12: TUNON_PAR | Y12: MAS_COM | AF12: PIGIER_LYO | AG12: BTS_TOU | AH12: BTS2
A13: MBway | B13: MBWAY_LYO | C13: BAC_MGT | D13: B2 | E13: ALT | F13: 3 | G13: 32 | H13: =F13*G13 | I13: 83 | J13: 654662 | K13: 702272 | L13: 30129 | M13: 573609 | N13: 39950 | O13: 90328 | P13: =K13-L13-M13 | Q13: =K13-L13 | R13: =L13+M13+N13 | S13: =K13-R13 | T13: =IF(AND(OR(Drill!$C$6="(Tous)",$A13=Drill!$C$6),OR(Drill!$D$6="(Tous)",$B13=Drill!$D$6),OR(Drill!$E$6="(Tous)",$C13=Drill!$E$6),OR(Drill!$F$6="(Tous)",$D13=Drill!$F$6),OR(Drill!$G$6="(Tous)",$E13=Drill!$G$6)),1,0) | U13: =IF(T13=1,SUM($T$5:T13),"") | X13: TUNON_LYO | Y13: MAS_MGT | AF13: TUNON_PAR | AG13: MAS_COM
A14: MBway | B14: MBWAY_LYO | C14: BAC_MGT | D14: B3 | E14: ALT | F14: 2 | G14: 32 | H14: =F14*G14 | I14: 55 | J14: 428668 | K14: 465361 | L14: 19965 | M14: 382406 | N14: 26473 | O14: 59477 | P14: =K14-L14-M14 | Q14: =K14-L14 | R14: =L14+M14+N14 | S14: =K14-R14 | T14: =IF(AND(OR(Drill!$C$6="(Tous)",$A14=Drill!$C$6),OR(Drill!$D$6="(Tous)",$B14=Drill!$D$6),OR(Drill!$E$6="(Tous)",$C14=Drill!$E$6),OR(Drill!$F$6="(Tous)",$D14=Drill!$F$6),OR(Drill!$G$6="(Tous)",$E14=Drill!$G$6)),1,0) | U14: =IF(T14=1,SUM($T$5:T14),"") | Y14: MAS_MKT | AF14: TUNON_LYO | AG14: MAS_MGT
A15: MBway | B15: MBWAY_LYO | C15: MAS_MGT | D15: M1 | E15: ALT | F15: 3 | G15: 26 | H15: =F15*G15 | I15: 68 | J15: 618613 | K15: 655638 | L15: 24684 | M15: 496392 | N15: 32730 | O15: 119655 | P15: =K15-L15-M15 | Q15: =K15-L15 | R15: =L15+M15+N15 | S15: =K15-R15 | T15: =IF(AND(OR(Drill!$C$6="(Tous)",$A15=Drill!$C$6),OR(Drill!$D$6="(Tous)",$B15=Drill!$D$6),OR(Drill!$E$6="(Tous)",$C15=Drill!$E$6),OR(Drill!$F$6="(Tous)",$D15=Drill!$F$6),OR(Drill!$G$6="(Tous)",$E15=Drill!$G$6)),1,0) | U15: =IF(T15=1,SUM($T$5:T15),"") | AG15: MAS_MKT
A16: MBway | B16: MBWAY_LYO | C16: MAS_MGT | D16: M2 | E16: ALT | F16: 3 | G16: 26 | H16: =F16*G16 | I16: 67 | J16: 602201 | K16: 645996 | L16: 24321 | M16: 496392 | N16: 32249 | O16: 114849 | P16: =K16-L16-M16 | Q16: =K16-L16 | R16: =L16+M16+N16 | S16: =K16-R16 | T16: =IF(AND(OR(Drill!$C$6="(Tous)",$A16=Drill!$C$6),OR(Drill!$D$6="(Tous)",$B16=Drill!$D$6),OR(Drill!$E$6="(Tous)",$C16=Drill!$E$6),OR(Drill!$F$6="(Tous)",$D16=Drill!$F$6),OR(Drill!$G$6="(Tous)",$E16=Drill!$G$6)),1,0) | U16: =IF(T16=1,SUM($T$5:T16),"")
A17: MBway | B17: MBWAY_BOR | C17: BAC_MGT | D17: B1 | E17: ALT | F17: 3 | G17: 32 | H17: =F17*G17 | I17: 80 | J17: 662919 | K17: 694301 | L17: 29040 | M17: 563399 | N17: 38506 | O17: 93340 | P17: =K17-L17-M17 | Q17: =K17-L17 | R17: =L17+M17+N17 | S17: =K17-R17 | T17: =IF(AND(OR(Drill!$C$6="(Tous)",$A17=Drill!$C$6),OR(Drill!$D$6="(Tous)",$B17=Drill!$D$6),OR(Drill!$E$6="(Tous)",$C17=Drill!$E$6),OR(Drill!$F$6="(Tous)",$D17=Drill!$F$6),OR(Drill!$G$6="(Tous)",$E17=Drill!$G$6)),1,0) | U17: =IF(T17=1,SUM($T$5:T17),"")
A18: MBway | B18: MBWAY_BOR | C18: BAC_MGT | D18: B2 | E18: ALT | F18: 3 | G18: 32 | H18: =F18*G18 | I18: 76 | J18: 622215 | K18: 659586 | L18: 27588 | M18: 563399 | N18: 36581 | O18: 64804 | P18: =K18-L18-M18 | Q18: =K18-L18 | R18: =L18+M18+N18 | S18: =K18-R18 | T18: =IF(AND(OR(Drill!$C$6="(Tous)",$A18=Drill!$C$6),OR(Drill!$D$6="(Tous)",$B18=Drill!$D$6),OR(Drill!$E$6="(Tous)",$C18=Drill!$E$6),OR(Drill!$F$6="(Tous)",$D18=Drill!$F$6),OR(Drill!$G$6="(Tous)",$E18=Drill!$G$6)),1,0) | U18: =IF(T18=1,SUM($T$5:T18),"")
A19: MBway | B19: MBWAY_BOR | C19: BAC_MGT | D19: B3 | E19: ALT | F19: 2 | G19: 32 | H19: =F19*G19 | I19: 52 | J19: 420678 | K19: 451295 | L19: 18876 | M19: 375599 | N19: 25029 | O19: 55287 | P19: =K19-L19-M19 | Q19: =K19-L19 | R19: =L19+M19+N19 | S19: =K19-R19 | T19: =IF(AND(OR(Drill!$C$6="(Tous)",$A19=Drill!$C$6),OR(Drill!$D$6="(Tous)",$B19=Drill!$D$6),OR(Drill!$E$6="(Tous)",$C19=Drill!$E$6),OR(Drill!$F$6="(Tous)",$D19=Drill!$F$6),OR(Drill!$G$6="(Tous)",$E19=Drill!$G$6)),1,0) | U19: =IF(T19=1,SUM($T$5:T19),"")
A20: MBway | B20: MBWAY_BOR | C20: MAS_MGT | D20: M1 | E20: ALT | F20: 2 | G20: 26 | H20: =F20*G20 | I20: 47 | J20: 443809 | K20: 464818 | L20: 17061 | M20: 325038 | N20: 22622 | O20: 112453 | P20: =K20-L20-M20 | Q20: =K20-L20 | R20: =L20+M20+N20 | S20: =K20-R20 | T20: =IF(AND(OR(Drill!$C$6="(Tous)",$A20=Drill!$C$6),OR(Drill!$D$6="(Tous)",$B20=Drill!$D$6),OR(Drill!$E$6="(Tous)",$C20=Drill!$E$6),OR(Drill!$F$6="(Tous)",$D20=Drill!$F$6),OR(Drill!$G$6="(Tous)",$E20=Drill!$G$6)),1,0) | U20: =IF(T20=1,SUM($T$5:T20),"")
A21: Iscom | B21: ISCOM_PAR | C21: BAC_COM | D21: B1 | E21: INIT | F21: 2 | G21: 32 | H21: =F21*G21 | I21: 58 | J21: 506547 | K21: 530258 | L21: 21054 | M21: 393118 | N21: 27917 | O21: 104990 | P21: =K21-L21-M21 | Q21: =K21-L21 | R21: =L21+M21+N21 | S21: =K21-R21 | T21: =IF(AND(OR(Drill!$C$6="(Tous)",$A21=Drill!$C$6),OR(Drill!$D$6="(Tous)",$B21=Drill!$D$6),OR(Drill!$E$6="(Tous)",$C21=Drill!$E$6),OR(Drill!$F$6="(Tous)",$D21=Drill!$F$6),OR(Drill!$G$6="(Tous)",$E21=Drill!$G$6)),1,0) | U21: =IF(T21=1,SUM($T$5:T21),"")
A22: Iscom | B22: ISCOM_PAR | C22: BAC_COM | D22: B1 | E22: ALT | F22: 2 | G22: 32 | H22: =F22*G22 | I22: 58 | J22: 457875 | K22: 485129 | L22: 21054 | M22: 393118 | N22: 27917 | O22: 66160 | P22: =K22-L22-M22 | Q22: =K22-L22 | R22: =L22+M22+N22 | S22: =K22-R22 | T22: =IF(AND(OR(Drill!$C$6="(Tous)",$A22=Drill!$C$6),OR(Drill!$D$6="(Tous)",$B22=Drill!$D$6),OR(Drill!$E$6="(Tous)",$C22=Drill!$E$6),OR(Drill!$F$6="(Tous)",$D22=Drill!$F$6),OR(Drill!$G$6="(Tous)",$E22=Drill!$G$6)),1,0) | U22: =IF(T22=1,SUM($T$5:T22),"")
A23: Iscom | B23: ISCOM_PAR | C23: BAC_COM | D23: B2 | E23: ALT | F23: 3 | G23: 32 | H23: =F23*G23 | I23: 86 | J23: 670868 | K23: 719330 | L23: 31218 | M23: 589678 | N23: 41394 | O23: 94533 | P23: =K23-L23-M23 | Q23: =K23-L23 | R23: =L23+M23+N23 | S23: =K23-R23 | T23: =IF(AND(OR(Drill!$C$6="(Tous)",$A23=Drill!$C$6),OR(Drill!$D$6="(Tous)",$B23=Drill!$D$6),OR(Drill!$E$6="(Tous)",$C23=Drill!$E$6),OR(Drill!$F$6="(Tous)",$D23=Drill!$F$6),OR(Drill!$G$6="(Tous)",$E23=Drill!$G$6)),1,0) | U23: =IF(T23=1,SUM($T$5:T23),"")
A24: Iscom | B24: ISCOM_PAR | C24: BAC_COM | D24: B3 | E24: ALT | F24: 3 | G24: 32 | H24: =F24*G24 | I24: 84 | J24: 671184 | K24: 702601 | L24: 30492 | M24: 589678 | N24: 40431 | O24: 74553 | P24: =K24-L24-M24 | Q24: =K24-L24 | R24: =L24+M24+N24 | S24: =K24-R24 | T24: =IF(AND(OR(Drill!$C$6="(Tous)",$A24=Drill!$C$6),OR(Drill!$D$6="(Tous)",$B24=Drill!$D$6),OR(Drill!$E$6="(Tous)",$C24=Drill!$E$6),OR(Drill!$F$6="(Tous)",$D24=Drill!$F$6),OR(Drill!$G$6="(Tous)",$E24=Drill!$G$6)),1,0) | U24: =IF(T24=1,SUM($T$5:T24),"")
A25: Iscom | B25: ISCOM_PAR | C25: MAS_COM | D25: M1 | E25: ALT | F25: 4 | G25: 26 | H25: =F25*G25 | I25: 92 | J25: 827627 | K25: 876890 | L25: 33396 | M25: 680397 | N25: 44282 | O25: 152070 | P25: =K25-L25-M25 | Q25: =K25-L25 | R25: =L25+M25+N25 | S25: =K25-R25 | T25: =IF(AND(OR(Drill!$C$6="(Tous)",$A25=Drill!$C$6),OR(Drill!$D$6="(Tous)",$B25=Drill!$D$6),OR(Drill!$E$6="(Tous)",$C25=Drill!$E$6),OR(Drill!$F$6="(Tous)",$D25=Drill!$F$6),OR(Drill!$G$6="(Tous)",$E25=Drill!$G$6)),1,0) | U25: =IF(T25=1,SUM($T$5:T25),"")
A26: Iscom | B26: ISCOM_PAR | C26: MAS_COM | D26: M2 | E26: ALT | F26: 3 | G26: 26 | H26: =F26*G26 | I26: 73 | J26: 648917 | K26: 695793 | L26: 26499 | M26: 510298 | N26: 35137 | O26: 152694 | P26: =K26-L26-M26 | Q26: =K26-L26 | R26: =L26+M26+N26 | S26: =K26-R26 | T26: =IF(AND(OR(Drill!$C$6="(Tous)",$A26=Drill!$C$6),OR(Drill!$D$6="(Tous)",$B26=Drill!$D$6),OR(Drill!$E$6="(Tous)",$C26=Drill!$E$6),OR(Drill!$F$6="(Tous)",$D26=Drill!$F$6),OR(Drill!$G$6="(Tous)",$E26=Drill!$G$6)),1,0) | U26: =IF(T26=1,SUM($T$5:T26),"")
A27: Iscom | B27: ISCOM_LIL | C27: BAC_COM | D27: B1 | E27: INIT | F27: 2 | G27: 32 | H27: =F27*G27 | I27: 52 | J27: 460735 | K27: 473466 | L27: 18876 | M27: 369644 | N27: 25029 | O27: 77211 | P27: =K27-L27-M27 | Q27: =K27-L27 | R27: =L27+M27+N27 | S27: =K27-R27 | T27: =IF(AND(OR(Drill!$C$6="(Tous)",$A27=Drill!$C$6),OR(Drill!$D$6="(Tous)",$B27=Drill!$D$6),OR(Drill!$E$6="(Tous)",$C27=Drill!$E$6),OR(Drill!$F$6="(Tous)",$D27=Drill!$F$6),OR(Drill!$G$6="(Tous)",$E27=Drill!$G$6)),1,0) | U27: =IF(T27=1,SUM($T$5:T27),"")
... A49: Tunon | B49: TUNON_LYO | C49: BTS_TOU | D49: BTS1 | E49: ALT | F49: 1 | G49: 30 | H49: =F49*G49 | I49: 13 | J49: 104765 | K49: 104068 | L49: 4719 | M49: 194787 | N49: 6257 | O49: -52646 | P49: =K49-L49-M49 | Q49: =K49-L49 | R49: =L49+M49+N49 | S49: =K49-R49 | T49: =IF(AND(OR(Drill!$C$6="(Tous)",$A49=Drill!$C$6),OR(Drill!$D$6="(Tous)",$B49=Drill!$D$6),OR(Drill!$E$6="(Tous)",$C49=Drill!$E$6),OR(Drill!$F$6="(Tous)",$D49=Drill!$F$6),OR(Drill!$G$6="(Tous)",$E49=Drill!$G$6)),1,0) | U49: =IF(T49=1,SUM($T$5:T49),"")
A50: TOTAL | H50: =SUM(H5:H49) | I50: =SUM(I5:I49) | J50: =SUM(J5:J49) | K50: =SUM(K5:K49) | L50: =SUM(L5:L49) | M50: =SUM(M5:M49) | N50: =SUM(N5:N49) | O50: =SUM(O5:O49) | ... S50: =SUM(S5:S49)

Sheet Drill
B2: Drill EBITDA — du groupe à la classe | M2: CONTRIBUTION vs COÛT COMPLET
B3: Marque → Campus → Programme → Année d'étude → Modalité · exercice 2026
B5: ① CHEMIN DE DRILL | C5: Marque | D5: Campus | E5: Programme | F5: Année d'étude | G5: Modalité
B6: remets « (Tous) » pour remonter d'un niveau | C6: (Tous) | D6: (Tous) | E6: (Tous) | F6: (Tous) | G6: (Tous) | O6: =5-COUNTIF($C$6:$G$6,"(Tous)")+1
B8: ="② Vous regardez : "&IF($O$6=1,"le GROUPE (tous périmètres)",IF($C$6="(Tous)","",$C$6)&IF($D$6="(Tous)",""," › "&$D$6)&IF($E$6="(Tous)",""," › "&$E$6)&IF($F$6="(Tous)",""," › "&$F$6)&IF($G$6="(Tous)",""," › "&$G$6))
B10: ② NIVEAU COURANT
B11: Agrégat de la sélection | C11: CA 2026 | D11: Δ CA | E11: EBITDA | F11: Marge EBITDA | G11: Contribution | H11: Coût complet | I11: Marge complète | J11: Effectifs | K11: Places | L11: Remplissage | M11: Statut
B12: =IF($O$6=1,"GROUPE",INDEX($C$6:$G$6,$O$6-1)) | C12: =SUMPRODUCT(Données!$T$5:$T$49,Données!$K$5:$K$49) | D12: =C12/SUMPRODUCT(Données!$T$5:$T$49,Données!$J$5:$J$49)-1 | E12: =SUMPRODUCT(Données!$T$5:$T$49,Données!$P$5:$P$49) | F12: =IFERROR(E12/C12,0) | G12: =SUMPRODUCT(Données!$T$5:$T$49,Données!$Q$5:$Q$49) | H12: =SUMPRODUCT(Données!$T$5:$T$49,Données!$R$5:$R$49) | I12: =SUMPRODUCT(Données!$T$5:$T$49,Données!$S$5:$S$49) | J12: =SUMPRODUCT(Données!$T$5:$T$49,Données!$I$5:$I$49) | K12: =SUMPRODUCT(Données!$T$5:$T$49,Données!$H$5:$H$49) | L12: =IFERROR(J12/K12,0) | M12: =IF(E12<0,"DÉFICITAIRE",IF(I12<0,"PIÈGE",IF(L12<0.75,"SOUS-REMPLI","SAIN")))
B14: =" ③ NIVEAU SUIVANT — "&IF($O$6>5,"grain classe atteint, voir le détail ci-dessous",UPPER(INDEX(Données!$AC$5:$AC$9,$O$6)))
B15: Membre | C15: CA 2026 | D15: Δ CA | E15: EBITDA | F15: Marge EBITDA | G15: Contribution | H15: Coût complet | I15: Marge complète | J15: Effectifs | K15: Places | L15: Remplissage | M15: Statut
B16: =IF($O$6>5,"",IFERROR(INDEX(Données!$W$5:$AA$16,1,$O$6),"")) | C16: =IF($B16="","",SUMPRODUCT(Données!$T$5:$T$49*(INDEX(Données!$A$5:$E$49,0,$O$6)=$B16)*Données!$K$5:$K$49)) | D16: =IF(OR($C16="",$C16=0),"",C16/SUMPRODUCT(Données!$T$5:$T$49*(INDEX(Données!$A$5:$E$49,0,$O$6)=$B16)*Données!$J$5:$J$49)-1) | E16: =IF(OR($C16="",$C16=0),"",SUMPRODUCT(Données!$T$5:$T$49*(INDEX(Données!$A$5:$E$49,0,$O$6)=$B16)*Données!$P$5:$P$49)) | F16: =IF(OR($C16="",$C16=0),"",E16/C16) | G16: =IF(OR($C16="",$C16=0),"",SUMPRODUCT(Données!$T$5:$T$49*(INDEX(Données!$A$5:$E$49,0,$O$6)=$B16)*Données!$Q$5:$Q$49)) | H16: =IF(OR($C16="",$C16=0),"",SUMPRODUCT(Données!$T$5:$T$49*(INDEX(Données!$A$5:$E$49,0,$O$6)=$B16)*Données!$R$5:$R$49)) | I16: =IF(OR($C16="",$C16=0),"",SUMPRODUCT(Données!$T$5:$T$49*(INDEX(Données!$A$5:$E$49,0,$O$6)=$B16)*Données!$S$5:$S$49)) | J16: =IF(OR($C16="",$C16=0),"",SUMPRODUCT(Données!$T$5:$T$49*(INDEX(Données!$A$5:$E$49,0,$O$6)=$B16)*Données!$I$5:$I$49)) | K16: =IF(OR($C16="",$C16=0),"",SUMPRODUCT(Données!$T$5:$T$49*(INDEX(Données!$A$5:$E$49,0,$O$6)=$B16)*Données!$H$5:$H$49)) | L16: =IF(OR($C16="",$C16=0),"",J16/K16) | M16: =IF(OR($C16="",$C16=0),"",IF(E16<0,"DÉFICITAIRE",IF(I16<0,"PIÈGE",IF(L16<0.75,"SOUS-REMPLI",""))))
B17: =IF($O$6>5,"",IFERROR(INDEX(Données!$W$5:$AA$16,2,$O$6),"")) | C17: =IF($B17="","",SUMPRODUCT(Données!$T$5:$T$49*(INDEX(Données!$A$5:$E$49,0,$O$6)=$B17)*Données!$K$5:$K$49)) | D17: =IF(OR($C17="",$C17=0),"",C17/SUMPRODUCT(Données!$T$5:$T$49*(INDEX(Données!$A$5:$E$49,0,$O$6)=$B17)*Données!$J$5:$J$49)-1) | E17: =IF(OR($C17="",$C17=0),"",SUMPRODUCT(Données!$T$5:$T$49*(INDEX(Données!$A$5:$E$49,0,$O$6)=$B17)*Données!$P$5:$P$49)) | F17: =IF(OR($C17="",$C17=0),"",E17/C17) | G17: =IF(OR($C17="",$C17=0),"",SUMPRODUCT(Données!$T$5:$T$49*(INDEX(Données!$A$5:$E$49,0,$O$6)=$B17)*Données!$Q$5:$Q$49)) | H17: =IF(OR($C17="",$C17=0),"",SUMPRODUCT(Données!$T$5:$T$49*(INDEX(Données!$A$5:$E$49,0,$O$6)=$B17)*Données!$R$5:$R$49)) | I17: =IF(OR($C17="",$C17=0),"",SUMPRODUCT(Données!$T$5:$T$49*(INDEX(Données!$A$5:$E$49,0,$O$6)=$B17)*Données!$S$5:$S$49)) | J17: =IF(OR($C17="",$C17=0),"",SUMPRODUCT(Données!$T$5:$T$49*(INDEX(Données!$A$5:$E$49,0,$O$6)=$B17)*Données!$I$5:$I$49)) | K17: =IF(OR($C17="",$C17=0),"",SUMPRODUCT(Données!$T$5:$T$49*(INDEX(Données!$A$5:$E$49,0,$O$6)=$B17)*Données!$H$5:$H$49)) | L17: =IF(OR($C17="",$C17=0),"",J17/K17) | M17: =IF(OR($C17="",$C17=0),"",IF(E17<0,"DÉFICITAIRE",IF(I17<0,"PIÈGE",IF(L17<0.75,"SOUS-REMPLI",""))))
B18: =IF($O$6>5,"",IFERROR(INDEX(Données!$W$5:$AA$16,3,$O$6),"")) | C18: =IF($B18="","",SUMPRODUCT(Données!$T$5:$T$49*(INDEX(Données!$A$5:$E$49,0,$O$6)=$B18)*Données!$K$5:$K$49)) | D18: =IF(OR($C18="",$C18=0),"",C18/SUMPRODUCT(Données!$T$5:$T$49*(INDEX(Données!$A$5:$E$49,0,$O$6)=$B18)*Données!$J$5:$J$49)-1) | E18: =IF(OR($C18="",$C18=0),"",SUMPRODUCT(Données!$T$5:$T$49*(INDEX(Données!$A$5:$E$49,0,$O$6)=$B18)*Données!$P$5:$P$49)) | F18: =IF(OR($C18="",$C18=0),"",E18/C18) | G18: =IF(OR($C18="",$C18=0),"",SUMPRODUCT(Données!$T$5:$T$49*(INDEX(Données!$A$5:$E$49,0,$O$6)=$B18)*Données!$Q$5:$Q$49)) | H18: =IF(OR($C18="",$C18=0),"",SUMPRODUCT(Données!$T$5:$T$49*(INDEX(Données!$A$5:$E$49,0,$O$6)=$B18)*Données!$R$5:$R$49)) | I18: =IF(OR($C18="",$C18=0),"",SUMPRODUCT(Données!$T$5:$T$49*(INDEX(Données!$A$5:$E$49,0,$O$6)=$B18)*Données!$S$5:$S$49)) | J18: =IF(OR($C18="",$C18=0),"",SUMPRODUCT(Données!$T$5:$T$49*(INDEX(Données!$A$5:$E$49,0,$O$6)=$B18)*Données!$I$5:$I$49)) | K18: =IF(OR($C18="",$C18=0),"",SUMPRODUCT(Données!$T$5:$T$49*(INDEX(Données!$A$5:$E$49,0,$O$6)=$B18)*Données!$H$5:$H$49)) | L18: =IF(OR($C18="",$C18=0),"",J18/K18) | M18: =IF(OR($C18="",$C18=0),"",IF(E18<0,"DÉFICITAIRE",IF(I18<0,"PIÈGE",IF(L18<0.75,"SOUS-REMPLI",""))))
B19: =IF($O$6>5,"",IFERROR(INDEX(Données!$W$5:$AA$16,4,$O$6),"")) | C19: =IF($B19="","",SUMPRODUCT(Données!$T$5:$T$49*(INDEX(Données!$A$5:$E$49,0,$O$6)=$B19)*Données!$K$5:$K$49)) | D19: =IF(OR($C19="",$C19=0),"",C19/SUMPRODUCT(Données!$T$5:$T$49*(INDEX(Données!$A$5:$E$49,0,$O$6)=$B19)*Données!$J$5:$J$49)-1) | E19: =IF(OR($C19="",$C19=0),"",SUMPRODUCT(Données!$T$5:$T$49*(INDEX(Données!$A$5:$E$49,0,$O$6)=$B19)*Données!$P$5:$P$49)) | F19: =IF(OR($C19="",$C19=0),"",E19/C19) | G19: =IF(OR($C19="",$C19=0),"",SUMPRODUCT(Données!$T$5:$T$49*(INDEX(Données!$A$5:$E$49,0,$O$6)=$B19)*Données!$Q$5:$Q$49)) | H19: =IF(OR($C19="",$C19=0),"",SUMPRODUCT(Données!$T$5:$T$49*(INDEX(Données!$A$5:$E$49,0,$O$6)=$B19)*Données!$R$5:$R$49)) | I19: =IF(OR($C19="",$C19=0),"",SUMPRODUCT(Données!$T$5:$T$49*(INDEX(Données!$A$5:$E$49,0,$O$6)=$B19)*Données!$S$5:$S$49)) | J19: =IF(OR($C19="",$C19=0),"",SUMPRODUCT(Données!$T$5:$T$49*(INDEX(Données!$A$5:$E$49,0,$O$6)=$B19)*Données!$I$5:$I$49)) | K19: =IF(OR($C19="",$C19=0),"",SUMPRODUCT(Données!$T$5:$T$49*(INDEX(Données!$A$5:$E$49,0,$O$6)=$B19)*Données!$H$5:$H$49)) | L19: =IF(OR($C19="",$C19=0),"",J19/K19) | M19: =IF(OR($C19="",$C19=0),"",IF(E19<0,"DÉFICITAIRE",IF(I19<0,"PIÈGE",IF(L19<0.75,"SOUS-REMPLI",""))))
B20: =IF($O$6>5,"",IFERROR(INDEX(Données!$W$5:$AA$16,5,$O$6),"")) | C20: =IF($B20="","",SUMPRODUCT(Données!$T$5:$T$49*(INDEX(Données!$A$5:$E$49,0,$O$6)=$B20)*Données!$K$5:$K$49)) | D20: =IF(OR($C20="",$C20=0),"",C20/SUMPRODUCT(Données!$T$5:$T$49*(INDEX(Données!$A$5:$E$49,0,$O$6)=$B20)*Données!$J$5:$J$49)-1) | E20: =IF(OR($C20="",$C20=0),"",SUMPRODUCT(Données!$T$5:$T$49*(INDEX(Données!$A$5:$E$49,0,$O$6)=$B20)*Données!$P$5:$P$49)) | F20: =IF(OR($C20="",$C20=0),"",E20/C20) | G20: =IF(OR($C20="",$C20=0),"",SUMPRODUCT(Données!$T$5:$T$49*(INDEX(Données!$A$5:$E$49,0,$O$6)=$B20)*Données!$Q$5:$Q$49)) | H20: =IF(OR($C20="",$C20=0),"",SUMPRODUCT(Données!$T$5:$T$49*(INDEX(Données!$A$5:$E$49,0,$O$6)=$B20)*Données!$R$5:$R$49)) | I20: =IF(OR($C20="",$C20=0),"",SUMPRODUCT(Données!$T$5:$T$49*(INDEX(Données!$A$5:$E$49,0,$O$6)=$B20)*Données!$S$5:$S$49)) | J20: =IF(OR($C20="",$C20=0),"",SUMPRODUCT(Données!$T$5:$T$49*(INDEX(Données!$A$5:$E$49,0,$O$6)=$B20)*Données!$I$5:$I$49)) | K20: =IF(OR($C20="",$C20=0),"",SUMPRODUCT(Données!$T$5:$T$49*(INDEX(Données!$A$5:$E$49,0,$O$6)=$B20)*Données!$H$5:$H$49)) | L20: =IF(OR($C20="",$C20=0),"",J20/K20) | M20: =IF(OR($C20="",$C20=0),"",IF(E20<0,"DÉFICITAIRE",IF(I20<0,"PIÈGE",IF(L20<0.75,"SOUS-REMPLI",""))))
B21: =IF($O$6>5,"",IFERROR(INDEX(Données!$W$5:$AA$16,6,$O$6),"")) | C21: =IF($B21="","",SUMPRODUCT(Données!$T$5:$T$49*(INDEX(Données!$A$5:$E$49,0,$O$6)=$B21)*Données!$K$5:$K$49)) | D21: =IF(OR($C21="",$C21=0),"",C21/SUMPRODUCT(Données!$T$5:$T$49*(INDEX(Données!$A$5:$E$49,0,$O$6)=$B21)*Données!$J$5:$J$49)-1) | E21: =IF(OR($C21="",$C21=0),"",SUMPRODUCT(Données!$T$5:$T$49*(INDEX(Données!$A$5:$E$49,0,$O$6)=$B21)*Données!$P$5:$P$49)) | F21: =IF(OR($C21="",$C21=0),"",E21/C21) | G21: =IF(OR($C21="",$C21=0),"",SUMPRODUCT(Données!$T$5:$T$49*(INDEX(Données!$A$5:$E$49,0,$O$6)=$B21)*Données!$Q$5:$Q$49)) | H21: =IF(OR($C21="",$C21=0),"",SUMPRODUCT(Données!$T$5:$T$49*(INDEX(Données!$A$5:$E$49,0,$O$6)=$B21)*Données!$R$5:$R$49)) | I21: =IF(OR($C21="",$C21=0),"",SUMPRODUCT(Données!$T$5:$T$49*(INDEX(Données!$A$5:$E$49,0,$O$6)=$B21)*Données!$S$5:$S$49)) | J21: =IF(OR($C21="",$C21=0),"",SUMPRODUCT(Données!$T$5:$T$49*(INDEX(Données!$A$5:$E$49,0,$O$6)=$B21)*Données!$I$5:$I$49)) | K21: =IF(OR($C21="",$C21=0),"",SUMPRODUCT(Données!$T$5:$T$49*(INDEX(Données!$A$5:$E$49,0,$O$6)=$B21)*Données!$H$5:$H$49)) | L21: =IF(OR($C21="",$C21=0),"",J21/K21) | M21: =IF(OR($C21="",$C21=0),"",IF(E21<0,"DÉFICITAIRE",IF(I21<0,"PIÈGE",IF(L21<0.75,"SOUS-REMPLI",""))))
B22: =IF($O$6>5,"",IFERROR(INDEX(Données!$W$5:$AA$16,7,$O$6),"")) | C22: =IF($B22="","",SUMPRODUCT(Données!$T$5:$T$49*(INDEX(Données!$A$5:$E$49,0,$O$6)=$B22)*Données!$K$5:$K$49)) | D22: =IF(OR($C22="",$C22=0),"",C22/SUMPRODUCT(Données!$T$5:$T$49*(INDEX(Données!$A$5:$E$49,0,$O$6)=$B22)*Données!$J$5:$J$49)-1) | E22: =IF(OR($C22="",$C22=0),"",SUMPRODUCT(Données!$T$5:$T$49*(INDEX(Données!$A$5:$E$49,0,$O$6)=$B22)*Données!$P$5:$P$49)) | F22: =IF(OR($C22="",$C22=0),"",E22/C22) | G22: =IF(OR($C22="",$C22=0),"",SUMPRODUCT(Données!$T$5:$T$49*(INDEX(Données!$A$5:$E$49,0,$O$6)=$B22)*Données!$Q$5:$Q$49)) | H22: =IF(OR($C22="",$C22=0),"",SUMPRODUCT(Données!$T$5:$T$49*(INDEX(Données!$A$5:$E$49,0,$O$6)=$B22)*Données!$R$5:$R$49)) | I22: =IF(OR($C22="",$C22=0),"",SUMPRODUCT(Données!$T$5:$T$49*(INDEX(Données!$A$5:$E$49,0,$O$6)=$B22)*Données!$S$5:$S$49)) | J22: =IF(OR($C22="",$C22=0),"",SUMPRODUCT(Données!$T$5:$T$49*(INDEX(Données!$A$5:$E$49,0,$O$6)=$B22)*Données!$I$5:$I$49)) | K22: =IF(OR($C22="",$C22=0),"",SUMPRODUCT(Données!$T$5:$T$49*(INDEX(Données!$A$5:$E$49,0,$O$6)=$B22)*Données!$H$5:$H$49)) | L22: =IF(OR($C22="",$C22=0),"",J22/K22) | M22: =IF(OR($C22="",$C22=0),"",IF(E22<0,"DÉFICITAIRE",IF(I22<0,"PIÈGE",IF(L22<0.75,"SOUS-REMPLI",""))))
B23: =IF($O$6>5,"",IFERROR(INDEX(Données!$W$5:$AA$16,8,$O$6),"")) | C23: =IF($B23="","",SUMPRODUCT(Données!$T$5:$T$49*(INDEX(Données!$A$5:$E$49,0,$O$6)=$B23)*Données!$K$5:$K$49)) | D23: =IF(OR($C23="",$C23=0),"",C23/SUMPRODUCT(Données!$T$5:$T$49*(INDEX(Données!$A$5:$E$49,0,$O$6)=$B23)*Données!$J$5:$J$49)-1) | E23: =IF(OR($C23="",$C23=0),"",SUMPRODUCT(Données!$T$5:$T$49*(INDEX(Données!$A$5:$E$49,0,$O$6)=$B23)*Données!$P$5:$P$49)) | F23: =IF(OR($C23="",$C23=0),"",E23/C23) | G23: =IF(OR($C23="",$C23=0),"",SUMPRODUCT(Données!$T$5:$T$49*(INDEX(Données!$A$5:$E$49,0,$O$6)=$B23)*Données!$Q$5:$Q$49)) | H23: =IF(OR($C23="",$C23=0),"",SUMPRODUCT(Données!$T$5:$T$49*(INDEX(Données!$A$5:$E$49,0,$O$6)=$B23)*Données!$R$5:$R$49)) | I23: =IF(OR($C23="",$C23=0),"",SUMPRODUCT(Données!$T$5:$T$49*(INDEX(Données!$A$5:$E$49,0,$O$6)=$B23)*Données!$S$5:$S$49)) | J23: =IF(OR($C23="",$C23=0),"",SUMPRODUCT(Données!$T$5:$T$49*(INDEX(Données!$A$5:$E$49,0,$O$6)=$B23)*Données!$I$5:$I$49)) | K23: =IF(OR($C23="",$C23=0),"",SUMPRODUCT(Données!$T$5:$T$49*(INDEX(Données!$A$5:$E$49,0,$O$6)=$B23)*Données!$H$5:$H$49)) | L23: =IF(OR($C23="",$C23=0),"",J23/K23) | M23: =IF(OR($C23="",$C23=0),"",IF(E23<0,"DÉFICITAIRE",IF(I23<0,"PIÈGE",IF(L23<0.75,"SOUS-REMPLI",""))))
B24: =IF($O$6>5,"",IFERROR(INDEX(Données!$W$5:$AA$16,9,$O$6),"")) | C24: =IF($B24="","",SUMPRODUCT(Données!$T$5:$T$49*(INDEX(Données!$A$5:$E$49,0,$O$6)=$B24)*Données!$K$5:$K$49)) | D24: =IF(OR($C24="",$C24=0),"",C24/SUMPRODUCT(Données!$T$5:$T$49*(INDEX(Données!$A$5:$E$49,0,$O$6)=$B24)*Données!$J$5:$J$49)-1) | E24: =IF(OR($C24="",$C24=0),"",SUMPRODUCT(Données!$T$5:$T$49*(INDEX(Données!$A$5:$E$49,0,$O$6)=$B24)*Données!$P$5:$P$49)) | F24: =IF(OR($C24="",$C24=0),"",E24/C24) | G24: =IF(OR($C24="",$C24=0),"",SUMPRODUCT(Données!$T$5:$T$49*(INDEX(Données!$A$5:$E$49,0,$O$6)=$B24)*Données!$Q$5:$Q$49)) | H24: =IF(OR($C24="",$C24=0),"",SUMPRODUCT(Données!$T$5:$T$49*(INDEX(Données!$A$5:$E$49,0,$O$6)=$B24)*Données!$R$5:$R$49)) | I24: =IF(OR($C24="",$C24=0),"",SUMPRODUCT(Données!$T$5:$T$49*(INDEX(Données!$A$5:$E$49,0,$O$6)=$B24)*Données!$S$5:$S$49)) | J24: =IF(OR($C24="",$C24=0),"",SUMPRODUCT(Données!$T$5:$T$49*(INDEX(Données!$A$5:$E$49,0,$O$6)=$B24)*Données!$I$5:$I$49)) | K24: =IF(OR($C24="",$C24=0),"",SUMPRODUCT(Données!$T$5:$T$49*(INDEX(Données!$A$5:$E$49,0,$O$6)=$B24)*Données!$H$5:$H$49)) | L24: =IF(OR($C24="",$C24=0),"",J24/K24) | M24: =IF(OR($C24="",$C24=0),"",IF(E24<0,"DÉFICITAIRE",IF(I24<0,"PIÈGE",IF(L24<0.75,"SOUS-REMPLI",""))))
B25: =IF($O$6>5,"",IFERROR(INDEX(Données!$W$5:$AA$16,10,$O$6),"")) | C25: =IF($B25="","",SUMPRODUCT(Données!$T$5:$T$49*(INDEX(Données!$A$5:$E$49,0,$O$6)=$B25)*Données!$K$5:$K$49)) | D25: =IF(OR($C25="",$C25=0),"",C25/SUMPRODUCT(Données!$T$5:$T$49*(INDEX(Données!$A$5:$E$49,0,$O$6)=$B25)*Données!$J$5:$J$49)-1) | E25: =IF(OR($C25="",$C25=0),"",SUMPRODUCT(Données!$T$5:$T$49*(INDEX(Données!$A$5:$E$49,0,$O$6)=$B25)*Données!$P$5:$P$49)) | F25: =IF(OR($C25="",$C25=0),"",E25/C25) | G25: =IF(OR($C25="",$C25=0),"",SUMPRODUCT(Données!$T$5:$T$49*(INDEX(Données!$A$5:$E$49,0,$O$6)=$B25)*Données!$Q$5:$Q$49)) | H25: =IF(OR($C25="",$C25=0),"",SUMPRODUCT(Données!$T$5:$T$49*(INDEX(Données!$A$5:$E$49,0,$O$6)=$B25)*Données!$R$5:$R$49)) | I25: =IF(OR($C25="",$C25=0),"",SUMPRODUCT(Données!$T$5:$T$49*(INDEX(Données!$A$5:$E$49,0,$O$6)=$B25)*Données!$S$5:$S$49)) | J25: =IF(OR($C25="",$C25=0),"",SUMPRODUCT(Données!$T$5:$T$49*(INDEX(Données!$A$5:$E$49,0,$O$6)=$B25)*Données!$I$5:$I$49)) | K25: =IF(OR($C25="",$C25=0),"",SUMPRODUCT(Données!$T$5:$T$49*(INDEX(Données!$A$5:$E$49,0,$O$6)=$B25)*Données!$H$5:$H$49)) | L25: =IF(OR($C25="",$C25=0),"",J25/K25) | M25: =IF(OR($C25="",$C25=0),"",IF(E25<0,"DÉFICITAIRE",IF(I25<0,"PIÈGE",IF(L25<0.75,"SOUS-REMPLI",""))))
B26: =IF($O$6>5,"",IFERROR(INDEX(Données!$W$5:$AA$16,11,$O$6),"")) | C26: =IF($B26="","",SUMPRODUCT(Données!$T$5:$T$49*(INDEX(Données!$A$5:$E$49,0,$O$6)=$B26)*Données!$K$5:$K$49)) | D26: =IF(OR($C26="",$C26=0),"",C26/SUMPRODUCT(Données!$T$5:$T$49*(INDEX(Données!$A$5:$E$49,0,$O$6)=$B26)*Données!$J$5:$J$49)-1) | E26: =IF(OR($C26="",$C26=0),"",SUMPRODUCT(Données!$T$5:$T$49*(INDEX(Données!$A$5:$E$49,0,$O$6)=$B26)*Données!$P$5:$P$49)) | F26: =IF(OR($C26="",$C26=0),"",E26/C26) | G26: =IF(OR($C26="",$C26=0),"",SUMPRODUCT(Données!$T$5:$T$49*(INDEX(Données!$A$5:$E$49,0,$O$6)=$B26)*Données!$Q$5:$Q$49)) | H26: =IF(OR($C26="",$C26=0),"",SUMPRODUCT(Données!$T$5:$T$49*(INDEX(Données!$A$5:$E$49,0,$O$6)=$B26)*Données!$R$5:$R$49)) | I26: =IF(OR($C26="",$C26=0),"",SUMPRODUCT(Données!$T$5:$T$49*(INDEX(Données!$A$5:$E$49,0,$O$6)=$B26)*Données!$S$5:$S$49)) | J26: =IF(OR($C26="",$C26=0),"",SUMPRODUCT(Données!$T$5:$T$49*(INDEX(Données!$A$5:$E$49,0,$O$6)=$B26)*Données!$I$5:$I$49)) | K26: =IF(OR($C26="",$C26=0),"",SUMPRODUCT(Données!$T$5:$T$49*(INDEX(Données!$A$5:$E$49,0,$O$6)=$B26)*Données!$H$5:$H$49)) | L26: =IF(OR($C26="",$C26=0),"",J26/K26) | M26: =IF(OR($C26="",$C26=0),"",IF(E26<0,"DÉFICITAIRE",IF(I26<0,"PIÈGE",IF(L26<0.75,"SOUS-REMPLI",""))))
B27: =IF($O$6>5,"",IFERROR(INDEX(Données!$W$5:$AA$16,12,$O$6),"")) | C27: =IF($B27="","",SUMPRODUCT(Données!$T$5:$T$49*(INDEX(Données!$A$5:$E$49,0,$O$6)=$B27)*Données!$K$5:$K$49)) | D27: =IF(OR($C27="",$C27=0),"",C27/SUMPRODUCT(Données!$T$5:$T$49*(INDEX(Données!$A$5:$E$49,0,$O$6)=$B27)*Données!$J$5:$J$49)-1) | E27: =IF(OR($C27="",$C27=0),"",SUMPRODUCT(Données!$T$5:$T$49*(INDEX(Données!$A$5:$E$49,0,$O$6)=$B27)*Données!$P$5:$P$49)) | F27: =IF(OR($C27="",$C27=0),"",E27/C27) | G27: =IF(OR($C27="",$C27=0),"",SUMPRODUCT(Données!$T$5:$T$49*(INDEX(Données!$A$5:$E$49,0,$O$6)=$B27)*Données!$Q$5:$Q$49)) | H27: =IF(OR($C27="",$C27=0),"",SUMPRODUCT(Données!$T$5:$T$49*(INDEX(Données!$A$5:$E$49,0,$O$6)=$B27)*Données!$R$5:$R$49)) | I27: =IF(OR($C27="",$C27=0),"",SUMPRODUCT(Données!$T$5:$T$49*(INDEX(Données!$A$5:$E$49,0,$O$6)=$B27)*Données!$S$5:$S$49)) | J27: =IF(OR($C27="",$C27=0),"",SUMPRODUCT(Données!$T$5:$T$49*(INDEX(Données!$A$5:$E$49,0,$O$6)=$B27)*Données!$I$5:$I$49)) | K27: =IF(OR($C27="",$C27=0),"",SUMPRODUCT(Données!$T$5:$T$49*(INDEX(Données!$A$5:$E$49,0,$O$6)=$B27)*Données!$H$5:$H$49)) | L27: =IF(OR($C27="",$C27=0),"",J27/K27) | M27: =IF(OR($C27="",$C27=0),"",IF(E27<0,"DÉFICITAIRE",IF(I27<0,"PIÈGE",IF(L27<0.75,"SOUS-REMPLI",""))))
B30: ④ DÉTAIL AU GRAIN CLASSE — le fond du drill
B31: Campus · Programme · Année · Modalité | C31: CA 2026 | D31: Δ CA | E31: EBITDA | F31: Marge EBITDA | G31: Contribution | H31: Coût complet | I31: Marge complète | J31: Effectifs | K31: Places | L31: Remplissage | M31: Statut
B32: =IF($N32="","",INDEX(Données!$B$5:$B$49,$N32)&" · "&INDEX(Données!$C$5:$C$49,$N32)&" · "&INDEX(Données!$D$5:$D$49,$N32)&" · "&INDEX(Données!$E$5:$E$49,$N32)) | C32: =IF($N32="","",INDEX(Données!$K$5:$K$49,$N32)) | D32: =IF($N32="","",C32/INDEX(Données!$J$5:$J$49,$N32)-1) | E32: =IF($N32="","",INDEX(Données!$P$5:$P$49,$N32)) | F32: =IF($N32="","",E32/C32) | G32: =IF($N32="","",INDEX(Données!$Q$5:$Q$49,$N32)) | H32: =IF($N32="","",INDEX(Données!$R$5:$R$49,$N32)) | I32: =IF($N32="","",INDEX(Données!$S$5:$S$49,$N32)) | J32: =IF($N32="","",INDEX(Données!$I$5:$I$49,$N32)) | K32: =IF($N32="","",INDEX(Données!$H$5:$H$49,$N32)) | L32: =IF($N32="","",J32/K32) | M32: =IF($N32="","",IF(E32<0,"DÉFICITAIRE",IF(I32<0,"PIÈGE",IF(L32<0.75,"SOUS-REMPLI","")))) | N32: =IFERROR(MATCH(1,Données!$U$5:$U$49,0),"")
B33: =IF($N33="","",INDEX(Données!$B$5:$B$49,$N33)&" · "&INDEX(Données!$C$5:$C$49,$N33)&" · "&INDEX(Données!$D$5:$D$49,$N33)&" · "&INDEX(Données!$E$5:$E$49,$N33)) | C33: =IF($N33="","",INDEX(Données!$K$5:$K$49,$N33)) | D33: =IF($N33="","",C33/INDEX(Données!$J$5:$J$49,$N33)-1) | E33: =IF($N33="","",INDEX(Données!$P$5:$P$49,$N33)) | F33: =IF($N33="","",E33/C33) | G33: =IF($N33="","",INDEX(Données!$Q$5:$Q$49,$N33)) | H33: =IF($N33="","",INDEX(Données!$R$5:$R$49,$N33)) | I33: =IF($N33="","",INDEX(Données!$S$5:$S$49,$N33)) | J33: =IF($N33="","",INDEX(Données!$I$5:$I$49,$N33)) | K33: =IF($N33="","",INDEX(Données!$H$5:$H$49,$N33)) | L33: =IF($N33="","",J33/K33) | M33: =IF($N33="","",IF(E33<0,"DÉFICITAIRE",IF(I33<0,"PIÈGE",IF(L33<0.75,"SOUS-REMPLI","")))) | N33: =IFERROR(MATCH(2,Données!$U$5:$U$49,0),"")
B34: =IF($N34="","",INDEX(Données!$B$5:$B$49,$N34)&" · "&INDEX(Données!$C$5:$C$49,$N34)&" · "&INDEX(Données!$D$5:$D$49,$N34)&" · "&INDEX(Données!$E$5:$E$49,$N34)) | C34: =IF($N34="","",INDEX(Données!$K$5:$K$49,$N34)) | D34: =IF($N34="","",C34/INDEX(Données!$J$5:$J$49,$N34)-1) | E34: =IF($N34="","",INDEX(Données!$P$5:$P$49,$N34)) | F34: =IF($N34="","",E34/C34) | G34: =IF($N34="","",INDEX(Données!$Q$5:$Q$49,$N34)) | H34: =IF($N34="","",INDEX(Données!$R$5:$R$49,$N34)) | I34: =IF($N34="","",INDEX(Données!$S$5:$S$49,$N34)) | J34: =IF($N34="","",INDEX(Données!$I$5:$I$49,$N34)) | K34: =IF($N34="","",INDEX(Données!$H$5:$H$49,$N34)) | L34: =IF($N34="","",J34/K34) | M34: =IF($N34="","",IF(E34<0,"DÉFICITAIRE",IF(I34<0,"PIÈGE",IF(L34<0.75,"SOUS-REMPLI","")))) | N34: =IFERROR(MATCH(3,Données!$U$5:$U$49,0),"")
B35: =IF($N35="","",INDEX(Données!$B$5:$B$49,$N35)&" · "&INDEX(Données!$C$5:$C$49,$N35)&" · "&INDEX(Données!$D$5:$D$49,$N35)&" · "&INDEX(Données!$E$5:$E$49,$N35)) | C35: =IF($N35="","",INDEX(Données!$K$5:$K$49,$N35)) | D35: =IF($N35="","",C35/INDEX(Données!$J$5:$J$49,$N35)-1) | E35: =IF($N35="","",INDEX(Données!$P$5:$P$49,$N35)) | F35: =IF($N35="","",E35/C35) | G35: =IF($N35="","",INDEX(Données!$Q$5:$Q$49,$N35)) | H35: =IF($N35="","",INDEX(Données!$R$5:$R$49,$N35)) | I35: =IF($N35="","",INDEX(Données!$S$5:$S$49,$N35)) | J35: =IF($N35="","",INDEX(Données!$I$5:$I$49,$N35)) | K35: =IF($N35="","",INDEX(Données!$H$5:$H$49,$N35)) | L35: =IF($N35="","",J35/K35) | M35: =IF($N35="","",IF(E35<0,"DÉFICITAIRE",IF(I35<0,"PIÈGE",IF(L35<0.75,"SOUS-REMPLI","")))) | N35: =IFERROR(MATCH(4,Données!$U$5:$U$49,0),"")
B36: =IF($N36="","",INDEX(Données!$B$5:$B$49,$N36)&" · "&INDEX(Données!$C$5:$C$49,$N36)&" · "&INDEX(Données!$D$5:$D$49,$N36)&" · "&INDEX(Données!$E$5:$E$49,$N36)) | C36: =IF($N36="","",INDEX(Données!$K$5:$K$49,$N36)) | D36: =IF($N36="","",C36/INDEX(Données!$J$5:$J$49,$N36)-1) | E36: =IF($N36="","",INDEX(Données!$P$5:$P$49,$N36)) | F36: =IF($N36="","",E36/C36) | G36: =IF($N36="","",INDEX(Données!$Q$5:$Q$49,$N36)) | H36: =IF($N36="","",INDEX(Données!$R$5:$R$49,$N36)) | I36: =IF($N36="","",INDEX(Données!$S$5:$S$49,$N36)) | J36: =IF($N36="","",INDEX(Données!$I$5:$I$49,$N36)) | K36: =IF($N36="","",INDEX(Données!$H$5:$H$49,$N36)) | L36: =IF($N36="","",J36/K36) | M36: =IF($N36="","",IF(E36<0,"DÉFICITAIRE",IF(I36<0,"PIÈGE",IF(L36<0.75,"SOUS-REMPLI","")))) | N36: =IFERROR(MATCH(5,Données!$U$5:$U$49,0),"")
B37: =IF($N37="","",INDEX(Données!$B$5:$B$49,$N37)&" · "&INDEX(Données!$C$5:$C$49,$N37)&" · "&INDEX(Données!$D$5:$D$49,$N37)&" · "&INDEX(Données!$E$5:$E$49,$N37)) | C37: =IF($N37="","",INDEX(Données!$K$5:$K$49,$N37)) | D37: =IF($N37="","",C37/INDEX(Données!$J$5:$J$49,$N37)-1) | E37: =IF($N37="","",INDEX(Données!$P$5:$P$49,$N37)) | F37: =IF($N37="","",E37/C37) | G37: =IF($N37="","",INDEX(Données!$Q$5:$Q$49,$N37)) | H37: =IF($N37="","",INDEX(Données!$R$5:$R$49,$N37)) | I37: =IF($N37="","",INDEX(Données!$S$5:$S$49,$N37)) | J37: =IF($N37="","",INDEX(Données!$I$5:$I$49,$N37)) | K37: =IF($N37="","",INDEX(Données!$H$5:$H$49,$N37)) | L37: =IF($N37="","",J37/K37) | M37: =IF($N37="","",IF(E37<0,"DÉFICITAIRE",IF(I37<0,"PIÈGE",IF(L37<0.75,"SOUS-REMPLI","")))) | N37: =IFERROR(MATCH(6,Données!$U$5:$U$49,0),"")
B38: =IF($N38="","",INDEX(Données!$B$5:$B$49,$N38)&" · "&INDEX(Données!$C$5:$C$49,$N38)&" · "&INDEX(Données!$D$5:$D$49,$N38)&" · "&INDEX(Données!$E$5:$E$49,$N38)) | C38: =IF($N38="","",INDEX(Données!$K$5:$K$49,$N38)) | D38: =IF($N38="","",C38/INDEX(Données!$J$5:$J$49,$N38)-1) | E38: =IF($N38="","",INDEX(Données!$P$5:$P$49,$N38)) | F38: =IF($N38="","",E38/C38) | G38: =IF($N38="","",INDEX(Données!$Q$5:$Q$49,$N38)) | H38: =IF($N38="","",INDEX(Données!$R$5:$R$49,$N38)) | I38: =IF($N38="","",INDEX(Données!$S$5:$S$49,$N38)) | J38: =IF($N38="","",INDEX(Données!$I$5:$I$49,$N38)) | K38: =IF($N38="","",INDEX(Données!$H$5:$H$49,$N38)) | L38: =IF($N38="","",J38/K38) | M38: =IF($N38="","",IF(E38<0,"DÉFICITAIRE",IF(I38<0,"PIÈGE",IF(L38<0.75,"SOUS-REMPLI","")))) | N38: =IFERROR(MATCH(7,Données!$U$5:$U$49,0),"")
B39: =IF($N39="","",INDEX(Données!$B$5:$B$49,$N39)&" · "&INDEX(Données!$C$5:$C$49,$N39)&" · "&INDEX(Données!$D$5:$D$49,$N39)&" · "&INDEX(Données!$E$5:$E$49,$N39)) | C39: =IF($N39="","",INDEX(Données!$K$5:$K$49,$N39)) | D39: =IF($N39="","",C39/INDEX(Données!$J$5:$J$49,$N39)-1) | E39: =IF($N39="","",INDEX(Données!$P$5:$P$49,$N39)) | F39: =IF($N39="","",E39/C39) | G39: =IF($N39="","",INDEX(Données!$Q$5:$Q$49,$N39)) | H39: =IF($N39="","",INDEX(Données!$R$5:$R$49,$N39)) | I39: =IF($N39="","",INDEX(Données!$S$5:$S$49,$N39)) | J39: =IF($N39="","",INDEX(Données!$I$5:$I$49,$N39)) | K39: =IF($N39="","",INDEX(Données!$H$5:$H$49,$N39)) | L39: =IF($N39="","",J39/K39) | M39: =IF($N39="","",IF(E39<0,"DÉFICITAIRE",IF(I39<0,"PIÈGE",IF(L39<0.75,"SOUS-REMPLI","")))) | N39: =IFERROR(MATCH(8,Données!$U$5:$U$49,0),"")
B40: =IF($N40="","",INDEX(Données!$B$5:$B$49,$N40)&" · "&INDEX(Données!$C$5:$C$49,$N40)&" · "&INDEX(Données!$D$5:$D$49,$N40)&" · "&INDEX(Données!$E$5:$E$49,$N40)) | C40: =IF($N40="","",INDEX(Données!$K$5:$K$49,$N40)) | D40: =IF($N40="","",C40/INDEX(Données!$J$5:$J$49,$N40)-1) | E40: =IF($N40="","",INDEX(Données!$P$5:$P$49,$N40)) | F40: =IF($N40="","",E40/C40) | G40: =IF($N40="","",INDEX(Données!$Q$5:$Q$49,$N40)) | H40: =IF($N40="","",INDEX(Données!$R$5:$R$49,$N40)) | I40: =IF($N40="","",INDEX(Données!$S$5:$S$49,$N40)) | J40: =IF($N40="","",INDEX(Données!$I$5:$I$49,$N40)) | K40: =IF($N40="","",INDEX(Données!$H$5:$H$49,$N40)) | L40: =IF($N40="","",J40/K40) | M40: =IF($N40="","",IF(E40<0,"DÉFICITAIRE",IF(I40<0,"PIÈGE",IF(L40<0.75,"SOUS-REMPLI","")))) | N40: =IFERROR(MATCH(9,Données!$U$5:$U$49,0),"")
B41: =IF($N41="","",INDEX(Données!$B$5:$B$49,$N41)&" · "&INDEX(Données!$C$5:$C$49,$N41)&" · "&INDEX(Données!$D$5:$D$49,$N41)&" · "&INDEX(Données!$E$5:$E$49,$N41)) | C41: =IF($N41="","",INDEX(Données!$K$5:$K$49,$N41)) | D41: =IF($N41="","",C41/INDEX(Données!$J$5:$J$49,$N41)-1) | E41: =IF($N41="","",INDEX(Données!$P$5:$P$49,$N41)) | F41: =IF($N41="","",E41/C41) | G41: =IF($N41="","",INDEX(Données!$Q$5:$Q$49,$N41)) | H41: =IF($N41="","",INDEX(Données!$R$5:$R$49,$N41)) | I41: =IF($N41="","",INDEX(Données!$S$5:$S$49,$N41)) | J41: =IF($N41="","",INDEX(Données!$I$5:$I$49,$N41)) | K41: =IF($N41="","",INDEX(Données!$H$5:$H$49,$N41)) | L41: =IF($N41="","",J41/K41) | M41: =IF($N41="","",IF(E41<0,"DÉFICITAIRE",IF(I41<0,"PIÈGE",IF(L41<0.75,"SOUS-REMPLI","")))) | N41: =IFERROR(MATCH(10,Données!$U$5:$U$49,0),"")
B42: =IF($N42="","",INDEX(Données!$B$5:$B$49,$N42)&" · "&INDEX(Données!$C$5:$C$49,$N42)&" · "&INDEX(Données!$D$5:$D$49,$N42)&" · "&INDEX(Données!$E$5:$E$49,$N42)) | C42: =IF($N42="","",INDEX(Données!$K$5:$K$49,$N42)) | D42: =IF($N42="","",C42/INDEX(Données!$J$5:$J$49,$N42)-1) | E42: =IF($N42="","",INDEX(Données!$P$5:$P$49,$N42)) | F42: =IF($N42="","",E42/C42) | G42: =IF($N42="","",INDEX(Données!$Q$5:$Q$49,$N42)) | H42: =IF($N42="","",INDEX(Données!$R$5:$R$49,$N42)) | I42: =IF($N42="","",INDEX(Données!$S$5:$S$49,$N42)) | J42: =IF($N42="","",INDEX(Données!$I$5:$I$49,$N42)) | K42: =IF($N42="","",INDEX(Données!$H$5:$H$49,$N42)) | L42: =IF($N42="","",J42/K42) | M42: =IF($N42="","",IF(E42<0,"DÉFICITAIRE",IF(I42<0,"PIÈGE",IF(L42<0.75,"SOUS-REMPLI","")))) | N42: =IFERROR(MATCH(11,Données!$U$5:$U$49,0),"")
B43: =IF($N43="","",INDEX(Données!$B$5:$B$49,$N43)&" · "&INDEX(Données!$C$5:$C$49,$N43)&" · "&INDEX(Données!$D$5:$D$49,$N43)&" · "&INDEX(Données!$E$5:$E$49,$N43)) | C43: =IF($N43="","",INDEX(Données!$K$5:$K$49,$N43)) | D43: =IF($N43="","",C43/INDEX(Données!$J$5:$J$49,$N43)-1) | E43: =IF($N43="","",INDEX(Données!$P$5:$P$49,$N43)) | F43: =IF($N43="","",E43/C43) | G43: =IF($N43="","",INDEX(Données!$Q$5:$Q$49,$N43)) | H43: =IF($N43="","",INDEX(Données!$R$5:$R$49,$N43)) | I43: =IF($N43="","",INDEX(Données!$S$5:$S$49,$N43)) | J43: =IF($N43="","",INDEX(Données!$I$5:$I$49,$N43)) | K43: =IF($N43="","",INDEX(Données!$H$5:$H$49,$N43)) | L43: =IF($N43="","",J43/K43) | M43: =IF($N43="","",IF(E43<0,"DÉFICITAIRE",IF(I43<0,"PIÈGE",IF(L43<0.75,"SOUS-REMPLI","")))) | N43: =IFERROR(MATCH(12,Données!$U$5:$U$49,0),"")
B44: =IF($N44="","",INDEX(Données!$B$5:$B$49,$N44)&" · "&INDEX(Données!$C$5:$C$49,$N44)&" · "&INDEX(Données!$D$5:$D$49,$N44)&" · "&INDEX(Données!$E$5:$E$49,$N44)) | C44: =IF($N44="","",INDEX(Données!$K$5:$K$49,$N44)) | D44: =IF($N44="","",C44/INDEX(Données!$J$5:$J$49,$N44)-1) | E44: =IF($N44="","",INDEX(Données!$P$5:$P$49,$N44)) | F44: =IF($N44="","",E44/C44) | G44: =IF($N44="","",INDEX(Données!$Q$5:$Q$49,$N44)) | H44: =IF($N44="","",INDEX(Données!$R$5:$R$49,$N44)) | I44: =IF($N44="","",INDEX(Données!$S$5:$S$49,$N44)) | J44: =IF($N44="","",INDEX(Données!$I$5:$I$49,$N44)) | K44: =IF($N44="","",INDEX(Données!$H$5:$H$49,$N44)) | L44: =IF($N44="","",J44/K44) | M44: =IF($N44="","",IF(E44<0,"DÉFICITAIRE",IF(I44<0,"PIÈGE",IF(L44<0.75,"SOUS-REMPLI","")))) | N44: =IFERROR(MATCH(13,Données!$U$5:$U$49,0),"")
B45: =IF($N45="","",INDEX(Données!$B$5:$B$49,$N45)&" · "&INDEX(Données!$C$5:$C$49,$N45)&" · "&INDEX(Données!$D$5:$D$49,$N45)&" · "&INDEX(Données!$E$5:$E$49,$N45)) | C45: =IF($N45="","",INDEX(Données!$K$5:$K$49,$N45)) | D45: =IF($N45="","",C45/INDEX(Données!$J$5:$J$49,$N45)-1) | E45: =IF($N45="","",INDEX(Données!$P$5:$P$49,$N45)) | F45: =IF($N45="","",E45/C45) | G45: =IF($N45="","",INDEX(Données!$Q$5:$Q$49,$N45)) | H45: =IF($N45="","",INDEX(Données!$R$5:$R$49,$N45)) | I45: =IF($N45="","",INDEX(Données!$S$5:$S$49,$N45)) | J45: =IF($N45="","",INDEX(Données!$I$5:$I$49,$N45)) | K45: =IF($N45="","",INDEX(Données!$H$5:$H$49,$N45)) | L45: =IF($N45="","",J45/K45) | M45: =IF($N45="","",IF(E45<0,"DÉFICITAIRE",IF(I45<0,"PIÈGE",IF(L45<0.75,"SOUS-REMPLI","")))) | N45: =IFERROR(MATCH(14,Données!$U$5:$U$49,0),"")
B46: =IF($N46="","",INDEX(Données!$B$5:$B$49,$N46)&" · "&INDEX(Données!$C$5:$C$49,$N46)&" · "&INDEX(Données!$D$5:$D$49,$N46)&" · "&INDEX(Données!$E$5:$E$49,$N46)) | C46: =IF($N46="","",INDEX(Données!$K$5:$K$49,$N46)) | D46: =IF($N46="","",C46/INDEX(Données!$J$5:$J$49,$N46)-1) | E46: =IF($N46="","",INDEX(Données!$P$5:$P$49,$N46)) | F46: =IF($N46="","",E46/C46) | G46: =IF($N46="","",INDEX(Données!$Q$5:$Q$49,$N46)) | H46: =IF($N46="","",INDEX(Données!$R$5:$R$49,$N46)) | I46: =IF($N46="","",INDEX(Données!$S$5:$S$49,$N46)) | J46: =IF($N46="","",INDEX(Données!$I$5:$I$49,$N46)) | K46: =IF($N46="","",INDEX(Données!$H$5:$H$49,$N46)) | L46: =IF($N46="","",J46/K46) | M46: =IF($N46="","",IF(E46<0,"DÉFICITAIRE",IF(I46<0,"PIÈGE",IF(L46<0.75,"SOUS-REMPLI","")))) | N46: =IFERROR(MATCH(15,Données!$U$5:$U$49,0),"")
B48: Comment lire. La CONTRIBUTION (CA − coûts évitables : vacataires et achats directs) répond à « que perd-on si on ferme ? ». La MARGE COMPLÈTE (après permanents, structure campus et siège) répond à « cette classe paie-t-elle sa part ? ». Aux niveaux hauts elles disent la même chose. Au grain classe elles se contredisent : « PIÈGE » = contribution positive mais marge complète négative — la fermer coûterait plus cher que la garder, parce que les coûts qu'on lui a affectés, eux, ne disparaissent pas. « DÉFICITAIRE » = son EBITDA lui-même est négatif : elle ne couvre pas ses coûts directs, et là seulement l’arbitrage de fermeture se pose vraiment.
...
