Workbook

Sheet 00_Notice
B2: EDUSERVICES GROUP — Pilotage budgétaire (v2)
B3: Cohortes · marketing mesuré sur l'historique · maille programme×année · cadrage cible · simulateur de décisions
B5: Les feuilles
B6: 01_Cadrage | C6: POSTE DE COMMANDE CFO : cadrage top-down (N-2 · atterrissage · objectif · budget · écart) + leviers %/scénarios + coefficients + graphes
B7: DATA_Referentiel | C7: RÉFÉRENTIEL Tagetik : dimensions CODE · DESCRIPTION · hiérarchies (Entité, Compte, Version, Programme, Année, Modalité, Période)
B8: DATA_Chargement | C8: TABLE DE FAITS Tagetik (format long) : entité×programme×année×modalité × compte × version — structure allouée jusqu'à la classe
B9: 04_Referentiel | C9: Dimensions : entités, comptes (fixe/variable)
B10: 05_Param_Prog_Annee | C10: DONNÉES DE RÉFÉRENCE par programme×année (capacité, heures, taux, pédago, CAC variable, passage)
B11: 06_Historique | C11: Réalisé N-1 par cellule (funnel, cohorte) + historique marketing N-2/N-1 → élasticité mesurée
B12: 07_Structure | C12: Réalisé par campus (loyers, ETP, D&A, m²)
B13: 08_Moteur | C13: Moteur budget par cellule (cohortes, marketing→volume, seuil=point mort)
B14: 09_Allocation | C14: Frais de structure alloués par driver
B15: 10_PnL | C15: P&L consolidé N-1 vs Budget + pont à 4 effets
B16: 11_Simulateur | C16: Décisions ouvrir/fermer/redistribuer (maille PROMO) → EBITDA AVANT → APRÈS
B17: 11b_Mutualisation | C17: Mutualisation inter-sections (maille CAMPUS) : sections économisables & économie potentielle
... B21: 14_Mapping_Tagetik | C21: Passerelle Tagetik
B23: Légende
B24: exemple | C24: Saisie / donnée réelle
B25: exemple | C25: Formule
B26: exemple | C26: Lien inter-feuilles
B27: exemple | C27: Hypothèse à remplir
B29: Marques/campus réels EDUSERVICES ; montants ILLUSTRATIFS calibrés sur des ordres de grandeur sourcés (scolarité 8-11 k€, NPEC ~7-10 k€, marge EBITDA ~20 %, classe ~30). À remplacer par le réel.
B32: Mode d'emploi — par où commencer
B33: 1 | C33: 01_Cadrage : choisis le SCÉNARIO et règle les leviers (%) ; pose l'objectif ; lis l'écart et le reste à trouver. Tout le budget se recalcule.
B34: 2 | C34: 08_Moteur : le budget se construit cellule par cellule (cohortes → marketing→volume → tarif → financement).
B35: 3 | C35: 10_PnL & 13_Simulation : lis le compte de résultat consolidé et les KPIs (Budget vs N-1).
B36: 4 | C36: 01_Cadrage (haut) : l'objectif vs le budget construit donne l'écart ; 12_Sensibilite : quel levier actionner pour combler l'écart.
B37: 5 | C37: 11 / 11b / 11c : simule des décisions (ouvrir / fermer / regrouper / mutualiser) — BAC À SABLE, sans impact sur le budget officiel.
B39: 3 façons d'utiliser le modèle
B40: Construire (bottom-up) | C40: Le budget monte tout seul depuis les drivers et l'historique — aucune saisie de résultat.
B41: Challenger | C41: Un directeur de campus ajuste SES effectifs / curseurs → version bottom-up à confronter au cadrage.
B42: Simuler | C42: Tester une ouverture / fermeture / mutualisation et voir l'impact EBITDA avant de trancher.
B44: 💡 Astuce : survole le TITRE d'un onglet pour lire son OBJET, et une ENTÊTE de colonne pour son explication. 🔵 bleu = à saisir · 🟡 jaune = hypothèse à remplir.

Sheet 01_Cadrage
B2: EDUSERVICES — Cadrage & pilotage TOP-DOWN (poste de commande CFO)
B3: Scénario actif : | D3: Cadrage | E3: ◄ bascule tout le budget
B4: Base de projection : | D4: Atterrissage N | E4: → facteur base : | F4: =IF($D$4="Réalisé N-1",$D$7/$E$7,1) | G4: (le budget construit projette depuis la base retenue)
B5: ① Cadrage top-down — N-2 · réalisé N-1 · atterrissage N · budget construit (base retenue) · objectif · écart | J5: ③ Coefficients stratégiques (marque × campus) — intensité marketing / prix
B6: Indicateur | C6: N-2 (réel) | D6: Réalisé N-1 | E6: Atterrissage N | F6: Budget construit | G6: 🟡 Objectif | H6: Écart | J6: Marque | K6: Ville | L6: Marketing | M6: Prix | N6: Posture | O6: Clé
B7: Chiffre d'affaires | C7: 17957736 | D7: 19035200 | E7: 19986960 | F7: =SUM('08_Moteur'!$AH$3:$AH$60)*$F$4 | G7: 21186178 | H7: =F7-G7 | J7: MBway | K7: Paris | L7: 1.2 | M7: 1 | N7: =IF(L7>=1.15,"Pousser",IF(L7<=0.85,"Défendre","Maintenir")) | O7: =J7&"|"&K7
B8: EBITDA | C8: 2478869 | D8: 2776333 | E8: 2915150 | F8: ='09_Allocation'!J20*$F$4 | G8: 3389788 | H8: =F8-G8 | J8: MBway | K8: Lyon | L8: 1.2 | M8: 1 | N8: =IF(L8>=1.15,"Pousser",IF(L8<=0.85,"Défendre","Maintenir")) | O8: =J8&"|"&K8
B9: Marge EBITDA % | C9: =IFERROR(C8/C7,0) | D9: =IFERROR(D8/D7,0) | E9: =IFERROR(E8/E7,0) | F9: =IFERROR(F8/F7,0) | G9: =IFERROR(G8/G7,0) | H9: =F9-G9 | J9: MBway | K9: Nantes | L9: 1.2 | M9: 1 | N9: =IF(L9>=1.15,"Pousser",IF(L9<=0.85,"Défendre","Maintenir")) | O9: =J9&"|"&K9
J10: MBway | K10: Bordeaux | L10: 1.2 | M10: 1 | N10: =IF(L10>=1.15,"Pousser",IF(L10<=0.85,"Défendre","Maintenir")) | O10: =J10&"|"&K10
B11: RESTE À TROUVER (EBITDA vs objectif) : | F11: =IF(G8-F8>0,G8-F8,0) | G11: =IF(G8-F8>0,"à combler","atteint") | J11: ISCOM | K11: Paris | L11: 1 | M11: 1.2 | N11: =IF(L11>=1.15,"Pousser",IF(L11<=0.85,"Défendre","Maintenir")) | O11: =J11&"|"&K11
J12: ISCOM | K12: Lille | L12: 1 | M12: 1.2 | N12: =IF(L12>=1.15,"Pousser",IF(L12<=0.85,"Défendre","Maintenir")) | O12: =J12&"|"&K12
B13: ② Leviers & hypothèses — varie en % · bascule par scénario (colonne ACTIF = scénario choisi) | J13: ISCOM | K13: Toulouse | L13: 1 | M13: 1.2 | N13: =IF(L13>=1.15,"Pousser",IF(L13<=0.85,"Défendre","Maintenir")) | O13: =J13&"|"&K13
J14: Ipac Bachelor Factory | K14: Nantes | L14: 1.3 | M14: 0.8 | N14: =IF(L14>=1.15,"Pousser",IF(L14<=0.85,"Défendre","Maintenir")) | O14: =J14&"|"&K14
B15: Paramètre | C15: Unité | D15: Base (atterr.) | E15: Cadrage | F15: Optimiste | G15: Prudent | H15: ACTIF | J15: Ipac Bachelor Factory | K15: Rennes | L15: 1.3 | M15: 0.8 | N15: =IF(L15>=1.15,"Pousser",IF(L15<=0.85,"Défendre","Maintenir")) | O15: =J15&"|"&K15
B16: Variation du budget marketing (→ volume) | C16: % | D16: 0 | E16: 0.1 | F16: 0.2 | G16: -0.05 | H16: =INDEX(E16:G16,MATCH($D$3,$E$15:$G$15,0)) | J16: Ipac Bachelor Factory | K16: Montpellier | L16: 1.3 | M16: 0.8 | N16: =IF(L16>=1.15,"Pousser",IF(L16<=0.85,"Défendre","Maintenir")) | O16: =J16&"|"&K16
B17: Hausse tarifaire (prix) | C17: % | D17: 0 | E17: 0.03 | F17: 0.04 | G17: 0.02 | H17: =INDEX(E17:G17,MATCH($D$3,$E$15:$G$15,0)) | J17: Pigier | K17: Lyon | L17: 0.7 | M17: 1 | N17: =IF(L17>=1.15,"Pousser",IF(L17<=0.85,"Défendre","Maintenir")) | O17: =J17&"|"&K17
B18: Gain de conversion admissions | C18: pts | D18: 0 | E18: 0.015 | F18: 0.04 | G18: 0 | H18: =INDEX(E18:G18,MATCH($D$3,$E$15:$G$15,0)) | J18: Pigier | K18: Bordeaux | L18: 0.7 | M18: 1 | N18: =IF(L18>=1.15,"Pousser",IF(L18<=0.85,"Défendre","Maintenir")) | O18: =J18&"|"&K18
B19: Amélioration du taux de passage | C19: pts | D19: 0 | E19: 0.01 | F19: 0.03 | G19: -0.01 | H19: =INDEX(E19:G19,MATCH($D$3,$E$15:$G$15,0)) | J19: Tunon | K19: Paris | L19: 1 | M19: 1.1 | N19: =IF(L19>=1.15,"Pousser",IF(L19<=0.85,"Défendre","Maintenir")) | O19: =J19&"|"&K19
B20: Inflation des charges (groupe) | C20: % | D20: 0 | E20: 0.02 | F20: 0.015 | G20: 0.03 | H20: =INDEX(E20:G20,MATCH($D$3,$E$15:$G$15,0)) | J20: Tunon | K20: Lyon | L20: 1 | M20: 1.1 | N20: =IF(L20>=1.15,"Pousser",IF(L20<=0.85,"Défendre","Maintenir")) | O20: =J20&"|"&K20
B21: Politique salariale (groupe) | C21: % | D21: 0 | E21: 0.025 | F21: 0.02 | G21: 0.03 | H21: =INDEX(E21:G21,MATCH($D$3,$E$15:$G$15,0))
B22: Constantes de référence — base = atterrissage · les 3 scénarios sont SAISISSABLES (€ : variation en % · taux : valeur en %)
B23: Coût chargé / ETP permanent | C23: € | D23: 58000 | E23: 0 | F23: 0 | G23: 0 | H23: =D23*(1+INDEX(E23:G23,MATCH($D$3,$E$15:$G$15,0)))
B24: Frais de dossier / nouvel inscrit | C24: € | D24: 90 | E24: 0 | F24: 0 | G24: 0 | H24: =D24*(1+INDEX(E24:G24,MATCH($D$3,$E$15:$G$15,0)))
B25: Frais de structure & marketing groupe (FIXE) | C25: € | D25: 2000000 | E25: 0 | F25: 0 | G25: 0 | H25: =D25*(1+INDEX(E25:G25,MATCH($D$3,$E$15:$G$15,0)))
B26: Autres charges d'exploitation / étudiant | C26: € | D26: 934 | E26: 0 | F26: 0 | G26: 0 | H26: =D26*(1+INDEX(E26:G26,MATCH($D$3,$E$15:$G$15,0)))
B27: Élasticité marketing (défaut) | C27: x | D27: 0.5 | E27: 0.5 | F27: 0.5 | G27: 0.5 | H27: =INDEX(E27:G27,MATCH($D$3,$E$15:$G$15,0))
B28: Conversion cand.→inscrit (défaut) | C28: % | D28: 0.372 | E28: 0.372 | F28: 0.372 | G28: 0.372 | H28: =INDEX(E28:G28,MATCH($D$3,$E$15:$G$15,0))
B32: Drivers d'allocation de la structure — en cascade (un driver par niveau)
B33: Groupe → MARQUE (par) : | D33: Chiffre d'affaires | E33: ◄ pilote l'allocation par campus (feuille 09)
B34: Marque → CAMPUS (par) : | D34: Effectifs
B35: Campus → PROGRAMME (par) : | D35: Nombre de classes | E35: ◄ pour l'allocation fine à la classe (feuille 11c)

Sheet DATA_Referentiel
B2: RÉFÉRENTIEL DES DIMENSIONS (à charger dans Tagetik) — CODE · DESCRIPTION · HIÉRARCHIE
B4: 1) Dimension ENTITÉ — hiérarchie Groupe → Marque → Campus
B5: Code | C5: Description | D5: Parent | E5: Niveau
B6: EDU | C6: EDUSERVICES (Groupe) | E6: Groupe
B7: MBWAY | C7: MBway | D7: EDU | E7: Marque
B8: ISCOM | C8: ISCOM | D8: EDU | E8: Marque
B9: IPAC | C9: Ipac Bachelor Factory | D9: EDU | E9: Marque
B10: PIGIER | C10: Pigier | D10: EDU | E10: Marque
B11: TUNON | C11: Tunon | D11: EDU | E11: Marque
B12: MBWAY_PAR | C12: MBway Paris | D12: MBWAY | E12: Campus
B13: MBWAY_LYO | C13: MBway Lyon | D13: MBWAY | E13: Campus
B14: MBWAY_NAN | C14: MBway Nantes | D14: MBWAY | E14: Campus
B15: MBWAY_BOR | C15: MBway Bordeaux | D15: MBWAY | E15: Campus
B16: ISCOM_PAR | C16: ISCOM Paris | D16: ISCOM | E16: Campus
B17: ISCOM_LIL | C17: ISCOM Lille | D17: ISCOM | E17: Campus
B18: ISCOM_TLS | C18: ISCOM Toulouse | D18: ISCOM | E18: Campus
... B25: TUNON_LYO | C25: Tunon Lyon | D25: TUNON | E25: Campus
B27: 2) Dimension COMPTE — hiérarchie P&L + statistiques (comptes comptables réels · codes techniques)
B28: Code | C28: Description | D28: Parent | E28: Type | F28: Sens
B29: PL | C29: Compte de résultat | E29: Noeud
B30: CA | C30: Chiffre d'affaires | D30: PL | E30: Noeud | F30: Produit
B31: COUTS_DIR | C31: Coûts directs évitables | D31: PL | E31: Noeud | F31: Charge
B32: STRUCTURE | C32: Structure (non-évitable) | D32: PL | E32: Noeud | F32: Charge
B33: AMORT | C33: Amortissements | D33: PL | E33: Noeud | F33: Charge
B34: STATS | C34: Statistiques (effectifs/flux) | E34: Noeud | F34: Technique
B35: INDUCT | C35: Inducteurs & prix unitaires | E35: Noeud | F35: Technique
B36: 706100 | C36: Droits de scolarité | D36: CA | E36: COMPTABLE | F36: Produit
B37: 708500 | C37: Frais de dossier / inscription | D37: CA | E37: COMPTABLE | F37: Produit
B38: 604100 | C38: Vacations & sous-traitance pédagogique | D38: COUTS_DIR | E38: COMPTABLE | F38: Charge
B39: 606300 | C39: Fournitures & ressources pédagogiques | D39: COUTS_DIR | E39: COMPTABLE | F39: Charge
B40: 623000 | C40: Publicité & marketing (acquisition) | D40: COUTS_DIR | E40: COMPTABLE | F40: Charge
B41: 613200 | C41: Locations immobilières (loyers) | D41: STRUCTURE | E41: COMPTABLE | F41: Charge
B42: 641100 | C42: Rémunérations du personnel permanent | D42: STRUCTURE | E42: COMPTABLE | F42: Charge
B43: 622600 | C43: Honoraires & frais de siège (structure groupe) | D43: STRUCTURE | E43: COMPTABLE | F43: Charge
B44: 606800 | C44: Autres achats & charges externes | D44: COUTS_DIR | E44: COMPTABLE | F44: Charge
B45: 681100 | C45: Dotations aux amortissements | D45: AMORT | E45: COMPTABLE | F45: Charge
B46: STA_EFF | C46: Effectif inscrit | D46: STATS | E46: TECHNIQUE | F46: Technique
B47: STA_CAND | C47: Candidatures reçues | D47: STATS | E47: TECHNIQUE | F47: Technique
... B57: CAC_LEAD | C57: Coût d'acquisition par lead | D57: INDUCT | E57: TECHNIQUE | F57: Technique
B59: 3) Dimension VERSION / SCÉNARIO — code Tagetik (année + type + version)
...

Sheet DATA_Chargement
B1: TABLE DE FAITS À CHARGER DANS TAGETIK — format long (une ligne = un croisement dimension × compte × version)
B2: Codes issus de DATA_Referentiel. Comptable = vrai compte PCG ; technique = code STA_/DRV_/PRX_/CAC_. Structure (loyers, permanents, siège, D&A) DÉJÀ ALLOUÉE jusqu'à la classe (par nb de classes). 3 versions : Réalisé N-2 · Réalisé N-1 · Atterrissage (Forecast V4).
B4: Entité | C4: Programme | D4: Année | E4: Modalité | F4: Compte | G4: Libellé compte | H4: Type | I4: Version | J4: Période | K4: Unité | L4: Montant
B5: MBWAY_PAR | C5: BAC_MGT | D5: B1 | E5: INIT | F5: 706100 | G5: Droits de scolarité | H5: COMPTABLE | I5: 2023ACT_VDEF | J5: 2023 | K5: EUR | L5: 596700
B6: MBWAY_PAR | C6: BAC_MGT | D6: B1 | E6: INIT | F6: 706100 | G6: Droits de scolarité | H6: COMPTABLE | I6: 2024ACT_VDEF | J6: 2024 | K6: EUR | L6: 629850
B7: MBWAY_PAR | C7: BAC_MGT | D7: B1 | E7: INIT | F7: 706100 | G7: Droits de scolarité | H7: COMPTABLE | I7: 2025FCST_V4 | J7: 2025 | K7: EUR | L7: 663000
B8: MBWAY_PAR | C8: BAC_MGT | D8: B1 | E8: INIT | F8: 708500 | G8: Frais de dossier / inscription | H8: COMPTABLE | I8: 2023ACT_VDEF | J8: 2023 | K8: EUR | L8: 6318
B9: MBWAY_PAR | C9: BAC_MGT | D9: B1 | E9: INIT | F9: 708500 | G9: Frais de dossier / inscription | H9: COMPTABLE | I9: 2024ACT_VDEF | J9: 2024 | K9: EUR | L9: 6669
B10: MBWAY_PAR | C10: BAC_MGT | D10: B1 | E10: INIT | F10: 708500 | G10: Frais de dossier / inscription | H10: COMPTABLE | I10: 2025FCST_V4 | J10: 2025 | K10: EUR | L10: 7020
B11: MBWAY_PAR | C11: BAC_MGT | D11: B1 | E11: INIT | F11: 604100 | G11: Vacations & sous-traitance pédagogique | H11: COMPTABLE | I11: 2023ACT_VDEF | J11: 2023 | K11: EUR | L11: 93960
B12: MBWAY_PAR | C12: BAC_MGT | D12: B1 | E12: INIT | F12: 604100 | G12: Vacations & sous-traitance pédagogique | H12: COMPTABLE | I12: 2024ACT_VDEF | J12: 2024 | K12: EUR | L12: 99180
B13: MBWAY_PAR | C13: BAC_MGT | D13: B1 | E13: INIT | F13: 604100 | G13: Vacations & sous-traitance pédagogique | H13: COMPTABLE | I13: 2025FCST_V4 | J13: 2025 | K13: EUR | L13: 104400
B14: MBWAY_PAR | C14: BAC_MGT | D14: B1 | E14: INIT | F14: 606300 | G14: Fournitures & ressources pédagogiques | H14: COMPTABLE | I14: 2023ACT_VDEF | J14: 2023 | K14: EUR | L14: 28080
B15: MBWAY_PAR | C15: BAC_MGT | D15: B1 | E15: INIT | F15: 606300 | G15: Fournitures & ressources pédagogiques | H15: COMPTABLE | I15: 2024ACT_VDEF | J15: 2024 | K15: EUR | L15: 29640
B16: MBWAY_PAR | C16: BAC_MGT | D16: B1 | E16: INIT | F16: 606300 | G16: Fournitures & ressources pédagogiques | H16: COMPTABLE | I16: 2025FCST_V4 | J16: 2025 | K16: EUR | L16: 31200
... B2959: TUNON_LYO | C2959: BAC_TOU | D2959: B3 | E2959: ALT | F2959: PRX_TARIF | G2959: Tarif moyen scolarité | H2959: TECHNIQUE | I2959: 2025FCST_V4 | J2959: 2025 | K2959: EUR | L2959: 8000

Sheet 04_Referentiel
B2: Référentiel — dimensions
B4: Entités : Groupe → Marque → Campus
B5: Marque | C5: Ville | D5: Domaine | E5: Niveau | F5: Devise
B6: EDUSERVICES GROUP | C6: — | D6: Tous | E6: Groupe | F6: EUR
B7: MBway | C7: Paris | D7: Management | E7: Campus | F7: EUR
B8: MBway | C8: Lyon | D8: Management | E8: Campus | F8: EUR
B9: MBway | C9: Nantes | D9: Management | E9: Campus | F9: EUR
B10: MBway | C10: Bordeaux | D10: Management | E10: Campus | F10: EUR
B11: ISCOM | C11: Paris | D11: Communication | E11: Campus | F11: EUR
B12: ISCOM | C12: Lille | D12: Communication | E12: Campus | F12: EUR
B13: ISCOM | C13: Toulouse | D13: Communication | E13: Campus | F13: EUR
B14: Ipac Bachelor Factory | C14: Nantes | D14: Commerce | E14: Campus | F14: EUR
B15: Ipac Bachelor Factory | C15: Rennes | D15: Commerce | E15: Campus | F15: EUR
B16: Ipac Bachelor Factory | C16: Montpellier | D16: Commerce | E16: Campus | F16: EUR
... B20: Tunon | C20: Lyon | D20: Tourisme | E20: Campus | F20: EUR
B22: Comptes (nature fixe/variable)
B23: Compte | C23: Libellé | D23: Rubrique | E23: Nature | F23: Inducteur
B24: 70600 | C24: Scolarité | D24: CA | E24: — | F24: Effectif × tarif
B25: 70800 | C25: Frais de dossier | D25: CA | E25: — | F25: Nouveaux
B26: 64100 | C26: Enseignement | D26: Coût direct | E26: Semi-fixe/classe | F26: Classes × heures
B27: 60700 | C27: Pédagogie | D27: Coût direct | E27: Variable | F27: Effectif
B28: 62300 | C28: Marketing | D28: Coût direct | E28: Variable | F28: Nouveaux / budget
B29: 61300 | C29: Loyers | D29: Structure | E29: Fixe | F29: Campus
B30: 64000 | C30: Personnel permanent | D30: Structure | E30: Fixe | F30: ETP
B31: 65000 | C31: Structure groupe | D31: Structure | E31: Fixe (alloué) | F31: Driver
B32: 68000 | C32: D&A | D32: D&A | E32: Fixe | F32: Campus

Sheet 05_Param_Prog_Annee
A1: Données de référence par programme × année (issues du réalisé — à charger)
A2: Bleu = saisie. Capacité, heures, taux, pédago, CAC variable et taux de passage varient par programme ET par année.
A3: Clé (prog|année) | B3: Programme | C3: Année | D3: Mod. | E3: Capacité | F3: Heures/classe | G3: Taux horaire | H3: Coût pédago/étu | I3: CAC variable | J3: Taux de passage
A4: Bachelor Management|B1 | B4: Bachelor Management | C4: B1 | D4: INIT | E4: 32 | F4: 600 | G4: 58 | H4: 400 | I4: 320
A5: Bachelor Management|B2 | B5: Bachelor Management | C5: B2 | D5: ALT | E5: 32 | F5: 560 | G5: 58 | H5: 400 | I5: 0 | J5: 0.93
A6: Bachelor Management|B3 | B6: Bachelor Management | C6: B3 | D6: ALT | E6: 32 | F6: 520 | G6: 58 | H6: 400 | I6: 0 | J6: 0.95
A7: Mastère Management|M1 | B7: Mastère Management | C7: M1 | D7: ALT | E7: 26 | F7: 480 | G7: 70 | H7: 520 | I7: 600
A8: Mastère Management|M2 | B8: Mastère Management | C8: M2 | D8: ALT | E8: 26 | F8: 440 | G8: 70 | H8: 520 | I8: 0 | J8: 0.96
A9: Bachelor Communication|B1 | B9: Bachelor Communication | C9: B1 | D9: INIT | E9: 32 | F9: 600 | G9: 62 | H9: 550 | I9: 320
A10: Bachelor Communication|B2 | B10: Bachelor Communication | C10: B2 | D10: ALT | E10: 32 | F10: 560 | G10: 62 | H10: 550 | I10: 0 | J10: 0.93
A11: Bachelor Communication|B3 | B11: Bachelor Communication | C11: B3 | D11: ALT | E11: 32 | F11: 520 | G11: 62 | H11: 550 | I11: 0 | J11: 0.95
A12: Mastère Communication|M1 | B12: Mastère Communication | C12: M1 | D12: ALT | E12: 26 | F12: 480 | G12: 74 | H12: 670 | I12: 600
A13: Mastère Communication|M2 | B13: Mastère Communication | C13: M2 | D13: ALT | E13: 26 | F13: 440 | G13: 74 | H13: 670 | I13: 0 | J13: 0.96
A14: Bachelor Commerce|B1 | B14: Bachelor Commerce | C14: B1 | D14: ALT | E14: 32 | F14: 600 | G14: 58 | H14: 380 | I14: 320
A15: Bachelor Commerce|B2 | B15: Bachelor Commerce | C15: B2 | D15: ALT | E15: 32 | F15: 560 | G15: 58 | H15: 380 | I15: 0 | J15: 0.93
A16: Bachelor Commerce|B3 | B16: Bachelor Commerce | C16: B3 | D16: ALT | E16: 32 | F16: 520 | G16: 58 | H16: 380 | I16: 0 | J16: 0.95
A17: BTS Gestion|1 | B17: BTS Gestion | C17: 1 | D17: ALT | E17: 30 | F17: 720 | G17: 55 | H17: 350 | I17: 250
A18: BTS Gestion|2 | B18: BTS Gestion | C18: 2 | D18: ALT | E18: 30 | F18: 680 | G18: 55 | H18: 350 | I18: 0 | J18: 0.94
A19: Bachelor RH|B1 | B19: Bachelor RH | C19: B1 | D19: ALT | E19: 32 | F19: 600 | G19: 58 | H19: 380 | I19: 320
A20: Bachelor RH|B3 | B20: Bachelor RH | C20: B3 | D20: ALT | E20: 32 | F20: 520 | G20: 58 | H20: 380 | I20: 0 | J20: 0.95
A21: Bachelor Tourisme|B1 | B21: Bachelor Tourisme | C21: B1 | D21: ALT | E21: 32 | F21: 600 | G21: 56 | H21: 450 | I21: 320
A22: Bachelor Tourisme|B2 | B22: Bachelor Tourisme | C22: B2 | D22: ALT | E22: 32 | F22: 560 | G22: 56 | H22: 450 | I22: 0 | J22: 0.93
A23: Bachelor Tourisme|B3 | B23: Bachelor Tourisme | C23: B3 | D23: ALT | E23: 32 | F23: 520 | G23: 56 | H23: 450 | I23: 0 | J23: 0.95

Sheet 06_Historique
A1: Réalisé N-1 par cellule (funnel + cohorte)
A3: Marque | B3: Ville | C3: Programme | D3: Type | E3: Année | F3: Mod. | G3: Entrée | H3: Cand N-1 | I3: Nouv N-1 | J3: Réins N-1 | K3: Effectif N-1 | L3: Eff. année inf. N-1 | M3: Tarif N-1 | N3: Classes N-1
A4: MBway | B4: Paris | C4: Bachelor Management | D4: BAC | E4: B1 | F4: INIT | G4: 1 | H4: 210 | I4: 78 | J4: 0 | K4: 78 | L4: 0 | M4: 8500 | N4: 3
A5: MBway | B5: Paris | C5: Bachelor Management | D5: BAC | E5: B2 | F5: ALT | G5: 0 | H5: 0 | I5: 0 | J5: 66 | K5: 66 | L5: 78 | M5: 8000 | N5: 3
A6: MBway | B6: Paris | C6: Bachelor Management | D6: BAC | E6: B3 | F6: ALT | G6: 0 | H6: 0 | I6: 0 | J6: 58 | K6: 58 | L6: 66 | M6: 8000 | N6: 2
A7: MBway | B7: Paris | C7: Mastère Management | D7: MAST | E7: M1 | F7: ALT | G7: 1 | H7: 126 | I7: 47 | J7: 0 | K7: 47 | L7: 0 | M7: 9000 | N7: 2
A8: MBway | B8: Paris | C8: Mastère Management | D8: MAST | E8: M2 | F8: ALT | G8: 0 | H8: 0 | I8: 0 | J8: 42 | K8: 42 | L8: 47 | M8: 9000 | N8: 2
A9: MBway | B9: Lyon | C9: Bachelor Management | D9: BAC | E9: B1 | F9: INIT | G9: 1 | H9: 177 | I9: 66 | J9: 0 | K9: 66 | L9: 0 | M9: 8500 | N9: 3
A10: MBway | B10: Lyon | C10: Bachelor Management | D10: BAC | E10: B2 | F10: ALT | G10: 0 | H10: 0 | I10: 0 | J10: 56 | K10: 56 | L10: 66 | M10: 8000 | N10: 2
A11: MBway | B11: Lyon | C11: Bachelor Management | D11: BAC | E11: B3 | F11: ALT | G11: 0 | H11: 0 | I11: 0 | J11: 50 | K11: 50 | L11: 56 | M11: 8000 | N11: 2
A12: MBway | B12: Lyon | C12: Mastère Management | D12: MAST | E12: M1 | F12: ALT | G12: 1 | H12: 108 | I12: 40 | J12: 0 | K12: 40 | L12: 0 | M12: 9000 | N12: 2
A13: MBway | B13: Lyon | C13: Mastère Management | D13: MAST | E13: M2 | F13: ALT | G13: 0 | H13: 0 | I13: 0 | J13: 36 | K13: 36 | L13: 40 | M13: 9000 | N13: 2
A14: MBway | B14: Nantes | C14: Bachelor Management | D14: BAC | E14: B1 | F14: INIT | G14: 1 | H14: 161 | I14: 60 | J14: 0 | K14: 60 | L14: 0 | M14: 8500 | N14: 2
A15: MBway | B15: Nantes | C15: Bachelor Management | D15: BAC | E15: B2 | F15: ALT | G15: 0 | H15: 0 | I15: 0 | J15: 51 | K15: 51 | L15: 60 | M15: 8000 | N15: 2
... A61: Tunon | B61: Lyon | C61: Bachelor Tourisme | D61: BAC | E61: B3 | F61: ALT | G61: 0 | H61: 0 | I61: 0 | J61: 30 | K61: 30 | L61: 34 | M61: 8000 | N61: 1
A64: Historique marketing par programme (issu du réalisé) → élasticité mesurée
A65: Programme | B65: Cand N-2 | C65: Cand N-1 | D65: Marketing N-2 | E65: Marketing N-1 | F65: Élasticité mesurée
A66: Bachelor Management | B66: 652 | C66: 685 | D66: 74182 | E66: 81600 | F66: =IFERROR((C66/B66-1)/(E66/D66-1),'01_Cadrage'!$H$27)
A67: Mastère Management | B67: 394 | C67: 414 | D67: 84000 | E67: 92400 | F67: =IFERROR((C67/B67-1)/(E67/D67-1),'01_Cadrage'!$H$27)
A68: Bachelor Communication | B68: 432 | C68: 454 | D68: 49164 | E68: 54080 | F68: =IFERROR((C68/B68-1)/(E68/D68-1),'01_Cadrage'!$H$27)
A69: Mastère Communication | B69: 259 | C69: 272 | D69: 55091 | E69: 60600 | F69: =IFERROR((C69/B69-1)/(E69/D69-1),'01_Cadrage'!$H$27)
A70: Bachelor Commerce | B70: 333 | C70: 350 | D70: 37818 | E70: 41600 | F70: =IFERROR((C70/B70-1)/(E70/D70-1),'01_Cadrage'!$H$27)
A71: BTS Gestion | B71: 169 | C71: 177 | D71: 15000 | E71: 16500 | F71: =IFERROR((C71/B71-1)/(E71/D71-1),'01_Cadrage'!$H$27)
A72: Bachelor RH | B72: 210 | C72: 221 | D72: 23855 | E72: 26240 | F72: =IFERROR((C72/B72-1)/(E72/D72-1),'01_Cadrage'!$H$27)
A73: Bachelor Tourisme | B73: 223 | C73: 234 | D73: 25309 | E73: 27840 | F73: =IFERROR((C73/B73-1)/(E73/D73-1),'01_Cadrage'!$H$27)

Sheet 07_Structure
A1: Réalisé N-1 par campus (structure)
A3: Marque | B3: Ville | C3: Effectif N-1 | D3: CA N-1 | E3: Contribution N-1 | F3: Loyer N-1 | G3: ETP perm. | H3: Masse perm. N-1 | I3: D&A N-1 | J3: Surface m² | K3: EBITDA campus N-1
A4: MBway | B4: Paris | C4: 291 | D4: 2467250 | E4: 1624256 | F4: 271000 | G4: 11 | H4: =G4*'01_Cadrage'!$H$23 | I4: 148000 | J4: 2328 | K4: =E4-F4-H4
A5: MBway | B5: Lyon | C5: 248 | D5: 2102540 | E5: 1358988 | F5: 231000 | G5: 9 | H5: =G5*'01_Cadrage'!$H$23 | I5: 126000 | J5: 1984 | K5: =E5-F5-H5
A6: MBway | B6: Nantes | C6: 224 | D6: 1898640 | E6: 1227184 | F6: 209000 | G6: 8 | H6: =G6*'01_Cadrage'!$H$23 | I6: 114000 | J6: 1792 | K6: =E6-F6-H6
A7: MBway | B7: Bordeaux | C7: 191 | D7: 1619880 | E7: 999406 | F7: 178000 | G7: 7 | H7: =G7*'01_Cadrage'!$H$23 | I7: 97000 | J7: 1528 | K7: =E7-F7-H7
A8: ISCOM | B8: Paris | C8: 269 | D8: 2280350 | E8: 1440794 | F8: 251000 | G8: 10 | H8: =G8*'01_Cadrage'!$H$23 | I8: 137000 | J8: 2152 | K8: =E8-F8-H8
A9: ISCOM | B9: Lille | C9: 187 | D9: 1585200 | E9: 922372 | F9: 174000 | G9: 7 | H9: =G9*'01_Cadrage'!$H$23 | I9: 95000 | J9: 1496 | K9: =E9-F9-H9
A10: ISCOM | B10: Toulouse | C10: 175 | D10: 1483250 | E10: 873430 | F10: 163000 | G10: 7 | H10: =G10*'01_Cadrage'!$H$23 | I10: 89000 | J10: 1400 | K10: =E10-F10-H10
A11: Ipac Bachelor Factory | B11: Nantes | C11: 130 | D11: 1044500 | E11: 662800 | F11: 115000 | G11: 5 | H11: =G11*'01_Cadrage'!$H$23 | I11: 63000 | J11: 1040 | K11: =E11-F11-H11
A12: Ipac Bachelor Factory | B12: Rennes | C12: 104 | D12: 835600 | E12: 521424 | F12: 92000 | G12: 4 | H12: =G12*'01_Cadrage'!$H$23 | I12: 50000 | J12: 832 | K12: =E12-F12-H12
A13: Ipac Bachelor Factory | B13: Montpellier | C13: 104 | D13: 835600 | E13: 521424 | F13: 92000 | G13: 4 | H13: =G13*'01_Cadrage'!$H$23 | I13: 50000 | J13: 832 | K13: =E13-F13-H13
A14: Pigier | B14: Lyon | C14: 149 | D14: 1130470 | E14: 628864 | F14: 124000 | G14: 6 | H14: =G14*'01_Cadrage'!$H$23 | I14: 68000 | J14: 1192 | K14: =E14-F14-H14
A15: Pigier | B15: Bordeaux | C15: 117 | D15: 887850 | E15: 540202 | F15: 98000 | G15: 5 | H15: =G15*'01_Cadrage'!$H$23 | I15: 53000 | J15: 936 | K15: =E15-F15-H15
... A17: Tunon | B17: Lyon | C17: 104 | D17: 835600 | E17: 519824 | F17: 92000 | G17: 4 | H17: =G17*'01_Cadrage'!$H$23 | I17: 50000 | J17: 832 | K17: =E17-F17-H17
A18: TOTAL | C18: =SUM(C4:C17) | D18: =SUM(D4:D17) | E18: =SUM(E4:E17) | F18: =SUM(F4:F17) | G18: =SUM(G4:G17) | H18: =SUM(H4:H17) | I18: =SUM(I4:I17) | J18: =SUM(J4:J17) | K18: =SUM(K4:K17)

Sheet 08_Moteur
A1: Moteur de budget par cellule (cohortes · marketing→volume mesuré · seuil=point mort)
A2: Marque | B2: Ville | C2: Programme | D2: Année | E2: Mod | F2: Entrée | G2: Eff N-1 | H2: Nouv N-1 | I2: Réins N-1 | J2: Cand N-1 | K2: EffInf N-1 | L2: Tarif N-1 | M2: Cl N-1 | N2: clé | O2: Cap | P2: Heures | Q2: Taux | R2: Pédago | S2: CACvar | T2: Passage | U2: Coût/cl | V2: cMkt | W2: cPrix | X2: Élast | Y2: Effort | Z2: Cand Bud | AA2: Conv | AB2: Nouv Bud | AC2: Réins Bud | AD2: Effectif Bud | AE2: Tarif Bud | AF2: (réservé) | AG2: (réservé2) | AH2: CA Bud | AI2: Cl besoin | AJ2: Enseign | AK2: Pédago€ | AL2: Mktg | AM2: Contrib | AN2: Rempl | AO2: Contr/étu | AP2: Pt mort
A3: ='06_Historique'!A4 | B3: ='06_Historique'!B4 | C3: ='06_Historique'!C4 | D3: ='06_Historique'!E4 | E3: ='06_Historique'!F4 | F3: ='06_Historique'!G4 | G3: ='06_Historique'!K4 | H3: ='06_Historique'!I4 | I3: ='06_Historique'!J4 | J3: ='06_Historique'!H4 | K3: ='06_Historique'!L4 | L3: ='06_Historique'!M4 | M3: ='06_Historique'!N4 | N3: =C3&"|"&D3 | O3: =INDEX('05_Param_Prog_Annee'!$E$4:$E$23,MATCH(N3,'05_Param_Prog_Annee'!$A$4:$A$23,0)) | P3: =INDEX('05_Param_Prog_Annee'!$F$4:$F$23,MATCH(N3,'05_Param_Prog_Annee'!$A$4:$A$23,0)) | Q3: =INDEX('05_Param_Prog_Annee'!$G$4:$G$23,MATCH(N3,'05_Param_Prog_Annee'!$A$4:$A$23,0)) | R3: =INDEX('05_Param_Prog_Annee'!$H$4:$H$23,MATCH(N3,'05_Param_Prog_Annee'!$A$4:$A$23,0)) | S3: =INDEX('05_Param_Prog_Annee'!$I$4:$I$23,MATCH(N3,'05_Param_Prog_Annee'!$A$4:$A$23,0)) | T3: =IFERROR(INDEX('05_Param_Prog_Annee'!$J$4:$J$23,MATCH(N3,'05_Param_Prog_Annee'!$A$4:$A$23,0)),0) | U3: =P3*Q3*(1+'01_Cadrage'!$H$21) | V3: =INDEX('01_Cadrage'!$L$7:$L$20,MATCH(A3&"|"&B3,'01_Cadrage'!$O$7:$O$20,0)) | W3: =INDEX('01_Cadrage'!$M$7:$M$20,MATCH(A3&"|"&B3,'01_Cadrage'!$O$7:$O$20,0)) | X3: =IFERROR(INDEX('06_Historique'!$F$66:$F$73,MATCH(C3,'06_Historique'!$A$66:$A$73,0)),'01_Cadrage'!$H$27) | Y3: ='01_Cadrage'!$H$16*V3 | Z3: =IF(F3=1,J3*(1+X3*Y3),0) | AA3: =IF(F3=1,IFERROR(H3/J3,'01_Cadrage'!$H$28)+'01_Cadrage'!$H$18,0) | AB3: =Z3*AA3 | AC3: =IF(F3=1,0,K3*(T3+'01_Cadrage'!$H$19)) | AD3: =AB3+AC3 | AE3: =L3*(1+'01_Cadrage'!$H$17*W3) | AF3: =1 | AG3: =1 | AH3: =AD3*AE3*AF3+AB3*'01_Cadrage'!$H$24 | AI3: =IF(AD3<=0,0,MAX(1,ROUNDUP(AD3/O3,0))) | AJ3: =AI3*U3 | AK3: =AD3*R3*(1+'01_Cadrage'!$H$20) | AL3: =H3*S3*(1+Y3) | AM3: =AH3-AJ3-AK3-AL3-AD3*'01_Cadrage'!$H$26*(1+'01_Cadrage'!$H$20) | AN3: =IFERROR(AD3/(AI3*O3),0) | AO3: =IFERROR(AM3/AD3,0) | AP3: =IFERROR(AI3*U3/(AE3*AF3-R3*(1+'01_Cadrage'!$H$20)),0)
A4: ='06_Historique'!A5 | B4: ='06_Historique'!B5 | C4: ='06_Historique'!C5 | D4: ='06_Historique'!E5 | E4: ='06_Historique'!F5 | F4: ='06_Historique'!G5 | G4: ='06_Historique'!K5 | H4: ='06_Historique'!I5 | I4: ='06_Historique'!J5 | J4: ='06_Historique'!H5 | K4: ='06_Historique'!L5 | L4: ='06_Historique'!M5 | M4: ='06_Historique'!N5 | N4: =C4&"|"&D4 | O4: =INDEX('05_Param_Prog_Annee'!$E$4:$E$23,MATCH(N4,'05_Param_Prog_Annee'!$A$4:$A$23,0)) | P4: =INDEX('05_Param_Prog_Annee'!$F$4:$F$23,MATCH(N4,'05_Param_Prog_Annee'!$A$4:$A$23,0)) | Q4: =INDEX('05_Param_Prog_Annee'!$G$4:$G$23,MATCH(N4,'05_Param_Prog_Annee'!$A$4:$A$23,0)) | R4: =INDEX('05_Param_Prog_Annee'!$H$4:$H$23,MATCH(N4,'05_Param_Prog_Annee'!$A$4:$A$23,0)) | S4: =INDEX('05_Param_Prog_Annee'!$I$4:$I$23,MATCH(N4,'05_Param_Prog_Annee'!$A$4:$A$23,0)) | T4: =IFERROR(INDEX('05_Param_Prog_Annee'!$J$4:$J$23,MATCH(N4,'05_Param_Prog_Annee'!$A$4:$A$23,0)),0) | U4: =P4*Q4*(1+'01_Cadrage'!$H$21) | V4: =INDEX('01_Cadrage'!$L$7:$L$20,MATCH(A4&"|"&B4,'01_Cadrage'!$O$7:$O$20,0)) | W4: =INDEX('01_Cadrage'!$M$7:$M$20,MATCH(A4&"|"&B4,'01_Cadrage'!$O$7:$O$20,0)) | X4: =IFERROR(INDEX('06_Historique'!$F$66:$F$73,MATCH(C4,'06_Historique'!$A$66:$A$73,0)),'01_Cadrage'!$H$27) | Y4: ='01_Cadrage'!$H$16*V4 | Z4: =IF(F4=1,J4*(1+X4*Y4),0) | AA4: =IF(F4=1,IFERROR(H4/J4,'01_Cadrage'!$H$28)+'01_Cadrage'!$H$18,0) | AB4: =Z4*AA4 | AC4: =IF(F4=1,0,K4*(T4+'01_Cadrage'!$H$19)) | AD4: =AB4+AC4 | AE4: =L4*(1+'01_Cadrage'!$H$17*W4) | AF4: =1 | AG4: =1 | AH4: =AD4*AE4*AF4+AB4*'01_Cadrage'!$H$24 | AI4: =IF(AD4<=0,0,MAX(1,ROUNDUP(AD4/O4,0))) | AJ4: =AI4*U4 | AK4: =AD4*R4*(1+'01_Cadrage'!$H$20) | AL4: =H4*S4*(1+Y4) | AM4: =AH4-AJ4-AK4-AL4-AD4*'01_Cadrage'!$H$26*(1+'01_Cadrage'!$H$20) | AN4: =IFERROR(AD4/(AI4*O4),0) | AO4: =IFERROR(AM4/AD4,0) | AP4: =IFERROR(AI4*U4/(AE4*AF4-R4*(1+'01_Cadrage'!$H$20)),0)
A5: ='06_Historique'!A6 | B5: ='06_Historique'!B6 | C5: ='06_Historique'!C6 | D5: ='06_Historique'!E6 | E5: ='06_Historique'!F6 | F5: ='06_Historique'!G6 | G5: ='06_Historique'!K6 | H5: ='06_Historique'!I6 | I5: ='06_Historique'!J6 | J5: ='06_Historique'!H6 | K5: ='06_Historique'!L6 | L5: ='06_Historique'!M6 | M5: ='06_Historique'!N6 | N5: =C5&"|"&D5 | O5: =INDEX('05_Param_Prog_Annee'!$E$4:$E$23,MATCH(N5,'05_Param_Prog_Annee'!$A$4:$A$23,0)) | P5: =INDEX('05_Param_Prog_Annee'!$F$4:$F$23,MATCH(N5,'05_Param_Prog_Annee'!$A$4:$A$23,0)) | Q5: =INDEX('05_Param_Prog_Annee'!$G$4:$G$23,MATCH(N5,'05_Param_Prog_Annee'!$A$4:$A$23,0)) | R5: =INDEX('05_Param_Prog_Annee'!$H$4:$H$23,MATCH(N5,'05_Param_Prog_Annee'!$A$4:$A$23,0)) | S5: =INDEX('05_Param_Prog_Annee'!$I$4:$I$23,MATCH(N5,'05_Param_Prog_Annee'!$A$4:$A$23,0)) | T5: =IFERROR(INDEX('05_Param_Prog_Annee'!$J$4:$J$23,MATCH(N5,'05_Param_Prog_Annee'!$A$4:$A$23,0)),0) | U5: =P5*Q5*(1+'01_Cadrage'!$H$21) | V5: =INDEX('01_Cadrage'!$L$7:$L$20,MATCH(A5&"|"&B5,'01_Cadrage'!$O$7:$O$20,0)) | W5: =INDEX('01_Cadrage'!$M$7:$M$20,MATCH(A5&"|"&B5,'01_Cadrage'!$O$7:$O$20,0)) | X5: =IFERROR(INDEX('06_Historique'!$F$66:$F$73,MATCH(C5,'06_Historique'!$A$66:$A$73,0)),'01_Cadrage'!$H$27) | Y5: ='01_Cadrage'!$H$16*V5 | Z5: =IF(F5=1,J5*(1+X5*Y5),0) | AA5: =IF(F5=1,IFERROR(H5/J5,'01_Cadrage'!$H$28)+'01_Cadrage'!$H$18,0) | AB5: =Z5*AA5 | AC5: =IF(F5=1,0,K5*(T5+'01_Cadrage'!$H$19)) | AD5: =AB5+AC5 | AE5: =L5*(1+'01_Cadrage'!$H$17*W5) | AF5: =1 | AG5: =1 | AH5: =AD5*AE5*AF5+AB5*'01_Cadrage'!$H$24 | AI5: =IF(AD5<=0,0,MAX(1,ROUNDUP(AD5/O5,0))) | AJ5: =AI5*U5 | AK5: =AD5*R5*(1+'01_Cadrage'!$H$20) | AL5: =H5*S5*(1+Y5) | AM5: =AH5-AJ5-AK5-AL5-AD5*'01_Cadrage'!$H$26*(1+'01_Cadrage'!$H$20) | AN5: =IFERROR(AD5/(AI5*O5),0) | AO5: =IFERROR(AM5/AD5,0) | AP5: =IFERROR(AI5*U5/(AE5*AF5-R5*(1+'01_Cadrage'!$H$20)),0)
A6: ='06_Historique'!A7 | B6: ='06_Historique'!B7 | C6: ='06_Historique'!C7 | D6: ='06_Historique'!E7 | E6: ='06_Historique'!F7 | F6: ='06_Historique'!G7 | G6: ='06_Historique'!K7 | H6: ='06_Historique'!I7 | I6: ='06_Historique'!J7 | J6: ='06_Historique'!H7 | K6: ='06_Historique'!L7 | L6: ='06_Historique'!M7 | M6: ='06_Historique'!N7 | N6: =C6&"|"&D6 | O6: =INDEX('05_Param_Prog_Annee'!$E$4:$E$23,MATCH(N6,'05_Param_Prog_Annee'!$A$4:$A$23,0)) | P6: =INDEX('05_Param_Prog_Annee'!$F$4:$F$23,MATCH(N6,'05_Param_Prog_Annee'!$A$4:$A$23,0)) | Q6: =INDEX('05_Param_Prog_Annee'!$G$4:$G$23,MATCH(N6,'05_Param_Prog_Annee'!$A$4:$A$23,0)) | R6: =INDEX('05_Param_Prog_Annee'!$H$4:$H$23,MATCH(N6,'05_Param_Prog_Annee'!$A$4:$A$23,0)) | S6: =INDEX('05_Param_Prog_Annee'!$I$4:$I$23,MATCH(N6,'05_Param_Prog_Annee'!$A$4:$A$23,0)) | T6: =IFERROR(INDEX('05_Param_Prog_Annee'!$J$4:$J$23,MATCH(N6,'05_Param_Prog_Annee'!$A$4:$A$23,0)),0) | U6: =P6*Q6*(1+'01_Cadrage'!$H$21) | V6: =INDEX('01_Cadrage'!$L$7:$L$20,MATCH(A6&"|"&B6,'01_Cadrage'!$O$7:$O$20,0)) | W6: =INDEX('01_Cadrage'!$M$7:$M$20,MATCH(A6&"|"&B6,'01_Cadrage'!$O$7:$O$20,0)) | X6: =IFERROR(INDEX('06_Historique'!$F$66:$F$73,MATCH(C6,'06_Historique'!$A$66:$A$73,0)),'01_Cadrage'!$H$27) | Y6: ='01_Cadrage'!$H$16*V6 | Z6: =IF(F6=1,J6*(1+X6*Y6),0) | AA6: =IF(F6=1,IFERROR(H6/J6,'01_Cadrage'!$H$28)+'01_Cadrage'!$H$18,0) | AB6: =Z6*AA6 | AC6: =IF(F6=1,0,K6*(T6+'01_Cadrage'!$H$19)) | AD6: =AB6+AC6 | AE6: =L6*(1+'01_Cadrage'!$H$17*W6) | AF6: =1 | AG6: =1 | AH6: =AD6*AE6*AF6+AB6*'01_Cadrage'!$H$24 | AI6: =IF(AD6<=0,0,MAX(1,ROUNDUP(AD6/O6,0))) | AJ6: =AI6*U6 | AK6: =AD6*R6*(1+'01_Cadrage'!$H$20) | AL6: =H6*S6*(1+Y6) | AM6: =AH6-AJ6-AK6-AL6-AD6*'01_Cadrage'!$H$26*(1+'01_Cadrage'!$H$20) | AN6: =IFERROR(AD6/(AI6*O6),0) | AO6: =IFERROR(AM6/AD6,0) | AP6: =IFERROR(AI6*U6/(AE6*AF6-R6*(1+'01_Cadrage'!$H$20)),0)
A7: ='06_Historique'!A8 | B7: ='06_Historique'!B8 | C7: ='06_Historique'!C8 | D7: ='06_Historique'!E8 | E7: ='06_Historique'!F8 | F7: ='06_Historique'!G8 | G7: ='06_Historique'!K8 | H7: ='06_Historique'!I8 | I7: ='06_Historique'!J8 | J7: ='06_Historique'!H8 | K7: ='06_Historique'!L8 | L7: ='06_Historique'!M8 | M7: ='06_Historique'!N8 | N7: =C7&"|"&D7 | O7: =INDEX('05_Param_Prog_Annee'!$E$4:$E$23,MATCH(N7,'05_Param_Prog_Annee'!$A$4:$A$23,0)) | P7: =INDEX('05_Param_Prog_Annee'!$F$4:$F$23,MATCH(N7,'05_Param_Prog_Annee'!$A$4:$A$23,0)) | Q7: =INDEX('05_Param_Prog_Annee'!$G$4:$G$23,MATCH(N7,'05_Param_Prog_Annee'!$A$4:$A$23,0)) | R7: =INDEX('05_Param_Prog_Annee'!$H$4:$H$23,MATCH(N7,'05_Param_Prog_Annee'!$A$4:$A$23,0)) | S7: =INDEX('05_Param_Prog_Annee'!$I$4:$I$23,MATCH(N7,'05_Param_Prog_Annee'!$A$4:$A$23,0)) | T7: =IFERROR(INDEX('05_Param_Prog_Annee'!$J$4:$J$23,MATCH(N7,'05_Param_Prog_Annee'!$A$4:$A$23,0)),0) | U7: =P7*Q7*(1+'01_Cadrage'!$H$21) | V7: =INDEX('01_Cadrage'!$L$7:$L$20,MATCH(A7&"|"&B7,'01_Cadrage'!$O$7:$O$20,0)) | W7: =INDEX('01_Cadrage'!$M$7:$M$20,MATCH(A7&"|"&B7,'01_Cadrage'!$O$7:$O$20,0)) | X7: =IFERROR(INDEX('06_Historique'!$F$66:$F$73,MATCH(C7,'06_Historique'!$A$66:$A$73,0)),'01_Cadrage'!$H$27) | Y7: ='01_Cadrage'!$H$16*V7 | Z7: =IF(F7=1,J7*(1+X7*Y7),0) | AA7: =IF(F7=1,IFERROR(H7/J7,'01_Cadrage'!$H$28)+'01_Cadrage'!$H$18,0) | AB7: =Z7*AA7 | AC7: =IF(F7=1,0,K7*(T7+'01_Cadrage'!$H$19)) | AD7: =AB7+AC7 | AE7: =L7*(1+'01_Cadrage'!$H$17*W7) | AF7: =1 | AG7: =1 | AH7: =AD7*AE7*AF7+AB7*'01_Cadrage'!$H$24 | AI7: =IF(AD7<=0,0,MAX(1,ROUNDUP(AD7/O7,0))) | AJ7: =AI7*U7 | AK7: =AD7*R7*(1+'01_Cadrage'!$H$20) | AL7: =H7*S7*(1+Y7) | AM7: =AH7-AJ7-AK7-AL7-AD7*'01_Cadrage'!$H$26*(1+'01_Cadrage'!$H$20) | AN7: =IFERROR(AD7/(AI7*O7),0) | AO7: =IFERROR(AM7/AD7,0) | AP7: =IFERROR(AI7*U7/(AE7*AF7-R7*(1+'01_Cadrage'!$H$20)),0)
A8: ='06_Historique'!A9 | B8: ='06_Historique'!B9 | C8: ='06_Historique'!C9 | D8: ='06_Historique'!E9 | E8: ='06_Historique'!F9 | F8: ='06_Historique'!G9 | G8: ='06_Historique'!K9 | H8: ='06_Historique'!I9 | I8: ='06_Historique'!J9 | J8: ='06_Historique'!H9 | K8: ='06_Historique'!L9 | L8: ='06_Historique'!M9 | M8: ='06_Historique'!N9 | N8: =C8&"|"&D8 | O8: =INDEX('05_Param_Prog_Annee'!$E$4:$E$23,MATCH(N8,'05_Param_Prog_Annee'!$A$4:$A$23,0)) | P8: =INDEX('05_Param_Prog_Annee'!$F$4:$F$23,MATCH(N8,'05_Param_Prog_Annee'!$A$4:$A$23,0)) | Q8: =INDEX('05_Param_Prog_Annee'!$G$4:$G$23,MATCH(N8,'05_Param_Prog_Annee'!$A$4:$A$23,0)) | R8: =INDEX('05_Param_Prog_Annee'!$H$4:$H$23,MATCH(N8,'05_Param_Prog_Annee'!$A$4:$A$23,0)) | S8: =INDEX('05_Param_Prog_Annee'!$I$4:$I$23,MATCH(N8,'05_Param_Prog_Annee'!$A$4:$A$23,0)) | T8: =IFERROR(INDEX('05_Param_Prog_Annee'!$J$4:$J$23,MATCH(N8,'05_Param_Prog_Annee'!$A$4:$A$23,0)),0) | U8: =P8*Q8*(1+'01_Cadrage'!$H$21) | V8: =INDEX('01_Cadrage'!$L$7:$L$20,MATCH(A8&"|"&B8,'01_Cadrage'!$O$7:$O$20,0)) | W8: =INDEX('01_Cadrage'!$M$7:$M$20,MATCH(A8&"|"&B8,'01_Cadrage'!$O$7:$O$20,0)) | X8: =IFERROR(INDEX('06_Historique'!$F$66:$F$73,MATCH(C8,'06_Historique'!$A$66:$A$73,0)),'01_Cadrage'!$H$27) | Y8: ='01_Cadrage'!$H$16*V8 | Z8: =IF(F8=1,J8*(1+X8*Y8),0) | AA8: =IF(F8=1,IFERROR(H8/J8,'01_Cadrage'!$H$28)+'01_Cadrage'!$H$18,0) | AB8: =Z8*AA8 | AC8: =IF(F8=1,0,K8*(T8+'01_Cadrage'!$H$19)) | AD8: =AB8+AC8 | AE8: =L8*(1+'01_Cadrage'!$H$17*W8) | AF8: =1 | AG8: =1 | AH8: =AD8*AE8*AF8+AB8*'01_Cadrage'!$H$24 | AI8: =IF(AD8<=0,0,MAX(1,ROUNDUP(AD8/O8,0))) | AJ8: =AI8*U8 | AK8: =AD8*R8*(1+'01_Cadrage'!$H$20) | AL8: =H8*S8*(1+Y8) | AM8: =AH8-AJ8-AK8-AL8-AD8*'01_Cadrage'!$H$26*(1+'01_Cadrage'!$H$20) | AN8: =IFERROR(AD8/(AI8*O8),0) | AO8: =IFERROR(AM8/AD8,0) | AP8: =IFERROR(AI8*U8/(AE8*AF8-R8*(1+'01_Cadrage'!$H$20)),0)
A9: ='06_Historique'!A10 | B9: ='06_Historique'!B10 | C9: ='06_Historique'!C10 | D9: ='06_Historique'!E10 | E9: ='06_Historique'!F10 | F9: ='06_Historique'!G10 | G9: ='06_Historique'!K10 | H9: ='06_Historique'!I10 | I9: ='06_Historique'!J10 | J9: ='06_Historique'!H10 | K9: ='06_Historique'!L10 | L9: ='06_Historique'!M10 | M9: ='06_Historique'!N10 | N9: =C9&"|"&D9 | O9: =INDEX('05_Param_Prog_Annee'!$E$4:$E$23,MATCH(N9,'05_Param_Prog_Annee'!$A$4:$A$23,0)) | P9: =INDEX('05_Param_Prog_Annee'!$F$4:$F$23,MATCH(N9,'05_Param_Prog_Annee'!$A$4:$A$23,0)) | Q9: =INDEX('05_Param_Prog_Annee'!$G$4:$G$23,MATCH(N9,'05_Param_Prog_Annee'!$A$4:$A$23,0)) | R9: =INDEX('05_Param_Prog_Annee'!$H$4:$H$23,MATCH(N9,'05_Param_Prog_Annee'!$A$4:$A$23,0)) | S9: =INDEX('05_Param_Prog_Annee'!$I$4:$I$23,MATCH(N9,'05_Param_Prog_Annee'!$A$4:$A$23,0)) | T9: =IFERROR(INDEX('05_Param_Prog_Annee'!$J$4:$J$23,MATCH(N9,'05_Param_Prog_Annee'!$A$4:$A$23,0)),0) | U9: =P9*Q9*(1+'01_Cadrage'!$H$21) | V9: =INDEX('01_Cadrage'!$L$7:$L$20,MATCH(A9&"|"&B9,'01_Cadrage'!$O$7:$O$20,0)) | W9: =INDEX('01_Cadrage'!$M$7:$M$20,MATCH(A9&"|"&B9,'01_Cadrage'!$O$7:$O$20,0)) | X9: =IFERROR(INDEX('06_Historique'!$F$66:$F$73,MATCH(C9,'06_Historique'!$A$66:$A$73,0)),'01_Cadrage'!$H$27) | Y9: ='01_Cadrage'!$H$16*V9 | Z9: =IF(F9=1,J9*(1+X9*Y9),0) | AA9: =IF(F9=1,IFERROR(H9/J9,'01_Cadrage'!$H$28)+'01_Cadrage'!$H$18,0) | AB9: =Z9*AA9 | AC9: =IF(F9=1,0,K9*(T9+'01_Cadrage'!$H$19)) | AD9: =AB9+AC9 | AE9: =L9*(1+'01_Cadrage'!$H$17*W9) | AF9: =1 | AG9: =1 | AH9: =AD9*AE9*AF9+AB9*'01_Cadrage'!$H$24 | AI9: =IF(AD9<=0,0,MAX(1,ROUNDUP(AD9/O9,0))) | AJ9: =AI9*U9 | AK9: =AD9*R9*(1+'01_Cadrage'!$H$20) | AL9: =H9*S9*(1+Y9) | AM9: =AH9-AJ9-AK9-AL9-AD9*'01_Cadrage'!$H$26*(1+'01_Cadrage'!$H$20) | AN9: =IFERROR(AD9/(AI9*O9),0) | AO9: =IFERROR(AM9/AD9,0) | AP9: =IFERROR(AI9*U9/(AE9*AF9-R9*(1+'01_Cadrage'!$H$20)),0)
A10: ='06_Historique'!A11 | B10: ='06_Historique'!B11 | C10: ='06_Historique'!C11 | D10: ='06_Historique'!E11 | E10: ='06_Historique'!F11 | F10: ='06_Historique'!G11 | G10: ='06_Historique'!K11 | H10: ='06_Historique'!I11 | I10: ='06_Historique'!J11 | J10: ='06_Historique'!H11 | K10: ='06_Historique'!L11 | L10: ='06_Historique'!M11 | M10: ='06_Historique'!N11 | N10: =C10&"|"&D10 | O10: =INDEX('05_Param_Prog_Annee'!$E$4:$E$23,MATCH(N10,'05_Param_Prog_Annee'!$A$4:$A$23,0)) | P10: =INDEX('05_Param_Prog_Annee'!$F$4:$F$23,MATCH(N10,'05_Param_Prog_Annee'!$A$4:$A$23,0)) | Q10: =INDEX('05_Param_Prog_Annee'!$G$4:$G$23,MATCH(N10,'05_Param_Prog_Annee'!$A$4:$A$23,0)) | R10: =INDEX('05_Param_Prog_Annee'!$H$4:$H$23,MATCH(N10,'05_Param_Prog_Annee'!$A$4:$A$23,0)) | S10: =INDEX('05_Param_Prog_Annee'!$I$4:$I$23,MATCH(N10,'05_Param_Prog_Annee'!$A$4:$A$23,0)) | T10: =IFERROR(INDEX('05_Param_Prog_Annee'!$J$4:$J$23,MATCH(N10,'05_Param_Prog_Annee'!$A$4:$A$23,0)),0) | U10: =P10*Q10*(1+'01_Cadrage'!$H$21) | V10: =INDEX('01_Cadrage'!$L$7:$L$20,MATCH(A10&"|"&B10,'01_Cadrage'!$O$7:$O$20,0)) | W10: =INDEX('01_Cadrage'!$M$7:$M$20,MATCH(A10&"|"&B10,'01_Cadrage'!$O$7:$O$20,0)) | X10: =IFERROR(INDEX('06_Historique'!$F$66:$F$73,MATCH(C10,'06_Historique'!$A$66:$A$73,0)),'01_Cadrage'!$H$27) | Y10: ='01_Cadrage'!$H$16*V10 | Z10: =IF(F10=1,J10*(1+X10*Y10),0) | AA10: =IF(F10=1,IFERROR(H10/J10,'01_Cadrage'!$H$28)+'01_Cadrage'!$H$18,0) | AB10: =Z10*AA10 | AC10: =IF(F10=1,0,K10*(T10+'01_Cadrage'!$H$19)) | AD10: =AB10+AC10 | AE10: =L10*(1+'01_Cadrage'!$H$17*W10) | AF10: =1 | AG10: =1 | AH10: =AD10*AE10*AF10+AB10*'01_Cadrage'!$H$24 | AI10: =IF(AD10<=0,0,MAX(1,ROUNDUP(AD10/O10,0))) | AJ10: =AI10*U10 | AK10: =AD10*R10*(1+'01_Cadrage'!$H$20) | AL10: =H10*S10*(1+Y10) | AM10: =AH10-AJ10-AK10-AL10-AD10*'01_Cadrage'!$H$26*(1+'01_Cadrage'!$H$20) | AN10: =IFERROR(AD10/(AI10*O10),0) | AO10: =IFERROR(AM10/AD10,0) | AP10: =IFERROR(AI10*U10/(AE10*AF10-R10*(1+'01_Cadrage'!$H$20)),0)
A11: ='06_Historique'!A12 | B11: ='06_Historique'!B12 | C11: ='06_Historique'!C12 | D11: ='06_Historique'!E12 | E11: ='06_Historique'!F12 | F11: ='06_Historique'!G12 | G11: ='06_Historique'!K12 | H11: ='06_Historique'!I12 | I11: ='06_Historique'!J12 | J11: ='06_Historique'!H12 | K11: ='06_Historique'!L12 | L11: ='06_Historique'!M12 | M11: ='06_Historique'!N12 | N11: =C11&"|"&D11 | O11: =INDEX('05_Param_Prog_Annee'!$E$4:$E$23,MATCH(N11,'05_Param_Prog_Annee'!$A$4:$A$23,0)) | P11: =INDEX('05_Param_Prog_Annee'!$F$4:$F$23,MATCH(N11,'05_Param_Prog_Annee'!$A$4:$A$23,0)) | Q11: =INDEX('05_Param_Prog_Annee'!$G$4:$G$23,MATCH(N11,'05_Param_Prog_Annee'!$A$4:$A$23,0)) | R11: =INDEX('05_Param_Prog_Annee'!$H$4:$H$23,MATCH(N11,'05_Param_Prog_Annee'!$A$4:$A$23,0)) | S11: =INDEX('05_Param_Prog_Annee'!$I$4:$I$23,MATCH(N11,'05_Param_Prog_Annee'!$A$4:$A$23,0)) | T11: =IFERROR(INDEX('05_Param_Prog_Annee'!$J$4:$J$23,MATCH(N11,'05_Param_Prog_Annee'!$A$4:$A$23,0)),0) | U11: =P11*Q11*(1+'01_Cadrage'!$H$21) | V11: =INDEX('01_Cadrage'!$L$7:$L$20,MATCH(A11&"|"&B11,'01_Cadrage'!$O$7:$O$20,0)) | W11: =INDEX('01_Cadrage'!$M$7:$M$20,MATCH(A11&"|"&B11,'01_Cadrage'!$O$7:$O$20,0)) | X11: =IFERROR(INDEX('06_Historique'!$F$66:$F$73,MATCH(C11,'06_Historique'!$A$66:$A$73,0)),'01_Cadrage'!$H$27) | Y11: ='01_Cadrage'!$H$16*V11 | Z11: =IF(F11=1,J11*(1+X11*Y11),0) | AA11: =IF(F11=1,IFERROR(H11/J11,'01_Cadrage'!$H$28)+'01_Cadrage'!$H$18,0) | AB11: =Z11*AA11 | AC11: =IF(F11=1,0,K11*(T11+'01_Cadrage'!$H$19)) | AD11: =AB11+AC11 | AE11: =L11*(1+'01_Cadrage'!$H$17*W11) | AF11: =1 | AG11: =1 | AH11: =AD11*AE11*AF11+AB11*'01_Cadrage'!$H$24 | AI11: =IF(AD11<=0,0,MAX(1,ROUNDUP(AD11/O11,0))) | AJ11: =AI11*U11 | AK11: =AD11*R11*(1+'01_Cadrage'!$H$20) | AL11: =H11*S11*(1+Y11) | AM11: =AH11-AJ11-AK11-AL11-AD11*'01_Cadrage'!$H$26*(1+'01_Cadrage'!$H$20) | AN11: =IFERROR(AD11/(AI11*O11),0) | AO11: =IFERROR(AM11/AD11,0) | AP11: =IFERROR(AI11*U11/(AE11*AF11-R11*(1+'01_Cadrage'!$H$20)),0)
A12: ='06_Historique'!A13 | B12: ='06_Historique'!B13 | C12: ='06_Historique'!C13 | D12: ='06_Historique'!E13 | E12: ='06_Historique'!F13 | F12: ='06_Historique'!G13 | G12: ='06_Historique'!K13 | H12: ='06_Historique'!I13 | I12: ='06_Historique'!J13 | J12: ='06_Historique'!H13 | K12: ='06_Historique'!L13 | L12: ='06_Historique'!M13 | M12: ='06_Historique'!N13 | N12: =C12&"|"&D12 | O12: =INDEX('05_Param_Prog_Annee'!$E$4:$E$23,MATCH(N12,'05_Param_Prog_Annee'!$A$4:$A$23,0)) | P12: =INDEX('05_Param_Prog_Annee'!$F$4:$F$23,MATCH(N12,'05_Param_Prog_Annee'!$A$4:$A$23,0)) | Q12: =INDEX('05_Param_Prog_Annee'!$G$4:$G$23,MATCH(N12,'05_Param_Prog_Annee'!$A$4:$A$23,0)) | R12: =INDEX('05_Param_Prog_Annee'!$H$4:$H$23,MATCH(N12,'05_Param_Prog_Annee'!$A$4:$A$23,0)) | S12: =INDEX('05_Param_Prog_Annee'!$I$4:$I$23,MATCH(N12,'05_Param_Prog_Annee'!$A$4:$A$23,0)) | T12: =IFERROR(INDEX('05_Param_Prog_Annee'!$J$4:$J$23,MATCH(N12,'05_Param_Prog_Annee'!$A$4:$A$23,0)),0) | U12: =P12*Q12*(1+'01_Cadrage'!$H$21) | V12: =INDEX('01_Cadrage'!$L$7:$L$20,MATCH(A12&"|"&B12,'01_Cadrage'!$O$7:$O$20,0)) | W12: =INDEX('01_Cadrage'!$M$7:$M$20,MATCH(A12&"|"&B12,'01_Cadrage'!$O$7:$O$20,0)) | X12: =IFERROR(INDEX('06_Historique'!$F$66:$F$73,MATCH(C12,'06_Historique'!$A$66:$A$73,0)),'01_Cadrage'!$H$27) | Y12: ='01_Cadrage'!$H$16*V12 | Z12: =IF(F12=1,J12*(1+X12*Y12),0) | AA12: =IF(F12=1,IFERROR(H12/J12,'01_Cadrage'!$H$28)+'01_Cadrage'!$H$18,0) | AB12: =Z12*AA12 | AC12: =IF(F12=1,0,K12*(T12+'01_Cadrage'!$H$19)) | AD12: =AB12+AC12 | AE12: =L12*(1+'01_Cadrage'!$H$17*W12) | AF12: =1 | AG12: =1 | AH12: =AD12*AE12*AF12+AB12*'01_Cadrage'!$H$24 | AI12: =IF(AD12<=0,0,MAX(1,ROUNDUP(AD12/O12,0))) | AJ12: =AI12*U12 | AK12: =AD12*R12*(1+'01_Cadrage'!$H$20) | AL12: =H12*S12*(1+Y12) | AM12: =AH12-AJ12-AK12-AL12-AD12*'01_Cadrage'!$H$26*(1+'01_Cadrage'!$H$20) | AN12: =IFERROR(AD12/(AI12*O12),0) | AO12: =IFERROR(AM12/AD12,0) | AP12: =IFERROR(AI12*U12/(AE12*AF12-R12*(1+'01_Cadrage'!$H$20)),0)
A13: ='06_Historique'!A14 | B13: ='06_Historique'!B14 | C13: ='06_Historique'!C14 | D13: ='06_Historique'!E14 | E13: ='06_Historique'!F14 | F13: ='06_Historique'!G14 | G13: ='06_Historique'!K14 | H13: ='06_Historique'!I14 | I13: ='06_Historique'!J14 | J13: ='06_Historique'!H14 | K13: ='06_Historique'!L14 | L13: ='06_Historique'!M14 | M13: ='06_Historique'!N14 | N13: =C13&"|"&D13 | O13: =INDEX('05_Param_Prog_Annee'!$E$4:$E$23,MATCH(N13,'05_Param_Prog_Annee'!$A$4:$A$23,0)) | P13: =INDEX('05_Param_Prog_Annee'!$F$4:$F$23,MATCH(N13,'05_Param_Prog_Annee'!$A$4:$A$23,0)) | Q13: =INDEX('05_Param_Prog_Annee'!$G$4:$G$23,MATCH(N13,'05_Param_Prog_Annee'!$A$4:$A$23,0)) | R13: =INDEX('05_Param_Prog_Annee'!$H$4:$H$23,MATCH(N13,'05_Param_Prog_Annee'!$A$4:$A$23,0)) | S13: =INDEX('05_Param_Prog_Annee'!$I$4:$I$23,MATCH(N13,'05_Param_Prog_Annee'!$A$4:$A$23,0)) | T13: =IFERROR(INDEX('05_Param_Prog_Annee'!$J$4:$J$23,MATCH(N13,'05_Param_Prog_Annee'!$A$4:$A$23,0)),0) | U13: =P13*Q13*(1+'01_Cadrage'!$H$21) | V13: =INDEX('01_Cadrage'!$L$7:$L$20,MATCH(A13&"|"&B13,'01_Cadrage'!$O$7:$O$20,0)) | W13: =INDEX('01_Cadrage'!$M$7:$M$20,MATCH(A13&"|"&B13,'01_Cadrage'!$O$7:$O$20,0)) | X13: =IFERROR(INDEX('06_Historique'!$F$66:$F$73,MATCH(C13,'06_Historique'!$A$66:$A$73,0)),'01_Cadrage'!$H$27) | Y13: ='01_Cadrage'!$H$16*V13 | Z13: =IF(F13=1,J13*(1+X13*Y13),0) | AA13: =IF(F13=1,IFERROR(H13/J13,'01_Cadrage'!$H$28)+'01_Cadrage'!$H$18,0) | AB13: =Z13*AA13 | AC13: =IF(F13=1,0,K13*(T13+'01_Cadrage'!$H$19)) | AD13: =AB13+AC13 | AE13: =L13*(1+'01_Cadrage'!$H$17*W13) | AF13: =1 | AG13: =1 | AH13: =AD13*AE13*AF13+AB13*'01_Cadrage'!$H$24 | AI13: =IF(AD13<=0,0,MAX(1,ROUNDUP(AD13/O13,0))) | AJ13: =AI13*U13 | AK13: =AD13*R13*(1+'01_Cadrage'!$H$20) | AL13: =H13*S13*(1+Y13) | AM13: =AH13-AJ13-AK13-AL13-AD13*'01_Cadrage'!$H$26*(1+'01_Cadrage'!$H$20) | AN13: =IFERROR(AD13/(AI13*O13),0) | AO13: =IFERROR(AM13/AD13,0) | AP13: =IFERROR(AI13*U13/(AE13*AF13-R13*(1+'01_Cadrage'!$H$20)),0)
A14: ='06_Historique'!A15 | B14: ='06_Historique'!B15 | C14: ='06_Historique'!C15 | D14: ='06_Historique'!E15 | E14: ='06_Historique'!F15 | F14: ='06_Historique'!G15 | G14: ='06_Historique'!K15 | H14: ='06_Historique'!I15 | I14: ='06_Historique'!J15 | J14: ='06_Historique'!H15 | K14: ='06_Historique'!L15 | L14: ='06_Historique'!M15 | M14: ='06_Historique'!N15 | N14: =C14&"|"&D14 | O14: =INDEX('05_Param_Prog_Annee'!$E$4:$E$23,MATCH(N14,'05_Param_Prog_Annee'!$A$4:$A$23,0)) | P14: =INDEX('05_Param_Prog_Annee'!$F$4:$F$23,MATCH(N14,'05_Param_Prog_Annee'!$A$4:$A$23,0)) | Q14: =INDEX('05_Param_Prog_Annee'!$G$4:$G$23,MATCH(N14,'05_Param_Prog_Annee'!$A$4:$A$23,0)) | R14: =INDEX('05_Param_Prog_Annee'!$H$4:$H$23,MATCH(N14,'05_Param_Prog_Annee'!$A$4:$A$23,0)) | S14: =INDEX('05_Param_Prog_Annee'!$I$4:$I$23,MATCH(N14,'05_Param_Prog_Annee'!$A$4:$A$23,0)) | T14: =IFERROR(INDEX('05_Param_Prog_Annee'!$J$4:$J$23,MATCH(N14,'05_Param_Prog_Annee'!$A$4:$A$23,0)),0) | U14: =P14*Q14*(1+'01_Cadrage'!$H$21) | V14: =INDEX('01_Cadrage'!$L$7:$L$20,MATCH(A14&"|"&B14,'01_Cadrage'!$O$7:$O$20,0)) | W14: =INDEX('01_Cadrage'!$M$7:$M$20,MATCH(A14&"|"&B14,'01_Cadrage'!$O$7:$O$20,0)) | X14: =IFERROR(INDEX('06_Historique'!$F$66:$F$73,MATCH(C14,'06_Historique'!$A$66:$A$73,0)),'01_Cadrage'!$H$27) | Y14: ='01_Cadrage'!$H$16*V14 | Z14: =IF(F14=1,J14*(1+X14*Y14),0) | AA14: =IF(F14=1,IFERROR(H14/J14,'01_Cadrage'!$H$28)+'01_Cadrage'!$H$18,0) | AB14: =Z14*AA14 | AC14: =IF(F14=1,0,K14*(T14+'01_Cadrage'!$H$19)) | AD14: =AB14+AC14 | AE14: =L14*(1+'01_Cadrage'!$H$17*W14) | AF14: =1 | AG14: =1 | AH14: =AD14*AE14*AF14+AB14*'01_Cadrage'!$H$24 | AI14: =IF(AD14<=0,0,MAX(1,ROUNDUP(AD14/O14,0))) | AJ14: =AI14*U14 | AK14: =AD14*R14*(1+'01_Cadrage'!$H$20) | AL14: =H14*S14*(1+Y14) | AM14: =AH14-AJ14-AK14-AL14-AD14*'01_Cadrage'!$H$26*(1+'01_Cadrage'!$H$20) | AN14: =IFERROR(AD14/(AI14*O14),0) | AO14: =IFERROR(AM14/AD14,0) | AP14: =IFERROR(AI14*U14/(AE14*AF14-R14*(1+'01_Cadrage'!$H$20)),0)
... A60: ='06_Historique'!A61 | B60: ='06_Historique'!B61 | C60: ='06_Historique'!C61 | D60: ='06_Historique'!E61 | E60: ='06_Historique'!F61 | F60: ='06_Historique'!G61 | G60: ='06_Historique'!K61 | H60: ='06_Historique'!I61 | I60: ='06_Historique'!J61 | J60: ='06_Historique'!H61 | K60: ='06_Historique'!L61 | L60: ='06_Historique'!M61 | M60: ='06_Historique'!N61 | N60: =C60&"|"&D60 | O60: =INDEX('05_Param_Prog_Annee'!$E$4:$E$23,MATCH(N60,'05_Param_Prog_Annee'!$A$4:$A$23,0)) | P60: =INDEX('05_Param_Prog_Annee'!$F$4:$F$23,MATCH(N60,'05_Param_Prog_Annee'!$A$4:$A$23,0)) | Q60: =INDEX('05_Param_Prog_Annee'!$G$4:$G$23,MATCH(N60,'05_Param_Prog_Annee'!$A$4:$A$23,0)) | R60: =INDEX('05_Param_Prog_Annee'!$H$4:$H$23,MATCH(N60,'05_Param_Prog_Annee'!$A$4:$A$23,0)) | S60: =INDEX('05_Param_Prog_Annee'!$I$4:$I$23,MATCH(N60,'05_Param_Prog_Annee'!$A$4:$A$23,0)) | T60: =IFERROR(INDEX('05_Param_Prog_Annee'!$J$4:$J$23,MATCH(N60,'05_Param_Prog_Annee'!$A$4:$A$23,0)),0) | U60: =P60*Q60*(1+'01_Cadrage'!$H$21) | V60: =INDEX('01_Cadrage'!$L$7:$L$20,MATCH(A60&"|"&B60,'01_Cadrage'!$O$7:$O$20,0)) | W60: =INDEX('01_Cadrage'!$M$7:$M$20,MATCH(A60&"|"&B60,'01_Cadrage'!$O$7:$O$20,0)) | X60: =IFERROR(INDEX('06_Historique'!$F$66:$F$73,MATCH(C60,'06_Historique'!$A$66:$A$73,0)),'01_Cadrage'!$H$27) | Y60: ='01_Cadrage'!$H$16*V60 | Z60: =IF(F60=1,J60*(1+X60*Y60),0) | AA60: =IF(F60=1,IFERROR(H60/J60,'01_Cadrage'!$H$28)+'01_Cadrage'!$H$18,0) | AB60: =Z60*AA60 | AC60: =IF(F60=1,0,K60*(T60+'01_Cadrage'!$H$19)) | AD60: =AB60+AC60 | AE60: =L60*(1+'01_Cadrage'!$H$17*W60) | AF60: =1 | AG60: =1 | AH60: =AD60*AE60*AF60+AB60*'01_Cadrage'!$H$24 | AI60: =IF(AD60<=0,0,MAX(1,ROUNDUP(AD60/O60,0))) | AJ60: =AI60*U60 | AK60: =AD60*R60*(1+'01_Cadrage'!$H$20) | AL60: =H60*S60*(1+Y60) | AM60: =AH60-AJ60-AK60-AL60-AD60*'01_Cadrage'!$H$26*(1+'01_Cadrage'!$H$20) | AN60: =IFERROR(AD60/(AI60*O60),0) | AO60: =IFERROR(AM60/AD60,0) | AP60: =IFERROR(AI60*U60/(AE60*AF60-R60*(1+'01_Cadrage'!$H$20)),0)
A61: TOTAL | F61: =SUM(F3:F60) | G61: =SUM(G3:G60) | H61: =SUM(H3:H60) | AB61: =SUM(AB3:AB60) | AC61: =SUM(AC3:AC60) | AD61: =SUM(AD3:AD60) | AH61: =SUM(AH3:AH60) | AI61: =SUM(AI3:AI60) | AJ61: =SUM(AJ3:AJ60) | AK61: =SUM(AK3:AK60) | AL61: =SUM(AL3:AL60) | AM61: =SUM(AM3:AM60)
A63: Guide de lecture — de gauche à droite, chaque bloc construit le budget de la cellule :
A64: A–F | B64: Identité & type : marque, campus, programme, année, modalité, année d'entrée (1 = on recrute)
A65: G–M | B65: Réalisé N-1 repris : effectif, nouveaux, réinscrits, candidatures, effectif année inférieure, tarif, classes
A66: N–T | B66: Paramètres programme×année (feuille 05) : capacité, heures, taux, pédago, CAC variable, taux de passage
A67: U–Y | B67: Coûts unitaires & coefficients : coût/classe, coeff marketing, coeff prix, élasticité, effort
A68: Z–AD | B68: COHORTE → VOLUME : candidatures budget → conversion → nouveaux + réinscrits = EFFECTIF budget
A69: AE–AH | B69: Tarif & CA budget : tarif budget, CA budget
A70: AI–AL | B70: Coûts budget : classes nécessaires, enseignement, pédagogie, marketing
A71: AM–AP | B71: RÉSULTATS : marge de CONTRIBUTION, remplissage, contribution/étudiant, point mort (seuil d'ouverture)

Sheet 09_Allocation
B2: Allocation des frais de structure par driver
B3: Driver actif : | C3: ='01_Cadrage'!$D$34 | E3: Frais de structure (fixe) à allouer : | H3: ='01_Cadrage'!$H$25*(1+'01_Cadrage'!$H$20)
B5: Marque | C5: Ville | D5: Contribution | E5: Loyer | F5: Masse perm. | G5: Driver | H5: Part | I5: Alloué | J5: EBITDA campus | K5: D&A | L5: EBIT
B6: MBway | C6: Paris | D6: =SUMIFS('08_Moteur'!$AM$3:$AM$60,'08_Moteur'!$A$3:$A$60,"MBway",'08_Moteur'!$B$3:$B$60,"Paris") | E6: ='07_Structure'!F4*(1+'01_Cadrage'!$H$20) | F6: ='07_Structure'!G4*'01_Cadrage'!$H$23*(1+'01_Cadrage'!$H$21) | G6: =IF($C$3="Effectifs",SUMIFS('08_Moteur'!$AD$3:$AD$60,'08_Moteur'!$A$3:$A$60,"MBway",'08_Moteur'!$B$3:$B$60,"Paris"),IF($C$3="Chiffre d'affaires",SUMIFS('08_Moteur'!$AH$3:$AH$60,'08_Moteur'!$A$3:$A$60,"MBway",'08_Moteur'!$B$3:$B$60,"Paris"),'07_Structure'!J4)) | H6: =IFERROR(G6/SUM($G$6:$G$19),0) | I6: =H6*$H$3 | J6: =D6-E6-F6-I6 | K6: ='07_Structure'!I4 | L6: =J6-K6
B7: MBway | C7: Lyon | D7: =SUMIFS('08_Moteur'!$AM$3:$AM$60,'08_Moteur'!$A$3:$A$60,"MBway",'08_Moteur'!$B$3:$B$60,"Lyon") | E7: ='07_Structure'!F5*(1+'01_Cadrage'!$H$20) | F7: ='07_Structure'!G5*'01_Cadrage'!$H$23*(1+'01_Cadrage'!$H$21) | G7: =IF($C$3="Effectifs",SUMIFS('08_Moteur'!$AD$3:$AD$60,'08_Moteur'!$A$3:$A$60,"MBway",'08_Moteur'!$B$3:$B$60,"Lyon"),IF($C$3="Chiffre d'affaires",SUMIFS('08_Moteur'!$AH$3:$AH$60,'08_Moteur'!$A$3:$A$60,"MBway",'08_Moteur'!$B$3:$B$60,"Lyon"),'07_Structure'!J5)) | H7: =IFERROR(G7/SUM($G$6:$G$19),0) | I7: =H7*$H$3 | J7: =D7-E7-F7-I7 | K7: ='07_Structure'!I5 | L7: =J7-K7
B8: MBway | C8: Nantes | D8: =SUMIFS('08_Moteur'!$AM$3:$AM$60,'08_Moteur'!$A$3:$A$60,"MBway",'08_Moteur'!$B$3:$B$60,"Nantes") | E8: ='07_Structure'!F6*(1+'01_Cadrage'!$H$20) | F8: ='07_Structure'!G6*'01_Cadrage'!$H$23*(1+'01_Cadrage'!$H$21) | G8: =IF($C$3="Effectifs",SUMIFS('08_Moteur'!$AD$3:$AD$60,'08_Moteur'!$A$3:$A$60,"MBway",'08_Moteur'!$B$3:$B$60,"Nantes"),IF($C$3="Chiffre d'affaires",SUMIFS('08_Moteur'!$AH$3:$AH$60,'08_Moteur'!$A$3:$A$60,"MBway",'08_Moteur'!$B$3:$B$60,"Nantes"),'07_Structure'!J6)) | H8: =IFERROR(G8/SUM($G$6:$G$19),0) | I8: =H8*$H$3 | J8: =D8-E8-F8-I8 | K8: ='07_Structure'!I6 | L8: =J8-K8
B9: MBway | C9: Bordeaux | D9: =SUMIFS('08_Moteur'!$AM$3:$AM$60,'08_Moteur'!$A$3:$A$60,"MBway",'08_Moteur'!$B$3:$B$60,"Bordeaux") | E9: ='07_Structure'!F7*(1+'01_Cadrage'!$H$20) | F9: ='07_Structure'!G7*'01_Cadrage'!$H$23*(1+'01_Cadrage'!$H$21) | G9: =IF($C$3="Effectifs",SUMIFS('08_Moteur'!$AD$3:$AD$60,'08_Moteur'!$A$3:$A$60,"MBway",'08_Moteur'!$B$3:$B$60,"Bordeaux"),IF($C$3="Chiffre d'affaires",SUMIFS('08_Moteur'!$AH$3:$AH$60,'08_Moteur'!$A$3:$A$60,"MBway",'08_Moteur'!$B$3:$B$60,"Bordeaux"),'07_Structure'!J7)) | H9: =IFERROR(G9/SUM($G$6:$G$19),0) | I9: =H9*$H$3 | J9: =D9-E9-F9-I9 | K9: ='07_Structure'!I7 | L9: =J9-K9
B10: ISCOM | C10: Paris | D10: =SUMIFS('08_Moteur'!$AM$3:$AM$60,'08_Moteur'!$A$3:$A$60,"ISCOM",'08_Moteur'!$B$3:$B$60,"Paris") | E10: ='07_Structure'!F8*(1+'01_Cadrage'!$H$20) | F10: ='07_Structure'!G8*'01_Cadrage'!$H$23*(1+'01_Cadrage'!$H$21) | G10: =IF($C$3="Effectifs",SUMIFS('08_Moteur'!$AD$3:$AD$60,'08_Moteur'!$A$3:$A$60,"ISCOM",'08_Moteur'!$B$3:$B$60,"Paris"),IF($C$3="Chiffre d'affaires",SUMIFS('08_Moteur'!$AH$3:$AH$60,'08_Moteur'!$A$3:$A$60,"ISCOM",'08_Moteur'!$B$3:$B$60,"Paris"),'07_Structure'!J8)) | H10: =IFERROR(G10/SUM($G$6:$G$19),0) | I10: =H10*$H$3 | J10: =D10-E10-F10-I10 | K10: ='07_Structure'!I8 | L10: =J10-K10
B11: ISCOM | C11: Lille | D11: =SUMIFS('08_Moteur'!$AM$3:$AM$60,'08_Moteur'!$A$3:$A$60,"ISCOM",'08_Moteur'!$B$3:$B$60,"Lille") | E11: ='07_Structure'!F9*(1+'01_Cadrage'!$H$20) | F11: ='07_Structure'!G9*'01_Cadrage'!$H$23*(1+'01_Cadrage'!$H$21) | G11: =IF($C$3="Effectifs",SUMIFS('08_Moteur'!$AD$3:$AD$60,'08_Moteur'!$A$3:$A$60,"ISCOM",'08_Moteur'!$B$3:$B$60,"Lille"),IF($C$3="Chiffre d'affaires",SUMIFS('08_Moteur'!$AH$3:$AH$60,'08_Moteur'!$A$3:$A$60,"ISCOM",'08_Moteur'!$B$3:$B$60,"Lille"),'07_Structure'!J9)) | H11: =IFERROR(G11/SUM($G$6:$G$19),0) | I11: =H11*$H$3 | J11: =D11-E11-F11-I11 | K11: ='07_Structure'!I9 | L11: =J11-K11
B12: ISCOM | C12: Toulouse | D12: =SUMIFS('08_Moteur'!$AM$3:$AM$60,'08_Moteur'!$A$3:$A$60,"ISCOM",'08_Moteur'!$B$3:$B$60,"Toulouse") | E12: ='07_Structure'!F10*(1+'01_Cadrage'!$H$20) | F12: ='07_Structure'!G10*'01_Cadrage'!$H$23*(1+'01_Cadrage'!$H$21) | G12: =IF($C$3="Effectifs",SUMIFS('08_Moteur'!$AD$3:$AD$60,'08_Moteur'!$A$3:$A$60,"ISCOM",'08_Moteur'!$B$3:$B$60,"Toulouse"),IF($C$3="Chiffre d'affaires",SUMIFS('08_Moteur'!$AH$3:$AH$60,'08_Moteur'!$A$3:$A$60,"ISCOM",'08_Moteur'!$B$3:$B$60,"Toulouse"),'07_Structure'!J10)) | H12: =IFERROR(G12/SUM($G$6:$G$19),0) | I12: =H12*$H$3 | J12: =D12-E12-F12-I12 | K12: ='07_Structure'!I10 | L12: =J12-K12
B13: Ipac Bachelor Factory | C13: Nantes | D13: =SUMIFS('08_Moteur'!$AM$3:$AM$60,'08_Moteur'!$A$3:$A$60,"Ipac Bachelor Factory",'08_Moteur'!$B$3:$B$60,"Nantes") | E13: ='07_Structure'!F11*(1+'01_Cadrage'!$H$20) | F13: ='07_Structure'!G11*'01_Cadrage'!$H$23*(1+'01_Cadrage'!$H$21) | G13: =IF($C$3="Effectifs",SUMIFS('08_Moteur'!$AD$3:$AD$60,'08_Moteur'!$A$3:$A$60,"Ipac Bachelor Factory",'08_Moteur'!$B$3:$B$60,"Nantes"),IF($C$3="Chiffre d'affaires",SUMIFS('08_Moteur'!$AH$3:$AH$60,'08_Moteur'!$A$3:$A$60,"Ipac Bachelor Factory",'08_Moteur'!$B$3:$B$60,"Nantes"),'07_Structure'!J11)) | H13: =IFERROR(G13/SUM($G$6:$G$19),0) | I13: =H13*$H$3 | J13: =D13-E13-F13-I13 | K13: ='07_Structure'!I11 | L13: =J13-K13
B14: Ipac Bachelor Factory | C14: Rennes | D14: =SUMIFS('08_Moteur'!$AM$3:$AM$60,'08_Moteur'!$A$3:$A$60,"Ipac Bachelor Factory",'08_Moteur'!$B$3:$B$60,"Rennes") | E14: ='07_Structure'!F12*(1+'01_Cadrage'!$H$20) | F14: ='07_Structure'!G12*'01_Cadrage'!$H$23*(1+'01_Cadrage'!$H$21) | G14: =IF($C$3="Effectifs",SUMIFS('08_Moteur'!$AD$3:$AD$60,'08_Moteur'!$A$3:$A$60,"Ipac Bachelor Factory",'08_Moteur'!$B$3:$B$60,"Rennes"),IF($C$3="Chiffre d'affaires",SUMIFS('08_Moteur'!$AH$3:$AH$60,'08_Moteur'!$A$3:$A$60,"Ipac Bachelor Factory",'08_Moteur'!$B$3:$B$60,"Rennes"),'07_Structure'!J12)) | H14: =IFERROR(G14/SUM($G$6:$G$19),0) | I14: =H14*$H$3 | J14: =D14-E14-F14-I14 | K14: ='07_Structure'!I12 | L14: =J14-K14
B15: Ipac Bachelor Factory | C15: Montpellier | D15: =SUMIFS('08_Moteur'!$AM$3:$AM$60,'08_Moteur'!$A$3:$A$60,"Ipac Bachelor Factory",'08_Moteur'!$B$3:$B$60,"Montpellier") | E15: ='07_Structure'!F13*(1+'01_Cadrage'!$H$20) | F15: ='07_Structure'!G13*'01_Cadrage'!$H$23*(1+'01_Cadrage'!$H$21) | G15: =IF($C$3="Effectifs",SUMIFS('08_Moteur'!$AD$3:$AD$60,'08_Moteur'!$A$3:$A$60,"Ipac Bachelor Factory",'08_Moteur'!$B$3:$B$60,"Montpellier"),IF($C$3="Chiffre d'affaires",SUMIFS('08_Moteur'!$AH$3:$AH$60,'08_Moteur'!$A$3:$A$60,"Ipac Bachelor Factory",'08_Moteur'!$B$3:$B$60,"Montpellier"),'07_Structure'!J13)) | H15: =IFERROR(G15/SUM($G$6:$G$19),0) | I15: =H15*$H$3 | J15: =D15-E15-F15-I15 | K15: ='07_Structure'!I13 | L15: =J15-K15
B16: Pigier | C16: Lyon | D16: =SUMIFS('08_Moteur'!$AM$3:$AM$60,'08_Moteur'!$A$3:$A$60,"Pigier",'08_Moteur'!$B$3:$B$60,"Lyon") | E16: ='07_Structure'!F14*(1+'01_Cadrage'!$H$20) | F16: ='07_Structure'!G14*'01_Cadrage'!$H$23*(1+'01_Cadrage'!$H$21) | G16: =IF($C$3="Effectifs",SUMIFS('08_Moteur'!$AD$3:$AD$60,'08_Moteur'!$A$3:$A$60,"Pigier",'08_Moteur'!$B$3:$B$60,"Lyon"),IF($C$3="Chiffre d'affaires",SUMIFS('08_Moteur'!$AH$3:$AH$60,'08_Moteur'!$A$3:$A$60,"Pigier",'08_Moteur'!$B$3:$B$60,"Lyon"),'07_Structure'!J14)) | H16: =IFERROR(G16/SUM($G$6:$G$19),0) | I16: =H16*$H$3 | J16: =D16-E16-F16-I16 | K16: ='07_Structure'!I14 | L16: =J16-K16
