Workbook

Sheet 00_Notice
B2: EDUSERVICES — Modèle de CA (v3, budget-driven, leads observés)
B3: Budget marketing → leads (CRM, socle organique + payant) → funnel mesuré → inscrits → CA. Revenu et taux différenciés alternance / initial.
B5: Les feuilles (périmètre : CA → EBITDA)
B6: 01_Cadrage | C6: POSTE DE COMMANDE CFO : objectif CA & EBITDA (calculé), scénarios, 9 leviers (CA + coûts), coefficients prix par marque×ville.
B7: 02_Base | C7: BASE DE RÉFÉRENCE (version unique) : fusion historique + paramètres. LEADS OBSERVÉS (CRM) et taux de funnel MESURÉS (lead→cand, cand→admis, admis→inscrit), différenciés par modalité.
B8: 02_CRM | C8: HISTORIQUE MULTISOURCE (format long) : leads organiques/payants + dépense marketing par campus × 3 exercices. Sert à MESURER CPL, rendement et part organique.
B9: 03_Campagnes | C9: MOTEUR D'ACQUISITION (campus) : CPL, rendement, part organique MESURÉS depuis le CRM, puis budget → leads (socle organique + part payante à rendement décroissant).
B10: 04_Moteur | C10: MOTEUR DE CA (cellule) : répartition des leads (mix réel) → funnel mesuré → effectif (+cohorte) → CA.
B12: Principe d'ancrage
B13: Au budget de référence, tous leviers à 0, le moteur reproduit l'historique. Les taux ne sont pas supposés : ils sont mesurés depuis les leads observés. Seul l'écart au budget de référence fait varier les volumes (part payante × courbe ^r).

Sheet 01_Cadrage
B1: POSTE DE COMMANDE CFO — Cadrage CA & EBITDA
B3: Scénario actif : | D3: Cadrage | E3: 🎯 Croissance CA cible : | F3: 0.05 | G3: Marge EBITDA cible : | H3: 0.15
B5: ① Réconciliation — Référence · 🎯 Cible (top-down) · 🔧 Construit (bottom-up) · Écart | J5: Coefficients prix (marque × ville)
B6: Indicateur | C6: Référence | D6: 🎯 Cible | E6: 🔧 Construit | F6: Écart | G6: Écart % | J6: Marque | K6: Ville | L6: Coeff prix | M6: clé
B7: Chiffre d'affaires | C7: 21936350 | D7: =21936350*(1+F3) | E7: ='04_Moteur'!$AA$62 | F7: =E7-D7 | G7: =IFERROR(E7/D7-1,0) | J7: MBway | K7: Paris | L7: 1.15 | M7: =J7&"|"&K7
B8: EBITDA (calculé) | C8: ='07_PnL'!$F$33 | D8: =D7*H3 | E8: ='07_PnL'!$G$33 | F8: =E8-D8 | G8: =IFERROR(E8/D8-1,0) | J8: MBway | K8: Lyon | L8: 1.05 | M8: =J8&"|"&K8
B9: Marge EBITDA % | C9: =IFERROR(C8/C7,0) | D9: =H3 | E9: =IFERROR(E8/E7,0) | G9: =IFERROR(E9-D9,0) | J9: MBway | K9: Nantes | L9: 1 | M9: =J9&"|"&K9
B10: Effectif total | C10: 2952 | D10: ='04_Moteur'!$AJ$62 | E10: ='04_Moteur'!$Y$62 | F10: =E10-D10 | G10: =IFERROR(E10/D10-1,0) | J10: MBway | K10: Bordeaux | L10: 0.95 | M10: =J10&"|"&K10
J11: ISCOM | K11: Paris | L11: 1.15 | M11: =J11&"|"&K11
B12: RESTE À TROUVER — CA : | D12: =IF(D7-E7>0,D7-E7,0) | E12: EBITDA : | F12: =IF(D8-E8>0,D8-E8,0) | J12: ISCOM | K12: Lille | L12: 1 | M12: =J12&"|"&K12
J13: ISCOM | K13: Toulouse | L13: 0.95 | M13: =J13&"|"&K13
B14: ② Leviers — bascule par scénario (colonne ACTIF) | J14: Ipac Bachelor Factory | K14: Nantes | L14: 1 | M14: =J14&"|"&K14
B15: Paramètre | C15: Unité | D15: Référence | E15: Cadrage | F15: Optimiste | G15: Prudent | H15: ACTIF | J15: Ipac Bachelor Factory | K15: Rennes | L15: 0.9 | M15: =J15&"|"&K15
B16: Variation du budget marketing (→ leads payants) | C16: % | D16: 0 | E16: 0.08 | F16: 0.15 | G16: -0.05 | H16: =INDEX(D16:G16,MATCH($D$3,$D$15:$G$15,0)) | J16: Ipac Bachelor Factory | K16: Montpellier | L16: 0.9 | M16: =J16&"|"&K16
B17: Hausse tarifaire (prix) | C17: % | D17: 0 | E17: 0.025 | F17: 0.035 | G17: 0.02 | H17: =INDEX(D17:G17,MATCH($D$3,$D$15:$G$15,0)) | J17: Pigier | K17: Lyon | L17: 1.05 | M17: =J17&"|"&K17
B18: Gain taux lead → candidature | C18: pts | D18: 0 | E18: 0.01 | F18: 0.03 | G18: 0 | H18: =INDEX(D18:G18,MATCH($D$3,$D$15:$G$15,0)) | J18: Pigier | K18: Bordeaux | L18: 0.95 | M18: =J18&"|"&K18
B19: Gain conversion admis → inscrit | C19: pts | D19: 0 | E19: 0.01 | F19: 0.025 | G19: 0 | H19: =INDEX(D19:G19,MATCH($D$3,$D$15:$G$15,0)) | J19: Tunon | K19: Paris | L19: 1.15 | M19: =J19&"|"&K19
B20: Amélioration du taux de passage | C20: pts | D20: 0 | E20: 0.005 | F20: 0.015 | G20: -0.01 | H20: =INDEX(D20:G20,MATCH($D$3,$D$15:$G$15,0)) | J20: Tunon | K20: Lyon | L20: 1.05 | M20: =J20&"|"&K20
B21: Inflation des charges externes | C21: % | D21: 0 | E21: 0.02 | F21: 0.015 | G21: 0.03 | H21: =INDEX(D21:G21,MATCH($D$3,$D$15:$G$15,0))
B22: Politique salariale (masse permanente) | C22: % | D22: 0 | E22: 0.025 | F22: 0.02 | G22: 0.03 | H22: =INDEX(D22:G22,MATCH($D$3,$D$15:$G$15,0)) | J22: Cap stratégique par marque
B23: Variation des effectifs permanents | C23: % | D23: 0 | E23: 0.04 | F23: 0.03 | G23: 0.05 | H23: =INDEX(D23:G23,MATCH($D$3,$D$15:$G$15,0)) | J23: Marque | K23: Poids CA réf | L23: 🔵 Cap | M23: Poids norm.
B24: Effort de productivité (achats & structure) | C24: % | D24: 0 | E24: 0.01 | F24: 0.03 | G24: 0 | H24: =INDEX(D24:G24,MATCH($D$3,$D$15:$G$15,0)) | J24: MBway | K24: 0.4254 | L24: 1 | M24: =IFERROR(K24*L24/SUMPRODUCT($K$24:$K$28,$L$24:$L$28),0)
B25: Leviers 1-5 → CA (moteur) · leviers 6-9 → coûts (P&L Budget → EBITDA). « Référence » remet tout à 0 = atterrissage. | J25: ISCOM | K25: 0.2795 | L25: 1 | M25: =IFERROR(K25*L25/SUMPRODUCT($K$24:$K$28,$L$24:$L$28),0)
B26: ③ Constante — frais de dossier (décision) | J26: Ipac Bachelor Factory | K26: 0.1131 | L26: 1 | M26: =IFERROR(K26*L26/SUMPRODUCT($K$24:$K$28,$L$24:$L$28),0)
B27: Paramètre | C27: Unité | D27: Référence | E27: Cadrage | F27: Optimiste | G27: Prudent | H27: ACTIF | J27: Pigier | K27: 0.0966 | L27: 1 | M27: =IFERROR(K27*L27/SUMPRODUCT($K$24:$K$28,$L$24:$L$28),0)
B28: Frais de dossier / nouvel inscrit | C28: € | D28: 90 | E28: 90 | F28: 90 | G28: 90 | H28: =INDEX(D28:G28,MATCH($D$3,$D$15:$G$15,0)) | J28: Tunon | K28: 0.0854 | L28: 1 | M28: =IFERROR(K28*L28/SUMPRODUCT($K$24:$K$28,$L$24:$L$28),0)
B30: Rendement, CPL et part organique ne sont pas saisis : ils sont MESURÉS depuis le CRM (voir 03_Campagnes). | J30: Cap = 1 partout → répartition proportionnelle au CA réf. Cap > 1 = pousser la marque (la cible se redistribue, total inchangé).

Sheet 02_Base
A1: BASE DE RÉFÉRENCE — version unique · fusion historique + paramètres · leads observés (CRM) & taux mesurés
A2: Une ligne = marque × ville × programme × année × modalité. Leads = donnée observée (CRM). Taux = mesurés (aval÷amont). Revenu différencié alternance (OPCO) / initial (étudiant).
A3: Marque | B3: Ville | C3: Programme | D3: Cycle | E3: Année | F3: Modalité | G3: Entrée | H3: Leads hist | I3: Cand hist | J3: Admis hist | K3: Nouv hist | L3: Réins hist | M3: Effectif hist | N3: Eff. année inf. | O3: Classes hist | P3: Revenu/étudiant | Q3: Taux passage | R3: Taux lead→cand | S3: Taux cand→admis | T3: Yield admis→inscrit
A4: MBway | B4: Paris | C4: Bachelor Management | D4: BAC | E4: B1 | F4: Initial | G4: 1 | H4: 646 | I4: 181 | J4: 130 | K4: 78 | L4: 0 | M4: 78 | N4: 0 | O4: 3 | P4: 8400 | Q4: 0 | R4: 0.2802 | S4: 0.7182 | T4: 0.6
A5: MBway | B5: Paris | C5: Bachelor Management | D5: BAC | E5: B2 | F5: Alternance | G5: 0 | H5: 0 | I5: 0 | J5: 0 | K5: 0 | L5: 73 | M5: 73 | N5: 78 | O5: 3 | P5: 7840 | Q5: 0.93 | R5: 0 | S5: 0 | T5: 0
A6: MBway | B6: Paris | C6: Bachelor Management | D6: BAC | E6: B3 | F6: Alternance | G6: 0 | H6: 0 | I6: 0 | J6: 0 | K6: 0 | L6: 69 | M6: 69 | N6: 73 | O6: 3 | P6: 7840 | Q6: 0.95 | R6: 0 | S6: 0 | T6: 0
A7: MBway | B7: Paris | C7: Mastère Management | D7: MAST | E7: M1 | F7: Alternance | G7: 1 | H7: 1330 | I7: 266 | J7: 186 | K7: 78 | L7: 0 | M7: 78 | N7: 0 | O7: 3 | P7: 8400 | Q7: 0 | R7: 0.2 | S7: 0.6992 | T7: 0.4194
A8: MBway | B8: Paris | C8: Mastère Management | D8: MAST | E8: M2 | F8: Alternance | G8: 0 | H8: 0 | I8: 0 | J8: 0 | K8: 0 | L8: 75 | M8: 75 | N8: 78 | O8: 3 | P8: 8400 | Q8: 0.96 | R8: 0 | S8: 0 | T8: 0
A9: MBway | B9: Lyon | C9: Bachelor Management | D9: BAC | E9: B1 | F9: Initial | G9: 1 | H9: 546 | I9: 153 | J9: 110 | K9: 66 | L9: 0 | M9: 66 | N9: 0 | O9: 3 | P9: 7875 | Q9: 0 | R9: 0.2802 | S9: 0.719 | T9: 0.6
A10: MBway | B10: Lyon | C10: Bachelor Management | D10: BAC | E10: B2 | F10: Alternance | G10: 0 | H10: 0 | I10: 0 | J10: 0 | K10: 0 | L10: 61 | M10: 61 | N10: 66 | O10: 2 | P10: 7350 | Q10: 0.93 | R10: 0 | S10: 0 | T10: 0
A11: MBway | B11: Lyon | C11: Bachelor Management | D11: BAC | E11: B3 | F11: Alternance | G11: 0 | H11: 0 | I11: 0 | J11: 0 | K11: 0 | L11: 58 | M11: 58 | N11: 61 | O11: 2 | P11: 7350 | Q11: 0.95 | R11: 0 | S11: 0 | T11: 0
A12: MBway | B12: Lyon | C12: Mastère Management | D12: MAST | E12: M1 | F12: Alternance | G12: 1 | H12: 1120 | I12: 224 | J12: 157 | K12: 66 | L12: 0 | M12: 66 | N12: 0 | O12: 3 | P12: 7875 | Q12: 0 | R12: 0.2 | S12: 0.7009 | T12: 0.4204
A13: MBway | B13: Lyon | C13: Mastère Management | D13: MAST | E13: M2 | F13: Alternance | G13: 0 | H13: 0 | I13: 0 | J13: 0 | K13: 0 | L13: 63 | M13: 63 | N13: 66 | O13: 3 | P13: 7875 | Q13: 0.96 | R13: 0 | S13: 0 | T13: 0
A14: MBway | B14: Nantes | C14: Bachelor Management | D14: BAC | E14: B1 | F14: Initial | G14: 1 | H14: 496 | I14: 139 | J14: 100 | K14: 60 | L14: 0 | M14: 60 | N14: 0 | O14: 2 | P14: 7500 | Q14: 0 | R14: 0.2802 | S14: 0.7194 | T14: 0.6
A15: MBway | B15: Nantes | C15: Bachelor Management | D15: BAC | E15: B2 | F15: Alternance | G15: 0 | H15: 0 | I15: 0 | J15: 0 | K15: 0 | L15: 56 | M15: 56 | N15: 60 | O15: 2 | P15: 7000 | Q15: 0.93 | R15: 0 | S15: 0 | T15: 0
... A61: Tunon | B61: Lyon | C61: Bachelor Tourisme | D61: BAC | E61: B3 | F61: Alternance | G61: 0 | H61: 0 | I61: 0 | J61: 0 | K61: 0 | L61: 35 | M61: 35 | N61: 37 | O61: 2 | P61: 7350 | Q61: 0.95 | R61: 0 | S61: 0 | T61: 0

Sheet 02_CRM
A1: CRM & MARKETING — historique multisource (format long, par année) : leads organiques/payants + dépense
A2: Source : CRM (leads, tag organique/payant) + compta (dépense). 3 années réelles (2024·2025·2026). 03_Campagnes MESURE le CPL, le rendement et la part organique depuis cet historique — rien n'est saisi.
A3: Marque | B3: Ville | C3: clé | D3: Année | E3: Leads organiques | F3: Leads payants | G3: Leads totaux | H3: Dépense marketing
A4: MBway | B4: Paris | C4: =A4&"|"&B4 | D4: 2024 | E4: 645 | F4: 1158 | G4: =E4+F4 | H4: 56438
A5: MBway | B5: Paris | C5: =A5&"|"&B5 | D5: 2025 | E5: 677 | F5: 1210 | G5: =E5+F5 | H5: 62082
A6: MBway | B6: Paris | C6: =A6&"|"&B6 | D6: 2026 | E6: 711 | F6: 1265 | G6: =E6+F6 | H6: 68291
A7: MBway | B7: Lyon | C7: =A7&"|"&B7 | D7: 2024 | E7: 650 | F7: 863 | G7: =E7+F7 | H7: 34532
A8: MBway | B8: Lyon | C8: =A8&"|"&B8 | D8: 2025 | E8: 682 | F8: 905 | G8: =E8+F8 | H8: 37985
A9: MBway | B9: Lyon | C9: =A9&"|"&B9 | D9: 2026 | E9: 716 | F9: 950 | G9: =E9+F9 | H9: 41783
A10: MBway | B10: Nantes | C10: =A10&"|"&B10 | D10: 2024 | E10: 660 | F10: 713 | G10: =E10+F10 | H10: 26060
A11: MBway | B11: Nantes | C11: =A11&"|"&B11 | D11: 2025 | E11: 693 | F11: 749 | G11: =E11+F11 | H11: 28666
A12: MBway | B12: Nantes | C12: =A12&"|"&B12 | D12: 2026 | E12: 728 | F12: 788 | G12: =E12+F12 | H12: 31533
A13: MBway | B13: Bordeaux | C13: =A13&"|"&B13 | D13: 2024 | E13: 572 | F13: 592 | G13: =E13+F13 | H13: 20597
A14: MBway | B14: Bordeaux | C14: =A14&"|"&B14 | D14: 2025 | E14: 600 | F14: 623 | G14: =E14+F14 | H14: 22657
A15: MBway | B15: Bordeaux | C15: =A15&"|"&B15 | D15: 2026 | E15: 630 | F15: 656 | G15: =E15+F15 | H15: 24923
... A45: Tunon | B45: Lyon | C45: =A45&"|"&B45 | D45: 2026 | E45: 252 | F45: 428 | G45: =E45+F45 | H45: 18850

Sheet 03_Campagnes
A1: MOTEUR D'ACQUISITION (campus) — CPL · rendement · part organique MESURÉS depuis le CRM, puis budget → leads
A2: Part org = org÷total (ATT). CPL = dépense÷payants (ATT). Rendement = ln(payants ATT÷N-2) ÷ ln(dépense ATT÷N-2). Leads payants actif = payants réf × (budget actif÷réf)^rendement. Total = organiques + payants.
A3: Marque | B3: Ville | C3: clé | D3: Leads organiques | E3: Leads payants réf | F3: Leads total réf | G3: Dépense mkt réf | H3: Part organique | I3: CPL mesuré | J3: Rendement mesuré | K3: Budget payant actif | L3: Leads payants actif | M3: Leads actif total | N3: CPL effectif | O3: Conv. lead→inscrit | P3: CAC marginal /inscrit
A5: MBway | B5: Paris | C5: =A5&"|"&B5 | D5: =SUMIFS('02_CRM'!$E$4:$E$45,'02_CRM'!$C$4:$C$45,C5,'02_CRM'!$D$4:$D$45,2026) | E5: =SUMIFS('02_CRM'!$F$4:$F$45,'02_CRM'!$C$4:$C$45,C5,'02_CRM'!$D$4:$D$45,2026) | F5: =D5+E5 | G5: =SUMIFS('02_CRM'!$H$4:$H$45,'02_CRM'!$C$4:$C$45,C5,'02_CRM'!$D$4:$D$45,2026) | H5: =IFERROR(D5/F5,0) | I5: =IFERROR(G5/E5,0) | J5: =IFERROR(LN(E5/SUMIFS('02_CRM'!$F$4:$F$45,'02_CRM'!$C$4:$C$45,C5,'02_CRM'!$D$4:$D$45,2024))/LN(G5/SUMIFS('02_CRM'!$H$4:$H$45,'02_CRM'!$C$4:$C$45,C5,'02_CRM'!$D$4:$D$45,2024)),0.5) | K5: =G5*(1+'01_Cadrage'!$H$16) | L5: =E5*(K5/G5)^J5 | M5: =D5+L5 | N5: =IFERROR(K5/L5,0) | O5: =IFERROR(SUMIFS('02_Base'!$K$4:$K$61,'02_Base'!$A$4:$A$61,A5,'02_Base'!$B$4:$B$61,B5,'02_Base'!$G$4:$G$61,1)/SUMIFS('02_Base'!$H$4:$H$61,'02_Base'!$A$4:$A$61,A5,'02_Base'!$B$4:$B$61,B5,'02_Base'!$G$4:$G$61,1),0) | P5: =IFERROR(I5/(J5*O5),0)
A6: MBway | B6: Lyon | C6: =A6&"|"&B6 | D6: =SUMIFS('02_CRM'!$E$4:$E$45,'02_CRM'!$C$4:$C$45,C6,'02_CRM'!$D$4:$D$45,2026) | E6: =SUMIFS('02_CRM'!$F$4:$F$45,'02_CRM'!$C$4:$C$45,C6,'02_CRM'!$D$4:$D$45,2026) | F6: =D6+E6 | G6: =SUMIFS('02_CRM'!$H$4:$H$45,'02_CRM'!$C$4:$C$45,C6,'02_CRM'!$D$4:$D$45,2026) | H6: =IFERROR(D6/F6,0) | I6: =IFERROR(G6/E6,0) | J6: =IFERROR(LN(E6/SUMIFS('02_CRM'!$F$4:$F$45,'02_CRM'!$C$4:$C$45,C6,'02_CRM'!$D$4:$D$45,2024))/LN(G6/SUMIFS('02_CRM'!$H$4:$H$45,'02_CRM'!$C$4:$C$45,C6,'02_CRM'!$D$4:$D$45,2024)),0.5) | K6: =G6*(1+'01_Cadrage'!$H$16) | L6: =E6*(K6/G6)^J6 | M6: =D6+L6 | N6: =IFERROR(K6/L6,0) | O6: =IFERROR(SUMIFS('02_Base'!$K$4:$K$61,'02_Base'!$A$4:$A$61,A6,'02_Base'!$B$4:$B$61,B6,'02_Base'!$G$4:$G$61,1)/SUMIFS('02_Base'!$H$4:$H$61,'02_Base'!$A$4:$A$61,A6,'02_Base'!$B$4:$B$61,B6,'02_Base'!$G$4:$G$61,1),0) | P6: =IFERROR(I6/(J6*O6),0)
A7: MBway | B7: Nantes | C7: =A7&"|"&B7 | D7: =SUMIFS('02_CRM'!$E$4:$E$45,'02_CRM'!$C$4:$C$45,C7,'02_CRM'!$D$4:$D$45,2026) | E7: =SUMIFS('02_CRM'!$F$4:$F$45,'02_CRM'!$C$4:$C$45,C7,'02_CRM'!$D$4:$D$45,2026) | F7: =D7+E7 | G7: =SUMIFS('02_CRM'!$H$4:$H$45,'02_CRM'!$C$4:$C$45,C7,'02_CRM'!$D$4:$D$45,2026) | H7: =IFERROR(D7/F7,0) | I7: =IFERROR(G7/E7,0) | J7: =IFERROR(LN(E7/SUMIFS('02_CRM'!$F$4:$F$45,'02_CRM'!$C$4:$C$45,C7,'02_CRM'!$D$4:$D$45,2024))/LN(G7/SUMIFS('02_CRM'!$H$4:$H$45,'02_CRM'!$C$4:$C$45,C7,'02_CRM'!$D$4:$D$45,2024)),0.5) | K7: =G7*(1+'01_Cadrage'!$H$16) | L7: =E7*(K7/G7)^J7 | M7: =D7+L7 | N7: =IFERROR(K7/L7,0) | O7: =IFERROR(SUMIFS('02_Base'!$K$4:$K$61,'02_Base'!$A$4:$A$61,A7,'02_Base'!$B$4:$B$61,B7,'02_Base'!$G$4:$G$61,1)/SUMIFS('02_Base'!$H$4:$H$61,'02_Base'!$A$4:$A$61,A7,'02_Base'!$B$4:$B$61,B7,'02_Base'!$G$4:$G$61,1),0) | P7: =IFERROR(I7/(J7*O7),0)
A8: MBway | B8: Bordeaux | C8: =A8&"|"&B8 | D8: =SUMIFS('02_CRM'!$E$4:$E$45,'02_CRM'!$C$4:$C$45,C8,'02_CRM'!$D$4:$D$45,2026) | E8: =SUMIFS('02_CRM'!$F$4:$F$45,'02_CRM'!$C$4:$C$45,C8,'02_CRM'!$D$4:$D$45,2026) | F8: =D8+E8 | G8: =SUMIFS('02_CRM'!$H$4:$H$45,'02_CRM'!$C$4:$C$45,C8,'02_CRM'!$D$4:$D$45,2026) | H8: =IFERROR(D8/F8,0) | I8: =IFERROR(G8/E8,0) | J8: =IFERROR(LN(E8/SUMIFS('02_CRM'!$F$4:$F$45,'02_CRM'!$C$4:$C$45,C8,'02_CRM'!$D$4:$D$45,2024))/LN(G8/SUMIFS('02_CRM'!$H$4:$H$45,'02_CRM'!$C$4:$C$45,C8,'02_CRM'!$D$4:$D$45,2024)),0.5) | K8: =G8*(1+'01_Cadrage'!$H$16) | L8: =E8*(K8/G8)^J8 | M8: =D8+L8 | N8: =IFERROR(K8/L8,0) | O8: =IFERROR(SUMIFS('02_Base'!$K$4:$K$61,'02_Base'!$A$4:$A$61,A8,'02_Base'!$B$4:$B$61,B8,'02_Base'!$G$4:$G$61,1)/SUMIFS('02_Base'!$H$4:$H$61,'02_Base'!$A$4:$A$61,A8,'02_Base'!$B$4:$B$61,B8,'02_Base'!$G$4:$G$61,1),0) | P8: =IFERROR(I8/(J8*O8),0)
A9: ISCOM | B9: Paris | C9: =A9&"|"&B9 | D9: =SUMIFS('02_CRM'!$E$4:$E$45,'02_CRM'!$C$4:$C$45,C9,'02_CRM'!$D$4:$D$45,2026) | E9: =SUMIFS('02_CRM'!$F$4:$F$45,'02_CRM'!$C$4:$C$45,C9,'02_CRM'!$D$4:$D$45,2026) | F9: =D9+E9 | G9: =SUMIFS('02_CRM'!$H$4:$H$45,'02_CRM'!$C$4:$C$45,C9,'02_CRM'!$D$4:$D$45,2026) | H9: =IFERROR(D9/F9,0) | I9: =IFERROR(G9/E9,0) | J9: =IFERROR(LN(E9/SUMIFS('02_CRM'!$F$4:$F$45,'02_CRM'!$C$4:$C$45,C9,'02_CRM'!$D$4:$D$45,2024))/LN(G9/SUMIFS('02_CRM'!$H$4:$H$45,'02_CRM'!$C$4:$C$45,C9,'02_CRM'!$D$4:$D$45,2024)),0.5) | K9: =G9*(1+'01_Cadrage'!$H$16) | L9: =E9*(K9/G9)^J9 | M9: =D9+L9 | N9: =IFERROR(K9/L9,0) | O9: =IFERROR(SUMIFS('02_Base'!$K$4:$K$61,'02_Base'!$A$4:$A$61,A9,'02_Base'!$B$4:$B$61,B9,'02_Base'!$G$4:$G$61,1)/SUMIFS('02_Base'!$H$4:$H$61,'02_Base'!$A$4:$A$61,A9,'02_Base'!$B$4:$B$61,B9,'02_Base'!$G$4:$G$61,1),0) | P9: =IFERROR(I9/(J9*O9),0)
A10: ISCOM | B10: Lille | C10: =A10&"|"&B10 | D10: =SUMIFS('02_CRM'!$E$4:$E$45,'02_CRM'!$C$4:$C$45,C10,'02_CRM'!$D$4:$D$45,2026) | E10: =SUMIFS('02_CRM'!$F$4:$F$45,'02_CRM'!$C$4:$C$45,C10,'02_CRM'!$D$4:$D$45,2026) | F10: =D10+E10 | G10: =SUMIFS('02_CRM'!$H$4:$H$45,'02_CRM'!$C$4:$C$45,C10,'02_CRM'!$D$4:$D$45,2026) | H10: =IFERROR(D10/F10,0) | I10: =IFERROR(G10/E10,0) | J10: =IFERROR(LN(E10/SUMIFS('02_CRM'!$F$4:$F$45,'02_CRM'!$C$4:$C$45,C10,'02_CRM'!$D$4:$D$45,2024))/LN(G10/SUMIFS('02_CRM'!$H$4:$H$45,'02_CRM'!$C$4:$C$45,C10,'02_CRM'!$D$4:$D$45,2024)),0.5) | K10: =G10*(1+'01_Cadrage'!$H$16) | L10: =E10*(K10/G10)^J10 | M10: =D10+L10 | N10: =IFERROR(K10/L10,0) | O10: =IFERROR(SUMIFS('02_Base'!$K$4:$K$61,'02_Base'!$A$4:$A$61,A10,'02_Base'!$B$4:$B$61,B10,'02_Base'!$G$4:$G$61,1)/SUMIFS('02_Base'!$H$4:$H$61,'02_Base'!$A$4:$A$61,A10,'02_Base'!$B$4:$B$61,B10,'02_Base'!$G$4:$G$61,1),0) | P10: =IFERROR(I10/(J10*O10),0)
A11: ISCOM | B11: Toulouse | C11: =A11&"|"&B11 | D11: =SUMIFS('02_CRM'!$E$4:$E$45,'02_CRM'!$C$4:$C$45,C11,'02_CRM'!$D$4:$D$45,2026) | E11: =SUMIFS('02_CRM'!$F$4:$F$45,'02_CRM'!$C$4:$C$45,C11,'02_CRM'!$D$4:$D$45,2026) | F11: =D11+E11 | G11: =SUMIFS('02_CRM'!$H$4:$H$45,'02_CRM'!$C$4:$C$45,C11,'02_CRM'!$D$4:$D$45,2026) | H11: =IFERROR(D11/F11,0) | I11: =IFERROR(G11/E11,0) | J11: =IFERROR(LN(E11/SUMIFS('02_CRM'!$F$4:$F$45,'02_CRM'!$C$4:$C$45,C11,'02_CRM'!$D$4:$D$45,2024))/LN(G11/SUMIFS('02_CRM'!$H$4:$H$45,'02_CRM'!$C$4:$C$45,C11,'02_CRM'!$D$4:$D$45,2024)),0.5) | K11: =G11*(1+'01_Cadrage'!$H$16) | L11: =E11*(K11/G11)^J11 | M11: =D11+L11 | N11: =IFERROR(K11/L11,0) | O11: =IFERROR(SUMIFS('02_Base'!$K$4:$K$61,'02_Base'!$A$4:$A$61,A11,'02_Base'!$B$4:$B$61,B11,'02_Base'!$G$4:$G$61,1)/SUMIFS('02_Base'!$H$4:$H$61,'02_Base'!$A$4:$A$61,A11,'02_Base'!$B$4:$B$61,B11,'02_Base'!$G$4:$G$61,1),0) | P11: =IFERROR(I11/(J11*O11),0)
A12: Ipac Bachelor Factory | B12: Nantes | C12: =A12&"|"&B12 | D12: =SUMIFS('02_CRM'!$E$4:$E$45,'02_CRM'!$C$4:$C$45,C12,'02_CRM'!$D$4:$D$45,2026) | E12: =SUMIFS('02_CRM'!$F$4:$F$45,'02_CRM'!$C$4:$C$45,C12,'02_CRM'!$D$4:$D$45,2026) | F12: =D12+E12 | G12: =SUMIFS('02_CRM'!$H$4:$H$45,'02_CRM'!$C$4:$C$45,C12,'02_CRM'!$D$4:$D$45,2026) | H12: =IFERROR(D12/F12,0) | I12: =IFERROR(G12/E12,0) | J12: =IFERROR(LN(E12/SUMIFS('02_CRM'!$F$4:$F$45,'02_CRM'!$C$4:$C$45,C12,'02_CRM'!$D$4:$D$45,2024))/LN(G12/SUMIFS('02_CRM'!$H$4:$H$45,'02_CRM'!$C$4:$C$45,C12,'02_CRM'!$D$4:$D$45,2024)),0.5) | K12: =G12*(1+'01_Cadrage'!$H$16) | L12: =E12*(K12/G12)^J12 | M12: =D12+L12 | N12: =IFERROR(K12/L12,0) | O12: =IFERROR(SUMIFS('02_Base'!$K$4:$K$61,'02_Base'!$A$4:$A$61,A12,'02_Base'!$B$4:$B$61,B12,'02_Base'!$G$4:$G$61,1)/SUMIFS('02_Base'!$H$4:$H$61,'02_Base'!$A$4:$A$61,A12,'02_Base'!$B$4:$B$61,B12,'02_Base'!$G$4:$G$61,1),0) | P12: =IFERROR(I12/(J12*O12),0)
A13: Ipac Bachelor Factory | B13: Rennes | C13: =A13&"|"&B13 | D13: =SUMIFS('02_CRM'!$E$4:$E$45,'02_CRM'!$C$4:$C$45,C13,'02_CRM'!$D$4:$D$45,2026) | E13: =SUMIFS('02_CRM'!$F$4:$F$45,'02_CRM'!$C$4:$C$45,C13,'02_CRM'!$D$4:$D$45,2026) | F13: =D13+E13 | G13: =SUMIFS('02_CRM'!$H$4:$H$45,'02_CRM'!$C$4:$C$45,C13,'02_CRM'!$D$4:$D$45,2026) | H13: =IFERROR(D13/F13,0) | I13: =IFERROR(G13/E13,0) | J13: =IFERROR(LN(E13/SUMIFS('02_CRM'!$F$4:$F$45,'02_CRM'!$C$4:$C$45,C13,'02_CRM'!$D$4:$D$45,2024))/LN(G13/SUMIFS('02_CRM'!$H$4:$H$45,'02_CRM'!$C$4:$C$45,C13,'02_CRM'!$D$4:$D$45,2024)),0.5) | K13: =G13*(1+'01_Cadrage'!$H$16) | L13: =E13*(K13/G13)^J13 | M13: =D13+L13 | N13: =IFERROR(K13/L13,0) | O13: =IFERROR(SUMIFS('02_Base'!$K$4:$K$61,'02_Base'!$A$4:$A$61,A13,'02_Base'!$B$4:$B$61,B13,'02_Base'!$G$4:$G$61,1)/SUMIFS('02_Base'!$H$4:$H$61,'02_Base'!$A$4:$A$61,A13,'02_Base'!$B$4:$B$61,B13,'02_Base'!$G$4:$G$61,1),0) | P13: =IFERROR(I13/(J13*O13),0)
A14: Ipac Bachelor Factory | B14: Montpellier | C14: =A14&"|"&B14 | D14: =SUMIFS('02_CRM'!$E$4:$E$45,'02_CRM'!$C$4:$C$45,C14,'02_CRM'!$D$4:$D$45,2026) | E14: =SUMIFS('02_CRM'!$F$4:$F$45,'02_CRM'!$C$4:$C$45,C14,'02_CRM'!$D$4:$D$45,2026) | F14: =D14+E14 | G14: =SUMIFS('02_CRM'!$H$4:$H$45,'02_CRM'!$C$4:$C$45,C14,'02_CRM'!$D$4:$D$45,2026) | H14: =IFERROR(D14/F14,0) | I14: =IFERROR(G14/E14,0) | J14: =IFERROR(LN(E14/SUMIFS('02_CRM'!$F$4:$F$45,'02_CRM'!$C$4:$C$45,C14,'02_CRM'!$D$4:$D$45,2024))/LN(G14/SUMIFS('02_CRM'!$H$4:$H$45,'02_CRM'!$C$4:$C$45,C14,'02_CRM'!$D$4:$D$45,2024)),0.5) | K14: =G14*(1+'01_Cadrage'!$H$16) | L14: =E14*(K14/G14)^J14 | M14: =D14+L14 | N14: =IFERROR(K14/L14,0) | O14: =IFERROR(SUMIFS('02_Base'!$K$4:$K$61,'02_Base'!$A$4:$A$61,A14,'02_Base'!$B$4:$B$61,B14,'02_Base'!$G$4:$G$61,1)/SUMIFS('02_Base'!$H$4:$H$61,'02_Base'!$A$4:$A$61,A14,'02_Base'!$B$4:$B$61,B14,'02_Base'!$G$4:$G$61,1),0) | P14: =IFERROR(I14/(J14*O14),0)
A15: Pigier | B15: Lyon | C15: =A15&"|"&B15 | D15: =SUMIFS('02_CRM'!$E$4:$E$45,'02_CRM'!$C$4:$C$45,C15,'02_CRM'!$D$4:$D$45,2026) | E15: =SUMIFS('02_CRM'!$F$4:$F$45,'02_CRM'!$C$4:$C$45,C15,'02_CRM'!$D$4:$D$45,2026) | F15: =D15+E15 | G15: =SUMIFS('02_CRM'!$H$4:$H$45,'02_CRM'!$C$4:$C$45,C15,'02_CRM'!$D$4:$D$45,2026) | H15: =IFERROR(D15/F15,0) | I15: =IFERROR(G15/E15,0) | J15: =IFERROR(LN(E15/SUMIFS('02_CRM'!$F$4:$F$45,'02_CRM'!$C$4:$C$45,C15,'02_CRM'!$D$4:$D$45,2024))/LN(G15/SUMIFS('02_CRM'!$H$4:$H$45,'02_CRM'!$C$4:$C$45,C15,'02_CRM'!$D$4:$D$45,2024)),0.5) | K15: =G15*(1+'01_Cadrage'!$H$16) | L15: =E15*(K15/G15)^J15 | M15: =D15+L15 | N15: =IFERROR(K15/L15,0) | O15: =IFERROR(SUMIFS('02_Base'!$K$4:$K$61,'02_Base'!$A$4:$A$61,A15,'02_Base'!$B$4:$B$61,B15,'02_Base'!$G$4:$G$61,1)/SUMIFS('02_Base'!$H$4:$H$61,'02_Base'!$A$4:$A$61,A15,'02_Base'!$B$4:$B$61,B15,'02_Base'!$G$4:$G$61,1),0) | P15: =IFERROR(I15/(J15*O15),0)
A16: Pigier | B16: Bordeaux | C16: =A16&"|"&B16 | D16: =SUMIFS('02_CRM'!$E$4:$E$45,'02_CRM'!$C$4:$C$45,C16,'02_CRM'!$D$4:$D$45,2026) | E16: =SUMIFS('02_CRM'!$F$4:$F$45,'02_CRM'!$C$4:$C$45,C16,'02_CRM'!$D$4:$D$45,2026) | F16: =D16+E16 | G16: =SUMIFS('02_CRM'!$H$4:$H$45,'02_CRM'!$C$4:$C$45,C16,'02_CRM'!$D$4:$D$45,2026) | H16: =IFERROR(D16/F16,0) | I16: =IFERROR(G16/E16,0) | J16: =IFERROR(LN(E16/SUMIFS('02_CRM'!$F$4:$F$45,'02_CRM'!$C$4:$C$45,C16,'02_CRM'!$D$4:$D$45,2024))/LN(G16/SUMIFS('02_CRM'!$H$4:$H$45,'02_CRM'!$C$4:$C$45,C16,'02_CRM'!$D$4:$D$45,2024)),0.5) | K16: =G16*(1+'01_Cadrage'!$H$16) | L16: =E16*(K16/G16)^J16 | M16: =D16+L16 | N16: =IFERROR(K16/L16,0) | O16: =IFERROR(SUMIFS('02_Base'!$K$4:$K$61,'02_Base'!$A$4:$A$61,A16,'02_Base'!$B$4:$B$61,B16,'02_Base'!$G$4:$G$61,1)/SUMIFS('02_Base'!$H$4:$H$61,'02_Base'!$A$4:$A$61,A16,'02_Base'!$B$4:$B$61,B16,'02_Base'!$G$4:$G$61,1),0) | P16: =IFERROR(I16/(J16*O16),0)
... A18: Tunon | B18: Lyon | C18: =A18&"|"&B18 | D18: =SUMIFS('02_CRM'!$E$4:$E$45,'02_CRM'!$C$4:$C$45,C18,'02_CRM'!$D$4:$D$45,2026) | E18: =SUMIFS('02_CRM'!$F$4:$F$45,'02_CRM'!$C$4:$C$45,C18,'02_CRM'!$D$4:$D$45,2026) | F18: =D18+E18 | G18: =SUMIFS('02_CRM'!$H$4:$H$45,'02_CRM'!$C$4:$C$45,C18,'02_CRM'!$D$4:$D$45,2026) | H18: =IFERROR(D18/F18,0) | I18: =IFERROR(G18/E18,0) | J18: =IFERROR(LN(E18/SUMIFS('02_CRM'!$F$4:$F$45,'02_CRM'!$C$4:$C$45,C18,'02_CRM'!$D$4:$D$45,2024))/LN(G18/SUMIFS('02_CRM'!$H$4:$H$45,'02_CRM'!$C$4:$C$45,C18,'02_CRM'!$D$4:$D$45,2024)),0.5) | K18: =G18*(1+'01_Cadrage'!$H$16) | L18: =E18*(K18/G18)^J18 | M18: =D18+L18 | N18: =IFERROR(K18/L18,0) | O18: =IFERROR(SUMIFS('02_Base'!$K$4:$K$61,'02_Base'!$A$4:$A$61,A18,'02_Base'!$B$4:$B$61,B18,'02_Base'!$G$4:$G$61,1)/SUMIFS('02_Base'!$H$4:$H$61,'02_Base'!$A$4:$A$61,A18,'02_Base'!$B$4:$B$61,B18,'02_Base'!$G$4:$G$61,1),0) | P18: =IFERROR(I18/(J18*O18),0)
A20: Indicateur d'attractivité : CAC marginal = coût marketing du prochain inscrit. Vert = investir ici (l'euro rapporte) · Rouge = marché cher/saturé.

Sheet 04_Moteur
A1: MOTEUR DE CA (cellule) — ① CIBLE (éclatée top-down) · ② CADRÉ (semé) · ③ AJUSTÉ (semé + ajustement contrôleur) · écart
A3: Marque | B3: Ville | C3: Programme | D3: Année | E3: Mod. | F3: Entrée | G3: Leads hist | H3: Cand hist | I3: Nouv hist | J3: Réins hist | K3: Eff hist | L3: Eff. inf. | M3: Revenu/étu | N3: Passage | O3: T.L→C | P3: T.C→A | Q3: Yield | R3: Part leads | S3: Leads campus | T3: Leads cellule | U3: Candidatures | V3: Admis | W3: Nouveaux ③ | X3: Réinscrits ③ | Y3: Effectif ③ | Z3: Revenu actif | AA3: CA ③ ajusté | AB3: Nouveaux ② | AC3: Réinscr. ② | AD3: Effectif ② | AE3: CA ② cadré | AF3: 🟢 Ajust.conv | AG3: 🟢 Ajust.pass | AH3: Poids | AI3: CA ① cible | AJ3: Effectif ① cible | AK3: Écart CA ③−① | AL3: Écart eff ③−①
A4: ='02_Base'!A4 | B4: ='02_Base'!B4 | C4: ='02_Base'!C4 | D4: ='02_Base'!E4 | E4: ='02_Base'!F4 | F4: ='02_Base'!G4 | G4: ='02_Base'!H4 | H4: ='02_Base'!I4 | I4: ='02_Base'!K4 | J4: ='02_Base'!L4 | K4: ='02_Base'!M4 | L4: ='02_Base'!N4 | M4: ='02_Base'!P4 | N4: ='02_Base'!Q4 | O4: ='02_Base'!R4 | P4: ='02_Base'!S4 | Q4: ='02_Base'!T4 | R4: =IF(F4=1,IFERROR(G4/INDEX('03_Campagnes'!$F$5:$F$18,MATCH(A4&"|"&B4,'03_Campagnes'!$C$5:$C$18,0)),0),0) | S4: =INDEX('03_Campagnes'!$M$5:$M$18,MATCH(A4&"|"&B4,'03_Campagnes'!$C$5:$C$18,0)) | T4: =S4*R4 | U4: =IF(F4=1,T4*(O4+'01_Cadrage'!$H$18),0) | V4: =U4*P4 | W4: =IF(F4=1,V4*(Q4+'01_Cadrage'!$H$19+AF4),0) | X4: =IF(F4=1,0,L4*(N4+'01_Cadrage'!$H$20+AG4)) | Y4: =W4+X4 | Z4: =M4*(1+'01_Cadrage'!$H$17*INDEX('01_Cadrage'!$L$7:$L$20,MATCH(A4&"|"&B4,'01_Cadrage'!$M$7:$M$20,0))) | AA4: =Y4*Z4+W4*'01_Cadrage'!$H$28 | AB4: =IF(F4=1,V4*(Q4+'01_Cadrage'!$H$19),0) | AC4: =IF(F4=1,0,L4*(N4+'01_Cadrage'!$H$20)) | AD4: =AB4+AC4 | AE4: =AD4*Z4+AB4*'01_Cadrage'!$H$28 | AF4: 0 | AG4: 0 | AH4: =K4*M4*INDEX('01_Cadrage'!$L$24:$L$28,MATCH(A4,'01_Cadrage'!$J$24:$J$28,0)) | AI4: =IFERROR((21936350*(1+'01_Cadrage'!$F$3))*AH4/SUM($AH$4:$AH$61),0) | AJ4: =IFERROR(AI4/Z4,0) | AK4: =AA4-AI4 | AL4: =Y4-AJ4
A5: ='02_Base'!A5 | B5: ='02_Base'!B5 | C5: ='02_Base'!C5 | D5: ='02_Base'!E5 | E5: ='02_Base'!F5 | F5: ='02_Base'!G5 | G5: ='02_Base'!H5 | H5: ='02_Base'!I5 | I5: ='02_Base'!K5 | J5: ='02_Base'!L5 | K5: ='02_Base'!M5 | L5: ='02_Base'!N5 | M5: ='02_Base'!P5 | N5: ='02_Base'!Q5 | O5: ='02_Base'!R5 | P5: ='02_Base'!S5 | Q5: ='02_Base'!T5 | R5: =IF(F5=1,IFERROR(G5/INDEX('03_Campagnes'!$F$5:$F$18,MATCH(A5&"|"&B5,'03_Campagnes'!$C$5:$C$18,0)),0),0) | S5: =INDEX('03_Campagnes'!$M$5:$M$18,MATCH(A5&"|"&B5,'03_Campagnes'!$C$5:$C$18,0)) | T5: =S5*R5 | U5: =IF(F5=1,T5*(O5+'01_Cadrage'!$H$18),0) | V5: =U5*P5 | W5: =IF(F5=1,V5*(Q5+'01_Cadrage'!$H$19+AF5),0) | X5: =IF(F5=1,0,L5*(N5+'01_Cadrage'!$H$20+AG5)) | Y5: =W5+X5 | Z5: =M5*(1+'01_Cadrage'!$H$17*INDEX('01_Cadrage'!$L$7:$L$20,MATCH(A5&"|"&B5,'01_Cadrage'!$M$7:$M$20,0))) | AA5: =Y5*Z5+W5*'01_Cadrage'!$H$28 | AB5: =IF(F5=1,V5*(Q5+'01_Cadrage'!$H$19),0) | AC5: =IF(F5=1,0,L5*(N5+'01_Cadrage'!$H$20)) | AD5: =AB5+AC5 | AE5: =AD5*Z5+AB5*'01_Cadrage'!$H$28 | AF5: 0 | AG5: 0 | AH5: =K5*M5*INDEX('01_Cadrage'!$L$24:$L$28,MATCH(A5,'01_Cadrage'!$J$24:$J$28,0)) | AI5: =IFERROR((21936350*(1+'01_Cadrage'!$F$3))*AH5/SUM($AH$4:$AH$61),0) | AJ5: =IFERROR(AI5/Z5,0) | AK5: =AA5-AI5 | AL5: =Y5-AJ5
A6: ='02_Base'!A6 | B6: ='02_Base'!B6 | C6: ='02_Base'!C6 | D6: ='02_Base'!E6 | E6: ='02_Base'!F6 | F6: ='02_Base'!G6 | G6: ='02_Base'!H6 | H6: ='02_Base'!I6 | I6: ='02_Base'!K6 | J6: ='02_Base'!L6 | K6: ='02_Base'!M6 | L6: ='02_Base'!N6 | M6: ='02_Base'!P6 | N6: ='02_Base'!Q6 | O6: ='02_Base'!R6 | P6: ='02_Base'!S6 | Q6: ='02_Base'!T6 | R6: =IF(F6=1,IFERROR(G6/INDEX('03_Campagnes'!$F$5:$F$18,MATCH(A6&"|"&B6,'03_Campagnes'!$C$5:$C$18,0)),0),0) | S6: =INDEX('03_Campagnes'!$M$5:$M$18,MATCH(A6&"|"&B6,'03_Campagnes'!$C$5:$C$18,0)) | T6: =S6*R6 | U6: =IF(F6=1,T6*(O6+'01_Cadrage'!$H$18),0) | V6: =U6*P6 | W6: =IF(F6=1,V6*(Q6+'01_Cadrage'!$H$19+AF6),0) | X6: =IF(F6=1,0,L6*(N6+'01_Cadrage'!$H$20+AG6)) | Y6: =W6+X6 | Z6: =M6*(1+'01_Cadrage'!$H$17*INDEX('01_Cadrage'!$L$7:$L$20,MATCH(A6&"|"&B6,'01_Cadrage'!$M$7:$M$20,0))) | AA6: =Y6*Z6+W6*'01_Cadrage'!$H$28 | AB6: =IF(F6=1,V6*(Q6+'01_Cadrage'!$H$19),0) | AC6: =IF(F6=1,0,L6*(N6+'01_Cadrage'!$H$20)) | AD6: =AB6+AC6 | AE6: =AD6*Z6+AB6*'01_Cadrage'!$H$28 | AF6: 0 | AG6: 0 | AH6: =K6*M6*INDEX('01_Cadrage'!$L$24:$L$28,MATCH(A6,'01_Cadrage'!$J$24:$J$28,0)) | AI6: =IFERROR((21936350*(1+'01_Cadrage'!$F$3))*AH6/SUM($AH$4:$AH$61),0) | AJ6: =IFERROR(AI6/Z6,0) | AK6: =AA6-AI6 | AL6: =Y6-AJ6
A7: ='02_Base'!A7 | B7: ='02_Base'!B7 | C7: ='02_Base'!C7 | D7: ='02_Base'!E7 | E7: ='02_Base'!F7 | F7: ='02_Base'!G7 | G7: ='02_Base'!H7 | H7: ='02_Base'!I7 | I7: ='02_Base'!K7 | J7: ='02_Base'!L7 | K7: ='02_Base'!M7 | L7: ='02_Base'!N7 | M7: ='02_Base'!P7 | N7: ='02_Base'!Q7 | O7: ='02_Base'!R7 | P7: ='02_Base'!S7 | Q7: ='02_Base'!T7 | R7: =IF(F7=1,IFERROR(G7/INDEX('03_Campagnes'!$F$5:$F$18,MATCH(A7&"|"&B7,'03_Campagnes'!$C$5:$C$18,0)),0),0) | S7: =INDEX('03_Campagnes'!$M$5:$M$18,MATCH(A7&"|"&B7,'03_Campagnes'!$C$5:$C$18,0)) | T7: =S7*R7 | U7: =IF(F7=1,T7*(O7+'01_Cadrage'!$H$18),0) | V7: =U7*P7 | W7: =IF(F7=1,V7*(Q7+'01_Cadrage'!$H$19+AF7),0) | X7: =IF(F7=1,0,L7*(N7+'01_Cadrage'!$H$20+AG7)) | Y7: =W7+X7 | Z7: =M7*(1+'01_Cadrage'!$H$17*INDEX('01_Cadrage'!$L$7:$L$20,MATCH(A7&"|"&B7,'01_Cadrage'!$M$7:$M$20,0))) | AA7: =Y7*Z7+W7*'01_Cadrage'!$H$28 | AB7: =IF(F7=1,V7*(Q7+'01_Cadrage'!$H$19),0) | AC7: =IF(F7=1,0,L7*(N7+'01_Cadrage'!$H$20)) | AD7: =AB7+AC7 | AE7: =AD7*Z7+AB7*'01_Cadrage'!$H$28 | AF7: 0 | AG7: 0 | AH7: =K7*M7*INDEX('01_Cadrage'!$L$24:$L$28,MATCH(A7,'01_Cadrage'!$J$24:$J$28,0)) | AI7: =IFERROR((21936350*(1+'01_Cadrage'!$F$3))*AH7/SUM($AH$4:$AH$61),0) | AJ7: =IFERROR(AI7/Z7,0) | AK7: =AA7-AI7 | AL7: =Y7-AJ7
A8: ='02_Base'!A8 | B8: ='02_Base'!B8 | C8: ='02_Base'!C8 | D8: ='02_Base'!E8 | E8: ='02_Base'!F8 | F8: ='02_Base'!G8 | G8: ='02_Base'!H8 | H8: ='02_Base'!I8 | I8: ='02_Base'!K8 | J8: ='02_Base'!L8 | K8: ='02_Base'!M8 | L8: ='02_Base'!N8 | M8: ='02_Base'!P8 | N8: ='02_Base'!Q8 | O8: ='02_Base'!R8 | P8: ='02_Base'!S8 | Q8: ='02_Base'!T8 | R8: =IF(F8=1,IFERROR(G8/INDEX('03_Campagnes'!$F$5:$F$18,MATCH(A8&"|"&B8,'03_Campagnes'!$C$5:$C$18,0)),0),0) | S8: =INDEX('03_Campagnes'!$M$5:$M$18,MATCH(A8&"|"&B8,'03_Campagnes'!$C$5:$C$18,0)) | T8: =S8*R8 | U8: =IF(F8=1,T8*(O8+'01_Cadrage'!$H$18),0) | V8: =U8*P8 | W8: =IF(F8=1,V8*(Q8+'01_Cadrage'!$H$19+AF8),0) | X8: =IF(F8=1,0,L8*(N8+'01_Cadrage'!$H$20+AG8)) | Y8: =W8+X8 | Z8: =M8*(1+'01_Cadrage'!$H$17*INDEX('01_Cadrage'!$L$7:$L$20,MATCH(A8&"|"&B8,'01_Cadrage'!$M$7:$M$20,0))) | AA8: =Y8*Z8+W8*'01_Cadrage'!$H$28 | AB8: =IF(F8=1,V8*(Q8+'01_Cadrage'!$H$19),0) | AC8: =IF(F8=1,0,L8*(N8+'01_Cadrage'!$H$20)) | AD8: =AB8+AC8 | AE8: =AD8*Z8+AB8*'01_Cadrage'!$H$28 | AF8: 0 | AG8: 0 | AH8: =K8*M8*INDEX('01_Cadrage'!$L$24:$L$28,MATCH(A8,'01_Cadrage'!$J$24:$J$28,0)) | AI8: =IFERROR((21936350*(1+'01_Cadrage'!$F$3))*AH8/SUM($AH$4:$AH$61),0) | AJ8: =IFERROR(AI8/Z8,0) | AK8: =AA8-AI8 | AL8: =Y8-AJ8
A9: ='02_Base'!A9 | B9: ='02_Base'!B9 | C9: ='02_Base'!C9 | D9: ='02_Base'!E9 | E9: ='02_Base'!F9 | F9: ='02_Base'!G9 | G9: ='02_Base'!H9 | H9: ='02_Base'!I9 | I9: ='02_Base'!K9 | J9: ='02_Base'!L9 | K9: ='02_Base'!M9 | L9: ='02_Base'!N9 | M9: ='02_Base'!P9 | N9: ='02_Base'!Q9 | O9: ='02_Base'!R9 | P9: ='02_Base'!S9 | Q9: ='02_Base'!T9 | R9: =IF(F9=1,IFERROR(G9/INDEX('03_Campagnes'!$F$5:$F$18,MATCH(A9&"|"&B9,'03_Campagnes'!$C$5:$C$18,0)),0),0) | S9: =INDEX('03_Campagnes'!$M$5:$M$18,MATCH(A9&"|"&B9,'03_Campagnes'!$C$5:$C$18,0)) | T9: =S9*R9 | U9: =IF(F9=1,T9*(O9+'01_Cadrage'!$H$18),0) | V9: =U9*P9 | W9: =IF(F9=1,V9*(Q9+'01_Cadrage'!$H$19+AF9),0) | X9: =IF(F9=1,0,L9*(N9+'01_Cadrage'!$H$20+AG9)) | Y9: =W9+X9 | Z9: =M9*(1+'01_Cadrage'!$H$17*INDEX('01_Cadrage'!$L$7:$L$20,MATCH(A9&"|"&B9,'01_Cadrage'!$M$7:$M$20,0))) | AA9: =Y9*Z9+W9*'01_Cadrage'!$H$28 | AB9: =IF(F9=1,V9*(Q9+'01_Cadrage'!$H$19),0) | AC9: =IF(F9=1,0,L9*(N9+'01_Cadrage'!$H$20)) | AD9: =AB9+AC9 | AE9: =AD9*Z9+AB9*'01_Cadrage'!$H$28 | AF9: 0 | AG9: 0 | AH9: =K9*M9*INDEX('01_Cadrage'!$L$24:$L$28,MATCH(A9,'01_Cadrage'!$J$24:$J$28,0)) | AI9: =IFERROR((21936350*(1+'01_Cadrage'!$F$3))*AH9/SUM($AH$4:$AH$61),0) | AJ9: =IFERROR(AI9/Z9,0) | AK9: =AA9-AI9 | AL9: =Y9-AJ9
A10: ='02_Base'!A10 | B10: ='02_Base'!B10 | C10: ='02_Base'!C10 | D10: ='02_Base'!E10 | E10: ='02_Base'!F10 | F10: ='02_Base'!G10 | G10: ='02_Base'!H10 | H10: ='02_Base'!I10 | I10: ='02_Base'!K10 | J10: ='02_Base'!L10 | K10: ='02_Base'!M10 | L10: ='02_Base'!N10 | M10: ='02_Base'!P10 | N10: ='02_Base'!Q10 | O10: ='02_Base'!R10 | P10: ='02_Base'!S10 | Q10: ='02_Base'!T10 | R10: =IF(F10=1,IFERROR(G10/INDEX('03_Campagnes'!$F$5:$F$18,MATCH(A10&"|"&B10,'03_Campagnes'!$C$5:$C$18,0)),0),0) | S10: =INDEX('03_Campagnes'!$M$5:$M$18,MATCH(A10&"|"&B10,'03_Campagnes'!$C$5:$C$18,0)) | T10: =S10*R10 | U10: =IF(F10=1,T10*(O10+'01_Cadrage'!$H$18),0) | V10: =U10*P10 | W10: =IF(F10=1,V10*(Q10+'01_Cadrage'!$H$19+AF10),0) | X10: =IF(F10=1,0,L10*(N10+'01_Cadrage'!$H$20+AG10)) | Y10: =W10+X10 | Z10: =M10*(1+'01_Cadrage'!$H$17*INDEX('01_Cadrage'!$L$7:$L$20,MATCH(A10&"|"&B10,'01_Cadrage'!$M$7:$M$20,0))) | AA10: =Y10*Z10+W10*'01_Cadrage'!$H$28 | AB10: =IF(F10=1,V10*(Q10+'01_Cadrage'!$H$19),0) | AC10: =IF(F10=1,0,L10*(N10+'01_Cadrage'!$H$20)) | AD10: =AB10+AC10 | AE10: =AD10*Z10+AB10*'01_Cadrage'!$H$28 | AF10: 0 | AG10: 0 | AH10: =K10*M10*INDEX('01_Cadrage'!$L$24:$L$28,MATCH(A10,'01_Cadrage'!$J$24:$J$28,0)) | AI10: =IFERROR((21936350*(1+'01_Cadrage'!$F$3))*AH10/SUM($AH$4:$AH$61),0) | AJ10: =IFERROR(AI10/Z10,0) | AK10: =AA10-AI10 | AL10: =Y10-AJ10
A11: ='02_Base'!A11 | B11: ='02_Base'!B11 | C11: ='02_Base'!C11 | D11: ='02_Base'!E11 | E11: ='02_Base'!F11 | F11: ='02_Base'!G11 | G11: ='02_Base'!H11 | H11: ='02_Base'!I11 | I11: ='02_Base'!K11 | J11: ='02_Base'!L11 | K11: ='02_Base'!M11 | L11: ='02_Base'!N11 | M11: ='02_Base'!P11 | N11: ='02_Base'!Q11 | O11: ='02_Base'!R11 | P11: ='02_Base'!S11 | Q11: ='02_Base'!T11 | R11: =IF(F11=1,IFERROR(G11/INDEX('03_Campagnes'!$F$5:$F$18,MATCH(A11&"|"&B11,'03_Campagnes'!$C$5:$C$18,0)),0),0) | S11: =INDEX('03_Campagnes'!$M$5:$M$18,MATCH(A11&"|"&B11,'03_Campagnes'!$C$5:$C$18,0)) | T11: =S11*R11 | U11: =IF(F11=1,T11*(O11+'01_Cadrage'!$H$18),0) | V11: =U11*P11 | W11: =IF(F11=1,V11*(Q11+'01_Cadrage'!$H$19+AF11),0) | X11: =IF(F11=1,0,L11*(N11+'01_Cadrage'!$H$20+AG11)) | Y11: =W11+X11 | Z11: =M11*(1+'01_Cadrage'!$H$17*INDEX('01_Cadrage'!$L$7:$L$20,MATCH(A11&"|"&B11,'01_Cadrage'!$M$7:$M$20,0))) | AA11: =Y11*Z11+W11*'01_Cadrage'!$H$28 | AB11: =IF(F11=1,V11*(Q11+'01_Cadrage'!$H$19),0) | AC11: =IF(F11=1,0,L11*(N11+'01_Cadrage'!$H$20)) | AD11: =AB11+AC11 | AE11: =AD11*Z11+AB11*'01_Cadrage'!$H$28 | AF11: 0 | AG11: 0 | AH11: =K11*M11*INDEX('01_Cadrage'!$L$24:$L$28,MATCH(A11,'01_Cadrage'!$J$24:$J$28,0)) | AI11: =IFERROR((21936350*(1+'01_Cadrage'!$F$3))*AH11/SUM($AH$4:$AH$61),0) | AJ11: =IFERROR(AI11/Z11,0) | AK11: =AA11-AI11 | AL11: =Y11-AJ11
A12: ='02_Base'!A12 | B12: ='02_Base'!B12 | C12: ='02_Base'!C12 | D12: ='02_Base'!E12 | E12: ='02_Base'!F12 | F12: ='02_Base'!G12 | G12: ='02_Base'!H12 | H12: ='02_Base'!I12 | I12: ='02_Base'!K12 | J12: ='02_Base'!L12 | K12: ='02_Base'!M12 | L12: ='02_Base'!N12 | M12: ='02_Base'!P12 | N12: ='02_Base'!Q12 | O12: ='02_Base'!R12 | P12: ='02_Base'!S12 | Q12: ='02_Base'!T12 | R12: =IF(F12=1,IFERROR(G12/INDEX('03_Campagnes'!$F$5:$F$18,MATCH(A12&"|"&B12,'03_Campagnes'!$C$5:$C$18,0)),0),0) | S12: =INDEX('03_Campagnes'!$M$5:$M$18,MATCH(A12&"|"&B12,'03_Campagnes'!$C$5:$C$18,0)) | T12: =S12*R12 | U12: =IF(F12=1,T12*(O12+'01_Cadrage'!$H$18),0) | V12: =U12*P12 | W12: =IF(F12=1,V12*(Q12+'01_Cadrage'!$H$19+AF12),0) | X12: =IF(F12=1,0,L12*(N12+'01_Cadrage'!$H$20+AG12)) | Y12: =W12+X12 | Z12: =M12*(1+'01_Cadrage'!$H$17*INDEX('01_Cadrage'!$L$7:$L$20,MATCH(A12&"|"&B12,'01_Cadrage'!$M$7:$M$20,0))) | AA12: =Y12*Z12+W12*'01_Cadrage'!$H$28 | AB12: =IF(F12=1,V12*(Q12+'01_Cadrage'!$H$19),0) | AC12: =IF(F12=1,0,L12*(N12+'01_Cadrage'!$H$20)) | AD12: =AB12+AC12 | AE12: =AD12*Z12+AB12*'01_Cadrage'!$H$28 | AF12: 0 | AG12: 0 | AH12: =K12*M12*INDEX('01_Cadrage'!$L$24:$L$28,MATCH(A12,'01_Cadrage'!$J$24:$J$28,0)) | AI12: =IFERROR((21936350*(1+'01_Cadrage'!$F$3))*AH12/SUM($AH$4:$AH$61),0) | AJ12: =IFERROR(AI12/Z12,0) | AK12: =AA12-AI12 | AL12: =Y12-AJ12
A13: ='02_Base'!A13 | B13: ='02_Base'!B13 | C13: ='02_Base'!C13 | D13: ='02_Base'!E13 | E13: ='02_Base'!F13 | F13: ='02_Base'!G13 | G13: ='02_Base'!H13 | H13: ='02_Base'!I13 | I13: ='02_Base'!K13 | J13: ='02_Base'!L13 | K13: ='02_Base'!M13 | L13: ='02_Base'!N13 | M13: ='02_Base'!P13 | N13: ='02_Base'!Q13 | O13: ='02_Base'!R13 | P13: ='02_Base'!S13 | Q13: ='02_Base'!T13 | R13: =IF(F13=1,IFERROR(G13/INDEX('03_Campagnes'!$F$5:$F$18,MATCH(A13&"|"&B13,'03_Campagnes'!$C$5:$C$18,0)),0),0) | S13: =INDEX('03_Campagnes'!$M$5:$M$18,MATCH(A13&"|"&B13,'03_Campagnes'!$C$5:$C$18,0)) | T13: =S13*R13 | U13: =IF(F13=1,T13*(O13+'01_Cadrage'!$H$18),0) | V13: =U13*P13 | W13: =IF(F13=1,V13*(Q13+'01_Cadrage'!$H$19+AF13),0) | X13: =IF(F13=1,0,L13*(N13+'01_Cadrage'!$H$20+AG13)) | Y13: =W13+X13 | Z13: =M13*(1+'01_Cadrage'!$H$17*INDEX('01_Cadrage'!$L$7:$L$20,MATCH(A13&"|"&B13,'01_Cadrage'!$M$7:$M$20,0))) | AA13: =Y13*Z13+W13*'01_Cadrage'!$H$28 | AB13: =IF(F13=1,V13*(Q13+'01_Cadrage'!$H$19),0) | AC13: =IF(F13=1,0,L13*(N13+'01_Cadrage'!$H$20)) | AD13: =AB13+AC13 | AE13: =AD13*Z13+AB13*'01_Cadrage'!$H$28 | AF13: 0 | AG13: 0 | AH13: =K13*M13*INDEX('01_Cadrage'!$L$24:$L$28,MATCH(A13,'01_Cadrage'!$J$24:$J$28,0)) | AI13: =IFERROR((21936350*(1+'01_Cadrage'!$F$3))*AH13/SUM($AH$4:$AH$61),0) | AJ13: =IFERROR(AI13/Z13,0) | AK13: =AA13-AI13 | AL13: =Y13-AJ13
A14: ='02_Base'!A14 | B14: ='02_Base'!B14 | C14: ='02_Base'!C14 | D14: ='02_Base'!E14 | E14: ='02_Base'!F14 | F14: ='02_Base'!G14 | G14: ='02_Base'!H14 | H14: ='02_Base'!I14 | I14: ='02_Base'!K14 | J14: ='02_Base'!L14 | K14: ='02_Base'!M14 | L14: ='02_Base'!N14 | M14: ='02_Base'!P14 | N14: ='02_Base'!Q14 | O14: ='02_Base'!R14 | P14: ='02_Base'!S14 | Q14: ='02_Base'!T14 | R14: =IF(F14=1,IFERROR(G14/INDEX('03_Campagnes'!$F$5:$F$18,MATCH(A14&"|"&B14,'03_Campagnes'!$C$5:$C$18,0)),0),0) | S14: =INDEX('03_Campagnes'!$M$5:$M$18,MATCH(A14&"|"&B14,'03_Campagnes'!$C$5:$C$18,0)) | T14: =S14*R14 | U14: =IF(F14=1,T14*(O14+'01_Cadrage'!$H$18),0) | V14: =U14*P14 | W14: =IF(F14=1,V14*(Q14+'01_Cadrage'!$H$19+AF14),0) | X14: =IF(F14=1,0,L14*(N14+'01_Cadrage'!$H$20+AG14)) | Y14: =W14+X14 | Z14: =M14*(1+'01_Cadrage'!$H$17*INDEX('01_Cadrage'!$L$7:$L$20,MATCH(A14&"|"&B14,'01_Cadrage'!$M$7:$M$20,0))) | AA14: =Y14*Z14+W14*'01_Cadrage'!$H$28 | AB14: =IF(F14=1,V14*(Q14+'01_Cadrage'!$H$19),0) | AC14: =IF(F14=1,0,L14*(N14+'01_Cadrage'!$H$20)) | AD14: =AB14+AC14 | AE14: =AD14*Z14+AB14*'01_Cadrage'!$H$28 | AF14: 0 | AG14: 0 | AH14: =K14*M14*INDEX('01_Cadrage'!$L$24:$L$28,MATCH(A14,'01_Cadrage'!$J$24:$J$28,0)) | AI14: =IFERROR((21936350*(1+'01_Cadrage'!$F$3))*AH14/SUM($AH$4:$AH$61),0) | AJ14: =IFERROR(AI14/Z14,0) | AK14: =AA14-AI14 | AL14: =Y14-AJ14
A15: ='02_Base'!A15 | B15: ='02_Base'!B15 | C15: ='02_Base'!C15 | D15: ='02_Base'!E15 | E15: ='02_Base'!F15 | F15: ='02_Base'!G15 | G15: ='02_Base'!H15 | H15: ='02_Base'!I15 | I15: ='02_Base'!K15 | J15: ='02_Base'!L15 | K15: ='02_Base'!M15 | L15: ='02_Base'!N15 | M15: ='02_Base'!P15 | N15: ='02_Base'!Q15 | O15: ='02_Base'!R15 | P15: ='02_Base'!S15 | Q15: ='02_Base'!T15 | R15: =IF(F15=1,IFERROR(G15/INDEX('03_Campagnes'!$F$5:$F$18,MATCH(A15&"|"&B15,'03_Campagnes'!$C$5:$C$18,0)),0),0) | S15: =INDEX('03_Campagnes'!$M$5:$M$18,MATCH(A15&"|"&B15,'03_Campagnes'!$C$5:$C$18,0)) | T15: =S15*R15 | U15: =IF(F15=1,T15*(O15+'01_Cadrage'!$H$18),0) | V15: =U15*P15 | W15: =IF(F15=1,V15*(Q15+'01_Cadrage'!$H$19+AF15),0) | X15: =IF(F15=1,0,L15*(N15+'01_Cadrage'!$H$20+AG15)) | Y15: =W15+X15 | Z15: =M15*(1+'01_Cadrage'!$H$17*INDEX('01_Cadrage'!$L$7:$L$20,MATCH(A15&"|"&B15,'01_Cadrage'!$M$7:$M$20,0))) | AA15: =Y15*Z15+W15*'01_Cadrage'!$H$28 | AB15: =IF(F15=1,V15*(Q15+'01_Cadrage'!$H$19),0) | AC15: =IF(F15=1,0,L15*(N15+'01_Cadrage'!$H$20)) | AD15: =AB15+AC15 | AE15: =AD15*Z15+AB15*'01_Cadrage'!$H$28 | AF15: 0 | AG15: 0 | AH15: =K15*M15*INDEX('01_Cadrage'!$L$24:$L$28,MATCH(A15,'01_Cadrage'!$J$24:$J$28,0)) | AI15: =IFERROR((21936350*(1+'01_Cadrage'!$F$3))*AH15/SUM($AH$4:$AH$61),0) | AJ15: =IFERROR(AI15/Z15,0) | AK15: =AA15-AI15 | AL15: =Y15-AJ15
... A61: ='02_Base'!A61 | B61: ='02_Base'!B61 | C61: ='02_Base'!C61 | D61: ='02_Base'!E61 | E61: ='02_Base'!F61 | F61: ='02_Base'!G61 | G61: ='02_Base'!H61 | H61: ='02_Base'!I61 | I61: ='02_Base'!K61 | J61: ='02_Base'!L61 | K61: ='02_Base'!M61 | L61: ='02_Base'!N61 | M61: ='02_Base'!P61 | N61: ='02_Base'!Q61 | O61: ='02_Base'!R61 | P61: ='02_Base'!S61 | Q61: ='02_Base'!T61 | R61: =IF(F61=1,IFERROR(G61/INDEX('03_Campagnes'!$F$5:$F$18,MATCH(A61&"|"&B61,'03_Campagnes'!$C$5:$C$18,0)),0),0) | S61: =INDEX('03_Campagnes'!$M$5:$M$18,MATCH(A61&"|"&B61,'03_Campagnes'!$C$5:$C$18,0)) | T61: =S61*R61 | U61: =IF(F61=1,T61*(O61+'01_Cadrage'!$H$18),0) | V61: =U61*P61 | W61: =IF(F61=1,V61*(Q61+'01_Cadrage'!$H$19+AF61),0) | X61: =IF(F61=1,0,L61*(N61+'01_Cadrage'!$H$20+AG61)) | Y61: =W61+X61 | Z61: =M61*(1+'01_Cadrage'!$H$17*INDEX('01_Cadrage'!$L$7:$L$20,MATCH(A61&"|"&B61,'01_Cadrage'!$M$7:$M$20,0))) | AA61: =Y61*Z61+W61*'01_Cadrage'!$H$28 | AB61: =IF(F61=1,V61*(Q61+'01_Cadrage'!$H$19),0) | AC61: =IF(F61=1,0,L61*(N61+'01_Cadrage'!$H$20)) | AD61: =AB61+AC61 | AE61: =AD61*Z61+AB61*'01_Cadrage'!$H$28 | AF61: 0 | AG61: 0 | AH61: =K61*M61*INDEX('01_Cadrage'!$L$24:$L$28,MATCH(A61,'01_Cadrage'!$J$24:$J$28,0)) | AI61: =IFERROR((21936350*(1+'01_Cadrage'!$F$3))*AH61/SUM($AH$4:$AH$61),0) | AJ61: =IFERROR(AI61/Z61,0) | AK61: =AA61-AI61 | AL61: =Y61-AJ61
A62: TOTAL | F62: =SUM(F4:F61) | G62: =SUM(G4:G61) | H62: =SUM(H4:H61) | I62: =SUM(I4:I61) | T62: =SUM(T4:T61) | U62: =SUM(U4:U61) | V62: =SUM(V4:V61) | W62: =SUM(W4:W61) | X62: =SUM(X4:X61) | Y62: =SUM(Y4:Y61) | AA62: =SUM(AA4:AA61) | AD62: =SUM(AD4:AD61) | AE62: =SUM(AE4:AE61) | AI62: =SUM(AI4:AI61) | AJ62: =SUM(AJ4:AJ61) | AK62: =SUM(AK4:AK61) | AL62: =SUM(AL4:AL61)
A64: Guide de lecture — les 3 états côte à côte :
A65: A–Q | B65: Identité + reprise base + taux mesurés (funnel, passage)
A66: R–V | B66: Acquisition : leads cellule → candidatures → admis
A67: W–AA | B67: ③ AJUSTÉ : nouveaux/réinscrits/effectif/CA avec ajustement contrôleur (= budget final)
A68: AB–AE | B68: ② CADRÉ : le même SANS ajustement (pré-budget semé top-down)
A69: AF–AG | B69: 🟢 AJUSTEMENT contrôleur (delta conversion / passage) — s'ajoute au semé, n'écrase rien
A70: AH–AJ | B70: ① CIBLE éclatée : poids (CA réf × cap marque) → CA cible → effectif cible
A71: AK–AL | B71: ÉCART ③ − ① : le construit atteint-il la cible ?

Sheet 05_Plan_Comptable
A1: PLAN COMPTABLE — comptes PCG · double hiérarchie (comptable + gestion) · prêt Tagetik (dimension Compte)
A3: Compte | B3: Libellé | C3: Classe PCG | D3: Poste PCG | E3: Ligne SIG | F3: Agrégat SIG | G3: Sens | H3: Rattachement | I3: Driver | J3: % du CA | K3: V/F
A4: 7062 | B4: Prestations de formation — alternance (OPCO) | C4: 7 — Produits d'exploitation | D4: 70 — Prestations de services | E4: Produits | F4: Marge de contribution | G4: Produit | H4: Campus | I4: — | J4: — | K4: —
A5: 706 | B5: Prestations de formation — scolarité (initial) | C5: 7 — Produits d'exploitation | D5: 70 — Prestations de services | E5: Produits | F5: Marge de contribution | G5: Produit | H5: Campus | I5: — | J5: — | K5: —
A6: 708 | B6: Frais de dossier & droits d'inscription | C6: 7 — Produits d'exploitation | D6: 70 — Prestations de services | E6: Produits | F6: Marge de contribution | G6: Produit | H6: Campus | I6: — | J6: — | K6: —
A7: 621 | B7: Personnel extérieur — vacataires & intervenants | C7: 6 — Charges d'exploitation | D7: 62 — Autres services extérieurs | E7: Coûts directs | F7: Marge de contribution | G7: Charge | H7: Campus | I7: classes | J7: 0.07 | K7: V
A8: 604 | B8: Sous-traitance pédagogique | C8: 6 — Charges d'exploitation | D8: 60 — Achats | E8: Coûts directs | F8: Marge de contribution | G8: Charge | H8: Campus | I8: effectif | J8: 0.03 | K8: V
A9: 6063 | B9: Fournitures pédagogiques & petit équipement | C9: 6 — Charges d'exploitation | D9: 60 — Achats | E9: Coûts directs | F9: Marge de contribution | G9: Charge | H9: Campus | I9: effectif | J9: 0.02 | K9: V
A10: 6231 | B10: Publicité & marketing d'acquisition (leads) | C10: 6 — Charges d'exploitation | D10: 62 — Autres services extérieurs | E10: Coûts directs | F10: Marge de contribution | G10: Charge | H10: Campus | I10: classes | J10: 0.021 | K10: V
A11: 6411 | B11: Rémunération enseignants permanents | C11: 6 — Charges d'exploitation | D11: 64 — Charges de personnel | E11: Personnel | F11: EBITDA | G11: Charge | H11: Campus | I11: classes | J11: 0.17 | K11: F
A12: 6413 | B12: Rémunération personnel administratif & pédagogique | C12: 6 — Charges d'exploitation | D12: 64 — Charges de personnel | E12: Personnel | F12: EBITDA | G12: Charge | H12: Campus | I12: effectif | J12: 0.09 | K12: F
A13: 6414 | B13: Rémunération direction & fonctions support (siège) | C13: 6 — Charges d'exploitation | D13: 64 — Charges de personnel | E13: Personnel | F13: EBITDA | G13: Charge | H13: Groupe | I13: CA | J13: 0.055 | K13: F
A14: 645 | B14: Charges sociales & de prévoyance | C14: 6 — Charges d'exploitation | D14: 64 — Charges de personnel | E14: Personnel | F14: EBITDA | G14: Charge | H14: Campus | I14: effectif | J14: 0.14 | K14: F
A15: 613 | B15: Loyers & charges locatives (campus) | C15: 6 — Charges d'exploitation | D15: 61 — Services extérieurs | E15: Structure | F15: EBITDA | G15: Charge | H15: Campus | I15: classes | J15: 0.105 | K15: F
A16: 615 | B16: Entretien & maintenance | C16: 6 — Charges d'exploitation | D16: 61 — Services extérieurs | E16: Structure | F16: EBITDA | G16: Charge | H16: Campus | I16: classes | J16: 0.015 | K16: F
A17: 616 | B17: Primes d'assurance | C17: 6 — Charges d'exploitation | D17: 61 — Services extérieurs | E17: Structure | F17: EBITDA | G17: Charge | H17: Campus | I17: effectif | J17: 0.01 | K17: F
A18: 6226 | B18: Honoraires (audit, conseil, juridique) | C18: 6 — Charges d'exploitation | D18: 62 — Autres services extérieurs | E18: Structure | F18: EBITDA | G18: Charge | H18: Groupe | I18: CA | J18: 0.025 | K18: F
... A26: 6811 | B26: Dotations aux amortissements (D&A) | C26: 6 — Charges d'exploitation | D26: 68 — Dotations & amort. | E26: Dotations | F26: Résultat d'exploitation (EBIT) | G26: Charge | H26: Campus | I26: classes | J26: 0.06 | K26: F
A29: Hiérarchie de gestion (dimension Compte — parent → enfant, prêt Tagetik)
A30: Code nœud | B30: Libellé | C30: Parent | D30: Type
A31: RESULTAT_EXPL | B31: Résultat d'exploitation (EBIT) | C31: (racine) | D31: Agrégat
A32: EBITDA | B32: EBITDA | C32: RESULTAT_EXPL | D32: Agrégat
A33: MARGE_CONTRIB | B33: Marge de contribution | C33: EBITDA | D33: Agrégat
A34: SIG_PROD | B34: Produits d'exploitation | C34: MARGE_CONTRIB | D34: Regroupement
A35: SIG_DIR | B35: Coûts directs | C35: MARGE_CONTRIB | D35: Regroupement
A36: SIG_PERS | B36: Charges de personnel | C36: EBITDA | D36: Regroupement
A37: SIG_STRUCT | B37: Charges de structure | C37: EBITDA | D37: Regroupement
A38: SIG_IMP | B38: Impôts & taxes | C38: EBITDA | D38: Regroupement
A39: SIG_DOT | B39: Dotations aux amortissements | C39: RESULTAT_EXPL | D39: Regroupement
A40: 7062 | B40: Prestations de formation — alternance (OPCO) | C40: SIG_PROD | D40: Compte (détail)
A41: 706 | B41: Prestations de formation — scolarité (initial) | C41: SIG_PROD | D41: Compte (détail)
... A62: 6811 | B62: Dotations aux amortissements (D&A) | C62: SIG_DOT | D62: Compte (détail)
A65: Dimension Version (référentiel — prêt Tagetik)
A66: Code version | B66: Libellé | C66: Type | D66: Année
A67: 2024ACT_VDEF | B67: 2024 (N-2) | C67: Actual | D67: 2024
A68: 2025ACT_VDEF | B68: 2025 (N-1) | C68: Actual | D68: 2025
A69: 2026ATT_VDEF | B69: 2026 (Atterr.) | C69: Forecast | D69: 2026

Sheet 06_Compta
A1: COMPTA CHARGÉE — écritures par entité × compte × version (format long, clés Tagetik)
A2: Clés : code entité (marque_ville), compte PCG, poste, version (2023ACT_VDEF / 2024ACT_VDEF / 2025ATT_VDEF). Charges réparties par driver. Somme des comptes = CA & EBITDA du P&L.
A3: Code entité | B3: Entité | C3: Marque | D3: Ville | E3: Compte | F3: Libellé compte | G3: Poste PCG | H3: Sens | I3: Ligne SIG | J3: Version | K3: Exercice | L3: Montant
A4: MBWAY_PARIS | B4: MBway Paris | C4: MBway | D4: Paris | E4: 7062 | F4: Prestations de formation — alternance (OPCO) | G4: 70 — Prestations de services | H4: Produit | I4: Produits | J4: 2024ACT_VDEF | K4: 2024 (N-2) | L4: 2134639
A5: MBWAY_LYON | B5: MBway Lyon | C5: MBway | D5: Lyon | E5: 7062 | F5: Prestations de formation — alternance (OPCO) | G5: 70 — Prestations de services | H5: Produit | I5: Produits | J5: 2024ACT_VDEF | K5: 2024 (N-2) | L5: 1682561
A6: MBWAY_NANTES | B6: MBway Nantes | C6: MBway | D6: Nantes | E6: 7062 | F6: Prestations de formation — alternance (OPCO) | G6: 70 — Prestations de services | H6: Produit | I6: Produits | J6: 2024ACT_VDEF | K6: 2024 (N-2) | L6: 1466714
A7: MBWAY_BORDEAUX | B7: MBway Bordeaux | C7: MBway | D7: Bordeaux | E7: 7062 | F7: Prestations de formation — alternance (OPCO) | G7: 70 — Prestations de services | H7: Produit | I7: Produits | J7: 2024ACT_VDEF | K7: 2024 (N-2) | L7: 1203435
A8: ISCOM_PARIS | B8: ISCOM Paris | C8: ISCOM | D8: Paris | E8: 7062 | F8: Prestations de formation — alternance (OPCO) | G8: 70 — Prestations de services | H8: Produit | I8: Produits | J8: 2024ACT_VDEF | K8: 2024 (N-2) | L8: 1968174
A9: ISCOM_LILLE | B9: ISCOM Lille | C9: ISCOM | D9: Lille | E9: 7062 | F9: Prestations de formation — alternance (OPCO) | G9: 70 — Prestations de services | H9: Produit | I9: Produits | J9: 2024ACT_VDEF | K9: 2024 (N-2) | L9: 1190548
A10: ISCOM_TOULOUSE | B10: ISCOM Toulouse | C10: ISCOM | D10: Toulouse | E10: 7062 | F10: Prestations de formation — alternance (OPCO) | G10: 70 — Prestations de services | H10: Produit | I10: Produits | J10: 2024ACT_VDEF | K10: 2024 (N-2) | L10: 1103880
A11: IPAC_BACHELOR_FACTORY_NANTES | B11: Ipac Bachelor Factory Nantes | C11: Ipac Bachelor Factory | D11: Nantes | E11: 7062 | F11: Prestations de formation — alternance (OPCO) | G11: 70 — Prestations de services | H11: Produit | I11: Produits | J11: 2024ACT_VDEF | K11: 2024 (N-2) | L11: 872197
A12: IPAC_BACHELOR_FACTORY_RENNES | B12: Ipac Bachelor Factory Rennes | C12: Ipac Bachelor Factory | D12: Rennes | E12: 7062 | F12: Prestations de formation — alternance (OPCO) | G12: 70 — Prestations de services | H12: Produit | I12: Produits | J12: 2024ACT_VDEF | K12: 2024 (N-2) | L12: 662869
A13: IPAC_BACHELOR_FACTORY_MONTPELLIER | B13: Ipac Bachelor Factory Montpellier | C13: Ipac Bachelor Factory | D13: Montpellier | E13: 7062 | F13: Prestations de formation — alternance (OPCO) | G13: 70 — Prestations de services | H13: Produit | I13: Produits | J13: 2024ACT_VDEF | K13: 2024 (N-2) | L13: 662869
A14: PIGIER_LYON | B14: Pigier Lyon | C14: Pigier | D14: Lyon | E14: 7062 | F14: Prestations de formation — alternance (OPCO) | G14: 70 — Prestations de services | H14: Produit | I14: Produits | J14: 2024ACT_VDEF | K14: 2024 (N-2) | L14: 1087754
A15: PIGIER_BORDEAUX | B15: Pigier Bordeaux | C15: Pigier | D15: Bordeaux | E15: 7062 | F15: Prestations de formation — alternance (OPCO) | G15: 70 — Prestations de services | H15: Produit | I15: Produits | J15: 2024ACT_VDEF | K15: 2024 (N-2) | L15: 785600
... A675: TUNON_LYON | B675: Tunon Lyon | C675: Tunon | D675: Lyon | E675: 6811 | F675: Dotations aux amortissements (D&A) | G675: 68 — Dotations & amort. | H675: Charge | I675: Dotations | J675: 2026ATT_VDEF | K675: 2026 (Atterr.) | L675: 60747

Sheet 07_PnL
B1: COMPTE DE RÉSULTAT (SIG) — réalisé 2024 · 2025 · atterrissage 2026 · BUDGET 2027 (piloté par le cadrage)
B3: Compte | C3: Libellé | D3: 2024 (N-2) | E3: 2025 (N-1) | F3: 2026 (Atterr.) | G3: 🟢 Budget 2027 | H3: Var Bud/Att %
B4: PRODUITS
B5: 7062 | C5: Prestations de formation — alternance (OPCO) | D5: =SUMIFS('06_Compta'!$L$4:$L$675,'06_Compta'!$E$4:$E$675,"7062",'06_Compta'!$J$4:$J$675,"2024ACT_VDEF") | E5: =SUMIFS('06_Compta'!$L$4:$L$675,'06_Compta'!$E$4:$E$675,"7062",'06_Compta'!$J$4:$J$675,"2025ACT_VDEF") | F5: =SUMIFS('06_Compta'!$L$4:$L$675,'06_Compta'!$E$4:$E$675,"7062",'06_Compta'!$J$4:$J$675,"2026ATT_VDEF") | G5: =F5*('04_Moteur'!$AA$62/21936350) | H5: =IFERROR(G5/F5-1,0)
B6: 706 | C6: Prestations de formation — scolarité (initial) | D6: =SUMIFS('06_Compta'!$L$4:$L$675,'06_Compta'!$E$4:$E$675,"706",'06_Compta'!$J$4:$J$675,"2024ACT_VDEF") | E6: =SUMIFS('06_Compta'!$L$4:$L$675,'06_Compta'!$E$4:$E$675,"706",'06_Compta'!$J$4:$J$675,"2025ACT_VDEF") | F6: =SUMIFS('06_Compta'!$L$4:$L$675,'06_Compta'!$E$4:$E$675,"706",'06_Compta'!$J$4:$J$675,"2026ATT_VDEF") | G6: =F6*('04_Moteur'!$AA$62/21936350) | H6: =IFERROR(G6/F6-1,0)
B7: 708 | C7: Frais de dossier & droits d'inscription | D7: =SUMIFS('06_Compta'!$L$4:$L$675,'06_Compta'!$E$4:$E$675,"708",'06_Compta'!$J$4:$J$675,"2024ACT_VDEF") | E7: =SUMIFS('06_Compta'!$L$4:$L$675,'06_Compta'!$E$4:$E$675,"708",'06_Compta'!$J$4:$J$675,"2025ACT_VDEF") | F7: =SUMIFS('06_Compta'!$L$4:$L$675,'06_Compta'!$E$4:$E$675,"708",'06_Compta'!$J$4:$J$675,"2026ATT_VDEF") | G7: =F7*('04_Moteur'!$AA$62/21936350) | H7: =IFERROR(G7/F7-1,0)
C8: CHIFFRE D'AFFAIRES | D8: =SUMIFS('06_Compta'!$L$4:$L$675,'06_Compta'!$H$4:$H$675,"Produit",'06_Compta'!$J$4:$J$675,"2024ACT_VDEF") | E8: =SUMIFS('06_Compta'!$L$4:$L$675,'06_Compta'!$H$4:$H$675,"Produit",'06_Compta'!$J$4:$J$675,"2025ACT_VDEF") | F8: =SUMIFS('06_Compta'!$L$4:$L$675,'06_Compta'!$H$4:$H$675,"Produit",'06_Compta'!$J$4:$J$675,"2026ATT_VDEF") | G8: =G5+G6+G7 | H8: =IFERROR(G8/F8-1,0)
B9: COÛTS DIRECTS
B10: 621 | C10: Personnel extérieur — vacataires & intervenants | D10: =-SUMIFS('06_Compta'!$L$4:$L$675,'06_Compta'!$E$4:$E$675,"621",'06_Compta'!$J$4:$J$675,"2024ACT_VDEF") | E10: =-SUMIFS('06_Compta'!$L$4:$L$675,'06_Compta'!$E$4:$E$675,"621",'06_Compta'!$J$4:$J$675,"2025ACT_VDEF") | F10: =-SUMIFS('06_Compta'!$L$4:$L$675,'06_Compta'!$E$4:$E$675,"621",'06_Compta'!$J$4:$J$675,"2026ATT_VDEF") | G10: =F10*(('04_Moteur'!$AA$62/21936350)*(1-'01_Cadrage'!$H$24)) | H10: =IFERROR(G10/F10-1,0)
B11: 604 | C11: Sous-traitance pédagogique | D11: =-SUMIFS('06_Compta'!$L$4:$L$675,'06_Compta'!$E$4:$E$675,"604",'06_Compta'!$J$4:$J$675,"2024ACT_VDEF") | E11: =-SUMIFS('06_Compta'!$L$4:$L$675,'06_Compta'!$E$4:$E$675,"604",'06_Compta'!$J$4:$J$675,"2025ACT_VDEF") | F11: =-SUMIFS('06_Compta'!$L$4:$L$675,'06_Compta'!$E$4:$E$675,"604",'06_Compta'!$J$4:$J$675,"2026ATT_VDEF") | G11: =F11*(('04_Moteur'!$AA$62/21936350)*(1-'01_Cadrage'!$H$24)) | H11: =IFERROR(G11/F11-1,0)
B12: 6063 | C12: Fournitures pédagogiques & petit équipement | D12: =-SUMIFS('06_Compta'!$L$4:$L$675,'06_Compta'!$E$4:$E$675,"6063",'06_Compta'!$J$4:$J$675,"2024ACT_VDEF") | E12: =-SUMIFS('06_Compta'!$L$4:$L$675,'06_Compta'!$E$4:$E$675,"6063",'06_Compta'!$J$4:$J$675,"2025ACT_VDEF") | F12: =-SUMIFS('06_Compta'!$L$4:$L$675,'06_Compta'!$E$4:$E$675,"6063",'06_Compta'!$J$4:$J$675,"2026ATT_VDEF") | G12: =F12*(('04_Moteur'!$AA$62/21936350)*(1-'01_Cadrage'!$H$24)) | H12: =IFERROR(G12/F12-1,0)
B13: 6231 | C13: Publicité & marketing d'acquisition (leads) | D13: =-SUMIFS('06_Compta'!$L$4:$L$675,'06_Compta'!$E$4:$E$675,"6231",'06_Compta'!$J$4:$J$675,"2024ACT_VDEF") | E13: =-SUMIFS('06_Compta'!$L$4:$L$675,'06_Compta'!$E$4:$E$675,"6231",'06_Compta'!$J$4:$J$675,"2025ACT_VDEF") | F13: =-SUMIFS('06_Compta'!$L$4:$L$675,'06_Compta'!$E$4:$E$675,"6231",'06_Compta'!$J$4:$J$675,"2026ATT_VDEF") | G13: =F13*(1+'01_Cadrage'!$H$16) | H13: =IFERROR(G13/F13-1,0)
C14: MARGE DE CONTRIBUTION | D14: =SUMIFS('06_Compta'!$L$4:$L$675,'06_Compta'!$H$4:$H$675,"Produit",'06_Compta'!$J$4:$J$675,"2024ACT_VDEF")-SUMIFS('06_Compta'!$L$4:$L$675,'06_Compta'!$I$4:$I$675,"Coûts directs",'06_Compta'!$J$4:$J$675,"2024ACT_VDEF") | E14: =SUMIFS('06_Compta'!$L$4:$L$675,'06_Compta'!$H$4:$H$675,"Produit",'06_Compta'!$J$4:$J$675,"2025ACT_VDEF")-SUMIFS('06_Compta'!$L$4:$L$675,'06_Compta'!$I$4:$I$675,"Coûts directs",'06_Compta'!$J$4:$J$675,"2025ACT_VDEF") | F14: =SUMIFS('06_Compta'!$L$4:$L$675,'06_Compta'!$H$4:$H$675,"Produit",'06_Compta'!$J$4:$J$675,"2026ATT_VDEF")-SUMIFS('06_Compta'!$L$4:$L$675,'06_Compta'!$I$4:$I$675,"Coûts directs",'06_Compta'!$J$4:$J$675,"2026ATT_VDEF") | G14: =G5+G6+G7+G10+G11+G12+G13 | H14: =IFERROR(G14/F14-1,0)
B15: PERSONNEL
B16: 6411 | C16: Rémunération enseignants permanents | D16: =-SUMIFS('06_Compta'!$L$4:$L$675,'06_Compta'!$E$4:$E$675,"6411",'06_Compta'!$J$4:$J$675,"2024ACT_VDEF") | E16: =-SUMIFS('06_Compta'!$L$4:$L$675,'06_Compta'!$E$4:$E$675,"6411",'06_Compta'!$J$4:$J$675,"2025ACT_VDEF") | F16: =-SUMIFS('06_Compta'!$L$4:$L$675,'06_Compta'!$E$4:$E$675,"6411",'06_Compta'!$J$4:$J$675,"2026ATT_VDEF") | G16: =F16*((1+'01_Cadrage'!$H$22)*(1+'01_Cadrage'!$H$23)) | H16: =IFERROR(G16/F16-1,0)
B17: 6413 | C17: Rémunération personnel administratif & pédagogique | D17: =-SUMIFS('06_Compta'!$L$4:$L$675,'06_Compta'!$E$4:$E$675,"6413",'06_Compta'!$J$4:$J$675,"2024ACT_VDEF") | E17: =-SUMIFS('06_Compta'!$L$4:$L$675,'06_Compta'!$E$4:$E$675,"6413",'06_Compta'!$J$4:$J$675,"2025ACT_VDEF") | F17: =-SUMIFS('06_Compta'!$L$4:$L$675,'06_Compta'!$E$4:$E$675,"6413",'06_Compta'!$J$4:$J$675,"2026ATT_VDEF") | G17: =F17*((1+'01_Cadrage'!$H$22)*(1+'01_Cadrage'!$H$23)) | H17: =IFERROR(G17/F17-1,0)
B18: 6414 | C18: Rémunération direction & fonctions support (siège) | D18: =-SUMIFS('06_Compta'!$L$4:$L$675,'06_Compta'!$E$4:$E$675,"6414",'06_Compta'!$J$4:$J$675,"2024ACT_VDEF") | E18: =-SUMIFS('06_Compta'!$L$4:$L$675,'06_Compta'!$E$4:$E$675,"6414",'06_Compta'!$J$4:$J$675,"2025ACT_VDEF") | F18: =-SUMIFS('06_Compta'!$L$4:$L$675,'06_Compta'!$E$4:$E$675,"6414",'06_Compta'!$J$4:$J$675,"2026ATT_VDEF") | G18: =F18*((1+'01_Cadrage'!$H$22)*(1+'01_Cadrage'!$H$23)) | H18: =IFERROR(G18/F18-1,0)
B19: 645 | C19: Charges sociales & de prévoyance | D19: =-SUMIFS('06_Compta'!$L$4:$L$675,'06_Compta'!$E$4:$E$675,"645",'06_Compta'!$J$4:$J$675,"2024ACT_VDEF") | E19: =-SUMIFS('06_Compta'!$L$4:$L$675,'06_Compta'!$E$4:$E$675,"645",'06_Compta'!$J$4:$J$675,"2025ACT_VDEF") | F19: =-SUMIFS('06_Compta'!$L$4:$L$675,'06_Compta'!$E$4:$E$675,"645",'06_Compta'!$J$4:$J$675,"2026ATT_VDEF") | G19: =F19*((1+'01_Cadrage'!$H$22)*(1+'01_Cadrage'!$H$23)) | H19: =IFERROR(G19/F19-1,0)
B20: STRUCTURE
B21: 613 | C21: Loyers & charges locatives (campus) | D21: =-SUMIFS('06_Compta'!$L$4:$L$675,'06_Compta'!$E$4:$E$675,"613",'06_Compta'!$J$4:$J$675,"2024ACT_VDEF") | E21: =-SUMIFS('06_Compta'!$L$4:$L$675,'06_Compta'!$E$4:$E$675,"613",'06_Compta'!$J$4:$J$675,"2025ACT_VDEF") | F21: =-SUMIFS('06_Compta'!$L$4:$L$675,'06_Compta'!$E$4:$E$675,"613",'06_Compta'!$J$4:$J$675,"2026ATT_VDEF") | G21: =F21*((1+'01_Cadrage'!$H$21)*(1-'01_Cadrage'!$H$24)) | H21: =IFERROR(G21/F21-1,0)
B22: 615 | C22: Entretien & maintenance | D22: =-SUMIFS('06_Compta'!$L$4:$L$675,'06_Compta'!$E$4:$E$675,"615",'06_Compta'!$J$4:$J$675,"2024ACT_VDEF") | E22: =-SUMIFS('06_Compta'!$L$4:$L$675,'06_Compta'!$E$4:$E$675,"615",'06_Compta'!$J$4:$J$675,"2025ACT_VDEF") | F22: =-SUMIFS('06_Compta'!$L$4:$L$675,'06_Compta'!$E$4:$E$675,"615",'06_Compta'!$J$4:$J$675,"2026ATT_VDEF") | G22: =F22*((1+'01_Cadrage'!$H$21)*(1-'01_Cadrage'!$H$24)) | H22: =IFERROR(G22/F22-1,0)
B23: 616 | C23: Primes d'assurance | D23: =-SUMIFS('06_Compta'!$L$4:$L$675,'06_Compta'!$E$4:$E$675,"616",'06_Compta'!$J$4:$J$675,"2024ACT_VDEF") | E23: =-SUMIFS('06_Compta'!$L$4:$L$675,'06_Compta'!$E$4:$E$675,"616",'06_Compta'!$J$4:$J$675,"2025ACT_VDEF") | F23: =-SUMIFS('06_Compta'!$L$4:$L$675,'06_Compta'!$E$4:$E$675,"616",'06_Compta'!$J$4:$J$675,"2026ATT_VDEF") | G23: =F23*((1+'01_Cadrage'!$H$21)*(1-'01_Cadrage'!$H$24)) | H23: =IFERROR(G23/F23-1,0)
