Workbook

Sheet Pilotage
B1: EDUSERVICES · budget 2027 piloté par l'EBITDA | O1: code scénario -> | P1: =IF($E$6="Cadrage","V01",IF($E$6="Optimiste","V02","V03"))
B2: PILOTAGE · le cockpit, campus par campus
B6: Scénario actif : | E6: Cadrage | G6: il commande les deux tableaux ci-dessous
B9: CHIFFRE D'AFFAIRES 2027 | D9: EBITDA APRÈS SIÈGE | F9: MARGE D'EBITDA | H9: EFFECTIF | J9: CROISSANCE DU CA
B10: =E55 | D10: =H55 | F10: =I55 | H10: =D55 | J10: =IFERROR(E55/Cadrage!$C$12-1,0)
B11: ="contre "&TEXT(Cadrage!$C$12,"#,##0 €")&" en 2026" | D11: ="contre "&TEXT(Cadrage!$C$13,"#,##0 €")&" en 2026" | F11: ="contre "&TEXT(Cadrage!$C$14,"0.0%")&" en 2026" | H11: ="contre "&TEXT(Cadrage!$C$15,"#,##0")&" en 2026" | J11: vs 2026 — la correction du patch
B16: ① CAP STRATÉGIQUE PAR CAMPUS
B17: Le cap retenu redistribue le budget d'acquisition entre campus, à enveloppe constante. Colonnes bleutées : elles viennent de l'onglet Campagne et se réalignent toutes seules sur le campus.
A18: Campus | B18: Marque | C18: Ville | D18: CAC marginal | E18: Croiss. leads | F18: Intensité mkt | G18: Cap effectif | H18: Cap moment | I18: Cap potentiel | J18: CAP RETENU | K18: Budget acq. réf.
A19: MBWAY_PAR | B19: MBway | C19: Paris | D19: =SUMIFS(Campagne!$N$2:$N$15,Campagne!$C$2:$C$15,$A19) | E19: 0.110736 | F19: 0.021756 | G19: 0.81498244 | H19: 1.059715 | I19: 0.842823 | J19: 1 | K19: =SUMIFS(Campagne!$G$2:$G$15,Campagne!$C$2:$C$15,$A19) | L19: =$A19
A20: MBWAY_LYO | B20: MBway | C20: Lyon | D20: =SUMIFS(Campagne!$N$2:$N$15,Campagne!$C$2:$C$15,$A20) | E20: 0.118871 | F20: 0.016735 | G20: 1.0912396 | H20: 1.137565 | I20: 1.095717 | J20: 1 | K20: =SUMIFS(Campagne!$G$2:$G$15,Campagne!$C$2:$C$15,$A20) | L20: =$A20
A21: MBWAY_NAN | B21: MBway | C21: Nantes | D21: =SUMIFS(Campagne!$N$2:$N$15,Campagne!$C$2:$C$15,$A21) | E21: 0.123795 | F21: 0.01461 | G21: 1.2475546 | H21: 1.184686 | I21: 1.255097 | J21: 1 | K21: =SUMIFS(Campagne!$G$2:$G$15,Campagne!$C$2:$C$15,$A21) | L21: =$A21
A22: MBWAY_BOR | B22: MBway | C22: Bordeaux | D22: =SUMIFS(Campagne!$N$2:$N$15,Campagne!$C$2:$C$15,$A22) | E22: 0.126094 | F22: 0.014052 | G22: 1.3513083 | H22: 1.206687 | I22: 1.304934 | J22: 1 | K22: =SUMIFS(Campagne!$G$2:$G$15,Campagne!$C$2:$C$15,$A22) | L22: =$A22
A23: ISCOM_PAR | B23: ISCOM | C23: Paris | D23: =SUMIFS(Campagne!$N$2:$N$15,Campagne!$C$2:$C$15,$A23) | E23: 0.077744 | F23: 0.020902 | G23: 0.78042932 | H23: 0.74399 | I23: 0.877261 | J23: 1 | K23: =SUMIFS(Campagne!$G$2:$G$15,Campagne!$C$2:$C$15,$A23) | L23: =$A23
A24: ISCOM_LIL | B24: ISCOM | C24: Lille | D24: =SUMIFS(Campagne!$N$2:$N$15,Campagne!$C$2:$C$15,$A24) | E24: 0.081545 | F24: 0.014363 | G24: 1.2284219 | H24: 0.780364 | I24: 1.276654 | J24: 1 | K24: =SUMIFS(Campagne!$G$2:$G$15,Campagne!$C$2:$C$15,$A24) | L24: =$A24
A25: ISCOM_TLS | B25: ISCOM | C25: Toulouse | D25: =SUMIFS(Campagne!$N$2:$N$15,Campagne!$C$2:$C$15,$A25) | E25: 0.082116 | F25: 0.013564 | G25: 1.3080188 | H25: 0.785829 | I25: 1.351829 | J25: 1 | K25: =SUMIFS(Campagne!$G$2:$G$15,Campagne!$C$2:$C$15,$A25) | L25: =$A25
A26: IPAC_NAN | B26: Ipac | C26: Nantes | D26: =SUMIFS(Campagne!$N$2:$N$15,Campagne!$C$2:$C$15,$A26) | E26: 0.137884 | F26: 0.021343 | G26: 0.98834297 | H26: 1.319514 | I26: 0.85913 | J26: 1 | K26: =SUMIFS(Campagne!$G$2:$G$15,Campagne!$C$2:$C$15,$A26) | L26: =$A26
A27: IPAC_REN | B27: Ipac | C27: Rennes | D27: =SUMIFS(Campagne!$N$2:$N$15,Campagne!$C$2:$C$15,$A27) | E27: 0.144781 | F27: 0.019104 | G27: 1.1552615 | H27: 1.385517 | I27: 0.959834 | J27: 1 | K27: =SUMIFS(Campagne!$G$2:$G$15,Campagne!$C$2:$C$15,$A27) | L27: =$A27
A28: IPAC_MTP | B28: Ipac | C28: Montpellier | D28: =SUMIFS(Campagne!$N$2:$N$15,Campagne!$C$2:$C$15,$A28) | E28: 0.144781 | F28: 0.019417 | G28: 1.1626041 | H28: 1.385517 | I28: 0.94434 | J28: 1 | K28: =SUMIFS(Campagne!$G$2:$G$15,Campagne!$C$2:$C$15,$A28) | L28: =$A28
A29: PIGIER_LYO | B29: Pigier | C29: Lyon | D29: =SUMIFS(Campagne!$N$2:$N$15,Campagne!$C$2:$C$15,$A29) | E29: 0.085003 | F29: 0.023262 | G29: 0.70505903 | H29: 0.813456 | I29: 0.788252 | J29: 1 | K29: =SUMIFS(Campagne!$G$2:$G$15,Campagne!$C$2:$C$15,$A29) | L29: =$A29
A30: PIGIER_BOR | B30: Pigier | C30: Bordeaux | D30: =SUMIFS(Campagne!$N$2:$N$15,Campagne!$C$2:$C$15,$A30) | E30: 0.087533 | F30: 0.019395 | G30: 0.87868042 | H30: 0.837668 | I30: 0.945444 | J30: 1 | K30: =SUMIFS(Campagne!$G$2:$G$15,Campagne!$C$2:$C$15,$A30) | L30: =$A30
... A32: TUNON_LYO | B32: Tunon | C32: Lyon | D32: =SUMIFS(Campagne!$N$2:$N$15,Campagne!$C$2:$C$15,$A32) | E32: 0.072555 | F32: 0.021828 | G32: 0.73991025 | H32: 0.694332 | I32: 0.840053 | J32: 1 | K32: =SUMIFS(Campagne!$G$2:$G$15,Campagne!$C$2:$C$15,$A32) | L32: =$A32
B33: La colonne CAP RETENU est la seule saisie de cette feuille. À 1 partout, la répartition d'origine est conservée.
B36: ② SYNTHÈSE PAR CAMPUS · du chiffre d'affaires à l'EBITDA
B37: Tout est calculé : chaque ligne interroge le moteur et le P&L par le nom du campus. Le sous-total campus, la quote-part du siège, puis le groupe.
A38: Campus | B38: Marque | C38: Ville | D38: Effectif | E38: CA 2027 | F38: Prix moyen | G38: Part du CA | H38: EBITDA campus | I38: Marge EBITDA | J38: EBITDA / étudiant | K38: Budget rejoué | L38: CAC marginal
A39: MBWAY_PAR | B39: MBway | C39: Paris | D39: =SUMIFS(Moteur!$P$1:$P$200,Moteur!$D$1:$D$200,$A39,Moteur!$B$1:$B$200,$P$1) | E39: =SUMIFS(Moteur!$R$1:$R$200,Moteur!$D$1:$D$200,$A39,Moteur!$B$1:$B$200,$P$1) | F39: =IFERROR(E39/D39,0) | G39: =IFERROR(E39/SUM($E$39:$E$52),0) | H39: =SUMIFS(_CALC_PNL!$T$1:$T$1347,_CALC_PNL!$A$1:$A$1347,$A39,_CALC_PNL!$D$1:$D$1347,$P$1,_CALC_PNL!$C$1:$C$1347,"2027") | I39: =IFERROR(H39/E39,0) | J39: =IFERROR(H39/D39,0) | K39: =SUMIFS(Pilotage!$K$19:$K$32,Pilotage!$A$19:$A$32,$A39)*SUMIFS(Pilotage!$J$19:$J$32,Pilotage!$A$19:$A$32,$A39)*(SUM(Pilotage!$K$19:$K$32)/SUMPRODUCT(Pilotage!$K$19:$K$32,Pilotage!$J$19:$J$32)) | L39: =SUMIFS(Pilotage!$D$19:$D$32,Pilotage!$A$19:$A$32,$A39)
A40: MBWAY_LYO | B40: MBway | C40: Lyon | D40: =SUMIFS(Moteur!$P$1:$P$200,Moteur!$D$1:$D$200,$A40,Moteur!$B$1:$B$200,$P$1) | E40: =SUMIFS(Moteur!$R$1:$R$200,Moteur!$D$1:$D$200,$A40,Moteur!$B$1:$B$200,$P$1) | F40: =IFERROR(E40/D40,0) | G40: =IFERROR(E40/SUM($E$39:$E$52),0) | H40: =SUMIFS(_CALC_PNL!$T$1:$T$1347,_CALC_PNL!$A$1:$A$1347,$A40,_CALC_PNL!$D$1:$D$1347,$P$1,_CALC_PNL!$C$1:$C$1347,"2027") | I40: =IFERROR(H40/E40,0) | J40: =IFERROR(H40/D40,0) | K40: =SUMIFS(Pilotage!$K$19:$K$32,Pilotage!$A$19:$A$32,$A40)*SUMIFS(Pilotage!$J$19:$J$32,Pilotage!$A$19:$A$32,$A40)*(SUM(Pilotage!$K$19:$K$32)/SUMPRODUCT(Pilotage!$K$19:$K$32,Pilotage!$J$19:$J$32)) | L40: =SUMIFS(Pilotage!$D$19:$D$32,Pilotage!$A$19:$A$32,$A40)
A41: MBWAY_NAN | B41: MBway | C41: Nantes | D41: =SUMIFS(Moteur!$P$1:$P$200,Moteur!$D$1:$D$200,$A41,Moteur!$B$1:$B$200,$P$1) | E41: =SUMIFS(Moteur!$R$1:$R$200,Moteur!$D$1:$D$200,$A41,Moteur!$B$1:$B$200,$P$1) | F41: =IFERROR(E41/D41,0) | G41: =IFERROR(E41/SUM($E$39:$E$52),0) | H41: =SUMIFS(_CALC_PNL!$T$1:$T$1347,_CALC_PNL!$A$1:$A$1347,$A41,_CALC_PNL!$D$1:$D$1347,$P$1,_CALC_PNL!$C$1:$C$1347,"2027") | I41: =IFERROR(H41/E41,0) | J41: =IFERROR(H41/D41,0) | K41: =SUMIFS(Pilotage!$K$19:$K$32,Pilotage!$A$19:$A$32,$A41)*SUMIFS(Pilotage!$J$19:$J$32,Pilotage!$A$19:$A$32,$A41)*(SUM(Pilotage!$K$19:$K$32)/SUMPRODUCT(Pilotage!$K$19:$K$32,Pilotage!$J$19:$J$32)) | L41: =SUMIFS(Pilotage!$D$19:$D$32,Pilotage!$A$19:$A$32,$A41)
A42: MBWAY_BOR | B42: MBway | C42: Bordeaux | D42: =SUMIFS(Moteur!$P$1:$P$200,Moteur!$D$1:$D$200,$A42,Moteur!$B$1:$B$200,$P$1) | E42: =SUMIFS(Moteur!$R$1:$R$200,Moteur!$D$1:$D$200,$A42,Moteur!$B$1:$B$200,$P$1) | F42: =IFERROR(E42/D42,0) | G42: =IFERROR(E42/SUM($E$39:$E$52),0) | H42: =SUMIFS(_CALC_PNL!$T$1:$T$1347,_CALC_PNL!$A$1:$A$1347,$A42,_CALC_PNL!$D$1:$D$1347,$P$1,_CALC_PNL!$C$1:$C$1347,"2027") | I42: =IFERROR(H42/E42,0) | J42: =IFERROR(H42/D42,0) | K42: =SUMIFS(Pilotage!$K$19:$K$32,Pilotage!$A$19:$A$32,$A42)*SUMIFS(Pilotage!$J$19:$J$32,Pilotage!$A$19:$A$32,$A42)*(SUM(Pilotage!$K$19:$K$32)/SUMPRODUCT(Pilotage!$K$19:$K$32,Pilotage!$J$19:$J$32)) | L42: =SUMIFS(Pilotage!$D$19:$D$32,Pilotage!$A$19:$A$32,$A42)
A43: ISCOM_PAR | B43: ISCOM | C43: Paris | D43: =SUMIFS(Moteur!$P$1:$P$200,Moteur!$D$1:$D$200,$A43,Moteur!$B$1:$B$200,$P$1) | E43: =SUMIFS(Moteur!$R$1:$R$200,Moteur!$D$1:$D$200,$A43,Moteur!$B$1:$B$200,$P$1) | F43: =IFERROR(E43/D43,0) | G43: =IFERROR(E43/SUM($E$39:$E$52),0) | H43: =SUMIFS(_CALC_PNL!$T$1:$T$1347,_CALC_PNL!$A$1:$A$1347,$A43,_CALC_PNL!$D$1:$D$1347,$P$1,_CALC_PNL!$C$1:$C$1347,"2027") | I43: =IFERROR(H43/E43,0) | J43: =IFERROR(H43/D43,0) | K43: =SUMIFS(Pilotage!$K$19:$K$32,Pilotage!$A$19:$A$32,$A43)*SUMIFS(Pilotage!$J$19:$J$32,Pilotage!$A$19:$A$32,$A43)*(SUM(Pilotage!$K$19:$K$32)/SUMPRODUCT(Pilotage!$K$19:$K$32,Pilotage!$J$19:$J$32)) | L43: =SUMIFS(Pilotage!$D$19:$D$32,Pilotage!$A$19:$A$32,$A43)
A44: ISCOM_LIL | B44: ISCOM | C44: Lille | D44: =SUMIFS(Moteur!$P$1:$P$200,Moteur!$D$1:$D$200,$A44,Moteur!$B$1:$B$200,$P$1) | E44: =SUMIFS(Moteur!$R$1:$R$200,Moteur!$D$1:$D$200,$A44,Moteur!$B$1:$B$200,$P$1) | F44: =IFERROR(E44/D44,0) | G44: =IFERROR(E44/SUM($E$39:$E$52),0) | H44: =SUMIFS(_CALC_PNL!$T$1:$T$1347,_CALC_PNL!$A$1:$A$1347,$A44,_CALC_PNL!$D$1:$D$1347,$P$1,_CALC_PNL!$C$1:$C$1347,"2027") | I44: =IFERROR(H44/E44,0) | J44: =IFERROR(H44/D44,0) | K44: =SUMIFS(Pilotage!$K$19:$K$32,Pilotage!$A$19:$A$32,$A44)*SUMIFS(Pilotage!$J$19:$J$32,Pilotage!$A$19:$A$32,$A44)*(SUM(Pilotage!$K$19:$K$32)/SUMPRODUCT(Pilotage!$K$19:$K$32,Pilotage!$J$19:$J$32)) | L44: =SUMIFS(Pilotage!$D$19:$D$32,Pilotage!$A$19:$A$32,$A44)
A45: ISCOM_TLS | B45: ISCOM | C45: Toulouse | D45: =SUMIFS(Moteur!$P$1:$P$200,Moteur!$D$1:$D$200,$A45,Moteur!$B$1:$B$200,$P$1) | E45: =SUMIFS(Moteur!$R$1:$R$200,Moteur!$D$1:$D$200,$A45,Moteur!$B$1:$B$200,$P$1) | F45: =IFERROR(E45/D45,0) | G45: =IFERROR(E45/SUM($E$39:$E$52),0) | H45: =SUMIFS(_CALC_PNL!$T$1:$T$1347,_CALC_PNL!$A$1:$A$1347,$A45,_CALC_PNL!$D$1:$D$1347,$P$1,_CALC_PNL!$C$1:$C$1347,"2027") | I45: =IFERROR(H45/E45,0) | J45: =IFERROR(H45/D45,0) | K45: =SUMIFS(Pilotage!$K$19:$K$32,Pilotage!$A$19:$A$32,$A45)*SUMIFS(Pilotage!$J$19:$J$32,Pilotage!$A$19:$A$32,$A45)*(SUM(Pilotage!$K$19:$K$32)/SUMPRODUCT(Pilotage!$K$19:$K$32,Pilotage!$J$19:$J$32)) | L45: =SUMIFS(Pilotage!$D$19:$D$32,Pilotage!$A$19:$A$32,$A45)
A46: IPAC_NAN | B46: Ipac | C46: Nantes | D46: =SUMIFS(Moteur!$P$1:$P$200,Moteur!$D$1:$D$200,$A46,Moteur!$B$1:$B$200,$P$1) | E46: =SUMIFS(Moteur!$R$1:$R$200,Moteur!$D$1:$D$200,$A46,Moteur!$B$1:$B$200,$P$1) | F46: =IFERROR(E46/D46,0) | G46: =IFERROR(E46/SUM($E$39:$E$52),0) | H46: =SUMIFS(_CALC_PNL!$T$1:$T$1347,_CALC_PNL!$A$1:$A$1347,$A46,_CALC_PNL!$D$1:$D$1347,$P$1,_CALC_PNL!$C$1:$C$1347,"2027") | I46: =IFERROR(H46/E46,0) | J46: =IFERROR(H46/D46,0) | K46: =SUMIFS(Pilotage!$K$19:$K$32,Pilotage!$A$19:$A$32,$A46)*SUMIFS(Pilotage!$J$19:$J$32,Pilotage!$A$19:$A$32,$A46)*(SUM(Pilotage!$K$19:$K$32)/SUMPRODUCT(Pilotage!$K$19:$K$32,Pilotage!$J$19:$J$32)) | L46: =SUMIFS(Pilotage!$D$19:$D$32,Pilotage!$A$19:$A$32,$A46)
A47: IPAC_REN | B47: Ipac | C47: Rennes | D47: =SUMIFS(Moteur!$P$1:$P$200,Moteur!$D$1:$D$200,$A47,Moteur!$B$1:$B$200,$P$1) | E47: =SUMIFS(Moteur!$R$1:$R$200,Moteur!$D$1:$D$200,$A47,Moteur!$B$1:$B$200,$P$1) | F47: =IFERROR(E47/D47,0) | G47: =IFERROR(E47/SUM($E$39:$E$52),0) | H47: =SUMIFS(_CALC_PNL!$T$1:$T$1347,_CALC_PNL!$A$1:$A$1347,$A47,_CALC_PNL!$D$1:$D$1347,$P$1,_CALC_PNL!$C$1:$C$1347,"2027") | I47: =IFERROR(H47/E47,0) | J47: =IFERROR(H47/D47,0) | K47: =SUMIFS(Pilotage!$K$19:$K$32,Pilotage!$A$19:$A$32,$A47)*SUMIFS(Pilotage!$J$19:$J$32,Pilotage!$A$19:$A$32,$A47)*(SUM(Pilotage!$K$19:$K$32)/SUMPRODUCT(Pilotage!$K$19:$K$32,Pilotage!$J$19:$J$32)) | L47: =SUMIFS(Pilotage!$D$19:$D$32,Pilotage!$A$19:$A$32,$A47)
A48: IPAC_MTP | B48: Ipac | C48: Montpellier | D48: =SUMIFS(Moteur!$P$1:$P$200,Moteur!$D$1:$D$200,$A48,Moteur!$B$1:$B$200,$P$1) | E48: =SUMIFS(Moteur!$R$1:$R$200,Moteur!$D$1:$D$200,$A48,Moteur!$B$1:$B$200,$P$1) | F48: =IFERROR(E48/D48,0) | G48: =IFERROR(E48/SUM($E$39:$E$52),0) | H48: =SUMIFS(_CALC_PNL!$T$1:$T$1347,_CALC_PNL!$A$1:$A$1347,$A48,_CALC_PNL!$D$1:$D$1347,$P$1,_CALC_PNL!$C$1:$C$1347,"2027") | I48: =IFERROR(H48/E48,0) | J48: =IFERROR(H48/D48,0) | K48: =SUMIFS(Pilotage!$K$19:$K$32,Pilotage!$A$19:$A$32,$A48)*SUMIFS(Pilotage!$J$19:$J$32,Pilotage!$A$19:$A$32,$A48)*(SUM(Pilotage!$K$19:$K$32)/SUMPRODUCT(Pilotage!$K$19:$K$32,Pilotage!$J$19:$J$32)) | L48: =SUMIFS(Pilotage!$D$19:$D$32,Pilotage!$A$19:$A$32,$A48)
A49: PIGIER_LYO | B49: Pigier | C49: Lyon | D49: =SUMIFS(Moteur!$P$1:$P$200,Moteur!$D$1:$D$200,$A49,Moteur!$B$1:$B$200,$P$1) | E49: =SUMIFS(Moteur!$R$1:$R$200,Moteur!$D$1:$D$200,$A49,Moteur!$B$1:$B$200,$P$1) | F49: =IFERROR(E49/D49,0) | G49: =IFERROR(E49/SUM($E$39:$E$52),0) | H49: =SUMIFS(_CALC_PNL!$T$1:$T$1347,_CALC_PNL!$A$1:$A$1347,$A49,_CALC_PNL!$D$1:$D$1347,$P$1,_CALC_PNL!$C$1:$C$1347,"2027") | I49: =IFERROR(H49/E49,0) | J49: =IFERROR(H49/D49,0) | K49: =SUMIFS(Pilotage!$K$19:$K$32,Pilotage!$A$19:$A$32,$A49)*SUMIFS(Pilotage!$J$19:$J$32,Pilotage!$A$19:$A$32,$A49)*(SUM(Pilotage!$K$19:$K$32)/SUMPRODUCT(Pilotage!$K$19:$K$32,Pilotage!$J$19:$J$32)) | L49: =SUMIFS(Pilotage!$D$19:$D$32,Pilotage!$A$19:$A$32,$A49)
A50: PIGIER_BOR | B50: Pigier | C50: Bordeaux | D50: =SUMIFS(Moteur!$P$1:$P$200,Moteur!$D$1:$D$200,$A50,Moteur!$B$1:$B$200,$P$1) | E50: =SUMIFS(Moteur!$R$1:$R$200,Moteur!$D$1:$D$200,$A50,Moteur!$B$1:$B$200,$P$1) | F50: =IFERROR(E50/D50,0) | G50: =IFERROR(E50/SUM($E$39:$E$52),0) | H50: =SUMIFS(_CALC_PNL!$T$1:$T$1347,_CALC_PNL!$A$1:$A$1347,$A50,_CALC_PNL!$D$1:$D$1347,$P$1,_CALC_PNL!$C$1:$C$1347,"2027") | I50: =IFERROR(H50/E50,0) | J50: =IFERROR(H50/D50,0) | K50: =SUMIFS(Pilotage!$K$19:$K$32,Pilotage!$A$19:$A$32,$A50)*SUMIFS(Pilotage!$J$19:$J$32,Pilotage!$A$19:$A$32,$A50)*(SUM(Pilotage!$K$19:$K$32)/SUMPRODUCT(Pilotage!$K$19:$K$32,Pilotage!$J$19:$J$32)) | L50: =SUMIFS(Pilotage!$D$19:$D$32,Pilotage!$A$19:$A$32,$A50)
... A52: TUNON_LYO | B52: Tunon | C52: Lyon | D52: =SUMIFS(Moteur!$P$1:$P$200,Moteur!$D$1:$D$200,$A52,Moteur!$B$1:$B$200,$P$1) | E52: =SUMIFS(Moteur!$R$1:$R$200,Moteur!$D$1:$D$200,$A52,Moteur!$B$1:$B$200,$P$1) | F52: =IFERROR(E52/D52,0) | G52: =IFERROR(E52/SUM($E$39:$E$52),0) | H52: =SUMIFS(_CALC_PNL!$T$1:$T$1347,_CALC_PNL!$A$1:$A$1347,$A52,_CALC_PNL!$D$1:$D$1347,$P$1,_CALC_PNL!$C$1:$C$1347,"2027") | I52: =IFERROR(H52/E52,0) | J52: =IFERROR(H52/D52,0) | K52: =SUMIFS(Pilotage!$K$19:$K$32,Pilotage!$A$19:$A$32,$A52)*SUMIFS(Pilotage!$J$19:$J$32,Pilotage!$A$19:$A$32,$A52)*(SUM(Pilotage!$K$19:$K$32)/SUMPRODUCT(Pilotage!$K$19:$K$32,Pilotage!$J$19:$J$32)) | L52: =SUMIFS(Pilotage!$D$19:$D$32,Pilotage!$A$19:$A$32,$A52)
A53: Sous-total campus | D53: =SUM(D39:D52) | E53: =SUM(E39:E52) | F53: =IFERROR(E53/D53,0) | G53: =SUM(G39:G52) | H53: =SUM(H39:H52) | I53: =IFERROR(H53/E53,0) | J53: =IFERROR(H53/D53,0) | K53: =SUM(K39:K52)
...
