Workbook
Name ALLOC_BRAND_CAMP: ALLOC!$C$8
Name ALLOC_CAMP_CLASS: ALLOC!$C$9
Name ALLOC_GRP_BRAND: ALLOC!$C$6
Name ALLOC_GRP_MARQUE: ALLOC!$C$7
Name BUD_REF_CAP: PIL!$K$15:$K$28
Name HYP_ACQ_BUD_V01: cad!$C$23
Name HYP_ACQ_BUD_V02: cad!$D$23
Name HYP_ACQ_BUD_V03: cad!$E$23
Name HYP_BRAND_BUD_V01: cad!$C$24
Name HYP_BRAND_BUD_V02: cad!$D$24
Name HYP_BRAND_BUD_V03: cad!$E$24
Name HYP_CAP_RETENU: PIL!$J$15:$J$28
Name HYP_CONV_ADM_V01: cad!$C$27
Name HYP_CONV_ADM_V02: cad!$D$27
Name HYP_CONV_ADM_V03: cad!$E$27
Name HYP_CONV_LEAD_V01: cad!$C$26
Name HYP_CONV_LEAD_V02: cad!$D$26
Name HYP_CONV_LEAD_V03: cad!$E$26
Name HYP_FEE_V01: cad!$C$39
Name HYP_FEE_V02: cad!$D$39
Name HYP_FEE_V03: cad!$E$39
Name HYP_FTE_PERM_V01: cad!$C$34
Name HYP_FTE_PERM_V02: cad!$D$34
Name HYP_FTE_PERM_V03: cad!$E$34
Name HYP_INFL_EXT_V01: cad!$C$32
Name HYP_INFL_EXT_V02: cad!$D$32
Name HYP_INFL_EXT_V03: cad!$E$32
Name HYP_PASSAGE_V01: cad!$C$28
Name HYP_PASSAGE_V02: cad!$D$28
Name HYP_PASSAGE_V03: cad!$E$28
Name HYP_PRICE_COEF_IPAC: cad!$J$14
Name HYP_PRICE_COEF_ISCOM: cad!$J$13
Name HYP_PRICE_COEF_MBWAY: cad!$J$12
Name HYP_PRICE_COEF_PIGIER: cad!$J$15
Name HYP_PRICE_COEF_TUNON: cad!$J$16
Name HYP_PRICE_V01: cad!$C$25
Name HYP_PRICE_V02: cad!$D$25
Name HYP_PRICE_V03: cad!$E$25
Name HYP_PRODUCTIVITY_V01: cad!$C$35
Name HYP_PRODUCTIVITY_V02: cad!$D$35
Name HYP_PRODUCTIVITY_V03: cad!$E$35
Name HYP_SALARY_V01: cad!$C$33
Name HYP_SALARY_V02: cad!$D$33
Name HYP_SALARY_V03: cad!$E$33
Name HYP_STRUCT_COST_V01: cad!$C$36
Name HYP_STRUCT_COST_V02: cad!$D$36
Name HYP_STRUCT_COST_V03: cad!$E$36
Name SCENARIO_ACTIF: cad!$C$5
Name SCENARIO_CODE: cad!$P$1
Name TEC_EBITDA: cad!$F$6
Name TEC_PL: cad!$F$5

Sheet _TGK_HIDDEN
A1: Template00 | B1: =cad!A65546 -> 0
A2: Template01 | B2: =Socle!A65536 -> 0
A3: Template02 | B3: =Campagne!A65536 -> 0
A4: Template03 | B4: =Moteur!A65536 -> 0
A5: Template04 | B5: =Compta!A65536 -> 0
A6: Template05 | B6: =PNL!A65536 -> 0
A7: Template06 | B7: =PIL!A65538 -> 0
A9: Template08 | B9: =Allocation!A65536 -> 0
A10: Template09 | B10: =ALLOC!B65537 -> 0

Sheet cad
P1: =IF(cad!$C$5="Optimiste","V02",IF(cad!$C$5="Prudent","V03","V01")) -> V02
B2: POSTE DE COMMANDE CFO — Cadrage CA & EBITDA 2027
B5: Scenario actif : | C5: Optimiste | E5: Croissance CA cible : | F5: 0.05
E6: Marge EBITDA cible : | F6: 0.15
B8: Reconciliation — Reference · Cible · Construit (scenario actif) | I8: Coeff prix par marque (decision)
B10: Indicateur | C10: Reference | D10: Cible | E10: Construit | F10: Ecart | G10: Ecart % | I10: Marque | J10: Coeff prix
C11: 2026
B12: Chiffre d'affaires | C12: 22544725 | D12: =C12*(1+cad!$F$5) -> 23671961 | E12: =_xlfn.SUMIFS(Moteur!$R$1:$R$175,Moteur!$B$1:$B$175,cad!$P$1) -> #VALUE! | F12: =E12-D12 -> #VALUE! | G12: =_xlfn.IFERROR(E12/D12-1,0) -> 0 | I12: MBway | J12: 1.2
B13: EBITDA | C13: 3291530 | D13: =D12*cad!$F$6 -> 3550794.2 | E13: =_xlfn.SUMIFS(_CALC_PNL!$T$1:$T$1347,_CALC_PNL!$D$1:$D$1347,cad!$P$1,_CALC_PNL!$C$1:$C$1347,"2027") -> #VALUE! | F13: =E13-D13 -> #VALUE! | G13: =_xlfn.IFERROR(E13/D13-1,0) -> 0 | I13: ISCOM | J13: 1.15
B14: Marge EBITDA % | C14: =_xlfn.IFERROR(C13/C12,0) -> 0.14600001 | D14: =cad!$F$6 -> 0.15 | E14: =_xlfn.IFERROR(E13/E12,0) -> 0 | F14: =E14-D14 -> -0.15 | I14: Ipac Bachelor Factory | J14: 0.95
B15: Effectif | C15: 3036 | E15: =_xlfn.SUMIFS(Moteur!$P$1:$P$175,Moteur!$B$1:$B$175,cad!$P$1) -> #VALUE! | F15: =E15-#REF! -> #VALUE! | G15: =_xlfn.IFERROR(E15/#REF!-1,0) -> 0 | I15: Pigier | J15: 0.9
I16: Tunon | J16: 1.05
B19: Leviers de CROISSANCE / REVENUS
B21: Paramètre | C21: =C22 -> Cadrage | D21: =D22 -> Optimiste | E21: =E22 -> Prudent | F21: ACTIF (scenario)
C22: Cadrage | D22: Optimiste | E22: Prudent
B23: Variation du budget d'acquisition → leads payants | C23: 0.08 | D23: 0.15 | E23: -0.05 | F23: #N/A
B24: Variation du budget de marque → socle organique | C24: 0.1 | D24: 0.2 | E24: -0.05 | F24: #N/A
B25: Hausse tarifaire (prix) | C25: 0.02 | D25: 0.035 | E25: 0.02 | F25: #N/A
B26: Gain du taux de conversion Lead → Candidature | C26: 0.01 | D26: 0.03 | E26: -0.01 | F26: #N/A
B27: Gain du taux de conversion Admis → Inscrit | C27: 0.01 | D27: 0.025 | E27: -0.01 | F27: #N/A
B28: Amélioration du taux de passage | C28: 0.005 | D28: 0.015 | E28: -0.01 | F28: #N/A
B30: Leviers de COUTS
B32: Inflation des charges externes | C32: 0.02 | D32: 0.015 | E32: 0.03 | F32: =INDEX(C32:E32,MATCH(cad!$C$5,$C$22:$E$22,0)) -> 0.015
B33: Politique salariale sur la masse permanente | C33: 0.025 | D33: 0.02 | E33: 0.03 | F33: =INDEX(C33:E33,MATCH(cad!$C$5,$C$22:$E$22,0)) -> 0.02
B34: Variation des effectifs permanents | C34: 0.04 | D34: 0.03 | E34: 0.05 | F34: =INDEX(C34:E34,MATCH(cad!$C$5,$C$22:$E$22,0)) -> 0.03
B35: Effort de productivité sur les achats et la structure | C35: 0.01 | D35: 0.03 | F35: =INDEX(C35:E35,MATCH(cad!$C$5,$C$22:$E$22,0)) -> 0.03
B36: Variation des coûts de structure (loyers, IT, siège…) | D36: -0.03 | E36: 0.04 | F36: =INDEX(C36:E36,MATCH(cad!$C$5,$C$22:$E$22,0)) -> -0.03
B38: Constante — frais de dossier (decision)
B39: Frais de dossier par nouvel inscrit | C39: 90 | D39: 90 | E39: 90 | F39: =INDEX(C39:E39,MATCH(cad!$C$5,$C$22:$E$22,0)) -> 90

Sheet PIL
B2: PILOTAGE · Cockpit de decision CFO — Budget 2027
B6: CA 2027 | D6: EBITDA (après siège) | F6: Marge EBITDA | H6: Effectif | J6: Croissance CA vs 2026
B7: =E49 -> #VALUE! | D7: =H49 -> #VALUE! | F7: =I49 -> 0 | H7: =D49 -> #VALUE! | J7: =_xlfn.IFERROR(E49/cad!$C$12-1,0) -> 0
B12: 1 · Cap strategique par campus (marque x ville) — arbitrage du budget d'acquisition
U13: à masquer | V13: à masquer | W13: à masquer
A14: Campus | B14: Marque | C14: Ville | D14: CAC marginal | E14: Croiss. leads | F14: Intensité mkt | G14: Cap Eff | H14: Cap mom. | I14: Cap pot. | J14: Cap retenu | K14: Budget acq réf. | L14: Entity | U14: CAP_EFF (live) | V14: CAP_MOM (live) | W14: CAP_POT (live)
A15: MBWAY_PAR | B15: MBway | C15: Paris | D15: 1475.0125 | E15: 0.11073637 | F15: 0.021756763 | G15: 0.8149808 | H15: 1.0597054 | I15: 0.86473065 | J15: 1 | K15: 68291 | L15: MBWAY_PAR
A16: MBWAY_LYO | B16: MBway | C16: Lyon | D16: 1101.595 | E16: 0.11887172 | F16: 0.016735257 | G16: 1.0912421 | H16: 1.1375577 | I16: 1.1241979 | J16: 1 | K16: 41783 | L16: MBWAY_LYO
A17: MBWAY_NAN | B17: MBway | C17: Nantes | D17: 963.56901 | E17: 0.1237954 | F17: 0.014610109 | G17: 1.2475566 | H17: 1.1846754 | I17: 1.2877207 | J17: 1 | K17: 31533 | L17: MBWAY_NAN
A18: MBWAY_BOR | B18: MBway | C18: Bordeaux | D18: 889.58534 | E18: 0.12609457 | F18: 0.01405213 | G18: 1.3513114 | H18: 1.2066776 | I18: 1.3388532 | J18: 1 | K18: 24923 | L18: MBWAY_BOR
A19: ISCOM_PAR | B19: ISCOM | C19: Paris | D19: 1540.3212 | E19: 0.077744807 | F19: 0.020902665 | G19: 0.78042607 | H19: 0.74398855 | I19: 0.90006419 | J19: 1 | K19: 60800 | L19: ISCOM_PAR
A20: ISCOM_LIL | B20: ISCOM | C20: Lille | D20: 978.58254 | E20: 0.081545064 | F20: 0.014363413 | G20: 1.2284164 | H20: 0.78035559 | I20: 1.3098377 | J20: 1 | K20: 25220 | L20: ISCOM_LIL
A21: ISCOM_TLS | B21: ISCOM | C21: Toulouse | D21: 919.03491 | E21: 0.082116788 | F21: 0.013564662 | G21: 1.30801 | H21: 0.78582677 | I21: 1.386967 | J21: 1 | K21: 22083 | L21: ISCOM_TLS
A22: IPAC_NAN | B22: Ipac | C22: Nantes | D22: 1216.283 | E22: 0.13788487 | F22: 0.021343795 | G22: 0.98834472 | H22: 1.3195064 | I22: 0.88146178 | J22: 1 | K22: 21760 | L22: IPAC_NAN
A23: IPAC_REN | B23: Ipac | C23: Rennes | D23: 1040.5484 | E23: 0.14478114 | F23: 0.019104458 | G23: 1.1552628 | H23: 1.3855011 | I23: 0.98478271 | J23: 1 | K23: 14933 | L23: IPAC_REN
A24: IPAC_MTP | B24: Ipac | C24: Montpellier | D24: 1033.9757 | E24: 0.14478114 | F24: 0.019417898 | G24: 1.1626065 | H24: 1.3855011 | I24: 0.96888656 | J24: 1 | K24: 15178 | L24: IPAC_MTP
A25: PIGIER_LYO | B25: Pigier | C25: Lyon | D25: 1704.9638 | E25: 0.085003455 | F25: 0.029279527 | G25: 0.70506298 | H25: 0.81345109 | I25: 0.64255614 | J25: 1 | K25: 36612 | L25: PIGIER_LYO
A26: PIGIER_BOR | B26: Pigier | C26: Bordeaux | D26: 1368.0761 | E26: 0.087533156 | F26: 0.024360438 | G26: 0.87868421 | H26: 0.83765937 | I26: 0.77230713 | J26: 1 | K26: 21968 | L26: PIGIER_BOR
... A28: TUNON_LYO | B28: Tunon | C28: Lyon | D28: 1624.6613 | E28: 0.072555205 | F28: 0.021828498 | G28: 0.7399123 | H28: 0.69432601 | I28: 0.86188889 | J28: 1 | K28: 18850 | L28: TUNON_LYO
B30: 2 · Synthese par campus (resultats budget, live)
A32: Campus | B32: Marque | C32: Ville | D32: Effectif | E32: CA 2027 | F32: Prix moy. | G32: Part CA | H32: EBITDA campus | I32: Mrg EBITDA | J32: EBITDA/etud. | K32: Rejoue | L32: CAC marg.
A33: MBWAY_PAR | B33: MBway | C33: Paris | D33: =_xlfn.SUMIFS(Moteur!$P$1:$P$175,Moteur!$D$1:$D$175,$A33,Moteur!$B$1:$B$175,cad!$P$1) -> #VALUE! | E33: =_xlfn.SUMIFS(Moteur!$R$1:$R$175,Moteur!$D$1:$D$175,$A33,Moteur!$B$1:$B$175,cad!$P$1) -> #VALUE! | F33: =_xlfn.IFERROR(E33/D33,0) -> 0 | G33: =_xlfn.IFERROR(E33/SUM($E$33:$E$46),0) -> 0 | H33: =_xlfn.SUMIFS(_CALC_PNL!$T$1:$T$1347,_CALC_PNL!$A$1:$A$1347,$A33,_CALC_PNL!$D$1:$D$1347,cad!$P$1,_CALC_PNL!$C$1:$C$1347,"2027") -> #VALUE! | I33: =_xlfn.IFERROR(H33/E33,0) -> 0 | J33: =_xlfn.IFERROR(H33/D33,0) -> 0 | K33: =_xlfn.SUMIFS(PIL!$K$15:$K$28,PIL!$A$15:$A$28,$A33)*_xlfn.SUMIFS(PIL!$J$15:$J$28,PIL!$A$15:$A$28,$A33)*(SUM(PIL!$K$15:$K$28)/SUMPRODUCT(PIL!$K$15:$K$28,PIL!$J$15:$J$28)) -> 68291 | L33: =_xlfn.SUMIFS(PIL!$D$15:$D$28,PIL!$A$15:$A$28,$A33) -> 1475.0125
A34: MBWAY_LYO | B34: MBway | C34: Lyon | D34: =_xlfn.SUMIFS(Moteur!$P$1:$P$175,Moteur!$D$1:$D$175,$A34,Moteur!$B$1:$B$175,cad!$P$1) -> #VALUE! | E34: =_xlfn.SUMIFS(Moteur!$R$1:$R$175,Moteur!$D$1:$D$175,$A34,Moteur!$B$1:$B$175,cad!$P$1) -> #VALUE! | F34: =_xlfn.IFERROR(E34/D34,0) -> 0 | G34: =_xlfn.IFERROR(E34/SUM($E$33:$E$46),0) -> 0 | H34: =_xlfn.SUMIFS(_CALC_PNL!$T$1:$T$1347,_CALC_PNL!$A$1:$A$1347,$A34,_CALC_PNL!$D$1:$D$1347,cad!$P$1,_CALC_PNL!$C$1:$C$1347,"2027") -> #VALUE! | I34: =_xlfn.IFERROR(H34/E34,0) -> 0 | J34: =_xlfn.IFERROR(H34/D34,0) -> 0 | K34: =_xlfn.SUMIFS(PIL!$K$15:$K$28,PIL!$A$15:$A$28,$A34)*_xlfn.SUMIFS(PIL!$J$15:$J$28,PIL!$A$15:$A$28,$A34)*(SUM(PIL!$K$15:$K$28)/SUMPRODUCT(PIL!$K$15:$K$28,PIL!$J$15:$J$28)) -> 41783 | L34: =_xlfn.SUMIFS(PIL!$D$15:$D$28,PIL!$A$15:$A$28,$A34) -> 1101.595
A35: MBWAY_NAN | B35: MBway | C35: Nantes | D35: =_xlfn.SUMIFS(Moteur!$P$1:$P$175,Moteur!$D$1:$D$175,$A35,Moteur!$B$1:$B$175,cad!$P$1) -> #VALUE! | E35: =_xlfn.SUMIFS(Moteur!$R$1:$R$175,Moteur!$D$1:$D$175,$A35,Moteur!$B$1:$B$175,cad!$P$1) -> #VALUE! | F35: =_xlfn.IFERROR(E35/D35,0) -> 0 | G35: =_xlfn.IFERROR(E35/SUM($E$33:$E$46),0) -> 0 | H35: =_xlfn.SUMIFS(_CALC_PNL!$T$1:$T$1347,_CALC_PNL!$A$1:$A$1347,$A35,_CALC_PNL!$D$1:$D$1347,cad!$P$1,_CALC_PNL!$C$1:$C$1347,"2027") -> #VALUE! | I35: =_xlfn.IFERROR(H35/E35,0) -> 0 | J35: =_xlfn.IFERROR(H35/D35,0) -> 0 | K35: =_xlfn.SUMIFS(PIL!$K$15:$K$28,PIL!$A$15:$A$28,$A35)*_xlfn.SUMIFS(PIL!$J$15:$J$28,PIL!$A$15:$A$28,$A35)*(SUM(PIL!$K$15:$K$28)/SUMPRODUCT(PIL!$K$15:$K$28,PIL!$J$15:$J$28)) -> 31533 | L35: =_xlfn.SUMIFS(PIL!$D$15:$D$28,PIL!$A$15:$A$28,$A35) -> 963.56901
A36: MBWAY_BOR | B36: MBway | C36: Bordeaux | D36: =_xlfn.SUMIFS(Moteur!$P$1:$P$175,Moteur!$D$1:$D$175,$A36,Moteur!$B$1:$B$175,cad!$P$1) -> #VALUE! | E36: =_xlfn.SUMIFS(Moteur!$R$1:$R$175,Moteur!$D$1:$D$175,$A36,Moteur!$B$1:$B$175,cad!$P$1) -> #VALUE! | F36: =_xlfn.IFERROR(E36/D36,0) -> 0 | G36: =_xlfn.IFERROR(E36/SUM($E$33:$E$46),0) -> 0 | H36: =_xlfn.SUMIFS(_CALC_PNL!$T$1:$T$1347,_CALC_PNL!$A$1:$A$1347,$A36,_CALC_PNL!$D$1:$D$1347,cad!$P$1,_CALC_PNL!$C$1:$C$1347,"2027") -> #VALUE! | I36: =_xlfn.IFERROR(H36/E36,0) -> 0 | J36: =_xlfn.IFERROR(H36/D36,0) -> 0 | K36: =_xlfn.SUMIFS(PIL!$K$15:$K$28,PIL!$A$15:$A$28,$A36)*_xlfn.SUMIFS(PIL!$J$15:$J$28,PIL!$A$15:$A$28,$A36)*(SUM(PIL!$K$15:$K$28)/SUMPRODUCT(PIL!$K$15:$K$28,PIL!$J$15:$J$28)) -> 24923 | L36: =_xlfn.SUMIFS(PIL!$D$15:$D$28,PIL!$A$15:$A$28,$A36) -> 889.58534
A37: ISCOM_PAR | B37: ISCOM | C37: Paris | D37: =_xlfn.SUMIFS(Moteur!$P$1:$P$175,Moteur!$D$1:$D$175,$A37,Moteur!$B$1:$B$175,cad!$P$1) -> #VALUE! | E37: =_xlfn.SUMIFS(Moteur!$R$1:$R$175,Moteur!$D$1:$D$175,$A37,Moteur!$B$1:$B$175,cad!$P$1) -> #VALUE! | F37: =_xlfn.IFERROR(E37/D37,0) -> 0 | G37: =_xlfn.IFERROR(E37/SUM($E$33:$E$46),0) -> 0 | H37: =_xlfn.SUMIFS(_CALC_PNL!$T$1:$T$1347,_CALC_PNL!$A$1:$A$1347,$A37,_CALC_PNL!$D$1:$D$1347,cad!$P$1,_CALC_PNL!$C$1:$C$1347,"2027") -> #VALUE! | I37: =_xlfn.IFERROR(H37/E37,0) -> 0 | J37: =_xlfn.IFERROR(H37/D37,0) -> 0 | K37: =_xlfn.SUMIFS(PIL!$K$15:$K$28,PIL!$A$15:$A$28,$A37)*_xlfn.SUMIFS(PIL!$J$15:$J$28,PIL!$A$15:$A$28,$A37)*(SUM(PIL!$K$15:$K$28)/SUMPRODUCT(PIL!$K$15:$K$28,PIL!$J$15:$J$28)) -> 60800 | L37: =_xlfn.SUMIFS(PIL!$D$15:$D$28,PIL!$A$15:$A$28,$A37) -> 1540.3212
A38: ISCOM_LIL | B38: ISCOM | C38: Lille | D38: =_xlfn.SUMIFS(Moteur!$P$1:$P$175,Moteur!$D$1:$D$175,$A38,Moteur!$B$1:$B$175,cad!$P$1) -> #VALUE! | E38: =_xlfn.SUMIFS(Moteur!$R$1:$R$175,Moteur!$D$1:$D$175,$A38,Moteur!$B$1:$B$175,cad!$P$1) -> #VALUE! | F38: =_xlfn.IFERROR(E38/D38,0) -> 0 | G38: =_xlfn.IFERROR(E38/SUM($E$33:$E$46),0) -> 0 | H38: =_xlfn.SUMIFS(_CALC_PNL!$T$1:$T$1347,_CALC_PNL!$A$1:$A$1347,$A38,_CALC_PNL!$D$1:$D$1347,cad!$P$1,_CALC_PNL!$C$1:$C$1347,"2027") -> #VALUE! | I38: =_xlfn.IFERROR(H38/E38,0) -> 0 | J38: =_xlfn.IFERROR(H38/D38,0) -> 0 | K38: =_xlfn.SUMIFS(PIL!$K$15:$K$28,PIL!$A$15:$A$28,$A38)*_xlfn.SUMIFS(PIL!$J$15:$J$28,PIL!$A$15:$A$28,$A38)*(SUM(PIL!$K$15:$K$28)/SUMPRODUCT(PIL!$K$15:$K$28,PIL!$J$15:$J$28)) -> 25220 | L38: =_xlfn.SUMIFS(PIL!$D$15:$D$28,PIL!$A$15:$A$28,$A38) -> 978.58254
A39: ISCOM_TLS | B39: ISCOM | C39: Toulouse | D39: =_xlfn.SUMIFS(Moteur!$P$1:$P$175,Moteur!$D$1:$D$175,$A39,Moteur!$B$1:$B$175,cad!$P$1) -> #VALUE! | E39: =_xlfn.SUMIFS(Moteur!$R$1:$R$175,Moteur!$D$1:$D$175,$A39,Moteur!$B$1:$B$175,cad!$P$1) -> #VALUE! | F39: =_xlfn.IFERROR(E39/D39,0) -> 0 | G39: =_xlfn.IFERROR(E39/SUM($E$33:$E$46),0) -> 0 | H39: =_xlfn.SUMIFS(_CALC_PNL!$T$1:$T$1347,_CALC_PNL!$A$1:$A$1347,$A39,_CALC_PNL!$D$1:$D$1347,cad!$P$1,_CALC_PNL!$C$1:$C$1347,"2027") -> #VALUE! | I39: =_xlfn.IFERROR(H39/E39,0) -> 0 | J39: =_xlfn.IFERROR(H39/D39,0) -> 0 | K39: =_xlfn.SUMIFS(PIL!$K$15:$K$28,PIL!$A$15:$A$28,$A39)*_xlfn.SUMIFS(PIL!$J$15:$J$28,PIL!$A$15:$A$28,$A39)*(SUM(PIL!$K$15:$K$28)/SUMPRODUCT(PIL!$K$15:$K$28,PIL!$J$15:$J$28)) -> 22083 | L39: =_xlfn.SUMIFS(PIL!$D$15:$D$28,PIL!$A$15:$A$28,$A39) -> 919.03491
A40: IPAC_NAN | B40: Ipac | C40: Nantes | D40: =_xlfn.SUMIFS(Moteur!$P$1:$P$175,Moteur!$D$1:$D$175,$A40,Moteur!$B$1:$B$175,cad!$P$1) -> #VALUE! | E40: =_xlfn.SUMIFS(Moteur!$R$1:$R$175,Moteur!$D$1:$D$175,$A40,Moteur!$B$1:$B$175,cad!$P$1) -> #VALUE! | F40: =_xlfn.IFERROR(E40/D40,0) -> 0 | G40: =_xlfn.IFERROR(E40/SUM($E$33:$E$46),0) -> 0 | H40: =_xlfn.SUMIFS(_CALC_PNL!$T$1:$T$1347,_CALC_PNL!$A$1:$A$1347,$A40,_CALC_PNL!$D$1:$D$1347,cad!$P$1,_CALC_PNL!$C$1:$C$1347,"2027") -> #VALUE! | I40: =_xlfn.IFERROR(H40/E40,0) -> 0 | J40: =_xlfn.IFERROR(H40/D40,0) -> 0 | K40: =_xlfn.SUMIFS(PIL!$K$15:$K$28,PIL!$A$15:$A$28,$A40)*_xlfn.SUMIFS(PIL!$J$15:$J$28,PIL!$A$15:$A$28,$A40)*(SUM(PIL!$K$15:$K$28)/SUMPRODUCT(PIL!$K$15:$K$28,PIL!$J$15:$J$28)) -> 21760 | L40: =_xlfn.SUMIFS(PIL!$D$15:$D$28,PIL!$A$15:$A$28,$A40) -> 1216.283
A41: IPAC_REN | B41: Ipac | C41: Rennes | D41: =_xlfn.SUMIFS(Moteur!$P$1:$P$175,Moteur!$D$1:$D$175,$A41,Moteur!$B$1:$B$175,cad!$P$1) -> #VALUE! | E41: =_xlfn.SUMIFS(Moteur!$R$1:$R$175,Moteur!$D$1:$D$175,$A41,Moteur!$B$1:$B$175,cad!$P$1) -> #VALUE! | F41: =_xlfn.IFERROR(E41/D41,0) -> 0 | G41: =_xlfn.IFERROR(E41/SUM($E$33:$E$46),0) -> 0 | H41: =_xlfn.SUMIFS(_CALC_PNL!$T$1:$T$1347,_CALC_PNL!$A$1:$A$1347,$A41,_CALC_PNL!$D$1:$D$1347,cad!$P$1,_CALC_PNL!$C$1:$C$1347,"2027") -> #VALUE! | I41: =_xlfn.IFERROR(H41/E41,0) -> 0 | J41: =_xlfn.IFERROR(H41/D41,0) -> 0 | K41: =_xlfn.SUMIFS(PIL!$K$15:$K$28,PIL!$A$15:$A$28,$A41)*_xlfn.SUMIFS(PIL!$J$15:$J$28,PIL!$A$15:$A$28,$A41)*(SUM(PIL!$K$15:$K$28)/SUMPRODUCT(PIL!$K$15:$K$28,PIL!$J$15:$J$28)) -> 14933 | L41: =_xlfn.SUMIFS(PIL!$D$15:$D$28,PIL!$A$15:$A$28,$A41) -> 1040.5484
A42: IPAC_MTP | B42: Ipac | C42: Montpellier | D42: =_xlfn.SUMIFS(Moteur!$P$1:$P$175,Moteur!$D$1:$D$175,$A42,Moteur!$B$1:$B$175,cad!$P$1) -> #VALUE! | E42: =_xlfn.SUMIFS(Moteur!$R$1:$R$175,Moteur!$D$1:$D$175,$A42,Moteur!$B$1:$B$175,cad!$P$1) -> #VALUE! | F42: =_xlfn.IFERROR(E42/D42,0) -> 0 | G42: =_xlfn.IFERROR(E42/SUM($E$33:$E$46),0) -> 0 | H42: =_xlfn.SUMIFS(_CALC_PNL!$T$1:$T$1347,_CALC_PNL!$A$1:$A$1347,$A42,_CALC_PNL!$D$1:$D$1347,cad!$P$1,_CALC_PNL!$C$1:$C$1347,"2027") -> #VALUE! | I42: =_xlfn.IFERROR(H42/E42,0) -> 0 | J42: =_xlfn.IFERROR(H42/D42,0) -> 0 | K42: =_xlfn.SUMIFS(PIL!$K$15:$K$28,PIL!$A$15:$A$28,$A42)*_xlfn.SUMIFS(PIL!$J$15:$J$28,PIL!$A$15:$A$28,$A42)*(SUM(PIL!$K$15:$K$28)/SUMPRODUCT(PIL!$K$15:$K$28,PIL!$J$15:$J$28)) -> 15178 | L42: =_xlfn.SUMIFS(PIL!$D$15:$D$28,PIL!$A$15:$A$28,$A42) -> 1033.9757
A43: PIGIER_LYO | B43: Pigier | C43: Lyon | D43: =_xlfn.SUMIFS(Moteur!$P$1:$P$175,Moteur!$D$1:$D$175,$A43,Moteur!$B$1:$B$175,cad!$P$1) -> #VALUE! | E43: =_xlfn.SUMIFS(Moteur!$R$1:$R$175,Moteur!$D$1:$D$175,$A43,Moteur!$B$1:$B$175,cad!$P$1) -> #VALUE! | F43: =_xlfn.IFERROR(E43/D43,0) -> 0 | G43: =_xlfn.IFERROR(E43/SUM($E$33:$E$46),0) -> 0 | H43: =_xlfn.SUMIFS(_CALC_PNL!$T$1:$T$1347,_CALC_PNL!$A$1:$A$1347,$A43,_CALC_PNL!$D$1:$D$1347,cad!$P$1,_CALC_PNL!$C$1:$C$1347,"2027") -> #VALUE! | I43: =_xlfn.IFERROR(H43/E43,0) -> 0 | J43: =_xlfn.IFERROR(H43/D43,0) -> 0 | K43: =_xlfn.SUMIFS(PIL!$K$15:$K$28,PIL!$A$15:$A$28,$A43)*_xlfn.SUMIFS(PIL!$J$15:$J$28,PIL!$A$15:$A$28,$A43)*(SUM(PIL!$K$15:$K$28)/SUMPRODUCT(PIL!$K$15:$K$28,PIL!$J$15:$J$28)) -> 36612 | L43: =_xlfn.SUMIFS(PIL!$D$15:$D$28,PIL!$A$15:$A$28,$A43) -> 1704.9638
A44: PIGIER_BOR | B44: Pigier | C44: Bordeaux | D44: =_xlfn.SUMIFS(Moteur!$P$1:$P$175,Moteur!$D$1:$D$175,$A44,Moteur!$B$1:$B$175,cad!$P$1) -> #VALUE! | E44: =_xlfn.SUMIFS(Moteur!$R$1:$R$175,Moteur!$D$1:$D$175,$A44,Moteur!$B$1:$B$175,cad!$P$1) -> #VALUE! | F44: =_xlfn.IFERROR(E44/D44,0) -> 0 | G44: =_xlfn.IFERROR(E44/SUM($E$33:$E$46),0) -> 0 | H44: =_xlfn.SUMIFS(_CALC_PNL!$T$1:$T$1347,_CALC_PNL!$A$1:$A$1347,$A44,_CALC_PNL!$D$1:$D$1347,cad!$P$1,_CALC_PNL!$C$1:$C$1347,"2027") -> #VALUE! | I44: =_xlfn.IFERROR(H44/E44,0) -> 0 | J44: =_xlfn.IFERROR(H44/D44,0) -> 0 | K44: =_xlfn.SUMIFS(PIL!$K$15:$K$28,PIL!$A$15:$A$28,$A44)*_xlfn.SUMIFS(PIL!$J$15:$J$28,PIL!$A$15:$A$28,$A44)*(SUM(PIL!$K$15:$K$28)/SUMPRODUCT(PIL!$K$15:$K$28,PIL!$J$15:$J$28)) -> 21968 | L44: =_xlfn.SUMIFS(PIL!$D$15:$D$28,PIL!$A$15:$A$28,$A44) -> 1368.0761
... A46: TUNON_LYO | B46: Tunon | C46: Lyon | D46: =_xlfn.SUMIFS(Moteur!$P$1:$P$175,Moteur!$D$1:$D$175,$A46,Moteur!$B$1:$B$175,cad!$P$1) -> #VALUE! | E46: =_xlfn.SUMIFS(Moteur!$R$1:$R$175,Moteur!$D$1:$D$175,$A46,Moteur!$B$1:$B$175,cad!$P$1) -> #VALUE! | F46: =_xlfn.IFERROR(E46/D46,0) -> 0 | G46: =_xlfn.IFERROR(E46/SUM($E$33:$E$46),0) -> 0 | H46: =_xlfn.SUMIFS(_CALC_PNL!$T$1:$T$1347,_CALC_PNL!$A$1:$A$1347,$A46,_CALC_PNL!$D$1:$D$1347,cad!$P$1,_CALC_PNL!$C$1:$C$1347,"2027") -> #VALUE! | I46: =_xlfn.IFERROR(H46/E46,0) -> 0 | J46: =_xlfn.IFERROR(H46/D46,0) -> 0 | K46: =_xlfn.SUMIFS(PIL!$K$15:$K$28,PIL!$A$15:$A$28,$A46)*_xlfn.SUMIFS(PIL!$J$15:$J$28,PIL!$A$15:$A$28,$A46)*(SUM(PIL!$K$15:$K$28)/SUMPRODUCT(PIL!$K$15:$K$28,PIL!$J$15:$J$28)) -> 18850 | L46: =_xlfn.SUMIFS(PIL!$D$15:$D$28,PIL!$A$15:$A$28,$A46) -> 1624.6613
A47: Sous-total campus | D47: =SUM(D33:D46) -> #VALUE! | E47: =SUM(E33:E46) -> #VALUE! | F47: =_xlfn.IFERROR(E47/D47,0) -> 0 | G47: =SUM(G33:G46) -> 0 | H47: =SUM(H33:H46) -> #VALUE! | I47: =_xlfn.IFERROR(H47/E47,0) -> 0 | J47: =_xlfn.IFERROR(H47/D47,0) -> 0 | K47: =SUM(K33:K46) -> 434174
A48: Siege / holding (GRP) | H48: =_xlfn.SUMIFS(_CALC_PNL!$T$1:$T$1347,_CALC_PNL!$A$1:$A$1347,"GRP",_CALC_PNL!$D$1:$D$1347,cad!$P$1,_CALC_PNL!$C$1:$C$1347,"2027") -> #VALUE!
A49: GROUPE 2027 V01 | D49: =D47 -> #VALUE! | E49: =E47 -> #VALUE! | F49: =_xlfn.IFERROR(E49/D49,0) -> 0 | G49: =SUM(G33:G46) -> 0 | H49: =H47+H48 -> #VALUE! | I49: =_xlfn.IFERROR(H49/E49,0) -> 0 | J49: =_xlfn.IFERROR(H49/D49,0) -> 0 | K49: =SUM(K33:K46) -> 434174

Sheet ALLOC
N1: =IF($C$6="Chiffre d'affaires","REV_CA",IF($C$6="Nombre de classes","VOL_CLASS","VOL_EFF")) -> VOL_EFF
B2: 3 · ALLOCATION & RENTABILITE — cout complet du groupe a la classe | N2: =IF($C$7="Chiffre d'affaires","REV_CA",IF($C$7="Nombre de classes","VOL_CLASS","VOL_EFF")) -> VOL_EFF
N3: =IF($C$8="Chiffre d'affaires","REV_CA",IF($C$8="Nombre de classes","VOL_CLASS","VOL_EFF")) -> REV_CA
N4: =IF($C$9="Chiffre d'affaires","REV_CA",IF($C$9="Nombre de classes","VOL_CLASS","VOL_EFF")) -> REV_CA
B5: Cles d'allocation (saisie)
B6: Clé d’allocation siège administratif → marque | C6: Effectif
B7: Clé d’allocation Campus → Classe | C7: Effectif
B8: Clé d’allocation Marque → Campus | C8: Chiffre d'affaires
B9: Clé d’allocation Pub de marque → marque | C9: Chiffre d'affaires
B14: Maille fine — deplie campus/classe avec les [+]
B17: Marque ▸ Campus ▸ Classe | C17: Effectif | D17: CA | E17: VAC | F17: PERM | G17: ODIR | H17: STRUCT | I17: Frais marque | J17: Holding | K17: Cout complet | L17: Marge complete | M17: Marge %
B18: MBway | C18: =_xlfn.SUMIFS(Allocation!$I$1:$I$175,Allocation!$C$1:$C$175,"2026",Allocation!$E$1:$E$175,"MBWAY") -> 1249 | D18: =_xlfn.SUMIFS(Allocation!$K$1:$K$175,Allocation!$C$1:$C$175,"2026",Allocation!$E$1:$E$175,"MBWAY") -> 9567455 | E18: =_xlfn.SUMIFS(Allocation!$V$1:$V$175,Allocation!$C$1:$C$175,"2026",Allocation!$E$1:$E$175,"MBWAY") -> 603646 | F18: =_xlfn.SUMIFS(Allocation!$W$1:$W$175,Allocation!$C$1:$C$175,"2026",Allocation!$E$1:$E$175,"MBWAY") -> 1528197 | G18: =_xlfn.SUMIFS(Allocation!$X$1:$X$175,Allocation!$C$1:$C$175,"2026",Allocation!$E$1:$E$175,"MBWAY") -> 631277 | H18: =_xlfn.SUMIFS(Allocation!$Y$1:$Y$175,Allocation!$C$1:$C$175,"2026",Allocation!$E$1:$E$175,"MBWAY") -> 1452771 | I18: =_xlfn.SUMIFS(Allocation!$AC$1:$AC$175,Allocation!$C$1:$C$175,"2026",Allocation!$E$1:$E$175,"MBWAY") -> 676344 | J18: =_xlfn.SUMIFS(Allocation!$Z$1:$Z$175,Allocation!$C$1:$C$175,"2026",Allocation!$E$1:$E$175,"MBWAY") -> 2891983 | K18: =E18+F18+G18+H18+I18+J18 -> 7784218 | L18: =_xlfn.SUMIFS(Allocation!$AA$1:$AA$175,Allocation!$C$1:$C$175,"2026",Allocation!$E$1:$E$175,"MBWAY") -> 1783237 | M18: =_xlfn.IFERROR(L18/D18,0) -> 0.18638572
B19: Paris (MBWAY_PAR) | C19: =_xlfn.SUMIFS(Allocation!$I$1:$I$175,Allocation!$C$1:$C$175,"2026",Allocation!$D$1:$D$175,"MBWAY_PAR") -> 382 | D19: =_xlfn.SUMIFS(Allocation!$K$1:$K$175,Allocation!$C$1:$C$175,"2026",Allocation!$D$1:$D$175,"MBWAY_PAR") -> 3138840 | E19: =_xlfn.SUMIFS(Allocation!$V$1:$V$175,Allocation!$C$1:$C$175,"2026",Allocation!$D$1:$D$175,"MBWAY_PAR") -> 181094 | F19: =_xlfn.SUMIFS(Allocation!$W$1:$W$175,Allocation!$C$1:$C$175,"2026",Allocation!$D$1:$D$175,"MBWAY_PAR") -> 605202 | G19: =_xlfn.SUMIFS(Allocation!$X$1:$X$175,Allocation!$C$1:$C$175,"2026",Allocation!$D$1:$D$175,"MBWAY_PAR") -> 210431 | H19: =_xlfn.SUMIFS(Allocation!$Y$1:$Y$175,Allocation!$C$1:$C$175,"2026",Allocation!$D$1:$D$175,"MBWAY_PAR") -> 1452771 | I19: =_xlfn.SUMIFS(Allocation!$AC$1:$AC$175,Allocation!$C$1:$C$175,"2026",Allocation!$D$1:$D$175,"MBWAY_PAR") -> 676344 | J19: =_xlfn.SUMIFS(Allocation!$Z$1:$Z$175,Allocation!$C$1:$C$175,"2026",Allocation!$D$1:$D$175,"MBWAY_PAR") -> 2891983 | K19: =E19+F19+G19+H19+I19+J19 -> 6017825 | L19: =_xlfn.SUMIFS(Allocation!$AA$1:$AA$175,Allocation!$C$1:$C$175,"2026",Allocation!$D$1:$D$175,"MBWAY_PAR") -> -2878985 | M19: =_xlfn.IFERROR(L19/D19,0) -> -0.91721305
B20: BAC_MGT B1 INIT | C20: =_xlfn.SUMIFS(Allocation!$I$1:$I$175,Allocation!$C$1:$C$175,"2026",Allocation!$D$1:$D$175,"MBWAY_PAR",Allocation!$F$1:$F$175,"BAC_MGT",Allocation!$G$1:$G$175,"B1",Allocation!$H$1:$H$175,"INIT") -> 78 | D20: =_xlfn.SUMIFS(Allocation!$K$1:$K$175,Allocation!$C$1:$C$175,"2026",Allocation!$D$1:$D$175,"MBWAY_PAR",Allocation!$F$1:$F$175,"BAC_MGT",Allocation!$G$1:$G$175,"B1",Allocation!$H$1:$H$175,"INIT") -> 662220 | E20: =_xlfn.SUMIFS(Allocation!$V$1:$V$175,Allocation!$C$1:$C$175,"2026",Allocation!$D$1:$D$175,"MBWAY_PAR",Allocation!$F$1:$F$175,"BAC_MGT",Allocation!$G$1:$G$175,"B1",Allocation!$H$1:$H$175,"INIT") -> 45273.5 | F20: =_xlfn.SUMIFS(Allocation!$W$1:$W$175,Allocation!$C$1:$C$175,"2026",Allocation!$D$1:$D$175,"MBWAY_PAR",Allocation!$F$1:$F$175,"BAC_MGT",Allocation!$G$1:$G$175,"B1",Allocation!$H$1:$H$175,"INIT") -> 151300.5 | G20: =_xlfn.SUMIFS(Allocation!$X$1:$X$175,Allocation!$C$1:$C$175,"2026",Allocation!$D$1:$D$175,"MBWAY_PAR",Allocation!$F$1:$F$175,"BAC_MGT",Allocation!$G$1:$G$175,"B1",Allocation!$H$1:$H$175,"INIT") -> 51787.017 | H20: =_xlfn.SUMIFS(Allocation!$Y$1:$Y$175,Allocation!$C$1:$C$175,"2026",Allocation!$D$1:$D$175,"MBWAY_PAR",Allocation!$F$1:$F$175,"BAC_MGT",Allocation!$G$1:$G$175,"B1",Allocation!$H$1:$H$175,"INIT") -> 1452771 | I20: =_xlfn.SUMIFS(Allocation!$AC$1:$AC$175,Allocation!$C$1:$C$175,"2026",Allocation!$D$1:$D$175,"MBWAY_PAR",Allocation!$F$1:$F$175,"BAC_MGT",Allocation!$G$1:$G$175,"B1",Allocation!$H$1:$H$175,"INIT") -> 676344 | J20: =_xlfn.SUMIFS(Allocation!$Z$1:$Z$175,Allocation!$C$1:$C$175,"2026",Allocation!$D$1:$D$175,"MBWAY_PAR",Allocation!$F$1:$F$175,"BAC_MGT",Allocation!$G$1:$G$175,"B1",Allocation!$H$1:$H$175,"INIT") -> 2891983 | K20: =E20+F20+G20+H20+I20+J20 -> 5269459 | L20: =_xlfn.SUMIFS(Allocation!$AA$1:$AA$175,Allocation!$C$1:$C$175,"2026",Allocation!$D$1:$D$175,"MBWAY_PAR",Allocation!$F$1:$F$175,"BAC_MGT",Allocation!$G$1:$G$175,"B1",Allocation!$H$1:$H$175,"INIT") -> -4607239 | M20: =_xlfn.IFERROR(L20/D20,0) -> -6.9572635
B21: BAC_MGT B2 ALT | C21: =_xlfn.SUMIFS(Allocation!$I$1:$I$175,Allocation!$C$1:$C$175,"2026",Allocation!$D$1:$D$175,"MBWAY_PAR",Allocation!$F$1:$F$175,"BAC_MGT",Allocation!$G$1:$G$175,"B2",Allocation!$H$1:$H$175,"ALT") -> 76 | D21: =_xlfn.SUMIFS(Allocation!$K$1:$K$175,Allocation!$C$1:$C$175,"2026",Allocation!$D$1:$D$175,"MBWAY_PAR",Allocation!$F$1:$F$175,"BAC_MGT",Allocation!$G$1:$G$175,"B2",Allocation!$H$1:$H$175,"ALT") -> 595840 | E21: =_xlfn.SUMIFS(Allocation!$V$1:$V$175,Allocation!$C$1:$C$175,"2026",Allocation!$D$1:$D$175,"MBWAY_PAR",Allocation!$F$1:$F$175,"BAC_MGT",Allocation!$G$1:$G$175,"B2",Allocation!$H$1:$H$175,"ALT") -> 36218.8 | F21: =_xlfn.SUMIFS(Allocation!$W$1:$W$175,Allocation!$C$1:$C$175,"2026",Allocation!$D$1:$D$175,"MBWAY_PAR",Allocation!$F$1:$F$175,"BAC_MGT",Allocation!$G$1:$G$175,"B2",Allocation!$H$1:$H$175,"ALT") -> 121040.4 | G21: =_xlfn.SUMIFS(Allocation!$X$1:$X$175,Allocation!$C$1:$C$175,"2026",Allocation!$D$1:$D$175,"MBWAY_PAR",Allocation!$F$1:$F$175,"BAC_MGT",Allocation!$G$1:$G$175,"B2",Allocation!$H$1:$H$175,"ALT") -> 28279.162 | H21: =_xlfn.SUMIFS(Allocation!$Y$1:$Y$175,Allocation!$C$1:$C$175,"2026",Allocation!$D$1:$D$175,"MBWAY_PAR",Allocation!$F$1:$F$175,"BAC_MGT",Allocation!$G$1:$G$175,"B2",Allocation!$H$1:$H$175,"ALT") -> 0 | I21: =_xlfn.SUMIFS(Allocation!$AC$1:$AC$175,Allocation!$C$1:$C$175,"2026",Allocation!$D$1:$D$175,"MBWAY_PAR",Allocation!$F$1:$F$175,"BAC_MGT",Allocation!$G$1:$G$175,"B2",Allocation!$H$1:$H$175,"ALT") -> 0 | J21: =_xlfn.SUMIFS(Allocation!$Z$1:$Z$175,Allocation!$C$1:$C$175,"2026",Allocation!$D$1:$D$175,"MBWAY_PAR",Allocation!$F$1:$F$175,"BAC_MGT",Allocation!$G$1:$G$175,"B2",Allocation!$H$1:$H$175,"ALT") -> 0 | K21: =E21+F21+G21+H21+I21+J21 -> 185538.36 | L21: =_xlfn.SUMIFS(Allocation!$AA$1:$AA$175,Allocation!$C$1:$C$175,"2026",Allocation!$D$1:$D$175,"MBWAY_PAR",Allocation!$F$1:$F$175,"BAC_MGT",Allocation!$G$1:$G$175,"B2",Allocation!$H$1:$H$175,"ALT") -> 410301.64 | M21: =_xlfn.IFERROR(L21/D21,0) -> 0.68861043
B22: BAC_MGT B3 ALT | C22: =_xlfn.SUMIFS(Allocation!$I$1:$I$175,Allocation!$C$1:$C$175,"2026",Allocation!$D$1:$D$175,"MBWAY_PAR",Allocation!$F$1:$F$175,"BAC_MGT",Allocation!$G$1:$G$175,"B3",Allocation!$H$1:$H$175,"ALT") -> 74 | D22: =_xlfn.SUMIFS(Allocation!$K$1:$K$175,Allocation!$C$1:$C$175,"2026",Allocation!$D$1:$D$175,"MBWAY_PAR",Allocation!$F$1:$F$175,"BAC_MGT",Allocation!$G$1:$G$175,"B3",Allocation!$H$1:$H$175,"ALT") -> 580160 | E22: =_xlfn.SUMIFS(Allocation!$V$1:$V$175,Allocation!$C$1:$C$175,"2026",Allocation!$D$1:$D$175,"MBWAY_PAR",Allocation!$F$1:$F$175,"BAC_MGT",Allocation!$G$1:$G$175,"B3",Allocation!$H$1:$H$175,"ALT") -> 36218.8 | F22: =_xlfn.SUMIFS(Allocation!$W$1:$W$175,Allocation!$C$1:$C$175,"2026",Allocation!$D$1:$D$175,"MBWAY_PAR",Allocation!$F$1:$F$175,"BAC_MGT",Allocation!$G$1:$G$175,"B3",Allocation!$H$1:$H$175,"ALT") -> 121040.4 | G22: =_xlfn.SUMIFS(Allocation!$X$1:$X$175,Allocation!$C$1:$C$175,"2026",Allocation!$D$1:$D$175,"MBWAY_PAR",Allocation!$F$1:$F$175,"BAC_MGT",Allocation!$G$1:$G$175,"B3",Allocation!$H$1:$H$175,"ALT") -> 27534.974 | H22: =_xlfn.SUMIFS(Allocation!$Y$1:$Y$175,Allocation!$C$1:$C$175,"2026",Allocation!$D$1:$D$175,"MBWAY_PAR",Allocation!$F$1:$F$175,"BAC_MGT",Allocation!$G$1:$G$175,"B3",Allocation!$H$1:$H$175,"ALT") -> 0 | I22: =_xlfn.SUMIFS(Allocation!$AC$1:$AC$175,Allocation!$C$1:$C$175,"2026",Allocation!$D$1:$D$175,"MBWAY_PAR",Allocation!$F$1:$F$175,"BAC_MGT",Allocation!$G$1:$G$175,"B3",Allocation!$H$1:$H$175,"ALT") -> 0 | J22: =_xlfn.SUMIFS(Allocation!$Z$1:$Z$175,Allocation!$C$1:$C$175,"2026",Allocation!$D$1:$D$175,"MBWAY_PAR",Allocation!$F$1:$F$175,"BAC_MGT",Allocation!$G$1:$G$175,"B3",Allocation!$H$1:$H$175,"ALT") -> 0 | K22: =E22+F22+G22+H22+I22+J22 -> 184794.17 | L22: =_xlfn.SUMIFS(Allocation!$AA$1:$AA$175,Allocation!$C$1:$C$175,"2026",Allocation!$D$1:$D$175,"MBWAY_PAR",Allocation!$F$1:$F$175,"BAC_MGT",Allocation!$G$1:$G$175,"B3",Allocation!$H$1:$H$175,"ALT") -> 395365.83 | M22: =_xlfn.IFERROR(L22/D22,0) -> 0.68147722
B23: MAS_MGT M1 ALT | C23: =_xlfn.SUMIFS(Allocation!$I$1:$I$175,Allocation!$C$1:$C$175,"2026",Allocation!$D$1:$D$175,"MBWAY_PAR",Allocation!$F$1:$F$175,"MAS_MGT",Allocation!$G$1:$G$175,"M1",Allocation!$H$1:$H$175,"ALT") -> 78 | D23: =_xlfn.SUMIFS(Allocation!$K$1:$K$175,Allocation!$C$1:$C$175,"2026",Allocation!$D$1:$D$175,"MBWAY_PAR",Allocation!$F$1:$F$175,"MAS_MGT",Allocation!$G$1:$G$175,"M1",Allocation!$H$1:$H$175,"ALT") -> 662220 | E23: =_xlfn.SUMIFS(Allocation!$V$1:$V$175,Allocation!$C$1:$C$175,"2026",Allocation!$D$1:$D$175,"MBWAY_PAR",Allocation!$F$1:$F$175,"MAS_MGT",Allocation!$G$1:$G$175,"M1",Allocation!$H$1:$H$175,"ALT") -> 31691.45 | F23: =_xlfn.SUMIFS(Allocation!$W$1:$W$175,Allocation!$C$1:$C$175,"2026",Allocation!$D$1:$D$175,"MBWAY_PAR",Allocation!$F$1:$F$175,"MAS_MGT",Allocation!$G$1:$G$175,"M1",Allocation!$H$1:$H$175,"ALT") -> 105910.35 | G23: =_xlfn.SUMIFS(Allocation!$X$1:$X$175,Allocation!$C$1:$C$175,"2026",Allocation!$D$1:$D$175,"MBWAY_PAR",Allocation!$F$1:$F$175,"MAS_MGT",Allocation!$G$1:$G$175,"M1",Allocation!$H$1:$H$175,"ALT") -> 74550.684 | H23: =_xlfn.SUMIFS(Allocation!$Y$1:$Y$175,Allocation!$C$1:$C$175,"2026",Allocation!$D$1:$D$175,"MBWAY_PAR",Allocation!$F$1:$F$175,"MAS_MGT",Allocation!$G$1:$G$175,"M1",Allocation!$H$1:$H$175,"ALT") -> 0 | I23: =_xlfn.SUMIFS(Allocation!$AC$1:$AC$175,Allocation!$C$1:$C$175,"2026",Allocation!$D$1:$D$175,"MBWAY_PAR",Allocation!$F$1:$F$175,"MAS_MGT",Allocation!$G$1:$G$175,"M1",Allocation!$H$1:$H$175,"ALT") -> 0 | J23: =_xlfn.SUMIFS(Allocation!$Z$1:$Z$175,Allocation!$C$1:$C$175,"2026",Allocation!$D$1:$D$175,"MBWAY_PAR",Allocation!$F$1:$F$175,"MAS_MGT",Allocation!$G$1:$G$175,"M1",Allocation!$H$1:$H$175,"ALT") -> 0 | K23: =E23+F23+G23+H23+I23+J23 -> 212152.48 | L23: =_xlfn.SUMIFS(Allocation!$AA$1:$AA$175,Allocation!$C$1:$C$175,"2026",Allocation!$D$1:$D$175,"MBWAY_PAR",Allocation!$F$1:$F$175,"MAS_MGT",Allocation!$G$1:$G$175,"M1",Allocation!$H$1:$H$175,"ALT") -> 450067.52 | M23: =_xlfn.IFERROR(L23/D23,0) -> 0.67963444
B24: MAS_MGT M2 ALT | C24: =_xlfn.SUMIFS(Allocation!$I$1:$I$175,Allocation!$C$1:$C$175,"2026",Allocation!$D$1:$D$175,"MBWAY_PAR",Allocation!$F$1:$F$175,"MAS_MGT",Allocation!$G$1:$G$175,"M2",Allocation!$H$1:$H$175,"ALT") -> 76 | D24: =_xlfn.SUMIFS(Allocation!$K$1:$K$175,Allocation!$C$1:$C$175,"2026",Allocation!$D$1:$D$175,"MBWAY_PAR",Allocation!$F$1:$F$175,"MAS_MGT",Allocation!$G$1:$G$175,"M2",Allocation!$H$1:$H$175,"ALT") -> 638400 | E24: =_xlfn.SUMIFS(Allocation!$V$1:$V$175,Allocation!$C$1:$C$175,"2026",Allocation!$D$1:$D$175,"MBWAY_PAR",Allocation!$F$1:$F$175,"MAS_MGT",Allocation!$G$1:$G$175,"M2",Allocation!$H$1:$H$175,"ALT") -> 31691.45 | F24: =_xlfn.SUMIFS(Allocation!$W$1:$W$175,Allocation!$C$1:$C$175,"2026",Allocation!$D$1:$D$175,"MBWAY_PAR",Allocation!$F$1:$F$175,"MAS_MGT",Allocation!$G$1:$G$175,"M2",Allocation!$H$1:$H$175,"ALT") -> 105910.35 | G24: =_xlfn.SUMIFS(Allocation!$X$1:$X$175,Allocation!$C$1:$C$175,"2026",Allocation!$D$1:$D$175,"MBWAY_PAR",Allocation!$F$1:$F$175,"MAS_MGT",Allocation!$G$1:$G$175,"M2",Allocation!$H$1:$H$175,"ALT") -> 28279.162 | H24: =_xlfn.SUMIFS(Allocation!$Y$1:$Y$175,Allocation!$C$1:$C$175,"2026",Allocation!$D$1:$D$175,"MBWAY_PAR",Allocation!$F$1:$F$175,"MAS_MGT",Allocation!$G$1:$G$175,"M2",Allocation!$H$1:$H$175,"ALT") -> 0 | I24: =_xlfn.SUMIFS(Allocation!$AC$1:$AC$175,Allocation!$C$1:$C$175,"2026",Allocation!$D$1:$D$175,"MBWAY_PAR",Allocation!$F$1:$F$175,"MAS_MGT",Allocation!$G$1:$G$175,"M2",Allocation!$H$1:$H$175,"ALT") -> 0 | J24: =_xlfn.SUMIFS(Allocation!$Z$1:$Z$175,Allocation!$C$1:$C$175,"2026",Allocation!$D$1:$D$175,"MBWAY_PAR",Allocation!$F$1:$F$175,"MAS_MGT",Allocation!$G$1:$G$175,"M2",Allocation!$H$1:$H$175,"ALT") -> 0 | K24: =E24+F24+G24+H24+I24+J24 -> 165880.96 | L24: =_xlfn.SUMIFS(Allocation!$AA$1:$AA$175,Allocation!$C$1:$C$175,"2026",Allocation!$D$1:$D$175,"MBWAY_PAR",Allocation!$F$1:$F$175,"MAS_MGT",Allocation!$G$1:$G$175,"M2",Allocation!$H$1:$H$175,"ALT") -> 472519.04 | M24: =_xlfn.IFERROR(L24/D24,0) -> 0.7401614
B25: Lyon (MBWAY_LYO) | C25: =_xlfn.SUMIFS(Allocation!$I$1:$I$175,Allocation!$C$1:$C$175,"2026",Allocation!$D$1:$D$175,"MBWAY_LYO") -> 324 | D25: =_xlfn.SUMIFS(Allocation!$K$1:$K$175,Allocation!$C$1:$C$175,"2026",Allocation!$D$1:$D$175,"MBWAY_LYO") -> 2496705 | E25: =_xlfn.SUMIFS(Allocation!$V$1:$V$175,Allocation!$C$1:$C$175,"2026",Allocation!$D$1:$D$175,"MBWAY_LYO") -> 156948 | F25: =_xlfn.SUMIFS(Allocation!$W$1:$W$175,Allocation!$C$1:$C$175,"2026",Allocation!$D$1:$D$175,"MBWAY_LYO") -> 362623 | G25: =_xlfn.SUMIFS(Allocation!$X$1:$X$175,Allocation!$C$1:$C$175,"2026",Allocation!$D$1:$D$175,"MBWAY_LYO") -> 162342 | H25: =_xlfn.SUMIFS(Allocation!$Y$1:$Y$175,Allocation!$C$1:$C$175,"2026",Allocation!$D$1:$D$175,"MBWAY_LYO") -> 0 | I25: =_xlfn.SUMIFS(Allocation!$AC$1:$AC$175,Allocation!$C$1:$C$175,"2026",Allocation!$D$1:$D$175,"MBWAY_LYO") -> 0 | J25: =_xlfn.SUMIFS(Allocation!$Z$1:$Z$175,Allocation!$C$1:$C$175,"2026",Allocation!$D$1:$D$175,"MBWAY_LYO") -> 0 | K25: =E25+F25+G25+H25+I25+J25 -> 681913 | L25: =_xlfn.SUMIFS(Allocation!$AA$1:$AA$175,Allocation!$C$1:$C$175,"2026",Allocation!$D$1:$D$175,"MBWAY_LYO") -> 1814792 | M25: =_xlfn.IFERROR(L25/D25,0) -> 0.72687482
B26: BAC_MGT B1 INIT | C26: =_xlfn.SUMIFS(Allocation!$I$1:$I$175,Allocation!$C$1:$C$175,"2026",Allocation!$D$1:$D$175,"MBWAY_LYO",Allocation!$F$1:$F$175,"BAC_MGT",Allocation!$G$1:$G$175,"B1",Allocation!$H$1:$H$175,"INIT") -> 66 | D26: =_xlfn.SUMIFS(Allocation!$K$1:$K$175,Allocation!$C$1:$C$175,"2026",Allocation!$D$1:$D$175,"MBWAY_LYO",Allocation!$F$1:$F$175,"BAC_MGT",Allocation!$G$1:$G$175,"B1",Allocation!$H$1:$H$175,"INIT") -> 525690 | E26: =_xlfn.SUMIFS(Allocation!$V$1:$V$175,Allocation!$C$1:$C$175,"2026",Allocation!$D$1:$D$175,"MBWAY_LYO",Allocation!$F$1:$F$175,"BAC_MGT",Allocation!$G$1:$G$175,"B1",Allocation!$H$1:$H$175,"INIT") -> 45273.462 | F26: =_xlfn.SUMIFS(Allocation!$W$1:$W$175,Allocation!$C$1:$C$175,"2026",Allocation!$D$1:$D$175,"MBWAY_LYO",Allocation!$F$1:$F$175,"BAC_MGT",Allocation!$G$1:$G$175,"B1",Allocation!$H$1:$H$175,"INIT") -> 104602.79 | G26: =_xlfn.SUMIFS(Allocation!$X$1:$X$175,Allocation!$C$1:$C$175,"2026",Allocation!$D$1:$D$175,"MBWAY_LYO",Allocation!$F$1:$F$175,"BAC_MGT",Allocation!$G$1:$G$175,"B1",Allocation!$H$1:$H$175,"INIT") -> 45449.815 | H26: =_xlfn.SUMIFS(Allocation!$Y$1:$Y$175,Allocation!$C$1:$C$175,"2026",Allocation!$D$1:$D$175,"MBWAY_LYO",Allocation!$F$1:$F$175,"BAC_MGT",Allocation!$G$1:$G$175,"B1",Allocation!$H$1:$H$175,"INIT") -> 0 | I26: =_xlfn.SUMIFS(Allocation!$AC$1:$AC$175,Allocation!$C$1:$C$175,"2026",Allocation!$D$1:$D$175,"MBWAY_LYO",Allocation!$F$1:$F$175,"BAC_MGT",Allocation!$G$1:$G$175,"B1",Allocation!$H$1:$H$175,"INIT") -> 0 | J26: =_xlfn.SUMIFS(Allocation!$Z$1:$Z$175,Allocation!$C$1:$C$175,"2026",Allocation!$D$1:$D$175,"MBWAY_LYO",Allocation!$F$1:$F$175,"BAC_MGT",Allocation!$G$1:$G$175,"B1",Allocation!$H$1:$H$175,"INIT") -> 0 | K26: =E26+F26+G26+H26+I26+J26 -> 195326.06 | L26: =_xlfn.SUMIFS(Allocation!$AA$1:$AA$175,Allocation!$C$1:$C$175,"2026",Allocation!$D$1:$D$175,"MBWAY_LYO",Allocation!$F$1:$F$175,"BAC_MGT",Allocation!$G$1:$G$175,"B1",Allocation!$H$1:$H$175,"INIT") -> 330363.94 | M26: =_xlfn.IFERROR(L26/D26,0) -> 0.62843869
B27: BAC_MGT B2 ALT | C27: =_xlfn.SUMIFS(Allocation!$I$1:$I$175,Allocation!$C$1:$C$175,"2026",Allocation!$D$1:$D$175,"MBWAY_LYO",Allocation!$F$1:$F$175,"BAC_MGT",Allocation!$G$1:$G$175,"B2",Allocation!$H$1:$H$175,"ALT") -> 64 | D27: =_xlfn.SUMIFS(Allocation!$K$1:$K$175,Allocation!$C$1:$C$175,"2026",Allocation!$D$1:$D$175,"MBWAY_LYO",Allocation!$F$1:$F$175,"BAC_MGT",Allocation!$G$1:$G$175,"B2",Allocation!$H$1:$H$175,"ALT") -> 470400 | E27: =_xlfn.SUMIFS(Allocation!$V$1:$V$175,Allocation!$C$1:$C$175,"2026",Allocation!$D$1:$D$175,"MBWAY_LYO",Allocation!$F$1:$F$175,"BAC_MGT",Allocation!$G$1:$G$175,"B2",Allocation!$H$1:$H$175,"ALT") -> 24145.846 | F27: =_xlfn.SUMIFS(Allocation!$W$1:$W$175,Allocation!$C$1:$C$175,"2026",Allocation!$D$1:$D$175,"MBWAY_LYO",Allocation!$F$1:$F$175,"BAC_MGT",Allocation!$G$1:$G$175,"B2",Allocation!$H$1:$H$175,"ALT") -> 55788.154 | G27: =_xlfn.SUMIFS(Allocation!$X$1:$X$175,Allocation!$C$1:$C$175,"2026",Allocation!$D$1:$D$175,"MBWAY_LYO",Allocation!$F$1:$F$175,"BAC_MGT",Allocation!$G$1:$G$175,"B2",Allocation!$H$1:$H$175,"ALT") -> 23814.123 | H27: =_xlfn.SUMIFS(Allocation!$Y$1:$Y$175,Allocation!$C$1:$C$175,"2026",Allocation!$D$1:$D$175,"MBWAY_LYO",Allocation!$F$1:$F$175,"BAC_MGT",Allocation!$G$1:$G$175,"B2",Allocation!$H$1:$H$175,"ALT") -> 0 | I27: =_xlfn.SUMIFS(Allocation!$AC$1:$AC$175,Allocation!$C$1:$C$175,"2026",Allocation!$D$1:$D$175,"MBWAY_LYO",Allocation!$F$1:$F$175,"BAC_MGT",Allocation!$G$1:$G$175,"B2",Allocation!$H$1:$H$175,"ALT") -> 0 | J27: =_xlfn.SUMIFS(Allocation!$Z$1:$Z$175,Allocation!$C$1:$C$175,"2026",Allocation!$D$1:$D$175,"MBWAY_LYO",Allocation!$F$1:$F$175,"BAC_MGT",Allocation!$G$1:$G$175,"B2",Allocation!$H$1:$H$175,"ALT") -> 0 | K27: =E27+F27+G27+H27+I27+J27 -> 103748.12 | L27: =_xlfn.SUMIFS(Allocation!$AA$1:$AA$175,Allocation!$C$1:$C$175,"2026",Allocation!$D$1:$D$175,"MBWAY_LYO",Allocation!$F$1:$F$175,"BAC_MGT",Allocation!$G$1:$G$175,"B2",Allocation!$H$1:$H$175,"ALT") -> 366651.88 | M27: =_xlfn.IFERROR(L27/D27,0) -> 0.77944702
B28: BAC_MGT B3 ALT | C28: =_xlfn.SUMIFS(Allocation!$I$1:$I$175,Allocation!$C$1:$C$175,"2026",Allocation!$D$1:$D$175,"MBWAY_LYO",Allocation!$F$1:$F$175,"BAC_MGT",Allocation!$G$1:$G$175,"B3",Allocation!$H$1:$H$175,"ALT") -> 63 | D28: =_xlfn.SUMIFS(Allocation!$K$1:$K$175,Allocation!$C$1:$C$175,"2026",Allocation!$D$1:$D$175,"MBWAY_LYO",Allocation!$F$1:$F$175,"BAC_MGT",Allocation!$G$1:$G$175,"B3",Allocation!$H$1:$H$175,"ALT") -> 463050 | E28: =_xlfn.SUMIFS(Allocation!$V$1:$V$175,Allocation!$C$1:$C$175,"2026",Allocation!$D$1:$D$175,"MBWAY_LYO",Allocation!$F$1:$F$175,"BAC_MGT",Allocation!$G$1:$G$175,"B3",Allocation!$H$1:$H$175,"ALT") -> 24145.846 | F28: =_xlfn.SUMIFS(Allocation!$W$1:$W$175,Allocation!$C$1:$C$175,"2026",Allocation!$D$1:$D$175,"MBWAY_LYO",Allocation!$F$1:$F$175,"BAC_MGT",Allocation!$G$1:$G$175,"B3",Allocation!$H$1:$H$175,"ALT") -> 55788.154 | G28: =_xlfn.SUMIFS(Allocation!$X$1:$X$175,Allocation!$C$1:$C$175,"2026",Allocation!$D$1:$D$175,"MBWAY_LYO",Allocation!$F$1:$F$175,"BAC_MGT",Allocation!$G$1:$G$175,"B3",Allocation!$H$1:$H$175,"ALT") -> 23442.028 | H28: =_xlfn.SUMIFS(Allocation!$Y$1:$Y$175,Allocation!$C$1:$C$175,"2026",Allocation!$D$1:$D$175,"MBWAY_LYO",Allocation!$F$1:$F$175,"BAC_MGT",Allocation!$G$1:$G$175,"B3",Allocation!$H$1:$H$175,"ALT") -> 0 | I28: =_xlfn.SUMIFS(Allocation!$AC$1:$AC$175,Allocation!$C$1:$C$175,"2026",Allocation!$D$1:$D$175,"MBWAY_LYO",Allocation!$F$1:$F$175,"BAC_MGT",Allocation!$G$1:$G$175,"B3",Allocation!$H$1:$H$175,"ALT") -> 0 | J28: =_xlfn.SUMIFS(Allocation!$Z$1:$Z$175,Allocation!$C$1:$C$175,"2026",Allocation!$D$1:$D$175,"MBWAY_LYO",Allocation!$F$1:$F$175,"BAC_MGT",Allocation!$G$1:$G$175,"B3",Allocation!$H$1:$H$175,"ALT") -> 0 | K28: =E28+F28+G28+H28+I28+J28 -> 103376.03 | L28: =_xlfn.SUMIFS(Allocation!$AA$1:$AA$175,Allocation!$C$1:$C$175,"2026",Allocation!$D$1:$D$175,"MBWAY_LYO",Allocation!$F$1:$F$175,"BAC_MGT",Allocation!$G$1:$G$175,"B3",Allocation!$H$1:$H$175,"ALT") -> 359673.97 | M28: =_xlfn.IFERROR(L28/D28,0) -> 0.77674975
B29: MAS_MGT M1 ALT | C29: =_xlfn.SUMIFS(Allocation!$I$1:$I$175,Allocation!$C$1:$C$175,"2026",Allocation!$D$1:$D$175,"MBWAY_LYO",Allocation!$F$1:$F$175,"MAS_MGT",Allocation!$G$1:$G$175,"M1",Allocation!$H$1:$H$175,"ALT") -> 66 | D29: =_xlfn.SUMIFS(Allocation!$K$1:$K$175,Allocation!$C$1:$C$175,"2026",Allocation!$D$1:$D$175,"MBWAY_LYO",Allocation!$F$1:$F$175,"MAS_MGT",Allocation!$G$1:$G$175,"M1",Allocation!$H$1:$H$175,"ALT") -> 525690 | E29: =_xlfn.SUMIFS(Allocation!$V$1:$V$175,Allocation!$C$1:$C$175,"2026",Allocation!$D$1:$D$175,"MBWAY_LYO",Allocation!$F$1:$F$175,"MAS_MGT",Allocation!$G$1:$G$175,"M1",Allocation!$H$1:$H$175,"ALT") -> 31691.423 | F29: =_xlfn.SUMIFS(Allocation!$W$1:$W$175,Allocation!$C$1:$C$175,"2026",Allocation!$D$1:$D$175,"MBWAY_LYO",Allocation!$F$1:$F$175,"MAS_MGT",Allocation!$G$1:$G$175,"M1",Allocation!$H$1:$H$175,"ALT") -> 73221.952 | G29: =_xlfn.SUMIFS(Allocation!$X$1:$X$175,Allocation!$C$1:$C$175,"2026",Allocation!$D$1:$D$175,"MBWAY_LYO",Allocation!$F$1:$F$175,"MAS_MGT",Allocation!$G$1:$G$175,"M1",Allocation!$H$1:$H$175,"ALT") -> 45449.815 | H29: =_xlfn.SUMIFS(Allocation!$Y$1:$Y$175,Allocation!$C$1:$C$175,"2026",Allocation!$D$1:$D$175,"MBWAY_LYO",Allocation!$F$1:$F$175,"MAS_MGT",Allocation!$G$1:$G$175,"M1",Allocation!$H$1:$H$175,"ALT") -> 0 | I29: =_xlfn.SUMIFS(Allocation!$AC$1:$AC$175,Allocation!$C$1:$C$175,"2026",Allocation!$D$1:$D$175,"MBWAY_LYO",Allocation!$F$1:$F$175,"MAS_MGT",Allocation!$G$1:$G$175,"M1",Allocation!$H$1:$H$175,"ALT") -> 0 | J29: =_xlfn.SUMIFS(Allocation!$Z$1:$Z$175,Allocation!$C$1:$C$175,"2026",Allocation!$D$1:$D$175,"MBWAY_LYO",Allocation!$F$1:$F$175,"MAS_MGT",Allocation!$G$1:$G$175,"M1",Allocation!$H$1:$H$175,"ALT") -> 0 | K29: =E29+F29+G29+H29+I29+J29 -> 150363.19 | L29: =_xlfn.SUMIFS(Allocation!$AA$1:$AA$175,Allocation!$C$1:$C$175,"2026",Allocation!$D$1:$D$175,"MBWAY_LYO",Allocation!$F$1:$F$175,"MAS_MGT",Allocation!$G$1:$G$175,"M1",Allocation!$H$1:$H$175,"ALT") -> 375326.81 | M29: =_xlfn.IFERROR(L29/D29,0) -> 0.71396985
B30: MAS_MGT M2 ALT | C30: =_xlfn.SUMIFS(Allocation!$I$1:$I$175,Allocation!$C$1:$C$175,"2026",Allocation!$D$1:$D$175,"MBWAY_LYO",Allocation!$F$1:$F$175,"MAS_MGT",Allocation!$G$1:$G$175,"M2",Allocation!$H$1:$H$175,"ALT") -> 65 | D30: =_xlfn.SUMIFS(Allocation!$K$1:$K$175,Allocation!$C$1:$C$175,"2026",Allocation!$D$1:$D$175,"MBWAY_LYO",Allocation!$F$1:$F$175,"MAS_MGT",Allocation!$G$1:$G$175,"M2",Allocation!$H$1:$H$175,"ALT") -> 511875 | E30: =_xlfn.SUMIFS(Allocation!$V$1:$V$175,Allocation!$C$1:$C$175,"2026",Allocation!$D$1:$D$175,"MBWAY_LYO",Allocation!$F$1:$F$175,"MAS_MGT",Allocation!$G$1:$G$175,"M2",Allocation!$H$1:$H$175,"ALT") -> 31691.423 | F30: =_xlfn.SUMIFS(Allocation!$W$1:$W$175,Allocation!$C$1:$C$175,"2026",Allocation!$D$1:$D$175,"MBWAY_LYO",Allocation!$F$1:$F$175,"MAS_MGT",Allocation!$G$1:$G$175,"M2",Allocation!$H$1:$H$175,"ALT") -> 73221.952 | G30: =_xlfn.SUMIFS(Allocation!$X$1:$X$175,Allocation!$C$1:$C$175,"2026",Allocation!$D$1:$D$175,"MBWAY_LYO",Allocation!$F$1:$F$175,"MAS_MGT",Allocation!$G$1:$G$175,"M2",Allocation!$H$1:$H$175,"ALT") -> 24186.219 | H30: =_xlfn.SUMIFS(Allocation!$Y$1:$Y$175,Allocation!$C$1:$C$175,"2026",Allocation!$D$1:$D$175,"MBWAY_LYO",Allocation!$F$1:$F$175,"MAS_MGT",Allocation!$G$1:$G$175,"M2",Allocation!$H$1:$H$175,"ALT") -> 0 | I30: =_xlfn.SUMIFS(Allocation!$AC$1:$AC$175,Allocation!$C$1:$C$175,"2026",Allocation!$D$1:$D$175,"MBWAY_LYO",Allocation!$F$1:$F$175,"MAS_MGT",Allocation!$G$1:$G$175,"M2",Allocation!$H$1:$H$175,"ALT") -> 0 | J30: =_xlfn.SUMIFS(Allocation!$Z$1:$Z$175,Allocation!$C$1:$C$175,"2026",Allocation!$D$1:$D$175,"MBWAY_LYO",Allocation!$F$1:$F$175,"MAS_MGT",Allocation!$G$1:$G$175,"M2",Allocation!$H$1:$H$175,"ALT") -> 0 | K30: =E30+F30+G30+H30+I30+J30 -> 129099.59 | L30: =_xlfn.SUMIFS(Allocation!$AA$1:$AA$175,Allocation!$C$1:$C$175,"2026",Allocation!$D$1:$D$175,"MBWAY_LYO",Allocation!$F$1:$F$175,"MAS_MGT",Allocation!$G$1:$G$175,"M2",Allocation!$H$1:$H$175,"ALT") -> 382775.41 | M30: =_xlfn.IFERROR(L30/D30,0) -> 0.74779078
B31: Nantes (MBWAY_NAN) | C31: =_xlfn.SUMIFS(Allocation!$I$1:$I$175,Allocation!$C$1:$C$175,"2026",Allocation!$D$1:$D$175,"MBWAY_NAN") -> 294 | D31: =_xlfn.SUMIFS(Allocation!$K$1:$K$175,Allocation!$C$1:$C$175,"2026",Allocation!$D$1:$D$175,"MBWAY_NAN") -> 2158300 | E31: =_xlfn.SUMIFS(Allocation!$V$1:$V$175,Allocation!$C$1:$C$175,"2026",Allocation!$D$1:$D$175,"MBWAY_NAN") -> 144875 | F31: =_xlfn.SUMIFS(Allocation!$W$1:$W$175,Allocation!$C$1:$C$175,"2026",Allocation!$D$1:$D$175,"MBWAY_NAN") -> 298865 | G31: =_xlfn.SUMIFS(Allocation!$X$1:$X$175,Allocation!$C$1:$C$175,"2026",Allocation!$D$1:$D$175,"MBWAY_NAN") -> 140929 | H31: =_xlfn.SUMIFS(Allocation!$Y$1:$Y$175,Allocation!$C$1:$C$175,"2026",Allocation!$D$1:$D$175,"MBWAY_NAN") -> 0 | I31: =_xlfn.SUMIFS(Allocation!$AC$1:$AC$175,Allocation!$C$1:$C$175,"2026",Allocation!$D$1:$D$175,"MBWAY_NAN") -> 0 | J31: =_xlfn.SUMIFS(Allocation!$Z$1:$Z$175,Allocation!$C$1:$C$175,"2026",Allocation!$D$1:$D$175,"MBWAY_NAN") -> 0 | K31: =E31+F31+G31+H31+I31+J31 -> 584669 | L31: =_xlfn.SUMIFS(Allocation!$AA$1:$AA$175,Allocation!$C$1:$C$175,"2026",Allocation!$D$1:$D$175,"MBWAY_NAN") -> 1573631 | M31: =_xlfn.IFERROR(L31/D31,0) -> 0.7291067
B32: BAC_MGT B1 INIT | C32: =_xlfn.SUMIFS(Allocation!$I$1:$I$175,Allocation!$C$1:$C$175,"2026",Allocation!$D$1:$D$175,"MBWAY_NAN",Allocation!$F$1:$F$175,"BAC_MGT",Allocation!$G$1:$G$175,"B1",Allocation!$H$1:$H$175,"INIT") -> 60 | D32: =_xlfn.SUMIFS(Allocation!$K$1:$K$175,Allocation!$C$1:$C$175,"2026",Allocation!$D$1:$D$175,"MBWAY_NAN",Allocation!$F$1:$F$175,"BAC_MGT",Allocation!$G$1:$G$175,"B1",Allocation!$H$1:$H$175,"INIT") -> 455400 | E32: =_xlfn.SUMIFS(Allocation!$V$1:$V$175,Allocation!$C$1:$C$175,"2026",Allocation!$D$1:$D$175,"MBWAY_NAN",Allocation!$F$1:$F$175,"BAC_MGT",Allocation!$G$1:$G$175,"B1",Allocation!$H$1:$H$175,"INIT") -> 30824.468 | F32: =_xlfn.SUMIFS(Allocation!$W$1:$W$175,Allocation!$C$1:$C$175,"2026",Allocation!$D$1:$D$175,"MBWAY_NAN",Allocation!$F$1:$F$175,"BAC_MGT",Allocation!$G$1:$G$175,"B1",Allocation!$H$1:$H$175,"INIT") -> 63588.298 | G32: =_xlfn.SUMIFS(Allocation!$X$1:$X$175,Allocation!$C$1:$C$175,"2026",Allocation!$D$1:$D$175,"MBWAY_NAN",Allocation!$F$1:$F$175,"BAC_MGT",Allocation!$G$1:$G$175,"B1",Allocation!$H$1:$H$175,"INIT") -> 38092.214 | H32: =_xlfn.SUMIFS(Allocation!$Y$1:$Y$175,Allocation!$C$1:$C$175,"2026",Allocation!$D$1:$D$175,"MBWAY_NAN",Allocation!$F$1:$F$175,"BAC_MGT",Allocation!$G$1:$G$175,"B1",Allocation!$H$1:$H$175,"INIT") -> 0 | I32: =_xlfn.SUMIFS(Allocation!$AC$1:$AC$175,Allocation!$C$1:$C$175,"2026",Allocation!$D$1:$D$175,"MBWAY_NAN",Allocation!$F$1:$F$175,"BAC_MGT",Allocation!$G$1:$G$175,"B1",Allocation!$H$1:$H$175,"INIT") -> 0 | J32: =_xlfn.SUMIFS(Allocation!$Z$1:$Z$175,Allocation!$C$1:$C$175,"2026",Allocation!$D$1:$D$175,"MBWAY_NAN",Allocation!$F$1:$F$175,"BAC_MGT",Allocation!$G$1:$G$175,"B1",Allocation!$H$1:$H$175,"INIT") -> 0 | K32: =E32+F32+G32+H32+I32+J32 -> 132504.98 | L32: =_xlfn.SUMIFS(Allocation!$AA$1:$AA$175,Allocation!$C$1:$C$175,"2026",Allocation!$D$1:$D$175,"MBWAY_NAN",Allocation!$F$1:$F$175,"BAC_MGT",Allocation!$G$1:$G$175,"B1",Allocation!$H$1:$H$175,"INIT") -> 322895.02 | M32: =_xlfn.IFERROR(L32/D32,0) -> 0.70903606
B33: BAC_MGT B2 ALT | C33: =_xlfn.SUMIFS(Allocation!$I$1:$I$175,Allocation!$C$1:$C$175,"2026",Allocation!$D$1:$D$175,"MBWAY_NAN",Allocation!$F$1:$F$175,"BAC_MGT",Allocation!$G$1:$G$175,"B2",Allocation!$H$1:$H$175,"ALT") -> 58 | D33: =_xlfn.SUMIFS(Allocation!$K$1:$K$175,Allocation!$C$1:$C$175,"2026",Allocation!$D$1:$D$175,"MBWAY_NAN",Allocation!$F$1:$F$175,"BAC_MGT",Allocation!$G$1:$G$175,"B2",Allocation!$H$1:$H$175,"ALT") -> 406000 | E33: =_xlfn.SUMIFS(Allocation!$V$1:$V$175,Allocation!$C$1:$C$175,"2026",Allocation!$D$1:$D$175,"MBWAY_NAN",Allocation!$F$1:$F$175,"BAC_MGT",Allocation!$G$1:$G$175,"B2",Allocation!$H$1:$H$175,"ALT") -> 24659.574 | F33: =_xlfn.SUMIFS(Allocation!$W$1:$W$175,Allocation!$C$1:$C$175,"2026",Allocation!$D$1:$D$175,"MBWAY_NAN",Allocation!$F$1:$F$175,"BAC_MGT",Allocation!$G$1:$G$175,"B2",Allocation!$H$1:$H$175,"ALT") -> 50870.638 | G33: =_xlfn.SUMIFS(Allocation!$X$1:$X$175,Allocation!$C$1:$C$175,"2026",Allocation!$D$1:$D$175,"MBWAY_NAN",Allocation!$F$1:$F$175,"BAC_MGT",Allocation!$G$1:$G$175,"B2",Allocation!$H$1:$H$175,"ALT") -> 21581.524 | H33: =_xlfn.SUMIFS(Allocation!$Y$1:$Y$175,Allocation!$C$1:$C$175,"2026",Allocation!$D$1:$D$175,"MBWAY_NAN",Allocation!$F$1:$F$175,"BAC_MGT",Allocation!$G$1:$G$175,"B2",Allocation!$H$1:$H$175,"ALT") -> 0 | I33: =_xlfn.SUMIFS(Allocation!$AC$1:$AC$175,Allocation!$C$1:$C$175,"2026",Allocation!$D$1:$D$175,"MBWAY_NAN",Allocation!$F$1:$F$175,"BAC_MGT",Allocation!$G$1:$G$175,"B2",Allocation!$H$1:$H$175,"ALT") -> 0 | J33: =_xlfn.SUMIFS(Allocation!$Z$1:$Z$175,Allocation!$C$1:$C$175,"2026",Allocation!$D$1:$D$175,"MBWAY_NAN",Allocation!$F$1:$F$175,"BAC_MGT",Allocation!$G$1:$G$175,"B2",Allocation!$H$1:$H$175,"ALT") -> 0 | K33: =E33+F33+G33+H33+I33+J33 -> 97111.737 | L33: =_xlfn.SUMIFS(Allocation!$AA$1:$AA$175,Allocation!$C$1:$C$175,"2026",Allocation!$D$1:$D$175,"MBWAY_NAN",Allocation!$F$1:$F$175,"BAC_MGT",Allocation!$G$1:$G$175,"B2",Allocation!$H$1:$H$175,"ALT") -> 308888.26 | M33: =_xlfn.IFERROR(L33/D33,0) -> 0.76080853
B34: BAC_MGT B3 ALT | C34: =_xlfn.SUMIFS(Allocation!$I$1:$I$175,Allocation!$C$1:$C$175,"2026",Allocation!$D$1:$D$175,"MBWAY_NAN",Allocation!$F$1:$F$175,"BAC_MGT",Allocation!$G$1:$G$175,"B3",Allocation!$H$1:$H$175,"ALT") -> 57 | D34: =_xlfn.SUMIFS(Allocation!$K$1:$K$175,Allocation!$C$1:$C$175,"2026",Allocation!$D$1:$D$175,"MBWAY_NAN",Allocation!$F$1:$F$175,"BAC_MGT",Allocation!$G$1:$G$175,"B3",Allocation!$H$1:$H$175,"ALT") -> 399000 | E34: =_xlfn.SUMIFS(Allocation!$V$1:$V$175,Allocation!$C$1:$C$175,"2026",Allocation!$D$1:$D$175,"MBWAY_NAN",Allocation!$F$1:$F$175,"BAC_MGT",Allocation!$G$1:$G$175,"B3",Allocation!$H$1:$H$175,"ALT") -> 24659.574 | F34: =_xlfn.SUMIFS(Allocation!$W$1:$W$175,Allocation!$C$1:$C$175,"2026",Allocation!$D$1:$D$175,"MBWAY_NAN",Allocation!$F$1:$F$175,"BAC_MGT",Allocation!$G$1:$G$175,"B3",Allocation!$H$1:$H$175,"ALT") -> 50870.638 | G34: =_xlfn.SUMIFS(Allocation!$X$1:$X$175,Allocation!$C$1:$C$175,"2026",Allocation!$D$1:$D$175,"MBWAY_NAN",Allocation!$F$1:$F$175,"BAC_MGT",Allocation!$G$1:$G$175,"B3",Allocation!$H$1:$H$175,"ALT") -> 21209.429 | H34: =_xlfn.SUMIFS(Allocation!$Y$1:$Y$175,Allocation!$C$1:$C$175,"2026",Allocation!$D$1:$D$175,"MBWAY_NAN",Allocation!$F$1:$F$175,"BAC_MGT",Allocation!$G$1:$G$175,"B3",Allocation!$H$1:$H$175,"ALT") -> 0 | I34: =_xlfn.SUMIFS(Allocation!$AC$1:$AC$175,Allocation!$C$1:$C$175,"2026",Allocation!$D$1:$D$175,"MBWAY_NAN",Allocation!$F$1:$F$175,"BAC_MGT",Allocation!$G$1:$G$175,"B3",Allocation!$H$1:$H$175,"ALT") -> 0 | J34: =_xlfn.SUMIFS(Allocation!$Z$1:$Z$175,Allocation!$C$1:$C$175,"2026",Allocation!$D$1:$D$175,"MBWAY_NAN",Allocation!$F$1:$F$175,"BAC_MGT",Allocation!$G$1:$G$175,"B3",Allocation!$H$1:$H$175,"ALT") -> 0 | K34: =E34+F34+G34+H34+I34+J34 -> 96739.641 | L34: =_xlfn.SUMIFS(Allocation!$AA$1:$AA$175,Allocation!$C$1:$C$175,"2026",Allocation!$D$1:$D$175,"MBWAY_NAN",Allocation!$F$1:$F$175,"BAC_MGT",Allocation!$G$1:$G$175,"B3",Allocation!$H$1:$H$175,"ALT") -> 302260.36 | M34: =_xlfn.IFERROR(L34/D34,0) -> 0.75754476
B35: MAS_MGT M1 ALT | C35: =_xlfn.SUMIFS(Allocation!$I$1:$I$175,Allocation!$C$1:$C$175,"2026",Allocation!$D$1:$D$175,"MBWAY_NAN",Allocation!$F$1:$F$175,"MAS_MGT",Allocation!$G$1:$G$175,"M1",Allocation!$H$1:$H$175,"ALT") -> 60 | D35: =_xlfn.SUMIFS(Allocation!$K$1:$K$175,Allocation!$C$1:$C$175,"2026",Allocation!$D$1:$D$175,"MBWAY_NAN",Allocation!$F$1:$F$175,"MAS_MGT",Allocation!$G$1:$G$175,"M1",Allocation!$H$1:$H$175,"ALT") -> 455400 | E35: =_xlfn.SUMIFS(Allocation!$V$1:$V$175,Allocation!$C$1:$C$175,"2026",Allocation!$D$1:$D$175,"MBWAY_NAN",Allocation!$F$1:$F$175,"MAS_MGT",Allocation!$G$1:$G$175,"M1",Allocation!$H$1:$H$175,"ALT") -> 32365.691 | F35: =_xlfn.SUMIFS(Allocation!$W$1:$W$175,Allocation!$C$1:$C$175,"2026",Allocation!$D$1:$D$175,"MBWAY_NAN",Allocation!$F$1:$F$175,"MAS_MGT",Allocation!$G$1:$G$175,"M1",Allocation!$H$1:$H$175,"ALT") -> 66767.713 | G35: =_xlfn.SUMIFS(Allocation!$X$1:$X$175,Allocation!$C$1:$C$175,"2026",Allocation!$D$1:$D$175,"MBWAY_NAN",Allocation!$F$1:$F$175,"MAS_MGT",Allocation!$G$1:$G$175,"M1",Allocation!$H$1:$H$175,"ALT") -> 38092.214 | H35: =_xlfn.SUMIFS(Allocation!$Y$1:$Y$175,Allocation!$C$1:$C$175,"2026",Allocation!$D$1:$D$175,"MBWAY_NAN",Allocation!$F$1:$F$175,"MAS_MGT",Allocation!$G$1:$G$175,"M1",Allocation!$H$1:$H$175,"ALT") -> 0 | I35: =_xlfn.SUMIFS(Allocation!$AC$1:$AC$175,Allocation!$C$1:$C$175,"2026",Allocation!$D$1:$D$175,"MBWAY_NAN",Allocation!$F$1:$F$175,"MAS_MGT",Allocation!$G$1:$G$175,"M1",Allocation!$H$1:$H$175,"ALT") -> 0 | J35: =_xlfn.SUMIFS(Allocation!$Z$1:$Z$175,Allocation!$C$1:$C$175,"2026",Allocation!$D$1:$D$175,"MBWAY_NAN",Allocation!$F$1:$F$175,"MAS_MGT",Allocation!$G$1:$G$175,"M1",Allocation!$H$1:$H$175,"ALT") -> 0 | K35: =E35+F35+G35+H35+I35+J35 -> 137225.62 | L35: =_xlfn.SUMIFS(Allocation!$AA$1:$AA$175,Allocation!$C$1:$C$175,"2026",Allocation!$D$1:$D$175,"MBWAY_NAN",Allocation!$F$1:$F$175,"MAS_MGT",Allocation!$G$1:$G$175,"M1",Allocation!$H$1:$H$175,"ALT") -> 318174.38 | M35: =_xlfn.IFERROR(L35/D35,0) -> 0.69867014
B36: MAS_MGT M2 ALT | C36: =_xlfn.SUMIFS(Allocation!$I$1:$I$175,Allocation!$C$1:$C$175,"2026",Allocation!$D$1:$D$175,"MBWAY_NAN",Allocation!$F$1:$F$175,"MAS_MGT",Allocation!$G$1:$G$175,"M2",Allocation!$H$1:$H$175,"ALT") -> 59 | D36: =_xlfn.SUMIFS(Allocation!$K$1:$K$175,Allocation!$C$1:$C$175,"2026",Allocation!$D$1:$D$175,"MBWAY_NAN",Allocation!$F$1:$F$175,"MAS_MGT",Allocation!$G$1:$G$175,"M2",Allocation!$H$1:$H$175,"ALT") -> 442500 | E36: =_xlfn.SUMIFS(Allocation!$V$1:$V$175,Allocation!$C$1:$C$175,"2026",Allocation!$D$1:$D$175,"MBWAY_NAN",Allocation!$F$1:$F$175,"MAS_MGT",Allocation!$G$1:$G$175,"M2",Allocation!$H$1:$H$175,"ALT") -> 32365.691 | F36: =_xlfn.SUMIFS(Allocation!$W$1:$W$175,Allocation!$C$1:$C$175,"2026",Allocation!$D$1:$D$175,"MBWAY_NAN",Allocation!$F$1:$F$175,"MAS_MGT",Allocation!$G$1:$G$175,"M2",Allocation!$H$1:$H$175,"ALT") -> 66767.713 | G36: =_xlfn.SUMIFS(Allocation!$X$1:$X$175,Allocation!$C$1:$C$175,"2026",Allocation!$D$1:$D$175,"MBWAY_NAN",Allocation!$F$1:$F$175,"MAS_MGT",Allocation!$G$1:$G$175,"M2",Allocation!$H$1:$H$175,"ALT") -> 21953.619 | H36: =_xlfn.SUMIFS(Allocation!$Y$1:$Y$175,Allocation!$C$1:$C$175,"2026",Allocation!$D$1:$D$175,"MBWAY_NAN",Allocation!$F$1:$F$175,"MAS_MGT",Allocation!$G$1:$G$175,"M2",Allocation!$H$1:$H$175,"ALT") -> 0 | I36: =_xlfn.SUMIFS(Allocation!$AC$1:$AC$175,Allocation!$C$1:$C$175,"2026",Allocation!$D$1:$D$175,"MBWAY_NAN",Allocation!$F$1:$F$175,"MAS_MGT",Allocation!$G$1:$G$175,"M2",Allocation!$H$1:$H$175,"ALT") -> 0 | J36: =_xlfn.SUMIFS(Allocation!$Z$1:$Z$175,Allocation!$C$1:$C$175,"2026",Allocation!$D$1:$D$175,"MBWAY_NAN",Allocation!$F$1:$F$175,"MAS_MGT",Allocation!$G$1:$G$175,"M2",Allocation!$H$1:$H$175,"ALT") -> 0 | K36: =E36+F36+G36+H36+I36+J36 -> 121087.02 | L36: =_xlfn.SUMIFS(Allocation!$AA$1:$AA$175,Allocation!$C$1:$C$175,"2026",Allocation!$D$1:$D$175,"MBWAY_NAN",Allocation!$F$1:$F$175,"MAS_MGT",Allocation!$G$1:$G$175,"M2",Allocation!$H$1:$H$175,"ALT") -> 321412.98 | M36: =_xlfn.IFERROR(L36/D36,0) -> 0.72635701
B37: Bordeaux (MBWAY_BOR) | C37: =_xlfn.SUMIFS(Allocation!$I$1:$I$175,Allocation!$C$1:$C$175,"2026",Allocation!$D$1:$D$175,"MBWAY_BOR") -> 249 | D37: =_xlfn.SUMIFS(Allocation!$K$1:$K$175,Allocation!$C$1:$C$175,"2026",Allocation!$D$1:$D$175,"MBWAY_BOR") -> 1773610 | E37: =_xlfn.SUMIFS(Allocation!$V$1:$V$175,Allocation!$C$1:$C$175,"2026",Allocation!$D$1:$D$175,"MBWAY_BOR") -> 120729 | F37: =_xlfn.SUMIFS(Allocation!$W$1:$W$175,Allocation!$C$1:$C$175,"2026",Allocation!$D$1:$D$175,"MBWAY_BOR") -> 261507 | G37: =_xlfn.SUMIFS(Allocation!$X$1:$X$175,Allocation!$C$1:$C$175,"2026",Allocation!$D$1:$D$175,"MBWAY_BOR") -> 117575 | H37: =_xlfn.SUMIFS(Allocation!$Y$1:$Y$175,Allocation!$C$1:$C$175,"2026",Allocation!$D$1:$D$175,"MBWAY_BOR") -> 0 | I37: =_xlfn.SUMIFS(Allocation!$AC$1:$AC$175,Allocation!$C$1:$C$175,"2026",Allocation!$D$1:$D$175,"MBWAY_BOR") -> 0 | J37: =_xlfn.SUMIFS(Allocation!$Z$1:$Z$175,Allocation!$C$1:$C$175,"2026",Allocation!$D$1:$D$175,"MBWAY_BOR") -> 0 | K37: =E37+F37+G37+H37+I37+J37 -> 499811 | L37: =_xlfn.SUMIFS(Allocation!$AA$1:$AA$175,Allocation!$C$1:$C$175,"2026",Allocation!$D$1:$D$175,"MBWAY_BOR") -> 1273799 | M37: =_xlfn.IFERROR(L37/D37,0) -> 0.71819566
B38: BAC_MGT B1 INIT | C38: =_xlfn.SUMIFS(Allocation!$I$1:$I$175,Allocation!$C$1:$C$175,"2026",Allocation!$D$1:$D$175,"MBWAY_BOR",Allocation!$F$1:$F$175,"BAC_MGT",Allocation!$G$1:$G$175,"B1",Allocation!$H$1:$H$175,"INIT") -> 51 | D38: =_xlfn.SUMIFS(Allocation!$K$1:$K$175,Allocation!$C$1:$C$175,"2026",Allocation!$D$1:$D$175,"MBWAY_BOR",Allocation!$F$1:$F$175,"BAC_MGT",Allocation!$G$1:$G$175,"B1",Allocation!$H$1:$H$175,"INIT") -> 375615 | E38: =_xlfn.SUMIFS(Allocation!$V$1:$V$175,Allocation!$C$1:$C$175,"2026",Allocation!$D$1:$D$175,"MBWAY_BOR",Allocation!$F$1:$F$175,"BAC_MGT",Allocation!$G$1:$G$175,"B1",Allocation!$H$1:$H$175,"INIT") -> 30182.25 | F38: =_xlfn.SUMIFS(Allocation!$W$1:$W$175,Allocation!$C$1:$C$175,"2026",Allocation!$D$1:$D$175,"MBWAY_BOR",Allocation!$F$1:$F$175,"BAC_MGT",Allocation!$G$1:$G$175,"B1",Allocation!$H$1:$H$175,"INIT") -> 65376.75 | G38: =_xlfn.SUMIFS(Allocation!$X$1:$X$175,Allocation!$C$1:$C$175,"2026",Allocation!$D$1:$D$175,"MBWAY_BOR",Allocation!$F$1:$F$175,"BAC_MGT",Allocation!$G$1:$G$175,"B1",Allocation!$H$1:$H$175,"INIT") -> 31438.416 | H38: =_xlfn.SUMIFS(Allocation!$Y$1:$Y$175,Allocation!$C$1:$C$175,"2026",Allocation!$D$1:$D$175,"MBWAY_BOR",Allocation!$F$1:$F$175,"BAC_MGT",Allocation!$G$1:$G$175,"B1",Allocation!$H$1:$H$175,"INIT") -> 0 | I38: =_xlfn.SUMIFS(Allocation!$AC$1:$AC$175,Allocation!$C$1:$C$175,"2026",Allocation!$D$1:$D$175,"MBWAY_BOR",Allocation!$F$1:$F$175,"BAC_MGT",Allocation!$G$1:$G$175,"B1",Allocation!$H$1:$H$175,"INIT") -> 0 | J38: =_xlfn.SUMIFS(Allocation!$Z$1:$Z$175,Allocation!$C$1:$C$175,"2026",Allocation!$D$1:$D$175,"MBWAY_BOR",Allocation!$F$1:$F$175,"BAC_MGT",Allocation!$G$1:$G$175,"B1",Allocation!$H$1:$H$175,"INIT") -> 0 | K38: =E38+F38+G38+H38+I38+J38 -> 126997.42 | L38: =_xlfn.SUMIFS(Allocation!$AA$1:$AA$175,Allocation!$C$1:$C$175,"2026",Allocation!$D$1:$D$175,"MBWAY_BOR",Allocation!$F$1:$F$175,"BAC_MGT",Allocation!$G$1:$G$175,"B1",Allocation!$H$1:$H$175,"INIT") -> 248617.58 | M38: =_xlfn.IFERROR(L38/D38,0) -> 0.66189472
